Workbook

Sheet S11.03
A1: 八卦路线 | F1: 八卦前亏损 | H1: {=SUM(VLOOKUP(A4:C100,$T$3:$W$36,4,FALSE))+H4*10-H8*50} -> 2396.664 | I1: 收尾路线 | Q1: 全局统计
A2: 行动 | D2: 统计 | I2: 行动 | L2: 统计 | Q2: 总经验 | R2: {=SUM(V3:V28*AB3:AB28)+H6+P6+R4*500} -> 65965 | T2: 地块 | U2: 粮草 | V2: 经验 | W2: 八卦前亏损 | X2: 总数 | Y2: 占领数 | Z2: 前期 | AA2: 收尾 | AB2: 中期 | AC2: 前期 | AD2: 收尾 | AE2: 中期
A3: 一队 | B3: 二队 | C3: 三队 | E3: 一队 | F3: 二队 | G3: 三队 | H3: 总 | I3: 一队 | J3: 二队 | K3: 三队 | M3: 一队 | N3: 二队 | O3: 三队 | P3: 总 | Q3: 天数 | R3: 91 | T3: 1级 | U3: 150 | V3: 35 | W3: =U3-V3/0.330882 -> 44.222109 | Y3: 19 | Z3: =COUNTIF($A$4:$C$100,T3) -> 13 | AA3: =COUNTIF($I$4:$K$100,T3) -> 6 | AB3: =Y3-Z3-AA3 -> 0 | AC3: 7 | AD3: 1 | AE3: 0 | AF3: =Z3-AC3 -> 6 | AG3: =AA3+AB3-AD3-AE3 -> 5
A4: 1级 | B4: 1级 | C4: 空 | D4: 跳步 | E4: 0 | F4: 0 | G4: 0 | H4: =SUM(E4:G4) -> 0 | I4: 商人 | J4: 2级 | K4: 2级 | L4: 跳步 | M4: 1 | N4: 0 | O4: 2 | P4: =SUM(M4:O4) -> 3 | Q4: 周数 | R4: 14 | T4: 2级 | U4: 160 | V4: 40 | W4: =U4-V4/0.330882 -> 39.110982 | Y4: 40 | Z4: =COUNTIF($A$4:$C$100,T4) -> 7 | AA4: =COUNTIF($I$4:$K$100,T4) -> 33 | AB4: =Y4-Z4-AA4 -> 0 | AC4: 23 | AD4: 22 | AE4: 0 | AF4: =Z4-AC4 -> -16 | AG4: =AA4+AB4-AD4-AE4 -> 11
A5: 1级 | B5: 1级 | C5: 空 | D5: 消耗粮草 | E5: =(SUM(粮草!A4:A100)+E4*10)-E8*50 -> 800 | F5: =(SUM(粮草!B4:B100)+F4*10)-F8*50 -> 5080 | G5: =(SUM(粮草!C4:C100)+G4*10)-G8*50 -> 6690 | H5: =SUM(E5:G5) -> 12570 | I5: 空 | J5: 2级 | K5: 2级 | L5: 消耗粮草 | M5: =(SUM(粮草!I4:I100)*0.8+M4*8)-M8*40 -> 648 | N5: =(SUM(粮草!J4:J100)*0.8+N4*8)-N8*40 -> 672 | O5: =(SUM(粮草!K4:K100)*0.8+O4*8)-O8*40 -> 4088 | P5: =SUM(M5:O5) -> 5408 | Q5: 种植粮草 | R5: 6000 | T5: 3级 | U5: 170 | V5: 45 | W5: 34 | Y5: 237 | Z5: =COUNTIF($A$4:$C$100,T5) -> 42 | AA5: =COUNTIF($I$4:$K$100,T5) -> 0 | AB5: =Y5-Z5-AA5 -> 195 | AC5: 38 | AD5: 0 | AE5: 206 | AF5: =Z5-AC5 -> 4 | AG5: =AA5+AB5-AD5-AE5 -> -11
A6: 商人 | B6: 1级 | C6: 1级 | D6: 获得经验 | E6: =(SUM(经验!A4:A100)) -> 205 | F6: =(SUM(经验!B4:B100)) -> 1595 | G6: =(SUM(经验!C4:C100)) -> 2320 | H6: =SUM(E6:G6) -> 4120 | I6: 1级 | J6: 塔2 | K6: 2级 | L6: 获得经验 | M6: =(SUM(经验!I4:I100)) -> 270 | N6: =(SUM(经验!J4:J100)) -> 230 | O6: =(SUM(经验!K4:K100)) -> 2000 | P6: =SUM(M6:O6) -> 2500 | Q6: 总粮草 | R6: =R3*1600-800+R5 -> 150800 | T6: 4级 | U6: 180 | V6: 50 | W6: 36 | X6: 267 | Y6: 267 | Z6: =COUNTIF($A$4:$C$100,T6) -> 2 | AA6: =COUNTIF($I$4:$K$100,T6) -> 0 | AB6: =Y6-Z6-AA6 -> 265 | AC6: 2 | AD6: 0 | AE6: 258 | AF6: =Z6-AC6 -> 0 | AG6: =AA6+AB6-AD6-AE6 -> 7
A7: 1级 | B7: 1级 | C7: 1级 | D7: 步数 | E7: =COUNTIF(A4:A100,"<>空") -> 6 | F7: =COUNTIF(B4:B100,"<>空") -> 31 | G7: =COUNTIF(C4:C100,"<>空") -> 44 | H7: =SUM(E7:G7) -> 81 | I7: 1级 | J7: 2级 | K7: 商人 | L7: 步数 | M7: =COUNTIF(I4:I100,"<>空") -> 9 | N7: =COUNTIF(J4:J100,"<>空") -> 6 | O7: =COUNTIF(K4:K100,"<>空") -> 41 | P7: =SUM(M7:O7) -> 56 | Q7: 中期跳步 | R7: 1 | T7: 5级 | U7: 190 | V7: 55 | W7: 38 | X7: 235 | Y7: 235 | Z7: =COUNTIF($A$4:$C$100,T7) -> 0 | AA7: =COUNTIF($I$4:$K$100,T7) -> 0 | AB7: =Y7-Z7-AA7 -> 235 | AC7: 0 | AD7: 0 | AE7: 238 | AF7: =Z7-AC7 -> 0 | AG7: =AA7+AB7-AD7-AE7 -> -3
A8: 1级 | B8: 1级 | C8: 1级 | D8: 传送 | E8: 0 | F8: 1 | G8: 0 | H8: =SUM(E8:G8) -> 1 | I8: 营地+ | J8: 2级 | K8: 2级 | L8: 传送 | M8: 0 | N8: 0 | O8: 2 | P8: =SUM(M8:O8) -> 2 | Q8: 剩余粮草 | R8: {=R6-P5-H5-SUM(U3:U28*AB3:AB28)*0.8-R7*8} -> 14 | T8: 6级 | U8: 200 | V8: 60 | X8: 194 | Y8: 194 | Z8: =COUNTIF($A$4:$C$100,T8) -> 0 | AA8: =COUNTIF($I$4:$K$100,T8) -> 0 | AB8: =Y8-Z8-AA8 -> 194 | AC8: 0 | AD8: 0 | AE8: 194 | AF8: =Z8-AC8 -> 0 | AG8: =AA8+AB8-AD8-AE8 -> 0
A9: 1级 | B9: 商人 | C9: 营地 | I9: 空 | J9: 商人 | K9: 2级 | L9: 性价比 | M9: =M6/M5 -> 0.41666667 | N9: =N6/N5 -> 0.3422619 | O9: =O6/O5 -> 0.48923679 | P9: =P6/P5 -> 0.46227811 | T9: 塔1 | U9: 150 | V9: 35 | W9: =U9-V9/0.330882 -> 44.222109 | X9: 5 | Y9: 0 | Z9: =COUNTIF($A$4:$C$100,T9) -> 0 | AA9: =COUNTIF($I$4:$K$100,T9) -> 0 | AB9: =Y9-Z9-AA9 -> 0 | AC9: 0 | AD9: 0 | AE9: 0 | AF9: =Z9-AC9 -> 0 | AG9: =AA9+AB9-AD9-AE9 -> 0
A10: 空 | B10: 空 | C10: 2级 | I10: 1级 | J10: 空 | K10: 2级 | T10: 塔2 | U10: 150 | V10: 40 | W10: =U10-V10/0.330882 -> 29.110982 | X10: 6 | Y10: 3 | Z10: =COUNTIF($A$4:$C$100,T10) -> 0 | AA10: =COUNTIF($I$4:$K$100,T10) -> 3 | AB10: =Y10-Z10-AA10 -> 0 | AC10: 0 | AD10: 0 | AE10: 0 | AF10: =Z10-AC10 -> 0 | AG10: =AA10+AB10-AD10-AE10 -> 3
A11: 空 | B11: 3级 | C11: 2级 | I11: 1级 | J11: 空 | K11: 商人 | T11: 塔3 | U11: 150 | V11: 45 | W11: =U11-V11/0.330882 -> 13.999855 | X11: 6 | Y11: 6 | Z11: =COUNTIF($A$4:$C$100,T11) -> 2 | AA11: =COUNTIF($I$4:$K$100,T11) -> 0 | AB11: =Y11-Z11-AA11 -> 4 | AC11: 2 | AD11: 0 | AE11: 4 | AF11: =Z11-AC11 -> 0 | AG11: =AA11+AB11-AD11-AE11 -> 0
A12: 空 | B12: 3级 | C12: 2级 | I12: 1级 | J12: 空 | K12: 空 | T12: 塔4 | U12: 150 | V12: 50 | X12: 3 | Y12: 3 | Z12: =COUNTIF($A$4:$C$100,T12) -> 0 | AA12: =COUNTIF($I$4:$K$100,T12) -> 0 | AB12: =Y12-Z12-AA12 -> 3 | AC12: 0 | AD12: 0 | AE12: 4 | AF12: =Z12-AC12 -> 0 | AG12: =AA12+AB12-AD12-AE12 -> -1
A13: 空 | B13: 3级 | C13: 2级 | I13: 1级 | J13: 空 | K13: 塔2 | T13: 塔5 | U13: 150 | V13: 55 | X13: 3 | Y13: 3 | Z13: =COUNTIF($A$4:$C$100,T13) -> 0 | AA13: =COUNTIF($I$4:$K$100,T13) -> 0 | AB13: =Y13-Z13-AA13 -> 3 | AC13: 0 | AD13: 0 | AE13: 3 | AF13: =Z13-AC13 -> 0 | AG13: =AA13+AB13-AD13-AE13 -> 0
A14: 空 | B14: 3级 | C14: 商人 | I14: 商人 | J14: 空 | K14: 2级 | T14: 塔6 | U14: 150 | V14: 60 | X14: 1 | Y14: 1 | Z14: =COUNTIF($A$4:$C$100,T14) -> 0 | AA14: =COUNTIF($I$4:$K$100,T14) -> 0 | AB14: =Y14-Z14-AA14 -> 1 | AC14: 0 | AD14: 0 | AE14: 1 | AF14: =Z14-AC14 -> 0 | AG14: =AA14+AB14-AD14-AE14 -> 0
A15: 空 | B15: 3级 | C15: 2级 | I15: 空 | J15: 空 | K15: 2级 | T15: 遗迹 | U15: 150 | V15: 35 | W15: =U15-V15/0.330882 -> 44.222109 | Y15: 0 | Z15: =COUNTIF($A$4:$C$100,T15) -> 0 | AA15: =COUNTIF($I$4:$K$100,T15) -> 0 | AB15: =Y15-Z15-AA15 -> 0 | AC15: 3 | AD15: 0 | AE15: 0 | AF15: =Z15-AC15 -> -3 | AG15: =AA15+AB15-AD15-AE15 -> 0
A16: 空 | B16: 3级 | C16: 2级 | I16: 空 | J16: 空 | K16: 2级 | T16: 商人 | U16: 50 | V16: 30 | W16: 10 | X16: 40 | Y16: 39 | Z16: =COUNTIF($A$4:$C$100,T16) -> 6 | AA16: =COUNTIF($I$4:$K$100,T16) -> 11 | AB16: =Y16-Z16-AA16 -> 22 | AC16: 3 | AD16: 8 | AE16: 27 | AF16: =Z16-AC16 -> 3 | AG16: =AA16+AB16-AD16-AE16 -> -2
A17: 空 | B17: 大卦 | C17: 2级 | I17: 空 | J17: 空 | K17: 塔2 | T17: 营地 | U17: -150 | V17: 0 | W17: 10 | X17: 1 | Y17: 1 | Z17: =COUNTIF($A$4:$C$100,T17) -> 1 | AA17: =COUNTIF($I$4:$K$100,T17) -> 0 | AB17: =Y17-Z17-AA17 -> 0 | AC17: 2 | AD17: 0 | AE17: 0 | AF17: =Z17-AC17 -> -1 | AG17: =AA17+AB17-AD17-AE17 -> 0
A18: 空 | B18: 3级 | C18: 3级 | I18: 空 | J18: 空 | K18: 2级 | T18: 大卦 | U18: 250 | V18: 300 | X18: 3 | Y18: 3 | Z18: =COUNTIF($A$4:$C$100,T18) -> 3 | AA18: =COUNTIF($I$4:$K$100,T18) -> 0 | AB18: =Y18-Z18-AA18 -> 0 | AC18: 3 | AD18: 0 | AE18: 0 | AF18: =Z18-AC18 -> 0 | AG18: =AA18+AB18-AD18-AE18 -> 0
A19: 空 | B19: 3级 | C19: 小卦 | I19: 空 | J19: 空 | K19: 商人 | T19: 小卦 | U19: 170 | V19: 45 | X19: 5 | Y19: 5 | Z19: =COUNTIF($A$4:$C$100,T19) -> 5 | AA19: =COUNTIF($I$4:$K$100,T19) -> 0 | AB19: =Y19-Z19-AA19 -> 0 | AC19: 5 | AD19: 0 | AE19: 0 | AF19: =Z19-AC19 -> 0 | AG19: =AA19+AB19-AD19-AE19 -> 0
A20: 空 | B20: 4级 | C20: 3级 | I20: 空 | J20: 空 | K20: 2级 | T20: 小boss | U20: 250 | V20: 200 | X20: 0 | Y20: 0 | Z20: =COUNTIF($A$4:$C$100,T20) -> 0 | AA20: =COUNTIF($I$4:$K$100,T20) -> 0 | AB20: =Y20-Z20-AA20 -> 0 | AC20: 0 | AD20: 0 | AE20: 0 | AF20: =Z20-AC20 -> 0 | AG20: =AA20+AB20-AD20-AE20 -> 0
A21: 空 | B21: 4级 | C21: 商人 | I21: 空 | J21: 空 | K21: 2级 | T21: 大boss | U21: 250 | V21: 1000 | X21: 2 | Y21: 2 | Z21: =COUNTIF($A$4:$C$100,T21) -> 0 | AA21: =COUNTIF($I$4:$K$100,T21) -> 0 | AB21: =Y21-Z21-AA21 -> 2 | AC21: 0 | AD21: 0 | AE21: 2 | AF21: =Z21-AC21 -> 0 | AG21: =AA21+AB21-AD21-AE21 -> 0
A22: 空 | B22: 3级 | C22: 3级 | I22: 空 | J22: 空 | K22: 2级 | T22: 中boss | U22: 250 | V22: 500 | X22: 3 | Y22: 3 | Z22: =COUNTIF($A$4:$C$100,T22) -> 0 | AA22: =COUNTIF($I$4:$K$100,T22) -> 0 | AB22: =Y22-Z22-AA22 -> 3 | AC22: 0 | AD22: 0 | AE22: 2 | AF22: =Z22-AC22 -> 0 | AG22: =AA22+AB22-AD22-AE22 -> 1
A23: 空 | B23: 塔3 | C23: 大卦 | I23: 空 | J23: 空 | K23: 2级 | T23: 奈良 | U23: 160 | V23: 40 | W23: =U23-V23/0.330882 -> 39.110982 | X23: 0 | Y23: 0 | Z23: =COUNTIF($A$4:$C$100,T23) -> 0 | AA23: =COUNTIF($I$4:$K$100,T23) -> 0 | AB23: =Y23-Z23-AA23 -> 0 | AC23: 0 | AD23: 0 | AE23: 0 | AF23: =Z23-AC23 -> 0 | AG23: =AA23+AB23-AD23-AE23 -> 0
A24: 空 | B24: 3级 | C24: 3级 | I24: 空 | J24: 空 | K24: 营地+ | T24: 山中 | U24: 160 | V24: 40 | W24: =U24-V24/0.330882 -> 39.110982 | X24: 0 | Y24: 0 | Z24: =COUNTIF($A$4:$C$100,T24) -> 0 | AA24: =COUNTIF($I$4:$K$100,T24) -> 0 | AB24: =Y24-Z24-AA24 -> 0 | AC24: 0 | AD24: 0 | AE24: 0 | AF24: =Z24-AC24 -> 0 | AG24: =AA24+AB24-AD24-AE24 -> 0
A25: 空 | B25: 3级 | C25: 3级 | I25: 空 | J25: 空 | K25: 2级 | T25: 秋道 | U25: 150 | V25: 35 | W25: =U25-V25/0.330882 -> 44.222109 | X25: 0 | Y25: 0 | Z25: =COUNTIF($A$4:$C$100,T25) -> 0 | AA25: =COUNTIF($I$4:$K$100,T25) -> 0 | AB25: =Y25-Z25-AA25 -> 0 | AC25: 0 | AD25: 0 | AE25: 0 | AF25: =Z25-AC25 -> 0 | AG25: =AA25+AB25-AD25-AE25 -> 0
A26: 空 | B26: 小卦 | C26: 塔3 | I26: 空 | J26: 空 | K26: 商人 | T26: 空 | U26: 0 | V26: 0 | W26: =U26-V26/0.330882 -> 0 | X26: 0 | Y26: 0 | AF26: =Z26-AC26 -> 0 | AG26: =AA26+AB26-AD26-AE26 -> 0
A27: 空 | B27: 3级 | C27: 3级 | I27: 空 | J27: 空 | K27: 2级 | T27: 营地+ | U27: -200 | V27: 0 | X27: 14 | Y27: 14 | Z27: =COUNTIF($A$4:$C$100,T27) -> 0 | AA27: =COUNTIF($I$4:$K$100,T27) -> 2 | AB27: =Y27-Z27-AA27 -> 12 | AC27: 0 | AD27: 2 | AE27: 11 | AF27: =Z27-AC27 -> 0 | AG27: =AA27+AB27-AD27-AE27 -> 1
A28: 空 | B28: 3级 | C28: 3级 | I28: 空 | J28: 空 | K28: 2级 | T28: 历练 | U28: 50 | V28: 520 | W28: 10 | X28: 3 | Y28: 3 | Z28: =COUNTIF($A$4:$C$100,T28) -> 0 | AA28: =COUNTIF($I$4:$K$100,T28) -> 1 | AB28: =Y28-Z28-AA28 -> 2 | AC28: 1 | AD28: 0 | AE28: 2 | AF28: =Z28-AC28 -> -1 | AG28: =AA28+AB28-AD28-AE28 -> 1
A29: 空 | B29: 3级 | C29: 商人 | I29: 空 | J29: 空 | K29: 商人 | T29: 跳步 | AF29: {=SUM(AF3:AF28*U3:U28)} -> -1180 | AG29: {=SUM(AG3:AG28*U3:U28*0.8)} -> 1304
A30: 空 | B30: 3级 | C30: 3级 | I30: 空 | J30: 空 | K30: 2级 | Y30: =SUM(Y3:Y28) -> 1078 | AC30: =SUM(AC3:AC28) -> 89
A31: 空 | B31: 3级 | C31: 3级 | I31: 空 | J31: 空 | K31: 2级 | AG31: =AG29+AF29+AC36-12 -> 168
A32: 空 | B32: 3级 | C32: 3级 | I32: 空 | J32: 空 | K32: 2级 | Q32: 使用说明 | R32: 1 | S32: 绿色格子需要手动填写
A33: 空 | B33: 3级 | C33: 小卦 | I33: 空 | J33: 空 | K33: 2级 | R33: 2 | S33: 在R列填写赛季基本信息
A34: 空 | B34: 3级 | C34: 3级 | I34: 空 | J34: 空 | K34: 商人 | R34: 3 | S34: 统计重要地块个数，填入X列 | AA34: 7 | AB34: 18 | AC34: =AA34*10+AB34*8 -> 214
A35: 空 | B35: 小卦 | C35: 3级 | I35: 空 | J35: 空 | K35: 空 | R35: 4 | S35: 规划八卦以及收尾路线，填入ABC，FGH列，填写跳步和传送次数 | AA35: 11 | AB35: 6 | AC35: =AA35*10+AB35*8 -> 158
A36: 空 | B36: 空 | C36: 3级 | I36: 空 | J36: 空 | K36: 历练 | S36: note：八卦路线为拿满八卦之前的路线，收尾路线原则上不包括任何三级地 | AC36: =AC34-AC35 -> 56
A37: 空 | B37: 空 | C37: 大卦 | I37: 空 | J37: 空 | K37: 2级 | R37: 5 | S37: 统计确定需要占领的各种地块个数，填入Y列
A38: 空 | B38: 空 | C38: 3级 | I38: 空 | J38: 空 | K38: 2级 | R38: 6 | S38: 根据剩余粮草，调整占领的三级地个数，直至粮草小于144
A39: 空 | B39: 空 | C39: 3级 | I39: 空 | J39: 空 | K39: 2级 | R39: 7 | S39: 对路线进行最终微调以最大化R2的总经验
A40: 空 | B40: 空 | C40: 3级 | I40: 空 | J40: 空 | K40: 2级
...

Sheet 粮草
A2: 行动 | I2: 行动
A3: 一队 | B3: 二队 | C3: 三队 | I3: 一队 | J3: 二队 | K3: 三队
A4: =(VLOOKUP('S11.03'!A4,'S11.03'!$T$3:$V$28,2,FALSE)) -> 150 | B4: =(VLOOKUP('S11.03'!B4,'S11.03'!$T$3:$V$28,2,FALSE)) -> 150 | C4: =(VLOOKUP('S11.03'!C4,'S11.03'!$T$3:$V$28,2,FALSE)) -> 0 | I4: =(VLOOKUP('S11.03'!I4,'S11.03'!$T$3:$V$28,2,FALSE)) -> 50 | J4: =(VLOOKUP('S11.03'!J4,'S11.03'!$T$3:$V$28,2,FALSE)) -> 160 | K4: =(VLOOKUP('S11.03'!K4,'S11.03'!$T$3:$V$28,2,FALSE)) -> 160
A5: =(VLOOKUP('S11.03'!A5,'S11.03'!$T$3:$V$28,2,FALSE)) -> 150 | B5: =(VLOOKUP('S11.03'!B5,'S11.03'!$T$3:$V$28,2,FALSE)) -> 150 | C5: =(VLOOKUP('S11.03'!C5,'S11.03'!$T$3:$V$28,2,FALSE)) -> 0 | I5: =(VLOOKUP('S11.03'!I5,'S11.03'!$T$3:$V$28,2,FALSE)) -> 0 | J5: =(VLOOKUP('S11.03'!J5,'S11.03'!$T$3:$V$28,2,FALSE)) -> 160 | K5: =(VLOOKUP('S11.03'!K5,'S11.03'!$T$3:$V$28,2,FALSE)) -> 160
A6: =(VLOOKUP('S11.03'!A6,'S11.03'!$T$3:$V$28,2,FALSE)) -> 50 | B6: =(VLOOKUP('S11.03'!B6,'S11.03'!$T$3:$V$28,2,FALSE)) -> 150 | C6: =(VLOOKUP('S11.03'!C6,'S11.03'!$T$3:$V$28,2,FALSE)) -> 150 | I6: =(VLOOKUP('S11.03'!I6,'S11.03'!$T$3:$V$28,2,FALSE)) -> 150 | J6: =(VLOOKUP('S11.03'!J6,'S11.03'!$T$3:$V$28,2,FALSE)) -> 150 | K6: =(VLOOKUP('S11.03'!K6,'S11.03'!$T$3:$V$28,2,FALSE)) -> 160
A7: =(VLOOKUP('S11.03'!A7,'S11.03'!$T$3:$V$28,2,FALSE)) -> 150 | B7: =(VLOOKUP('S11.03'!B7,'S11.03'!$T$3:$V$28,2,FALSE)) -> 150 | C7: =(VLOOKUP('S11.03'!C7,'S11.03'!$T$3:$V$28,2,FALSE)) -> 150 | I7: =(VLOOKUP('S11.03'!I7,'S11.03'!$T$3:$V$28,2,FALSE)) -> 150 | J7: =(VLOOKUP('S11.03'!J7,'S11.03'!$T$3:$V$28,2,FALSE)) -> 160 | K7: =(VLOOKUP('S11.03'!K7,'S11.03'!$T$3:$V$28,2,FALSE)) -> 50
A8: =(VLOOKUP('S11.03'!A8,'S11.03'!$T$3:$V$28,2,FALSE)) -> 150 | B8: =(VLOOKUP('S11.03'!B8,'S11.03'!$T$3:$V$28,2,FALSE)) -> 150 | C8: =(VLOOKUP('S11.03'!C8,'S11.03'!$T$3:$V$28,2,FALSE)) -> 150 | I8: =(VLOOKUP('S11.03'!I8,'S11.03'!$T$3:$V$28,2,FALSE)) -> -200 | J8: =(VLOOKUP('S11.03'!J8,'S11.03'!$T$3:$V$28,2,FALSE)) -> 160 | K8: =(VLOOKUP('S11.03'!K8,'S11.03'!$T$3:$V$28,2,FALSE)) -> 160
A9: =(VLOOKUP('S11.03'!A9,'S11.03'!$T$3:$V$28,2,FALSE)) -> 150 | B9: =(VLOOKUP('S11.03'!B9,'S11.03'!$T$3:$V$28,2,FALSE)) -> 50 | C9: =(VLOOKUP('S11.03'!C9,'S11.03'!$T$3:$V$28,2,FALSE)) -> -150 | I9: =(VLOOKUP('S11.03'!I9,'S11.03'!$T$3:$V$28,2,FALSE)) -> 0 | J9: =(VLOOKUP('S11.03'!J9,'S11.03'!$T$3:$V$28,2,FALSE)) -> 50 | K9: =(VLOOKUP('S11.03'!K9,'S11.03'!$T$3:$V$28,2,FALSE)) -> 160
A10: =(VLOOKUP('S11.03'!A10,'S11.03'!$T$3:$V$28,2,FALSE)) -> 0 | B10: =(VLOOKUP('S11.03'!B10,'S11.03'!$T$3:$V$28,2,FALSE)) -> 0 | C10: =(VLOOKUP('S11.03'!C10,'S11.03'!$T$3:$V$28,2,FALSE)) -> 160 | I10: =(VLOOKUP('S11.03'!I10,'S11.03'!$T$3:$V$28,2,FALSE)) -> 150 | J10: =(VLOOKUP('S11.03'!J10,'S11.03'!$T$3:$V$28,2,FALSE)) -> 0 | K10: =(VLOOKUP('S11.03'!K10,'S11.03'!$T$3:$V$28,2,FALSE)) -> 160
A11: =(VLOOKUP('S11.03'!A11,'S11.03'!$T$3:$V$28,2,FALSE)) -> 0 | B11: =(VLOOKUP('S11.03'!B11,'S11.03'!$T$3:$V$28,2,FALSE)) -> 170 | C11: =(VLOOKUP('S11.03'!C11,'S11.03'!$T$3:$V$28,2,FALSE)) -> 160 | I11: =(VLOOKUP('S11.03'!I11,'S11.03'!$T$3:$V$28,2,FALSE)) -> 150 | J11: =(VLOOKUP('S11.03'!J11,'S11.03'!$T$3:$V$28,2,FALSE)) -> 0 | K11: =(VLOOKUP('S11.03'!K11,'S11.03'!$T$3:$V$28,2,FALSE)) -> 50
A12: =(VLOOKUP('S11.03'!A12,'S11.03'!$T$3:$V$28,2,FALSE)) -> 0 | B12: =(VLOOKUP('S11.03'!B12,'S11.03'!$T$3:$V$28,2,FALSE)) -> 170 | C12: =(VLOOKUP('S11.03'!C12,'S11.03'!$T$3:$V$28,2,FALSE)) -> 160 | I12: =(VLOOKUP('S11.03'!I12,'S11.03'!$T$3:$V$28,2,FALSE)) -> 150 | J12: =(VLOOKUP('S11.03'!J12,'S11.03'!$T$3:$V$28,2,FALSE)) -> 0 | K12: =(VLOOKUP('S11.03'!K12,'S11.03'!$T$3:$V$28,2,FALSE)) -> 0
A13: =(VLOOKUP('S11.03'!A13,'S11.03'!$T$3:$V$28,2,FALSE)) -> 0 | B13: =(VLOOKUP('S11.03'!B13,'S11.03'!$T$3:$V$28,2,FALSE)) -> 170 | C13: =(VLOOKUP('S11.03'!C13,'S11.03'!$T$3:$V$28,2,FALSE)) -> 160 | I13: =(VLOOKUP('S11.03'!I13,'S11.03'!$T$3:$V$28,2,FALSE)) -> 150 | J13: =(VLOOKUP('S11.03'!J13,'S11.03'!$T$3:$V$28,2,FALSE)) -> 0 | K13: =(VLOOKUP('S11.03'!K13,'S11.03'!$T$3:$V$28,2,FALSE)) -> 150
A14: =(VLOOKUP('S11.03'!A14,'S11.03'!$T$3:$V$28,2,FALSE)) -> 0 | B14: =(VLOOKUP('S11.03'!B14,'S11.03'!$T$3:$V$28,2,FALSE)) -> 170 | C14: =(VLOOKUP('S11.03'!C14,'S11.03'!$T$3:$V$28,2,FALSE)) -> 50 | I14: =(VLOOKUP('S11.03'!I14,'S11.03'!$T$3:$V$28,2,FALSE)) -> 50 | J14: =(VLOOKUP('S11.03'!J14,'S11.03'!$T$3:$V$28,2,FALSE)) -> 0 | K14: =(VLOOKUP('S11.03'!K14,'S11.03'!$T$3:$V$28,2,FALSE)) -> 160
A15: =(VLOOKUP('S11.03'!A15,'S11.03'!$T$3:$V$28,2,FALSE)) -> 0 | B15: =(VLOOKUP('S11.03'!B15,'S11.03'!$T$3:$V$28,2,FALSE)) -> 170 | C15: =(VLOOKUP('S11.03'!C15,'S11.03'!$T$3:$V$28,2,FALSE)) -> 160 | I15: =(VLOOKUP('S11.03'!I15,'S11.03'!$T$3:$V$28,2,FALSE)) -> 0 | J15: =(VLOOKUP('S11.03'!J15,'S11.03'!$T$3:$V$28,2,FALSE)) -> 0 | K15: =(VLOOKUP('S11.03'!K15,'S11.03'!$T$3:$V$28,2,FALSE)) -> 160
... A100: =(VLOOKUP('S11.03'!A100,'S11.03'!$T$3:$V$28,2,FALSE)) -> 0 | B100: =(VLOOKUP('S11.03'!B100,'S11.03'!$T$3:$V$28,2,FALSE)) -> 0 | C100: =(VLOOKUP('S11.03'!C100,'S11.03'!$T$3:$V$28,2,FALSE)) -> 0 | I100: =(VLOOKUP('S11.03'!I100,'S11.03'!$T$3:$V$28,2,FALSE)) -> 0 | J100: =(VLOOKUP('S11.03'!J100,'S11.03'!$T$3:$V$28,2,FALSE)) -> 0 | K100: =(VLOOKUP('S11.03'!K100,'S11.03'!$T$3:$V$28,2,FALSE)) -> 0

Sheet 经验
A2: 行动 | I2: 行动
A3: 一队 | B3: 二队 | C3: 三队 | I3: 一队 | J3: 二队 | K3: 三队
A4: =(VLOOKUP('S11.03'!A4,'S11.03'!$T$3:$V$28,3,FALSE)) -> 35 | B4: =(VLOOKUP('S11.03'!B4,'S11.03'!$T$3:$V$28,3,FALSE)) -> 35 | C4: =(VLOOKUP('S11.03'!C4,'S11.03'!$T$3:$V$28,3,FALSE)) -> 0 | I4: =(VLOOKUP('S11.03'!I4,'S11.03'!$T$3:$V$28,3,FALSE)) -> 30 | J4: =(VLOOKUP('S11.03'!J4,'S11.03'!$T$3:$V$28,3,FALSE)) -> 40 | K4: =(VLOOKUP('S11.03'!K4,'S11.03'!$T$3:$V$28,3,FALSE)) -> 40
A5: =(VLOOKUP('S11.03'!A5,'S11.03'!$T$3:$V$28,3,FALSE)) -> 35 | B5: =(VLOOKUP('S11.03'!B5,'S11.03'!$T$3:$V$28,3,FALSE)) -> 35 | C5: =(VLOOKUP('S11.03'!C5,'S11.03'!$T$3:$V$28,3,FALSE)) -> 0 | I5: =(VLOOKUP('S11.03'!I5,'S11.03'!$T$3:$V$28,3,FALSE)) -> 0 | J5: =(VLOOKUP('S11.03'!J5,'S11.03'!$T$3:$V$28,3,FALSE)) -> 40 | K5: =(VLOOKUP('S11.03'!K5,'S11.03'!$T$3:$V$28,3,FALSE)) -> 40
A6: =(VLOOKUP('S11.03'!A6,'S11.03'!$T$3:$V$28,3,FALSE)) -> 30 | B6: =(VLOOKUP('S11.03'!B6,'S11.03'!$T$3:$V$28,3,FALSE)) -> 35 | C6: =(VLOOKUP('S11.03'!C6,'S11.03'!$T$3:$V$28,3,FALSE)) -> 35 | I6: =(VLOOKUP('S11.03'!I6,'S11.03'!$T$3:$V$28,3,FALSE)) -> 35 | J6: =(VLOOKUP('S11.03'!J6,'S11.03'!$T$3:$V$28,3,FALSE)) -> 40 | K6: =(VLOOKUP('S11.03'!K6,'S11.03'!$T$3:$V$28,3,FALSE)) -> 40
A7: =(VLOOKUP('S11.03'!A7,'S11.03'!$T$3:$V$28,3,FALSE)) -> 35 | B7: =(VLOOKUP('S11.03'!B7,'S11.03'!$T$3:$V$28,3,FALSE)) -> 35 | C7: =(VLOOKUP('S11.03'!C7,'S11.03'!$T$3:$V$28,3,FALSE)) -> 35 | I7: =(VLOOKUP('S11.03'!I7,'S11.03'!$T$3:$V$28,3,FALSE)) -> 35 | J7: =(VLOOKUP('S11.03'!J7,'S11.03'!$T$3:$V$28,3,FALSE)) -> 40 | K7: =(VLOOKUP('S11.03'!K7,'S11.03'!$T$3:$V$28,3,FALSE)) -> 30
A8: =(VLOOKUP('S11.03'!A8,'S11.03'!$T$3:$V$28,3,FALSE)) -> 35 | B8: =(VLOOKUP('S11.03'!B8,'S11.03'!$T$3:$V$28,3,FALSE)) -> 35 | C8: =(VLOOKUP('S11.03'!C8,'S11.03'!$T$3:$V$28,3,FALSE)) -> 35 | I8: =(VLOOKUP('S11.03'!I8,'S11.03'!$T$3:$V$28,3,FALSE)) -> 0 | J8: =(VLOOKUP('S11.03'!J8,'S11.03'!$T$3:$V$28,3,FALSE)) -> 40 | K8: =(VLOOKUP('S11.03'!K8,'S11.03'!$T$3:$V$28,3,FALSE)) -> 40
A9: =(VLOOKUP('S11.03'!A9,'S11.03'!$T$3:$V$28,3,FALSE)) -> 35 | B9: =(VLOOKUP('S11.03'!B9,'S11.03'!$T$3:$V$28,3,FALSE)) -> 30 | C9: =(VLOOKUP('S11.03'!C9,'S11.03'!$T$3:$V$28,3,FALSE)) -> 0 | I9: =(VLOOKUP('S11.03'!I9,'S11.03'!$T$3:$V$28,3,FALSE)) -> 0 | J9: =(VLOOKUP('S11.03'!J9,'S11.03'!$T$3:$V$28,3,FALSE)) -> 30 | K9: =(VLOOKUP('S11.03'!K9,'S11.03'!$T$3:$V$28,3,FALSE)) -> 40
A10: =(VLOOKUP('S11.03'!A10,'S11.03'!$T$3:$V$28,3,FALSE)) -> 0 | B10: =(VLOOKUP('S11.03'!B10,'S11.03'!$T$3:$V$28,3,FALSE)) -> 0 | C10: =(VLOOKUP('S11.03'!C10,'S11.03'!$T$3:$V$28,3,FALSE)) -> 40 | I10: =(VLOOKUP('S11.03'!I10,'S11.03'!$T$3:$V$28,3,FALSE)) -> 35 | J10: =(VLOOKUP('S11.03'!J10,'S11.03'!$T$3:$V$28,3,FALSE)) -> 0 | K10: =(VLOOKUP('S11.03'!K10,'S11.03'!$T$3:$V$28,3,FALSE)) -> 40
A11: =(VLOOKUP('S11.03'!A11,'S11.03'!$T$3:$V$28,3,FALSE)) -> 0 | B11: =(VLOOKUP('S11.03'!B11,'S11.03'!$T$3:$V$28,3,FALSE)) -> 45 | C11: =(VLOOKUP('S11.03'!C11,'S11.03'!$T$3:$V$28,3,FALSE)) -> 40 | I11: =(VLOOKUP('S11.03'!I11,'S11.03'!$T$3:$V$28,3,FALSE)) -> 35 | J11: =(VLOOKUP('S11.03'!J11,'S11.03'!$T$3:$V$28,3,FALSE)) -> 0 | K11: =(VLOOKUP('S11.03'!K11,'S11.03'!$T$3:$V$28,3,FALSE)) -> 30
A12: =(VLOOKUP('S11.03'!A12,'S11.03'!$T$3:$V$28,3,FALSE)) -> 0 | B12: =(VLOOKUP('S11.03'!B12,'S11.03'!$T$3:$V$28,3,FALSE)) -> 45 | C12: =(VLOOKUP('S11.03'!C12,'S11.03'!$T$3:$V$28,3,FALSE)) -> 40 | I12: =(VLOOKUP('S11.03'!I12,'S11.03'!$T$3:$V$28,3,FALSE)) -> 35 | J12: =(VLOOKUP('S11.03'!J12,'S11.03'!$T$3:$V$28,3,FALSE)) -> 0 | K12: =(VLOOKUP('S11.03'!K12,'S11.03'!$T$3:$V$28,3,FALSE)) -> 0
A13: =(VLOOKUP('S11.03'!A13,'S11.03'!$T$3:$V$28,3,FALSE)) -> 0 | B13: =(VLOOKUP('S11.03'!B13,'S11.03'!$T$3:$V$28,3,FALSE)) -> 45 | C13: =(VLOOKUP('S11.03'!C13,'S11.03'!$T$3:$V$28,3,FALSE)) -> 40 | I13: =(VLOOKUP('S11.03'!I13,'S11.03'!$T$3:$V$28,3,FALSE)) -> 35 | J13: =(VLOOKUP('S11.03'!J13,'S11.03'!$T$3:$V$28,3,FALSE)) -> 0 | K13: =(VLOOKUP('S11.03'!K13,'S11.03'!$T$3:$V$28,3,FALSE)) -> 40
A14: =(VLOOKUP('S11.03'!A14,'S11.03'!$T$3:$V$28,3,FALSE)) -> 0 | B14: =(VLOOKUP('S11.03'!B14,'S11.03'!$T$3:$V$28,3,FALSE)) -> 45 | C14: =(VLOOKUP('S11.03'!C14,'S11.03'!$T$3:$V$28,3,FALSE)) -> 30 | I14: =(VLOOKUP('S11.03'!I14,'S11.03'!$T$3:$V$28,3,FALSE)) -> 30 | J14: =(VLOOKUP('S11.03'!J14,'S11.03'!$T$3:$V$28,3,FALSE)) -> 0 | K14: =(VLOOKUP('S11.03'!K14,'S11.03'!$T$3:$V$28,3,FALSE)) -> 40
A15: =(VLOOKUP('S11.03'!A15,'S11.03'!$T$3:$V$28,3,FALSE)) -> 0 | B15: =(VLOOKUP('S11.03'!B15,'S11.03'!$T$3:$V$28,3,FALSE)) -> 45 | C15: =(VLOOKUP('S11.03'!C15,'S11.03'!$T$3:$V$28,3,FALSE)) -> 40 | I15: =(VLOOKUP('S11.03'!I15,'S11.03'!$T$3:$V$28,3,FALSE)) -> 0 | J15: =(VLOOKUP('S11.03'!J15,'S11.03'!$T$3:$V$28,3,FALSE)) -> 0 | K15: =(VLOOKUP('S11.03'!K15,'S11.03'!$T$3:$V$28,3,FALSE)) -> 40
... A100: =(VLOOKUP('S11.03'!A100,'S11.03'!$T$3:$V$28,3,FALSE)) -> 0 | B100: =(VLOOKUP('S11.03'!B100,'S11.03'!$T$3:$V$28,3,FALSE)) -> 0 | C100: =(VLOOKUP('S11.03'!C100,'S11.03'!$T$3:$V$28,3,FALSE)) -> 0 | I100: =(VLOOKUP('S11.03'!I100,'S11.03'!$T$3:$V$28,3,FALSE)) -> 0 | J100: =(VLOOKUP('S11.03'!J100,'S11.03'!$T$3:$V$28,3,FALSE)) -> 0 | K100: =(VLOOKUP('S11.03'!K100,'S11.03'!$T$3:$V$28,3,FALSE)) -> 0
