Workbook

Sheet 11.07
A1: =(_xlfn.DAYS(TODAY(),A4)+2)/((_xlfn.DAYS(A94,A4))+1) -> 1 | I1: 工作区 | AM1: 使用方法：按自己规划的路线，将下表中的地块名复制粘贴至工作区。初次使用传送门，当天跳步次数+5。重复使用传送门，当天跳步次数+1
A2: version 11.07 | B2: 八卦前亏 | C2: =SUM(亏损!A4:X94)+SUM(AG4:AG14)*10 -> 29558.881 | D2: 合计经验 | F2: =SUM(F4:F94)+SUM(H4:H94) -> 65530 | I2: 队伍一 风 | K2: 步数 | L2: =COUNTIF(I4:P94,"<>空") -> 512 | M2: (不算跳步和传送) | Q2: 队伍二 土 | S2: 步数 | T2: =COUNTIF(Q4:X94,"<>空") -> 52 | U2: (不算跳步和传送) | Y2: 队伍三 火 | AA2: 总步数 | AB2: =COUNTIF(Y4:AF94,"<>空") -> 513 | AC2: (不算跳步和传送) | AG2: =SUM(AG4:AG94) -> 7 | AH2: =SUM(AH4:AH94) -> 1 | AI2: =SUM(AI4:AI94) -> 5 | AJ2: =SUM(AJ4:AJ94) -> 1 | AK2: 八卦全开 | AS2: 总地块 | AT2: =SUM(AT4:AT29) -> 1077 | AV2: 总经验 | AW2: =SUM(AU4:AW29)+7000 -> 65530 | AY2: 粮草系数
A3: 日期 | B3: 获得粮草 | C3: 粮草调整 | D3: 消耗粮草 | E3: 剩余粮草 | F3: 获得经验 | G3: 累计经验 | H3: 任务经验 | I3: 1 | J3: 2 | K3: 3 | L3: 4 | M3: 5 | N3: 6 | O3: 7 | P3: 8 | Q3: 1 | R3: 2 | S3: 3 | T3: 4 | U3: 5 | V3: 6 | W3: 7 | X3: 8 | Y3: 1 | Z3: 2 | AA3: 3 | AB3: 4 | AC3: 5 | AD3: 6 | AE3: 7 | AF3: 8 | AG3: 跳步次数 | AH3: 1队跳步 | AI3: 2队跳步 | AJ3: 3队跳步 | AM3: 地块 | AN3: 粮草 | AO3: 经验 | AP3: 八卦前亏损 | AQ3: 一队地块 | AR3: 二队地块 | AS3: 三队地块 | AT3: 总地块 | AU3: 一队经验 | AV3: 二队经验 | AW3: 三队经验 | AX3: 八卦前 | AY3: 1
A4: 45002 | B4: 800 | C4: 6000 | D4: =(SUM(粮草!A4:X4)+AG4*10)*IF(AK4="是",$AY$4,$AY$3) -> 1550 | E4: =SUM($B$4:B4)+SUM($C$4:C4)-SUM($D$4:D4) -> 5250 | F4: =SUM(经验!A4:X4) -> 380 | G4: =SUM($F$4:F4)+SUM($H$4:H4) -> 880 | H4: 500 | I4: 1级 | J4: 1级 | K4: 1级 | L4: 空 | M4: 空 | N4: 空 | O4: 空 | P4: 空 | Q4: 1级 | R4: 1级 | S4: 空 | T4: 空 | U4: 空 | V4: 空 | W4: 空 | X4: 空 | Y4: 1级 | Z4: 1级 | AA4: 1级 | AB4: 1级 | AC4: 1级 | AD4: 商人 | AE4: 空 | AF4: 空 | AG4: =AH4+AI4+AJ4 -> 0 | AK4: 否 | AM4: 1级 | AN4: 150 | AO4: 35 | AP4: 44.222109 | AQ4: =COUNTIF($I$4:$P$94,AM4) -> 3 | AR4: =COUNTIF($Q$4:$X$94,AM4) -> 4 | AS4: =COUNTIF($Y$4:$AF$94,AM4) -> 8 | AT4: =AQ4+AR4+AS4 -> 15 | AU4: =AQ4*$AO4 -> 105 | AV4: =AR4*$AO4 -> 140 | AW4: =AS4*$AO4 -> 280 | AX4: 八卦后 | AY4: 0.8 | BA4: =AN4*0.8 -> 120
A5: 45003 | B5: 1600 | D5: =(SUM(粮草!A5:X5)+AG5*10)*IF(AK5="是",$AY$4,$AY$3) -> 940 | E5: =SUM($B$4:B5)+SUM($C$4:C5)-SUM($D$4:D5) -> 5910 | F5: =SUM(经验!A5:X5) -> 265 | G5: =SUM($F$4:F5)+SUM($H$4:H5) -> 1145 | H5: 0 | I5: 空 | J5: 空 | K5: 空 | L5: 空 | M5: 空 | N5: 空 | O5: 空 | P5: 空 | Q5: 空 | R5: 空 | S5: 空 | T5: 空 | U5: 空 | V5: 空 | W5: 空 | X5: 空 | Y5: 1级 | Z5: 1级 | AA5: 1级 | AB5: 营地 | AC5: 2级 | AD5: 2级 | AE5: 2级 | AF5: 2级 | AG5: =AH5+AI5+AJ5 -> 0 | AK5: 否 | AM5: 2级 | AN5: 160 | AO5: 40 | AP5: 39.110982 | AQ5: =COUNTIF($I$4:$P$94,AM5) -> 4 | AR5: =COUNTIF($Q$4:$X$94,AM5) -> 22 | AS5: =COUNTIF($Y$4:$AF$94,AM5) -> 13 | AT5: =AQ5+AR5+AS5 -> 39 | AU5: =AQ5*$AO5 -> 160 | AV5: =AR5*$AO5 -> 880 | AW5: =AS5*$AO5 -> 520 | AX5: Note：开完八卦当天可能需要手动计算粮草 | BA5: =AN5*0.8 -> 128
A6: 45004 | B6: 1600 | D6: =(SUM(粮草!A6:X6)+AG6*10)*IF(AK6="是",$AY$4,$AY$3) -> 870 | E6: =SUM($B$4:B6)+SUM($C$4:C6)-SUM($D$4:D6) -> 6640 | F6: =SUM(经验!A6:X6) -> 240 | G6: =SUM($F$4:F6)+SUM($H$4:H6) -> 1385 | H6: 0 | I6: 空 | J6: 空 | K6: 空 | L6: 空 | M6: 空 | N6: 空 | O6: 空 | P6: 空 | Q6: 空 | R6: 空 | S6: 空 | T6: 空 | U6: 空 | V6: 空 | W6: 空 | X6: 空 | Y6: 商人 | Z6: 2级 | AA6: 2级 | AB6: 2级 | AC6: 3级 | AD6: 小卦 | AE6: 空 | AF6: 空 | AG6: =AH6+AI6+AJ6 -> 0 | AK6: 否 | AM6: 3级 | AN6: 170 | AO6: 45 | AP6: 34 | AQ6: =COUNTIF($I$4:$P$94,AM6) -> 151 | AR6: =COUNTIF($Q$4:$X$94,AM6) -> 12 | AS6: =COUNTIF($Y$4:$AF$94,AM6) -> 81 | AT6: =AQ6+AR6+AS6 -> 244 | AU6: =AQ6*$AO6 -> 6795 | AV6: =AR6*$AO6 -> 540 | AW6: =AS6*$AO6 -> 3645 | BA6: =AN6*0.8 -> 136
A7: 45005 | B7: 1600 | C7: 50 | D7: =(SUM(粮草!A7:X7)+AG7*10)*IF(AK7="是",$AY$4,$AY$3) -> 2050 | E7: =SUM($B$4:B7)+SUM($C$4:C7)-SUM($D$4:D7) -> 6240 | F7: =SUM(经验!A7:X7) -> 810 | G7: =SUM($F$4:F7)+SUM($H$4:H7) -> 2395 | H7: 200 | I7: 商人 | J7: 3级 | K7: 3级 | L7: 3级 | M7: 3级 | N7: 3级 | O7: 3级 | P7: 空 | Q7: 空 | R7: 空 | S7: 空 | T7: 空 | U7: 空 | V7: 空 | W7: 空 | X7: 空 | Y7: 3级 | Z7: 商人 | AA7: 3级 | AB7: 大卦 | AC7: 3级 | AD7: 3级 | AE7: 空 | AF7: 空 | AG7: =AH7+AI7+AJ7 -> 0 | AK7: 否 | AM7: 4级 | AN7: 180 | AO7: 50 | AP7: 36 | AQ7: =COUNTIF($I$4:$P$94,AM7) -> 103 | AR7: =COUNTIF($Q$4:$X$94,AM7) -> 0 | AS7: =COUNTIF($Y$4:$AF$94,AM7) -> 164 | AT7: =AQ7+AR7+AS7 -> 267 | AU7: =AQ7*$AO7 -> 5150 | AV7: =AR7*$AO7 -> 0 | AW7: =AS7*$AO7 -> 8200 | BA7: =AN7*0.8 -> 144
A8: 45006 | B8: 1600 | D8: =(SUM(粮草!A8:X8)+AG8*10)*IF(AK8="是",$AY$4,$AY$3) -> 2000 | E8: =SUM($B$4:B8)+SUM($C$4:C8)-SUM($D$4:D8) -> 5840 | F8: =SUM(经验!A8:X8) -> 790 | G8: =SUM($F$4:F8)+SUM($H$4:H8) -> 3285 | H8: 100 | I8: 大卦 | J8: 3级 | K8: 3级 | L8: 4级 | M8: 4级 | N8: 3级 | O8: 空 | P8: 空 | Q8: 空 | R8: 空 | S8: 空 | T8: 空 | U8: 空 | V8: 空 | W8: 空 | X8: 空 | Y8: 塔3 | Z8: 3级 | AA8: 3级 | AB8: 商人 | AC8: 3级 | AD8: 3级 | AE8: 空 | AF8: 空 | AG8: =AH8+AI8+AJ8 -> 0 | AK8: 否 | AM8: 5级 | AN8: 190 | AO8: 55 | AP8: 38 | AQ8: =COUNTIF($I$4:$P$94,AM8) -> 128 | AR8: =COUNTIF($Q$4:$X$94,AM8) -> 0 | AS8: =COUNTIF($Y$4:$AF$94,AM8) -> 107 | AT8: =AQ8+AR8+AS8 -> 235 | AU8: =AQ8*$AO8 -> 7040 | AV8: =AR8*$AO8 -> 0 | AW8: =AS8*$AO8 -> 5885 | BA8: =AN8*0.8 -> 152
A9: 45007 | B9: 1600 | D9: =(SUM(粮草!A9:X9)+AG9*10)*IF(AK9="是",$AY$4,$AY$3) -> 2100 | E9: =SUM($B$4:B9)+SUM($C$4:C9)-SUM($D$4:D9) -> 5340 | F9: =SUM(经验!A9:X9) -> 795 | G9: =SUM($F$4:F9)+SUM($H$4:H9) -> 4280 | H9: 200 | I9: 塔3 | J9: 3级 | K9: 3级 | L9: 小卦 | M9: 3级 | N9: 3级 | O9: 空 | P9: 空 | Q9: 空 | R9: 空 | S9: 空 | T9: 空 | U9: 空 | V9: 空 | W9: 空 | X9: 空 | Y9: 3级 | Z9: 小卦 | AA9: 3级 | AB9: 3级 | AC9: 3级 | AD9: 大卦 | AE9: 空 | AF9: 空 | AG9: =AH9+AI9+AJ9 -> 0 | AK9: 否 | AM9: 6级 | AN9: 200 | AO9: 60 | AQ9: =COUNTIF($I$4:$P$94,AM9) -> 90 | AR9: =COUNTIF($Q$4:$X$94,AM9) -> 0 | AS9: =COUNTIF($Y$4:$AF$94,AM9) -> 104 | AT9: =AQ9+AR9+AS9 -> 194 | AU9: =AQ9*$AO9 -> 5400 | AV9: =AR9*$AO9 -> 0 | AW9: =AS9*$AO9 -> 6240 | BA9: =AN9*0.8 -> 160
A10: 45008 | B10: 1600 | D10: =(SUM(粮草!A10:X10)+AG10*10)*IF(AK10="是",$AY$4,$AY$3) -> 2210 | E10: =SUM($B$4:B10)+SUM($C$4:C10)-SUM($D$4:D10) -> 4730 | F10: =SUM(经验!A10:X10) -> 585 | G10: =SUM($F$4:F10)+SUM($H$4:H10) -> 4865 | H10: 0 | I10: 3级 | J10: 3级 | K10: 3级 | L10: 3级 | M10: 3级 | N10: 3级 | O10: 小卦 | P10: 空 | Q10: 空 | R10: 空 | S10: 空 | T10: 空 | U10: 空 | V10: 空 | W10: 空 | X10: 空 | Y10: 3级 | Z10: 3级 | AA10: 3级 | AB10: 3级 | AC10: 3级 | AD10: 3级 | AE10: 空 | AF10: 空 | AG10: =AH10+AI10+AJ10 -> 0 | AK10: 否 | AM10: 塔1 | AN10: 150 | AO10: 35 | AP10: 44.222109 | AQ10: =COUNTIF($I$4:$P$94,AM10) -> 0 | AR10: =COUNTIF($Q$4:$X$94,AM10) -> 0 | AS10: =COUNTIF($Y$4:$AF$94,AM10) -> 0 | AT10: =AQ10+AR10+AS10 -> 0 | AU10: =AQ10*$AO10 -> 0 | AV10: =AR10*$AO10 -> 0 | AW10: =AS10*$AO10 -> 0 | BA10: =AN10*0.8 -> 120
A11: 45009 | B11: 1600 | D11: =(SUM(粮草!A11:X11)+AG11*10)*IF(AK11="是",$AY$4,$AY$3) -> 900 | E11: =SUM($B$4:B11)+SUM($C$4:C11)-SUM($D$4:D11) -> 5430 | F11: =SUM(经验!A11:X11) -> 255 | G11: =SUM($F$4:F11)+SUM($H$4:H11) -> 5120 | H11: 0 | I11: 空 | J11: 空 | K11: 空 | L11: 空 | M11: 空 | N11: 空 | O11: 空 | P11: 空 | Q11: 空 | R11: 空 | S11: 空 | T11: 空 | U11: 空 | V11: 空 | W11: 空 | X11: 空 | Y11: 商人 | Z11: 3级 | AA11: 3级 | AB11: 3级 | AC11: 3级 | AD11: 小卦 | AE11: 空 | AF11: 空 | AG11: =AH11+AI11+AJ11 -> 0 | AK11: 否 | AM11: 塔2 | AN11: 150 | AO11: 40 | AP11: 29.110982 | AQ11: =COUNTIF($I$4:$P$94,AM11) -> 1 | AR11: =COUNTIF($Q$4:$X$94,AM11) -> 1 | AS11: =COUNTIF($Y$4:$AF$94,AM11) -> 0 | AT11: =AQ11+AR11+AS11 -> 2 | AU11: =AQ11*$AO11 -> 40 | AV11: =AR11*$AO11 -> 40 | AW11: =AS11*$AO11 -> 0 | BA11: =AN11*0.8 -> 120
A12: 45010 | B12: 1600 | D12: =(SUM(粮草!A12:X12)+AG12*10)*IF(AK12="是",$AY$4,$AY$3) -> 1632 | E12: =SUM($B$4:B12)+SUM($C$4:C12)-SUM($D$4:D12) -> 5398 | F12: =SUM(经验!A12:X12) -> 540 | G12: =SUM($F$4:F12)+SUM($H$4:H12) -> 5660 | H12: 0 | I12: 3级 | J12: 3级 | K12: 3级 | L12: 3级 | M12: 3级 | N12: 3级 | O12: 空 | P12: 空 | Q12: 空 | R12: 空 | S12: 空 | T12: 空 | U12: 空 | V12: 空 | W12: 空 | X12: 空 | Y12: 3级 | Z12: 3级 | AA12: 3级 | AB12: 3级 | AC12: 3级 | AD12: 3级 | AE12: 空 | AF12: 空 | AG12: =AH12+AI12+AJ12 -> 0 | AK12: 是 | AM12: 塔3 | AN12: 150 | AO12: 45 | AP12: 13.999855 | AQ12: =COUNTIF($I$4:$P$94,AM12) -> 3 | AR12: =COUNTIF($Q$4:$X$94,AM12) -> 0 | AS12: =COUNTIF($Y$4:$AF$94,AM12) -> 3 | AT12: =AQ12+AR12+AS12 -> 6 | AU12: =AQ12*$AO12 -> 135 | AV12: =AR12*$AO12 -> 0 | AW12: =AS12*$AO12 -> 135 | BA12: =AN12*0.8 -> 120
A13: 45011 | B13: 1600 | D13: =(SUM(粮草!A13:X13)+AG13*10)*IF(AK13="是",$AY$4,$AY$3) -> 1616 | E13: =SUM($B$4:B13)+SUM($C$4:C13)-SUM($D$4:D13) -> 5382 | F13: =SUM(经验!A13:X13) -> 540 | G13: =SUM($F$4:F13)+SUM($H$4:H13) -> 6200 | H13: 0 | I13: 3级 | J13: 塔3 | K13: 3级 | L13: 3级 | M13: 3级 | N13: 3级 | O13: 空 | P13: 空 | Q13: 空 | R13: 空 | S13: 空 | T13: 空 | U13: 空 | V13: 空 | W13: 空 | X13: 空 | Y13: 3级 | Z13: 3级 | AA13: 3级 | AB13: 3级 | AC13: 3级 | AD13: 3级 | AE13: 空 | AF13: 空 | AG13: =AH13+AI13+AJ13 -> 0 | AK13: 是 | AM13: 塔4 | AN13: 150 | AO13: 50 | AQ13: =COUNTIF($I$4:$P$94,AM13) -> 1 | AR13: =COUNTIF($Q$4:$X$94,AM13) -> 0 | AS13: =COUNTIF($Y$4:$AF$94,AM13) -> 2 | AT13: =AQ13+AR13+AS13 -> 3 | AU13: =AQ13*$AO13 -> 50 | AV13: =AR13*$AO13 -> 0 | AW13: =AS13*$AO13 -> 100 | BA13: =AN13*0.8 -> 120
A14: 45012 | B14: 1600 | D14: =(SUM(粮草!A14:X14)+AG14*10)*IF(AK14="是",$AY$4,$AY$3) -> 1536 | E14: =SUM($B$4:B14)+SUM($C$4:C14)-SUM($D$4:D14) -> 5446 | F14: =SUM(经验!A14:X14) -> 525 | G14: =SUM($F$4:F14)+SUM($H$4:H14) -> 7025 | H14: 300 | I14: 3级 | J14: 3级 | K14: 3级 | L14: 3级 | M14: 3级 | N14: 3级 | O14: 空 | P14: 空 | Q14: 空 | R14: 空 | S14: 空 | T14: 空 | U14: 空 | V14: 空 | W14: 空 | X14: 空 | Y14: 3级 | Z14: 3级 | AA14: 3级 | AB14: 3级 | AC14: 商人 | AD14: 3级 | AE14: 空 | AF14: 空 | AG14: =AH14+AI14+AJ14 -> 0 | AK14: 是 | AM14: 塔5 | AN14: 150 | AO14: 55 | AQ14: =COUNTIF($I$4:$P$94,AM14) -> 2 | AR14: =COUNTIF($Q$4:$X$94,AM14) -> 0 | AS14: =COUNTIF($Y$4:$AF$94,AM14) -> 1 | AT14: =AQ14+AR14+AS14 -> 3 | AU14: =AQ14*$AO14 -> 110 | AV14: =AR14*$AO14 -> 0 | AW14: =AS14*$AO14 -> 55 | BA14: =AN14*0.8 -> 120
A15: 45013 | B15: 1600 | D15: =(SUM(粮草!A15:X15)+AG15*10)*IF(AK15="是",$AY$4,$AY$3) -> 1632 | E15: =SUM($B$4:B15)+SUM($C$4:C15)-SUM($D$4:D15) -> 5414 | F15: =SUM(经验!A15:X15) -> 540 | G15: =SUM($F$4:F15)+SUM($H$4:H15) -> 7565 | H15: 0 | I15: 3级 | J15: 3级 | K15: 3级 | L15: 3级 | M15: 3级 | N15: 3级 | O15: 空 | P15: 空 | Q15: 空 | R15: 空 | S15: 空 | T15: 空 | U15: 空 | V15: 空 | W15: 空 | X15: 空 | Y15: 3级 | Z15: 3级 | AA15: 3级 | AB15: 3级 | AC15: 3级 | AD15: 3级 | AE15: 空 | AF15: 空 | AG15: =AH15+AI15+AJ15 -> 0 | AK15: 是 | AM15: 塔6 | AN15: 150 | AO15: 60 | AQ15: =COUNTIF($I$4:$P$94,AM15) -> 0 | AR15: =COUNTIF($Q$4:$X$94,AM15) -> 0 | AS15: =COUNTIF($Y$4:$AF$94,AM15) -> 1 | AT15: =AQ15+AR15+AS15 -> 1 | AU15: =AQ15*$AO15 -> 0 | AV15: =AR15*$AO15 -> 0 | AW15: =AS15*$AO15 -> 60 | BA15: =AN15*0.8 -> 120
A16: 45014 | B16: 1600 | D16: =(SUM(粮草!A16:X16)+AG16*10)*IF(AK16="是",$AY$4,$AY$3) -> 1632 | E16: =SUM($B$4:B16)+SUM($C$4:C16)-SUM($D$4:D16) -> 5382 | F16: =SUM(经验!A16:X16) -> 540 | G16: =SUM($F$4:F16)+SUM($H$4:H16) -> 8305 | H16: 200 | I16: 3级 | J16: 3级 | K16: 3级 | L16: 3级 | M16: 3级 | N16: 3级 | O16: 空 | P16: 空 | Q16: 空 | R16: 空 | S16: 空 | T16: 空 | U16: 空 | V16: 空 | W16: 空 | X16: 空 | Y16: 3级 | Z16: 3级 | AA16: 3级 | AB16: 3级 | AC16: 3级 | AD16: 3级 | AE16: 空 | AF16: 空 | AG16: =AH16+AI16+AJ16 -> 0 | AK16: 是 | AM16: 遗迹 | AN16: 150 | AO16: 35 | AP16: 44.222109 | AQ16: =COUNTIF($I$4:$P$94,AM16) -> 0 | AR16: =COUNTIF($Q$4:$X$94,AM16) -> 0 | AS16: =COUNTIF($Y$4:$AF$94,AM16) -> 0 | AT16: =AQ16+AR16+AS16 -> 0 | AU16: =AQ16*$AO16 -> 0 | AV16: =AR16*$AO16 -> 0 | AW16: =AS16*$AO16 -> 0 | BA16: =AN16*0.8 -> 120
A17: 45015 | B17: 1600 | D17: =(SUM(粮草!A17:X17)+AG17*10)*IF(AK17="是",$AY$4,$AY$3) -> 1600 | E17: =SUM($B$4:B17)+SUM($C$4:C17)-SUM($D$4:D17) -> 5382 | F17: =SUM(经验!A17:X17) -> 540 | G17: =SUM($F$4:F17)+SUM($H$4:H17) -> 8845 | H17: 0 | I17: 3级 | J17: 3级 | K17: 3级 | L17: 塔3 | M17: 3级 | N17: 3级 | O17: 空 | P17: 空 | Q17: 空 | R17: 空 | S17: 空 | T17: 空 | U17: 空 | V17: 空 | W17: 空 | X17: 空 | Y17: 3级 | Z17: 3级 | AA17: 3级 | AB17: 3级 | AC17: 塔3 | AD17: 3级 | AE17: 空 | AF17: 空 | AG17: =AH17+AI17+AJ17 -> 0 | AK17: 是 | AM17: 商人 | AN17: 50 | AO17: 30 | AP17: 10 | AQ17: =COUNTIF($I$4:$P$94,AM17) -> 14 | AR17: =COUNTIF($Q$4:$X$94,AM17) -> 9 | AS17: =COUNTIF($Y$4:$AF$94,AM17) -> 15 | AT17: =AQ17+AR17+AS17 -> 38 | AU17: =AQ17*$AO17 -> 420 | AV17: =AR17*$AO17 -> 270 | AW17: =AS17*$AO17 -> 450 | BA17: =AN17*0.8 -> 40
A18: 45016 | B18: 1600 | D18: =(SUM(粮草!A18:X18)+AG18*10)*IF(AK18="是",$AY$4,$AY$3) -> 1632 | E18: =SUM($B$4:B18)+SUM($C$4:C18)-SUM($D$4:D18) -> 5350 | F18: =SUM(经验!A18:X18) -> 540 | G18: =SUM($F$4:F18)+SUM($H$4:H18) -> 9385 | H18: 0 | I18: 3级 | J18: 3级 | K18: 3级 | L18: 3级 | M18: 3级 | N18: 3级 | O18: 空 | P18: 空 | Q18: 空 | R18: 空 | S18: 空 | T18: 空 | U18: 空 | V18: 空 | W18: 空 | X18: 空 | Y18: 3级 | Z18: 3级 | AA18: 3级 | AB18: 3级 | AC18: 3级 | AD18: 3级 | AE18: 空 | AF18: 空 | AG18: =AH18+AI18+AJ18 -> 0 | AK18: 是 | AL18: 八卦前 | AM18: 营地 | AN18: -150 | AO18: 0 | AP18: 10 | AQ18: =COUNTIF($I$4:$P$94,AM18) -> 0 | AR18: =COUNTIF($Q$4:$X$94,AM18) -> 0 | AS18: =COUNTIF($Y$4:$AF$94,AM18) -> 1 | AT18: =AQ18+AR18+AS18 -> 1 | AU18: =AQ18*$AO18 -> 0 | AV18: =AR18*$AO18 -> 0 | AW18: =AS18*$AO18 -> 0 | BA18: =AN18*0.8 -> -120
A19: 45017 | B19: 1600 | D19: =(SUM(粮草!A19:X19)+AG19*10)*IF(AK19="是",$AY$4,$AY$3) -> 1536 | E19: =SUM($B$4:B19)+SUM($C$4:C19)-SUM($D$4:D19) -> 5414 | F19: =SUM(经验!A19:X19) -> 525 | G19: =SUM($F$4:F19)+SUM($H$4:H19) -> 9910 | H19: 0 | I19: 3级 | J19: 3级 | K19: 3级 | L19: 3级 | M19: 3级 | N19: 3级 | O19: 空 | P19: 空 | Q19: 空 | R19: 空 | S19: 空 | T19: 空 | U19: 空 | V19: 空 | W19: 空 | X19: 空 | Y19: 3级 | Z19: 商人 | AA19: 3级 | AB19: 3级 | AC19: 3级 | AD19: 3级 | AE19: 空 | AF19: 空 | AG19: =AH19+AI19+AJ19 -> 0 | AK19: 是 | AM19: 大卦 | AN19: 250 | AO19: 300 | AQ19: =COUNTIF($I$4:$P$94,AM19) -> 1 | AR19: =COUNTIF($Q$4:$X$94,AM19) -> 0 | AS19: =COUNTIF($Y$4:$AF$94,AM19) -> 2 | AT19: =AQ19+AR19+AS19 -> 3 | AU19: =AQ19*$AO19 -> 300 | AV19: =AR19*$AO19 -> 0 | AW19: =AS19*$AO19 -> 600 | BA19: =AN19*0.8 -> 200
A20: 45018 | B20: 1600 | D20: =(SUM(粮草!A20:X20)+AG20*10)*IF(AK20="是",$AY$4,$AY$3) -> 1632 | E20: =SUM($B$4:B20)+SUM($C$4:C20)-SUM($D$4:D20) -> 5382 | F20: =SUM(经验!A20:X20) -> 540 | G20: =SUM($F$4:F20)+SUM($H$4:H20) -> 10450 | H20: 0 | I20: 3级 | J20: 3级 | K20: 3级 | L20: 3级 | M20: 3级 | N20: 3级 | O20: 空 | P20: 空 | Q20: 空 | R20: 空 | S20: 空 | T20: 空 | U20: 空 | V20: 空 | W20: 空 | X20: 空 | Y20: 3级 | Z20: 3级 | AA20: 3级 | AB20: 3级 | AC20: 3级 | AD20: 3级 | AE20: 空 | AF20: 空 | AG20: =AH20+AI20+AJ20 -> 0 | AK20: 是 | AM20: 小卦 | AN20: 170 | AO20: 45 | AQ20: =COUNTIF($I$4:$P$94,AM20) -> 2 | AR20: =COUNTIF($Q$4:$X$94,AM20) -> 0 | AS20: =COUNTIF($Y$4:$AF$94,AM20) -> 3 | AT20: =AQ20+AR20+AS20 -> 5 | AU20: =AQ20*$AO20 -> 90 | AV20: =AR20*$AO20 -> 0 | AW20: =AS20*$AO20 -> 135 | BA20: =AN20*0.8 -> 136
A21: 45019 | B21: 1600 | D21: =(SUM(粮草!A21:X21)+AG21*10)*IF(AK21="是",$AY$4,$AY$3) -> 1632 | E21: =SUM($B$4:B21)+SUM($C$4:C21)-SUM($D$4:D21) -> 5350 | F21: =SUM(经验!A21:X21) -> 540 | G21: =SUM($F$4:F21)+SUM($H$4:H21) -> 11190 | H21: 200 | I21: 3级 | J21: 3级 | K21: 3级 | L21: 3级 | M21: 3级 | N21: 3级 | O21: 空 | P21: 空 | Q21: 空 | R21: 空 | S21: 空 | T21: 空 | U21: 空 | V21: 空 | W21: 空 | X21: 空 | Y21: 3级 | Z21: 3级 | AA21: 3级 | AB21: 3级 | AC21: 3级 | AD21: 3级 | AE21: 空 | AF21: 空 | AG21: =AH21+AI21+AJ21 -> 0 | AK21: 是 | AM21: 小boss | AN21: 250 | AO21: 200 | AQ21: =COUNTIF($I$4:$P$94,AM21) -> 0 | AR21: =COUNTIF($Q$4:$X$94,AM21) -> 0 | AS21: =COUNTIF($Y$4:$AF$94,AM21) -> 0 | AT21: =AQ21+AR21+AS21 -> 0 | AU21: =AQ21*$AO21 -> 0 | AV21: =AR21*$AO21 -> 0 | AW21: =AS21*$AO21 -> 0 | BA21: =AN21*0.8 -> 200
A22: 45020 | B22: 1600 | D22: =(SUM(粮草!A22:X22)+AG22*10)*IF(AK22="是",$AY$4,$AY$3) -> 1632 | E22: =SUM($B$4:B22)+SUM($C$4:C22)-SUM($D$4:D22) -> 5318 | F22: =SUM(经验!A22:X22) -> 610 | G22: =SUM($F$4:F22)+SUM($H$4:H22) -> 11900 | H22: 100 | I22: 3级 | J22: 3级 | K22: 3级 | L22: 3级 | M22: 3级 | N22: 3级 | O22: 空 | P22: 空 | Q22: 空 | R22: 空 | S22: 空 | T22: 空 | U22: 空 | V22: 空 | W22: 空 | X22: 空 | Y22: 4级 | Z22: 3级 | AA22: 塔3 | AB22: 4级 | AC22: 4级 | AD22: 4级 | AE22: 营地+ | AF22: 4级 | AG22: =AH22+AI22+AJ22 -> 0 | AK22: 是 | AM22: 大boss | AN22: 250 | AO22: 1000 | AQ22: =COUNTIF($I$4:$P$94,AM22) -> 1 | AR22: =COUNTIF($Q$4:$X$94,AM22) -> 0 | AS22: =COUNTIF($Y$4:$AF$94,AM22) -> 1 | AT22: =AQ22+AR22+AS22 -> 2 | AU22: =AQ22*$AO22 -> 1000 | AV22: =AR22*$AO22 -> 0 | AW22: =AS22*$AO22 -> 1000 | BA22: =AN22*0.8 -> 200
A23: 45021 | B23: 1600 | D23: =(SUM(粮草!A23:X23)+AG23*10)*IF(AK23="是",$AY$4,$AY$3) -> 1680 | E23: =SUM($B$4:B23)+SUM($C$4:C23)-SUM($D$4:D23) -> 5238 | F23: =SUM(经验!A23:X23) -> 570 | G23: =SUM($F$4:F23)+SUM($H$4:H23) -> 12670 | H23: 200 | I23: 3级 | J23: 3级 | K23: 3级 | L23: 3级 | M23: 3级 | N23: 3级 | O23: 空 | P23: 空 | Q23: 空 | R23: 空 | S23: 空 | T23: 空 | U23: 空 | V23: 空 | W23: 空 | X23: 空 | Y23: 4级 | Z23: 4级 | AA23: 4级 | AB23: 4级 | AC23: 4级 | AD23: 4级 | AE23: 空 | AF23: 空 | AG23: =AH23+AI23+AJ23 -> 0 | AK23: 是 | AM23: 中boss | AN23: 250 | AO23: 500 | AQ23: =COUNTIF($I$4:$P$94,AM23) -> 1 | AR23: =COUNTIF($Q$4:$X$94,AM23) -> 0 | AS23: =COUNTIF($Y$4:$AF$94,AM23) -> 1 | AT23: =AQ23+AR23+AS23 -> 2 | AU23: =AQ23*$AO23 -> 500 | AV23: =AR23*$AO23 -> 0 | AW23: =AS23*$AO23 -> 500 | BA23: =AN23*0.8 -> 200
A24: 45022 | B24: 1600 | D24: =(SUM(粮草!A24:X24)+AG24*10)*IF(AK24="是",$AY$4,$AY$3) -> 1680 | E24: =SUM($B$4:B24)+SUM($C$4:C24)-SUM($D$4:D24) -> 5158 | F24: =SUM(经验!A24:X24) -> 570 | G24: =SUM($F$4:F24)+SUM($H$4:H24) -> 13240 | H24: 0 | I24: 3级 | J24: 3级 | K24: 3级 | L24: 3级 | M24: 3级 | N24: 3级 | O24: 空 | P24: 空 | Q24: 空 | R24: 空 | S24: 空 | T24: 空 | U24: 空 | V24: 空 | W24: 空 | X24: 空 | Y24: 4级 | Z24: 4级 | AA24: 4级 | AB24: 4级 | AC24: 4级 | AD24: 4级 | AE24: 空 | AF24: 空 | AG24: =AH24+AI24+AJ24 -> 0 | AK24: 是 | AM24: 奈良 | AN24: 160 | AO24: 40 | AP24: 39.110982 | AQ24: =COUNTIF($I$4:$P$94,AM24) -> 0 | AR24: =COUNTIF($Q$4:$X$94,AM24) -> 0 | AS24: =COUNTIF($Y$4:$AF$94,AM24) -> 0 | AT24: =AQ24+AR24+AS24 -> 0 | AU24: =AQ24*$AO24 -> 0 | AV24: =AR24*$AO24 -> 0 | AW24: =AS24*$AO24 -> 0 | BA24: =AN24*0.8 -> 128
A25: 45023 | B25: 1600 | D25: =(SUM(粮草!A25:X25)+AG25*10)*IF(AK25="是",$AY$4,$AY$3) -> 1680 | E25: =SUM($B$4:B25)+SUM($C$4:C25)-SUM($D$4:D25) -> 5078 | F25: =SUM(经验!A25:X25) -> 570 | G25: =SUM($F$4:F25)+SUM($H$4:H25) -> 13810 | H25: 0 | I25: 3级 | J25: 3级 | K25: 3级 | L25: 3级 | M25: 3级 | N25: 3级 | O25: 空 | P25: 空 | Q25: 空 | R25: 空 | S25: 空 | T25: 空 | U25: 空 | V25: 空 | W25: 空 | X25: 空 | Y25: 4级 | Z25: 4级 | AA25: 4级 | AB25: 4级 | AC25: 4级 | AD25: 4级 | AE25: 空 | AF25: 空 | AG25: =AH25+AI25+AJ25 -> 0 | AK25: 是 | AM25: 山中 | AN25: 160 | AO25: 40 | AP25: 39.110982 | AQ25: =COUNTIF($I$4:$P$94,AM25) -> 0 | AR25: =COUNTIF($Q$4:$X$94,AM25) -> 0 | AS25: =COUNTIF($Y$4:$AF$94,AM25) -> 0 | AT25: =AQ25+AR25+AS25 -> 0 | AU25: =AQ25*$AO25 -> 0 | AV25: =AR25*$AO25 -> 0 | AW25: =AS25*$AO25 -> 0 | BA25: =AN25*0.8 -> 128
A26: 45024 | B26: 1600 | D26: =(SUM(粮草!A26:X26)+AG26*10)*IF(AK26="是",$AY$4,$AY$3) -> 1584 | E26: =SUM($B$4:B26)+SUM($C$4:C26)-SUM($D$4:D26) -> 5094 | F26: =SUM(经验!A26:X26) -> 555 | G26: =SUM($F$4:F26)+SUM($H$4:H26) -> 14365 | H26: 0 | I26: 3级 | J26: 3级 | K26: 商人 | L26: 3级 | M26: 3级 | N26: 3级 | O26: 空 | P26: 空 | Q26: 空 | R26: 空 | S26: 空 | T26: 空 | U26: 空 | V26: 空 | W26: 空 | X26: 空 | Y26: 4级 | Z26: 4级 | AA26: 4级 | AB26: 4级 | AC26: 4级 | AD26: 4级 | AE26: 空 | AF26: 空 | AG26: =AH26+AI26+AJ26 -> 0 | AK26: 是 | AM26: 秋道 | AN26: 150 | AO26: 35 | AP26: 44.222109 | AQ26: =COUNTIF($I$4:$P$94,AM26) -> 0 | AR26: =COUNTIF($Q$4:$X$94,AM26) -> 0 | AS26: =COUNTIF($Y$4:$AF$94,AM26) -> 0 | AT26: =AQ26+AR26+AS26 -> 0 | AU26: =AQ26*$AO26 -> 0 | AV26: =AR26*$AO26 -> 0 | AW26: =AS26*$AO26 -> 0 | BA26: =AN26*0.8 -> 120
A27: 45025 | B27: 1600 | D27: =(SUM(粮草!A27:X27)+AG27*10)*IF(AK27="是",$AY$4,$AY$3) -> 1680 | E27: =SUM($B$4:B27)+SUM($C$4:C27)-SUM($D$4:D27) -> 5014 | F27: =SUM(经验!A27:X27) -> 570 | G27: =SUM($F$4:F27)+SUM($H$4:H27) -> 14935 | H27: 0 | I27: 3级 | J27: 3级 | K27: 3级 | L27: 3级 | M27: 3级 | N27: 3级 | O27: 空 | P27: 空 | Q27: 空 | R27: 空 | S27: 空 | T27: 空 | U27: 空 | V27: 空 | W27: 空 | X27: 空 | Y27: 4级 | Z27: 4级 | AA27: 4级 | AB27: 4级 | AC27: 4级 | AD27: 4级 | AE27: 空 | AF27: 空 | AG27: =AH27+AI27+AJ27 -> 0 | AK27: 是 | AM27: 空 | AN27: 0 | AO27: 0 | AP27: 0 | AU27: =AQ27*$AO27 -> 0 | AV27: =AR27*$AO27 -> 0 | AW27: =AS27*$AO27 -> 0 | BA27: =AN27*0.8 -> 0
A28: 45026 | B28: 1600 | D28: =(SUM(粮草!A28:X28)+AG28*10)*IF(AK28="是",$AY$4,$AY$3) -> 1592 | E28: =SUM($B$4:B28)+SUM($C$4:C28)-SUM($D$4:D28) -> 5022 | F28: =SUM(经验!A28:X28) -> 560 | G28: =SUM($F$4:F28)+SUM($H$4:H28) -> 15695 | H28: 200 | I28: 3级 | J28: 3级 | K28: 3级 | L28: 3级 | M28: 3级 | N28: 商人 | O28: 空 | P28: 空 | Q28: 空 | R28: 空 | S28: 空 | T28: 空 | U28: 空 | V28: 空 | W28: 空 | X28: 空 | Y28: 4级 | Z28: 4级 | AA28: 4级 | AB28: 4级 | AC28: 4级 | AD28: 5级 | AE28: 空 | AF28: 空 | AG28: =AH28+AI28+AJ28 -> 0 | AK28: 是 | AL28: 八卦后 | AM28: 营地+ | AN28: -200 | AO28: 0 | AQ28: =COUNTIF($I$4:$P$94,AM28) -> 6 | AR28: =COUNTIF($Q$4:$X$94,AM28) -> 3 | AS28: =COUNTIF($Y$4:$AF$94,AM28) -> 5 | AT28: =AQ28+AR28+AS28 -> 14 | AU28: =AQ28*$AO28 -> 0 | AV28: =AR28*$AO28 -> 0 | AW28: =AS28*$AO28 -> 0 | BA28: =AN28*0.8 -> -160
A29: 45027 | B29: 1600 | D29: =(SUM(粮草!A29:X29)+AG29*10)*IF(AK29="是",$AY$4,$AY$3) -> 1728 | E29: =SUM($B$4:B29)+SUM($C$4:C29)-SUM($D$4:D29) -> 4894 | F29: =SUM(经验!A29:X29) -> 600 | G29: =SUM($F$4:F29)+SUM($H$4:H29) -> 16395 | H29: 100 | I29: 3级 | J29: 3级 | K29: 3级 | L29: 3级 | M29: 3级 | N29: 3级 | O29: 空 | P29: 空 | Q29: 空 | R29: 空 | S29: 空 | T29: 空 | U29: 空 | V29: 空 | W29: 空 | X29: 空 | Y29: 5级 | Z29: 5级 | AA29: 5级 | AB29: 5级 | AC29: 5级 | AD29: 5级 | AE29: 空 | AF29: 空 | AG29: =AH29+AI29+AJ29 -> 0 | AK29: 是 | AM29: 历练 | AN29: 50 | AO29: 520 | AQ29: =COUNTIF($I$4:$P$94,AM29) -> 1 | AR29: =COUNTIF($Q$4:$X$94,AM29) -> 1 | AS29: =COUNTIF($Y$4:$AF$94,AM29) -> 1 | AT29: =AQ29+AR29+AS29 -> 3 | AU29: =AQ29*$AO29 -> 520 | AV29: =AR29*$AO29 -> 520 | AW29: =AS29*$AO29 -> 520 | BA29: =AN29*0.8 -> 40
A30: 45028 | B30: 1600 | D30: =(SUM(粮草!A30:X30)+AG30*10)*IF(AK30="是",$AY$4,$AY$3) -> 1616 | E30: =SUM($B$4:B30)+SUM($C$4:C30)-SUM($D$4:D30) -> 4878 | F30: =SUM(经验!A30:X30) -> 575 | G30: =SUM($F$4:F30)+SUM($H$4:H30) -> 17170 | H30: 200 | I30: 3级 | J30: 3级 | K30: 3级 | L30: 3级 | M30: 3级 | N30: 3级 | O30: 空 | P30: 空 | Q30: 空 | R30: 空 | S30: 空 | T30: 空 | U30: 空 | V30: 空 | W30: 空 | X30: 空 | Y30: 商人 | Z30: 5级 | AA30: 5级 | AB30: 5级 | AC30: 5级 | AD30: 5级 | AE30: 空 | AF30: 空 | AG30: =AH30+AI30+AJ30 -> 0 | AK30: 是
A31: 45029 | B31: 1600 | D31: =(SUM(粮草!A31:X31)+AG31*10)*IF(AK31="是",$AY$4,$AY$3) -> 1632 | E31: =SUM($B$4:B31)+SUM($C$4:C31)-SUM($D$4:D31) -> 4846 | F31: =SUM(经验!A31:X31) -> 585 | G31: =SUM($F$4:F31)+SUM($H$4:H31) -> 17755 | H31: 0 | I31: 3级 | J31: 3级 | K31: 3级 | L31: 3级 | M31: 3级 | N31: 商人 | O31: 空 | P31: 空 | Q31: 空 | R31: 空 | S31: 空 | T31: 空 | U31: 空 | V31: 空 | W31: 空 | X31: 空 | Y31: 5级 | Z31: 5级 | AA31: 5级 | AB31: 5级 | AC31: 5级 | AD31: 5级 | AE31: 空 | AF31: 空 | AG31: =AH31+AI31+AJ31 -> 0 | AK31: 是
A32: 45030 | B32: 1600 | D32: =(SUM(粮草!A32:X32)+AG32*10)*IF(AK32="是",$AY$4,$AY$3) -> 1512 | E32: =SUM($B$4:B32)+SUM($C$4:C32)-SUM($D$4:D32) -> 4934 | F32: =SUM(经验!A32:X32) -> 610 | G32: =SUM($F$4:F32)+SUM($H$4:H32) -> 18365 | H32: 0 | I32: 3级 | J32: 3级 | K32: 3级 | L32: 营地+ | M32: 3级 | N32: 3级 | O32: 商人 | P32: 空 | Q32: 空 | R32: 空 | S32: 空 | T32: 空 | U32: 空 | V32: 空 | W32: 空 | X32: 空 | Y32: 5级 | Z32: 6级 | AA32: 6级 | AB32: 6级 | AC32: 6级 | AD32: 6级 | AE32: 空 | AF32: 空 | AG32: =AH32+AI32+AJ32 -> 0 | AK32: 是
A33: 45031 | B33: 1600 | D33: =(SUM(粮草!A33:X33)+AG33*10)*IF(AK33="是",$AY$4,$AY$3) -> 1776 | E33: =SUM($B$4:B33)+SUM($C$4:C33)-SUM($D$4:D33) -> 4758 | F33: =SUM(经验!A33:X33) -> 630 | G33: =SUM($F$4:F33)+SUM($H$4:H33) -> 18995 | H33: 0 | I33: 3级 | J33: 3级 | K33: 3级 | L33: 3级 | M33: 3级 | N33: 3级 | O33: 空 | P33: 空 | Q33: 空 | R33: 空 | S33: 空 | T33: 空 | U33: 空 | V33: 空 | W33: 空 | X33: 空 | Y33: 6级 | Z33: 6级 | AA33: 6级 | AB33: 6级 | AC33: 6级 | AD33: 6级 | AE33: 空 | AF33: 空 | AG33: =AH33+AI33+AJ33 -> 0 | AK33: 是
A34: 45032 | B34: 1600 | D34: =(SUM(粮草!A34:X34)+AG34*10)*IF(AK34="是",$AY$4,$AY$3) -> 1824 | E34: =SUM($B$4:B34)+SUM($C$4:C34)-SUM($D$4:D34) -> 4534 | F34: =SUM(经验!A34:X34) -> 660 | G34: =SUM($F$4:F34)+SUM($H$4:H34) -> 19655 | H34: 0 | I34: 4级 | J34: 4级 | K34: 4级 | L34: 4级 | M34: 4级 | N34: 4级 | O34: 空 | P34: 空 | Q34: 空 | R34: 空 | S34: 空 | T34: 空 | U34: 空 | V34: 空 | W34: 空 | X34: 空 | Y34: 6级 | Z34: 6级 | AA34: 6级 | AB34: 6级 | AC34: 6级 | AD34: 6级 | AE34: 空 | AF34: 空 | AG34: =AH34+AI34+AJ34 -> 0 | AK34: 是
A35: 45033 | B35: 1600 | D35: =(SUM(粮草!A35:X35)+AG35*10)*IF(AK35="是",$AY$4,$AY$3) -> 1816 | E35: =SUM($B$4:B35)+SUM($C$4:C35)-SUM($D$4:D35) -> 4318 | F35: =SUM(经验!A35:X35) -> 655 | G35: =SUM($F$4:F35)+SUM($H$4:H35) -> 20510 | H35: 200 | I35: 4级 | J35: 4级 | K35: 4级 | L35: 4级 | M35: 4级 | N35: 3级 | O35: 空 | P35: 空 | Q35: 空 | R35: 空 | S35: 空 | T35: 空 | U35: 空 | V35: 空 | W35: 空 | X35: 空 | Y35: 6级 | Z35: 6级 | AA35: 6级 | AB35: 6级 | AC35: 6级 | AD35: 6级 | AE35: 空 | AF35: 空 | AG35: =AH35+AI35+AJ35 -> 0 | AK35: 是
A36: 45034 | B36: 1600 | D36: =(SUM(粮草!A36:X36)+AG36*10)*IF(AK36="是",$AY$4,$AY$3) -> 1680 | E36: =SUM($B$4:B36)+SUM($C$4:C36)-SUM($D$4:D36) -> 4238 | F36: =SUM(经验!A36:X36) -> 615 | G36: =SUM($F$4:F36)+SUM($H$4:H36) -> 21225 | H36: 100 | I36: 3级 | J36: 3级 | K36: 3级 | L36: 商人 | M36: 3级 | N36: 3级 | O36: 空 | P36: 空 | Q36: 空 | R36: 空 | S36: 空 | T36: 空 | U36: 空 | V36: 空 | W36: 空 | X36: 空 | Y36: 6级 | Z36: 6级 | AA36: 6级 | AB36: 6级 | AC36: 6级 | AD36: 6级 | AE36: 空 | AF36: 空 | AG36: =AH36+AI36+AJ36 -> 0 | AK36: 是
A37: 45035 | B37: 1600 | D37: =(SUM(粮草!A37:X37)+AG37*10)*IF(AK37="是",$AY$4,$AY$3) -> 1824 | E37: =SUM($B$4:B37)+SUM($C$4:C37)-SUM($D$4:D37) -> 4014 | F37: =SUM(经验!A37:X37) -> 660 | G37: =SUM($F$4:F37)+SUM($H$4:H37) -> 22085 | H37: 200 | I37: 4级 | J37: 4级 | K37: 4级 | L37: 4级 | M37: 4级 | N37: 4级 | O37: 空 | P37: 空 | Q37: 空 | R37: 空 | S37: 空 | T37: 空 | U37: 空 | V37: 空 | W37: 空 | X37: 空 | Y37: 6级 | Z37: 6级 | AA37: 6级 | AB37: 6级 | AC37: 6级 | AD37: 6级 | AE37: 空 | AF37: 空 | AG37: =AH37+AI37+AJ37 -> 0 | AK37: 是
A38: 45036 | B38: 1600 | D38: =(SUM(粮草!A38:X38)+AG38*10)*IF(AK38="是",$AY$4,$AY$3) -> 1680 | E38: =SUM($B$4:B38)+SUM($C$4:C38)-SUM($D$4:D38) -> 3934 | F38: =SUM(经验!A38:X38) -> 640 | G38: =SUM($F$4:F38)+SUM($H$4:H38) -> 22725 | H38: 0 | I38: 4级 | J38: 4级 | K38: 4级 | L38: 4级 | M38: 4级 | N38: 商人 | O38: 空 | P38: 空 | Q38: 空 | R38: 空 | S38: 空 | T38: 空 | U38: 空 | V38: 空 | W38: 空 | X38: 空 | Y38: 6级 | Z38: 6级 | AA38: 6级 | AB38: 6级 | AC38: 塔6 | AD38: 6级 | AE38: 空 | AF38: 空 | AG38: =AH38+AI38+AJ38 -> 0 | AK38: 是
A39: 45037 | B39: 1600 | D39: =(SUM(粮草!A39:X39)+AG39*10)*IF(AK39="是",$AY$4,$AY$3) -> 1824 | E39: =SUM($B$4:B39)+SUM($C$4:C39)-SUM($D$4:D39) -> 3710 | F39: =SUM(经验!A39:X39) -> 660 | G39: =SUM($F$4:F39)+SUM($H$4:H39) -> 23385 | H39: 0 | I39: 4级 | J39: 4级 | K39: 4级 | L39: 4级 | M39: 4级 | N39: 4级 | O39: 空 | P39: 空 | Q39: 空 | R39: 空 | S39: 空 | T39: 空 | U39: 空 | V39: 空 | W39: 空 | X39: 空 | Y39: 6级 | Z39: 6级 | AA39: 6级 | AB39: 6级 | AC39: 6级 | AD39: 6级 | AE39: 空 | AF39: 空 | AG39: =AH39+AI39+AJ39 -> 0 | AK39: 是 | AM39: 2级194
A40: 45038 | B40: 1600 | D40: =(SUM(粮草!A40:X40)+AG40*10)*IF(AK40="是",$AY$4,$AY$3) -> 1824 | E40: =SUM($B$4:B40)+SUM($C$4:C40)-SUM($D$4:D40) -> 3486 | F40: =SUM(经验!A40:X40) -> 660 | G40: =SUM($F$4:F40)+SUM($H$4:H40) -> 24045 | H40: 0 | I40: 4级 | J40: 4级 | K40: 4级 | L40: 4级 | M40: 4级 | N40: 4级 | O40: 空 | P40: 空 | Q40: 空 | R40: 空 | S40: 空 | T40: 空 | U40: 空 | V40: 空 | W40: 空 | X40: 空 | Y40: 6级 | Z40: 6级 | AA40: 6级 | AB40: 6级 | AC40: 6级 | AD40: 6级 | AE40: 空 | AF40: 空 | AG40: =AH40+AI40+AJ40 -> 0 | AK40: 是 | AM40: 3级349
...

Sheet 粮草
A2: 队伍一 风 | C2: 步数 | D2: =COUNTIF(A4:H94,"<>空") -> 728 | E2: (不算跳步和传送) | I2: 队伍二 雷 | K2: 步数 | L2: =COUNTIF(I4:P94,"<>空") -> 728 | M2: (不算跳步和传送) | Q2: 队伍三 | S2: 总步数 | T2: =COUNTIF(Q4:X94,"<>空") -> 728 | U2: (不算跳步和传送)
A3: 1 | B3: 2 | C3: 3 | D3: 4 | E3: 5 | F3: 6 | G3: 7 | H3: 8 | I3: 1 | J3: 2 | K3: 3 | L3: 4 | M3: 5 | N3: 6 | O3: 7 | P3: 8 | Q3: 1 | R3: 2 | S3: 3 | T3: 4 | U3: 5 | V3: 6 | W3: 7 | X3: 8
A4: =(VLOOKUP('11.07'!I4,'11.07'!$AM$4:$AO$55,2,FALSE))*IF('11.07'!AK$4="是",'11.07'!$AY$4,'11.07'!$AY$3) -> 150 | B4: =(VLOOKUP('11.07'!J4,'11.07'!$AM$4:$AO$55,2,FALSE))*IF('11.07'!AL$4="是",'11.07'!$AY$4,'11.07'!$AY$3) -> 150 | C4: =(VLOOKUP('11.07'!K4,'11.07'!$AM$4:$AO$55,2,FALSE))*IF('11.07'!AM$4="是",'11.07'!$AY$4,'11.07'!$AY$3) -> 150 | D4: =(VLOOKUP('11.07'!L4,'11.07'!$AM$4:$AO$55,2,FALSE))*IF('11.07'!AN$4="是",'11.07'!$AY$4,'11.07'!$AY$3) -> 0 | E4: =(VLOOKUP('11.07'!M4,'11.07'!$AM$4:$AO$55,2,FALSE))*IF('11.07'!AO$4="是",'11.07'!$AY$4,'11.07'!$AY$3) -> 0 | F4: =(VLOOKUP('11.07'!N4,'11.07'!$AM$4:$AO$55,2,FALSE))*IF('11.07'!AQ$4="是",'11.07'!$AY$4,'11.07'!$AY$3) -> 0 | G4: =(VLOOKUP('11.07'!O4,'11.07'!$AM$4:$AO$55,2,FALSE))*IF('11.07'!AR$4="是",'11.07'!$AY$4,'11.07'!$AY$3) -> 0 | H4: =(VLOOKUP('11.07'!P4,'11.07'!$AM$4:$AO$55,2,FALSE))*IF('11.07'!AS$4="是",'11.07'!$AY$4,'11.07'!$AY$3) -> 0 | I4: =(VLOOKUP('11.07'!Q4,'11.07'!$AM$4:$AO$55,2,FALSE))*IF('11.07'!AT$4="是",'11.07'!$AY$4,'11.07'!$AY$3) -> 150 | J4: =(VLOOKUP('11.07'!R4,'11.07'!$AM$4:$AO$55,2,FALSE))*IF('11.07'!AU$4="是",'11.07'!$AY$4,'11.07'!$AY$3) -> 150 | K4: =(VLOOKUP('11.07'!S4,'11.07'!$AM$4:$AO$55,2,FALSE))*IF('11.07'!AV$4="是",'11.07'!$AY$4,'11.07'!$AY$3) -> 0 | L4: =(VLOOKUP('11.07'!T4,'11.07'!$AM$4:$AO$55,2,FALSE))*IF('11.07'!AW$4="是",'11.07'!$AY$4,'11.07'!$AY$3) -> 0 | M4: =(VLOOKUP('11.07'!U4,'11.07'!$AM$4:$AO$55,2,FALSE))*IF('11.07'!AX$4="是",'11.07'!$AY$4,'11.07'!$AY$3) -> 0 | ... X4: =(VLOOKUP('11.07'!AF4,'11.07'!$AM$4:$AO$55,2,FALSE))*IF('11.07'!BI$4="是",'11.07'!$AY$4,'11.07'!$AY$3) -> 0
A5: =(VLOOKUP('11.07'!I5,'11.07'!$AM$4:$AO$55,2,FALSE))*IF('11.07'!AK$4="是",'11.07'!$AY$4,'11.07'!$AY$3) -> 0 | B5: =(VLOOKUP('11.07'!J5,'11.07'!$AM$4:$AO$55,2,FALSE))*IF('11.07'!AL$4="是",'11.07'!$AY$4,'11.07'!$AY$3) -> 0 | C5: =(VLOOKUP('11.07'!K5,'11.07'!$AM$4:$AO$55,2,FALSE))*IF('11.07'!AM$4="是",'11.07'!$AY$4,'11.07'!$AY$3) -> 0 | D5: =(VLOOKUP('11.07'!L5,'11.07'!$AM$4:$AO$55,2,FALSE))*IF('11.07'!AN$4="是",'11.07'!$AY$4,'11.07'!$AY$3) -> 0 | E5: =(VLOOKUP('11.07'!M5,'11.07'!$AM$4:$AO$55,2,FALSE))*IF('11.07'!AO$4="是",'11.07'!$AY$4,'11.07'!$AY$3) -> 0 | F5: =(VLOOKUP('11.07'!N5,'11.07'!$AM$4:$AO$55,2,FALSE))*IF('11.07'!AQ$4="是",'11.07'!$AY$4,'11.07'!$AY$3) -> 0 | G5: =(VLOOKUP('11.07'!O5,'11.07'!$AM$4:$AO$55,2,FALSE))*IF('11.07'!AR$4="是",'11.07'!$AY$4,'11.07'!$AY$3) -> 0 | H5: =(VLOOKUP('11.07'!P5,'11.07'!$AM$4:$AO$55,2,FALSE))*IF('11.07'!AS$4="是",'11.07'!$AY$4,'11.07'!$AY$3) -> 0 | I5: =(VLOOKUP('11.07'!Q5,'11.07'!$AM$4:$AO$55,2,FALSE))*IF('11.07'!AT$4="是",'11.07'!$AY$4,'11.07'!$AY$3) -> 0 | J5: =(VLOOKUP('11.07'!R5,'11.07'!$AM$4:$AO$55,2,FALSE))*IF('11.07'!AU$4="是",'11.07'!$AY$4,'11.07'!$AY$3) -> 0 | K5: =(VLOOKUP('11.07'!S5,'11.07'!$AM$4:$AO$55,2,FALSE))*IF('11.07'!AV$4="是",'11.07'!$AY$4,'11.07'!$AY$3) -> 0 | L5: =(VLOOKUP('11.07'!T5,'11.07'!$AM$4:$AO$55,2,FALSE))*IF('11.07'!AW$4="是",'11.07'!$AY$4,'11.07'!$AY$3) -> 0 | M5: =(VLOOKUP('11.07'!U5,'11.07'!$AM$4:$AO$55,2,FALSE))*IF('11.07'!AX$4="是",'11.07'!$AY$4,'11.07'!$AY$3) -> 0 | ... X5: =(VLOOKUP('11.07'!AF5,'11.07'!$AM$4:$AO$55,2,FALSE))*IF('11.07'!BI$4="是",'11.07'!$AY$4,'11.07'!$AY$3) -> 160
A6: =(VLOOKUP('11.07'!I6,'11.07'!$AM$4:$AO$55,2,FALSE))*IF('11.07'!AK$4="是",'11.07'!$AY$4,'11.07'!$AY$3) -> 0 | B6: =(VLOOKUP('11.07'!J6,'11.07'!$AM$4:$AO$55,2,FALSE))*IF('11.07'!AL$4="是",'11.07'!$AY$4,'11.07'!$AY$3) -> 0 | C6: =(VLOOKUP('11.07'!K6,'11.07'!$AM$4:$AO$55,2,FALSE))*IF('11.07'!AM$4="是",'11.07'!$AY$4,'11.07'!$AY$3) -> 0 | D6: =(VLOOKUP('11.07'!L6,'11.07'!$AM$4:$AO$55,2,FALSE))*IF('11.07'!AN$4="是",'11.07'!$AY$4,'11.07'!$AY$3) -> 0 | E6: =(VLOOKUP('11.07'!M6,'11.07'!$AM$4:$AO$55,2,FALSE))*IF('11.07'!AO$4="是",'11.07'!$AY$4,'11.07'!$AY$3) -> 0 | F6: =(VLOOKUP('11.07'!N6,'11.07'!$AM$4:$AO$55,2,FALSE))*IF('11.07'!AQ$4="是",'11.07'!$AY$4,'11.07'!$AY$3) -> 0 | G6: =(VLOOKUP('11.07'!O6,'11.07'!$AM$4:$AO$55,2,FALSE))*IF('11.07'!AR$4="是",'11.07'!$AY$4,'11.07'!$AY$3) -> 0 | H6: =(VLOOKUP('11.07'!P6,'11.07'!$AM$4:$AO$55,2,FALSE))*IF('11.07'!AS$4="是",'11.07'!$AY$4,'11.07'!$AY$3) -> 0 | I6: =(VLOOKUP('11.07'!Q6,'11.07'!$AM$4:$AO$55,2,FALSE))*IF('11.07'!AT$4="是",'11.07'!$AY$4,'11.07'!$AY$3) -> 0 | J6: =(VLOOKUP('11.07'!R6,'11.07'!$AM$4:$AO$55,2,FALSE))*IF('11.07'!AU$4="是",'11.07'!$AY$4,'11.07'!$AY$3) -> 0 | K6: =(VLOOKUP('11.07'!S6,'11.07'!$AM$4:$AO$55,2,FALSE))*IF('11.07'!AV$4="是",'11.07'!$AY$4,'11.07'!$AY$3) -> 0 | L6: =(VLOOKUP('11.07'!T6,'11.07'!$AM$4:$AO$55,2,FALSE))*IF('11.07'!AW$4="是",'11.07'!$AY$4,'11.07'!$AY$3) -> 0 | M6: =(VLOOKUP('11.07'!U6,'11.07'!$AM$4:$AO$55,2,FALSE))*IF('11.07'!AX$4="是",'11.07'!$AY$4,'11.07'!$AY$3) -> 0 | ... X6: =(VLOOKUP('11.07'!AF6,'11.07'!$AM$4:$AO$55,2,FALSE))*IF('11.07'!BI$4="是",'11.07'!$AY$4,'11.07'!$AY$3) -> 0
A7: =(VLOOKUP('11.07'!I7,'11.07'!$AM$4:$AO$55,2,FALSE))*IF('11.07'!AK$4="是",'11.07'!$AY$4,'11.07'!$AY$3) -> 50 | B7: =(VLOOKUP('11.07'!J7,'11.07'!$AM$4:$AO$55,2,FALSE))*IF('11.07'!AL$4="是",'11.07'!$AY$4,'11.07'!$AY$3) -> 170 | C7: =(VLOOKUP('11.07'!K7,'11.07'!$AM$4:$AO$55,2,FALSE))*IF('11.07'!AM$4="是",'11.07'!$AY$4,'11.07'!$AY$3) -> 170 | D7: =(VLOOKUP('11.07'!L7,'11.07'!$AM$4:$AO$55,2,FALSE))*IF('11.07'!AN$4="是",'11.07'!$AY$4,'11.07'!$AY$3) -> 170 | E7: =(VLOOKUP('11.07'!M7,'11.07'!$AM$4:$AO$55,2,FALSE))*IF('11.07'!AO$4="是",'11.07'!$AY$4,'11.07'!$AY$3) -> 170 | F7: =(VLOOKUP('11.07'!N7,'11.07'!$AM$4:$AO$55,2,FALSE))*IF('11.07'!AQ$4="是",'11.07'!$AY$4,'11.07'!$AY$3) -> 170 | G7: =(VLOOKUP('11.07'!O7,'11.07'!$AM$4:$AO$55,2,FALSE))*IF('11.07'!AR$4="是",'11.07'!$AY$4,'11.07'!$AY$3) -> 170 | H7: =(VLOOKUP('11.07'!P7,'11.07'!$AM$4:$AO$55,2,FALSE))*IF('11.07'!AS$4="是",'11.07'!$AY$4,'11.07'!$AY$3) -> 0 | I7: =(VLOOKUP('11.07'!Q7,'11.07'!$AM$4:$AO$55,2,FALSE))*IF('11.07'!AT$4="是",'11.07'!$AY$4,'11.07'!$AY$3) -> 0 | J7: =(VLOOKUP('11.07'!R7,'11.07'!$AM$4:$AO$55,2,FALSE))*IF('11.07'!AU$4="是",'11.07'!$AY$4,'11.07'!$AY$3) -> 0 | K7: =(VLOOKUP('11.07'!S7,'11.07'!$AM$4:$AO$55,2,FALSE))*IF('11.07'!AV$4="是",'11.07'!$AY$4,'11.07'!$AY$3) -> 0 | L7: =(VLOOKUP('11.07'!T7,'11.07'!$AM$4:$AO$55,2,FALSE))*IF('11.07'!AW$4="是",'11.07'!$AY$4,'11.07'!$AY$3) -> 0 | M7: =(VLOOKUP('11.07'!U7,'11.07'!$AM$4:$AO$55,2,FALSE))*IF('11.07'!AX$4="是",'11.07'!$AY$4,'11.07'!$AY$3) -> 0 | ... X7: =(VLOOKUP('11.07'!AF7,'11.07'!$AM$4:$AO$55,2,FALSE))*IF('11.07'!BI$4="是",'11.07'!$AY$4,'11.07'!$AY$3) -> 0
A8: =(VLOOKUP('11.07'!I8,'11.07'!$AM$4:$AO$55,2,FALSE))*IF('11.07'!AK$4="是",'11.07'!$AY$4,'11.07'!$AY$3) -> 250 | B8: =(VLOOKUP('11.07'!J8,'11.07'!$AM$4:$AO$55,2,FALSE))*IF('11.07'!AL$4="是",'11.07'!$AY$4,'11.07'!$AY$3) -> 170 | C8: =(VLOOKUP('11.07'!K8,'11.07'!$AM$4:$AO$55,2,FALSE))*IF('11.07'!AM$4="是",'11.07'!$AY$4,'11.07'!$AY$3) -> 170 | D8: =(VLOOKUP('11.07'!L8,'11.07'!$AM$4:$AO$55,2,FALSE))*IF('11.07'!AN$4="是",'11.07'!$AY$4,'11.07'!$AY$3) -> 180 | E8: =(VLOOKUP('11.07'!M8,'11.07'!$AM$4:$AO$55,2,FALSE))*IF('11.07'!AO$4="是",'11.07'!$AY$4,'11.07'!$AY$3) -> 180 | F8: =(VLOOKUP('11.07'!N8,'11.07'!$AM$4:$AO$55,2,FALSE))*IF('11.07'!AQ$4="是",'11.07'!$AY$4,'11.07'!$AY$3) -> 170 | G8: =(VLOOKUP('11.07'!O8,'11.07'!$AM$4:$AO$55,2,FALSE))*IF('11.07'!AR$4="是",'11.07'!$AY$4,'11.07'!$AY$3) -> 0 | H8: =(VLOOKUP('11.07'!P8,'11.07'!$AM$4:$AO$55,2,FALSE))*IF('11.07'!AS$4="是",'11.07'!$AY$4,'11.07'!$AY$3) -> 0 | I8: =(VLOOKUP('11.07'!Q8,'11.07'!$AM$4:$AO$55,2,FALSE))*IF('11.07'!AT$4="是",'11.07'!$AY$4,'11.07'!$AY$3) -> 0 | J8: =(VLOOKUP('11.07'!R8,'11.07'!$AM$4:$AO$55,2,FALSE))*IF('11.07'!AU$4="是",'11.07'!$AY$4,'11.07'!$AY$3) -> 0 | K8: =(VLOOKUP('11.07'!S8,'11.07'!$AM$4:$AO$55,2,FALSE))*IF('11.07'!AV$4="是",'11.07'!$AY$4,'11.07'!$AY$3) -> 0 | L8: =(VLOOKUP('11.07'!T8,'11.07'!$AM$4:$AO$55,2,FALSE))*IF('11.07'!AW$4="是",'11.07'!$AY$4,'11.07'!$AY$3) -> 0 | M8: =(VLOOKUP('11.07'!U8,'11.07'!$AM$4:$AO$55,2,FALSE))*IF('11.07'!AX$4="是",'11.07'!$AY$4,'11.07'!$AY$3) -> 0 | ... X8: =(VLOOKUP('11.07'!AF8,'11.07'!$AM$4:$AO$55,2,FALSE))*IF('11.07'!BI$4="是",'11.07'!$AY$4,'11.07'!$AY$3) -> 0
A9: =(VLOOKUP('11.07'!I9,'11.07'!$AM$4:$AO$55,2,FALSE))*IF('11.07'!AK$4="是",'11.07'!$AY$4,'11.07'!$AY$3) -> 150 | B9: =(VLOOKUP('11.07'!J9,'11.07'!$AM$4:$AO$55,2,FALSE))*IF('11.07'!AL$4="是",'11.07'!$AY$4,'11.07'!$AY$3) -> 170 | C9: =(VLOOKUP('11.07'!K9,'11.07'!$AM$4:$AO$55,2,FALSE))*IF('11.07'!AM$4="是",'11.07'!$AY$4,'11.07'!$AY$3) -> 170 | D9: =(VLOOKUP('11.07'!L9,'11.07'!$AM$4:$AO$55,2,FALSE))*IF('11.07'!AN$4="是",'11.07'!$AY$4,'11.07'!$AY$3) -> 170 | E9: =(VLOOKUP('11.07'!M9,'11.07'!$AM$4:$AO$55,2,FALSE))*IF('11.07'!AO$4="是",'11.07'!$AY$4,'11.07'!$AY$3) -> 170 | F9: =(VLOOKUP('11.07'!N9,'11.07'!$AM$4:$AO$55,2,FALSE))*IF('11.07'!AQ$4="是",'11.07'!$AY$4,'11.07'!$AY$3) -> 170 | G9: =(VLOOKUP('11.07'!O9,'11.07'!$AM$4:$AO$55,2,FALSE))*IF('11.07'!AR$4="是",'11.07'!$AY$4,'11.07'!$AY$3) -> 0 | H9: =(VLOOKUP('11.07'!P9,'11.07'!$AM$4:$AO$55,2,FALSE))*IF('11.07'!AS$4="是",'11.07'!$AY$4,'11.07'!$AY$3) -> 0 | I9: =(VLOOKUP('11.07'!Q9,'11.07'!$AM$4:$AO$55,2,FALSE))*IF('11.07'!AT$4="是",'11.07'!$AY$4,'11.07'!$AY$3) -> 0 | J9: =(VLOOKUP('11.07'!R9,'11.07'!$AM$4:$AO$55,2,FALSE))*IF('11.07'!AU$4="是",'11.07'!$AY$4,'11.07'!$AY$3) -> 0 | K9: =(VLOOKUP('11.07'!S9,'11.07'!$AM$4:$AO$55,2,FALSE))*IF('11.07'!AV$4="是",'11.07'!$AY$4,'11.07'!$AY$3) -> 0 | L9: =(VLOOKUP('11.07'!T9,'11.07'!$AM$4:$AO$55,2,FALSE))*IF('11.07'!AW$4="是",'11.07'!$AY$4,'11.07'!$AY$3) -> 0 | M9: =(VLOOKUP('11.07'!U9,'11.07'!$AM$4:$AO$55,2,FALSE))*IF('11.07'!AX$4="是",'11.07'!$AY$4,'11.07'!$AY$3) -> 0 | ... X9: =(VLOOKUP('11.07'!AF9,'11.07'!$AM$4:$AO$55,2,FALSE))*IF('11.07'!BI$4="是",'11.07'!$AY$4,'11.07'!$AY$3) -> 0
A10: =(VLOOKUP('11.07'!I10,'11.07'!$AM$4:$AO$55,2,FALSE))*IF('11.07'!AK$4="是",'11.07'!$AY$4,'11.07'!$AY$3) -> 170 | B10: =(VLOOKUP('11.07'!J10,'11.07'!$AM$4:$AO$55,2,FALSE))*IF('11.07'!AL$4="是",'11.07'!$AY$4,'11.07'!$AY$3) -> 170 | C10: =(VLOOKUP('11.07'!K10,'11.07'!$AM$4:$AO$55,2,FALSE))*IF('11.07'!AM$4="是",'11.07'!$AY$4,'11.07'!$AY$3) -> 170 | D10: =(VLOOKUP('11.07'!L10,'11.07'!$AM$4:$AO$55,2,FALSE))*IF('11.07'!AN$4="是",'11.07'!$AY$4,'11.07'!$AY$3) -> 170 | E10: =(VLOOKUP('11.07'!M10,'11.07'!$AM$4:$AO$55,2,FALSE))*IF('11.07'!AO$4="是",'11.07'!$AY$4,'11.07'!$AY$3) -> 170 | F10: =(VLOOKUP('11.07'!N10,'11.07'!$AM$4:$AO$55,2,FALSE))*IF('11.07'!AQ$4="是",'11.07'!$AY$4,'11.07'!$AY$3) -> 170 | G10: =(VLOOKUP('11.07'!O10,'11.07'!$AM$4:$AO$55,2,FALSE))*IF('11.07'!AR$4="是",'11.07'!$AY$4,'11.07'!$AY$3) -> 170 | H10: =(VLOOKUP('11.07'!P10,'11.07'!$AM$4:$AO$55,2,FALSE))*IF('11.07'!AS$4="是",'11.07'!$AY$4,'11.07'!$AY$3) -> 0 | I10: =(VLOOKUP('11.07'!Q10,'11.07'!$AM$4:$AO$55,2,FALSE))*IF('11.07'!AT$4="是",'11.07'!$AY$4,'11.07'!$AY$3) -> 0 | J10: =(VLOOKUP('11.07'!R10,'11.07'!$AM$4:$AO$55,2,FALSE))*IF('11.07'!AU$4="是",'11.07'!$AY$4,'11.07'!$AY$3) -> 0 | K10: =(VLOOKUP('11.07'!S10,'11.07'!$AM$4:$AO$55,2,FALSE))*IF('11.07'!AV$4="是",'11.07'!$AY$4,'11.07'!$AY$3) -> 0 | L10: =(VLOOKUP('11.07'!T10,'11.07'!$AM$4:$AO$55,2,FALSE))*IF('11.07'!AW$4="是",'11.07'!$AY$4,'11.07'!$AY$3) -> 0 | M10: =(VLOOKUP('11.07'!U10,'11.07'!$AM$4:$AO$55,2,FALSE))*IF('11.07'!AX$4="是",'11.07'!$AY$4,'11.07'!$AY$3) -> 0 | ... X10: =(VLOOKUP('11.07'!AF10,'11.07'!$AM$4:$AO$55,2,FALSE))*IF('11.07'!BI$4="是",'11.07'!$AY$4,'11.07'!$AY$3) -> 0
A11: =(VLOOKUP('11.07'!I11,'11.07'!$AM$4:$AO$55,2,FALSE))*IF('11.07'!AK$4="是",'11.07'!$AY$4,'11.07'!$AY$3) -> 0 | B11: =(VLOOKUP('11.07'!J11,'11.07'!$AM$4:$AO$55,2,FALSE))*IF('11.07'!AL$4="是",'11.07'!$AY$4,'11.07'!$AY$3) -> 0 | C11: =(VLOOKUP('11.07'!K11,'11.07'!$AM$4:$AO$55,2,FALSE))*IF('11.07'!AM$4="是",'11.07'!$AY$4,'11.07'!$AY$3) -> 0 | D11: =(VLOOKUP('11.07'!L11,'11.07'!$AM$4:$AO$55,2,FALSE))*IF('11.07'!AN$4="是",'11.07'!$AY$4,'11.07'!$AY$3) -> 0 | E11: =(VLOOKUP('11.07'!M11,'11.07'!$AM$4:$AO$55,2,FALSE))*IF('11.07'!AO$4="是",'11.07'!$AY$4,'11.07'!$AY$3) -> 0 | F11: =(VLOOKUP('11.07'!N11,'11.07'!$AM$4:$AO$55,2,FALSE))*IF('11.07'!AQ$4="是",'11.07'!$AY$4,'11.07'!$AY$3) -> 0 | G11: =(VLOOKUP('11.07'!O11,'11.07'!$AM$4:$AO$55,2,FALSE))*IF('11.07'!AR$4="是",'11.07'!$AY$4,'11.07'!$AY$3) -> 0 | H11: =(VLOOKUP('11.07'!P11,'11.07'!$AM$4:$AO$55,2,FALSE))*IF('11.07'!AS$4="是",'11.07'!$AY$4,'11.07'!$AY$3) -> 0 | I11: =(VLOOKUP('11.07'!Q11,'11.07'!$AM$4:$AO$55,2,FALSE))*IF('11.07'!AT$4="是",'11.07'!$AY$4,'11.07'!$AY$3) -> 0 | J11: =(VLOOKUP('11.07'!R11,'11.07'!$AM$4:$AO$55,2,FALSE))*IF('11.07'!AU$4="是",'11.07'!$AY$4,'11.07'!$AY$3) -> 0 | K11: =(VLOOKUP('11.07'!S11,'11.07'!$AM$4:$AO$55,2,FALSE))*IF('11.07'!AV$4="是",'11.07'!$AY$4,'11.07'!$AY$3) -> 0 | L11: =(VLOOKUP('11.07'!T11,'11.07'!$AM$4:$AO$55,2,FALSE))*IF('11.07'!AW$4="是",'11.07'!$AY$4,'11.07'!$AY$3) -> 0 | M11: =(VLOOKUP('11.07'!U11,'11.07'!$AM$4:$AO$55,2,FALSE))*IF('11.07'!AX$4="是",'11.07'!$AY$4,'11.07'!$AY$3) -> 0 | ... X11: =(VLOOKUP('11.07'!AF11,'11.07'!$AM$4:$AO$55,2,FALSE))*IF('11.07'!BI$4="是",'11.07'!$AY$4,'11.07'!$AY$3) -> 0
A12: =(VLOOKUP('11.07'!I12,'11.07'!$AM$4:$AO$55,2,FALSE))*IF('11.07'!AK$4="是",'11.07'!$AY$4,'11.07'!$AY$3) -> 170 | B12: =(VLOOKUP('11.07'!J12,'11.07'!$AM$4:$AO$55,2,FALSE))*IF('11.07'!AL$4="是",'11.07'!$AY$4,'11.07'!$AY$3) -> 170 | C12: =(VLOOKUP('11.07'!K12,'11.07'!$AM$4:$AO$55,2,FALSE))*IF('11.07'!AM$4="是",'11.07'!$AY$4,'11.07'!$AY$3) -> 170 | D12: =(VLOOKUP('11.07'!L12,'11.07'!$AM$4:$AO$55,2,FALSE))*IF('11.07'!AN$4="是",'11.07'!$AY$4,'11.07'!$AY$3) -> 170 | E12: =(VLOOKUP('11.07'!M12,'11.07'!$AM$4:$AO$55,2,FALSE))*IF('11.07'!AO$4="是",'11.07'!$AY$4,'11.07'!$AY$3) -> 170 | F12: =(VLOOKUP('11.07'!N12,'11.07'!$AM$4:$AO$55,2,FALSE))*IF('11.07'!AQ$4="是",'11.07'!$AY$4,'11.07'!$AY$3) -> 170 | G12: =(VLOOKUP('11.07'!O12,'11.07'!$AM$4:$AO$55,2,FALSE))*IF('11.07'!AR$4="是",'11.07'!$AY$4,'11.07'!$AY$3) -> 0 | H12: =(VLOOKUP('11.07'!P12,'11.07'!$AM$4:$AO$55,2,FALSE))*IF('11.07'!AS$4="是",'11.07'!$AY$4,'11.07'!$AY$3) -> 0 | I12: =(VLOOKUP('11.07'!Q12,'11.07'!$AM$4:$AO$55,2,FALSE))*IF('11.07'!AT$4="是",'11.07'!$AY$4,'11.07'!$AY$3) -> 0 | J12: =(VLOOKUP('11.07'!R12,'11.07'!$AM$4:$AO$55,2,FALSE))*IF('11.07'!AU$4="是",'11.07'!$AY$4,'11.07'!$AY$3) -> 0 | K12: =(VLOOKUP('11.07'!S12,'11.07'!$AM$4:$AO$55,2,FALSE))*IF('11.07'!AV$4="是",'11.07'!$AY$4,'11.07'!$AY$3) -> 0 | L12: =(VLOOKUP('11.07'!T12,'11.07'!$AM$4:$AO$55,2,FALSE))*IF('11.07'!AW$4="是",'11.07'!$AY$4,'11.07'!$AY$3) -> 0 | M12: =(VLOOKUP('11.07'!U12,'11.07'!$AM$4:$AO$55,2,FALSE))*IF('11.07'!AX$4="是",'11.07'!$AY$4,'11.07'!$AY$3) -> 0 | ... X12: =(VLOOKUP('11.07'!AF12,'11.07'!$AM$4:$AO$55,2,FALSE))*IF('11.07'!BI$4="是",'11.07'!$AY$4,'11.07'!$AY$3) -> 0
A13: =(VLOOKUP('11.07'!I13,'11.07'!$AM$4:$AO$55,2,FALSE))*IF('11.07'!AK$4="是",'11.07'!$AY$4,'11.07'!$AY$3) -> 170 | B13: =(VLOOKUP('11.07'!J13,'11.07'!$AM$4:$AO$55,2,FALSE))*IF('11.07'!AL$4="是",'11.07'!$AY$4,'11.07'!$AY$3) -> 150 | C13: =(VLOOKUP('11.07'!K13,'11.07'!$AM$4:$AO$55,2,FALSE))*IF('11.07'!AM$4="是",'11.07'!$AY$4,'11.07'!$AY$3) -> 170 | D13: =(VLOOKUP('11.07'!L13,'11.07'!$AM$4:$AO$55,2,FALSE))*IF('11.07'!AN$4="是",'11.07'!$AY$4,'11.07'!$AY$3) -> 170 | E13: =(VLOOKUP('11.07'!M13,'11.07'!$AM$4:$AO$55,2,FALSE))*IF('11.07'!AO$4="是",'11.07'!$AY$4,'11.07'!$AY$3) -> 170 | F13: =(VLOOKUP('11.07'!N13,'11.07'!$AM$4:$AO$55,2,FALSE))*IF('11.07'!AQ$4="是",'11.07'!$AY$4,'11.07'!$AY$3) -> 170 | G13: =(VLOOKUP('11.07'!O13,'11.07'!$AM$4:$AO$55,2,FALSE))*IF('11.07'!AR$4="是",'11.07'!$AY$4,'11.07'!$AY$3) -> 0 | H13: =(VLOOKUP('11.07'!P13,'11.07'!$AM$4:$AO$55,2,FALSE))*IF('11.07'!AS$4="是",'11.07'!$AY$4,'11.07'!$AY$3) -> 0 | I13: =(VLOOKUP('11.07'!Q13,'11.07'!$AM$4:$AO$55,2,FALSE))*IF('11.07'!AT$4="是",'11.07'!$AY$4,'11.07'!$AY$3) -> 0 | J13: =(VLOOKUP('11.07'!R13,'11.07'!$AM$4:$AO$55,2,FALSE))*IF('11.07'!AU$4="是",'11.07'!$AY$4,'11.07'!$AY$3) -> 0 | K13: =(VLOOKUP('11.07'!S13,'11.07'!$AM$4:$AO$55,2,FALSE))*IF('11.07'!AV$4="是",'11.07'!$AY$4,'11.07'!$AY$3) -> 0 | L13: =(VLOOKUP('11.07'!T13,'11.07'!$AM$4:$AO$55,2,FALSE))*IF('11.07'!AW$4="是",'11.07'!$AY$4,'11.07'!$AY$3) -> 0 | M13: =(VLOOKUP('11.07'!U13,'11.07'!$AM$4:$AO$55,2,FALSE))*IF('11.07'!AX$4="是",'11.07'!$AY$4,'11.07'!$AY$3) -> 0 | ... X13: =(VLOOKUP('11.07'!AF13,'11.07'!$AM$4:$AO$55,2,FALSE))*IF('11.07'!BI$4="是",'11.07'!$AY$4,'11.07'!$AY$3) -> 0
A14: =(VLOOKUP('11.07'!I14,'11.07'!$AM$4:$AO$55,2,FALSE))*IF('11.07'!AK$4="是",'11.07'!$AY$4,'11.07'!$AY$3) -> 170 | B14: =(VLOOKUP('11.07'!J14,'11.07'!$AM$4:$AO$55,2,FALSE))*IF('11.07'!AL$4="是",'11.07'!$AY$4,'11.07'!$AY$3) -> 170 | C14: =(VLOOKUP('11.07'!K14,'11.07'!$AM$4:$AO$55,2,FALSE))*IF('11.07'!AM$4="是",'11.07'!$AY$4,'11.07'!$AY$3) -> 170 | D14: =(VLOOKUP('11.07'!L14,'11.07'!$AM$4:$AO$55,2,FALSE))*IF('11.07'!AN$4="是",'11.07'!$AY$4,'11.07'!$AY$3) -> 170 | E14: =(VLOOKUP('11.07'!M14,'11.07'!$AM$4:$AO$55,2,FALSE))*IF('11.07'!AO$4="是",'11.07'!$AY$4,'11.07'!$AY$3) -> 170 | F14: =(VLOOKUP('11.07'!N14,'11.07'!$AM$4:$AO$55,2,FALSE))*IF('11.07'!AQ$4="是",'11.07'!$AY$4,'11.07'!$AY$3) -> 170 | G14: =(VLOOKUP('11.07'!O14,'11.07'!$AM$4:$AO$55,2,FALSE))*IF('11.07'!AR$4="是",'11.07'!$AY$4,'11.07'!$AY$3) -> 0 | H14: =(VLOOKUP('11.07'!P14,'11.07'!$AM$4:$AO$55,2,FALSE))*IF('11.07'!AS$4="是",'11.07'!$AY$4,'11.07'!$AY$3) -> 0 | I14: =(VLOOKUP('11.07'!Q14,'11.07'!$AM$4:$AO$55,2,FALSE))*IF('11.07'!AT$4="是",'11.07'!$AY$4,'11.07'!$AY$3) -> 0 | J14: =(VLOOKUP('11.07'!R14,'11.07'!$AM$4:$AO$55,2,FALSE))*IF('11.07'!AU$4="是",'11.07'!$AY$4,'11.07'!$AY$3) -> 0 | K14: =(VLOOKUP('11.07'!S14,'11.07'!$AM$4:$AO$55,2,FALSE))*IF('11.07'!AV$4="是",'11.07'!$AY$4,'11.07'!$AY$3) -> 0 | L14: =(VLOOKUP('11.07'!T14,'11.07'!$AM$4:$AO$55,2,FALSE))*IF('11.07'!AW$4="是",'11.07'!$AY$4,'11.07'!$AY$3) -> 0 | M14: =(VLOOKUP('11.07'!U14,'11.07'!$AM$4:$AO$55,2,FALSE))*IF('11.07'!AX$4="是",'11.07'!$AY$4,'11.07'!$AY$3) -> 0 | ... X14: =(VLOOKUP('11.07'!AF14,'11.07'!$AM$4:$AO$55,2,FALSE))*IF('11.07'!BI$4="是",'11.07'!$AY$4,'11.07'!$AY$3) -> 0
A15: =(VLOOKUP('11.07'!I15,'11.07'!$AM$4:$AO$55,2,FALSE))*IF('11.07'!AK$4="是",'11.07'!$AY$4,'11.07'!$AY$3) -> 170 | B15: =(VLOOKUP('11.07'!J15,'11.07'!$AM$4:$AO$55,2,FALSE))*IF('11.07'!AL$4="是",'11.07'!$AY$4,'11.07'!$AY$3) -> 170 | C15: =(VLOOKUP('11.07'!K15,'11.07'!$AM$4:$AO$55,2,FALSE))*IF('11.07'!AM$4="是",'11.07'!$AY$4,'11.07'!$AY$3) -> 170 | D15: =(VLOOKUP('11.07'!L15,'11.07'!$AM$4:$AO$55,2,FALSE))*IF('11.07'!AN$4="是",'11.07'!$AY$4,'11.07'!$AY$3) -> 170 | E15: =(VLOOKUP('11.07'!M15,'11.07'!$AM$4:$AO$55,2,FALSE))*IF('11.07'!AO$4="是",'11.07'!$AY$4,'11.07'!$AY$3) -> 170 | F15: =(VLOOKUP('11.07'!N15,'11.07'!$AM$4:$AO$55,2,FALSE))*IF('11.07'!AQ$4="是",'11.07'!$AY$4,'11.07'!$AY$3) -> 170 | G15: =(VLOOKUP('11.07'!O15,'11.07'!$AM$4:$AO$55,2,FALSE))*IF('11.07'!AR$4="是",'11.07'!$AY$4,'11.07'!$AY$3) -> 0 | H15: =(VLOOKUP('11.07'!P15,'11.07'!$AM$4:$AO$55,2,FALSE))*IF('11.07'!AS$4="是",'11.07'!$AY$4,'11.07'!$AY$3) -> 0 | I15: =(VLOOKUP('11.07'!Q15,'11.07'!$AM$4:$AO$55,2,FALSE))*IF('11.07'!AT$4="是",'11.07'!$AY$4,'11.07'!$AY$3) -> 0 | J15: =(VLOOKUP('11.07'!R15,'11.07'!$AM$4:$AO$55,2,FALSE))*IF('11.07'!AU$4="是",'11.07'!$AY$4,'11.07'!$AY$3) -> 0 | K15: =(VLOOKUP('11.07'!S15,'11.07'!$AM$4:$AO$55,2,FALSE))*IF('11.07'!AV$4="是",'11.07'!$AY$4,'11.07'!$AY$3) -> 0 | L15: =(VLOOKUP('11.07'!T15,'11.07'!$AM$4:$AO$55,2,FALSE))*IF('11.07'!AW$4="是",'11.07'!$AY$4,'11.07'!$AY$3) -> 0 | M15: =(VLOOKUP('11.07'!U15,'11.07'!$AM$4:$AO$55,2,FALSE))*IF('11.07'!AX$4="是",'11.07'!$AY$4,'11.07'!$AY$3) -> 0 | ... X15: =(VLOOKUP('11.07'!AF15,'11.07'!$AM$4:$AO$55,2,FALSE))*IF('11.07'!BI$4="是",'11.07'!$AY$4,'11.07'!$AY$3) -> 0
... A94: =(VLOOKUP('11.07'!I94,'11.07'!$AM$4:$AO$55,2,FALSE))*IF('11.07'!AK$4="是",'11.07'!$AY$4,'11.07'!$AY$3) -> 160 | B94: =(VLOOKUP('11.07'!J94,'11.07'!$AM$4:$AO$55,2,FALSE))*IF('11.07'!AL$4="是",'11.07'!$AY$4,'11.07'!$AY$3) -> 160 | C94: =(VLOOKUP('11.07'!K94,'11.07'!$AM$4:$AO$55,2,FALSE))*IF('11.07'!AM$4="是",'11.07'!$AY$4,'11.07'!$AY$3) -> 50 | D94: =(VLOOKUP('11.07'!L94,'11.07'!$AM$4:$AO$55,2,FALSE))*IF('11.07'!AN$4="是",'11.07'!$AY$4,'11.07'!$AY$3) -> 0 | E94: =(VLOOKUP('11.07'!M94,'11.07'!$AM$4:$AO$55,2,FALSE))*IF('11.07'!AO$4="是",'11.07'!$AY$4,'11.07'!$AY$3) -> 0 | F94: =(VLOOKUP('11.07'!N94,'11.07'!$AM$4:$AO$55,2,FALSE))*IF('11.07'!AQ$4="是",'11.07'!$AY$4,'11.07'!$AY$3) -> 0 | G94: =(VLOOKUP('11.07'!O94,'11.07'!$AM$4:$AO$55,2,FALSE))*IF('11.07'!AR$4="是",'11.07'!$AY$4,'11.07'!$AY$3) -> 0 | H94: =(VLOOKUP('11.07'!P94,'11.07'!$AM$4:$AO$55,2,FALSE))*IF('11.07'!AS$4="是",'11.07'!$AY$4,'11.07'!$AY$3) -> 0 | I94: =(VLOOKUP('11.07'!Q94,'11.07'!$AM$4:$AO$55,2,FALSE))*IF('11.07'!AT$4="是",'11.07'!$AY$4,'11.07'!$AY$3) -> 160 | J94: =(VLOOKUP('11.07'!R94,'11.07'!$AM$4:$AO$55,2,FALSE))*IF('11.07'!AU$4="是",'11.07'!$AY$4,'11.07'!$AY$3) -> 160 | K94: =(VLOOKUP('11.07'!S94,'11.07'!$AM$4:$AO$55,2,FALSE))*IF('11.07'!AV$4="是",'11.07'!$AY$4,'11.07'!$AY$3) -> 160 | L94: =(VLOOKUP('11.07'!T94,'11.07'!$AM$4:$AO$55,2,FALSE))*IF('11.07'!AW$4="是",'11.07'!$AY$4,'11.07'!$AY$3) -> 160 | M94: =(VLOOKUP('11.07'!U94,'11.07'!$AM$4:$AO$55,2,FALSE))*IF('11.07'!AX$4="是",'11.07'!$AY$4,'11.07'!$AY$3) -> 50 | ... X94: =(VLOOKUP('11.07'!AF94,'11.07'!$AM$4:$AO$55,2,FALSE))*IF('11.07'!BI$4="是",'11.07'!$AY$4,'11.07'!$AY$3) -> 50

Sheet 经验
A2: 队伍一 风 | C2: 步数 | D2: =COUNTIF(A4:H94,"<>空") -> 728 | E2: (不算跳步和传送) | I2: 队伍二 雷 | K2: 步数 | L2: =COUNTIF(I4:P94,"<>空") -> 728 | M2: (不算跳步和传送) | Q2: 队伍三 | S2: 总步数 | T2: =COUNTIF(Q4:X94,"<>空") -> 728 | U2: (不算跳步和传送)
A3: 1 | B3: 2 | C3: 3 | D3: 4 | E3: 5 | F3: 6 | G3: 7 | H3: 8 | I3: 1 | J3: 2 | K3: 3 | L3: 4 | M3: 5 | N3: 6 | O3: 7 | P3: 8 | Q3: 1 | R3: 2 | S3: 3 | T3: 4 | U3: 5 | V3: 6 | W3: 7 | X3: 8
A4: =(VLOOKUP('11.07'!I4,'11.07'!$AM$4:$AO$55,3,FALSE)) -> 35 | B4: =(VLOOKUP('11.07'!J4,'11.07'!$AM$4:$AO$55,3,FALSE)) -> 35 | C4: =(VLOOKUP('11.07'!K4,'11.07'!$AM$4:$AO$55,3,FALSE)) -> 35 | D4: =(VLOOKUP('11.07'!L4,'11.07'!$AM$4:$AO$55,3,FALSE)) -> 0 | E4: =(VLOOKUP('11.07'!M4,'11.07'!$AM$4:$AO$55,3,FALSE)) -> 0 | F4: =(VLOOKUP('11.07'!N4,'11.07'!$AM$4:$AO$55,3,FALSE)) -> 0 | G4: =(VLOOKUP('11.07'!O4,'11.07'!$AM$4:$AO$55,3,FALSE)) -> 0 | H4: =(VLOOKUP('11.07'!P4,'11.07'!$AM$4:$AO$55,3,FALSE)) -> 0 | ... X4: =(VLOOKUP('11.07'!AF4,'11.07'!$AM$4:$AO$55,3,FALSE)) -> 0
A5: =(VLOOKUP('11.07'!I5,'11.07'!$AM$4:$AO$55,3,FALSE)) -> 0 | B5: =(VLOOKUP('11.07'!J5,'11.07'!$AM$4:$AO$55,3,FALSE)) -> 0 | C5: =(VLOOKUP('11.07'!K5,'11.07'!$AM$4:$AO$55,3,FALSE)) -> 0 | D5: =(VLOOKUP('11.07'!L5,'11.07'!$AM$4:$AO$55,3,FALSE)) -> 0 | E5: =(VLOOKUP('11.07'!M5,'11.07'!$AM$4:$AO$55,3,FALSE)) -> 0 | F5: =(VLOOKUP('11.07'!N5,'11.07'!$AM$4:$AO$55,3,FALSE)) -> 0 | G5: =(VLOOKUP('11.07'!O5,'11.07'!$AM$4:$AO$55,3,FALSE)) -> 0 | H5: =(VLOOKUP('11.07'!P5,'11.07'!$AM$4:$AO$55,3,FALSE)) -> 0 | ... X5: =(VLOOKUP('11.07'!AF5,'11.07'!$AM$4:$AO$55,3,FALSE)) -> 40
A6: =(VLOOKUP('11.07'!I6,'11.07'!$AM$4:$AO$55,3,FALSE)) -> 0 | B6: =(VLOOKUP('11.07'!J6,'11.07'!$AM$4:$AO$55,3,FALSE)) -> 0 | C6: =(VLOOKUP('11.07'!K6,'11.07'!$AM$4:$AO$55,3,FALSE)) -> 0 | D6: =(VLOOKUP('11.07'!L6,'11.07'!$AM$4:$AO$55,3,FALSE)) -> 0 | E6: =(VLOOKUP('11.07'!M6,'11.07'!$AM$4:$AO$55,3,FALSE)) -> 0 | F6: =(VLOOKUP('11.07'!N6,'11.07'!$AM$4:$AO$55,3,FALSE)) -> 0 | G6: =(VLOOKUP('11.07'!O6,'11.07'!$AM$4:$AO$55,3,FALSE)) -> 0 | H6: =(VLOOKUP('11.07'!P6,'11.07'!$AM$4:$AO$55,3,FALSE)) -> 0 | ... X6: =(VLOOKUP('11.07'!AF6,'11.07'!$AM$4:$AO$55,3,FALSE)) -> 0
A7: =(VLOOKUP('11.07'!I7,'11.07'!$AM$4:$AO$55,3,FALSE)) -> 30 | B7: =(VLOOKUP('11.07'!J7,'11.07'!$AM$4:$AO$55,3,FALSE)) -> 45 | C7: =(VLOOKUP('11.07'!K7,'11.07'!$AM$4:$AO$55,3,FALSE)) -> 45 | D7: =(VLOOKUP('11.07'!L7,'11.07'!$AM$4:$AO$55,3,FALSE)) -> 45 | E7: =(VLOOKUP('11.07'!M7,'11.07'!$AM$4:$AO$55,3,FALSE)) -> 45 | F7: =(VLOOKUP('11.07'!N7,'11.07'!$AM$4:$AO$55,3,FALSE)) -> 45 | G7: =(VLOOKUP('11.07'!O7,'11.07'!$AM$4:$AO$55,3,FALSE)) -> 45 | H7: =(VLOOKUP('11.07'!P7,'11.07'!$AM$4:$AO$55,3,FALSE)) -> 0 | ... X7: =(VLOOKUP('11.07'!AF7,'11.07'!$AM$4:$AO$55,3,FALSE)) -> 0
A8: =(VLOOKUP('11.07'!I8,'11.07'!$AM$4:$AO$55,3,FALSE)) -> 300 | B8: =(VLOOKUP('11.07'!J8,'11.07'!$AM$4:$AO$55,3,FALSE)) -> 45 | C8: =(VLOOKUP('11.07'!K8,'11.07'!$AM$4:$AO$55,3,FALSE)) -> 45 | D8: =(VLOOKUP('11.07'!L8,'11.07'!$AM$4:$AO$55,3,FALSE)) -> 50 | E8: =(VLOOKUP('11.07'!M8,'11.07'!$AM$4:$AO$55,3,FALSE)) -> 50 | F8: =(VLOOKUP('11.07'!N8,'11.07'!$AM$4:$AO$55,3,FALSE)) -> 45 | G8: =(VLOOKUP('11.07'!O8,'11.07'!$AM$4:$AO$55,3,FALSE)) -> 0 | H8: =(VLOOKUP('11.07'!P8,'11.07'!$AM$4:$AO$55,3,FALSE)) -> 0 | ... X8: =(VLOOKUP('11.07'!AF8,'11.07'!$AM$4:$AO$55,3,FALSE)) -> 0
A9: =(VLOOKUP('11.07'!I9,'11.07'!$AM$4:$AO$55,3,FALSE)) -> 45 | B9: =(VLOOKUP('11.07'!J9,'11.07'!$AM$4:$AO$55,3,FALSE)) -> 45 | C9: =(VLOOKUP('11.07'!K9,'11.07'!$AM$4:$AO$55,3,FALSE)) -> 45 | D9: =(VLOOKUP('11.07'!L9,'11.07'!$AM$4:$AO$55,3,FALSE)) -> 45 | E9: =(VLOOKUP('11.07'!M9,'11.07'!$AM$4:$AO$55,3,FALSE)) -> 45 | F9: =(VLOOKUP('11.07'!N9,'11.07'!$AM$4:$AO$55,3,FALSE)) -> 45 | G9: =(VLOOKUP('11.07'!O9,'11.07'!$AM$4:$AO$55,3,FALSE)) -> 0 | H9: =(VLOOKUP('11.07'!P9,'11.07'!$AM$4:$AO$55,3,FALSE)) -> 0 | ... X9: =(VLOOKUP('11.07'!AF9,'11.07'!$AM$4:$AO$55,3,FALSE)) -> 0
A10: =(VLOOKUP('11.07'!I10,'11.07'!$AM$4:$AO$55,3,FALSE)) -> 45 | B10: =(VLOOKUP('11.07'!J10,'11.07'!$AM$4:$AO$55,3,FALSE)) -> 45 | C10: =(VLOOKUP('11.07'!K10,'11.07'!$AM$4:$AO$55,3,FALSE)) -> 45 | D10: =(VLOOKUP('11.07'!L10,'11.07'!$AM$4:$AO$55,3,FALSE)) -> 45 | E10: =(VLOOKUP('11.07'!M10,'11.07'!$AM$4:$AO$55,3,FALSE)) -> 45 | F10: =(VLOOKUP('11.07'!N10,'11.07'!$AM$4:$AO$55,3,FALSE)) -> 45 | G10: =(VLOOKUP('11.07'!O10,'11.07'!$AM$4:$AO$55,3,FALSE)) -> 45 | H10: =(VLOOKUP('11.07'!P10,'11.07'!$AM$4:$AO$55,3,FALSE)) -> 0 | ... X10: =(VLOOKUP('11.07'!AF10,'11.07'!$AM$4:$AO$55,3,FALSE)) -> 0
A11: =(VLOOKUP('11.07'!I11,'11.07'!$AM$4:$AO$55,3,FALSE)) -> 0 | B11: =(VLOOKUP('11.07'!J11,'11.07'!$AM$4:$AO$55,3,FALSE)) -> 0 | C11: =(VLOOKUP('11.07'!K11,'11.07'!$AM$4:$AO$55,3,FALSE)) -> 0 | D11: =(VLOOKUP('11.07'!L11,'11.07'!$AM$4:$AO$55,3,FALSE)) -> 0 | E11: =(VLOOKUP('11.07'!M11,'11.07'!$AM$4:$AO$55,3,FALSE)) -> 0 | F11: =(VLOOKUP('11.07'!N11,'11.07'!$AM$4:$AO$55,3,FALSE)) -> 0 | G11: =(VLOOKUP('11.07'!O11,'11.07'!$AM$4:$AO$55,3,FALSE)) -> 0 | H11: =(VLOOKUP('11.07'!P11,'11.07'!$AM$4:$AO$55,3,FALSE)) -> 0 | ... X11: =(VLOOKUP('11.07'!AF11,'11.07'!$AM$4:$AO$55,3,FALSE)) -> 0
A12: =(VLOOKUP('11.07'!I12,'11.07'!$AM$4:$AO$55,3,FALSE)) -> 45 | B12: =(VLOOKUP('11.07'!J12,'11.07'!$AM$4:$AO$55,3,FALSE)) -> 45 | C12: =(VLOOKUP('11.07'!K12,'11.07'!$AM$4:$AO$55,3,FALSE)) -> 45 | D12: =(VLOOKUP('11.07'!L12,'11.07'!$AM$4:$AO$55,3,FALSE)) -> 45 | E12: =(VLOOKUP('11.07'!M12,'11.07'!$AM$4:$AO$55,3,FALSE)) -> 45 | F12: =(VLOOKUP('11.07'!N12,'11.07'!$AM$4:$AO$55,3,FALSE)) -> 45 | G12: =(VLOOKUP('11.07'!O12,'11.07'!$AM$4:$AO$55,3,FALSE)) -> 0 | H12: =(VLOOKUP('11.07'!P12,'11.07'!$AM$4:$AO$55,3,FALSE)) -> 0 | ... X12: =(VLOOKUP('11.07'!AF12,'11.07'!$AM$4:$AO$55,3,FALSE)) -> 0
A13: =(VLOOKUP('11.07'!I13,'11.07'!$AM$4:$AO$55,3,FALSE)) -> 45 | B13: =(VLOOKUP('11.07'!J13,'11.07'!$AM$4:$AO$55,3,FALSE)) -> 45 | C13: =(VLOOKUP('11.07'!K13,'11.07'!$AM$4:$AO$55,3,FALSE)) -> 45 | D13: =(VLOOKUP('11.07'!L13,'11.07'!$AM$4:$AO$55,3,FALSE)) -> 45 | E13: =(VLOOKUP('11.07'!M13,'11.07'!$AM$4:$AO$55,3,FALSE)) -> 45 | F13: =(VLOOKUP('11.07'!N13,'11.07'!$AM$4:$AO$55,3,FALSE)) -> 45 | G13: =(VLOOKUP('11.07'!O13,'11.07'!$AM$4:$AO$55,3,FALSE)) -> 0 | H13: =(VLOOKUP('11.07'!P13,'11.07'!$AM$4:$AO$55,3,FALSE)) -> 0 | ... X13: =(VLOOKUP('11.07'!AF13,'11.07'!$AM$4:$AO$55,3,FALSE)) -> 0
A14: =(VLOOKUP('11.07'!I14,'11.07'!$AM$4:$AO$55,3,FALSE)) -> 45 | B14: =(VLOOKUP('11.07'!J14,'11.07'!$AM$4:$AO$55,3,FALSE)) -> 45 | C14: =(VLOOKUP('11.07'!K14,'11.07'!$AM$4:$AO$55,3,FALSE)) -> 45 | D14: =(VLOOKUP('11.07'!L14,'11.07'!$AM$4:$AO$55,3,FALSE)) -> 45 | E14: =(VLOOKUP('11.07'!M14,'11.07'!$AM$4:$AO$55,3,FALSE)) -> 45 | F14: =(VLOOKUP('11.07'!N14,'11.07'!$AM$4:$AO$55,3,FALSE)) -> 45 | G14: =(VLOOKUP('11.07'!O14,'11.07'!$AM$4:$AO$55,3,FALSE)) -> 0 | H14: =(VLOOKUP('11.07'!P14,'11.07'!$AM$4:$AO$55,3,FALSE)) -> 0 | ... X14: =(VLOOKUP('11.07'!AF14,'11.07'!$AM$4:$AO$55,3,FALSE)) -> 0
A15: =(VLOOKUP('11.07'!I15,'11.07'!$AM$4:$AO$55,3,FALSE)) -> 45 | B15: =(VLOOKUP('11.07'!J15,'11.07'!$AM$4:$AO$55,3,FALSE)) -> 45 | C15: =(VLOOKUP('11.07'!K15,'11.07'!$AM$4:$AO$55,3,FALSE)) -> 45 | D15: =(VLOOKUP('11.07'!L15,'11.07'!$AM$4:$AO$55,3,FALSE)) -> 45 | E15: =(VLOOKUP('11.07'!M15,'11.07'!$AM$4:$AO$55,3,FALSE)) -> 45 | F15: =(VLOOKUP('11.07'!N15,'11.07'!$AM$4:$AO$55,3,FALSE)) -> 45 | G15: =(VLOOKUP('11.07'!O15,'11.07'!$AM$4:$AO$55,3,FALSE)) -> 0 | H15: =(VLOOKUP('11.07'!P15,'11.07'!$AM$4:$AO$55,3,FALSE)) -> 0 | ... X15: =(VLOOKUP('11.07'!AF15,'11.07'!$AM$4:$AO$55,3,FALSE)) -> 0
... A94: =(VLOOKUP('11.07'!I94,'11.07'!$AM$4:$AO$55,3,FALSE)) -> 40 | B94: =(VLOOKUP('11.07'!J94,'11.07'!$AM$4:$AO$55,3,FALSE)) -> 40 | C94: =(VLOOKUP('11.07'!K94,'11.07'!$AM$4:$AO$55,3,FALSE)) -> 30 | D94: =(VLOOKUP('11.07'!L94,'11.07'!$AM$4:$AO$55,3,FALSE)) -> 0 | E94: =(VLOOKUP('11.07'!M94,'11.07'!$AM$4:$AO$55,3,FALSE)) -> 0 | F94: =(VLOOKUP('11.07'!N94,'11.07'!$AM$4:$AO$55,3,FALSE)) -> 0 | G94: =(VLOOKUP('11.07'!O94,'11.07'!$AM$4:$AO$55,3,FALSE)) -> 0 | H94: =(VLOOKUP('11.07'!P94,'11.07'!$AM$4:$AO$55,3,FALSE)) -> 0 | ... X94: =(VLOOKUP('11.07'!AF94,'11.07'!$AM$4:$AO$55,3,FALSE)) -> 30

Sheet 亏损
A2: 队伍一 风 | C2: 步数 | D2: =COUNTIF(A4:H94,"<>空") -> 728 | E2: (不算跳步和传送) | I2: 队伍二 雷 | K2: 步数 | L2: =COUNTIF(I4:P94,"<>空") -> 728 | M2: (不算跳步和传送) | Q2: 队伍三 | S2: 总步数 | T2: =COUNTIF(Q4:X94,"<>空") -> 728 | U2: (不算跳步和传送)
A3: 1 | B3: 2 | C3: 3 | D3: 4 | E3: 5 | F3: 6 | G3: 7 | H3: 8 | I3: 1 | J3: 2 | K3: 3 | L3: 4 | M3: 5 | N3: 6 | O3: 7 | P3: 8 | Q3: 1 | R3: 2 | S3: 3 | T3: 4 | U3: 5 | V3: 6 | W3: 7 | X3: 8
A4: =(VLOOKUP('11.07'!I4,'11.07'!$AM$4:$AP$55,4,FALSE)) -> 44.222109 | B4: =(VLOOKUP('11.07'!J4,'11.07'!$AM$4:$AP$55,4,FALSE)) -> 44.222109 | C4: =(VLOOKUP('11.07'!K4,'11.07'!$AM$4:$AP$55,4,FALSE)) -> 44.222109 | D4: =(VLOOKUP('11.07'!L4,'11.07'!$AM$4:$AP$55,4,FALSE)) -> 0 | E4: =(VLOOKUP('11.07'!M4,'11.07'!$AM$4:$AP$55,4,FALSE)) -> 0 | F4: =(VLOOKUP('11.07'!N4,'11.07'!$AM$4:$AP$55,4,FALSE)) -> 0 | G4: =(VLOOKUP('11.07'!O4,'11.07'!$AM$4:$AP$55,4,FALSE)) -> 0 | H4: =(VLOOKUP('11.07'!P4,'11.07'!$AM$4:$AP$55,4,FALSE)) -> 0 | ... X4: =(VLOOKUP('11.07'!AF4,'11.07'!$AM$4:$AP$55,4,FALSE)) -> 0
A5: =(VLOOKUP('11.07'!I5,'11.07'!$AM$4:$AP$55,4,FALSE)) -> 0 | B5: =(VLOOKUP('11.07'!J5,'11.07'!$AM$4:$AP$55,4,FALSE)) -> 0 | C5: =(VLOOKUP('11.07'!K5,'11.07'!$AM$4:$AP$55,4,FALSE)) -> 0 | D5: =(VLOOKUP('11.07'!L5,'11.07'!$AM$4:$AP$55,4,FALSE)) -> 0 | E5: =(VLOOKUP('11.07'!M5,'11.07'!$AM$4:$AP$55,4,FALSE)) -> 0 | F5: =(VLOOKUP('11.07'!N5,'11.07'!$AM$4:$AP$55,4,FALSE)) -> 0 | G5: =(VLOOKUP('11.07'!O5,'11.07'!$AM$4:$AP$55,4,FALSE)) -> 0 | H5: =(VLOOKUP('11.07'!P5,'11.07'!$AM$4:$AP$55,4,FALSE)) -> 0 | ... X5: =(VLOOKUP('11.07'!AF5,'11.07'!$AM$4:$AP$55,4,FALSE)) -> 39.110982
A6: =(VLOOKUP('11.07'!I6,'11.07'!$AM$4:$AP$55,4,FALSE)) -> 0 | B6: =(VLOOKUP('11.07'!J6,'11.07'!$AM$4:$AP$55,4,FALSE)) -> 0 | C6: =(VLOOKUP('11.07'!K6,'11.07'!$AM$4:$AP$55,4,FALSE)) -> 0 | D6: =(VLOOKUP('11.07'!L6,'11.07'!$AM$4:$AP$55,4,FALSE)) -> 0 | E6: =(VLOOKUP('11.07'!M6,'11.07'!$AM$4:$AP$55,4,FALSE)) -> 0 | F6: =(VLOOKUP('11.07'!N6,'11.07'!$AM$4:$AP$55,4,FALSE)) -> 0 | G6: =(VLOOKUP('11.07'!O6,'11.07'!$AM$4:$AP$55,4,FALSE)) -> 0 | H6: =(VLOOKUP('11.07'!P6,'11.07'!$AM$4:$AP$55,4,FALSE)) -> 0 | ... X6: =(VLOOKUP('11.07'!AF6,'11.07'!$AM$4:$AP$55,4,FALSE)) -> 0
A7: =(VLOOKUP('11.07'!I7,'11.07'!$AM$4:$AP$55,4,FALSE)) -> 10 | B7: =(VLOOKUP('11.07'!J7,'11.07'!$AM$4:$AP$55,4,FALSE)) -> 34 | C7: =(VLOOKUP('11.07'!K7,'11.07'!$AM$4:$AP$55,4,FALSE)) -> 34 | D7: =(VLOOKUP('11.07'!L7,'11.07'!$AM$4:$AP$55,4,FALSE)) -> 34 | E7: =(VLOOKUP('11.07'!M7,'11.07'!$AM$4:$AP$55,4,FALSE)) -> 34 | F7: =(VLOOKUP('11.07'!N7,'11.07'!$AM$4:$AP$55,4,FALSE)) -> 34 | G7: =(VLOOKUP('11.07'!O7,'11.07'!$AM$4:$AP$55,4,FALSE)) -> 34 | H7: =(VLOOKUP('11.07'!P7,'11.07'!$AM$4:$AP$55,4,FALSE)) -> 0 | ... X7: =(VLOOKUP('11.07'!AF7,'11.07'!$AM$4:$AP$55,4,FALSE)) -> 0
A8: =(VLOOKUP('11.07'!I8,'11.07'!$AM$4:$AP$55,4,FALSE)) -> 0 | B8: =(VLOOKUP('11.07'!J8,'11.07'!$AM$4:$AP$55,4,FALSE)) -> 34 | C8: =(VLOOKUP('11.07'!K8,'11.07'!$AM$4:$AP$55,4,FALSE)) -> 34 | D8: =(VLOOKUP('11.07'!L8,'11.07'!$AM$4:$AP$55,4,FALSE)) -> 36 | E8: =(VLOOKUP('11.07'!M8,'11.07'!$AM$4:$AP$55,4,FALSE)) -> 36 | F8: =(VLOOKUP('11.07'!N8,'11.07'!$AM$4:$AP$55,4,FALSE)) -> 34 | G8: =(VLOOKUP('11.07'!O8,'11.07'!$AM$4:$AP$55,4,FALSE)) -> 0 | H8: =(VLOOKUP('11.07'!P8,'11.07'!$AM$4:$AP$55,4,FALSE)) -> 0 | ... X8: =(VLOOKUP('11.07'!AF8,'11.07'!$AM$4:$AP$55,4,FALSE)) -> 0
