Workbook

Sheet 组织分包
A1: 序号 | D1: 1.战力每两周更新一次，阵容不同会有所浮动 | T1: 礼包扣除DKP值 | V1: 数量 | W1: 已发放数量 | X1: 剩余数量 | Z1: 总积分
D2: 2.战力加成按照当前战力值的十万分之一计算，并取整并减去2，计入DKP值 | R2: 1 | S2: 传说 | T2: =if($C$13=1,'礼包'!N12,'礼包'!N6) -> 15 | V2: 7 | W2: =COUNTIF($R$18:$R$273,1) -> 0 | X2: =V2-W2 -> 7 | Z2: =T2*V2 -> 105
D3: 3.组织战全勤，DKP+1 | R3: 2 | S3: 英雄 | T3: =if($C$13=1,'礼包'!N13,'礼包'!N7) -> 9 | V3: 7 | W3: =COUNTIF($R$18:$R$273,2) -> 0 | X3: =V3-W3 -> 7 | Z3: =T3*V3 -> 63
D4: 4.参加忍战，单场获得DKP+1 | R4: 3 | S4: 精英 | T4: =if($C$13=1,'礼包'!N14,'礼包'!N8) -> 5 | V4: 23 | W4: =COUNTIF($R$18:$R$273,3) -> 0 | X4: =V4-W4 -> 23 | Z4: =T4*V4 -> 115
D5: 5.周贡献值统计时间为每周一早上5点，至周六早上3点(左右）
D6: 6.周贡献值小于6000，DKP+1；大于等于6000且小于12000，DKP+2;大于等于12000，DKP+3
D7: 7.未参加忍战者，周贡献不计入DKP计算内 | T7: 黄色标记格子需要输入
T8: 绿色格子为自动计算
A10: 统计时间 | B10: 起 | S10: 单次忍战积分 | T10: 3
B11: 止 | S11: 忍战全勤额外积分 | T11: 3
S12: 本周忍战全勤次数 | T12: 4
A13: 本周忍战为 | B13: =IF($C$13=1,"本服","跨服") -> 本服 | C13: 1
W15: Max
H16: =COUNTIF(H18:H88,">0") -> 36 | K16: DKP值加成 | W16: =MAX(W18:W59) -> 60
D17: 成员名字 | F17: 战力 | I17: 贡献值/周 | K17: 战力 | L17: 忍战参战 | M17: 忍战全勤 | N17: 周贡献 | P17: DKP上周结余 | Q17: 本周DKP值 | R17: 本周礼包 | T17: 礼包扣除DKP | U17: DKP结余 | V17: 备注 | W17: 备注2
D18: 青衫 | F18: =VLOOKUP(D18,'战力表'!A:B,2,) -> 2725673 | H18: 1 | K18: =IF(H18>0,VLOOKUP(D18,'战力表'!$A$3:$G$39,7,FALSE),0) -> 10 | L18: =H18*$T$10 -> 3 | M18: =IF(H18=$T$12,$T$11,0) -> 0 | N18: =IF(AND(I18<6000,I18>0),1,IF(AND(I18<12000,I18>=6000),2,IF(AND(I18<=30000,I18>=12000),3))) -> FALSE | P18: 47 | Q18: =K18+L18+M18+N18 -> 13 | S18: =IF(R18=$R$2,$S$2,IF(R18=$R$3,$S$3,IF(R18=$R$4,$S$4))) -> FALSE | T18: =-IF(R18=$R$2,$T$2,IF(R18=$R$3,$T$3,IF(R18=$R$4,$T$4))) -> 0 | U18: =P18+Q18+T18 -> 60 | V18: =IF(H18=0,List!$C$5,$C$3) | W18: =IF(R18>0,U18-100,IF(V18=0,U18,0)) -> 60 | X18: =IF(R18>0,"",IF(W18=$W$16,"yes","")) -> yes
D19: 神、夜月 | F19: =VLOOKUP(D19,'战力表'!A:B,2,) -> 2317235 | H19: 2 | K19: =IF(H19>0,VLOOKUP(D19,'战力表'!$A$3:$G$39,7,FALSE),0) -> 10 | L19: =H19*$T$10 -> 6 | M19: =IF(H19=$T$12,$T$11,0) -> 0 | N19: =IF(AND(I19<6000,I19>0),1,IF(AND(I19<12000,I19>=6000),2,IF(AND(I19<=30000,I19>=12000),3))) -> FALSE | P19: 32 | Q19: =K19+L19+M19+N19 -> 16 | S19: =IF(R19=$R$2,$S$2,IF(R19=$R$3,$S$3,IF(R19=$R$4,$S$4))) -> FALSE | T19: =-IF(R19=$R$2,$T$2,IF(R19=$R$3,$T$3,IF(R19=$R$4,$T$4))) -> 0 | U19: =P19+Q19+T19 -> 48 | V19: =IF(H19=0,List!$C$5,$C$3) | W19: =IF(R19>0,U19-100,IF(V19=0,U19,0)) -> 48 | X19: =IF(R19>0,"",IF(W19=$W$16,"yes",""))
D20: 无羡 | F20: =VLOOKUP(D20,'战力表'!A:B,2,) -> 2144859 | H20: 3 | K20: =IF(H20>0,VLOOKUP(D20,'战力表'!$A$3:$G$39,7,FALSE),0) -> 10 | L20: =H20*$T$10 -> 9 | M20: =IF(H20=$T$12,$T$11,0) -> 0 | N20: =IF(AND(I20<6000,I20>0),1,IF(AND(I20<12000,I20>=6000),2,IF(AND(I20<=30000,I20>=12000),3))) -> FALSE | P20: 37 | Q20: =K20+L20+M20+N20 -> 19 | S20: =IF(R20=$R$2,$S$2,IF(R20=$R$3,$S$3,IF(R20=$R$4,$S$4))) -> FALSE | T20: =-IF(R20=$R$2,$T$2,IF(R20=$R$3,$T$3,IF(R20=$R$4,$T$4))) -> 0 | U20: =P20+Q20+T20 -> 56 | V20: =IF(H20=0,List!$C$5,$C$3) | W20: =IF(R20>0,U20-100,IF(V20=0,U20,0)) -> 56 | X20: =IF(R20>0,"",IF(W20=$W$16,"yes",""))
D21: 神域メ万丈红尘 | F21: =VLOOKUP(D21,'战力表'!A:B,2,) -> 2105354 | H21: 4 | K21: =IF(H21>0,VLOOKUP(D21,'战力表'!$A$3:$G$39,7,FALSE),0) -> 8 | L21: =H21*$T$10 -> 12 | M21: =IF(H21=$T$12,$T$11,0) -> 3 | N21: =IF(AND(I21<6000,I21>0),1,IF(AND(I21<12000,I21>=6000),2,IF(AND(I21<=30000,I21>=12000),3))) -> FALSE | P21: 37 | Q21: =K21+L21+M21+N21 -> 23 | S21: =IF(R21=$R$2,$S$2,IF(R21=$R$3,$S$3,IF(R21=$R$4,$S$4))) -> FALSE | T21: =-IF(R21=$R$2,$T$2,IF(R21=$R$3,$T$3,IF(R21=$R$4,$T$4))) -> 0 | U21: =P21+Q21+T21 -> 60 | V21: =IF(H21=0,List!$C$5,$C$3) | W21: =IF(R21>0,U21-100,IF(V21=0,U21,0)) -> 60 | X21: =IF(R21>0,"",IF(W21=$W$16,"yes","")) -> yes
D22: 败家の喵了个咪 | F22: =VLOOKUP(D22,'战力表'!A:B,2,) -> 2013595 | H22: 3 | K22: =IF(H22>0,VLOOKUP(D22,'战力表'!$A$3:$G$39,7,FALSE),0) -> 6 | L22: =H22*$T$10 -> 9 | M22: =IF(H22=$T$12,$T$11,0) -> 0 | N22: =IF(AND(I22<6000,I22>0),1,IF(AND(I22<12000,I22>=6000),2,IF(AND(I22<=30000,I22>=12000),3))) -> FALSE | P22: 37 | Q22: =K22+L22+M22+N22 -> 15 | S22: =IF(R22=$R$2,$S$2,IF(R22=$R$3,$S$3,IF(R22=$R$4,$S$4))) -> FALSE | T22: =-IF(R22=$R$2,$T$2,IF(R22=$R$3,$T$3,IF(R22=$R$4,$T$4))) -> 0 | U22: =P22+Q22+T22 -> 52 | V22: =IF(H22=0,List!$C$5,$C$3) | W22: =IF(R22>0,U22-100,IF(V22=0,U22,0)) -> 52 | X22: =IF(R22>0,"",IF(W22=$W$16,"yes",""))
D23: 晚一 | F23: =VLOOKUP(D23,'战力表'!A:B,2,) -> 2071893 | H23: 2 | K23: =IF(H23>0,VLOOKUP(D23,'战力表'!$A$3:$G$39,7,FALSE),0) -> 6 | L23: =H23*$T$10 -> 6 | M23: =IF(H23=$T$12,$T$11,0) -> 0 | N23: =IF(AND(I23<6000,I23>0),1,IF(AND(I23<12000,I23>=6000),2,IF(AND(I23<=30000,I23>=12000),3))) -> FALSE | P23: 37 | Q23: =K23+L23+M23+N23 -> 12 | S23: =IF(R23=$R$2,$S$2,IF(R23=$R$3,$S$3,IF(R23=$R$4,$S$4))) -> FALSE | T23: =-IF(R23=$R$2,$T$2,IF(R23=$R$3,$T$3,IF(R23=$R$4,$T$4))) -> 0 | U23: =P23+Q23+T23 -> 49 | V23: =IF(H23=0,List!$C$5,$C$3) | W23: =IF(R23>0,U23-100,IF(V23=0,U23,0)) -> 49 | X23: =IF(R23>0,"",IF(W23=$W$16,"yes",""))
D24: 无式 | F24: =VLOOKUP(D24,'战力表'!A:B,2,) -> 2051741 | H24: 4 | K24: =IF(H24>0,VLOOKUP(D24,'战力表'!$A$3:$G$39,7,FALSE),0) -> 6 | L24: =H24*$T$10 -> 12 | M24: =IF(H24=$T$12,$T$11,0) -> 3 | N24: =IF(AND(I24<6000,I24>0),1,IF(AND(I24<12000,I24>=6000),2,IF(AND(I24<=30000,I24>=12000),3))) -> FALSE | P24: 36 | Q24: =K24+L24+M24+N24 -> 21 | S24: =IF(R24=$R$2,$S$2,IF(R24=$R$3,$S$3,IF(R24=$R$4,$S$4))) -> FALSE | T24: =-IF(R24=$R$2,$T$2,IF(R24=$R$3,$T$3,IF(R24=$R$4,$T$4))) -> 0 | U24: =P24+Q24+T24 -> 57 | V24: =IF(H24=0,List!$C$5,$C$3) | W24: =IF(R24>0,U24-100,IF(V24=0,U24,0)) -> 57 | X24: =IF(R24>0,"",IF(W24=$W$16,"yes",""))
D25: 宇智波斑 | F25: =VLOOKUP(D25,'战力表'!A:B,2,) -> 2034644 | H25: 4 | K25: =IF(H25>0,VLOOKUP(D25,'战力表'!$A$3:$G$39,7,FALSE),0) -> 6 | L25: =H25*$T$10 -> 12 | M25: =IF(H25=$T$12,$T$11,0) -> 3 | N25: =IF(AND(I25<6000,I25>0),1,IF(AND(I25<12000,I25>=6000),2,IF(AND(I25<=30000,I25>=12000),3))) -> FALSE | P25: 36 | Q25: =K25+L25+M25+N25 -> 21 | S25: =IF(R25=$R$2,$S$2,IF(R25=$R$3,$S$3,IF(R25=$R$4,$S$4))) -> FALSE | T25: =-IF(R25=$R$2,$T$2,IF(R25=$R$3,$T$3,IF(R25=$R$4,$T$4))) -> 0 | U25: =P25+Q25+T25 -> 57 | V25: =IF(H25=0,List!$C$5,$C$3) | W25: =IF(R25>0,U25-100,IF(V25=0,U25,0)) -> 57 | X25: =IF(R25>0,"",IF(W25=$W$16,"yes",""))
D26: 文浩 | F26: =VLOOKUP(D26,'战力表'!A:B,2,) -> 1946441 | H26: 4 | K26: =IF(H26>0,VLOOKUP(D26,'战力表'!$A$3:$G$39,7,FALSE),0) -> 6 | L26: =H26*$T$10 -> 12 | M26: =IF(H26=$T$12,$T$11,0) -> 3 | N26: =IF(AND(I26<6000,I26>0),1,IF(AND(I26<12000,I26>=6000),2,IF(AND(I26<=30000,I26>=12000),3))) -> FALSE | P26: 36 | Q26: =K26+L26+M26+N26 -> 21 | S26: =IF(R26=$R$2,$S$2,IF(R26=$R$3,$S$3,IF(R26=$R$4,$S$4))) -> FALSE | T26: =-IF(R26=$R$2,$T$2,IF(R26=$R$3,$T$3,IF(R26=$R$4,$T$4))) -> 0 | U26: =P26+Q26+T26 -> 57 | V26: =IF(H26=0,List!$C$5,$C$3) | W26: =IF(R26>0,U26-100,IF(V26=0,U26,0)) -> 57 | X26: =IF(R26>0,"",IF(W26=$W$16,"yes",""))
D27: 胖纸 | F27: =VLOOKUP(D27,'战力表'!A:B,2,) -> 1902010 | H27: 4 | K27: =IF(H27>0,VLOOKUP(D27,'战力表'!$A$3:$G$39,7,FALSE),0) -> 6 | L27: =H27*$T$10 -> 12 | M27: =IF(H27=$T$12,$T$11,0) -> 3 | N27: =IF(AND(I27<6000,I27>0),1,IF(AND(I27<12000,I27>=6000),2,IF(AND(I27<=30000,I27>=12000),3))) -> FALSE | P27: 36 | Q27: =K27+L27+M27+N27 -> 21 | S27: =IF(R27=$R$2,$S$2,IF(R27=$R$3,$S$3,IF(R27=$R$4,$S$4))) -> FALSE | T27: =-IF(R27=$R$2,$T$2,IF(R27=$R$3,$T$3,IF(R27=$R$4,$T$4))) -> 0 | U27: =P27+Q27+T27 -> 57 | V27: =IF(H27=0,List!$C$5,$C$3) | W27: =IF(R27>0,U27-100,IF(V27=0,U27,0)) -> 57 | X27: =IF(R27>0,"",IF(W27=$W$16,"yes",""))
D28: 小李马路 | F28: =VLOOKUP(D28,'战力表'!A:B,2,) -> 1868233 | K28: =IF(H28>0,VLOOKUP(D28,'战力表'!$A$3:$G$39,7,FALSE),0) -> 0 | L28: =H28*$T$10 -> 0 | M28: =IF(H28=$T$12,$T$11,0) -> 0 | N28: =IF(AND(I28<6000,I28>0),1,IF(AND(I28<12000,I28>=6000),2,IF(AND(I28<=30000,I28>=12000),3))) -> FALSE | P28: 34 | Q28: =K28+L28+M28+N28 -> 0 | S28: =IF(R28=$R$2,$S$2,IF(R28=$R$3,$S$3,IF(R28=$R$4,$S$4))) -> FALSE | T28: =-IF(R28=$R$2,$T$2,IF(R28=$R$3,$T$3,IF(R28=$R$4,$T$4))) -> 0 | U28: =P28+Q28+T28 -> 34 | V28: =IF(H28=0,List!$C$5,$C$3) -> 没有忍战，无法分包 | W28: =IF(R28>0,U28-100,IF(V28=0,U28,0)) -> 0 | X28: =IF(R28>0,"",IF(W28=$W$16,"yes",""))
D29: 拾壹月拾壹 | F29: =VLOOKUP(D29,'战力表'!A:B,2,) -> 1927372 | H29: 3 | K29: =IF(H29>0,VLOOKUP(D29,'战力表'!$A$3:$G$39,7,FALSE),0) -> 6 | L29: =H29*$T$10 -> 9 | M29: =IF(H29=$T$12,$T$11,0) -> 0 | N29: =IF(AND(I29<6000,I29>0),1,IF(AND(I29<12000,I29>=6000),2,IF(AND(I29<=30000,I29>=12000),3))) -> FALSE | P29: 37 | Q29: =K29+L29+M29+N29 -> 15 | S29: =IF(R29=$R$2,$S$2,IF(R29=$R$3,$S$3,IF(R29=$R$4,$S$4))) -> FALSE | T29: =-IF(R29=$R$2,$T$2,IF(R29=$R$3,$T$3,IF(R29=$R$4,$T$4))) -> 0 | U29: =P29+Q29+T29 -> 52 | V29: =IF(H29=0,List!$C$5,$C$3) | W29: =IF(R29>0,U29-100,IF(V29=0,U29,0)) -> 52 | X29: =IF(R29>0,"",IF(W29=$W$16,"yes",""))
D30: 嘿嘿嘿 | F30: =VLOOKUP(D30,'战力表'!A:B,2,) -> 1883583 | H30: 3 | K30: =IF(H30>0,VLOOKUP(D30,'战力表'!$A$3:$G$39,7,FALSE),0) -> 6 | L30: =H30*$T$10 -> 9 | M30: =IF(H30=$T$12,$T$11,0) -> 0 | N30: =IF(AND(I30<6000,I30>0),1,IF(AND(I30<12000,I30>=6000),2,IF(AND(I30<=30000,I30>=12000),3))) -> FALSE | P30: 37 | Q30: =K30+L30+M30+N30 -> 15 | S30: =IF(R30=$R$2,$S$2,IF(R30=$R$3,$S$3,IF(R30=$R$4,$S$4))) -> FALSE | T30: =-IF(R30=$R$2,$T$2,IF(R30=$R$3,$T$3,IF(R30=$R$4,$T$4))) -> 0 | U30: =P30+Q30+T30 -> 52 | V30: =IF(H30=0,List!$C$5,$C$3) | W30: =IF(R30>0,U30-100,IF(V30=0,U30,0)) -> 52 | X30: =IF(R30>0,"",IF(W30=$W$16,"yes",""))
D31: 零点 | F31: =VLOOKUP(D31,'战力表'!A:B,2,) -> 1798517 | H31: 4 | K31: =IF(H31>0,VLOOKUP(D31,'战力表'!$A$3:$G$39,7,FALSE),0) -> 6 | L31: =H31*$T$10 -> 12 | M31: =IF(H31=$T$12,$T$11,0) -> 3 | N31: =IF(AND(I31<6000,I31>0),1,IF(AND(I31<12000,I31>=6000),2,IF(AND(I31<=30000,I31>=12000),3))) -> FALSE | P31: 37 | Q31: =K31+L31+M31+N31 -> 21 | S31: =IF(R31=$R$2,$S$2,IF(R31=$R$3,$S$3,IF(R31=$R$4,$S$4))) -> FALSE | T31: =-IF(R31=$R$2,$T$2,IF(R31=$R$3,$T$3,IF(R31=$R$4,$T$4))) -> 0 | U31: =P31+Q31+T31 -> 58 | V31: =IF(H31=0,List!$C$5,$C$3) | W31: =IF(R31>0,U31-100,IF(V31=0,U31,0)) -> 58 | X31: =IF(R31>0,"",IF(W31=$W$16,"yes",""))
D32: 血魂 | F32: =VLOOKUP(D32,'战力表'!A:B,2,) -> 1785448 | H32: 4 | K32: =IF(H32>0,VLOOKUP(D32,'战力表'!$A$3:$G$39,7,FALSE),0) -> 6 | L32: =H32*$T$10 -> 12 | M32: =IF(H32=$T$12,$T$11,0) -> 3 | N32: =IF(AND(I32<6000,I32>0),1,IF(AND(I32<12000,I32>=6000),2,IF(AND(I32<=30000,I32>=12000),3))) -> FALSE | P32: 36 | Q32: =K32+L32+M32+N32 -> 21 | S32: =IF(R32=$R$2,$S$2,IF(R32=$R$3,$S$3,IF(R32=$R$4,$S$4))) -> FALSE | T32: =-IF(R32=$R$2,$T$2,IF(R32=$R$3,$T$3,IF(R32=$R$4,$T$4))) -> 0 | U32: =P32+Q32+T32 -> 57 | V32: =IF(H32=0,List!$C$5,$C$3) | W32: =IF(R32>0,U32-100,IF(V32=0,U32,0)) -> 57 | X32: =IF(R32>0,"",IF(W32=$W$16,"yes",""))
D33: 风起时 | F33: =VLOOKUP(D33,'战力表'!A:B,2,) -> 1777952 | H33: 4 | K33: =IF(H33>0,VLOOKUP(D33,'战力表'!$A$3:$G$39,7,FALSE),0) -> 6 | L33: =H33*$T$10 -> 12 | M33: =IF(H33=$T$12,$T$11,0) -> 3 | N33: =IF(AND(I33<6000,I33>0),1,IF(AND(I33<12000,I33>=6000),2,IF(AND(I33<=30000,I33>=12000),3))) -> FALSE | P33: 37 | Q33: =K33+L33+M33+N33 -> 21 | S33: =IF(R33=$R$2,$S$2,IF(R33=$R$3,$S$3,IF(R33=$R$4,$S$4))) -> FALSE | T33: =-IF(R33=$R$2,$T$2,IF(R33=$R$3,$T$3,IF(R33=$R$4,$T$4))) -> 0 | U33: =P33+Q33+T33 -> 58 | V33: =IF(H33=0,List!$C$5,$C$3) | W33: =IF(R33>0,U33-100,IF(V33=0,U33,0)) -> 58 | X33: =IF(R33>0,"",IF(W33=$W$16,"yes",""))
D34: Ms、音梵塔 | F34: =VLOOKUP(D34,'战力表'!A:B,2,) -> 1801464 | H34: 4 | K34: =IF(H34>0,VLOOKUP(D34,'战力表'!$A$3:$G$39,7,FALSE),0) -> 6 | L34: =H34*$T$10 -> 12 | M34: =IF(H34=$T$12,$T$11,0) -> 3 | N34: =IF(AND(I34<6000,I34>0),1,IF(AND(I34<12000,I34>=6000),2,IF(AND(I34<=30000,I34>=12000),3))) -> FALSE | P34: 37 | Q34: =K34+L34+M34+N34 -> 21 | S34: =IF(R34=$R$2,$S$2,IF(R34=$R$3,$S$3,IF(R34=$R$4,$S$4))) -> FALSE | T34: =-IF(R34=$R$2,$T$2,IF(R34=$R$3,$T$3,IF(R34=$R$4,$T$4))) -> 0 | U34: =P34+Q34+T34 -> 58 | V34: =IF(H34=0,List!$C$5,$C$3) | W34: =IF(R34>0,U34-100,IF(V34=0,U34,0)) -> 58 | X34: =IF(R34>0,"",IF(W34=$W$16,"yes",""))
D35: }蟑螂恶霸{ | F35: =VLOOKUP(D35,'战力表'!A:B,2,) -> 1738888 | H35: 3 | K35: =IF(H35>0,VLOOKUP(D35,'战力表'!$A$3:$G$39,7,FALSE),0) -> 6 | L35: =H35*$T$10 -> 9 | M35: =IF(H35=$T$12,$T$11,0) -> 0 | N35: =IF(AND(I35<6000,I35>0),1,IF(AND(I35<12000,I35>=6000),2,IF(AND(I35<=30000,I35>=12000),3))) -> FALSE | P35: 37 | Q35: =K35+L35+M35+N35 -> 15 | S35: =IF(R35=$R$2,$S$2,IF(R35=$R$3,$S$3,IF(R35=$R$4,$S$4))) -> FALSE | T35: =-IF(R35=$R$2,$T$2,IF(R35=$R$3,$T$3,IF(R35=$R$4,$T$4))) -> 0 | U35: =P35+Q35+T35 -> 52 | V35: =IF(H35=0,List!$C$5,$C$3) | W35: =IF(R35>0,U35-100,IF(V35=0,U35,0)) -> 52 | X35: =IF(R35>0,"",IF(W35=$W$16,"yes",""))
D36: 佩恩天道づ | F36: =VLOOKUP(D36,'战力表'!A:B,2,) -> 1651300 | H36: 4 | K36: =IF(H36>0,VLOOKUP(D36,'战力表'!$A$3:$G$39,7,FALSE),0) -> 6 | L36: =H36*$T$10 -> 12 | M36: =IF(H36=$T$12,$T$11,0) -> 3 | N36: =IF(AND(I36<6000,I36>0),1,IF(AND(I36<12000,I36>=6000),2,IF(AND(I36<=30000,I36>=12000),3))) -> FALSE | P36: 37 | Q36: =K36+L36+M36+N36 -> 21 | S36: =IF(R36=$R$2,$S$2,IF(R36=$R$3,$S$3,IF(R36=$R$4,$S$4))) -> FALSE | T36: =-IF(R36=$R$2,$T$2,IF(R36=$R$3,$T$3,IF(R36=$R$4,$T$4))) -> 0 | U36: =P36+Q36+T36 -> 58 | V36: =IF(H36=0,List!$C$5,$C$3) | W36: =IF(R36>0,U36-100,IF(V36=0,U36,0)) -> 58 | X36: =IF(R36>0,"",IF(W36=$W$16,"yes",""))
D37: 旗木卡卡西づ | F37: =VLOOKUP(D37,'战力表'!A:B,2,) -> 1676205 | H37: 1 | K37: =IF(H37>0,VLOOKUP(D37,'战力表'!$A$3:$G$39,7,FALSE),0) -> 6 | L37: =H37*$T$10 -> 3 | M37: =IF(H37=$T$12,$T$11,0) -> 0 | N37: =IF(AND(I37<6000,I37>0),1,IF(AND(I37<12000,I37>=6000),2,IF(AND(I37<=30000,I37>=12000),3))) -> FALSE | P37: 34 | Q37: =K37+L37+M37+N37 -> 9 | S37: =IF(R37=$R$2,$S$2,IF(R37=$R$3,$S$3,IF(R37=$R$4,$S$4))) -> FALSE | T37: =-IF(R37=$R$2,$T$2,IF(R37=$R$3,$T$3,IF(R37=$R$4,$T$4))) -> 0 | U37: =P37+Q37+T37 -> 43 | V37: =IF(H37=0,List!$C$5,$C$3) | W37: =IF(R37>0,U37-100,IF(V37=0,U37,0)) -> 43 | X37: =IF(R37>0,"",IF(W37=$W$16,"yes",""))
D38: 过路人停驻 | F38: =VLOOKUP(D38,'战力表'!A:B,2,) -> 1647787 | H38: 4 | K38: =IF(H38>0,VLOOKUP(D38,'战力表'!$A$3:$G$39,7,FALSE),0) -> 6 | L38: =H38*$T$10 -> 12 | M38: =IF(H38=$T$12,$T$11,0) -> 3 | N38: =IF(AND(I38<6000,I38>0),1,IF(AND(I38<12000,I38>=6000),2,IF(AND(I38<=30000,I38>=12000),3))) -> FALSE | P38: 37 | Q38: =K38+L38+M38+N38 -> 21 | S38: =IF(R38=$R$2,$S$2,IF(R38=$R$3,$S$3,IF(R38=$R$4,$S$4))) -> FALSE | T38: =-IF(R38=$R$2,$T$2,IF(R38=$R$3,$T$3,IF(R38=$R$4,$T$4))) -> 0 | U38: =P38+Q38+T38 -> 58 | V38: =IF(H38=0,List!$C$5,$C$3) | W38: =IF(R38>0,U38-100,IF(V38=0,U38,0)) -> 58 | X38: =IF(R38>0,"",IF(W38=$W$16,"yes",""))
D39: 失研患者 | F39: =VLOOKUP(D39,'战力表'!A:B,2,) -> 1680630 | H39: 4 | K39: =IF(H39>0,VLOOKUP(D39,'战力表'!$A$3:$G$39,7,FALSE),0) -> 6 | L39: =H39*$T$10 -> 12 | M39: =IF(H39=$T$12,$T$11,0) -> 3 | N39: =IF(AND(I39<6000,I39>0),1,IF(AND(I39<12000,I39>=6000),2,IF(AND(I39<=30000,I39>=12000),3))) -> FALSE | P39: 37 | Q39: =K39+L39+M39+N39 -> 21 | S39: =IF(R39=$R$2,$S$2,IF(R39=$R$3,$S$3,IF(R39=$R$4,$S$4))) -> FALSE | T39: =-IF(R39=$R$2,$T$2,IF(R39=$R$3,$T$3,IF(R39=$R$4,$T$4))) -> 0 | U39: =P39+Q39+T39 -> 58 | V39: =IF(H39=0,List!$C$5,$C$3) | W39: =IF(R39>0,U39-100,IF(V39=0,U39,0)) -> 58 | X39: =IF(R39>0,"",IF(W39=$W$16,"yes",""))
D40: 神域メ诗航 | F40: =VLOOKUP(D40,'战力表'!A:B,2,) -> 1586948 | H40: 1 | K40: =IF(H40>0,VLOOKUP(D40,'战力表'!$A$3:$G$39,7,FALSE),0) -> 5 | L40: =H40*$T$10 -> 3 | M40: =IF(H40=$T$12,$T$11,0) -> 0 | N40: =IF(AND(I40<6000,I40>0),1,IF(AND(I40<12000,I40>=6000),2,IF(AND(I40<=30000,I40>=12000),3))) -> FALSE | P40: 35 | Q40: =K40+L40+M40+N40 -> 8 | S40: =IF(R40=$R$2,$S$2,IF(R40=$R$3,$S$3,IF(R40=$R$4,$S$4))) -> FALSE | T40: =-IF(R40=$R$2,$T$2,IF(R40=$R$3,$T$3,IF(R40=$R$4,$T$4))) -> 0 | U40: =P40+Q40+T40 -> 43 | V40: =IF(H40=0,List!$C$5,$C$3) | W40: =IF(R40>0,U40-100,IF(V40=0,U40,0)) -> 43 | X40: =IF(R40>0,"",IF(W40=$W$16,"yes",""))
... D49: 神域メ影皇 | F49: =VLOOKUP(D49,'战力表'!A:B,2,) -> 1245460 | H49: 4 | K49: =IF(H49>0,VLOOKUP(D49,'战力表'!$A$3:$G$39,7,FALSE),0) -> 5 | L49: =H49*$T$10 -> 12 | M49: =IF(H49=$T$12,$T$11,0) -> 3 | N49: =IF(AND(I49<6000,I49>0),1,IF(AND(I49<12000,I49>=6000),2,IF(AND(I49<=30000,I49>=12000),3))) -> FALSE | P49: 28 | Q49: =K49+L49+M49+N49 -> 20 | S49: =IF(R49=$R$2,$S$2,IF(R49=$R$3,$S$3,IF(R49=$R$4,$S$4))) -> FALSE | T49: =-IF(R49=$R$2,$T$2,IF(R49=$R$3,$T$3,IF(R49=$R$4,$T$4))) -> 0 | U49: =P49+Q49+T49 -> 48 | V49: =IF(H49=0,List!$C$5,$C$3) | W49: =IF(R49>0,U49-100,IF(V49=0,U49,0)) -> 48 | X49: =IF(R49>0,"",IF(W49=$W$16,"yes",""))
D50: 神域メ咸湿老 | F50: =VLOOKUP(D50,'战力表'!A:B,2,) -> 1218787 | K50: =IF(H50>0,VLOOKUP(D50,'战力表'!$A$3:$G$39,7,FALSE),0) -> 0 | L50: =H50*$T$10 -> 0 | M50: =IF(H50=$T$12,$T$11,0) -> 0 | N50: =IF(AND(I50<6000,I50>0),1,IF(AND(I50<12000,I50>=6000),2,IF(AND(I50<=30000,I50>=12000),3))) -> FALSE | P50: 15 | Q50: =K50+L50+M50+N50 -> 0 | S50: =IF(R50=$R$2,$S$2,IF(R50=$R$3,$S$3,IF(R50=$R$4,$S$4))) -> FALSE | T50: =-IF(R50=$R$2,$T$2,IF(R50=$R$3,$T$3,IF(R50=$R$4,$T$4))) -> 0 | U50: =P50+Q50+T50 -> 15 | V50: =IF(H50=0,List!$C$5,$C$3) -> 没有忍战，无法分包 | W50: =IF(R50>0,U50-100,IF(V50=0,U50,0)) -> 0 | X50: =IF(R50>0,"",IF(W50=$W$16,"yes",""))
...

Sheet 积分调整（单次）
C2: 积分 | E2: 0.1
B3: 青衫 | C3: 477 | E3: =INT(C3*$E$2) -> 47
B4: 神、夜月 | C4: 329 | E4: =INT(C4*$E$2) -> 32
B5: 无羡 | C5: 372 | E5: =INT(C5*$E$2) -> 37
B6: 神域メ万丈红尘 | C6: 370 | E6: =INT(C6*$E$2) -> 37
B7: 败家の喵了个咪 | C7: 373 | E7: =INT(C7*$E$2) -> 37
B8: 晚一 | C8: 372 | E8: =INT(C8*$E$2) -> 37
B9: 无式 | C9: 366 | E9: =INT(C9*$E$2) -> 36
B10: 宇智波斑 | C10: 367 | E10: =INT(C10*$E$2) -> 36
B11: 文浩 | C11: 367 | E11: =INT(C11*$E$2) -> 36
B12: 胖纸 | C12: 366 | E12: =INT(C12*$E$2) -> 36
B13: 小李马路 | C13: 348 | E13: =INT(C13*$E$2) -> 34
B14: 拾壹月拾壹 | C14: 370 | E14: =INT(C14*$E$2) -> 37
... B39: 烟头 | C39: 112 | E39: =INT(C39*$E$2) -> 11

Sheet List
C4: 种类
C5: 没有忍战，无法分包

Sheet 战力表
B1: =COUNT(B3:B39) -> 37 | C1: =COUNT(C3:C39) -> 35
B2: 战力 | C2: 参战与否 | G2: 战力积分 | K2: 战力分布 | L2: 战力积分
A3: 青衫 | B3: 2725673 | C3: =IF(VLOOKUP(A3,'组织分包'!$D$18:$H$59,5,FALSE)>0,1,"0") -> 1 | D3: =1/C3 -> 1 | E3: =IF(C3>0,1,"") -> 1 | F3: =IF(C3=0,"",E3) -> 1 | G3: =IF(C3=0,"",IF(F3<$N$3,$L$3,IF(F3<N4,$L$4,IF(F3<$N$5,$L$5,IF(F3<$N$6,$L$6,$L$7))))) -> 10 | K3: 0.1 | L3: 10 | M3: =ROUNDUP($C$1*K3) -> 4 | N3: =M3 -> 4
A4: 神、夜月 | B4: 2317235 | C4: =IF(VLOOKUP(A4,'组织分包'!$D$18:$H$59,5,FALSE)>0,1,"0") -> 1 | D4: =1/C4 -> 1 | E4: =E3+D4 -> 2 | F4: =IF(D4=0,"",E4) -> 2 | G4: =IF(C4=0,"",IF(F4<$N$3,$L$3,IF(F4<N5,$L$4,IF(F4<$N$5,$L$5,IF(F4<$N$6,$L$6,$L$7))))) -> 10 | K4: 0.2 | L4: 8 | M4: =ROUNDUP($C$1*K4) -> 7 | N4: =N3+M4 -> 11
A5: 无羡 | B5: 2144859 | C5: =IF(VLOOKUP(A5,'组织分包'!$D$18:$H$59,5,FALSE)>0,1,"0") -> 1 | D5: =1/C5 -> 1 | E5: =E4+D5 -> 3 | F5: =IF(D5=0,"",E5) -> 3 | G5: =IF(C5=0,"",IF(F5<$N$3,$L$3,IF(F5<N6,$L$4,IF(F5<$N$5,$L$5,IF(F5<$N$6,$L$6,$L$7))))) -> 10 | K5: 0.3 | L5: 6 | M5: =ROUNDUP($C$1*K5) -> 11 | N5: =N4+M5 -> 22
A6: 神域メ万丈红尘 | B6: 2105354 | C6: =IF(VLOOKUP(A6,'组织分包'!$D$18:$H$59,5,FALSE)>0,1,"0") -> 1 | D6: =1/C6 -> 1 | E6: =E5+D6 -> 4 | F6: =IF(D6=0,"",E6) -> 4 | G6: =IF(C6=0,"",IF(F6<$N$3,$L$3,IF(F6<N7,$L$4,IF(F6<$N$5,$L$5,IF(F6<$N$6,$L$6,$L$7))))) -> 8 | K6: 0.3 | L6: 5 | M6: =ROUNDUP($C$1*K6) -> 11 | N6: =N5+M6 -> 33
A7: 晚一 | B7: 2071893 | C7: =IF(VLOOKUP(A7,'组织分包'!$D$18:$H$59,5,FALSE)>0,1,"0") -> 1 | D7: =1/C7 -> 1 | E7: =E6+D7 -> 5 | F7: =IF(D7=0,"",E7) -> 5 | G7: =IF(C7=0,"",IF(F7<$N$3,$L$3,IF(F7<N8,$L$4,IF(F7<$N$5,$L$5,IF(F7<$N$6,$L$6,$L$7))))) -> 6 | K7: 0.1 | L7: 3 | M7: =$C$1-SUM(M3:M6) -> 2 | N7: =N6+M7 -> 35
A8: 无式 | B8: 2051741 | C8: =IF(VLOOKUP(A8,'组织分包'!$D$18:$H$59,5,FALSE)>0,1,"0") -> 1 | D8: =1/C8 -> 1 | E8: =E7+D8 -> 6 | F8: =IF(D8=0,"",E8) -> 6 | G8: =IF(C8=0,"",IF(F8<$N$3,$L$3,IF(F8<N9,$L$4,IF(F8<$N$5,$L$5,IF(F8<$N$6,$L$6,$L$7))))) -> 6
A9: 宇智波斑 | B9: 2034644 | C9: =IF(VLOOKUP(A9,'组织分包'!$D$18:$H$59,5,FALSE)>0,1,"0") -> 1 | D9: =1/C9 -> 1 | E9: =E8+D9 -> 7 | F9: =IF(D9=0,"",E9) -> 7 | G9: =IF(C9=0,"",IF(F9<$N$3,$L$3,IF(F9<N10,$L$4,IF(F9<$N$5,$L$5,IF(F9<$N$6,$L$6,$L$7))))) -> 6
A10: 败家の喵了个咪 | B10: 2013595 | C10: =IF(VLOOKUP(A10,'组织分包'!$D$18:$H$59,5,FALSE)>0,1,"0") -> 1 | D10: =1/C10 -> 1 | E10: =E9+D10 -> 8 | F10: =IF(D10=0,"",E10) -> 8 | G10: =IF(C10=0,"",IF(F10<$N$3,$L$3,IF(F10<N11,$L$4,IF(F10<$N$5,$L$5,IF(F10<$N$6,$L$6,$L$7))))) -> 6
A11: 文浩 | B11: 1946441 | C11: =IF(VLOOKUP(A11,'组织分包'!$D$18:$H$59,5,FALSE)>0,1,"0") -> 1 | D11: =1/C11 -> 1 | E11: =E10+D11 -> 9 | F11: =IF(D11=0,"",E11) -> 9 | G11: =IF(C11=0,"",IF(F11<$N$3,$L$3,IF(F11<N12,$L$4,IF(F11<$N$5,$L$5,IF(F11<$N$6,$L$6,$L$7))))) -> 6
A12: 拾壹月拾壹 | B12: 1927372 | C12: =IF(VLOOKUP(A12,'组织分包'!$D$18:$H$59,5,FALSE)>0,1,"0") -> 1 | D12: =1/C12 -> 1 | E12: =E11+D12 -> 10 | F12: =IF(D12=0,"",E12) -> 10 | G12: =IF(C12=0,"",IF(F12<$N$3,$L$3,IF(F12<N13,$L$4,IF(F12<$N$5,$L$5,IF(F12<$N$6,$L$6,$L$7))))) -> 6
A13: 胖纸 | B13: 1902010 | C13: =IF(VLOOKUP(A13,'组织分包'!$D$18:$H$59,5,FALSE)>0,1,"0") -> 1 | D13: =1/C13 -> 1 | E13: =E12+D13 -> 11 | F13: =IF(D13=0,"",E13) -> 11 | G13: =IF(C13=0,"",IF(F13<$N$3,$L$3,IF(F13<N14,$L$4,IF(F13<$N$5,$L$5,IF(F13<$N$6,$L$6,$L$7))))) -> 6
A14: 嘿嘿嘿 | B14: 1883583 | C14: =IF(VLOOKUP(A14,'组织分包'!$D$18:$H$59,5,FALSE)>0,1,"0") -> 1 | D14: =1/C14 -> 1 | E14: =E13+D14 -> 12 | F14: =IF(D14=0,"",E14) -> 12 | G14: =IF(C14=0,"",IF(F14<$N$3,$L$3,IF(F14<N15,$L$4,IF(F14<$N$5,$L$5,IF(F14<$N$6,$L$6,$L$7))))) -> 6
A15: 小李马路 | B15: 1868233 | C15: =IF(VLOOKUP(A15,'组织分包'!$D$18:$H$59,5,FALSE)>0,1,"0") -> 0 | D15: =IFError(1/C15,0) -> 0 | E15: =E14+D15 -> 12 | F15: =IF(D15=0,"",E15) | G15: =IF(C15=0,"",IF(F15<$N$3,$L$3,IF(F15<$N$4,$L$4,IF(F15<$N$5,$L$5,IF(F15<$N$6,$L$6,$L$7))))) -> 3
A16: Ms、音梵塔 | B16: 1801464 | C16: =IF(VLOOKUP(A16,'组织分包'!$D$18:$H$59,5,FALSE)>0,1,"0") -> 1 | D16: =1/C16 -> 1 | E16: =E15+D16 -> 13 | F16: =IF(D16=0,"",E16) -> 13 | G16: =IF(C16=0,"",IF(F16<$N$3,$L$3,IF(F16<N17,$L$4,IF(F16<$N$5,$L$5,IF(F16<$N$6,$L$6,$L$7))))) -> 6
A17: 零点 | B17: 1798517 | C17: =IF(VLOOKUP(A17,'组织分包'!$D$18:$H$59,5,FALSE)>0,1,"0") -> 1 | D17: =1/C17 -> 1 | E17: =E16+D17 -> 14 | F17: =IF(D17=0,"",E17) -> 14 | G17: =IF(C17=0,"",IF(F17<$N$3,$L$3,IF(F17<N18,$L$4,IF(F17<$N$5,$L$5,IF(F17<$N$6,$L$6,$L$7))))) -> 6
A18: 血魂 | B18: 1785448 | C18: =IF(VLOOKUP(A18,'组织分包'!$D$18:$H$59,5,FALSE)>0,1,"0") -> 1 | D18: =1/C18 -> 1 | E18: =E17+D18 -> 15 | F18: =IF(D18=0,"",E18) -> 15 | G18: =IF(C18=0,"",IF(F18<$N$3,$L$3,IF(F18<N19,$L$4,IF(F18<$N$5,$L$5,IF(F18<$N$6,$L$6,$L$7))))) -> 6
A19: 风起时 | B19: 1777952 | C19: =IF(VLOOKUP(A19,'组织分包'!$D$18:$H$59,5,FALSE)>0,1,"0") -> 1 | D19: =1/C19 -> 1 | E19: =E18+D19 -> 16 | F19: =IF(D19=0,"",E19) -> 16 | G19: =IF(C19=0,"",IF(F19<$N$3,$L$3,IF(F19<N20,$L$4,IF(F19<$N$5,$L$5,IF(F19<$N$6,$L$6,$L$7))))) -> 6
A20: }蟑螂恶霸{ | B20: 1738888 | C20: =IF(VLOOKUP(A20,'组织分包'!$D$18:$H$59,5,FALSE)>0,1,"0") -> 1 | D20: =1/C20 -> 1 | E20: =E19+D20 -> 17 | F20: =IF(D20=0,"",E20) -> 17 | G20: =IF(C20=0,"",IF(F20<$N$3,$L$3,IF(F20<N21,$L$4,IF(F20<$N$5,$L$5,IF(F20<$N$6,$L$6,$L$7))))) -> 6
A21: 失研患者 | B21: 1680630 | C21: =IF(VLOOKUP(A21,'组织分包'!$D$18:$H$59,5,FALSE)>0,1,"0") -> 1 | D21: =1/C21 -> 1 | E21: =E20+D21 -> 18 | F21: =IF(D21=0,"",E21) -> 18 | G21: =IF(C21=0,"",IF(F21<$N$3,$L$3,IF(F21<N22,$L$4,IF(F21<$N$5,$L$5,IF(F21<$N$6,$L$6,$L$7))))) -> 6
A22: 旗木卡卡西づ | B22: 1676205 | C22: =IF(VLOOKUP(A22,'组织分包'!$D$18:$H$59,5,FALSE)>0,1,"0") -> 1 | D22: =1/C22 -> 1 | E22: =E21+D22 -> 19 | F22: =IF(D22=0,"",E22) -> 19 | G22: =IF(C22=0,"",IF(F22<$N$3,$L$3,IF(F22<N23,$L$4,IF(F22<$N$5,$L$5,IF(F22<$N$6,$L$6,$L$7))))) -> 6
A23: 佩恩天道づ | B23: 1651300 | C23: =IF(VLOOKUP(A23,'组织分包'!$D$18:$H$59,5,FALSE)>0,1,"0") -> 1 | D23: =1/C23 -> 1 | E23: =E22+D23 -> 20 | F23: =IF(D23=0,"",E23) -> 20 | G23: =IF(C23=0,"",IF(F23<$N$3,$L$3,IF(F23<N24,$L$4,IF(F23<$N$5,$L$5,IF(F23<$N$6,$L$6,$L$7))))) -> 6
A24: 过路人停驻 | B24: 1647787 | C24: =IF(VLOOKUP(A24,'组织分包'!$D$18:$H$59,5,FALSE)>0,1,"0") -> 1 | D24: =1/C24 -> 1 | E24: =E23+D24 -> 21 | F24: =IF(D24=0,"",E24) -> 21 | G24: =IF(C24=0,"",IF(F24<$N$3,$L$3,IF(F24<N25,$L$4,IF(F24<$N$5,$L$5,IF(F24<$N$6,$L$6,$L$7))))) -> 6
A25: 神域メ诗航 | B25: 1586948 | C25: =IF(VLOOKUP(A25,'组织分包'!$D$18:$H$59,5,FALSE)>0,1,"0") -> 1 | D25: =1/C25 -> 1 | E25: =E24+D25 -> 22 | F25: =IF(D25=0,"",E25) -> 22 | G25: =IF(C25=0,"",IF(F25<$N$3,$L$3,IF(F25<N26,$L$4,IF(F25<$N$5,$L$5,IF(F25<$N$6,$L$6,$L$7))))) -> 5
A26: 小宫山云空 | B26: 1564713 | C26: =IF(VLOOKUP(A26,'组织分包'!$D$18:$H$59,5,FALSE)>0,1,"0") -> 1 | D26: =1/C26 -> 1 | E26: =E25+D26 -> 23 | F26: =IF(D26=0,"",E26) -> 23 | G26: =IF(C26=0,"",IF(F26<$N$3,$L$3,IF(F26<N27,$L$4,IF(F26<$N$5,$L$5,IF(F26<$N$6,$L$6,$L$7))))) -> 5
A27: 神域メ宗麟 | B27: 1509937 | C27: =IF(VLOOKUP(A27,'组织分包'!$D$18:$H$59,5,FALSE)>0,1,"0") -> 1 | D27: =1/C27 -> 1 | E27: =E26+D27 -> 24 | F27: =IF(D27=0,"",E27) -> 24 | G27: =IF(C27=0,"",IF(F27<$N$3,$L$3,IF(F27<N28,$L$4,IF(F27<$N$5,$L$5,IF(F27<$N$6,$L$6,$L$7))))) -> 5
... A31: 神域メ快乐 | B31: 1412660 | C31: =IF(VLOOKUP(A31,'组织分包'!$D$18:$H$59,5,FALSE)>0,1,"0") -> 1 | D31: =1/C31 -> 1 | E31: =E30+D31 -> 28 | F31: =IF(D31=0,"",E31) -> 28 | G31: =IF(C31=0,"",IF(F31<$N$3,$L$3,IF(F31<N32,$L$4,IF(F31<$N$5,$L$5,IF(F31<$N$6,$L$6,$L$7))))) -> 5
A32: Mythe | B32: 1390656 | C32: =IF(VLOOKUP(A32,'组织分包'!$D$18:$H$59,5,FALSE)>0,1,"0") -> 1 | D32: =1/C32 -> 1 | E32: =E31+D32 -> 29 | F32: =IF(D32=0,"",E32) -> 29 | G32: =IF(C32=0,"",IF(F32<$N$3,$L$3,IF(F32<N33,$L$4,IF(F32<$N$5,$L$5,IF(F32<$N$6,$L$6,$L$7))))) -> 5 | K32: 0.2
A33: 六道轮回 | B33: 1388077 | C33: =IF(VLOOKUP(A33,'组织分包'!$D$18:$H$59,5,FALSE)>0,1,"0") -> 1 | D33: =1/C33 -> 1 | E33: =E32+D33 -> 30 | F33: =IF(D33=0,"",E33) -> 30 | G33: =IF(C33=0,"",IF(F33<$N$3,$L$3,IF(F33<N34,$L$4,IF(F33<$N$5,$L$5,IF(F33<$N$6,$L$6,$L$7))))) -> 5
A34: 神域メ影皇 | B34: 1245460 | C34: =IF(VLOOKUP(A34,'组织分包'!$D$18:$H$59,5,FALSE)>0,1,"0") -> 1 | D34: =1/C34 -> 1 | E34: =E33+D34 -> 31 | F34: =IF(D34=0,"",E34) -> 31 | G34: =IF(C34=0,"",IF(F34<$N$3,$L$3,IF(F34<N35,$L$4,IF(F34<$N$5,$L$5,IF(F34<$N$6,$L$6,$L$7))))) -> 5
A35: 神域メ橙子 | B35: 1219648 | C35: =IF(VLOOKUP(A35,'组织分包'!$D$18:$H$59,5,FALSE)>0,1,"0") -> 1 | D35: =1/C35 -> 1 | E35: =E34+D35 -> 32 | F35: =IF(D35=0,"",E35) -> 32 | G35: =IF(C35=0,"",IF(F35<$N$3,$L$3,IF(F35<N36,$L$4,IF(F35<$N$5,$L$5,IF(F35<$N$6,$L$6,$L$7))))) -> 5
A36: 神域メ咸湿老 | B36: 1218787 | C36: =IF(VLOOKUP(A36,'组织分包'!$D$18:$H$59,5,FALSE)>0,1,"0") -> 0 | D36: =IFError(1/C36,0) -> 0 | E36: =E35+D36 -> 32 | F36: =IF(D36=0,"",E36) | G36: =IF(C36=0,"",IF(F36<$N$3,$L$3,IF(F36<N37,$L$4,IF(F36<$N$5,$L$5,IF(F36<$N$6,$L$6,$L$7))))) -> 3
A37: 服部鬼 | B37: 1179860 | C37: =IF(VLOOKUP(A37,'组织分包'!$D$18:$H$59,5,FALSE)>0,1,"0") -> 1 | D37: =1/C37 -> 1 | E37: =E36+D37 -> 33 | F37: =IF(D37=0,"",E37) -> 33 | G37: =IF(C37=0,"",IF(F37<$N$3,$L$3,IF(F37<N38,$L$4,IF(F37<$N$5,$L$5,IF(F37<$N$6,$L$6,$L$7))))) -> 3
A38: 神域メ空调 | B38: 958322 | C38: =IF(VLOOKUP(A38,'组织分包'!$D$18:$H$59,5,FALSE)>0,1,"0") -> 1 | D38: =1/C38 -> 1 | E38: =E37+D38 -> 34 | F38: =IF(D38=0,"",E38) -> 34 | G38: =IF(C38=0,"",IF(F38<$N$3,$L$3,IF(F38<N39,$L$4,IF(F38<$N$5,$L$5,IF(F38<$N$6,$L$6,$L$7))))) -> 3
A39: 烟头 | B39: 915558 | C39: =IF(VLOOKUP(A39,'组织分包'!$D$18:$H$59,5,FALSE)>0,1,"0") -> 1 | D39: =1/C39 -> 1 | E39: =E38+D39 -> 35 | F39: =IF(D39=0,"",E39) -> 35 | G39: =IF(C39=0,"",IF(F39<$N$3,$L$3,IF(F39<N40,$L$4,IF(F39<$N$5,$L$5,IF(F39<$N$6,$L$6,$L$7))))) -> 3
A40: 一诺千金
A43: 一条仙菊
A44: 迷妹
A45: 咸鱼扶不上墙
...

Sheet 礼包
C2: 礼包积分计算
E3: 单价（元宝） | F3: 198 | G3: 100 | H3: 10
F4: 封印 | G4: 通灵 | H4: 原石 | I4: 小计 | J4: 消耗积分
C5: 跨服 | D5: 传说 | E5: 数量 | F5: 5 | G5: 7 | H5: 20
E6: 元宝 | F6: =F5*$F$3 -> 990 | G6: =G5*$G$3 -> 700 | H6: =H5*$H$3 -> 200 | I6: =SUM(F6:H6) -> 1890 | J6: 19 | L6: 19 | N6: =INT(L6*1.2) -> 22
D7: 英雄 | E7: 数量 | F7: 4 | G7: 6 | H7: 15 | L7: 15 | N7: =INT(L7/1.1) -> 13
E8: 元宝 | F8: =F7*$F$3 -> 792 | G8: =G7*$G$3 -> 600 | H8: =H7*$H$3 -> 150 | I8: =SUM(F8:H8) -> 1542 | J8: 15 | L8: 12 | N8: =INT(L8/1.2) -> 10
D9: 精英 | E9: 数量 | F9: 3 | G9: 5 | H9: 10
E10: 元宝 | F10: =F9*$F$3 -> 594 | G10: =G9*$G$3 -> 500 | H10: =H9*$H$3 -> 100 | I10: =SUM(F10:H10) -> 1194 | J10: 12
C11: 本服 | D11: 传说 | E11: 数量 | F11: 4 | G11: 5
E12: 元宝 | F12: =F11*$F$3 -> 792 | G12: =G11*$G$3 -> 500 | I12: =SUM(F12:H12) -> 1292 | J12: 13 | L12: 13 | N12: =INT(L12*1.2) -> 15
D13: 英雄 | E13: 数量 | F13: 3 | G13: 4 | L13: 10 | N13: =INT(L13/1.1) -> 9
E14: 元宝 | F14: =F13*$F$3 -> 594 | G14: =G13*$G$3 -> 400 | I14: =SUM(F14:H14) -> 994 | J14: 10 | L14: 7 | N14: =INT(L14/1.2) -> 5
D15: 精英 | E15: 数量 | F15: 2 | G15: 3
E16: 元宝 | F16: =F15*$F$3 -> 396 | G16: =G15*$G$3 -> 300 | I16: =SUM(F16:H16) -> 696 | J16: 7
C19: 积分原则
B20: 1 | C20: 参加忍战一次，积2分
B21: 2 | C21: 本周忍战全勤，额外活动2分
B22: 3 | C22: 战力对应积分计算。当前战力，除以10万，取整数，再减去3。距离65万战力，65/10-3 = 3积分
C25: 获得礼包时扣除相应的积分。
C26: 发放礼包时不因礼包颜色而有区别，当前分高者优先获得橙色，橙色发放完，发紫色，直至没有礼包。

Sheet 忍战
B21: 9分 | C21: 第1组 | G21: 8分 | H21: 第1组 | L21: 7分 | M21: 第1组
B22: 分组 | C22: 战力 | D22: 阵容 | G22: 分组 | H22: 战力 | I22: 阵容 | L22: 分组 | M22: 战力 | N22: 阵容
B23: 小李马路 | G23: 风起时 | L23: 神域メ文浩 | T23: 1501376 | V23: 4
B24: 神域メ零点 | G24: 木叶の白牙 | L24: 血魂 | T24: 1420718 | V24: 3
B25: }蟑螂恶霸{ | G25: 飘逸的白 | L25: 胖纸 | T25: 1190800 | V25: 4
T26: 1200000 | V26: 4
B27: 9分 | C27: 第2组 | G27: 8分 | H27: 第2组 | L27: 7分 | M27: 第2组
B28: 分组 | C28: 战力 | D28: 阵容 | G28: 分组 | H28: 战力 | I28: 阵容 | L28: 分组 | M28: 战力 | N28: 阵容 | T28: 1123253 | V28: 4
B29: 青衫 | G29: 拾壹月拾壹 | L29: 焦芭芭、 | T29: 1155096 | V29: 4
B30: 败家の喵了个咪 | G30: 无式 | L30: 水墨白衣 | T30: 1139283 | V30: 4
B31: 神域メ晚一 | G31: 虎 | L31: 嘿嘿嘿
T32: 1100000 | V32: 4
B33: 9分 | C33: 第3组 | G33: 8分 | H33: 第3组 | T33: 1100164 | V33: 3
B34: 分组 | C34: 战力 | D34: 阵容 | G34: 分组 | H34: 战力 | I34: 阵容 | T34: 1110760 | V34: 4
T35: 1102029 | V35: 4
T36: 1070154 | V36: 4
T37: 1060527 | V37: 4
B39: 6分 | C39: 第1组 | G39: 5分 | H39: 第1组 | L39: 4分 | M39: 第1组 | T39: 1063224 | V39: 3
B40: 分组 | C40: 战力 | D40: 阵容 | G40: 分组 | H40: 战力 | I40: 阵容 | L40: 分组 | M40: 战力 | N40: 阵容 | T40: 1034040 | V40: 4
B41: 佩恩天道づ | D41: 须鼬、虎皮斑、火主、希 | G41: 过路人停驻 | I41: 须鼬、虎皮斑、火主、希 | L41: 小宫山云空 | N41: 须鼬、虎皮斑、初代、火主 | T41: 1032007 | V41: 3
B42: Ms、音梵塔 | D42: 须鼬、虎皮斑、火主、希 | G42: 神域メ舔蒂 | I42: 须鼬、虎皮斑、火主、希 | L42: 神域メ宗麟 | N42: 须鼬、虎皮斑、火主、希 | T42: 995826
B43: 旗木卡卡西づ | D43: 须鼬、虎皮斑、初代、火主 | G43: 失研患者 | I43: 须鼬、虎皮斑、初代、火主 | L43: 神域メ斋藤 | N43: 须鼬、虎皮斑、火主、希 | T43: 973412 | V43: 4
T44: 965513 | V44: 2
B45: 6分 | C45: 第2组 | G45: 5分 | H45: 第2组 | L45: 4分 | M45: 第2组
B46: 分组 | C46: 战力 | D46: 阵容 | G46: 分组 | H46: 战力 | I46: 阵容 | L46: 分组 | M46: 战力 | N46: 阵容 | T46: 950439 | V46: 4
B47: 千手柱间づ | D47: 须鼬、虎皮斑、初代、火主 | G47: 神域メ诗航 | I47: 虎皮斑、仙鸣、火主、三船 | L47: 神域メ快乐 | N47: 虎皮斑、仙鸣、火主、希 | T47: 948971 | V47: 4
B48: 宇智波斑 | D48: 须鼬、虎皮斑、火主、希 | G48: 月光の胜者达 | I48: 虎皮斑、仙鸣、火主、希 | L48: 神域メ咸湿老 | N48: 虎皮斑、仙鸣、火主、三船 | T48: 980807 | V48: 3
B49: 神域メ万丈红尘 | D49: 须鼬、虎皮斑、火主、希 | G49: 神域メ空空 | I49: 虎皮斑、仙鸣、火主、希 | L49: 神域メ影皇 | N49: 虎皮斑、仙鸣、火主、希 | Q49: 1
T50: 943206 | V50: 2
T51: 904165 | V51: 1
T52: 894496 | V52: 4
T53: 849053 | V53: 3
T54: 864377 | V54: 4
T55: 858014 | V55: 4
T56: 866126 | V56: 2
T57: 860060 | V57: 4
T59: 855437 | V59: 4
T60: 837969 | V60: 4
T61: 800000 | V61: 4
T62: 807538 | V62: 4
...
