Workbook

Sheet 组织分包
A1: 序号 | B1: 1 | D1: 1.战力先攻每两周更新一次，阵容不同会有所浮动 | W1: 礼包扣除DKP值 | Y1: 数量 | Z1: 已发放数量 | AA1: 剩余数量
D2: 2.战力加成按照当前战力值的十万分之一计算，四舍五入并减去3，计入DKP值，组织集结打满得1分，未打满记0分 | U2: 1 | V2: 传说 | W2: 19 | Y2: 8 | Z2: =COUNTIF($U$18:$U$289,1) -> 0 | AA2: =Y2-Z2 -> 8
D3: 3.组织战全勤，DKP+1 | U3: 2 | V3: 英雄 | W3: 15 | Y3: 8 | Z3: =COUNTIF($U$18:$U$289,2) -> 0 | AA3: =Y3-Z3 -> 8
D4: 4.参加忍战，单场获得DKP+1 | U4: 3 | V4: 精英 | W4: 12 | Y4: 12 | Z4: =COUNTIF($U$18:$U$289,3) -> 0 | AA4: =Y4-Z4 -> 12
D5: 5.周贡献值统计时间为每周一早上5点，至周六下午3点(左右）
D6: 6.周贡献值小于6000，DKP+1；大于等于6000且小于12000，DKP+2;大于等于12000，DKP+3
D7: 7.未参加忍战者本周无dkp | W7: 黄色标记格子需要输入
W8: 绿色格子为自动计算
V9: 战力调整值 | W9: 3
A10: 统计时间 | B10: 起 | C10: 月日 | V10: 单次忍战积分 | W10: 2
B11: 止 | C11: 月日 | V11: 忍战全勤额外积分 | W11: 2
V12: 本周忍战全勤次数 | W12: 4
A13: 本周忍战为 | B13: 跨服
M16: DKP值加成
D17: 成员名字 | F17: 战力 | H17: 先攻 | I17: 参战次数 | J17: 贡献值/周 | L17: 组织集结 | M17: 战力 | N17: 先攻 | O17: 忍战参战 | P17: 忍战全勤 | Q17: 周贡献 | S17: DKP上周结余 | T17: 本周DKP值 | U17: 本周礼包 | W17: 礼包扣除DKP | X17: DKP结余 | Y17: 备注 | Z17: 备注2 | AA17: 下次礼包
A18: 全勤 | C18: 1 | D18: 云朵朵 | F18: 736640 | H18: 3769 | I18: 4 | M18: =IF(F18>200000,IF(I18>0,ROUND(F18/100000,1)-$W$9,0),0) -> 4.4 | N18: =IF(H18>2000,IF(I18>0,ROUND(H18/10000,2),0),0)*5 -> 1.9 | O18: =I18*$W$10 -> 8 | P18: =IF(I18=$W$12,$W$11,0) -> 2 | Q18: =IF(AND(J18<6000,J18>0),1,IF(AND(J18<12000,J18>=6000),2,IF(AND(J18<=30000,J18>=12000),3))) -> FALSE | T18: =M18+O18+P18+Q18+L18+N18 -> 16.3 | V18: =IF(U18=$U$2,$V$2,IF(U18=$U$3,$V$3,IF(U18=$U$4,$V$4))) -> FALSE | W18: =-IF(U18=$U$2,$W$2,IF(U18=$U$3,$W$3,IF(U18=$U$4,$W$4))) -> 0 | X18: =S18+T18+W18 -> 16.3 | Y18: =IF(I18=0,List!$C$5,$C$3) -> 0
A19: 忍战缺1 | C19: 2 | D19: 花小鹿 | F19: 690700 | H19: 3300 | I19: 3 | M19: =IF(F19>200000,IF(I19>0,ROUND(F19/100000,1)-$W$9,0),0) -> 3.9 | N19: =IF(H19>2000,IF(I19>0,ROUND(H19/10000,2),0),0)*5 -> 1.65 | O19: =I19*$W$10 -> 6 | P19: =IF(I19=$W$12,$W$11,0) -> 0 | Q19: =IF(AND(J19<6000,J19>0),1,IF(AND(J19<12000,J19>=6000),2,IF(AND(J19<=30000,J19>=12000),3))) -> FALSE | T19: =M19+O19+P19+Q19+L19+N19 -> 11.55 | V19: =IF(U19=$U$2,$V$2,IF(U19=$U$3,$V$3,IF(U19=$U$4,$V$4))) -> FALSE | W19: =-IF(U19=$U$2,$W$2,IF(U19=$U$3,$W$3,IF(U19=$U$4,$W$4))) -> 0 | X19: =S19+T19+W19 -> 11.55 | Y19: =IF(I19=0,List!$C$5,$C$3) -> 0
C20: 3 | D20: 裤裤破了 | F20: 671896 | H20: 3130 | M20: =IF(F20>200000,IF(I20>0,ROUND(F20/100000,1)-$W$9,0),0) -> 0 | N20: =IF(H20>2000,IF(I20>0,ROUND(H20/10000,2),0),0)*5 -> 0 | O20: =I20*$W$10 -> 0 | P20: =IF(I20=$W$12,$W$11,0) -> 0 | Q20: =IF(AND(J20<6000,J20>0),1,IF(AND(J20<12000,J20>=6000),2,IF(AND(J20<=30000,J20>=12000),3))) -> FALSE | T20: =M20+O20+P20+Q20+L20+N20 -> 0 | V20: =IF(U20=$U$2,$V$2,IF(U20=$U$3,$V$3,IF(U20=$U$4,$V$4))) -> FALSE | W20: =-IF(U20=$U$2,$W$2,IF(U20=$U$3,$W$3,IF(U20=$U$4,$W$4))) -> 0 | X20: =S20+T20+W20 -> 0 | Y20: =IF(I20=0,List!$C$5,$C$3) -> 没有忍战，无法分包
A21: 忍战未参加 | C21: 4 | D21: 鬼月 | F21: 639288 | H21: 3080 | I21: 0 | M21: =IF(F21>200000,IF(I21>0,ROUND(F21/100000,1)-$W$9,0),0) -> 0 | N21: =IF(H21>2000,IF(I21>0,ROUND(H21/10000,2),0),0)*5 -> 0 | O21: =I21*$W$10 -> 0 | P21: =IF(I21=$W$12,$W$11,0) -> 0 | Q21: =IF(AND(J21<6000,J21>0),1,IF(AND(J21<12000,J21>=6000),2,IF(AND(J21<=30000,J21>=12000),3))) -> FALSE | T21: =M21+O21+P21+Q21+L21+N21 -> 0 | V21: =IF(U21=$U$2,$V$2,IF(U21=$U$3,$V$3,IF(U21=$U$4,$V$4))) -> FALSE | W21: =-IF(U21=$U$2,$W$2,IF(U21=$U$3,$W$3,IF(U21=$U$4,$W$4))) -> 0 | X21: =S21+T21+W21 -> 0 | Y21: =IF(I21=0,List!$C$5,$C$3) -> 没有忍战，无法分包
C22: 5 | D22: 扉间 | F22: 637707 | H22: 3006 | M22: =IF(F22>200000,IF(I22>0,ROUND(F22/100000,1)-$W$9,0),0) -> 0 | N22: =IF(H22>2000,IF(I22>0,ROUND(H22/10000,2),0),0)*5 -> 0 | O22: =I22*$W$10 -> 0 | P22: =IF(I22=$W$12,$W$11,0) -> 0 | Q22: =IF(AND(J22<6000,J22>0),1,IF(AND(J22<12000,J22>=6000),2,IF(AND(J22<=30000,J22>=12000),3))) -> FALSE | T22: =M22+O22+P22+Q22+L22+N22 -> 0 | V22: =IF(U22=$U$2,$V$2,IF(U22=$U$3,$V$3,IF(U22=$U$4,$V$4))) -> FALSE | W22: =-IF(U22=$U$2,$W$2,IF(U22=$U$3,$W$3,IF(U22=$U$4,$W$4))) -> 0 | X22: =S22+T22+W22 -> 0 | Y22: =IF(I22=0,List!$C$5,$C$3) -> 没有忍战，无法分包
C23: 6 | D23: 干你老师 | F23: 634778 | H23: 2954 | M23: =IF(F23>200000,IF(I23>0,ROUND(F23/100000,1)-$W$9,0),0) -> 0 | N23: =IF(H23>2000,IF(I23>0,ROUND(H23/10000,2),0),0)*5 -> 0 | O23: =I23*$W$10 -> 0 | P23: =IF(I23=$W$12,$W$11,0) -> 0 | Q23: =IF(AND(J23<6000,J23>0),1,IF(AND(J23<12000,J23>=6000),2,IF(AND(J23<=30000,J23>=12000),3))) -> FALSE | T23: =M23+O23+P23+Q23+L23+N23 -> 0 | V23: =IF(U23=$U$2,$V$2,IF(U23=$U$3,$V$3,IF(U23=$U$4,$V$4))) -> FALSE | W23: =-IF(U23=$U$2,$W$2,IF(U23=$U$3,$W$3,IF(U23=$U$4,$W$4))) -> 0 | X23: =S23+T23+W23 -> 0 | Y23: =IF(I23=0,List!$C$5,$C$3) -> 没有忍战，无法分包
C24: 7 | D24: 小柠檬 | F24: 634252 | H24: 3190 | M24: =IF(F24>200000,IF(I24>0,ROUND(F24/100000,1)-$W$9,0),0) -> 0 | N24: =IF(H24>2000,IF(I24>0,ROUND(H24/10000,2),0),0)*5 -> 0 | O24: =I24*$W$10 -> 0 | P24: =IF(I24=$W$12,$W$11,0) -> 0 | Q24: =IF(AND(J24<6000,J24>0),1,IF(AND(J24<12000,J24>=6000),2,IF(AND(J24<=30000,J24>=12000),3))) -> FALSE | T24: =M24+O24+P24+Q24+L24+N24 -> 0 | V24: =IF(U24=$U$2,$V$2,IF(U24=$U$3,$V$3,IF(U24=$U$4,$V$4))) -> FALSE | W24: =-IF(U24=$U$2,$W$2,IF(U24=$U$3,$W$3,IF(U24=$U$4,$W$4))) -> 0 | X24: =S24+T24+W24 -> 0 | Y24: =IF(I24=0,List!$C$5,$C$3) -> 没有忍战，无法分包
C25: 8 | D25: 爱老婆薪 | F25: 629148 | H25: 2828 | M25: =IF(F25>200000,IF(I25>0,ROUND(F25/100000,1)-$W$9,0),0) -> 0 | N25: =IF(H25>2000,IF(I25>0,ROUND(H25/10000,2),0),0)*5 -> 0 | O25: =I25*$W$10 -> 0 | P25: =IF(I25=$W$12,$W$11,0) -> 0 | Q25: =IF(AND(J25<6000,J25>0),1,IF(AND(J25<12000,J25>=6000),2,IF(AND(J25<=30000,J25>=12000),3))) -> FALSE | T25: =M25+O25+P25+Q25+L25+N25 -> 0 | V25: =IF(U25=$U$2,$V$2,IF(U25=$U$3,$V$3,IF(U25=$U$4,$V$4))) -> FALSE | W25: =-IF(U25=$U$2,$W$2,IF(U25=$U$3,$W$3,IF(U25=$U$4,$W$4))) -> 0 | X25: =S25+T25+W25 -> 0 | Y25: =IF(I25=0,List!$C$5,$C$3) -> 没有忍战，无法分包
C26: 9 | D26: 蛋总 | F26: 615876 | H26: 2741 | M26: =IF(F26>200000,IF(I26>0,ROUND(F26/100000,1)-$W$9,0),0) -> 0 | N26: =IF(H26>2000,IF(I26>0,ROUND(H26/10000,2),0),0)*5 -> 0 | O26: =I26*$W$10 -> 0 | P26: =IF(I26=$W$12,$W$11,0) -> 0 | Q26: =IF(AND(J26<6000,J26>0),1,IF(AND(J26<12000,J26>=6000),2,IF(AND(J26<=30000,J26>=12000),3))) -> FALSE | T26: =M26+O26+P26+Q26+L26+N26 -> 0 | V26: =IF(U26=$U$2,$V$2,IF(U26=$U$3,$V$3,IF(U26=$U$4,$V$4))) -> FALSE | W26: =-IF(U26=$U$2,$W$2,IF(U26=$U$3,$W$3,IF(U26=$U$4,$W$4))) -> 0 | X26: =S26+T26+W26 -> 0 | Y26: =IF(I26=0,List!$C$5,$C$3) -> 没有忍战，无法分包
C27: 10 | D27: Kolos | F27: 595824 | H27: 2913 | M27: =IF(F27>200000,IF(I27>0,ROUND(F27/100000,1)-$W$9,0),0) -> 0 | N27: =IF(H27>2000,IF(I27>0,ROUND(H27/10000,2),0),0)*5 -> 0 | O27: =I27*$W$10 -> 0 | P27: =IF(I27=$W$12,$W$11,0) -> 0 | Q27: =IF(AND(J27<6000,J27>0),1,IF(AND(J27<12000,J27>=6000),2,IF(AND(J27<=30000,J27>=12000),3))) -> FALSE | T27: =M27+O27+P27+Q27+L27+N27 -> 0 | V27: =IF(U27=$U$2,$V$2,IF(U27=$U$3,$V$3,IF(U27=$U$4,$V$4))) -> FALSE | W27: =-IF(U27=$U$2,$W$2,IF(U27=$U$3,$W$3,IF(U27=$U$4,$W$4))) -> 0 | X27: =S27+T27+W27 -> 0 | Y27: =IF(I27=0,List!$C$5,$C$3) -> 没有忍战，无法分包
C28: 11 | D28: 佐助 | F28: 589370 | H28: 2721 | M28: =IF(F28>200000,IF(I28>0,ROUND(F28/100000,1)-$W$9,0),0) -> 0 | N28: =IF(H28>2000,IF(I28>0,ROUND(H28/10000,2),0),0)*5 -> 0 | O28: =I28*$W$10 -> 0 | P28: =IF(I28=$W$12,$W$11,0) -> 0 | Q28: =IF(AND(J28<6000,J28>0),1,IF(AND(J28<12000,J28>=6000),2,IF(AND(J28<=30000,J28>=12000),3))) -> FALSE | T28: =M28+O28+P28+Q28+L28+N28 -> 0 | V28: =IF(U28=$U$2,$V$2,IF(U28=$U$3,$V$3,IF(U28=$U$4,$V$4))) -> FALSE | W28: =-IF(U28=$U$2,$W$2,IF(U28=$U$3,$W$3,IF(U28=$U$4,$W$4))) -> 0 | X28: =S28+T28+W28 -> 0 | Y28: =IF(I28=0,List!$C$5,$C$3) -> 没有忍战，无法分包
C29: 12 | D29: 智恩 | F29: 583620 | H29: 3042 | M29: =IF(F29>200000,IF(I29>0,ROUND(F29/100000,1)-$W$9,0),0) -> 0 | N29: =IF(H29>2000,IF(I29>0,ROUND(H29/10000,2),0),0)*5 -> 0 | O29: =I29*$W$10 -> 0 | P29: =IF(I29=$W$12,$W$11,0) -> 0 | Q29: =IF(AND(J29<6000,J29>0),1,IF(AND(J29<12000,J29>=6000),2,IF(AND(J29<=30000,J29>=12000),3))) -> FALSE | T29: =M29+O29+P29+Q29+L29+N29 -> 0 | V29: =IF(U29=$U$2,$V$2,IF(U29=$U$3,$V$3,IF(U29=$U$4,$V$4))) -> FALSE | W29: =-IF(U29=$U$2,$W$2,IF(U29=$U$3,$W$3,IF(U29=$U$4,$W$4))) -> 0 | X29: =S29+T29+W29 -> 0 | Y29: =IF(I29=0,List!$C$5,$C$3) -> 没有忍战，无法分包
C30: 13 | D30: 阿水 | F30: 575751 | H30: 2768 | M30: =IF(F30>200000,IF(I30>0,ROUND(F30/100000,1)-$W$9,0),0) -> 0 | N30: =IF(H30>2000,IF(I30>0,ROUND(H30/10000,2),0),0)*5 -> 0 | O30: =I30*$W$10 -> 0 | P30: =IF(I30=$W$12,$W$11,0) -> 0 | Q30: =IF(AND(J30<6000,J30>0),1,IF(AND(J30<12000,J30>=6000),2,IF(AND(J30<=30000,J30>=12000),3))) -> FALSE | T30: =M30+O30+P30+Q30+L30+N30 -> 0 | V30: =IF(U30=$U$2,$V$2,IF(U30=$U$3,$V$3,IF(U30=$U$4,$V$4))) -> FALSE | W30: =-IF(U30=$U$2,$W$2,IF(U30=$U$3,$W$3,IF(U30=$U$4,$W$4))) -> 0 | X30: =S30+T30+W30 -> 0 | Y30: =IF(I30=0,List!$C$5,$C$3) -> 没有忍战，无法分包
C31: 14 | D31: 雨 | F31: 566756 | H31: 2485 | M31: =IF(F31>200000,IF(I31>0,ROUND(F31/100000,1)-$W$9,0),0) -> 0 | N31: =IF(H31>2000,IF(I31>0,ROUND(H31/10000,2),0),0)*5 -> 0 | O31: =I31*$W$10 -> 0 | P31: =IF(I31=$W$12,$W$11,0) -> 0 | Q31: =IF(AND(J31<6000,J31>0),1,IF(AND(J31<12000,J31>=6000),2,IF(AND(J31<=30000,J31>=12000),3))) -> FALSE | T31: =M31+O31+P31+Q31+L31+N31 -> 0 | V31: =IF(U31=$U$2,$V$2,IF(U31=$U$3,$V$3,IF(U31=$U$4,$V$4))) -> FALSE | W31: =-IF(U31=$U$2,$W$2,IF(U31=$U$3,$W$3,IF(U31=$U$4,$W$4))) -> 0 | X31: =S31+T31+W31 -> 0 | Y31: =IF(I31=0,List!$C$5,$C$3) -> 没有忍战，无法分包
C32: 15 | D32: 霂霖 | F32: 561014 | H32: 2515 | M32: =IF(F32>200000,IF(I32>0,ROUND(F32/100000,1)-$W$9,0),0) -> 0 | N32: =IF(H32>2000,IF(I32>0,ROUND(H32/10000,2),0),0)*5 -> 0 | O32: =I32*$W$10 -> 0 | P32: =IF(I32=$W$12,$W$11,0) -> 0 | Q32: =IF(AND(J32<6000,J32>0),1,IF(AND(J32<12000,J32>=6000),2,IF(AND(J32<=30000,J32>=12000),3))) -> FALSE | T32: =M32+O32+P32+Q32+L32+N32 -> 0 | V32: =IF(U32=$U$2,$V$2,IF(U32=$U$3,$V$3,IF(U32=$U$4,$V$4))) -> FALSE | W32: =-IF(U32=$U$2,$W$2,IF(U32=$U$3,$W$3,IF(U32=$U$4,$W$4))) -> 0 | X32: =S32+T32+W32 -> 0 | Y32: =IF(I32=0,List!$C$5,$C$3) -> 没有忍战，无法分包
C33: 16 | D33: 裤裤旧了 | F33: 545640 | H33: 2739 | M33: =IF(F33>200000,IF(I33>0,ROUND(F33/100000,1)-$W$9,0),0) -> 0 | N33: =IF(H33>2000,IF(I33>0,ROUND(H33/10000,2),0),0)*5 -> 0 | O33: =I33*$W$10 -> 0 | P33: =IF(I33=$W$12,$W$11,0) -> 0 | Q33: =IF(AND(J33<6000,J33>0),1,IF(AND(J33<12000,J33>=6000),2,IF(AND(J33<=30000,J33>=12000),3))) -> FALSE | T33: =M33+O33+P33+Q33+L33+N33 -> 0 | V33: =IF(U33=$U$2,$V$2,IF(U33=$U$3,$V$3,IF(U33=$U$4,$V$4))) -> FALSE | W33: =-IF(U33=$U$2,$W$2,IF(U33=$U$3,$W$3,IF(U33=$U$4,$W$4))) -> 0 | X33: =S33+T33+W33 -> 0 | Y33: =IF(I33=0,List!$C$5,$C$3) -> 没有忍战，无法分包
... C41: 24 | D41: 路明畅 | F41: 507146 | H41: 2578 | M41: =IF(F41>200000,IF(I41>0,ROUND(F41/100000,1)-$W$9,0),0) -> 0 | N41: =IF(H41>2000,IF(I41>0,ROUND(H41/10000,2),0),0)*5 -> 0 | O41: =I41*$W$10 -> 0 | P41: =IF(I41=$W$12,$W$11,0) -> 0 | Q41: =IF(AND(J41<6000,J41>0),1,IF(AND(J41<12000,J41>=6000),2,IF(AND(J41<=30000,J41>=12000),3))) -> FALSE | T41: =M41+O41+P41+Q41+L41+N41 -> 0 | V41: =IF(U41=$U$2,$V$2,IF(U41=$U$3,$V$3,IF(U41=$U$4,$V$4))) -> FALSE | W41: =-IF(U41=$U$2,$W$2,IF(U41=$U$3,$W$3,IF(U41=$U$4,$W$4))) -> 0 | X41: =S41+T41+W41 -> 0 | Y41: =IF(I41=0,List!$C$5,$C$3) -> 没有忍战，无法分包
A42: 全勤 | C42: 25 | D42: 咸鱼 | F42: 501846 | H42: 2214 | I42: 4 | M42: =IF(F42>200000,IF(I42>0,ROUND(F42/100000,1)-$W$9,0),0) -> 2 | N42: =IF(H42>2000,IF(I42>0,ROUND(H42/10000,2),0),0)*5 -> 1.1 | O42: =I42*$W$10 -> 8 | P42: =IF(I42=$W$12,$W$11,0) -> 2 | Q42: =IF(AND(J42<6000,J42>0),1,IF(AND(J42<12000,J42>=6000),2,IF(AND(J42<=30000,J42>=12000),3))) -> FALSE | T42: =M42+O42+P42+Q42+L42+N42 -> 13.1 | V42: =IF(U42=$U$2,$V$2,IF(U42=$U$3,$V$3,IF(U42=$U$4,$V$4))) -> FALSE | W42: =-IF(U42=$U$2,$W$2,IF(U42=$U$3,$W$3,IF(U42=$U$4,$W$4))) -> 0 | X42: =S42+T42+W42 -> 13.1 | Y42: =IF(I42=0,List!$C$5,$C$3) -> 0
C43: 26 | D43: 浪漫本希 | F43: 501068 | H43: 2661 | M43: =IF(F43>200000,IF(I43>0,ROUND(F43/100000,1)-$W$9,0),0) -> 0 | N43: =IF(H43>2000,IF(I43>0,ROUND(H43/10000,2),0),0)*5 -> 0 | O43: =I43*$W$10 -> 0 | P43: =IF(I43=$W$12,$W$11,0) -> 0 | Q43: =IF(AND(J43<6000,J43>0),1,IF(AND(J43<12000,J43>=6000),2,IF(AND(J43<=30000,J43>=12000),3))) -> FALSE | T43: =M43+O43+P43+Q43+L43+N43 -> 0 | V43: =IF(U43=$U$2,$V$2,IF(U43=$U$3,$V$3,IF(U43=$U$4,$V$4))) -> FALSE | W43: =-IF(U43=$U$2,$W$2,IF(U43=$U$3,$W$3,IF(U43=$U$4,$W$4))) -> 0 | X43: =S43+T43+W43 -> 0 | Y43: =IF(I43=0,List!$C$5,$C$3) -> 没有忍战，无法分包
C44: 27 | D44: 奥卡 | F44: 497280 | H44: 2481 | M44: =IF(F44>200000,IF(I44>0,ROUND(F44/100000,1)-$W$9,0),0) -> 0 | N44: =IF(H44>2000,IF(I44>0,ROUND(H44/10000,2),0),0)*5 -> 0 | O44: =I44*$W$10 -> 0 | P44: =IF(I44=$W$12,$W$11,0) -> 0 | Q44: =IF(AND(J44<6000,J44>0),1,IF(AND(J44<12000,J44>=6000),2,IF(AND(J44<=30000,J44>=12000),3))) -> FALSE | T44: =M44+O44+P44+Q44+L44+N44 -> 0 | V44: =IF(U44=$U$2,$V$2,IF(U44=$U$3,$V$3,IF(U44=$U$4,$V$4))) -> FALSE | W44: =-IF(U44=$U$2,$W$2,IF(U44=$U$3,$W$3,IF(U44=$U$4,$W$4))) -> 0 | X44: =S44+T44+W44 -> 0 | Y44: =IF(I44=0,List!$C$5,$C$3) -> 没有忍战，无法分包
C45: 28 | D45: 赌圣 | F45: 490240 | H45: 2330 | M45: =IF(F45>200000,IF(I45>0,ROUND(F45/100000,1)-$W$9,0),0) -> 0 | N45: =IF(H45>2000,IF(I45>0,ROUND(H45/10000,2),0),0)*5 -> 0 | O45: =I45*$W$10 -> 0 | P45: =IF(I45=$W$12,$W$11,0) -> 0 | Q45: =IF(AND(J45<6000,J45>0),1,IF(AND(J45<12000,J45>=6000),2,IF(AND(J45<=30000,J45>=12000),3))) -> FALSE | T45: =M45+O45+P45+Q45+L45+N45 -> 0 | V45: =IF(U45=$U$2,$V$2,IF(U45=$U$3,$V$3,IF(U45=$U$4,$V$4))) -> FALSE | W45: =-IF(U45=$U$2,$W$2,IF(U45=$U$3,$W$3,IF(U45=$U$4,$W$4))) -> 0 | X45: =S45+T45+W45 -> 0 | Y45: =IF(I45=0,List!$C$5,$C$3) -> 没有忍战，无法分包
C46: 29 | D46: 狮子座 | F46: 490023 | H46: 2378 | M46: =IF(F46>200000,IF(I46>0,ROUND(F46/100000,1)-$W$9,0),0) -> 0 | N46: =IF(H46>2000,IF(I46>0,ROUND(H46/10000,2),0),0)*5 -> 0 | O46: =I46*$W$10 -> 0 | P46: =IF(I46=$W$12,$W$11,0) -> 0 | Q46: =IF(AND(J46<6000,J46>0),1,IF(AND(J46<12000,J46>=6000),2,IF(AND(J46<=30000,J46>=12000),3))) -> FALSE | T46: =M46+O46+P46+Q46+L46+N46 -> 0 | V46: =IF(U46=$U$2,$V$2,IF(U46=$U$3,$V$3,IF(U46=$U$4,$V$4))) -> FALSE | W46: =-IF(U46=$U$2,$W$2,IF(U46=$U$3,$W$3,IF(U46=$U$4,$W$4))) -> 0 | X46: =S46+T46+W46 -> 0 | Y46: =IF(I46=0,List!$C$5,$C$3) -> 没有忍战，无法分包
C47: 30 | D47: 鸭咧鸭咧 | F47: 477340 | H47: 2463 | M47: =IF(F47>200000,IF(I47>0,ROUND(F47/100000,1)-$W$9,0),0) -> 0 | N47: =IF(H47>2000,IF(I47>0,ROUND(H47/10000,2),0),0)*5 -> 0 | O47: =I47*$W$10 -> 0 | P47: =IF(I47=$W$12,$W$11,0) -> 0 | Q47: =IF(AND(J47<6000,J47>0),1,IF(AND(J47<12000,J47>=6000),2,IF(AND(J47<=30000,J47>=12000),3))) -> FALSE | T47: =M47+O47+P47+Q47+L47+N47 -> 0 | V47: =IF(U47=$U$2,$V$2,IF(U47=$U$3,$V$3,IF(U47=$U$4,$V$4))) -> FALSE | W47: =-IF(U47=$U$2,$W$2,IF(U47=$U$3,$W$3,IF(U47=$U$4,$W$4))) -> 0 | X47: =S47+T47+W47 -> 0 | Y47: =IF(I47=0,List!$C$5,$C$3) -> 没有忍战，无法分包
C48: 31 | D48: 深田&咏美 | F48: 472926 | H48: 2489 | M48: =IF(F48>200000,IF(I48>0,ROUND(F48/100000,1)-$W$9,0),0) -> 0 | N48: =IF(H48>2000,IF(I48>0,ROUND(H48/10000,2),0),0)*5 -> 0 | O48: =I48*$W$10 -> 0 | P48: =IF(I48=$W$12,$W$11,0) -> 0 | Q48: =IF(AND(J48<6000,J48>0),1,IF(AND(J48<12000,J48>=6000),2,IF(AND(J48<=30000,J48>=12000),3))) -> FALSE | T48: =M48+O48+P48+Q48+L48+N48 -> 0 | V48: =IF(U48=$U$2,$V$2,IF(U48=$U$3,$V$3,IF(U48=$U$4,$V$4))) -> FALSE | W48: =-IF(U48=$U$2,$W$2,IF(U48=$U$3,$W$3,IF(U48=$U$4,$W$4))) -> 0 | X48: =S48+T48+W48 -> 0 | Y48: =IF(I48=0,List!$C$5,$C$3) -> 没有忍战，无法分包
C49: 32 | D49: 大黄蜂 | F49: 471531 | H49: 2437 | M49: =IF(F49>200000,IF(I49>0,ROUND(F49/100000,1)-$W$9,0),0) -> 0 | N49: =IF(H49>2000,IF(I49>0,ROUND(H49/10000,2),0),0)*5 -> 0 | O49: =I49*$W$10 -> 0 | P49: =IF(I49=$W$12,$W$11,0) -> 0 | Q49: =IF(AND(J49<6000,J49>0),1,IF(AND(J49<12000,J49>=6000),2,IF(AND(J49<=30000,J49>=12000),3))) -> FALSE | T49: =M49+O49+P49+Q49+L49+N49 -> 0 | V49: =IF(U49=$U$2,$V$2,IF(U49=$U$3,$V$3,IF(U49=$U$4,$V$4))) -> FALSE | W49: =-IF(U49=$U$2,$W$2,IF(U49=$U$3,$W$3,IF(U49=$U$4,$W$4))) -> 0 | X49: =S49+T49+W49 -> 0 | Y49: =IF(I49=0,List!$C$5,$C$3) -> 没有忍战，无法分包
...

Sheet List
C4: 种类
C5: 没有忍战，无法分包

Sheet 战力表
B1: 战力
A2: 花小鹿 | B2: 677760
A3: 鬼月 | B3: 639288
A4: 蛋总 | B4: 615876
A5: 佐助 | B5: 589370
A6: 智恩 | B6: 583620
A7: 残梦 | B7: 538826
A8: 阿水 | B8: 575751
A9: 霂霖 | B9: 561014
A10: 端弟 | B10: 536955
A11: 欧蜃 | B11: 515757
A12: 醉逍遥 | B12: 514761
A13: 咸鱼 | B13: 501846
... A40: 深田&咏美 | B40: 472926

Sheet 礼包
C2: 礼包积分计算
E3: 单价（元宝） | F3: 198 | G3: 100 | H3: 10
F4: 封印 | G4: 通灵 | H4: 原石 | I4: 小计 | J4: 消耗积分
C5: 跨服 | D5: 传说 | E5: 数量 | F5: 5 | G5: 7 | H5: 20
E6: 元宝 | F6: =F5*$F$3 -> 990 | G6: =G5*$G$3 -> 700 | H6: =H5*$H$3 -> 200 | I6: =SUM(F6:H6) -> 1890 | J6: 19
D7: 英雄 | E7: 数量 | F7: 4 | G7: 6 | H7: 15
E8: 元宝 | F8: =F7*$F$3 -> 792 | G8: =G7*$G$3 -> 600 | H8: =H7*$H$3 -> 150 | I8: =SUM(F8:H8) -> 1542 | J8: 15
D9: 精英 | E9: 数量 | F9: 3 | G9: 5 | H9: 10
E10: 元宝 | F10: =F9*$F$3 -> 594 | G10: =G9*$G$3 -> 500 | H10: =H9*$H$3 -> 100 | I10: =SUM(F10:H10) -> 1194 | J10: 12
C11: 本服 | D11: 传说 | E11: 数量 | F11: 4 | G11: 5
E12: 元宝 | F12: =F11*$F$3 -> 792 | G12: =G11*$G$3 -> 500 | I12: =SUM(F12:H12) -> 1292 | J12: 13
D13: 英雄 | E13: 数量 | F13: 3 | G13: 4
E14: 元宝 | F14: =F13*$F$3 -> 594 | G14: =G13*$G$3 -> 400 | I14: =SUM(F14:H14) -> 994 | J14: 10
D15: 精英 | E15: 数量 | F15: 2 | G15: 3
E16: 元宝 | F16: =F15*$F$3 -> 396 | G16: =G15*$G$3 -> 300 | I16: =SUM(F16:H16) -> 696 | J16: 7
C19: 积分原则
B20: 1 | C20: 参加忍战一次，积2分
B21: 2 | C21: 本周忍战全勤，额外活动2分
B22: 3 | C22: 战力对应积分计算。当前战力，除以10万，取整数，再减去3。举例65万战力，（65/10）四舍五入-3 = 4积分
B23: 4 | C23: 先攻对应积分计算。当前先攻，除以1万，保留两位小数再乘5，举例3300先攻（3300/10000*5）=1.65
C25: 获得礼包时扣除相应的积分。
C26: 发放礼包时不因礼包颜色而有区别，当前分高者优先获得橙色，橙色发放完，发紫色，直至没有礼包。
