Workbook

Sheet 黑名单

Sheet Sep2019
A1: 157区 活动中心 2019 9月 分包贡献明细
AH2: 礼包类别 | AI2: 分数
A3: 日期 | D3: 9月4日 & 9月7日 | I3: 9月11日 & 9月14日 | N3: 9月18日 & 9月21日 | S3: 9月25日 & 9月28日 | X3: 总分 | AD3: 备注 | AH3: 跨服传说礼包6分 | AI3: 6
A4: 编号 | B4: 昵称 | C4: 曾用名 | D4: 周三 | E4: 周六 | G4: 合计 | H4: 分包 | I4: 周三 | J4: 周六 | L4: 合计 | M4: 分包 | N4: 周三 | O4: 周六 | Q4: 合计 | R4: 分包 | S4: 周三 | T4: 周六 | U4: 贡献 | V4: 合计 | W4: 分包 | X4: 参战次数 | Y4: 本月得分 | Z4: 上月得分 | AA4: 礼包耗费 | AB4: 分包总分 | AC4: 轮入下月 | AH4: 跨服英雄礼包5分 | AI4: 5
A5: 1 | B5: Forever`欢喜 | D5: 0 | E5: 0 | G5: =D5+E5 -> 0 | H5: 未分包 | I5: 0 | J5: 0 | L5: =I5+J5 -> 0 | M5: 未分包 | N5: 0 | O5: 0 | Q5: =N5+O5 -> 0 | R5: 未分包 | S5: 0 | T5: 4 | U5: 32000 | V5: =S5+T5 -> 4 | W5: 未分包 | X5: =G5+L5+Q5+V5 -> 4 | Y5: =X5+U5/10000 -> 7.2 | Z5: 0 | AA5: =VLOOKUP(H5,$AH$3:$AI$9,2,FALSE)+VLOOKUP(M5,$AH$3:$AI$9,2,FALSE)+VLOOKUP(R5,$AH$3:$AI$9,2,FALSE)+VLOOKUP(W5,$AH$3:$AI$9,2,FALSE) -> 0 | AB5: =Y5+Z5-AA5 -> 7.2 | AC5: =AB5-MIN($AB$5:$AB$60) -> 7 | AE5: XXX 0战 | AH5: 跨服精英礼包4分 | AI5: 4
A6: 2 | B6: Forever`弟弟 | D6: 0 | E6: 0 | G6: =D6+E6 -> 0 | H6: 未分包 | I6: 0 | J6: 0 | L6: =I6+J6 -> 0 | M6: 未分包 | N6: 0 | O6: 0 | Q6: =N6+O6 -> 0 | R6: 未分包 | S6: 0 | T6: 4 | U6: 33800 | V6: =S6+T6 -> 4 | W6: 未分包 | X6: =G6+L6+Q6+V6 -> 4 | Y6: =X6+U6/10000 -> 7.38 | Z6: 0 | AA6: =VLOOKUP(H6,$AH$3:$AI$9,2,FALSE)+VLOOKUP(M6,$AH$3:$AI$9,2,FALSE)+VLOOKUP(R6,$AH$3:$AI$9,2,FALSE)+VLOOKUP(W6,$AH$3:$AI$9,2,FALSE) -> 0 | AB6: =Y6+Z6-AA6 -> 7.38 | AC6: =AB6-MIN($AB$5:$AB$60) -> 7.18 | AE6: XXX 1战 | AH6: 传说功勋礼包4分 | AI6: 4
A7: 3 | B7: Forever`暴风 | D7: 0 | E7: 0 | G7: =D7+E7 -> 0 | H7: 未分包 | I7: 0 | J7: 0 | L7: =I7+J7 -> 0 | M7: 未分包 | N7: 0 | O7: 0 | Q7: =N7+O7 -> 0 | R7: 未分包 | S7: 0 | T7: 4 | U7: 20000 | V7: =S7+T7 -> 4 | W7: 未分包 | X7: =G7+L7+Q7+V7 -> 4 | Y7: =X7+U7/10000 -> 6 | Z7: 0 | AA7: =VLOOKUP(H7,$AH$3:$AI$9,2,FALSE)+VLOOKUP(M7,$AH$3:$AI$9,2,FALSE)+VLOOKUP(R7,$AH$3:$AI$9,2,FALSE)+VLOOKUP(W7,$AH$3:$AI$9,2,FALSE) -> 0 | AB7: =Y7+Z7-AA7 -> 6 | AC7: =AB7-MIN($AB$5:$AB$60) -> 5.8 | AE7: XXX 2战 | AH7: 英雄功勋礼包3分 | AI7: 3
A8: 4 | B8: Forever`利 | D8: 0 | E8: 0 | G8: =D8+E8 -> 0 | H8: 未分包 | I8: 0 | J8: 0 | L8: =I8+J8 -> 0 | M8: 未分包 | N8: 0 | O8: 0 | Q8: =N8+O8 -> 0 | R8: 未分包 | S8: 0 | T8: 4 | U8: 14000 | V8: =S8+T8 -> 4 | W8: 未分包 | X8: =G8+L8+Q8+V8 -> 4 | Y8: =X8+U8/10000 -> 5.4 | Z8: 0 | AA8: =VLOOKUP(H8,$AH$3:$AI$9,2,FALSE)+VLOOKUP(M8,$AH$3:$AI$9,2,FALSE)+VLOOKUP(R8,$AH$3:$AI$9,2,FALSE)+VLOOKUP(W8,$AH$3:$AI$9,2,FALSE) -> 0 | AB8: =Y8+Z8-AA8 -> 5.4 | AC8: =AB8-MIN($AB$5:$AB$60) -> 5.2 | AE8: XXX 3战 | AH8: 精英功勋礼包2分 | AI8: 2
A9: 5 | B9: Forever`輪回 | D9: 0 | E9: 0 | G9: =D9+E9 -> 0 | H9: 未分包 | I9: 0 | J9: 0 | L9: =I9+J9 -> 0 | M9: 未分包 | N9: 0 | O9: 0 | Q9: =N9+O9 -> 0 | R9: 未分包 | S9: 0 | T9: 4 | U9: 14000 | V9: =S9+T9 -> 4 | W9: 未分包 | X9: =G9+L9+Q9+V9 -> 4 | Y9: =X9+U9/10000 -> 5.4 | Z9: 0 | AA9: =VLOOKUP(H9,$AH$3:$AI$9,2,FALSE)+VLOOKUP(M9,$AH$3:$AI$9,2,FALSE)+VLOOKUP(R9,$AH$3:$AI$9,2,FALSE)+VLOOKUP(W9,$AH$3:$AI$9,2,FALSE) -> 0 | AB9: =Y9+Z9-AA9 -> 5.4 | AC9: =AB9-MIN($AB$5:$AB$60) -> 5.2 | AE9: XXX 4战 | AH9: 未分包 | AI9: 0
A10: 6 | B10: Forever`等待 | D10: 0 | E10: 0 | G10: =D10+E10 -> 0 | H10: 未分包 | I10: 0 | J10: 0 | L10: =I10+J10 -> 0 | M10: 未分包 | N10: 0 | O10: 0 | Q10: =N10+O10 -> 0 | R10: 未分包 | S10: 0 | T10: 4 | U10: 13800 | V10: =S10+T10 -> 4 | W10: 未分包 | X10: =G10+L10+Q10+V10 -> 4 | Y10: =X10+U10/10000 -> 5.38 | Z10: 0 | AA10: =VLOOKUP(H10,$AH$3:$AI$9,2,FALSE)+VLOOKUP(M10,$AH$3:$AI$9,2,FALSE)+VLOOKUP(R10,$AH$3:$AI$9,2,FALSE)+VLOOKUP(W10,$AH$3:$AI$9,2,FALSE) -> 0 | AB10: =Y10+Z10-AA10 -> 5.38 | AC10: =AB10-MIN($AB$5:$AB$60) -> 5.18 | AE10: XXX 5战
A11: 7 | B11: Forever`瓶子 | D11: 0 | E11: 0 | G11: =D11+E11 -> 0 | H11: 未分包 | I11: 0 | J11: 0 | L11: =I11+J11 -> 0 | M11: 未分包 | N11: 0 | O11: 0 | Q11: =N11+O11 -> 0 | R11: 未分包 | S11: 0 | T11: 4 | U11: 13000 | V11: =S11+T11 -> 4 | W11: 未分包 | X11: =G11+L11+Q11+V11 -> 4 | Y11: =X11+U11/10000 -> 5.3 | Z11: 0 | AA11: =VLOOKUP(H11,$AH$3:$AI$9,2,FALSE)+VLOOKUP(M11,$AH$3:$AI$9,2,FALSE)+VLOOKUP(R11,$AH$3:$AI$9,2,FALSE)+VLOOKUP(W11,$AH$3:$AI$9,2,FALSE) -> 0 | AB11: =Y11+Z11-AA11 -> 5.3 | AC11: =AB11-MIN($AB$5:$AB$60) -> 5.1 | AE11: XXX 6战
A12: 8 | B12: Forever`了佳 | D12: 0 | E12: 0 | G12: =D12+E12 -> 0 | H12: 未分包 | I12: 0 | J12: 0 | L12: =I12+J12 -> 0 | M12: 未分包 | N12: 0 | O12: 0 | Q12: =N12+O12 -> 0 | R12: 未分包 | S12: 0 | T12: 4 | U12: 10200 | V12: =S12+T12 -> 4 | W12: 未分包 | X12: =G12+L12+Q12+V12 -> 4 | Y12: =X12+U12/10000 -> 5.02 | Z12: 0 | AA12: =VLOOKUP(H12,$AH$3:$AI$9,2,FALSE)+VLOOKUP(M12,$AH$3:$AI$9,2,FALSE)+VLOOKUP(R12,$AH$3:$AI$9,2,FALSE)+VLOOKUP(W12,$AH$3:$AI$9,2,FALSE) -> 0 | AB12: =Y12+Z12-AA12 -> 5.02 | AC12: =AB12-MIN($AB$5:$AB$60) -> 4.82 | AE12: XXX 7战
A13: 9 | B13: Forever`释空 | D13: 0 | E13: 0 | G13: =D13+E13 -> 0 | H13: 未分包 | I13: 0 | J13: 0 | L13: =I13+J13 -> 0 | M13: 未分包 | N13: 0 | O13: 0 | Q13: =N13+O13 -> 0 | R13: 未分包 | S13: 0 | T13: 3 | U13: 32000 | V13: =S13+T13 -> 3 | W13: 未分包 | X13: =G13+L13+Q13+V13 -> 3 | Y13: =X13+U13/10000 -> 6.2 | Z13: 0 | AA13: =VLOOKUP(H13,$AH$3:$AI$9,2,FALSE)+VLOOKUP(M13,$AH$3:$AI$9,2,FALSE)+VLOOKUP(R13,$AH$3:$AI$9,2,FALSE)+VLOOKUP(W13,$AH$3:$AI$9,2,FALSE) -> 0 | AB13: =Y13+Z13-AA13 -> 6.2 | AC13: =AB13-MIN($AB$5:$AB$60) -> 6 | AE13: XXX 8战
A14: 10 | B14: Forever`随风 | D14: 0 | E14: 0 | G14: =D14+E14 -> 0 | H14: 未分包 | I14: 0 | J14: 0 | L14: =I14+J14 -> 0 | M14: 未分包 | N14: 0 | O14: 0 | Q14: =N14+O14 -> 0 | R14: 未分包 | S14: 0 | T14: 3 | U14: 31600 | V14: =S14+T14 -> 3 | W14: 未分包 | X14: =G14+L14+Q14+V14 -> 3 | Y14: =X14+U14/10000 -> 6.16 | Z14: 0 | AA14: =VLOOKUP(H14,$AH$3:$AI$9,2,FALSE)+VLOOKUP(M14,$AH$3:$AI$9,2,FALSE)+VLOOKUP(R14,$AH$3:$AI$9,2,FALSE)+VLOOKUP(W14,$AH$3:$AI$9,2,FALSE) -> 0 | AB14: =Y14+Z14-AA14 -> 6.16 | AC14: =AB14-MIN($AB$5:$AB$60) -> 5.96 | AE14: XXX 9战
A15: 11 | B15: Forever`白泽 | D15: 0 | E15: 0 | G15: =D15+E15 -> 0 | H15: 未分包 | I15: 0 | J15: 0 | L15: =I15+J15 -> 0 | M15: 未分包 | N15: 0 | O15: 0 | Q15: =N15+O15 -> 0 | R15: 未分包 | S15: 0 | T15: 3 | U15: 35000 | V15: =S15+T15 -> 3 | W15: 未分包 | X15: =G15+L15+Q15+V15 -> 3 | Y15: =X15+U15/10000 -> 6.5 | Z15: 0 | AA15: =VLOOKUP(H15,$AH$3:$AI$9,2,FALSE)+VLOOKUP(M15,$AH$3:$AI$9,2,FALSE)+VLOOKUP(R15,$AH$3:$AI$9,2,FALSE)+VLOOKUP(W15,$AH$3:$AI$9,2,FALSE) -> 0 | AB15: =Y15+Z15-AA15 -> 6.5 | AC15: =AB15-MIN($AB$5:$AB$60) -> 6.3 | AE15: XXX 10战
A16: 12 | B16: Forever`仙尊 | D16: 0 | E16: 0 | G16: =D16+E16 -> 0 | H16: 未分包 | I16: 0 | J16: 0 | L16: =I16+J16 -> 0 | M16: 未分包 | N16: 0 | O16: 0 | Q16: =N16+O16 -> 0 | R16: 未分包 | S16: 0 | T16: 3 | U16: 29000 | V16: =S16+T16 -> 3 | W16: 未分包 | X16: =G16+L16+Q16+V16 -> 3 | Y16: =X16+U16/10000 -> 5.9 | Z16: 0 | AA16: =VLOOKUP(H16,$AH$3:$AI$9,2,FALSE)+VLOOKUP(M16,$AH$3:$AI$9,2,FALSE)+VLOOKUP(R16,$AH$3:$AI$9,2,FALSE)+VLOOKUP(W16,$AH$3:$AI$9,2,FALSE) -> 0 | AB16: =Y16+Z16-AA16 -> 5.9 | AC16: =AB16-MIN($AB$5:$AB$60) -> 5.7 | AE16: XXX 11战
A17: 13 | B17: Forever`雷柱 | D17: 0 | E17: 0 | G17: =D17+E17 -> 0 | H17: 未分包 | I17: 0 | J17: 0 | L17: =I17+J17 -> 0 | M17: 未分包 | N17: 0 | O17: 0 | Q17: =N17+O17 -> 0 | R17: 未分包 | S17: 0 | T17: 3 | U17: 23000 | V17: =S17+T17 -> 3 | W17: 未分包 | X17: =G17+L17+Q17+V17 -> 3 | Y17: =X17+U17/10000 -> 5.3 | Z17: 0 | AA17: =VLOOKUP(H17,$AH$3:$AI$9,2,FALSE)+VLOOKUP(M17,$AH$3:$AI$9,2,FALSE)+VLOOKUP(R17,$AH$3:$AI$9,2,FALSE)+VLOOKUP(W17,$AH$3:$AI$9,2,FALSE) -> 0 | AB17: =Y17+Z17-AA17 -> 5.3 | AC17: =AB17-MIN($AB$5:$AB$60) -> 5.1 | AE17: XXX 12战
A18: 14 | B18: Forever`初见 | D18: 0 | E18: 0 | G18: =D18+E18 -> 0 | H18: 未分包 | I18: 0 | J18: 0 | L18: =I18+J18 -> 0 | M18: 未分包 | N18: 0 | O18: 0 | Q18: =N18+O18 -> 0 | R18: 未分包 | S18: 0 | T18: 3 | U18: 22200 | V18: =S18+T18 -> 3 | W18: 未分包 | X18: =G18+L18+Q18+V18 -> 3 | Y18: =X18+U18/10000 -> 5.22 | Z18: 0 | AA18: =VLOOKUP(H18,$AH$3:$AI$9,2,FALSE)+VLOOKUP(M18,$AH$3:$AI$9,2,FALSE)+VLOOKUP(R18,$AH$3:$AI$9,2,FALSE)+VLOOKUP(W18,$AH$3:$AI$9,2,FALSE) -> 0 | AB18: =Y18+Z18-AA18 -> 5.22 | AC18: =AB18-MIN($AB$5:$AB$60) -> 5.02 | AE18: XXX 13战
A19: 15 | B19: Forever`Gai | D19: 0 | E19: 0 | G19: =D19+E19 -> 0 | H19: 未分包 | I19: 0 | J19: 0 | L19: =I19+J19 -> 0 | M19: 未分包 | N19: 0 | O19: 0 | Q19: =N19+O19 -> 0 | R19: 未分包 | S19: 0 | T19: 3 | U19: 19200 | V19: =S19+T19 -> 3 | W19: 未分包 | X19: =G19+L19+Q19+V19 -> 3 | Y19: =X19+U19/10000 -> 4.92 | Z19: 0 | AA19: =VLOOKUP(H19,$AH$3:$AI$9,2,FALSE)+VLOOKUP(M19,$AH$3:$AI$9,2,FALSE)+VLOOKUP(R19,$AH$3:$AI$9,2,FALSE)+VLOOKUP(W19,$AH$3:$AI$9,2,FALSE) -> 0 | AB19: =Y19+Z19-AA19 -> 4.92 | AC19: =AB19-MIN($AB$5:$AB$60) -> 4.72 | AE19: XXX 14战
A20: 16 | B20: Forever`啾啾 | D20: 0 | E20: 0 | G20: =D20+E20 -> 0 | H20: 未分包 | I20: 0 | J20: 0 | L20: =I20+J20 -> 0 | M20: 未分包 | N20: 0 | O20: 0 | Q20: =N20+O20 -> 0 | R20: 未分包 | S20: 0 | T20: 3 | U20: 17000 | V20: =S20+T20 -> 3 | W20: 未分包 | X20: =G20+L20+Q20+V20 -> 3 | Y20: =X20+U20/10000 -> 4.7 | Z20: 0 | AA20: =VLOOKUP(H20,$AH$3:$AI$9,2,FALSE)+VLOOKUP(M20,$AH$3:$AI$9,2,FALSE)+VLOOKUP(R20,$AH$3:$AI$9,2,FALSE)+VLOOKUP(W20,$AH$3:$AI$9,2,FALSE) -> 0 | AB20: =Y20+Z20-AA20 -> 4.7 | AC20: =AB20-MIN($AB$5:$AB$60) -> 4.5 | AE20: XXX 15战
A21: 17 | B21: Forever`珞珞 | D21: 0 | E21: 0 | G21: =D21+E21 -> 0 | H21: 未分包 | I21: 0 | J21: 0 | L21: =I21+J21 -> 0 | M21: 未分包 | N21: 0 | O21: 0 | Q21: =N21+O21 -> 0 | R21: 未分包 | S21: 0 | T21: 3 | U21: 14000 | V21: =S21+T21 -> 3 | W21: 未分包 | X21: =G21+L21+Q21+V21 -> 3 | Y21: =X21+U21/10000 -> 4.4 | Z21: 0 | AA21: =VLOOKUP(H21,$AH$3:$AI$9,2,FALSE)+VLOOKUP(M21,$AH$3:$AI$9,2,FALSE)+VLOOKUP(R21,$AH$3:$AI$9,2,FALSE)+VLOOKUP(W21,$AH$3:$AI$9,2,FALSE) -> 0 | AB21: =Y21+Z21-AA21 -> 4.4 | AC21: =AB21-MIN($AB$5:$AB$60) -> 4.2 | AE21: XXX 16战
A22: 18 | B22: 万事如意 | D22: 0 | E22: 0 | G22: =D22+E22 -> 0 | H22: 未分包 | I22: 0 | J22: 0 | L22: =I22+J22 -> 0 | M22: 未分包 | N22: 0 | O22: 0 | Q22: =N22+O22 -> 0 | R22: 未分包 | S22: 0 | T22: 3 | U22: 14000 | V22: =S22+T22 -> 3 | W22: 未分包 | X22: =G22+L22+Q22+V22 -> 3 | Y22: =X22+U22/10000 -> 4.4 | Z22: 0 | AA22: =VLOOKUP(H22,$AH$3:$AI$9,2,FALSE)+VLOOKUP(M22,$AH$3:$AI$9,2,FALSE)+VLOOKUP(R22,$AH$3:$AI$9,2,FALSE)+VLOOKUP(W22,$AH$3:$AI$9,2,FALSE) -> 0 | AB22: =Y22+Z22-AA22 -> 4.4 | AC22: =AB22-MIN($AB$5:$AB$60) -> 4.2
A23: 19 | B23: 林一 | D23: 0 | E23: 0 | G23: =D23+E23 -> 0 | H23: 未分包 | I23: 0 | J23: 0 | L23: =I23+J23 -> 0 | M23: 未分包 | N23: 0 | O23: 0 | Q23: =N23+O23 -> 0 | R23: 未分包 | S23: 0 | T23: 3 | U23: 12000 | V23: =S23+T23 -> 3 | W23: 未分包 | X23: =G23+L23+Q23+V23 -> 3 | Y23: =X23+U23/10000 -> 4.2 | Z23: 0 | AA23: =VLOOKUP(H23,$AH$3:$AI$9,2,FALSE)+VLOOKUP(M23,$AH$3:$AI$9,2,FALSE)+VLOOKUP(R23,$AH$3:$AI$9,2,FALSE)+VLOOKUP(W23,$AH$3:$AI$9,2,FALSE) -> 0 | AB23: =Y23+Z23-AA23 -> 4.2 | AC23: =AB23-MIN($AB$5:$AB$60) -> 4 | AE23: 精英功勋礼包2分
A24: 20 | B24: Forever`孤王 | D24: 0 | E24: 0 | G24: =D24+E24 -> 0 | H24: 未分包 | I24: 0 | J24: 0 | L24: =I24+J24 -> 0 | M24: 未分包 | N24: 0 | O24: 0 | Q24: =N24+O24 -> 0 | R24: 未分包 | S24: 0 | T24: 2 | U24: 31000 | V24: =S24+T24 -> 2 | W24: 未分包 | X24: =G24+L24+Q24+V24 -> 2 | Y24: =X24+U24/10000 -> 5.1 | Z24: 0 | AA24: =VLOOKUP(H24,$AH$3:$AI$9,2,FALSE)+VLOOKUP(M24,$AH$3:$AI$9,2,FALSE)+VLOOKUP(R24,$AH$3:$AI$9,2,FALSE)+VLOOKUP(W24,$AH$3:$AI$9,2,FALSE) -> 0 | AB24: =Y24+Z24-AA24 -> 5.1 | AC24: =AB24-MIN($AB$5:$AB$60) -> 4.9 | AE24: 英雄功勋礼包3分
A25: 21 | B25: Forever`里瞳 | D25: 0 | E25: 0 | G25: =D25+E25 -> 0 | H25: 未分包 | I25: 0 | J25: 0 | L25: =I25+J25 -> 0 | M25: 未分包 | N25: 0 | O25: 0 | Q25: =N25+O25 -> 0 | R25: 未分包 | S25: 0 | T25: 2 | U25: 30200 | V25: =S25+T25 -> 2 | W25: 未分包 | X25: =G25+L25+Q25+V25 -> 2 | Y25: =X25+U25/10000 -> 5.02 | Z25: 0 | AA25: =VLOOKUP(H25,$AH$3:$AI$9,2,FALSE)+VLOOKUP(M25,$AH$3:$AI$9,2,FALSE)+VLOOKUP(R25,$AH$3:$AI$9,2,FALSE)+VLOOKUP(W25,$AH$3:$AI$9,2,FALSE) -> 0 | AB25: =Y25+Z25-AA25 -> 5.02 | AC25: =AB25-MIN($AB$5:$AB$60) -> 4.82 | AE25: 传说功勋礼包4分
A26: 22 | B26: Forever`天刀 | D26: 0 | E26: 0 | G26: =D26+E26 -> 0 | H26: 未分包 | I26: 0 | J26: 0 | L26: =I26+J26 -> 0 | M26: 未分包 | N26: 0 | O26: 0 | Q26: =N26+O26 -> 0 | R26: 未分包 | S26: 0 | T26: 1 | U26: 14000 | V26: =S26+T26 -> 1 | W26: 未分包 | X26: =G26+L26+Q26+V26 -> 1 | Y26: =X26+U26/10000 -> 2.4 | Z26: 0 | AA26: =VLOOKUP(H26,$AH$3:$AI$9,2,FALSE)+VLOOKUP(M26,$AH$3:$AI$9,2,FALSE)+VLOOKUP(R26,$AH$3:$AI$9,2,FALSE)+VLOOKUP(W26,$AH$3:$AI$9,2,FALSE) -> 0 | AB26: =Y26+Z26-AA26 -> 2.4 | AC26: =AB26-MIN($AB$5:$AB$60) -> 2.2 | AE26: 跨服精英礼包4分
A27: 23 | B27: Forever`三傻 | D27: 0 | E27: 0 | G27: =D27+E27 -> 0 | H27: 未分包 | I27: 0 | J27: 0 | L27: =I27+J27 -> 0 | M27: 未分包 | N27: 0 | O27: 0 | Q27: =N27+O27 -> 0 | R27: 未分包 | S27: 0 | T27: 2 | U27: 30000 | V27: =S27+T27 -> 2 | W27: 未分包 | X27: =G27+L27+Q27+V27 -> 2 | Y27: =X27+U27/10000 -> 5 | Z27: 0 | AA27: =VLOOKUP(H27,$AH$3:$AI$9,2,FALSE)+VLOOKUP(M27,$AH$3:$AI$9,2,FALSE)+VLOOKUP(R27,$AH$3:$AI$9,2,FALSE)+VLOOKUP(W27,$AH$3:$AI$9,2,FALSE) -> 0 | AB27: =Y27+Z27-AA27 -> 5 | AC27: =AB27-MIN($AB$5:$AB$60) -> 4.8 | AE27: 跨服英雄礼包5分
A28: 24 | B28: Forever`孤心 | D28: 0 | E28: 0 | G28: =D28+E28 -> 0 | H28: 未分包 | I28: 0 | J28: 0 | L28: =I28+J28 -> 0 | M28: 未分包 | N28: 0 | O28: 0 | Q28: =N28+O28 -> 0 | R28: 未分包 | S28: 0 | T28: 2 | U28: 15000 | V28: =S28+T28 -> 2 | W28: 未分包 | X28: =G28+L28+Q28+V28 -> 2 | Y28: =X28+U28/10000 -> 3.5 | Z28: 0 | AA28: =VLOOKUP(H28,$AH$3:$AI$9,2,FALSE)+VLOOKUP(M28,$AH$3:$AI$9,2,FALSE)+VLOOKUP(R28,$AH$3:$AI$9,2,FALSE)+VLOOKUP(W28,$AH$3:$AI$9,2,FALSE) -> 0 | AB28: =Y28+Z28-AA28 -> 3.5 | AC28: =AB28-MIN($AB$5:$AB$60) -> 3.3 | AE28: 跨服传说礼包6分
A29: 25 | B29: Forever`天刀 | D29: 0 | E29: 0 | G29: =D29+E29 -> 0 | H29: 未分包 | I29: 0 | J29: 0 | L29: =I29+J29 -> 0 | M29: 未分包 | N29: 0 | O29: 0 | Q29: =N29+O29 -> 0 | R29: 未分包 | S29: 0 | T29: 1 | U29: 14000 | V29: =S29+T29 -> 1 | W29: 未分包 | X29: =G29+L29+Q29+V29 -> 1 | Y29: =X29+U29/10000 -> 2.4 | Z29: 0 | AA29: =VLOOKUP(H29,$AH$3:$AI$9,2,FALSE)+VLOOKUP(M29,$AH$3:$AI$9,2,FALSE)+VLOOKUP(R29,$AH$3:$AI$9,2,FALSE)+VLOOKUP(W29,$AH$3:$AI$9,2,FALSE) -> 0 | AB29: =Y29+Z29-AA29 -> 2.4 | AC29: =AB29-MIN($AB$5:$AB$60) -> 2.2
A30: 26 | B30: Forever`二傻 | D30: 0 | E30: 0 | G30: =D30+E30 -> 0 | H30: 未分包 | I30: 0 | J30: 0 | L30: =I30+J30 -> 0 | M30: 未分包 | N30: 0 | O30: 0 | Q30: =N30+O30 -> 0 | R30: 未分包 | S30: 0 | T30: 1 | U30: 11000 | V30: =S30+T30 -> 1 | W30: 未分包 | X30: =G30+L30+Q30+V30 -> 1 | Y30: =X30+U30/10000 -> 2.1 | Z30: 0 | AA30: =VLOOKUP(H30,$AH$3:$AI$9,2,FALSE)+VLOOKUP(M30,$AH$3:$AI$9,2,FALSE)+VLOOKUP(R30,$AH$3:$AI$9,2,FALSE)+VLOOKUP(W30,$AH$3:$AI$9,2,FALSE) -> 0 | AB30: =Y30+Z30-AA30 -> 2.1 | AC30: =AB30-MIN($AB$5:$AB$60) -> 1.9
A31: 27 | B31: Forever`為你 | D31: 0 | E31: 0 | G31: =D31+E31 -> 0 | H31: 未分包 | I31: 0 | J31: 0 | L31: =I31+J31 -> 0 | M31: 未分包 | N31: 0 | O31: 0 | Q31: =N31+O31 -> 0 | R31: 未分包 | S31: 0 | T31: 0 | U31: 34000 | V31: =S31+T31 -> 0 | W31: 未分包 | X31: =G31+L31+Q31+V31 -> 0 | Y31: =X31+U31/10000 -> 3.4 | Z31: 0 | AA31: =VLOOKUP(H31,$AH$3:$AI$9,2,FALSE)+VLOOKUP(M31,$AH$3:$AI$9,2,FALSE)+VLOOKUP(R31,$AH$3:$AI$9,2,FALSE)+VLOOKUP(W31,$AH$3:$AI$9,2,FALSE) -> 0 | AB31: =Y31+Z31-AA31 -> 3.4 | AC31: =AB31-MIN($AB$5:$AB$60) -> 3.2
A32: 28 | B32: Forever`鹿丸 | D32: 0 | E32: 0 | G32: =D32+E32 -> 0 | H32: 未分包 | I32: 0 | J32: 0 | L32: =I32+J32 -> 0 | M32: 未分包 | N32: 0 | O32: 0 | Q32: =N32+O32 -> 0 | R32: 未分包 | S32: 0 | T32: 0 | U32: 22400 | V32: =S32+T32 -> 0 | W32: 未分包 | X32: =G32+L32+Q32+V32 -> 0 | Y32: =X32+U32/10000 -> 2.24 | Z32: 0 | AA32: =VLOOKUP(H32,$AH$3:$AI$9,2,FALSE)+VLOOKUP(M32,$AH$3:$AI$9,2,FALSE)+VLOOKUP(R32,$AH$3:$AI$9,2,FALSE)+VLOOKUP(W32,$AH$3:$AI$9,2,FALSE) -> 0 | AB32: =Y32+Z32-AA32 -> 2.24 | AC32: =AB32-MIN($AB$5:$AB$60) -> 2.04
A33: 29 | B33: Forever`别吵 | D33: 0 | E33: 0 | G33: =D33+E33 -> 0 | H33: 未分包 | I33: 0 | J33: 0 | L33: =I33+J33 -> 0 | M33: 未分包 | N33: 0 | O33: 0 | Q33: =N33+O33 -> 0 | R33: 未分包 | S33: 0 | T33: 0 | U33: 11600 | V33: =S33+T33 -> 0 | W33: 未分包 | X33: =G33+L33+Q33+V33 -> 0 | Y33: =X33+U33/10000 -> 1.16 | Z33: 0 | AA33: =VLOOKUP(H33,$AH$3:$AI$9,2,FALSE)+VLOOKUP(M33,$AH$3:$AI$9,2,FALSE)+VLOOKUP(R33,$AH$3:$AI$9,2,FALSE)+VLOOKUP(W33,$AH$3:$AI$9,2,FALSE) -> 0 | AB33: =Y33+Z33-AA33 -> 1.16 | AC33: =AB33-MIN($AB$5:$AB$60) -> 0.96
A34: 30 | B34: 晨曦心 | D34: 0 | E34: 0 | G34: =D34+E34 -> 0 | H34: 未分包 | I34: 0 | J34: 0 | L34: =I34+J34 -> 0 | M34: 未分包 | N34: 0 | O34: 0 | Q34: =N34+O34 -> 0 | R34: 未分包 | S34: 0 | T34: 0 | U34: 10000 | V34: =S34+T34 -> 0 | W34: 未分包 | X34: =G34+L34+Q34+V34 -> 0 | Y34: =X34+U34/10000 -> 1 | Z34: 0 | AA34: =VLOOKUP(H34,$AH$3:$AI$9,2,FALSE)+VLOOKUP(M34,$AH$3:$AI$9,2,FALSE)+VLOOKUP(R34,$AH$3:$AI$9,2,FALSE)+VLOOKUP(W34,$AH$3:$AI$9,2,FALSE) -> 0 | AB34: =Y34+Z34-AA34 -> 1 | AC34: =AB34-MIN($AB$5:$AB$60) -> 0.8
A35: 31 | B35: Nobita | D35: 0 | E35: 0 | G35: =D35+E35 -> 0 | H35: 未分包 | I35: 0 | J35: 0 | L35: =I35+J35 -> 0 | M35: 未分包 | N35: 0 | O35: 0 | Q35: =N35+O35 -> 0 | R35: 未分包 | S35: 0 | T35: 0 | U35: 10000 | V35: =S35+T35 -> 0 | W35: 未分包 | X35: =G35+L35+Q35+V35 -> 0 | Y35: =X35+U35/10000 -> 1 | Z35: 0 | AA35: =VLOOKUP(H35,$AH$3:$AI$9,2,FALSE)+VLOOKUP(M35,$AH$3:$AI$9,2,FALSE)+VLOOKUP(R35,$AH$3:$AI$9,2,FALSE)+VLOOKUP(W35,$AH$3:$AI$9,2,FALSE) -> 0 | AB35: =Y35+Z35-AA35 -> 1 | AC35: =AB35-MIN($AB$5:$AB$60) -> 0.8
A36: 32 | B36: 清风术语 | D36: 0 | E36: 0 | G36: =D36+E36 -> 0 | H36: 未分包 | I36: 0 | J36: 0 | L36: =I36+J36 -> 0 | M36: 未分包 | N36: 0 | O36: 0 | Q36: =N36+O36 -> 0 | R36: 未分包 | S36: 0 | T36: 0 | U36: 9200 | V36: =S36+T36 -> 0 | W36: 未分包 | X36: =G36+L36+Q36+V36 -> 0 | Y36: =X36+U36/10000 -> 0.92 | Z36: 0 | AA36: =VLOOKUP(H36,$AH$3:$AI$9,2,FALSE)+VLOOKUP(M36,$AH$3:$AI$9,2,FALSE)+VLOOKUP(R36,$AH$3:$AI$9,2,FALSE)+VLOOKUP(W36,$AH$3:$AI$9,2,FALSE) -> 0 | AB36: =Y36+Z36-AA36 -> 0.92 | AC36: =AB36-MIN($AB$5:$AB$60) -> 0.72
A37: 33 | B37: Forever`大傻 | D37: 0 | E37: 0 | G37: =D37+E37 -> 0 | H37: 未分包 | I37: 0 | J37: 0 | L37: =I37+J37 -> 0 | M37: 未分包 | N37: 0 | O37: 0 | Q37: =N37+O37 -> 0 | R37: 未分包 | S37: 0 | T37: 0 | U37: 7000 | V37: =S37+T37 -> 0 | W37: 未分包 | X37: =G37+L37+Q37+V37 -> 0 | Y37: =X37+U37/10000 -> 0.7 | Z37: 0 | AA37: =VLOOKUP(H37,$AH$3:$AI$9,2,FALSE)+VLOOKUP(M37,$AH$3:$AI$9,2,FALSE)+VLOOKUP(R37,$AH$3:$AI$9,2,FALSE)+VLOOKUP(W37,$AH$3:$AI$9,2,FALSE) -> 0 | AB37: =Y37+Z37-AA37 -> 0.7 | AC37: =AB37-MIN($AB$5:$AB$60) -> 0.5
A38: 34 | B38: Forever`劳模 | D38: 0 | E38: 0 | G38: =D38+E38 -> 0 | H38: 未分包 | I38: 0 | J38: 0 | L38: =I38+J38 -> 0 | M38: 未分包 | N38: 0 | O38: 0 | Q38: =N38+O38 -> 0 | R38: 未分包 | S38: 0 | T38: 0 | U38: 6000 | V38: =S38+T38 -> 0 | W38: 未分包 | X38: =G38+L38+Q38+V38 -> 0 | Y38: =X38+U38/10000 -> 0.6 | Z38: 0 | AA38: =VLOOKUP(H38,$AH$3:$AI$9,2,FALSE)+VLOOKUP(M38,$AH$3:$AI$9,2,FALSE)+VLOOKUP(R38,$AH$3:$AI$9,2,FALSE)+VLOOKUP(W38,$AH$3:$AI$9,2,FALSE) -> 0 | AB38: =Y38+Z38-AA38 -> 0.6 | AC38: =AB38-MIN($AB$5:$AB$60) -> 0.4
A39: 35 | B39: 神罗天征 | D39: 0 | E39: 0 | G39: =D39+E39 -> 0 | H39: 未分包 | I39: 0 | J39: 0 | L39: =I39+J39 -> 0 | M39: 未分包 | N39: 0 | O39: 0 | Q39: =N39+O39 -> 0 | R39: 未分包 | S39: 0 | T39: 0 | U39: 4000 | V39: =S39+T39 -> 0 | W39: 未分包 | X39: =G39+L39+Q39+V39 -> 0 | Y39: =X39+U39/10000 -> 0.4 | Z39: 0 | AA39: =VLOOKUP(H39,$AH$3:$AI$9,2,FALSE)+VLOOKUP(M39,$AH$3:$AI$9,2,FALSE)+VLOOKUP(R39,$AH$3:$AI$9,2,FALSE)+VLOOKUP(W39,$AH$3:$AI$9,2,FALSE) -> 0 | AB39: =Y39+Z39-AA39 -> 0.4 | AC39: =AB39-MIN($AB$5:$AB$60) -> 0.2
A40: 36 | B40: 卟离卟弃 | D40: 0 | E40: 0 | G40: =D40+E40 -> 0 | H40: 未分包 | I40: 0 | J40: 0 | L40: =I40+J40 -> 0 | M40: 未分包 | N40: 0 | O40: 0 | Q40: =N40+O40 -> 0 | R40: 未分包 | S40: 0 | T40: 0 | U40: 4000 | V40: =S40+T40 -> 0 | W40: 未分包 | X40: =G40+L40+Q40+V40 -> 0 | Y40: =X40+U40/10000 -> 0.4 | Z40: 0 | AA40: =VLOOKUP(H40,$AH$3:$AI$9,2,FALSE)+VLOOKUP(M40,$AH$3:$AI$9,2,FALSE)+VLOOKUP(R40,$AH$3:$AI$9,2,FALSE)+VLOOKUP(W40,$AH$3:$AI$9,2,FALSE) -> 0 | AB40: =Y40+Z40-AA40 -> 0.4 | AC40: =AB40-MIN($AB$5:$AB$60) -> 0.2
...

Sheet Oct2019
A1: 157区 活动中心 分包贡献明细 By:Forever`二傻 | AF1: 人数 | AG1: 56
AF2: 礼包类别 | AG2: 消耗分数 | AH2: 封印卷個數 | AI2: 通靈卷個數 | AJ2: 價值（金幣）
A3: 日期 | D3: 10月2日 & 10月5日 | I3: 10月9日 & 10月12日 | N3: 10月16日 & 10月19日 | S3: 10月23日 & 10月26日 | X3: 总分 | AE3: 备注 | AF3: 跨服传说礼包 | AG3: =AJ3/200 -> 8.5 | AH3: 5 | AI3: 7 | AJ3: =AH3*200+AI3*100 -> 1700
A4: 编号 | B4: 昵称 | C4: 曾用名 | D4: 周三 | E4: 周六 | F4: 贡献 | G4: 参战 | H4: 分包 | I4: 周三 | J4: 周六 | K4: 贡献 | L4: 参战 | M4: 分包 | N4: 周三 | O4: 周六 | P4: 贡献 | Q4: 参战 | R4: 分包 | S4: 周三 | T4: 周六 | U4: 贡献 | V4: 参战 | W4: 分包 | X4: 参战次数 | Y4: 本月得分 | Z4: 上月得分 | AA4: 礼包耗费 | AB4: 分包总分 | AC4: 新人战力排名 | AD4: 新人初始分 | AF4: 跨服英雄礼包 | AG4: =AJ4/200 -> 7 | AH4: 4 | AI4: 6 | AJ4: =AH4*200+AI4*100 -> 1400
A5: 57 | B5: Forever`习惯 | C5: 习惯 | D5: 0 | E5: 0 | F5: 12000 | G5: 3 | H5: 未分包 | I5: 0 | J5: 4 | K5: 12000 | L5: =I5+J5 -> 4 | M5: 未分包 | N5: 0 | O5: 3 | P5: 12000 | Q5: =N5+O5 -> 3 | R5: 未分包 | S5: 0 | T5: 0 | U5: 0 | V5: =S5+T5 -> 0 | W5: 未分包 | X5: =G5+L5+Q5+V5 -> 10 | Y5: =X5+F5/10000+K5/10000+P5/10000+U5/10000 -> 13.6 | Z5: 1.95 | AA5: =VLOOKUP(H5,$AF$3:$AG$9,2,FALSE)+VLOOKUP(M5,$AF$3:$AG$9,2,FALSE)+VLOOKUP(R5,$AF$3:$AG$9,2,FALSE)+VLOOKUP(W5,$AF$3:$AG$9,2,FALSE) -> 0 | AB5: =Y5+Z5-AA5 -> 15.55 | AC5: 44 | AD5: 1.95 | AF5: 跨服精英礼包 | AG5: =AJ5/200 -> 5.5 | AH5: 3 | AI5: 5 | AJ5: =AH5*200+AI5*100 -> 1100
A6: 58 | B6: Forever`大欢 | D6: 0 | E6: 0 | F6: 11000 | G6: 3 | H6: 未分包 | I6: 0 | J6: 3 | K6: 11200 | L6: =I6+J6 -> 3 | M6: 未分包 | N6: 0 | O6: 3 | P6: 9600 | Q6: =N6+O6 -> 3 | R6: 未分包 | S6: 0 | T6: 0 | U6: 0 | V6: =S6+T6 -> 0 | W6: 未分包 | X6: =G6+L6+Q6+V6 -> 9 | Y6: =X6+F6/10000+K6/10000+P6/10000+U6/10000 -> 12.18 | Z6: 3.1828571 | AA6: =VLOOKUP(H6,$AF$3:$AG$9,2,FALSE)+VLOOKUP(M6,$AF$3:$AG$9,2,FALSE)+VLOOKUP(R6,$AF$3:$AG$9,2,FALSE)+VLOOKUP(W6,$AF$3:$AG$9,2,FALSE) -> 0 | AB6: =Y6+Z6-AA6 -> 15.362857 | AC6: 32 | AD6: 3.1828571 | AF6: 传说功勋礼包 | AG6: =AJ6/200 -> 6.5 | AH6: 4 | AI6: 5 | AJ6: =AH6*200+AI6*100 -> 1300
A7: 34 | B7: Forever`劳模 | D7: 0 | E7: 0 | F7: 12000 | G7: 4 | H7: 未分包 | I7: 0 | J7: 3 | K7: 12000 | L7: =I7+J7 -> 3 | M7: 未分包 | N7: 0 | O7: 3 | P7: 12000 | Q7: =N7+O7 -> 3 | R7: 未分包 | S7: 0 | T7: 0 | U7: 0 | V7: =S7+T7 -> 0 | W7: 未分包 | X7: =G7+L7+Q7+V7 -> 10 | Y7: =X7+F7/10000+K7/10000+P7/10000+U7/10000 -> 13.6 | Z7: ='Sep2019'!AC38 -> 0.4 | AA7: =VLOOKUP(H7,$AF$3:$AG$9,2,FALSE)+VLOOKUP(M7,$AF$3:$AG$9,2,FALSE)+VLOOKUP(R7,$AF$3:$AG$9,2,FALSE)+VLOOKUP(W7,$AF$3:$AG$9,2,FALSE) -> 0 | AB7: =Y7+Z7-AA7 -> 14 | AF7: 英雄功勋礼包 | AG7: =AJ7/200 -> 5 | AH7: 3 | AI7: 4 | AJ7: =AH7*200+AI7*100 -> 1000
A8: 13 | B8: Forever`雷柱 | D8: 0 | E8: 0 | F8: 12000 | G8: 4 | H8: 精英功勋礼包 | I8: 0 | J8: 4 | K8: 12000 | L8: =I8+J8 -> 4 | M8: 精英功勋礼包 | N8: 0 | O8: 4 | P8: 12000 | Q8: =N8+O8 -> 4 | R8: 未分包 | S8: 0 | T8: 0 | U8: 0 | V8: =S8+T8 -> 0 | W8: 未分包 | X8: =G8+L8+Q8+V8 -> 12 | Y8: =X8+F8/10000+K8/10000+P8/10000+U8/10000 -> 15.6 | Z8: ='Sep2019'!AC17 -> 5.1 | AA8: =VLOOKUP(H8,$AF$3:$AG$9,2,FALSE)+VLOOKUP(M8,$AF$3:$AG$9,2,FALSE)+VLOOKUP(R8,$AF$3:$AG$9,2,FALSE)+VLOOKUP(W8,$AF$3:$AG$9,2,FALSE) -> 7 | AB8: =Y8+Z8-AA8 -> 13.7 | AF8: 精英功勋礼包 | AG8: =AJ8/200 -> 3.5 | AH8: 2 | AI8: 3 | AJ8: =AH8*200+AI8*100 -> 700
A9: 12 | B9: Forever`仙尊 | D9: 0 | E9: 0 | F9: 19200 | G9: 4 | H9: 英雄功勋礼包 | I9: 0 | J9: 4 | K9: 12000 | L9: =I9+J9 -> 4 | M9: 精英功勋礼包 | N9: 0 | O9: 4 | P9: 12000 | Q9: =N9+O9 -> 4 | R9: 未分包 | S9: 0 | T9: 0 | U9: 0 | V9: =S9+T9 -> 0 | W9: 未分包 | X9: =G9+L9+Q9+V9 -> 12 | Y9: =X9+F9/10000+K9/10000+P9/10000+U9/10000 -> 16.32 | Z9: ='Sep2019'!AC16 -> 5.7 | AA9: =VLOOKUP(H9,$AF$3:$AG$9,2,FALSE)+VLOOKUP(M9,$AF$3:$AG$9,2,FALSE)+VLOOKUP(R9,$AF$3:$AG$9,2,FALSE)+VLOOKUP(W9,$AF$3:$AG$9,2,FALSE) -> 8.5 | AB9: =Y9+Z9-AA9 -> 13.52 | AF9: 未分包 | AG9: 0
A10: 15 | B10: Forever`Gai | D10: 0 | E10: 0 | F10: 14400 | G10: 3 | H10: 未分包 | I10: 0 | J10: 4 | K10: 12000 | L10: =I10+J10 -> 4 | M10: 传说功勋礼包 | N10: 0 | O10: 4 | P10: 12000 | Q10: =N10+O10 -> 4 | R10: 未分包 | S10: 0 | T10: 0 | U10: 0 | V10: =S10+T10 -> 0 | W10: 未分包 | X10: =G10+L10+Q10+V10 -> 11 | Y10: =X10+F10/10000+K10/10000+P10/10000+U10/10000 -> 14.84 | Z10: ='Sep2019'!AC19 -> 4.72 | AA10: =VLOOKUP(H10,$AF$3:$AG$9,2,FALSE)+VLOOKUP(M10,$AF$3:$AG$9,2,FALSE)+VLOOKUP(R10,$AF$3:$AG$9,2,FALSE)+VLOOKUP(W10,$AF$3:$AG$9,2,FALSE) -> 6.5 | AB10: =Y10+Z10-AA10 -> 13.06
A11: 52 | B11: Forever`七夜 | D11: 0 | E11: 0 | F11: 12000 | G11: 4 | H11: 未分包 | I11: 0 | J11: 4 | K11: 15000 | L11: =I11+J11 -> 4 | M11: 英雄功勋礼包 | N11: 0 | O11: 3 | P11: 12000 | Q11: =N11+O11 -> 3 | R11: 未分包 | S11: 0 | T11: 0 | U11: 0 | V11: =S11+T11 -> 0 | W11: 未分包 | X11: =G11+L11+Q11+V11 -> 11 | Y11: =X11+F11/10000+K11/10000+P11/10000+U11/10000 -> 14.9 | Z11: ='Sep2019'!AC56 -> 3.1 | AA11: =VLOOKUP(H11,$AF$3:$AG$9,2,FALSE)+VLOOKUP(M11,$AF$3:$AG$9,2,FALSE)+VLOOKUP(R11,$AF$3:$AG$9,2,FALSE)+VLOOKUP(W11,$AF$3:$AG$9,2,FALSE) -> 5 | AB11: =Y11+Z11-AA11 -> 13
A12: 5 | B12: Forever`輪回 | D12: 0 | E12: 0 | F12: 12000 | G12: 3 | H12: 未分包 | I12: 0 | J12: 4 | K12: 12000 | L12: =I12+J12 -> 4 | M12: 传说功勋礼包 | N12: 0 | O12: 4 | P12: 9000 | Q12: =N12+O12 -> 4 | R12: 未分包 | S12: 0 | T12: 0 | U12: 0 | V12: =S12+T12 -> 0 | W12: 未分包 | X12: =G12+L12+Q12+V12 -> 11 | Y12: =X12+F12/10000+K12/10000+P12/10000+U12/10000 -> 14.3 | Z12: ='Sep2019'!AC9 -> 5.2 | AA12: =VLOOKUP(H12,$AF$3:$AG$9,2,FALSE)+VLOOKUP(M12,$AF$3:$AG$9,2,FALSE)+VLOOKUP(R12,$AF$3:$AG$9,2,FALSE)+VLOOKUP(W12,$AF$3:$AG$9,2,FALSE) -> 6.5 | AB12: =Y12+Z12-AA12 -> 13
A13: 9 | B13: Forever`释空 | D13: 0 | E13: 0 | F13: 27000 | G13: 4 | H13: 传说功勋礼包 | I13: 0 | J13: 4 | K13: 15000 | L13: =I13+J13 -> 4 | M13: 未分包 | N13: 0 | O13: 0 | P13: 12000 | Q13: =N13+O13 -> 0 | R13: 未分包 | S13: 0 | T13: 0 | U13: 0 | V13: =S13+T13 -> 0 | W13: 未分包 | X13: =G13+L13+Q13+V13 -> 8 | Y13: =X13+F13/10000+K13/10000+P13/10000+U13/10000 -> 13.4 | Z13: ='Sep2019'!AC13 -> 6 | AA13: =VLOOKUP(H13,$AF$3:$AG$9,2,FALSE)+VLOOKUP(M13,$AF$3:$AG$9,2,FALSE)+VLOOKUP(R13,$AF$3:$AG$9,2,FALSE)+VLOOKUP(W13,$AF$3:$AG$9,2,FALSE) -> 6.5 | AB13: =Y13+Z13-AA13 -> 12.9
A14: 17 | B14: Forever`珞珞 | D14: 0 | E14: 0 | F14: 12000 | G14: 4 | H14: 未分包 | I14: 0 | J14: 2 | K14: 12000 | L14: =I14+J14 -> 2 | M14: 英雄功勋礼包 | N14: 0 | O14: 4 | P14: 12000 | Q14: =N14+O14 -> 4 | R14: 未分包 | S14: 0 | T14: 0 | U14: 0 | V14: =S14+T14 -> 0 | W14: 未分包 | X14: =G14+L14+Q14+V14 -> 10 | Y14: =X14+F14/10000+K14/10000+P14/10000+U14/10000 -> 13.6 | Z14: ='Sep2019'!AC21 -> 4.2 | AA14: =VLOOKUP(H14,$AF$3:$AG$9,2,FALSE)+VLOOKUP(M14,$AF$3:$AG$9,2,FALSE)+VLOOKUP(R14,$AF$3:$AG$9,2,FALSE)+VLOOKUP(W14,$AF$3:$AG$9,2,FALSE) -> 5 | AB14: =Y14+Z14-AA14 -> 12.8
A15: 45 | B15: Forever`杜莎 | D15: 0 | E15: 0 | F15: 20600 | G15: 1 | H15: 未分包 | I15: 0 | J15: 3 | K15: 12000 | L15: =I15+J15 -> 3 | M15: 未分包 | N15: 0 | O15: 0 | P15: 12000 | Q15: =N15+O15 -> 0 | R15: 未分包 | S15: 0 | T15: 0 | U15: 0 | V15: =S15+T15 -> 0 | W15: 未分包 | X15: =G15+L15+Q15+V15 -> 4 | Y15: =X15+F15/10000+K15/10000+P15/10000+U15/10000 -> 8.46 | Z15: ='Sep2019'!AC49 -> 4.3 | AA15: =VLOOKUP(H15,$AF$3:$AG$9,2,FALSE)+VLOOKUP(M15,$AF$3:$AG$9,2,FALSE)+VLOOKUP(R15,$AF$3:$AG$9,2,FALSE)+VLOOKUP(W15,$AF$3:$AG$9,2,FALSE) -> 0 | AB15: =Y15+Z15-AA15 -> 12.76
A16: 53 | B16: Forever`清风 | D16: 0 | E16: 0 | F16: 16200 | G16: 4 | H16: 未分包 | I16: 0 | J16: 4 | K16: 12600 | L16: =I16+J16 -> 4 | M16: 传说功勋礼包 | N16: 0 | O16: 4 | P16: 12000 | Q16: =N16+O16 -> 4 | R16: 未分包 | S16: 0 | T16: 0 | U16: 0 | V16: =S16+T16 -> 0 | W16: 未分包 | X16: =G16+L16+Q16+V16 -> 12 | Y16: =X16+F16/10000+K16/10000+P16/10000+U16/10000 -> 16.08 | Z16: ='Sep2019'!AC57 -> 3.06 | AA16: =VLOOKUP(H16,$AF$3:$AG$9,2,FALSE)+VLOOKUP(M16,$AF$3:$AG$9,2,FALSE)+VLOOKUP(R16,$AF$3:$AG$9,2,FALSE)+VLOOKUP(W16,$AF$3:$AG$9,2,FALSE) -> 6.5 | AB16: =Y16+Z16-AA16 -> 12.64
A17: 56 | B17: Forever`真吾 | D17: 0 | E17: 0 | F17: 26200 | G17: 3 | H17: 未分包 | I17: 0 | J17: 2 | K17: 12000 | L17: =I17+J17 -> 2 | M17: 未分包 | N17: 0 | O17: 2 | P17: 12000 | Q17: =N17+O17 -> 2 | R17: 未分包 | S17: 0 | T17: 0 | U17: 0 | V17: =S17+T17 -> 0 | W17: 未分包 | X17: =G17+L17+Q17+V17 -> 7 | Y17: =X17+F17/10000+K17/10000+P17/10000+U17/10000 -> 12.02 | Z17: ='Sep2019'!AC60 -> 0.56 | AA17: =VLOOKUP(H17,$AF$3:$AG$9,2,FALSE)+VLOOKUP(M17,$AF$3:$AG$9,2,FALSE)+VLOOKUP(R17,$AF$3:$AG$9,2,FALSE)+VLOOKUP(W17,$AF$3:$AG$9,2,FALSE) -> 0 | AB17: =Y17+Z17-AA17 -> 12.58
A18: 51 | B18: Forever`sky | D18: 0 | E18: 0 | F18: 20000 | G18: 4 | H18: 英雄功勋礼包 | I18: 0 | J18: 2 | K18: 16000 | L18: =I18+J18 -> 2 | M18: 未分包 | N18: 0 | O18: 2 | P18: 12000 | Q18: =N18+O18 -> 2 | R18: 未分包 | S18: 0 | T18: 0 | U18: 0 | V18: =S18+T18 -> 0 | W18: 未分包 | X18: =G18+L18+Q18+V18 -> 8 | Y18: =X18+F18/10000+K18/10000+P18/10000+U18/10000 -> 12.8 | Z18: ='Sep2019'!AC55 -> 4.4 | AA18: =VLOOKUP(H18,$AF$3:$AG$9,2,FALSE)+VLOOKUP(M18,$AF$3:$AG$9,2,FALSE)+VLOOKUP(R18,$AF$3:$AG$9,2,FALSE)+VLOOKUP(W18,$AF$3:$AG$9,2,FALSE) -> 5 | AB18: =Y18+Z18-AA18 -> 12.2
A19: 48 | B19: Forever`胖子 | D19: 0 | E19: 0 | F19: 18000 | G19: 4 | H19: 未分包 | I19: 0 | J19: 2 | K19: 12000 | L19: =I19+J19 -> 2 | M19: 精英功勋礼包 | N19: 0 | O19: 3 | P19: 8000 | Q19: =N19+O19 -> 3 | R19: 未分包 | S19: 0 | T19: 0 | U19: 0 | V19: =S19+T19 -> 0 | W19: 未分包 | X19: =G19+L19+Q19+V19 -> 9 | Y19: =X19+F19/10000+K19/10000+P19/10000+U19/10000 -> 12.8 | Z19: ='Sep2019'!AC52 -> 2.8 | AA19: =VLOOKUP(H19,$AF$3:$AG$9,2,FALSE)+VLOOKUP(M19,$AF$3:$AG$9,2,FALSE)+VLOOKUP(R19,$AF$3:$AG$9,2,FALSE)+VLOOKUP(W19,$AF$3:$AG$9,2,FALSE) -> 3.5 | AB19: =Y19+Z19-AA19 -> 12.1
A20: 62 | B20: Forever`Thoma | D20: 0 | E20: 0 | F20: 8400 | G20: 0 | H20: 未分包 | I20: 0 | J20: 1 | K20: 18000 | L20: =I20+J20 -> 1 | M20: 未分包 | N20: 0 | O20: 2 | P20: 12000 | Q20: =N20+O20 -> 2 | R20: 未分包 | S20: 0 | T20: 0 | U20: 0 | V20: =S20+T20 -> 0 | W20: 未分包 | X20: =G20+L20+Q20+V20 -> 3 | Y20: =X20+F20/10000+K20/10000+P20/10000+U20/10000 -> 6.84 | Z20: 4.5457143 | AA20: =VLOOKUP(H20,$AF$3:$AG$9,2,FALSE)+VLOOKUP(M20,$AF$3:$AG$9,2,FALSE)+VLOOKUP(R20,$AF$3:$AG$9,2,FALSE)+VLOOKUP(W20,$AF$3:$AG$9,2,FALSE) -> 0 | AB20: =Y20+Z20-AA20 -> 11.385714 | AC20: 24 | AD20: 4.5457143
A21: 23 | B21: Forever`三傻 | D21: 0 | E21: 0 | F21: 17800 | G21: 4 | H21: 英雄功勋礼包 | I21: 0 | J21: 4 | K21: 19000 | L21: =I21+J21 -> 4 | M21: 未分包 | N21: 0 | O21: 4 | P21: 6000 | Q21: =N21+O21 -> 4 | R21: 英雄功勋礼包 | S21: 0 | T21: 0 | U21: 0 | V21: =S21+T21 -> 0 | W21: 未分包 | X21: =G21+L21+Q21+V21 -> 12 | Y21: =X21+F21/10000+K21/10000+P21/10000+U21/10000 -> 16.28 | Z21: ='Sep2019'!AC27 -> 4.8 | AA21: =VLOOKUP(H21,$AF$3:$AG$9,2,FALSE)+VLOOKUP(M21,$AF$3:$AG$9,2,FALSE)+VLOOKUP(R21,$AF$3:$AG$9,2,FALSE)+VLOOKUP(W21,$AF$3:$AG$9,2,FALSE) -> 10 | AB21: =Y21+Z21-AA21 -> 11.08
A22: 8 | B22: Forever`了佳 | D22: 0 | E22: 0 | F22: 17400 | G22: 4 | H22: 英雄功勋礼包 | I22: 0 | J22: 4 | K22: 12000 | L22: =I22+J22 -> 4 | M22: 未分包 | N22: 0 | O22: 4 | P22: 12000 | Q22: =N22+O22 -> 4 | R22: 英雄功勋礼包 | S22: 0 | T22: 0 | U22: 0 | V22: =S22+T22 -> 0 | W22: 未分包 | X22: =G22+L22+Q22+V22 -> 12 | Y22: =X22+F22/10000+K22/10000+P22/10000+U22/10000 -> 16.14 | Z22: ='Sep2019'!AC12 -> 4.82 | AA22: =VLOOKUP(H22,$AF$3:$AG$9,2,FALSE)+VLOOKUP(M22,$AF$3:$AG$9,2,FALSE)+VLOOKUP(R22,$AF$3:$AG$9,2,FALSE)+VLOOKUP(W22,$AF$3:$AG$9,2,FALSE) -> 10 | AB22: =Y22+Z22-AA22 -> 10.96
A23: 20 | B23: Forever`孤王 | D23: 0 | E23: 0 | F23: 18800 | G23: 1 | H23: 未分包 | I23: 0 | J23: 4 | K23: 9800 | L23: =I23+J23 -> 4 | M23: 英雄功勋礼包 | N23: 0 | O23: 2 | P23: 11000 | Q23: =N23+O23 -> 2 | R23: 未分包 | S23: 0 | T23: 0 | U23: 0 | V23: =S23+T23 -> 0 | W23: 未分包 | X23: =G23+L23+Q23+V23 -> 7 | Y23: =X23+F23/10000+K23/10000+P23/10000+U23/10000 -> 10.96 | Z23: ='Sep2019'!AC24 -> 4.9 | AA23: =VLOOKUP(H23,$AF$3:$AG$9,2,FALSE)+VLOOKUP(M23,$AF$3:$AG$9,2,FALSE)+VLOOKUP(R23,$AF$3:$AG$9,2,FALSE)+VLOOKUP(W23,$AF$3:$AG$9,2,FALSE) -> 5 | AB23: =Y23+Z23-AA23 -> 10.86
A24: 43 | B24: Forever`阿良 | D24: 0 | E24: 0 | F24: 30000 | G24: 3 | H24: 未分包 | I24: 0 | J24: 4 | K24: 30000 | L24: =I24+J24 -> 4 | M24: 传说功勋礼包 | N24: 0 | O24: 4 | P24: 30000 | Q24: =N24+O24 -> 4 | R24: 英雄功勋礼包 | S24: 0 | T24: 0 | U24: 0 | V24: =S24+T24 -> 0 | W24: 未分包 | X24: =G24+L24+Q24+V24 -> 11 | Y24: =X24+F24/10000+K24/10000+P24/10000+U24/10000 -> 20 | Z24: ='Sep2019'!AC47 -> 2.3 | AA24: =VLOOKUP(H24,$AF$3:$AG$9,2,FALSE)+VLOOKUP(M24,$AF$3:$AG$9,2,FALSE)+VLOOKUP(R24,$AF$3:$AG$9,2,FALSE)+VLOOKUP(W24,$AF$3:$AG$9,2,FALSE) -> 11.5 | AB24: =Y24+Z24-AA24 -> 10.8
A25: 36 | B25: 卟离卟弃 | D25: 0 | E25: 0 | F25: 12000 | G25: 2 | H25: 未分包 | I25: 0 | J25: 2 | K25: 12000 | L25: =I25+J25 -> 2 | M25: 未分包 | N25: 0 | O25: 3 | P25: 12000 | Q25: =N25+O25 -> 3 | R25: 未分包 | S25: 0 | T25: 0 | U25: 0 | V25: =S25+T25 -> 0 | W25: 未分包 | X25: =G25+L25+Q25+V25 -> 7 | Y25: =X25+F25/10000+K25/10000+P25/10000+U25/10000 -> 10.6 | Z25: ='Sep2019'!AC40 -> 0.2 | AA25: =VLOOKUP(H25,$AF$3:$AG$9,2,FALSE)+VLOOKUP(M25,$AF$3:$AG$9,2,FALSE)+VLOOKUP(R25,$AF$3:$AG$9,2,FALSE)+VLOOKUP(W25,$AF$3:$AG$9,2,FALSE) -> 0 | AB25: =Y25+Z25-AA25 -> 10.8
A26: 4 | B26: Forever`利 | D26: 0 | E26: 0 | F26: 12000 | G26: 4 | H26: 英雄功勋礼包 | I26: 0 | J26: 4 | K26: 12000 | L26: =I26+J26 -> 4 | M26: 未分包 | N26: 0 | O26: 4 | P26: 12000 | Q26: =N26+O26 -> 4 | R26: 英雄功勋礼包 | S26: 0 | T26: 0 | U26: 0 | V26: =S26+T26 -> 0 | W26: 未分包 | X26: =G26+L26+Q26+V26 -> 12 | Y26: =X26+F26/10000+K26/10000+P26/10000+U26/10000 -> 15.6 | Z26: ='Sep2019'!AC8 -> 5.2 | AA26: =VLOOKUP(H26,$AF$3:$AG$9,2,FALSE)+VLOOKUP(M26,$AF$3:$AG$9,2,FALSE)+VLOOKUP(R26,$AF$3:$AG$9,2,FALSE)+VLOOKUP(W26,$AF$3:$AG$9,2,FALSE) -> 10 | AB26: =Y26+Z26-AA26 -> 10.8
A27: 10 | B27: Forever`随风 | D27: 0 | E27: 0 | F27: 28200 | G27: 4 | H27: 传说功勋礼包 | I27: 0 | J27: 4 | K27: 18600 | L27: =I27+J27 -> 4 | M27: 精英功勋礼包 | N27: 0 | O27: 4 | P27: 16200 | Q27: =N27+O27 -> 4 | R27: 精英功勋礼包 | S27: 0 | T27: 0 | U27: 0 | V27: =S27+T27 -> 0 | W27: 未分包 | X27: =G27+L27+Q27+V27 -> 12 | Y27: =X27+F27/10000+K27/10000+P27/10000+U27/10000 -> 18.3 | Z27: ='Sep2019'!AC14 -> 5.96 | AA27: =VLOOKUP(H27,$AF$3:$AG$9,2,FALSE)+VLOOKUP(M27,$AF$3:$AG$9,2,FALSE)+VLOOKUP(R27,$AF$3:$AG$9,2,FALSE)+VLOOKUP(W27,$AF$3:$AG$9,2,FALSE) -> 13.5 | AB27: =Y27+Z27-AA27 -> 10.76
A28: 14 | B28: Forever`初见 | D28: 0 | E28: 0 | F28: 12000 | G28: 2 | H28: 未分包 | I28: 0 | J28: 0 | K28: 12000 | L28: =I28+J28 -> 0 | M28: 未分包 | N28: 0 | O28: 4 | P28: 8000 | Q28: =N28+O28 -> 4 | R28: 精英功勋礼包 | S28: 0 | T28: 0 | U28: 0 | V28: =S28+T28 -> 0 | W28: 未分包 | X28: =G28+L28+Q28+V28 -> 6 | Y28: =X28+F28/10000+K28/10000+P28/10000+U28/10000 -> 9.2 | Z28: ='Sep2019'!AC18 -> 5.02 | AA28: =VLOOKUP(H28,$AF$3:$AG$9,2,FALSE)+VLOOKUP(M28,$AF$3:$AG$9,2,FALSE)+VLOOKUP(R28,$AF$3:$AG$9,2,FALSE)+VLOOKUP(W28,$AF$3:$AG$9,2,FALSE) -> 3.5 | AB28: =Y28+Z28-AA28 -> 10.72
A29: 69 | B29: Forever`时光 | D29: 0 | E29: 0 | F29: 0 | G29: 0 | H29: 未分包 | I29: 0 | J29: 4 | K29: 9200 | L29: =I29+J29 -> 4 | M29: 未分包 | N29: 0 | O29: 4 | P29: 12000 | Q29: =N29+O29 -> 4 | R29: 未分包 | S29: 0 | T29: 0 | U29: 0 | V29: =S29+T29 -> 0 | W29: 未分包 | X29: =G29+L29+Q29+V29 -> 8 | Y29: =X29+F29/10000+K29/10000+P29/10000+U29/10000 -> 10.12 | Z29: 0.5525 | AA29: =VLOOKUP(H29,$AF$3:$AG$9,2,FALSE)+VLOOKUP(M29,$AF$3:$AG$9,2,FALSE)+VLOOKUP(R29,$AF$3:$AG$9,2,FALSE)+VLOOKUP(W29,$AF$3:$AG$9,2,FALSE) -> 0 | AB29: =Y29+Z29-AA29 -> 10.6725 | AC29: 49 | AD29: 0.5525
A30: 46 | B30: Forever`帆锅 | D30: 0 | E30: 0 | F30: 16800 | G30: 3 | H30: 精英功勋礼包 | I30: 0 | J30: 4 | K30: 16200 | L30: =I30+J30 -> 4 | M30: 精英功勋礼包 | N30: 0 | O30: 4 | P30: 17400 | Q30: =N30+O30 -> 4 | R30: 精英功勋礼包 | S30: 0 | T30: 0 | U30: 0 | V30: =S30+T30 -> 0 | W30: 未分包 | X30: =G30+L30+Q30+V30 -> 11 | Y30: =X30+F30/10000+K30/10000+P30/10000+U30/10000 -> 16.04 | Z30: ='Sep2019'!AC50 -> 5.06 | AA30: =VLOOKUP(H30,$AF$3:$AG$9,2,FALSE)+VLOOKUP(M30,$AF$3:$AG$9,2,FALSE)+VLOOKUP(R30,$AF$3:$AG$9,2,FALSE)+VLOOKUP(W30,$AF$3:$AG$9,2,FALSE) -> 10.5 | AB30: =Y30+Z30-AA30 -> 10.6
A31: 29 | B31: Forever`别吵 | D31: 0 | E31: 0 | F31: 21600 | G31: 4 | H31: 未分包 | I31: 0 | J31: 4 | K31: 12000 | L31: =I31+J31 -> 4 | M31: 英雄功勋礼包 | N31: 0 | O31: 2 | P31: 12000 | Q31: =N31+O31 -> 2 | R31: 未分包 | S31: 0 | T31: 0 | U31: 0 | V31: =S31+T31 -> 0 | W31: 未分包 | X31: =G31+L31+Q31+V31 -> 10 | Y31: =X31+F31/10000+K31/10000+P31/10000+U31/10000 -> 14.56 | Z31: ='Sep2019'!AC33 -> 0.96 | AA31: =VLOOKUP(H31,$AF$3:$AG$9,2,FALSE)+VLOOKUP(M31,$AF$3:$AG$9,2,FALSE)+VLOOKUP(R31,$AF$3:$AG$9,2,FALSE)+VLOOKUP(W31,$AF$3:$AG$9,2,FALSE) -> 5 | AB31: =Y31+Z31-AA31 -> 10.52
A32: 54 | B32: Forever`XXX | D32: 0 | E32: 0 | F32: 18000 | G32: 3 | H32: 未分包 | I32: 0 | J32: 4 | K32: 12000 | L32: =I32+J32 -> 4 | M32: 英雄功勋礼包 | N32: 0 | O32: 4 | P32: 12000 | Q32: =N32+O32 -> 4 | R32: 精英功勋礼包 | S32: 0 | T32: 0 | U32: 0 | V32: =S32+T32 -> 0 | W32: 未分包 | X32: =G32+L32+Q32+V32 -> 11 | Y32: =X32+F32/10000+K32/10000+P32/10000+U32/10000 -> 15.2 | Z32: ='Sep2019'!AC58 -> 3.8 | AA32: =VLOOKUP(H32,$AF$3:$AG$9,2,FALSE)+VLOOKUP(M32,$AF$3:$AG$9,2,FALSE)+VLOOKUP(R32,$AF$3:$AG$9,2,FALSE)+VLOOKUP(W32,$AF$3:$AG$9,2,FALSE) -> 8.5 | AB32: =Y32+Z32-AA32 -> 10.5
A33: 11 | B33: Forever`白泽 | D33: 0 | E33: 0 | F33: 15000 | G33: 4 | H33: 传说功勋礼包 | I33: 0 | J33: 4 | K33: 15000 | L33: =I33+J33 -> 4 | M33: 未分包 | N33: 0 | O33: 2 | P33: 12000 | Q33: =N33+O33 -> 2 | R33: 精英功勋礼包 | S33: 0 | T33: 0 | U33: 0 | V33: =S33+T33 -> 0 | W33: 未分包 | X33: =G33+L33+Q33+V33 -> 10 | Y33: =X33+F33/10000+K33/10000+P33/10000+U33/10000 -> 14.2 | Z33: ='Sep2019'!AC15 -> 6.3 | AA33: =VLOOKUP(H33,$AF$3:$AG$9,2,FALSE)+VLOOKUP(M33,$AF$3:$AG$9,2,FALSE)+VLOOKUP(R33,$AF$3:$AG$9,2,FALSE)+VLOOKUP(W33,$AF$3:$AG$9,2,FALSE) -> 10 | AB33: =Y33+Z33-AA33 -> 10.5
A34: 1 | B34: Forever`欢喜 | D34: 0 | E34: 0 | F34: 18000 | G34: 4 | H34: 传说功勋礼包 | I34: 0 | J34: 4 | K34: 14800 | L34: =I34+J34 -> 4 | M34: 未分包 | N34: 0 | O34: 4 | P34: 12000 | Q34: =N34+O34 -> 4 | R34: 传说功勋礼包 | S34: 0 | T34: 0 | U34: 0 | V34: =S34+T34 -> 0 | W34: 未分包 | X34: =G34+L34+Q34+V34 -> 12 | Y34: =X34+F34/10000+K34/10000+P34/10000+U34/10000 -> 16.48 | Z34: ='Sep2019'!AC5 -> 7 | AA34: =VLOOKUP(H34,$AF$3:$AG$9,2,FALSE)+VLOOKUP(M34,$AF$3:$AG$9,2,FALSE)+VLOOKUP(R34,$AF$3:$AG$9,2,FALSE)+VLOOKUP(W34,$AF$3:$AG$9,2,FALSE) -> 13 | AB34: =Y34+Z34-AA34 -> 10.48
A35: 16 | B35: Forever`啾啾 | D35: 0 | E35: 0 | F35: 16200 | G35: 4 | H35: 精英功勋礼包 | I35: 0 | J35: 3 | K35: 18000 | L35: =I35+J35 -> 3 | M35: 未分包 | N35: 0 | O35: 4 | P35: 13800 | Q35: =N35+O35 -> 4 | R35: 传说功勋礼包 | S35: 0 | T35: 0 | U35: 0 | V35: =S35+T35 -> 0 | W35: 未分包 | X35: =G35+L35+Q35+V35 -> 11 | Y35: =X35+F35/10000+K35/10000+P35/10000+U35/10000 -> 15.8 | Z35: ='Sep2019'!AC20 -> 4.5 | AA35: =VLOOKUP(H35,$AF$3:$AG$9,2,FALSE)+VLOOKUP(M35,$AF$3:$AG$9,2,FALSE)+VLOOKUP(R35,$AF$3:$AG$9,2,FALSE)+VLOOKUP(W35,$AF$3:$AG$9,2,FALSE) -> 10 | AB35: =Y35+Z35-AA35 -> 10.3
A36: 49 | B36: Forever`小傻 | D36: 0 | E36: 0 | F36: 11600 | G36: 4 | H36: 精英功勋礼包 | I36: 0 | J36: 4 | K36: 12000 | L36: =I36+J36 -> 4 | M36: 未分包 | N36: 0 | O36: 4 | P36: 12000 | Q36: =N36+O36 -> 4 | R36: 传说功勋礼包 | S36: 0 | T36: 0 | U36: 0 | V36: =S36+T36 -> 0 | W36: 未分包 | X36: =G36+L36+Q36+V36 -> 12 | Y36: =X36+F36/10000+K36/10000+P36/10000+U36/10000 -> 15.56 | Z36: ='Sep2019'!AC53 -> 4.66 | AA36: =VLOOKUP(H36,$AF$3:$AG$9,2,FALSE)+VLOOKUP(M36,$AF$3:$AG$9,2,FALSE)+VLOOKUP(R36,$AF$3:$AG$9,2,FALSE)+VLOOKUP(W36,$AF$3:$AG$9,2,FALSE) -> 10 | AB36: =Y36+Z36-AA36 -> 10.22
A37: 28 | B37: Forever`鹿丸 | D37: 0 | E37: 0 | F37: 18000 | G37: 2 | H37: 未分包 | I37: 0 | J37: 2 | K37: 21000 | L37: =I37+J37 -> 2 | M37: 未分包 | N37: 0 | O37: 4 | P37: 12000 | Q37: =N37+O37 -> 4 | R37: 英雄功勋礼包 | S37: 0 | T37: 0 | U37: 0 | V37: =S37+T37 -> 0 | W37: 未分包 | X37: =G37+L37+Q37+V37 -> 8 | Y37: =X37+F37/10000+K37/10000+P37/10000+U37/10000 -> 13.1 | Z37: ='Sep2019'!AC32 -> 2.04 | AA37: =VLOOKUP(H37,$AF$3:$AG$9,2,FALSE)+VLOOKUP(M37,$AF$3:$AG$9,2,FALSE)+VLOOKUP(R37,$AF$3:$AG$9,2,FALSE)+VLOOKUP(W37,$AF$3:$AG$9,2,FALSE) -> 5 | AB37: =Y37+Z37-AA37 -> 10.14
A38: 2 | B38: Forever`弟弟 | D38: 0 | E38: 0 | F38: 22200 | G38: 3 | H38: 传说功勋礼包 | I38: 0 | J38: 4 | K38: 14400 | L38: =I38+J38 -> 4 | M38: 未分包 | N38: 0 | O38: 4 | P38: 12000 | Q38: =N38+O38 -> 4 | R38: 传说功勋礼包 | S38: 0 | T38: 0 | U38: 0 | V38: =S38+T38 -> 0 | W38: 未分包 | X38: =G38+L38+Q38+V38 -> 11 | Y38: =X38+F38/10000+K38/10000+P38/10000+U38/10000 -> 15.86 | Z38: ='Sep2019'!AC6 -> 7.18 | AA38: =VLOOKUP(H38,$AF$3:$AG$9,2,FALSE)+VLOOKUP(M38,$AF$3:$AG$9,2,FALSE)+VLOOKUP(R38,$AF$3:$AG$9,2,FALSE)+VLOOKUP(W38,$AF$3:$AG$9,2,FALSE) -> 13 | AB38: =Y38+Z38-AA38 -> 10.04
A39: 35 | B39: 神罗天征 | D39: 0 | E39: 0 | F39: 0 | G39: =D39+E39 -> 0 | H39: 未分包 | I39: 0 | J39: 0 | K39: 0 | L39: =I39+J39 -> 0 | M39: 未分包 | N39: 0 | O39: 0 | P39: 0 | Q39: =N39+O39 -> 0 | R39: 未分包 | S39: 0 | T39: 0 | U39: 0 | V39: =S39+T39 -> 0 | W39: 未分包 | X39: =G39+L39+Q39+V39 -> 0 | Y39: =X39+F39/10000+K39/10000+P39/10000+U39/10000 -> 0 | Z39: ='Sep2019'!AC39 -> 0.2 | AA39: =VLOOKUP(H39,$AF$3:$AG$9,2,FALSE)+VLOOKUP(M39,$AF$3:$AG$9,2,FALSE)+VLOOKUP(R39,$AF$3:$AG$9,2,FALSE)+VLOOKUP(W39,$AF$3:$AG$9,2,FALSE) -> 0 | AB39: =Y39+Z39-AA39 -> 0.2
A40: 33 | B40: Forever`大傻 | D40: 0 | E40: 0 | F40: 22000 | G40: 4 | H40: 未分包 | I40: 0 | J40: 3 | K40: 15000 | L40: =I40+J40 -> 3 | M40: 未分包 | N40: 0 | O40: 4 | P40: 12000 | Q40: =N40+O40 -> 4 | R40: 传说功勋礼包 | S40: 0 | T40: 0 | U40: 0 | V40: =S40+T40 -> 0 | W40: 未分包 | X40: =G40+L40+Q40+V40 -> 11 | Y40: =X40+F40/10000+K40/10000+P40/10000+U40/10000 -> 15.9 | Z40: ='Sep2019'!AC37 -> 0.5 | AA40: =VLOOKUP(H40,$AF$3:$AG$9,2,FALSE)+VLOOKUP(M40,$AF$3:$AG$9,2,FALSE)+VLOOKUP(R40,$AF$3:$AG$9,2,FALSE)+VLOOKUP(W40,$AF$3:$AG$9,2,FALSE) -> 6.5 | AB40: =Y40+Z40-AA40 -> 9.9
...

Sheet Oct26th2019
A1: 157区 活动中心 分包贡献明细 By:Forever`二傻 | AF1: 人数 | AG1: 52
AF2: 礼包类别 | AG2: 消耗分数 | AH2: 封印卷個數 | AI2: 通靈卷個數 | AJ2: 價值（金幣）
A3: 日期 | D3: 10月2日 & 10月5日 | I3: 10月9日 & 10月12日 | N3: 10月16日 & 10月19日 | S3: 10月23日 & 10月26日 | X3: 总分 | AE3: 备注 | AF3: 跨服传说礼包 | AG3: =AJ3/200 -> 8.5 | AH3: 5 | AI3: 7 | AJ3: =AH3*200+AI3*100 -> 1700
A4: 编号 | B4: 昵称 | C4: 曾用名 | D4: 周三 | E4: 周六 | F4: 贡献 | G4: 参战 | H4: 分包 | I4: 周三 | J4: 周六 | K4: 贡献 | L4: 参战 | M4: 分包 | N4: 周三 | O4: 周六 | P4: 贡献 | Q4: 参战 | R4: 分包 | S4: 周三 | T4: 周六 | U4: 贡献 | V4: 参战 | W4: 分包 | X4: 参战次数 | Y4: 本月得分 | Z4: 上月得分 | AA4: 礼包耗费 | AB4: 分包总分 | AC4: 新人战力排名 | AD4: 新人初始分 | AF4: 跨服英雄礼包 | AG4: =AJ4/200 -> 7 | AH4: 4 | AI4: 6 | AJ4: =AH4*200+AI4*100 -> 1400
A5: 1 | B5: Forever`欢喜 | D5: 0 | E5: 0 | F5: 18000 | G5: 4 | H5: 传说功勋礼包 | I5: 0 | J5: 4 | K5: 14800 | L5: =I5+J5 -> 4 | M5: 未分包 | N5: 0 | O5: 4 | P5: 12000 | Q5: =N5+O5 -> 4 | R5: 传说功勋礼包 | S5: 0 | T5: 3 | U5: 12000 | V5: =S5+T5 -> 3 | W5: 未分包 | X5: =G5+L5+Q5+V5 -> 15 | Y5: =X5+F5/10000+K5/10000+P5/10000+U5/10000 -> 20.68 | Z5: ='Sep2019'!AC5 -> 7 | AA5: =VLOOKUP(H5,$AF$3:$AG$9,2,FALSE)+VLOOKUP(M5,$AF$3:$AG$9,2,FALSE)+VLOOKUP(R5,$AF$3:$AG$9,2,FALSE)+VLOOKUP(W5,$AF$3:$AG$9,2,FALSE) -> 13 | AB5: =Y5+Z5-AA5 -> 14.68 | AF5: 跨服精英礼包 | AG5: =AJ5/200 -> 5.5 | AH5: 3 | AI5: 5 | AJ5: =AH5*200+AI5*100 -> 1100
A6: 51 | B6: Forever`sky | D6: 0 | E6: 0 | F6: 20000 | G6: 4 | H6: 英雄功勋礼包 | I6: 0 | J6: 2 | K6: 16000 | L6: =I6+J6 -> 2 | M6: 未分包 | N6: 0 | O6: 2 | P6: 12000 | Q6: =N6+O6 -> 2 | R6: 未分包 | S6: 0 | T6: 1 | U6: 12000 | V6: =S6+T6 -> 1 | W6: 未分包 | X6: =G6+L6+Q6+V6 -> 9 | Y6: =X6+F6/10000+K6/10000+P6/10000+U6/10000 -> 15 | Z6: ='Sep2019'!AC55 -> 4.4 | AA6: =VLOOKUP(H6,$AF$3:$AG$9,2,FALSE)+VLOOKUP(M6,$AF$3:$AG$9,2,FALSE)+VLOOKUP(R6,$AF$3:$AG$9,2,FALSE)+VLOOKUP(W6,$AF$3:$AG$9,2,FALSE) -> 5 | AB6: =Y6+Z6-AA6 -> 14.4 | AF6: 传说功勋礼包 | AG6: =AJ6/200 -> 6.5 | AH6: 4 | AI6: 5 | AJ6: =AH6*200+AI6*100 -> 1300
A7: 52 | B7: Forever`七夜 | D7: 0 | E7: 0 | F7: 12000 | G7: 4 | H7: 未分包 | I7: 0 | J7: 4 | K7: 15000 | L7: =I7+J7 -> 4 | M7: 英雄功勋礼包 | N7: 0 | O7: 3 | P7: 12000 | Q7: =N7+O7 -> 3 | R7: 未分包 | S7: 0 | T7: 0 | U7: 12000 | V7: =S7+T7 -> 0 | W7: 未分包 | X7: =G7+L7+Q7+V7 -> 11 | Y7: =X7+F7/10000+K7/10000+P7/10000+U7/10000 -> 16.1 | Z7: ='Sep2019'!AC56 -> 3.1 | AA7: =VLOOKUP(H7,$AF$3:$AG$9,2,FALSE)+VLOOKUP(M7,$AF$3:$AG$9,2,FALSE)+VLOOKUP(R7,$AF$3:$AG$9,2,FALSE)+VLOOKUP(W7,$AF$3:$AG$9,2,FALSE) -> 5 | AB7: =Y7+Z7-AA7 -> 14.2 | AF7: 英雄功勋礼包 | AG7: =AJ7/200 -> 5 | AH7: 3 | AI7: 4 | AJ7: =AH7*200+AI7*100 -> 1000
A8: 9 | B8: Forever`释空 | D8: 0 | E8: 0 | F8: 27000 | G8: 4 | H8: 传说功勋礼包 | I8: 0 | J8: 4 | K8: 15000 | L8: =I8+J8 -> 4 | M8: 未分包 | N8: 0 | O8: 0 | P8: 12000 | Q8: =N8+O8 -> 0 | R8: 未分包 | S8: 0 | T8: 0 | U8: 8000 | V8: =S8+T8 -> 0 | W8: 未分包 | X8: =G8+L8+Q8+V8 -> 8 | Y8: =X8+F8/10000+K8/10000+P8/10000+U8/10000 -> 14.2 | Z8: ='Sep2019'!AC13 -> 6 | AA8: =VLOOKUP(H8,$AF$3:$AG$9,2,FALSE)+VLOOKUP(M8,$AF$3:$AG$9,2,FALSE)+VLOOKUP(R8,$AF$3:$AG$9,2,FALSE)+VLOOKUP(W8,$AF$3:$AG$9,2,FALSE) -> 6.5 | AB8: =Y8+Z8-AA8 -> 13.7 | AF8: 精英功勋礼包 | AG8: =AJ8/200 -> 3.5 | AH8: 2 | AI8: 3 | AJ8: =AH8*200+AI8*100 -> 700
A9: 86 | B9: Forever`一笑 | D9: 0 | E9: 0 | F9: 0 | G9: 0 | H9: 未分包 | I9: 0 | J9: 0 | K9: 0 | L9: =I9+J9 -> 0 | M9: 未分包 | N9: 0 | O9: 0 | P9: 0 | Q9: =N9+O9 -> 0 | R9: 未分包 | S9: 0 | T9: 3 | U9: 9000 | V9: =S9+T9 -> 3 | W9: 未分包 | X9: =G9+L9+Q9+V9 -> 3 | Y9: =X9+F9/10000+K9/10000+P9/10000+U9/10000 -> 3.9 | Z9: 8.7 | AA9: =VLOOKUP(H9,$AF$3:$AG$9,2,FALSE)+VLOOKUP(M9,$AF$3:$AG$9,2,FALSE)+VLOOKUP(R9,$AF$3:$AG$9,2,FALSE)+VLOOKUP(W9,$AF$3:$AG$9,2,FALSE) -> 0 | AB9: =Y9+Z9-AA9 -> 12.6 | AC9: 37 | AD9: 8.7 | AF9: 未分包 | AG9: 0
A10: 87 | B10: 【镜像】夜幕 | D10: 0 | E10: 0 | F10: 0 | G10: 0 | H10: 未分包 | I10: 0 | J10: 0 | K10: 0 | L10: =I10+J10 -> 0 | M10: 未分包 | N10: 0 | O10: 0 | P10: 0 | Q10: =N10+O10 -> 0 | R10: 未分包 | S10: 0 | T10: 3 | U10: 8000 | V10: =S10+T10 -> 3 | W10: 未分包 | X10: =G10+L10+Q10+V10 -> 3 | Y10: =X10+F10/10000+K10/10000+P10/10000+U10/10000 -> 3.8 | Z10: 8.76 | AA10: =VLOOKUP(H10,$AF$3:$AG$9,2,FALSE)+VLOOKUP(M10,$AF$3:$AG$9,2,FALSE)+VLOOKUP(R10,$AF$3:$AG$9,2,FALSE)+VLOOKUP(W10,$AF$3:$AG$9,2,FALSE) -> 0 | AB10: =Y10+Z10-AA10 -> 12.56 | AC10: 34 | AD10: 8.76
A11: 13 | B11: Forever`雷柱 | D11: 0 | E11: 0 | F11: 12000 | G11: 4 | H11: 精英功勋礼包 | I11: 0 | J11: 4 | K11: 12000 | L11: =I11+J11 -> 4 | M11: 精英功勋礼包 | N11: 0 | O11: 4 | P11: 12000 | Q11: =N11+O11 -> 4 | R11: 未分包 | S11: 0 | T11: 3 | U11: 12000 | V11: =S11+T11 -> 3 | W11: 跨服精英礼包 | X11: =G11+L11+Q11+V11 -> 15 | Y11: =X11+F11/10000+K11/10000+P11/10000+U11/10000 -> 19.8 | Z11: ='Sep2019'!AC17 -> 5.1 | AA11: =VLOOKUP(H11,$AF$3:$AG$9,2,FALSE)+VLOOKUP(M11,$AF$3:$AG$9,2,FALSE)+VLOOKUP(R11,$AF$3:$AG$9,2,FALSE)+VLOOKUP(W11,$AF$3:$AG$9,2,FALSE) -> 12.5 | AB11: =Y11+Z11-AA11 -> 12.4
A12: 14 | B12: Forever`初见 | D12: 0 | E12: 0 | F12: 12000 | G12: 2 | H12: 未分包 | I12: 0 | J12: 0 | K12: 12000 | L12: =I12+J12 -> 0 | M12: 未分包 | N12: 0 | O12: 4 | P12: 8000 | Q12: =N12+O12 -> 4 | R12: 精英功勋礼包 | S12: 0 | T12: 1 | U12: 6000 | V12: =S12+T12 -> 1 | W12: 未分包 | X12: =G12+L12+Q12+V12 -> 7 | Y12: =X12+F12/10000+K12/10000+P12/10000+U12/10000 -> 10.8 | Z12: ='Sep2019'!AC18 -> 5.02 | AA12: =VLOOKUP(H12,$AF$3:$AG$9,2,FALSE)+VLOOKUP(M12,$AF$3:$AG$9,2,FALSE)+VLOOKUP(R12,$AF$3:$AG$9,2,FALSE)+VLOOKUP(W12,$AF$3:$AG$9,2,FALSE) -> 3.5 | AB12: =Y12+Z12-AA12 -> 12.32
A13: 48 | B13: Forever`胖子 | D13: 0 | E13: 0 | F13: 18000 | G13: 4 | H13: 未分包 | I13: 0 | J13: 2 | K13: 12000 | L13: =I13+J13 -> 2 | M13: 精英功勋礼包 | N13: 0 | O13: 3 | P13: 8000 | Q13: =N13+O13 -> 3 | R13: 未分包 | S13: 0 | T13: 0 | U13: 0 | V13: =S13+T13 -> 0 | W13: 未分包 | X13: =G13+L13+Q13+V13 -> 9 | Y13: =X13+F13/10000+K13/10000+P13/10000+U13/10000 -> 12.8 | Z13: ='Sep2019'!AC52 -> 2.8 | AA13: =VLOOKUP(H13,$AF$3:$AG$9,2,FALSE)+VLOOKUP(M13,$AF$3:$AG$9,2,FALSE)+VLOOKUP(R13,$AF$3:$AG$9,2,FALSE)+VLOOKUP(W13,$AF$3:$AG$9,2,FALSE) -> 3.5 | AB13: =Y13+Z13-AA13 -> 12.1
A14: 36 | B14: 卟离卟弃 | D14: 0 | E14: 0 | F14: 12000 | G14: 2 | H14: 未分包 | I14: 0 | J14: 2 | K14: 12000 | L14: =I14+J14 -> 2 | M14: 未分包 | N14: 0 | O14: 3 | P14: 12000 | Q14: =N14+O14 -> 3 | R14: 未分包 | S14: 0 | T14: 0 | U14: 12000 | V14: =S14+T14 -> 0 | W14: 未分包 | X14: =G14+L14+Q14+V14 -> 7 | Y14: =X14+F14/10000+K14/10000+P14/10000+U14/10000 -> 11.8 | Z14: ='Sep2019'!AC40 -> 0.2 | AA14: =VLOOKUP(H14,$AF$3:$AG$9,2,FALSE)+VLOOKUP(M14,$AF$3:$AG$9,2,FALSE)+VLOOKUP(R14,$AF$3:$AG$9,2,FALSE)+VLOOKUP(W14,$AF$3:$AG$9,2,FALSE) -> 0 | AB14: =Y14+Z14-AA14 -> 12
A15: 28 | B15: Forever`鹿丸 | D15: 0 | E15: 0 | F15: 18000 | G15: 2 | H15: 未分包 | I15: 0 | J15: 2 | K15: 21000 | L15: =I15+J15 -> 2 | M15: 未分包 | N15: 0 | O15: 4 | P15: 12000 | Q15: =N15+O15 -> 4 | R15: 英雄功勋礼包 | S15: 0 | T15: 0 | U15: 12000 | V15: =S15+T15 -> 0 | W15: 未分包 | X15: =G15+L15+Q15+V15 -> 8 | Y15: =X15+F15/10000+K15/10000+P15/10000+U15/10000 -> 14.3 | Z15: ='Sep2019'!AC32 -> 2.04 | AA15: =VLOOKUP(H15,$AF$3:$AG$9,2,FALSE)+VLOOKUP(M15,$AF$3:$AG$9,2,FALSE)+VLOOKUP(R15,$AF$3:$AG$9,2,FALSE)+VLOOKUP(W15,$AF$3:$AG$9,2,FALSE) -> 5 | AB15: =Y15+Z15-AA15 -> 11.34
A16: 72 | B16: Forever`火年 | D16: 0 | E16: 0 | F16: 0 | G16: 0 | H16: 未分包 | I16: 0 | J16: 0 | K16: 4000 | L16: =I16+J16 -> 0 | M16: 未分包 | N16: 0 | O16: 4 | P16: 12000 | Q16: =N16+O16 -> 4 | R16: 未分包 | S16: 0 | T16: 2 | U16: 12000 | V16: =S16+T16 -> 2 | W16: 未分包 | X16: =G16+L16+Q16+V16 -> 6 | Y16: =X16+F16/10000+K16/10000+P16/10000+U16/10000 -> 8.8 | Z16: 2.3142857 | AA16: =VLOOKUP(H16,$AF$3:$AG$9,2,FALSE)+VLOOKUP(M16,$AF$3:$AG$9,2,FALSE)+VLOOKUP(R16,$AF$3:$AG$9,2,FALSE)+VLOOKUP(W16,$AF$3:$AG$9,2,FALSE) -> 0 | AB16: =Y16+Z16-AA16 -> 11.114286
A17: 27 | B17: Forever`為你 | D17: 0 | E17: 0 | F17: 22200 | G17: =D17+E17 -> 0 | H17: 未分包 | I17: 0 | J17: 2 | K17: 13200 | L17: =I17+J17 -> 2 | M17: 未分包 | N17: 0 | O17: 0 | P17: 6000 | Q17: =N17+O17 -> 0 | R17: 未分包 | S17: 0 | T17: 1 | U17: 7600 | V17: =S17+T17 -> 1 | W17: 未分包 | X17: =G17+L17+Q17+V17 -> 3 | Y17: =X17+F17/10000+K17/10000+P17/10000+U17/10000 -> 7.9 | Z17: ='Sep2019'!AC31 -> 3.2 | AA17: =VLOOKUP(H17,$AF$3:$AG$9,2,FALSE)+VLOOKUP(M17,$AF$3:$AG$9,2,FALSE)+VLOOKUP(R17,$AF$3:$AG$9,2,FALSE)+VLOOKUP(W17,$AF$3:$AG$9,2,FALSE) -> 0 | AB17: =Y17+Z17-AA17 -> 11.1
A18: 58 | B18: Forever`大欢 | D18: 0 | E18: 0 | F18: 11000 | G18: 3 | H18: 未分包 | I18: 0 | J18: 3 | K18: 11200 | L18: =I18+J18 -> 3 | M18: 未分包 | N18: 0 | O18: 3 | P18: 9600 | Q18: =N18+O18 -> 3 | R18: 未分包 | S18: 0 | T18: 3 | U18: 12000 | V18: =S18+T18 -> 3 | W18: 跨服传说礼包 | X18: =G18+L18+Q18+V18 -> 12 | Y18: =X18+F18/10000+K18/10000+P18/10000+U18/10000 -> 16.38 | Z18: 3.1828571 | AA18: =VLOOKUP(H18,$AF$3:$AG$9,2,FALSE)+VLOOKUP(M18,$AF$3:$AG$9,2,FALSE)+VLOOKUP(R18,$AF$3:$AG$9,2,FALSE)+VLOOKUP(W18,$AF$3:$AG$9,2,FALSE) -> 8.5 | AB18: =Y18+Z18-AA18 -> 11.062857
A19: 20 | B19: Forever`孤王 | D19: 0 | E19: 0 | F19: 18800 | G19: 1 | H19: 未分包 | I19: 0 | J19: 4 | K19: 9800 | L19: =I19+J19 -> 4 | M19: 英雄功勋礼包 | N19: 0 | O19: 2 | P19: 11000 | Q19: =N19+O19 -> 2 | R19: 未分包 | S19: 0 | T19: 0 | U19: 0 | V19: =S19+T19 -> 0 | W19: 未分包 | X19: =G19+L19+Q19+V19 -> 7 | Y19: =X19+F19/10000+K19/10000+P19/10000+U19/10000 -> 10.96 | Z19: ='Sep2019'!AC24 -> 4.9 | AA19: =VLOOKUP(H19,$AF$3:$AG$9,2,FALSE)+VLOOKUP(M19,$AF$3:$AG$9,2,FALSE)+VLOOKUP(R19,$AF$3:$AG$9,2,FALSE)+VLOOKUP(W19,$AF$3:$AG$9,2,FALSE) -> 5 | AB19: =Y19+Z19-AA19 -> 10.86
A20: 29 | B20: Forever`别吵 | D20: 0 | E20: 0 | F20: 21600 | G20: 4 | H20: 未分包 | I20: 0 | J20: 4 | K20: 12000 | L20: =I20+J20 -> 4 | M20: 英雄功勋礼包 | N20: 0 | O20: 2 | P20: 12000 | Q20: =N20+O20 -> 2 | R20: 未分包 | S20: 0 | T20: 0 | U20: 0 | V20: =S20+T20 -> 0 | W20: 未分包 | X20: =G20+L20+Q20+V20 -> 10 | Y20: =X20+F20/10000+K20/10000+P20/10000+U20/10000 -> 14.56 | Z20: ='Sep2019'!AC33 -> 0.96 | AA20: =VLOOKUP(H20,$AF$3:$AG$9,2,FALSE)+VLOOKUP(M20,$AF$3:$AG$9,2,FALSE)+VLOOKUP(R20,$AF$3:$AG$9,2,FALSE)+VLOOKUP(W20,$AF$3:$AG$9,2,FALSE) -> 5 | AB20: =Y20+Z20-AA20 -> 10.52
A21: 73 | B21: Forever`靓仔 | D21: 0 | E21: 0 | F21: 0 | G21: 0 | H21: 未分包 | I21: 0 | J21: 0 | K21: 4000 | L21: =I21+J21 -> 0 | M21: 未分包 | N21: 0 | O21: 4 | P21: 13200 | Q21: =N21+O21 -> 4 | R21: 未分包 | S21: 0 | T21: 3 | U21: 13200 | V21: =S21+T21 -> 3 | W21: 未分包 | X21: =G21+L21+Q21+V21 -> 7 | Y21: =X21+F21/10000+K21/10000+P21/10000+U21/10000 -> 10.04 | Z21: 0.21785714 | AA21: =VLOOKUP(H21,$AF$3:$AG$9,2,FALSE)+VLOOKUP(M21,$AF$3:$AG$9,2,FALSE)+VLOOKUP(R21,$AF$3:$AG$9,2,FALSE)+VLOOKUP(W21,$AF$3:$AG$9,2,FALSE) -> 0 | AB21: =Y21+Z21-AA21 -> 10.257857
A22: 57 | B22: Forever`习惯 | C22: 习惯 | D22: 0 | E22: 0 | F22: 12000 | G22: 3 | H22: 未分包 | I22: 0 | J22: 4 | K22: 12000 | L22: =I22+J22 -> 4 | M22: 未分包 | N22: 0 | O22: 3 | P22: 12000 | Q22: =N22+O22 -> 3 | R22: 未分包 | S22: 0 | T22: 2 | U22: 12000 | V22: =S22+T22 -> 2 | W22: 跨服传说礼包 | X22: =G22+L22+Q22+V22 -> 12 | Y22: =X22+F22/10000+K22/10000+P22/10000+U22/10000 -> 16.8 | Z22: 1.95 | AA22: =VLOOKUP(H22,$AF$3:$AG$9,2,FALSE)+VLOOKUP(M22,$AF$3:$AG$9,2,FALSE)+VLOOKUP(R22,$AF$3:$AG$9,2,FALSE)+VLOOKUP(W22,$AF$3:$AG$9,2,FALSE) -> 8.5 | AB22: =Y22+Z22-AA22 -> 10.25
A23: 88 | B23: 钊_ | D23: 0 | E23: 0 | F23: 0 | G23: 0 | H23: 未分包 | I23: 0 | J23: 0 | K23: 0 | L23: =I23+J23 -> 0 | M23: 未分包 | N23: 0 | O23: 0 | P23: 0 | Q23: =N23+O23 -> 0 | R23: 未分包 | S23: 0 | T23: 1 | U23: 9000 | V23: =S23+T23 -> 1 | W23: 未分包 | X23: =G23+L23+Q23+V23 -> 1 | Y23: =X23+F23/10000+K23/10000+P23/10000+U23/10000 -> 1.9 | Z23: 8.2 | AA23: =VLOOKUP(H23,$AF$3:$AG$9,2,FALSE)+VLOOKUP(M23,$AF$3:$AG$9,2,FALSE)+VLOOKUP(R23,$AF$3:$AG$9,2,FALSE)+VLOOKUP(W23,$AF$3:$AG$9,2,FALSE) -> 0 | AB23: =Y23+Z23-AA23 -> 10.1 | AC23: 40 | AD23: 8.2
A24: 80 | B24: Forever`丝控 | D24: 0 | E24: 0 | F24: 0 | G24: 0 | H24: 未分包 | I24: 0 | J24: 0 | K24: 2000 | L24: =I24+J24 -> 0 | M24: 未分包 | N24: 0 | O24: 3 | P24: 12000 | Q24: =N24+O24 -> 3 | R24: 未分包 | S24: 0 | T24: 2 | U24: 12000 | V24: =S24+T24 -> 2 | W24: 未分包 | X24: =G24+L24+Q24+V24 -> 5 | Y24: =X24+F24/10000+K24/10000+P24/10000+U24/10000 -> 7.6 | Z24: 2.2446429 | AA24: =VLOOKUP(H24,$AF$3:$AG$9,2,FALSE)+VLOOKUP(M24,$AF$3:$AG$9,2,FALSE)+VLOOKUP(R24,$AF$3:$AG$9,2,FALSE)+VLOOKUP(W24,$AF$3:$AG$9,2,FALSE) -> 0 | AB24: =Y24+Z24-AA24 -> 9.8446429
A25: 53 | B25: Forever`清风 | D25: 0 | E25: 0 | F25: 16200 | G25: 4 | H25: 未分包 | I25: 0 | J25: 4 | K25: 12600 | L25: =I25+J25 -> 4 | M25: 传说功勋礼包 | N25: 0 | O25: 4 | P25: 12000 | Q25: =N25+O25 -> 4 | R25: 未分包 | S25: 0 | T25: 3 | U25: 12000 | V25: =S25+T25 -> 3 | W25: 跨服英雄礼包 | X25: =G25+L25+Q25+V25 -> 15 | Y25: =X25+F25/10000+K25/10000+P25/10000+U25/10000 -> 20.28 | Z25: ='Sep2019'!AC57 -> 3.06 | AA25: =VLOOKUP(H25,$AF$3:$AG$9,2,FALSE)+VLOOKUP(M25,$AF$3:$AG$9,2,FALSE)+VLOOKUP(R25,$AF$3:$AG$9,2,FALSE)+VLOOKUP(W25,$AF$3:$AG$9,2,FALSE) -> 13.5 | AB25: =Y25+Z25-AA25 -> 9.84
A26: 34 | B26: Forever`劳模 | D26: 0 | E26: 0 | F26: 12000 | G26: 4 | H26: 未分包 | I26: 0 | J26: 3 | K26: 12000 | L26: =I26+J26 -> 3 | M26: 未分包 | N26: 0 | O26: 3 | P26: 12000 | Q26: =N26+O26 -> 3 | R26: 未分包 | S26: 0 | T26: 3 | U26: 12000 | V26: =S26+T26 -> 3 | W26: 跨服传说礼包 | X26: =G26+L26+Q26+V26 -> 13 | Y26: =X26+F26/10000+K26/10000+P26/10000+U26/10000 -> 17.8 | Z26: ='Sep2019'!AC38 -> 0.4 | AA26: =VLOOKUP(H26,$AF$3:$AG$9,2,FALSE)+VLOOKUP(M26,$AF$3:$AG$9,2,FALSE)+VLOOKUP(R26,$AF$3:$AG$9,2,FALSE)+VLOOKUP(W26,$AF$3:$AG$9,2,FALSE) -> 8.5 | AB26: =Y26+Z26-AA26 -> 9.7
A27: 5 | B27: Forever`輪回 | D27: 0 | E27: 0 | F27: 12000 | G27: 3 | H27: 未分包 | I27: 0 | J27: 4 | K27: 12000 | L27: =I27+J27 -> 4 | M27: 传说功勋礼包 | N27: 0 | O27: 4 | P27: 9000 | Q27: =N27+O27 -> 4 | R27: 未分包 | S27: 0 | T27: 3 | U27: 6000 | V27: =S27+T27 -> 3 | W27: 跨服英雄礼包 | X27: =G27+L27+Q27+V27 -> 14 | Y27: =X27+F27/10000+K27/10000+P27/10000+U27/10000 -> 17.9 | Z27: ='Sep2019'!AC9 -> 5.2 | AA27: =VLOOKUP(H27,$AF$3:$AG$9,2,FALSE)+VLOOKUP(M27,$AF$3:$AG$9,2,FALSE)+VLOOKUP(R27,$AF$3:$AG$9,2,FALSE)+VLOOKUP(W27,$AF$3:$AG$9,2,FALSE) -> 13.5 | AB27: =Y27+Z27-AA27 -> 9.6
A28: 89 | B28: Forever`阿呆 | D28: 0 | E28: 0 | F28: 0 | G28: 0 | H28: 未分包 | I28: 0 | J28: 0 | K28: 0 | L28: =I28+J28 -> 0 | M28: 未分包 | N28: 0 | O28: 0 | P28: 0 | Q28: =N28+O28 -> 0 | R28: 未分包 | S28: 0 | T28: 0 | U28: 11000 | V28: =S28+T28 -> 0 | W28: 未分包 | X28: =G28+L28+Q28+V28 -> 0 | Y28: =X28+F28/10000+K28/10000+P28/10000+U28/10000 -> 1.1 | Z28: 8.5 | AA28: =VLOOKUP(H28,$AF$3:$AG$9,2,FALSE)+VLOOKUP(M28,$AF$3:$AG$9,2,FALSE)+VLOOKUP(R28,$AF$3:$AG$9,2,FALSE)+VLOOKUP(W28,$AF$3:$AG$9,2,FALSE) -> 0 | AB28: =Y28+Z28-AA28 -> 9.6 | AC28: 38 | AD28: 8.5
A29: 10 | B29: Forever`随风 | D29: 0 | E29: 0 | F29: 28200 | G29: 4 | H29: 传说功勋礼包 | I29: 0 | J29: 4 | K29: 18600 | L29: =I29+J29 -> 4 | M29: 精英功勋礼包 | N29: 0 | O29: 4 | P29: 16200 | Q29: =N29+O29 -> 4 | R29: 精英功勋礼包 | S29: 0 | T29: 3 | U29: 13200 | V29: =S29+T29 -> 3 | W29: 跨服精英礼包 | X29: =G29+L29+Q29+V29 -> 15 | Y29: =X29+F29/10000+K29/10000+P29/10000+U29/10000 -> 22.62 | Z29: ='Sep2019'!AC14 -> 5.96 | AA29: =VLOOKUP(H29,$AF$3:$AG$9,2,FALSE)+VLOOKUP(M29,$AF$3:$AG$9,2,FALSE)+VLOOKUP(R29,$AF$3:$AG$9,2,FALSE)+VLOOKUP(W29,$AF$3:$AG$9,2,FALSE) -> 19 | AB29: =Y29+Z29-AA29 -> 9.58
A30: 35 | B30: 神罗天征 | D30: 0 | E30: 0 | F30: 0 | G30: =D30+E30 -> 0 | H30: 未分包 | I30: 0 | J30: 0 | K30: 0 | L30: =I30+J30 -> 0 | M30: 未分包 | N30: 0 | O30: 0 | P30: 0 | Q30: =N30+O30 -> 0 | R30: 未分包 | S30: 0 | T30: 0 | U30: 0 | V30: =S30+T30 -> 0 | W30: 未分包 | X30: =G30+L30+Q30+V30 -> 0 | Y30: =X30+F30/10000+K30/10000+P30/10000+U30/10000 -> 0 | Z30: ='Sep2019'!AC39 -> 0.2 | AA30: =VLOOKUP(H30,$AF$3:$AG$9,2,FALSE)+VLOOKUP(M30,$AF$3:$AG$9,2,FALSE)+VLOOKUP(R30,$AF$3:$AG$9,2,FALSE)+VLOOKUP(W30,$AF$3:$AG$9,2,FALSE) -> 0 | AB30: =Y30+Z30-AA30 -> 0.2
A31: 8 | B31: Forever`法师 | C31: Forever`了佳 | D31: 0 | E31: 0 | F31: 17400 | G31: 4 | H31: 英雄功勋礼包 | I31: 0 | J31: 4 | K31: 12000 | L31: =I31+J31 -> 4 | M31: 未分包 | N31: 0 | O31: 4 | P31: 12000 | Q31: =N31+O31 -> 4 | R31: 英雄功勋礼包 | S31: 0 | T31: 3 | U31: 11000 | V31: =S31+T31 -> 3 | W31: 跨服精英礼包 | X31: =G31+L31+Q31+V31 -> 15 | Y31: =X31+F31/10000+K31/10000+P31/10000+U31/10000 -> 20.24 | Z31: ='Sep2019'!AC12 -> 4.82 | AA31: =VLOOKUP(H31,$AF$3:$AG$9,2,FALSE)+VLOOKUP(M31,$AF$3:$AG$9,2,FALSE)+VLOOKUP(R31,$AF$3:$AG$9,2,FALSE)+VLOOKUP(W31,$AF$3:$AG$9,2,FALSE) -> 15.5 | AB31: =Y31+Z31-AA31 -> 9.56
A32: 43 | B32: Forever`阿良 | D32: 0 | E32: 0 | F32: 30000 | G32: 3 | H32: 未分包 | I32: 0 | J32: 4 | K32: 30000 | L32: =I32+J32 -> 4 | M32: 传说功勋礼包 | N32: 0 | O32: 4 | P32: 30000 | Q32: =N32+O32 -> 4 | R32: 英雄功勋礼包 | S32: 0 | T32: 3 | U32: 12000 | V32: =S32+T32 -> 3 | W32: 跨服精英礼包 | X32: =G32+L32+Q32+V32 -> 14 | Y32: =X32+F32/10000+K32/10000+P32/10000+U32/10000 -> 24.2 | Z32: ='Sep2019'!AC47 -> 2.3 | AA32: =VLOOKUP(H32,$AF$3:$AG$9,2,FALSE)+VLOOKUP(M32,$AF$3:$AG$9,2,FALSE)+VLOOKUP(R32,$AF$3:$AG$9,2,FALSE)+VLOOKUP(W32,$AF$3:$AG$9,2,FALSE) -> 17 | AB32: =Y32+Z32-AA32 -> 9.5
A33: 69 | B33: Forever`时光 | D33: 0 | E33: 0 | F33: 0 | G33: 0 | H33: 未分包 | I33: 0 | J33: 4 | K33: 9200 | L33: =I33+J33 -> 4 | M33: 未分包 | N33: 0 | O33: 4 | P33: 12000 | Q33: =N33+O33 -> 4 | R33: 未分包 | S33: 0 | T33: 3 | U33: 12000 | V33: =S33+T33 -> 3 | W33: 跨服精英礼包 | X33: =G33+L33+Q33+V33 -> 11 | Y33: =X33+F33/10000+K33/10000+P33/10000+U33/10000 -> 14.32 | Z33: 0.5525 | AA33: =VLOOKUP(H33,$AF$3:$AG$9,2,FALSE)+VLOOKUP(M33,$AF$3:$AG$9,2,FALSE)+VLOOKUP(R33,$AF$3:$AG$9,2,FALSE)+VLOOKUP(W33,$AF$3:$AG$9,2,FALSE) -> 5.5 | AB33: =Y33+Z33-AA33 -> 9.3725
A34: 46 | B34: Forever`帆锅 | D34: 0 | E34: 0 | F34: 16800 | G34: 3 | H34: 精英功勋礼包 | I34: 0 | J34: 4 | K34: 16200 | L34: =I34+J34 -> 4 | M34: 精英功勋礼包 | N34: 0 | O34: 4 | P34: 17400 | Q34: =N34+O34 -> 4 | R34: 精英功勋礼包 | S34: 0 | T34: 3 | U34: 12000 | V34: =S34+T34 -> 3 | W34: 跨服精英礼包 | X34: =G34+L34+Q34+V34 -> 14 | Y34: =X34+F34/10000+K34/10000+P34/10000+U34/10000 -> 20.24 | Z34: ='Sep2019'!AC50 -> 5.06 | AA34: =VLOOKUP(H34,$AF$3:$AG$9,2,FALSE)+VLOOKUP(M34,$AF$3:$AG$9,2,FALSE)+VLOOKUP(R34,$AF$3:$AG$9,2,FALSE)+VLOOKUP(W34,$AF$3:$AG$9,2,FALSE) -> 16 | AB34: =Y34+Z34-AA34 -> 9.3
A35: 12 | B35: Forever`仙尊 | D35: 0 | E35: 0 | F35: 19200 | G35: 4 | H35: 英雄功勋礼包 | I35: 0 | J35: 4 | K35: 12000 | L35: =I35+J35 -> 4 | M35: 精英功勋礼包 | N35: 0 | O35: 4 | P35: 12000 | Q35: =N35+O35 -> 4 | R35: 未分包 | S35: 0 | T35: 3 | U35: 12000 | V35: =S35+T35 -> 3 | W35: 跨服传说礼包 | X35: =G35+L35+Q35+V35 -> 15 | Y35: =X35+F35/10000+K35/10000+P35/10000+U35/10000 -> 20.52 | Z35: ='Sep2019'!AC16 -> 5.7 | AA35: =VLOOKUP(H35,$AF$3:$AG$9,2,FALSE)+VLOOKUP(M35,$AF$3:$AG$9,2,FALSE)+VLOOKUP(R35,$AF$3:$AG$9,2,FALSE)+VLOOKUP(W35,$AF$3:$AG$9,2,FALSE) -> 17 | AB35: =Y35+Z35-AA35 -> 9.22
A36: 23 | B36: Forever`三傻 | D36: 0 | E36: 0 | F36: 17800 | G36: 4 | H36: 英雄功勋礼包 | I36: 0 | J36: 4 | K36: 19000 | L36: =I36+J36 -> 4 | M36: 未分包 | N36: 0 | O36: 4 | P36: 6000 | Q36: =N36+O36 -> 4 | R36: 英雄功勋礼包 | S36: 0 | T36: 3 | U36: 6000 | V36: =S36+T36 -> 3 | W36: 跨服精英礼包 | X36: =G36+L36+Q36+V36 -> 15 | Y36: =X36+F36/10000+K36/10000+P36/10000+U36/10000 -> 19.88 | Z36: ='Sep2019'!AC27 -> 4.8 | AA36: =VLOOKUP(H36,$AF$3:$AG$9,2,FALSE)+VLOOKUP(M36,$AF$3:$AG$9,2,FALSE)+VLOOKUP(R36,$AF$3:$AG$9,2,FALSE)+VLOOKUP(W36,$AF$3:$AG$9,2,FALSE) -> 15.5 | AB36: =Y36+Z36-AA36 -> 9.18
A37: 16 | B37: Forever`啾啾 | D37: 0 | E37: 0 | F37: 16200 | G37: 4 | H37: 精英功勋礼包 | I37: 0 | J37: 3 | K37: 18000 | L37: =I37+J37 -> 3 | M37: 未分包 | N37: 0 | O37: 4 | P37: 13800 | Q37: =N37+O37 -> 4 | R37: 传说功勋礼包 | S37: 0 | T37: 3 | U37: 13200 | V37: =S37+T37 -> 3 | W37: 跨服精英礼包 | X37: =G37+L37+Q37+V37 -> 14 | Y37: =X37+F37/10000+K37/10000+P37/10000+U37/10000 -> 20.12 | Z37: ='Sep2019'!AC20 -> 4.5 | AA37: =VLOOKUP(H37,$AF$3:$AG$9,2,FALSE)+VLOOKUP(M37,$AF$3:$AG$9,2,FALSE)+VLOOKUP(R37,$AF$3:$AG$9,2,FALSE)+VLOOKUP(W37,$AF$3:$AG$9,2,FALSE) -> 15.5 | AB37: =Y37+Z37-AA37 -> 9.12
