Workbook

Sheet main
A1: =(_xlfn.DAYS(TODAY(),A4)+2)/((_xlfn.DAYS(A93,A4))+1) -> 0.066666667 | I1: 工作区
D2: 合计经验 | F2: =SUM(F4:F93)+SUM(H4:H93) -> 63460 | I2: 队伍一 火 | K2: 步数 | L2: =COUNTIF(I4:P93,"<>空") -> 98 | M2: (不算跳步和传送) | Q2: 队伍二 雷 | S2: 步数 | T2: =COUNTIF(Q4:X93,"<>空") -> 508 | U2: (不算跳步和传送) | Y2: 队伍三 | AA2: 总步数 | AB2: =COUNTIF(Y4:AF93,"<>空") -> 439 | AC2: (不算跳步和传送) | AG2: =SUM(AG4:AG93) -> 81 | AH2: =SUM(AH4:AH93) -> 10 | AI2: =SUM(AI4:AI93) -> 58 | AJ2: =SUM(AJ4:AJ93) -> 13 | AK2: 八卦全开 | AU2: 总地块 | AV2: =SUM(AV4:AV29) -> 1045 | AW2: 剩余粮草 | AX2: =AR47 -> 124 | AY2: 总经验 | AZ2: =SUM(AX4:AZ29)+7000 -> 63460 | BB2: 粮草系数
A3: 日期 | B3: 获得粮草 | C3: 粮草调整 | D3: 消耗粮草 | E3: 剩余粮草 | F3: 获得经验 | G3: 累计经验 | H3: 任务经验 | I3: 1 | J3: 2 | K3: 3 | L3: 4 | M3: 5 | N3: 6 | O3: 7 | P3: 8 | Q3: 1 | R3: 2 | S3: 3 | T3: 4 | U3: 5 | V3: 6 | W3: 7 | X3: 8 | Y3: 1 | Z3: 2 | AA3: 3 | AB3: 4 | AC3: 5 | AD3: 6 | AE3: 7 | AF3: 8 | AG3: 跳步次数 | AH3: 1队跳步 | AI3: 2队跳步 | AJ3: 3队跳步 | AL3: 1队剩步 | AM3: 2队剩步 | AN3: 3队剩步 | AO3: 地块 | AP3: 粮草 | AQ3: 经验 | AR3: 八卦前亏损 | AS3: 一队地块 | AT3: 二队地块 | AU3: 三队地块 | AV3: 总地块 | AX3: 一队经验 | AY3: 二队经验 | AZ3: 三队经验 | BA3: 八卦前 | BB3: 1 | BD3: 亏损
A4: 46185 | B4: 800 | C4: 6000 | D4: =(SUM(粮草!A4:X4)+AG4*10*IF(AK4="是",$BB$4,$BB$3)) -> 2860 | E4: =SUM($B$4:B4)+SUM($C$4:C4)-SUM($D$4:D4) -> 3940 | F4: =SUM(经验!A4:X4) -> 820 | G4: =SUM($F$4:F4)+SUM($H$4:H4) -> 1320 | H4: 500 | I4: 1级 | J4: 1级 | K4: 1级 | L4: 1级 | M4: 1级 | N4: 1级 | O4: 1级 | P4: 1级 | Q4: 商人 | R4: 商人 | S4: 商人 | T4: 商人 | U4: 商人 | V4: 商人 | W4: 空 | X4: 空 | Y4: 3级 | Z4: 3级 | AA4: 3级 | AB4: 3级 | AC4: 3级 | AD4: 3级 | AE4: 3级 | AF4: 3级 | AG4: =AH4+AI4+AJ4 -> 0 | AK4: 否 | AL4: 0 | AM4: 0 | AN4: 0 | AO4: 1级 | AP4: 150 | AQ4: 35 | AR4: 44.222109 | AS4: =COUNTIF($I$4:$P$93,AO4) -> 20 | AT4: =COUNTIF($Q$4:$X$93,AO4) -> 0 | AU4: =COUNTIF($Y$4:$AF$93,AO4) -> 0 | AV4: =AS4+AT4+AU4 -> 20 | AX4: =AS4*$AQ4 -> 700 | AY4: =AT4*$AQ4 -> 0 | AZ4: =AU4*$AQ4 -> 0 | BA4: 八卦后 | BB4: 0.8 | BD4: =AR4*AV4 -> 884.44219
A5: 46186 | B5: 1600 | D5: =(SUM(粮草!A5:X5)+AG5*10*IF(AK5="是",$BB$4,$BB$3)) -> 3070 | E5: =SUM($B$4:B5)+SUM($C$4:C5)-SUM($D$4:D5) -> 2470 | F5: =SUM(经验!A5:X5) -> 835 | G5: =SUM($F$4:F5)+SUM($H$4:H5) -> 2155 | H5: 0 | I5: 1级 | J5: 1级 | K5: 1级 | L5: 1级 | M5: 1级 | N5: 1级 | O5: 1级 | P5: 1级 | Q5: 塔2 | R5: 草2 | S5: 草2 | T5: 草2 | U5: 营地 | V5: 塔1 | W5: 空 | X5: 空 | Y5: 3级 | Z5: 3级 | AA5: 3级 | AB5: 3级 | AC5: 3级 | AD5: 3级 | AE5: 3级 | AF5: 3级 | AG5: =AH5+AI5+AJ5 -> 0 | AK5: 否 | AL5: 0 | AM5: 0 | AN5: 0 | AO5: 2级 | AP5: 160 | AQ5: 40 | AR5: 39.110982 | AS5: =COUNTIF($I$4:$P$93,AO5) -> 53 | AT5: =COUNTIF($Q$4:$X$93,AO5) -> 0 | AU5: =COUNTIF($Y$4:$AF$93,AO5) -> 0 | AV5: =AS5+AT5+AU5 -> 53 | AX5: =AS5*$AQ5 -> 2120 | AY5: =AT5*$AQ5 -> 0 | AZ5: =AU5*$AQ5 -> 0 | BA5: Note：开完八卦当天可能需要手动计算粮草 | BD5: =AR5*AV5 -> 2072.8821
A6: 46187 | B6: 1600 | D6: =(SUM(粮草!A6:X6)+AG6*10*IF(AK6="是",$BB$4,$BB$3)) -> 3090 | E6: =SUM($B$4:B6)+SUM($C$4:C6)-SUM($D$4:D6) -> 980 | F6: =SUM(经验!A6:X6) -> 800 | G6: =SUM($F$4:F6)+SUM($H$4:H6) -> 2955 | H6: 0 | I6: 2级 | J6: 2级 | K6: 2级 | L6: 2级 | M6: 2级 | N6: 2级 | O6: 2级 | P6: 2级 | Q6: 空 | R6: 草2 | S6: 草2 | T6: 草2 | U6: 空 | V6: 空 | W6: 空 | X6: 空 | Y6: 3级 | Z6: 3级 | AA6: 3级 | AB6: 3级 | AC6: 3级 | AD6: 3级 | AE6: 3级 | AF6: 3级 | AG6: =AH6+AI6+AJ6 -> 0 | AK6: 否 | AL6: 0 | AM6: 0 | AN6: 0 | AO6: 3级 | AP6: 170 | AQ6: 45 | AR6: 34 | AS6: =COUNTIF($I$4:$P$93,AO6) -> 0 | AT6: =COUNTIF($Q$4:$X$93,AO6) -> 36 | AU6: =COUNTIF($Y$4:$AF$93,AO6) -> 140 | AV6: =AS6+AT6+AU6 -> 176 | AX6: =AS6*$AQ6 -> 0 | AY6: =AT6*$AQ6 -> 1620 | AZ6: =AU6*$AQ6 -> 6300 | BD6: =AR6*AV6 -> 5984
A7: 46188 | B7: 1600 | D7: =(SUM(粮草!A7:X7)+AG7*10*IF(AK7="是",$BB$4,$BB$3)) -> 2890 | E7: =SUM($B$4:B7)+SUM($C$4:C10)-SUM($D$4:D7) -> -1180 | F7: =SUM(经验!A7:X7) -> 830 | G7: =SUM($F$4:F7)+SUM($H$4:H7) -> 3985 | H7: 200 | I7: 2级 | J7: 2级 | K7: 2级 | L7: 2级 | M7: 2级 | N7: 2级 | O7: 2级 | P7: 2级 | Q7: 商人 | R7: 商人 | S7: 商人 | T7: 商人 | U7: 商人 | V7: 空 | W7: 空 | X7: 空 | Y7: 3级 | Z7: 3级 | AA7: 3级 | AB7: 3级 | AC7: 3级 | AD7: 3级 | AE7: 3级 | AF7: 3级 | AG7: =AH7+AI7+AJ7 -> 0 | AK7: 否 | AL7: 18 | AM7: 18 | AN7: 0 | AO7: 4级 | AP7: 180 | AQ7: 50 | AR7: 36 | AS7: =COUNTIF($I$4:$P$93,AO7) -> 0 | AT7: =COUNTIF($Q$4:$X$93,AO7) -> 244 | AU7: =COUNTIF($Y$4:$AF$93,AO7) -> 16 | AV7: =AS7+AT7+AU7 -> 260 | AX7: =AS7*$AQ7 -> 0 | AY7: =AT7*$AQ7 -> 12200 | AZ7: =AU7*$AQ7 -> 800 | BD7: =AR7*AV7 -> 9360
A8: 46189 | B8: 1600 | D8: =(SUM(粮草!A8:X8)+AG8*10*IF(AK8="是",$BB$4,$BB$3)) -> 1020 | E8: =SUM($B$4:B8)+SUM($C$4:C8)-SUM($D$4:D8) -> 270 | F8: =SUM(经验!A8:X8) -> 400 | G8: =SUM($F$4:F8)+SUM($H$4:H8) -> 4685 | H8: 300 | I8: 2级 | J8: 空 | K8: 空 | L8: 空 | M8: 空 | N8: 空 | O8: 空 | P8: 空 | Q8: 营地 | R8: 营地 | S8: 空 | T8: 空 | U8: 空 | V8: 空 | W8: 空 | X8: 空 | Y8: 3级 | Z8: 3级 | AA8: 3级 | AB8: 3级 | AC8: 3级 | AD8: 3级 | AE8: 3级 | AF8: 3级 | AG8: =AH8+AI8+AJ8 -> 0 | AK8: 否 | AL8: =MIN(AL7+6,18)-COUNTIF(I8:P8,"<>空")+COUNTIF(I8:P8,"历练")+COUNTIF(I8:P8,"营地")*2+COUNTIF(I8:P8,"塔1")*5 -> 17 | AM8: =MIN(AM7+6,18)-COUNTIF(Q8:X8,"<>空")+COUNTIF(Q8:X8,"历练")+COUNTIF(Q8:X8,"营地")*2+COUNTIF(Q8:X8,"塔1")*5 -> 20 | AN8: =MIN(AN7+6,18)-COUNTIF(Y8:AF8,"<>空")+COUNTIF(Y8:AF8,"历练")+COUNTIF(Y8:AF8,"营地")*2+COUNTIF(Y8:AF8,"塔1")*5 -> -2 | AO8: 5级 | AP8: 190 | AQ8: 55 | AR8: 38 | AS8: =COUNTIF($I$4:$P$93,AO8) -> 2 | AT8: =COUNTIF($Q$4:$X$93,AO8) -> 101 | AU8: =COUNTIF($Y$4:$AF$93,AO8) -> 120 | AV8: =AS8+AT8+AU8 -> 223 | AX8: =AS8*$AQ8 -> 110 | AY8: =AT8*$AQ8 -> 5555 | AZ8: =AU8*$AQ8 -> 6600 | BD8: =AR8*AV8 -> 8474
A9: 46190 | B9: 1600 | D9: =(SUM(粮草!A9:X9)+AG9*10*IF(AK9="是",$BB$4,$BB$3)) -> 1990 | E9: =SUM($B$4:B9)+SUM($C$4:C9)-SUM($D$4:D9) -> -120 | F9: =SUM(经验!A9:X9) -> 555 | G9: =SUM($F$4:F9)+SUM($H$4:H9) -> 5240 | H9: 0 | I9: 空 | J9: 空 | K9: 空 | L9: 空 | M9: 空 | N9: 空 | O9: 空 | P9: 空 | Q9: 3级卦 | R9: 3级卦 | S9: 3级卦 | T9: 3级卦 | U9: 3级卦 | V9: 空 | W9: 空 | X9: 空 | Y9: 5级 | Z9: 5级 | AA9: 5级 | AB9: 5级 | AC9: 5级 | AD9: 5级 | AE9: 空 | AF9: 空 | AG9: =AH9+AI9+AJ9 -> 0 | AK9: 否 | AL9: =MIN(AL8+6,18)-COUNTIF(I9:P9,"<>空")+COUNTIF(I9:P9,"历练")+COUNTIF(I9:P9,"营地")*2+COUNTIF(I9:P9,"塔1")*5 -> 18 | AM9: =MIN(AM8+6,18)-COUNTIF(Q9:X9,"<>空")+COUNTIF(Q9:X9,"历练")+COUNTIF(Q9:X9,"营地")*2+COUNTIF(Q9:X9,"塔1")*5 -> 13 | AN9: =MIN(AN8+6,18)-COUNTIF(Y9:AF9,"<>空")+COUNTIF(Y9:AF9,"历练")+COUNTIF(Y9:AF9,"营地")*2+COUNTIF(Y9:AF9,"塔1")*5 -> -2 | AO9: 6级 | AP9: 200 | AQ9: 60 | AR9: 40 | AS9: =COUNTIF($I$4:$P$93,AO9) -> 0 | AT9: =COUNTIF($Q$4:$X$93,AO9) -> 55 | AU9: =COUNTIF($Y$4:$AF$93,AO9) -> 131 | AV9: =AS9+AT9+AU9 -> 186 | AX9: =AS9*$AQ9 -> 0 | AY9: =AT9*$AQ9 -> 3300 | AZ9: =AU9*$AQ9 -> 7860 | BD9: =AR9*AV9 -> 7440
A10: 46191 | B10: 1600 | C10: -870 | D10: =(SUM(粮草!A10:X10)+AG10*10*IF(AK10="是",$BB$4,$BB$3)) -> 800 | E10: =SUM($B$4:B10)+SUM($C$4:C10)-SUM($D$4:D10) -> -190 | F10: =SUM(经验!A10:X10) -> 1420 | G10: =SUM($F$4:F10)+SUM($H$4:H10) -> 6660 | H10: 0 | I10: 空 | J10: 空 | K10: 空 | L10: 空 | M10: 空 | N10: 空 | O10: 空 | P10: 空 | Q10: 大卦 | R10: 大卦 | S10: 大卦 | T10: 历练 | U10: 空 | V10: 空 | W10: 空 | X10: 空 | Y10: 空 | Z10: 空 | AA10: 空 | AB10: 空 | AC10: 空 | AD10: 空 | AE10: 空 | AF10: 空 | AG10: =AH10+AI10+AJ10 -> 0 | AK10: 否 | AL10: =MIN(AL9+6,18)-COUNTIF(I10:P10,"<>空")+COUNTIF(I10:P10,"历练")+COUNTIF(I10:P10,"营地")*2+COUNTIF(I10:P10,"塔1")*5 -> 18 | AM10: =MIN(AM9+6,18)-COUNTIF(Q10:X10,"<>空")+COUNTIF(Q10:X10,"历练")+COUNTIF(Q10:X10,"营地")*2+COUNTIF(Q10:X10,"塔1")*5 -> 15 | AN10: =MIN(AN9+6,18)-COUNTIF(Y10:AF10,"<>空")+COUNTIF(Y10:AF10,"历练")+COUNTIF(Y10:AF10,"营地")*2+COUNTIF(Y10:AF10,"塔1")*5 -> 4 | AO10: 草1 | AP10: 150 | AQ10: 35 | AR10: 44.222109 | AS10: =COUNTIF($I$4:$P$93,AO10) -> 0 | AT10: =COUNTIF($Q$4:$X$93,AO10) -> 0 | AU10: =COUNTIF($Y$4:$AF$93,AO10) -> 0 | AV10: =AS10+AT10+AU10 -> 0 | AX10: =AS10*$AQ10 -> 0 | AY10: =AT10*$AQ10 -> 0 | AZ10: =AU10*$AQ10 -> 0 | BD10: =AR10*AV10 -> 0
A11: 46192 | B11: 1600 | D11: =(SUM(粮草!A11:X11)+AG11*10*IF(AK11="是",$BB$4,$BB$3)) -> 2652 | E11: =SUM($B$4:B11)+SUM($C$4:C11)-SUM($D$4:D11) -> -1242 | F11: =SUM(经验!A11:X11) -> 1020 | G11: =SUM($F$4:F11)+SUM($H$4:H11) -> 7680 | H11: 0 | I11: 5级 | J11: 5级 | K11: 2级 | L11: 2级 | M11: 2级 | N11: 商人 | O11: 2级 | P11: 空 | Q11: 5级 | R11: 5级 | S11: 草5 | T11: 5级 | U11: 5级 | V11: 商人 | W11: 4级 | X11: 4级 | Y11: 3级 | Z11: 3级 | AA11: 3级 | AB11: 营地 | AC11: 3级 | AD11: 3级 | AE11: 3级 | AF11: 3级 | AG11: =AH11+AI11+AJ11 -> 6 | AH11: 6 | AK11: 是 | AL11: =MIN(AL10+6,18)-COUNTIF(I11:P11,"<>空")+COUNTIF(I11:P11,"历练")+COUNTIF(I11:P11,"营地")*2+COUNTIF(I11:P11,"塔1")*5 -> 11 | AM11: =MIN(AM10+6,18)-COUNTIF(Q11:X11,"<>空")+COUNTIF(Q11:X11,"历练")+COUNTIF(Q11:X11,"营地")*2+COUNTIF(Q11:X11,"塔1")*5 -> 10 | AN11: =MIN(AN10+6,18)-COUNTIF(Y11:AF11,"<>空")+COUNTIF(Y11:AF11,"历练")+COUNTIF(Y11:AF11,"营地")*2+COUNTIF(Y11:AF11,"塔1")*5 -> 4 | AO11: 草2 | AP11: 150 | AQ11: 40 | AR11: 29.110982 | AS11: =COUNTIF($I$4:$P$93,AO11) -> 10 | AT11: =COUNTIF($Q$4:$X$93,AO11) -> 19 | AU11: =COUNTIF($Y$4:$AF$93,AO11) -> 14 | AV11: =AS11+AT11+AU11 -> 43 | AX11: =AS11*$AQ11 -> 400 | AY11: =AT11*$AQ11 -> 760 | AZ11: =AU11*$AQ11 -> 560 | BD11: =AR11*AV11 -> 1251.7722
A12: 46193 | B12: 1600 | D12: =(SUM(粮草!A12:X12)+AG12*10*IF(AK12="是",$BB$4,$BB$3)) -> 1560 | E12: =SUM($B$4:B12)+SUM($C$4:C12)-SUM($D$4:D12) -> -1202 | F12: =SUM(经验!A12:X12) -> 700 | G12: =SUM($F$4:F12)+SUM($H$4:H12) -> 8380 | H12: 0 | I12: 2级 | J12: 2级 | K12: 营地 | L12: 草2 | M12: 2级 | N12: 草2 | O12: 2级 | P12: 2级 | Q12: 5级 | R12: 营地 | S12: 空 | T12: 空 | U12: 空 | V12: 空 | W12: 空 | X12: 空 | Y12: 3级 | Z12: 3级 | AA12: 3级 | AB12: 商人 | AC12: 3级 | AD12: 3级 | AE12: 5级 | AF12: 5级 | AG12: =AH12+AI12+AJ12 -> 3 | AH12: 3 | AK12: 是 | AL12: =MIN(AL11+6,18)-COUNTIF(I12:P12,"<>空")+COUNTIF(I12:P12,"历练")+COUNTIF(I12:P12,"营地")*2+COUNTIF(I12:P12,"塔1")*5 -> 11 | AM12: =MIN(AM11+6,18)-COUNTIF(Q12:X12,"<>空")+COUNTIF(Q12:X12,"历练")+COUNTIF(Q12:X12,"营地")*2+COUNTIF(Q12:X12,"塔1")*5 -> 16 | AN12: =MIN(AN11+6,18)-COUNTIF(Y12:AF12,"<>空")+COUNTIF(Y12:AF12,"历练")+COUNTIF(Y12:AF12,"营地")*2+COUNTIF(Y12:AF12,"塔1")*5 -> 2 | AO12: 草3 | AP12: 150 | AQ12: 45 | AR12: 13.999855 | AS12: =COUNTIF($I$4:$P$93,AO12) -> 0 | AT12: =COUNTIF($Q$4:$X$93,AO12) -> 1 | AU12: =COUNTIF($Y$4:$AF$93,AO12) -> 3 | AV12: =AS12+AT12+AU12 -> 4 | AX12: =AS12*$AQ12 -> 0 | AY12: =AT12*$AQ12 -> 45 | AZ12: =AU12*$AQ12 -> 135 | BD12: =AR12*AV12 -> 55.99942
A13: 46194 | B13: 1600 | D13: =(SUM(粮草!A13:X13)+AG13*10*IF(AK13="是",$BB$4,$BB$3)) -> 8 | E13: =SUM($B$4:B13)+SUM($C$4:C13)-SUM($D$4:D13) -> 390 | F13: =SUM(经验!A13:X13) -> 175 | G13: =SUM($F$4:F13)+SUM($H$4:H13) -> 8555 | H13: 0 | I13: 草2 | J13: 2级 | K13: 2级 | L13: 营地 | M13: 空 | N13: 空 | O13: 空 | P13: 空 | Q13: 空 | R13: 空 | S13: 空 | T13: 空 | U13: 空 | V13: 空 | W13: 空 | X13: 空 | Y13: 5级 | Z13: 营地 | AA13: 空 | AB13: 空 | AC13: 空 | AD13: 空 | AE13: 空 | AF13: 空 | AG13: =AH13+AI13+AJ13 -> 0 | AK13: 是 | AL13: =MIN(AL12+6,18)-COUNTIF(I13:P13,"<>空")+COUNTIF(I13:P13,"历练")+COUNTIF(I13:P13,"营地")*2+COUNTIF(I13:P13,"塔1")*5 -> 15 | AM13: =MIN(AM12+6,18)-COUNTIF(Q13:X13,"<>空")+COUNTIF(Q13:X13,"历练")+COUNTIF(Q13:X13,"营地")*2+COUNTIF(Q13:X13,"塔1")*5 -> 18 | AN13: =MIN(AN12+6,18)-COUNTIF(Y13:AF13,"<>空")+COUNTIF(Y13:AF13,"历练")+COUNTIF(Y13:AF13,"营地")*2+COUNTIF(Y13:AF13,"塔1")*5 -> 8 | AO13: 草4 | AP13: 150 | AQ13: 50 | AS13: =COUNTIF($I$4:$P$93,AO13) -> 0 | AT13: =COUNTIF($Q$4:$X$93,AO13) -> 2 | AU13: =COUNTIF($Y$4:$AF$93,AO13) -> 1 | AV13: =AS13+AT13+AU13 -> 3 | AX13: =AS13*$AQ13 -> 0 | AY13: =AT13*$AQ13 -> 100 | AZ13: =AU13*$AQ13 -> 50 | BD13: =AR13*AV13 -> 0
A14: 46195 | B14: 1600 | D14: =(SUM(粮草!A14:X14)+AG14*10*IF(AK14="是",$BB$4,$BB$3)) -> 952 | E14: =SUM($B$4:B14)+SUM($C$4:C14)-SUM($D$4:D14) -> 1038 | F14: =SUM(经验!A14:X14) -> 355 | G14: =SUM($F$4:F14)+SUM($H$4:H14) -> 8910 | H14: 0 | I14: 空 | J14: 空 | K14: 空 | L14: 空 | M14: 空 | N14: 空 | O14: 空 | P14: 空 | Q14: 空 | R14: 空 | S14: 空 | T14: 空 | U14: 空 | V14: 空 | W14: 空 | X14: 空 | Y14: 6级 | Z14: 6级 | AA14: 6级 | AB14: 6级 | AC14: 6级 | AD14: 5级 | AE14: 空 | AF14: 空 | AG14: =AH14+AI14+AJ14 -> 0 | AK14: 是 | AL14: =MIN(AL13+6,18)-COUNTIF(I14:P14,"<>空")+COUNTIF(I14:P14,"历练")+COUNTIF(I14:P14,"营地")*2+COUNTIF(I14:P14,"塔1")*5 -> 18 | AM14: =MIN(AM13+6,18)-COUNTIF(Q14:X14,"<>空")+COUNTIF(Q14:X14,"历练")+COUNTIF(Q14:X14,"营地")*2+COUNTIF(Q14:X14,"塔1")*5 -> 18 | AN14: =MIN(AN13+6,18)-COUNTIF(Y14:AF14,"<>空")+COUNTIF(Y14:AF14,"历练")+COUNTIF(Y14:AF14,"营地")*2+COUNTIF(Y14:AF14,"塔1")*5 -> 8 | AO14: 草5 | AP14: 150 | AQ14: 55 | AS14: =COUNTIF($I$4:$P$93,AO14) -> 0 | AT14: =COUNTIF($Q$4:$X$93,AO14) -> 3 | AU14: =COUNTIF($Y$4:$AF$93,AO14) -> 0 | AV14: =AS14+AT14+AU14 -> 3 | AX14: =AS14*$AQ14 -> 0 | AY14: =AT14*$AQ14 -> 165 | AZ14: =AU14*$AQ14 -> 0 | BD14: =AR14*AV14 -> 0
A15: 46196 | B15: 1600 | D15: =(SUM(粮草!A15:X15)+AG15*10*IF(AK15="是",$BB$4,$BB$3)) -> 952 | E15: =SUM($B$4:B15)+SUM($C$4:C15)-SUM($D$4:D15) -> 1686 | F15: =SUM(经验!A15:X15) -> 355 | G15: =SUM($F$4:F15)+SUM($H$4:H15) -> 9565 | H15: 300 | I15: 空 | J15: 空 | K15: 空 | L15: 空 | M15: 空 | N15: 空 | O15: 空 | P15: 空 | Q15: 空 | R15: 空 | S15: 空 | T15: 空 | U15: 空 | V15: 空 | W15: 空 | X15: 空 | Y15: 5级 | Z15: 6级 | AA15: 6级 | AB15: 6级 | AC15: 6级 | AD15: 6级 | AE15: 空 | AF15: 空 | AG15: =AH15+AI15+AJ15 -> 0 | AK15: 是 | AL15: =MIN(AL14+6,18)-COUNTIF(I15:P15,"<>空")+COUNTIF(I15:P15,"历练")+COUNTIF(I15:P15,"营地")*2+COUNTIF(I15:P15,"塔1")*5 -> 18 | AM15: =MIN(AM14+6,18)-COUNTIF(Q15:X15,"<>空")+COUNTIF(Q15:X15,"历练")+COUNTIF(Q15:X15,"营地")*2+COUNTIF(Q15:X15,"塔1")*5 -> 18 | AN15: =MIN(AN14+6,18)-COUNTIF(Y15:AF15,"<>空")+COUNTIF(Y15:AF15,"历练")+COUNTIF(Y15:AF15,"营地")*2+COUNTIF(Y15:AF15,"塔1")*5 -> 8 | AO15: 草6 | AP15: 150 | AQ15: 60 | AS15: =COUNTIF($I$4:$P$93,AO15) -> 0 | AT15: =COUNTIF($Q$4:$X$93,AO15) -> 0 | AU15: =COUNTIF($Y$4:$AF$93,AO15) -> 1 | AV15: =AS15+AT15+AU15 -> 1 | AX15: =AS15*$AQ15 -> 0 | AY15: =AT15*$AQ15 -> 0 | AZ15: =AU15*$AQ15 -> 60 | BD15: =AR15*AV15 -> 0
A16: 46197 | B16: 1600 | D16: =(SUM(粮草!A16:X16)+AG16*10*IF(AK16="是",$BB$4,$BB$3)) -> 640 | E16: =SUM($B$4:B16)+SUM($C$4:C16)-SUM($D$4:D16) -> 2646 | F16: =SUM(经验!A16:X16) -> 240 | G16: =SUM($F$4:F16)+SUM($H$4:H16) -> 10005 | H16: 200 | I16: 空 | J16: 空 | K16: 空 | L16: 空 | M16: 空 | N16: 空 | O16: 空 | P16: 空 | Q16: 空 | R16: 空 | S16: 空 | T16: 空 | U16: 空 | V16: 空 | W16: 空 | X16: 空 | Y16: 6级 | Z16: 6级 | AA16: 6级 | AB16: 6级 | AC16: 空 | AD16: 空 | AE16: 空 | AF16: 空 | AG16: =AH16+AI16+AJ16 -> 0 | AK16: 是 | AL16: =MIN(AL15+6,18)-COUNTIF(I16:P16,"<>空")+COUNTIF(I16:P16,"历练")+COUNTIF(I16:P16,"营地")*2+COUNTIF(I16:P16,"塔1")*5 -> 18 | AM16: =MIN(AM15+6,18)-COUNTIF(Q16:X16,"<>空")+COUNTIF(Q16:X16,"历练")+COUNTIF(Q16:X16,"营地")*2+COUNTIF(Q16:X16,"塔1")*5 -> 18 | AN16: =MIN(AN15+6,18)-COUNTIF(Y16:AF16,"<>空")+COUNTIF(Y16:AF16,"历练")+COUNTIF(Y16:AF16,"营地")*2+COUNTIF(Y16:AF16,"塔1")*5 -> 10 | AO16: 遗迹 | AP16: 150 | AQ16: 40 | AR16: 29.110982 | AS16: =COUNTIF($I$4:$P$93,AO16) -> 0 | AT16: =COUNTIF($Q$4:$X$93,AO16) -> 0 | AU16: =COUNTIF($Y$4:$AF$93,AO16) -> 0 | AV16: =AS16+AT16+AU16 -> 0 | AX16: =AS16*$AQ16 -> 0 | AY16: =AT16*$AQ16 -> 0 | AZ16: =AU16*$AQ16 -> 0 | BD16: =AR16*AV16 -> 0
A17: 46198 | B17: 1600 | D17: =(SUM(粮草!A17:X17)+AG17*10*IF(AK17="是",$BB$4,$BB$3)) -> 1652 | E17: =SUM($B$4:B17)+SUM($C$4:C17)-SUM($D$4:D17) -> 2594 | F17: =SUM(经验!A17:X17) -> 735 | G17: =SUM($F$4:F17)+SUM($H$4:H17) -> 10740 | H17: 0 | I17: 空 | J17: 空 | K17: 空 | L17: 空 | M17: 空 | N17: 空 | O17: 空 | P17: 空 | Q17: 3级 | R17: 3级 | S17: 3级 | T17: 营地 | U17: 3级 | V17: 3级 | W17: 3级 | X17: 3级 | Y17: 6级 | Z17: 6级 | AA17: 6级 | AB17: 营地 | AC17: 6级 | AD17: 6级 | AE17: 6级 | AF17: 6级 | AG17: =AH17+AI17+AJ17 -> 0 | AK17: 是 | AL17: =MIN(AL16+6,18)-COUNTIF(I17:P17,"<>空")+COUNTIF(I17:P17,"历练")+COUNTIF(I17:P17,"营地")*2+COUNTIF(I17:P17,"塔1")*5 -> 18 | AM17: =MIN(AM16+6,18)-COUNTIF(Q17:X17,"<>空")+COUNTIF(Q17:X17,"历练")+COUNTIF(Q17:X17,"营地")*2+COUNTIF(Q17:X17,"塔1")*5 -> 12 | AN17: =MIN(AN16+6,18)-COUNTIF(Y17:AF17,"<>空")+COUNTIF(Y17:AF17,"历练")+COUNTIF(Y17:AF17,"营地")*2+COUNTIF(Y17:AF17,"塔1")*5 -> 10 | AO17: 商人 | AP17: 50 | AQ17: 30 | AR17: 10 | AS17: =COUNTIF($I$4:$P$93,AO17) -> 11 | AT17: =COUNTIF($Q$4:$X$93,AO17) -> 21 | AU17: =COUNTIF($Y$4:$AF$93,AO17) -> 7 | AV17: =AS17+AT17+AU17 -> 39 | AX17: =AS17*$AQ17 -> 330 | AY17: =AT17*$AQ17 -> 630 | AZ17: =AU17*$AQ17 -> 210 | BD17: =AR17*AV17 -> 390
A18: 46199 | B18: 1600 | D18: =(SUM(粮草!A18:X18)+AG18*10*IF(AK18="是",$BB$4,$BB$3)) -> 1918 | E18: =SUM($B$4:B18)+SUM($C$4:C18)-SUM($D$4:D18) -> 2276 | F18: =SUM(经验!A18:X18) -> 775 | G18: =SUM($F$4:F18)+SUM($H$4:H18) -> 11515 | H18: 0 | I18: 空 | J18: 空 | K18: 空 | L18: 空 | M18: 空 | N18: 空 | O18: 空 | P18: 空 | Q18: 3级 | R18: 3级 | S18: 3级 | T18: 商人 | U18: 3级 | V18: 3级 | W18: 5级 | X18: 5级 | Y18: 6级 | Z18: 6级 | AA18: 6级 | AB18: 6级 | AC18: 6级 | AD18: 5级 | AE18: 营地 | AF18: 5级 | AG18: =AH18+AI18+AJ18 -> 0 | AK18: 是 | AL18: =MIN(AL17+6,18)-COUNTIF(I18:P18,"<>空")+COUNTIF(I18:P18,"历练")+COUNTIF(I18:P18,"营地")*2+COUNTIF(I18:P18,"塔1")*5 -> 18 | AM18: =MIN(AM17+6,18)-COUNTIF(Q18:X18,"<>空")+COUNTIF(Q18:X18,"历练")+COUNTIF(Q18:X18,"营地")*2+COUNTIF(Q18:X18,"塔1")*5 -> 10 | AN18: =MIN(AN17+6,18)-COUNTIF(Y18:AF18,"<>空")+COUNTIF(Y18:AF18,"历练")+COUNTIF(Y18:AF18,"营地")*2+COUNTIF(Y18:AF18,"塔1")*5 -> 10 | AO18: 营地 | AP18: -150 | AQ18: 0 | AR18: 10 | AS18: =COUNTIF($I$4:$P$93,AO18) -> 2 | AT18: =COUNTIF($Q$4:$X$93,AO18) -> 8 | AU18: =COUNTIF($Y$4:$AF$93,AO18) -> 5 | AV18: =AS18+AT18+AU18 -> 15 | AX18: =AS18*$AQ18 -> 0 | AY18: =AT18*$AQ18 -> 0 | AZ18: =AU18*$AQ18 -> 0 | BD18: =AR18*AV18 -> 150
A19: 46200 | B19: 1600 | D19: =(SUM(粮草!A19:X19)+AG19*10*IF(AK19="是",$BB$4,$BB$3)) -> 1638 | E19: =SUM($B$4:B19)+SUM($C$4:C19)-SUM($D$4:D19) -> 2238 | F19: =SUM(经验!A19:X19) -> 690 | G19: =SUM($F$4:F19)+SUM($H$4:H19) -> 12205 | H19: 0 | I19: 空 | J19: 空 | K19: 空 | L19: 空 | M19: 空 | N19: 空 | O19: 空 | P19: 空 | Q19: 5级 | R19: 营地 | S19: 5级 | T19: 草5 | U19: 5级 | V19: 商人 | W19: 5级 | X19: 5级 | Y19: 5级 | Z19: 5级 | AA19: 5级 | AB19: 5级 | AC19: 5级 | AD19: 5级 | AE19: 空 | AF19: 空 | AG19: =AH19+AI19+AJ19 -> 2 | AI19: 2 | AK19: 是 | AL19: =MIN(AL18+6,18)-COUNTIF(I19:P19,"<>空")+COUNTIF(I19:P19,"历练")+COUNTIF(I19:P19,"营地")*2+COUNTIF(I19:P19,"塔1")*5 -> 18 | AM19: =MIN(AM18+6,18)-COUNTIF(Q19:X19,"<>空")+COUNTIF(Q19:X19,"历练")+COUNTIF(Q19:X19,"营地")*2+COUNTIF(Q19:X19,"塔1")*5 -> 10 | AN19: =MIN(AN18+6,18)-COUNTIF(Y19:AF19,"<>空")+COUNTIF(Y19:AF19,"历练")+COUNTIF(Y19:AF19,"营地")*2+COUNTIF(Y19:AF19,"塔1")*5 -> 10 | AO19: 大卦 | AP19: 250 | AQ19: 300 | AS19: =COUNTIF($I$4:$P$93,AO19) -> 0 | AT19: =COUNTIF($Q$4:$X$93,AO19) -> 3 | AU19: =COUNTIF($Y$4:$AF$93,AO19) -> 0 | AV19: =AS19+AT19+AU19 -> 3 | AX19: =AS19*$AQ19 -> 0 | AY19: =AT19*$AQ19 -> 900 | AZ19: =AU19*$AQ19 -> 0 | BD19: =AR19*AV19 -> 0
A20: 46201 | B20: 1600 | D20: =(SUM(粮草!A20:X20)+AG20*10*IF(AK20="是",$BB$4,$BB$3)) -> 1832 | E20: =SUM($B$4:B20)+SUM($C$4:C20)-SUM($D$4:D20) -> 2006 | F20: =SUM(经验!A20:X20) -> 640 | G20: =SUM($F$4:F20)+SUM($H$4:H20) -> 12845 | H20: 0 | I20: 空 | J20: 空 | K20: 空 | L20: 空 | M20: 空 | N20: 空 | O20: 空 | P20: 空 | Q20: 4级 | R20: 5级 | S20: 5级 | T20: 4级 | U20: 4级 | V20: 4级 | W20: 空 | X20: 空 | Y20: 5级 | Z20: 5级 | AA20: 5级 | AB20: 5级 | AC20: 5级 | AD20: 5级 | AE20: 空 | AF20: 空 | AG20: =AH20+AI20+AJ20 -> 5 | AI20: 5 | AK20: 是 | AL20: =MIN(AL19+6,18)-COUNTIF(I20:P20,"<>空")+COUNTIF(I20:P20,"历练")+COUNTIF(I20:P20,"营地")*2+COUNTIF(I20:P20,"塔1")*5 -> 18 | AM20: =MIN(AM19+6,18)-COUNTIF(Q20:X20,"<>空")+COUNTIF(Q20:X20,"历练")+COUNTIF(Q20:X20,"营地")*2+COUNTIF(Q20:X20,"塔1")*5 -> 10 | AN20: =MIN(AN19+6,18)-COUNTIF(Y20:AF20,"<>空")+COUNTIF(Y20:AF20,"历练")+COUNTIF(Y20:AF20,"营地")*2+COUNTIF(Y20:AF20,"塔1")*5 -> 10 | AO20: 3级卦 | AP20: 170 | AQ20: 45 | AS20: =COUNTIF($I$4:$P$93,AO20) -> 0 | AT20: =COUNTIF($Q$4:$X$93,AO20) -> 5 | AU20: =COUNTIF($Y$4:$AF$93,AO20) -> 0 | AV20: =AS20+AT20+AU20 -> 5 | AX20: =AS20*$AQ20 -> 0 | AY20: =AT20*$AQ20 -> 225 | AZ20: =AU20*$AQ20 -> 0 | BD20: =AR20*AV20 -> 0
A21: 46202 | B21: 1600 | D21: =(SUM(粮草!A21:X21)+AG21*10*IF(AK21="是",$BB$4,$BB$3)) -> 1840 | E21: =SUM($B$4:B21)+SUM($C$4:C21)-SUM($D$4:D21) -> 1766 | F21: =SUM(经验!A21:X21) -> 665 | G21: =SUM($F$4:F21)+SUM($H$4:H21) -> 13710 | H21: 200 | I21: 空 | J21: 空 | K21: 空 | L21: 空 | M21: 空 | N21: 空 | O21: 空 | P21: 空 | Q21: 5级 | R21: 5级 | S21: 4级 | T21: 4级 | U21: 5级 | V21: 5级 | W21: 空 | X21: 空 | Y21: 5级 | Z21: 5级 | AA21: 5级 | AB21: 6级 | AC21: 6级 | AD21: 6级 | AE21: 空 | AF21: 空 | AG21: =AH21+AI21+AJ21 -> 1 | AJ21: 1 | AK21: 是 | AL21: =MIN(AL20+6,18)-COUNTIF(I21:P21,"<>空")+COUNTIF(I21:P21,"历练")+COUNTIF(I21:P21,"营地")*2+COUNTIF(I21:P21,"塔1")*5 -> 18 | AM21: =MIN(AM20+6,18)-COUNTIF(Q21:X21,"<>空")+COUNTIF(Q21:X21,"历练")+COUNTIF(Q21:X21,"营地")*2+COUNTIF(Q21:X21,"塔1")*5 -> 10 | AN21: =MIN(AN20+6,18)-COUNTIF(Y21:AF21,"<>空")+COUNTIF(Y21:AF21,"历练")+COUNTIF(Y21:AF21,"营地")*2+COUNTIF(Y21:AF21,"塔1")*5 -> 10 | AO21: 巨卦 | AP21: 250 | AQ21: 400 | AS21: =COUNTIF($I$4:$P$93,AO21) -> 0 | AT21: =COUNTIF($Q$4:$X$93,AO21) -> 0 | AU21: =COUNTIF($Y$4:$AF$93,AO21) -> 0 | AV21: =AS21+AT21+AU21 -> 0 | AX21: =AS21*$AQ21 -> 0 | AY21: =AT21*$AQ21 -> 0 | AZ21: =AU21*$AQ21 -> 0 | BD21: =AR21*AV21 -> 0
A22: 46203 | B22: 1600 | D22: =(SUM(粮草!A22:X22)+AG22*10*IF(AK22="是",$BB$4,$BB$3)) -> 1862 | E22: =SUM($B$4:B22)+SUM($C$4:C22)-SUM($D$4:D22) -> 1504 | F22: =SUM(经验!A22:X22) -> 725 | G22: =SUM($F$4:F22)+SUM($H$4:H22) -> 14535 | H22: 100 | I22: 空 | J22: 空 | K22: 空 | L22: 空 | M22: 空 | N22: 空 | O22: 空 | P22: 空 | Q22: 4级 | R22: 营地 | S22: 5级 | T22: 5级 | U22: 4级 | V22: 4级 | W22: 4级 | X22: 5级 | Y22: 6级 | Z22: 6级 | AA22: 6级 | AB22: 6级 | AC22: 6级 | AD22: 6级 | AE22: 空 | AF22: 空 | AG22: =AH22+AI22+AJ22 -> 10 | AI22: 5 | AJ22: 5 | AK22: 是 | AL22: =MIN(AL21+6,18)-COUNTIF(I22:P22,"<>空")+COUNTIF(I22:P22,"历练")+COUNTIF(I22:P22,"营地")*2+COUNTIF(I22:P22,"塔1")*5 -> 18 | AM22: =MIN(AM21+6,18)-COUNTIF(Q22:X22,"<>空")+COUNTIF(Q22:X22,"历练")+COUNTIF(Q22:X22,"营地")*2+COUNTIF(Q22:X22,"塔1")*5 -> 10 | AN22: =MIN(AN21+6,18)-COUNTIF(Y22:AF22,"<>空")+COUNTIF(Y22:AF22,"历练")+COUNTIF(Y22:AF22,"营地")*2+COUNTIF(Y22:AF22,"塔1")*5 -> 10 | AO22: 大boss | AP22: 250 | AQ22: 1000 | AR22: 60 | AS22: =COUNTIF($I$4:$P$93,AO22) -> 0 | AT22: =COUNTIF($Q$4:$X$93,AO22) -> 2 | AU22: =COUNTIF($Y$4:$AF$93,AO22) -> 0 | AV22: =AS22+AT22+AU22 -> 2 | AX22: =AS22*$AQ22 -> 0 | AY22: =AT22*$AQ22 -> 2000 | AZ22: =AU22*$AQ22 -> 0 | BD22: =AR22*AV22 -> 120
A23: 46204 | B23: 1600 | D23: =(SUM(粮草!A23:X23)+AG23*10*IF(AK23="是",$BB$4,$BB$3)) -> 1412 | E23: =SUM($B$4:B23)+SUM($C$4:C23)-SUM($D$4:D23) -> 1692 | F23: =SUM(经验!A23:X23) -> 665 | G23: =SUM($F$4:F23)+SUM($H$4:H23) -> 15400 | H23: 200 | I23: 空 | J23: 空 | K23: 空 | L23: 空 | M23: 空 | N23: 空 | O23: 空 | P23: 空 | Q23: 4级 | R23: 4级 | S23: 4级 | T23: 4级 | U23: 5级 | V23: 4级 | W23: 营地 | X23: 空 | Y23: 6级 | Z23: 6级 | AA23: 6级 | AB23: 6级 | AC23: 6级 | AD23: 6级 | AE23: 营地 | AF23: 空 | AG23: =AH23+AI23+AJ23 -> 0 | AK23: 是 | AL23: =MIN(AL22+6,18)-COUNTIF(I23:P23,"<>空")+COUNTIF(I23:P23,"历练")+COUNTIF(I23:P23,"营地")*2+COUNTIF(I23:P23,"塔1")*5 -> 18 | AM23: =MIN(AM22+6,18)-COUNTIF(Q23:X23,"<>空")+COUNTIF(Q23:X23,"历练")+COUNTIF(Q23:X23,"营地")*2+COUNTIF(Q23:X23,"塔1")*5 -> 11 | AN23: =MIN(AN22+6,18)-COUNTIF(Y23:AF23,"<>空")+COUNTIF(Y23:AF23,"历练")+COUNTIF(Y23:AF23,"营地")*2+COUNTIF(Y23:AF23,"塔1")*5 -> 11 | AO23: 中boss | AP23: 250 | AQ23: 500 | AS23: =COUNTIF($I$4:$P$93,AO23) -> 0 | AT23: =COUNTIF($Q$4:$X$93,AO23) -> 2 | AU23: =COUNTIF($Y$4:$AF$93,AO23) -> 0 | AV23: =AS23+AT23+AU23 -> 2 | AX23: =AS23*$AQ23 -> 0 | AY23: =AT23*$AQ23 -> 1000 | AZ23: =AU23*$AQ23 -> 0 | BD23: =AR23*AV23 -> 0
A24: 46205 | B24: 1600 | D24: =(SUM(粮草!A24:X24)+AG24*10*IF(AK24="是",$BB$4,$BB$3)) -> 1816 | E24: =SUM($B$4:B24)+SUM($C$4:C24)-SUM($D$4:D24) -> 1476 | F24: =SUM(经验!A24:X24) -> 660 | G24: =SUM($F$4:F24)+SUM($H$4:H24) -> 16060 | H24: 0 | I24: 空 | J24: 空 | K24: 空 | L24: 空 | M24: 空 | N24: 空 | O24: 空 | P24: 空 | Q24: 4级 | R24: 4级 | S24: 4级 | T24: 草2 | U24: 5级 | V24: 5级 | W24: 空 | X24: 空 | Y24: 6级 | Z24: 6级 | AA24: 6级 | AB24: 6级 | AC24: 6级 | AD24: 6级 | AE24: 空 | AF24: 空 | AG24: =AH24+AI24+AJ24 -> 0 | AK24: 是 | AL24: =MIN(AL23+6,18)-COUNTIF(I24:P24,"<>空")+COUNTIF(I24:P24,"历练")+COUNTIF(I24:P24,"营地")*2+COUNTIF(I24:P24,"塔1")*5 -> 18 | AM24: =MIN(AM23+6,18)-COUNTIF(Q24:X24,"<>空")+COUNTIF(Q24:X24,"历练")+COUNTIF(Q24:X24,"营地")*2+COUNTIF(Q24:X24,"塔1")*5 -> 11 | AN24: =MIN(AN23+6,18)-COUNTIF(Y24:AF24,"<>空")+COUNTIF(Y24:AF24,"历练")+COUNTIF(Y24:AF24,"营地")*2+COUNTIF(Y24:AF24,"塔1")*5 -> 11 | AO24: 4级卦 | AP24: 180 | AQ24: 50 | AR24: 39.110982 | AS24: =COUNTIF($I$4:$P$93,AO24) -> 0 | AT24: =COUNTIF($Q$4:$X$93,AO24) -> 0 | AU24: =COUNTIF($Y$4:$AF$93,AO24) -> 0 | AV24: =AS24+AT24+AU24 -> 0 | AX24: =AS24*$AQ24 -> 0 | AY24: =AT24*$AQ24 -> 0 | AZ24: =AU24*$AQ24 -> 0 | BD24: =AR24*AV24 -> 0
A25: 46206 | B25: 1600 | D25: =(SUM(粮草!A25:X25)+AG25*10*IF(AK25="是",$BB$4,$BB$3)) -> 1832 | E25: =SUM($B$4:B25)+SUM($C$4:C25)-SUM($D$4:D25) -> 1244 | F25: =SUM(经验!A25:X25) -> 665 | G25: =SUM($F$4:F25)+SUM($H$4:H25) -> 16725 | H25: 0 | I25: 空 | J25: 空 | K25: 空 | L25: 空 | M25: 空 | N25: 空 | O25: 空 | P25: 空 | Q25: 4级 | R25: 5级 | S25: 4级 | T25: 4级 | U25: 4级 | V25: 4级 | W25: 空 | X25: 空 | Y25: 6级 | Z25: 6级 | AA25: 6级 | AB25: 6级 | AC25: 6级 | AD25: 6级 | AE25: 空 | AF25: 空 | AG25: =AH25+AI25+AJ25 -> 0 | AK25: 是 | AL25: =MIN(AL24+6,18)-COUNTIF(I25:P25,"<>空")+COUNTIF(I25:P25,"历练")+COUNTIF(I25:P25,"营地")*2+COUNTIF(I25:P25,"塔1")*5 -> 18 | AM25: =MIN(AM24+6,18)-COUNTIF(Q25:X25,"<>空")+COUNTIF(Q25:X25,"历练")+COUNTIF(Q25:X25,"营地")*2+COUNTIF(Q25:X25,"塔1")*5 -> 11 | AN25: =MIN(AN24+6,18)-COUNTIF(Y25:AF25,"<>空")+COUNTIF(Y25:AF25,"历练")+COUNTIF(Y25:AF25,"营地")*2+COUNTIF(Y25:AF25,"塔1")*5 -> 11 | AO25: 塔1 | AP25: 160 | AQ25: 35 | AR25: 44.222109 | AS25: =COUNTIF($I$4:$P$93,AO25) -> 0 | AT25: =COUNTIF($Q$4:$X$93,AO25) -> 1 | AU25: =COUNTIF($Y$4:$AF$93,AO25) -> 0 | AV25: =AS25+AT25+AU25 -> 1 | AX25: =AS25*$AQ25 -> 0 | AY25: =AT25*$AQ25 -> 35 | AZ25: =AU25*$AQ25 -> 0 | BD25: =AR25*AV25 -> 44.222109
A26: 46207 | B26: 1600 | D26: =(SUM(粮草!A26:X26)+AG26*10*IF(AK26="是",$BB$4,$BB$3)) -> 896 | E26: =SUM($B$4:B26)+SUM($C$4:C26)-SUM($D$4:D26) -> 1948 | F26: =SUM(经验!A26:X26) -> 320 | G26: =SUM($F$4:F26)+SUM($H$4:H26) -> 17045 | H26: 0 | I26: 空 | J26: 空 | K26: 空 | L26: 空 | M26: 空 | N26: 空 | O26: 空 | P26: 空 | Q26: 5级 | R26: 5级 | S26: 5级 | T26: 5级 | U26: 4级 | V26: 4级 | W26: 空 | X26: 空 | Y26: 空 | Z26: 空 | AA26: 空 | AB26: 空 | AC26: 空 | AD26: 空 | AE26: 空 | AF26: 空 | AG26: =AH26+AI26+AJ26 -> 0 | AK26: 是 | AL26: =MIN(AL25+6,18)-COUNTIF(I26:P26,"<>空")+COUNTIF(I26:P26,"历练")+COUNTIF(I26:P26,"营地")*2+COUNTIF(I26:P26,"塔1")*5 -> 18 | AM26: =MIN(AM25+6,18)-COUNTIF(Q26:X26,"<>空")+COUNTIF(Q26:X26,"历练")+COUNTIF(Q26:X26,"营地")*2+COUNTIF(Q26:X26,"塔1")*5 -> 11 | AN26: =MIN(AN25+6,18)-COUNTIF(Y26:AF26,"<>空")+COUNTIF(Y26:AF26,"历练")+COUNTIF(Y26:AF26,"营地")*2+COUNTIF(Y26:AF26,"塔1")*5 -> 17 | AO26: 塔2 | AP26: 150 | AQ26: 40 | AR26: 29.110982 | AS26: =COUNTIF($I$4:$P$93,AO26) -> 0 | AT26: =COUNTIF($Q$4:$X$93,AO26) -> 1 | AU26: =COUNTIF($Y$4:$AF$93,AO26) -> 0 | AV26: =AS26+AT26+AU26 -> 1 | AX26: =AS26*$AQ26 -> 0 | AY26: =AT26*$AQ26 -> 40 | AZ26: =AU26*$AQ26 -> 0 | BD26: =AR26*AV26 -> 29.110982
A27: 46208 | B27: 1600 | D27: =(SUM(粮草!A27:X27)+AG27*10*IF(AK27="是",$BB$4,$BB$3)) -> 1816 | E27: =SUM($B$4:B27)+SUM($C$4:C27)-SUM($D$4:D27) -> 1732 | F27: =SUM(经验!A27:X27) -> 675 | G27: =SUM($F$4:F27)+SUM($H$4:H27) -> 17720 | H27: 0 | I27: 空 | J27: 空 | K27: 空 | L27: 空 | M27: 空 | N27: 空 | O27: 空 | P27: 空 | Q27: 4级 | R27: 4级 | S27: 4级 | T27: 5级 | U27: 5级 | V27: 草5 | W27: 空 | X27: 空 | Y27: 6级 | Z27: 6级 | AA27: 6级 | AB27: 6级 | AC27: 6级 | AD27: 6级 | AE27: 空 | AF27: 空 | AG27: =AH27+AI27+AJ27 -> 0 | AK27: 是 | AL27: =MIN(AL26+6,18)-COUNTIF(I27:P27,"<>空")+COUNTIF(I27:P27,"历练")+COUNTIF(I27:P27,"营地")*2+COUNTIF(I27:P27,"塔1")*5 -> 18 | AM27: =MIN(AM26+6,18)-COUNTIF(Q27:X27,"<>空")+COUNTIF(Q27:X27,"历练")+COUNTIF(Q27:X27,"营地")*2+COUNTIF(Q27:X27,"塔1")*5 -> 11 | AN27: =MIN(AN26+6,18)-COUNTIF(Y27:AF27,"<>空")+COUNTIF(Y27:AF27,"历练")+COUNTIF(Y27:AF27,"营地")*2+COUNTIF(Y27:AF27,"塔1")*5 -> 12 | AO27: 塔3 | AP27: 150 | AQ27: 45 | AR27: 13.999855 | AS27: =COUNTIF($I$4:$P$93,AO27) -> 0 | AT27: =COUNTIF($Q$4:$X$93,AO27) -> 1 | AU27: =COUNTIF($Y$4:$AF$93,AO27) -> 1 | AV27: =AS27+AT27+AU27 -> 2 | AX27: =AS27*$AQ27 -> 0 | AY27: =AT27*$AQ27 -> 45 | AZ27: =AU27*$AQ27 -> 45 | BD27: =AR27*AV27 -> 27.99971
A28: 46209 | B28: 1600 | D28: =(SUM(粮草!A28:X28)+AG28*10*IF(AK28="是",$BB$4,$BB$3)) -> 1824 | E28: =SUM($B$4:B28)+SUM($C$4:C28)-SUM($D$4:D28) -> 1508 | F28: =SUM(经验!A28:X28) -> 680 | G28: =SUM($F$4:F28)+SUM($H$4:H28) -> 18600 | H28: 200 | I28: 空 | J28: 空 | K28: 空 | L28: 空 | M28: 空 | N28: 空 | O28: 空 | P28: 空 | Q28: 4级 | R28: 5级 | S28: 4级 | T28: 5级 | U28: 5级 | V28: 5级 | W28: 空 | X28: 空 | Y28: 6级 | Z28: 草6 | AA28: 6级 | AB28: 6级 | AC28: 6级 | AD28: 6级 | AE28: 空 | AF28: 空 | AG28: =AH28+AI28+AJ28 -> 1 | AI28: 1 | AK28: 是 | AL28: =MIN(AL27+6,18)-COUNTIF(I28:P28,"<>空")+COUNTIF(I28:P28,"历练")+COUNTIF(I28:P28,"营地")*2+COUNTIF(I28:P28,"塔1")*5 -> 18 | AM28: =MIN(AM27+6,18)-COUNTIF(Q28:X28,"<>空")+COUNTIF(Q28:X28,"历练")+COUNTIF(Q28:X28,"营地")*2+COUNTIF(Q28:X28,"塔1")*5 -> 11 | AN28: =MIN(AN27+6,18)-COUNTIF(Y28:AF28,"<>空")+COUNTIF(Y28:AF28,"历练")+COUNTIF(Y28:AF28,"营地")*2+COUNTIF(Y28:AF28,"塔1")*5 -> 12 | AO28: 空 | AP28: 0 | AQ28: 0 | AS28: =COUNTIF($I$4:$P$93,#REF!) -> 0 | AT28: =COUNTIF($Q$4:$X$93,#REF!) -> 0 | AU28: =COUNTIF($Y$4:$AF$93,#REF!) -> 0 | AV28: =AS28+AT28+AU28 -> 0 | AX28: =AS28*$AQ28 -> 0 | AY28: =AT28*$AQ28 -> 0 | AZ28: =AU28*$AQ28 -> 0 | BD28: =AR28*AV28 -> 0
A29: 46210 | B29: 1600 | D29: =(SUM(粮草!A29:X29)+AG29*10*IF(AK29="是",$BB$4,$BB$3)) -> 888 | E29: =SUM($B$4:B29)+SUM($C$4:C29)-SUM($D$4:D29) -> 2220 | F29: =SUM(经验!A29:X29) -> 315 | G29: =SUM($F$4:F29)+SUM($H$4:H29) -> 19015 | H29: 100 | I29: 空 | J29: 空 | K29: 空 | L29: 空 | M29: 空 | N29: 空 | O29: 空 | P29: 空 | Q29: 5级 | R29: 4级 | S29: 5级 | T29: 4级 | U29: 5级 | V29: 4级 | W29: 空 | X29: 空 | Y29: 空 | Z29: 空 | AA29: 空 | AB29: 空 | AC29: 空 | AD29: 空 | AE29: 空 | AF29: 空 | AG29: =AH29+AI29+AJ29 -> 0 | AK29: 是 | AL29: =MIN(AL28+6,18)-COUNTIF(I29:P29,"<>空")+COUNTIF(I29:P29,"历练")+COUNTIF(I29:P29,"营地")*2+COUNTIF(I29:P29,"塔1")*5 -> 18 | AM29: =MIN(AM28+6,18)-COUNTIF(Q29:X29,"<>空")+COUNTIF(Q29:X29,"历练")+COUNTIF(Q29:X29,"营地")*2+COUNTIF(Q29:X29,"塔1")*5 -> 11 | AN29: =MIN(AN28+6,18)-COUNTIF(Y29:AF29,"<>空")+COUNTIF(Y29:AF29,"历练")+COUNTIF(Y29:AF29,"营地")*2+COUNTIF(Y29:AF29,"塔1")*5 -> 18 | AO29: 历练 | AP29: 50 | AQ29: 520 | AS29: =COUNTIF($I$4:$P$93,AO29) -> 0 | AT29: =COUNTIF($Q$4:$X$93,AO29) -> 3 | AU29: =COUNTIF($Y$4:$AF$93,AO29) -> 0 | AV29: =AS29+AT29+AU29 -> 3 | AX29: =AS29*$AQ29 -> 0 | AY29: =AT29*$AQ29 -> 1560 | AZ29: =AU29*$AQ29 -> 0 | BD29: =AR29*AV29 -> 0
A30: 46211 | B30: 1600 | D30: =(SUM(粮草!A30:X30)+AG30*10*IF(AK30="是",$BB$4,$BB$3)) -> 1848 | E30: =SUM($B$4:B30)+SUM($C$4:C30)-SUM($D$4:D30) -> 1972 | F30: =SUM(经验!A30:X30) -> 675 | G30: =SUM($F$4:F30)+SUM($H$4:H30) -> 19890 | H30: 200 | I30: 空 | J30: 空 | K30: 空 | L30: 空 | M30: 空 | N30: 空 | O30: 空 | P30: 空 | Q30: 4级 | R30: 5级 | S30: 5级 | T30: 4级 | U30: 4级 | V30: 5级 | W30: 空 | X30: 空 | Y30: 6级 | Z30: 6级 | AA30: 6级 | AB30: 6级 | AC30: 6级 | AD30: 6级 | AE30: 空 | AF30: 空 | AG30: =AH30+AI30+AJ30 -> 0 | AK30: 是 | AL30: =MIN(AL29+6,18)-COUNTIF(I30:P30,"<>空")+COUNTIF(I30:P30,"历练")+COUNTIF(I30:P30,"营地")*2+COUNTIF(I30:P30,"塔1")*5 -> 18 | AM30: =MIN(AM29+6,18)-COUNTIF(Q30:X30,"<>空")+COUNTIF(Q30:X30,"历练")+COUNTIF(Q30:X30,"营地")*2+COUNTIF(Q30:X30,"塔1")*5 -> 11 | AN30: =MIN(AN29+6,18)-COUNTIF(Y30:AF30,"<>空")+COUNTIF(Y30:AF30,"历练")+COUNTIF(Y30:AF30,"营地")*2+COUNTIF(Y30:AF30,"塔1")*5 -> 12 | BD30: =SUM(BD4:BD29)+AG2*10 -> 37094.429
A31: 46212 | B31: 1600 | D31: =(SUM(粮草!A31:X31)+AG31*10*IF(AK31="是",$BB$4,$BB$3)) -> 1840 | E31: =SUM($B$4:B31)+SUM($C$4:C31)-SUM($D$4:D31) -> 1732 | F31: =SUM(经验!A31:X31) -> 670 | G31: =SUM($F$4:F31)+SUM($H$4:H31) -> 20560 | H31: 0 | I31: 空 | J31: 空 | K31: 空 | L31: 空 | M31: 空 | N31: 空 | O31: 空 | P31: 空 | Q31: 4级 | R31: 4级 | S31: 4级 | T31: 4级 | U31: 5级 | V31: 5级 | W31: 空 | X31: 空 | Y31: 6级 | Z31: 6级 | AA31: 6级 | AB31: 6级 | AC31: 6级 | AD31: 6级 | AE31: 空 | AF31: 空 | AG31: =AH31+AI31+AJ31 -> 0 | AK31: 是 | AL31: =MIN(AL30+6,18)-COUNTIF(I31:P31,"<>空")+COUNTIF(I31:P31,"历练")+COUNTIF(I31:P31,"营地")*2+COUNTIF(I31:P31,"塔1")*5 -> 18 | AM31: =MIN(AM30+6,18)-COUNTIF(Q31:X31,"<>空")+COUNTIF(Q31:X31,"历练")+COUNTIF(Q31:X31,"营地")*2+COUNTIF(Q31:X31,"塔1")*5 -> 11 | AN31: =MIN(AN30+6,18)-COUNTIF(Y31:AF31,"<>空")+COUNTIF(Y31:AF31,"历练")+COUNTIF(Y31:AF31,"营地")*2+COUNTIF(Y31:AF31,"塔1")*5 -> 12
A32: 46213 | B32: 1600 | D32: =(SUM(粮草!A32:X32)+AG32*10*IF(AK32="是",$BB$4,$BB$3)) -> 816 | E32: =SUM($B$4:B32)+SUM($C$4:C32)-SUM($D$4:D32) -> 2516 | F32: =SUM(经验!A32:X32) -> 290 | G32: =SUM($F$4:F32)+SUM($H$4:H32) -> 20850 | H32: 0 | I32: 空 | J32: 空 | K32: 空 | L32: 空 | M32: 空 | N32: 空 | O32: 空 | P32: 空 | Q32: 草2 | R32: 4级 | S32: 4级 | T32: 4级 | U32: 4级 | V32: 草4 | W32: 空 | X32: 空 | Y32: 空 | Z32: 空 | AA32: 空 | AB32: 空 | AC32: 空 | AD32: 空 | AE32: 空 | AF32: 空 | AG32: =AH32+AI32+AJ32 -> 0 | AK32: 是 | AL32: =MIN(AL31+6,18)-COUNTIF(I32:P32,"<>空")+COUNTIF(I32:P32,"历练")+COUNTIF(I32:P32,"营地")*2+COUNTIF(I32:P32,"塔1")*5 -> 18 | AM32: =MIN(AM31+6,18)-COUNTIF(Q32:X32,"<>空")+COUNTIF(Q32:X32,"历练")+COUNTIF(Q32:X32,"营地")*2+COUNTIF(Q32:X32,"塔1")*5 -> 11 | AN32: =MIN(AN31+6,18)-COUNTIF(Y32:AF32,"<>空")+COUNTIF(Y32:AF32,"历练")+COUNTIF(Y32:AF32,"营地")*2+COUNTIF(Y32:AF32,"塔1")*5 -> 18 | AO32: 地块统计 | AP32: 应占领 | AQ32: 缺少 | AR32: 粮草 | AS32: 分数
A33: 46214 | B33: 1600 | D33: =(SUM(粮草!A33:X33)+AG33*10*IF(AK33="是",$BB$4,$BB$3)) -> 1824 | E33: =SUM($B$4:B33)+SUM($C$4:C33)-SUM($D$4:D33) -> 2292 | F33: =SUM(经验!A33:X33) -> 665 | G33: =SUM($F$4:F33)+SUM($H$4:H33) -> 21515 | H33: 0 | I33: 空 | J33: 空 | K33: 空 | L33: 空 | M33: 空 | N33: 空 | O33: 空 | P33: 空 | Q33: 5级 | R33: 4级 | S33: 5级 | T33: 4级 | U33: 5级 | V33: 草2 | W33: 空 | X33: 空 | Y33: 6级 | Z33: 6级 | AA33: 6级 | AB33: 6级 | AC33: 6级 | AD33: 6级 | AE33: 空 | AF33: 空 | AG33: =AH33+AI33+AJ33 -> 0 | AK33: 是 | AL33: =MIN(AL32+6,18)-COUNTIF(I33:P33,"<>空")+COUNTIF(I33:P33,"历练")+COUNTIF(I33:P33,"营地")*2+COUNTIF(I33:P33,"塔1")*5 -> 18 | AM33: =MIN(AM32+6,18)-COUNTIF(Q33:X33,"<>空")+COUNTIF(Q33:X33,"历练")+COUNTIF(Q33:X33,"营地")*2+COUNTIF(Q33:X33,"塔1")*5 -> 11 | AN33: =MIN(AN32+6,18)-COUNTIF(Y33:AF33,"<>空")+COUNTIF(Y33:AF33,"历练")+COUNTIF(Y33:AF33,"营地")*2+COUNTIF(Y33:AF33,"塔1")*5 -> 12 | AO33: 3级 | AP33: 190 | AQ33: =AP33-AV6 -> 14 | AR33: =AQ33*AP6*0.8 -> 1904 | AS33: =AQ33*AQ6 -> 630
A34: 46215 | B34: 1600 | D34: =(SUM(粮草!A34:X34)+AG34*10*IF(AK34="是",$BB$4,$BB$3)) -> 1720 | E34: =SUM($B$4:B34)+SUM($C$4:C34)-SUM($D$4:D34) -> 2172 | F34: =SUM(经验!A34:X34) -> 625 | G34: =SUM($F$4:F34)+SUM($H$4:H34) -> 22140 | H34: 0 | I34: 空 | J34: 空 | K34: 空 | L34: 空 | M34: 空 | N34: 空 | O34: 空 | P34: 空 | Q34: 4级 | R34: 4级 | S34: 5级 | T34: 5级 | U34: 5级 | V34: 空 | W34: 空 | X34: 空 | Y34: 6级 | Z34: 6级 | AA34: 6级 | AB34: 6级 | AC34: 6级 | AD34: 6级 | AE34: 空 | AF34: 空 | AG34: =AH34+AI34+AJ34 -> 2 | AI34: 2 | AK34: 是 | AL34: =MIN(AL33+6,18)-COUNTIF(I34:P34,"<>空")+COUNTIF(I34:P34,"历练")+COUNTIF(I34:P34,"营地")*2+COUNTIF(I34:P34,"塔1")*5 -> 18 | AM34: =MIN(AM33+6,18)-COUNTIF(Q34:X34,"<>空")+COUNTIF(Q34:X34,"历练")+COUNTIF(Q34:X34,"营地")*2+COUNTIF(Q34:X34,"塔1")*5 -> 12 | AN34: =MIN(AN33+6,18)-COUNTIF(Y34:AF34,"<>空")+COUNTIF(Y34:AF34,"历练")+COUNTIF(Y34:AF34,"营地")*2+COUNTIF(Y34:AF34,"塔1")*5 -> 12 | AO34: 4级 | AP34: 266 | AQ34: =AP34-AV7 -> 6 | AR34: =AQ34*AP7*0.8 -> 864 | AS34: =AQ34*AQ7 -> 300
A35: 46216 | B35: 1600 | D35: =(SUM(粮草!A35:X35)+AG35*10*IF(AK35="是",$BB$4,$BB$3)) -> 856 | E35: =SUM($B$4:B35)+SUM($C$4:C35)-SUM($D$4:D35) -> 2916 | F35: =SUM(经验!A35:X35) -> 295 | G35: =SUM($F$4:F35)+SUM($H$4:H35) -> 22635 | H35: 200 | I35: 空 | J35: 空 | K35: 空 | L35: 空 | M35: 空 | N35: 空 | O35: 空 | P35: 空 | Q35: 3级 | R35: 4级 | S35: 4级 | T35: 4级 | U35: 4级 | V35: 4级 | W35: 空 | X35: 空 | Y35: 空 | Z35: 空 | AA35: 空 | AB35: 空 | AC35: 空 | AD35: 空 | AE35: 空 | AF35: 空 | AG35: =AH35+AI35+AJ35 -> 0 | AK35: 是 | AL35: =MIN(AL34+6,18)-COUNTIF(I35:P35,"<>空")+COUNTIF(I35:P35,"历练")+COUNTIF(I35:P35,"营地")*2+COUNTIF(I35:P35,"塔1")*5 -> 18 | AM35: =MIN(AM34+6,18)-COUNTIF(Q35:X35,"<>空")+COUNTIF(Q35:X35,"历练")+COUNTIF(Q35:X35,"营地")*2+COUNTIF(Q35:X35,"塔1")*5 -> 12 | AN35: =MIN(AN34+6,18)-COUNTIF(Y35:AF35,"<>空")+COUNTIF(Y35:AF35,"历练")+COUNTIF(Y35:AF35,"营地")*2+COUNTIF(Y35:AF35,"塔1")*5 -> 18 | AO35: 5级 | AP35: 219 | AQ35: =AP35-AV8 -> -4 | AR35: =AQ35*AP8*0.8 -> -608 | AS35: =AQ35*AQ8 -> -220
A36: 46217 | B36: 1600 | D36: =(SUM(粮草!A36:X36)+AG36*10*IF(AK36="是",$BB$4,$BB$3)) -> 1696 | E36: =SUM($B$4:B36)+SUM($C$4:C36)-SUM($D$4:D36) -> 2820 | F36: =SUM(经验!A36:X36) -> 610 | G36: =SUM($F$4:F36)+SUM($H$4:H36) -> 23345 | H36: 100 | I36: 空 | J36: 空 | K36: 空 | L36: 空 | M36: 空 | N36: 空 | O36: 空 | P36: 空 | Q36: 4级 | R36: 4级 | S36: 4级 | T36: 4级 | U36: 4级 | V36: 6级 | W36: 空 | X36: 空 | Y36: 6级 | Z36: 6级 | AA36: 6级 | AB36: 6级 | AC36: 6级 | AD36: 空 | AE36: 空 | AF36: 空 | AG36: =AH36+AI36+AJ36 -> 2 | AJ36: 2 | AK36: 是 | AL36: =MIN(AL35+6,18)-COUNTIF(I36:P36,"<>空")+COUNTIF(I36:P36,"历练")+COUNTIF(I36:P36,"营地")*2+COUNTIF(I36:P36,"塔1")*5 -> 18 | AM36: =MIN(AM35+6,18)-COUNTIF(Q36:X36,"<>空")+COUNTIF(Q36:X36,"历练")+COUNTIF(Q36:X36,"营地")*2+COUNTIF(Q36:X36,"塔1")*5 -> 12 | AN36: =MIN(AN35+6,18)-COUNTIF(Y36:AF36,"<>空")+COUNTIF(Y36:AF36,"历练")+COUNTIF(Y36:AF36,"营地")*2+COUNTIF(Y36:AF36,"塔1")*5 -> 13 | AO36: 6级 | AP36: 197 | AQ36: =AP36-AV9 -> 11 | AR36: =AQ36*AP9*0.8 -> 1760 | AS36: =AQ36*AQ9 -> 660
A37: 46218 | B37: 1600 | D37: =(SUM(粮草!A37:X37)+AG37*10*IF(AK37="是",$BB$4,$BB$3)) -> 1928 | E37: =SUM($B$4:B37)+SUM($C$4:C37)-SUM($D$4:D37) -> 2492 | F37: =SUM(经验!A37:X37) -> 720 | G37: =SUM($F$4:F37)+SUM($H$4:H37) -> 24265 | H37: 200 | I37: 空 | J37: 空 | K37: 空 | L37: 空 | M37: 空 | N37: 空 | O37: 空 | P37: 空 | Q37: 6级 | R37: 6级 | S37: 6级 | T37: 6级 | U37: 6级 | V37: 6级 | W37: 空 | X37: 空 | Y37: 6级 | Z37: 6级 | AA37: 6级 | AB37: 6级 | AC37: 6级 | AD37: 6级 | AE37: 空 | AF37: 空 | AG37: =AH37+AI37+AJ37 -> 1 | AJ37: 1 | AK37: 是 | AL37: =MIN(AL36+6,18)-COUNTIF(I37:P37,"<>空")+COUNTIF(I37:P37,"历练")+COUNTIF(I37:P37,"营地")*2+COUNTIF(I37:P37,"塔1")*5 -> 18 | AM37: =MIN(AM36+6,18)-COUNTIF(Q37:X37,"<>空")+COUNTIF(Q37:X37,"历练")+COUNTIF(Q37:X37,"营地")*2+COUNTIF(Q37:X37,"塔1")*5 -> 12 | AN37: =MIN(AN36+6,18)-COUNTIF(Y37:AF37,"<>空")+COUNTIF(Y37:AF37,"历练")+COUNTIF(Y37:AF37,"营地")*2+COUNTIF(Y37:AF37,"塔1")*5 -> 12 | AO37: 商人 | AP37: 38 | AQ37: =AP37-AV17 -> -1 | AR37: =AQ37*AP17*0.8 -> -40 | AS37: =AQ37*AQ17 -> -30
A38: 46219 | B38: 1600 | D38: =(SUM(粮草!A38:X38)+AG38*10*IF(AK38="是",$BB$4,$BB$3)) -> 960 | E38: =SUM($B$4:B38)+SUM($C$4:C38)-SUM($D$4:D38) -> 3132 | F38: =SUM(经验!A38:X38) -> 360 | G38: =SUM($F$4:F38)+SUM($H$4:H38) -> 24625 | H38: 0 | I38: 空 | J38: 空 | K38: 空 | L38: 空 | M38: 空 | N38: 空 | O38: 空 | P38: 空 | Q38: 6级 | R38: 6级 | S38: 6级 | T38: 6级 | U38: 6级 | V38: 6级 | W38: 空 | X38: 空 | Y38: 空 | Z38: 空 | AA38: 空 | AB38: 空 | AC38: 空 | AD38: 空 | AE38: 空 | AF38: 空 | AG38: =AH38+AI38+AJ38 -> 0 | AK38: 是 | AL38: =MIN(AL37+6,18)-COUNTIF(I38:P38,"<>空")+COUNTIF(I38:P38,"历练")+COUNTIF(I38:P38,"营地")*2+COUNTIF(I38:P38,"塔1")*5 -> 18 | AM38: =MIN(AM37+6,18)-COUNTIF(Q38:X38,"<>空")+COUNTIF(Q38:X38,"历练")+COUNTIF(Q38:X38,"营地")*2+COUNTIF(Q38:X38,"塔1")*5 -> 12 | AN38: =MIN(AN37+6,18)-COUNTIF(Y38:AF38,"<>空")+COUNTIF(Y38:AF38,"历练")+COUNTIF(Y38:AF38,"营地")*2+COUNTIF(Y38:AF38,"塔1")*5 -> 18 | AO38: 草2 | AP38: 35 | AQ38: =AP38-AV11 -> -8 | AR38: =AQ38*AP11*0.8 -> -960 | AS38: =AQ38*AQ11 -> -320
A39: 46220 | B39: 1600 | D39: =(SUM(粮草!A39:X39)+AG39*10*IF(AK39="是",$BB$4,$BB$3)) -> 1808 | E39: =SUM($B$4:B39)+SUM($C$4:C39)-SUM($D$4:D39) -> 2924 | F39: =SUM(经验!A39:X39) -> 690 | G39: =SUM($F$4:F39)+SUM($H$4:H39) -> 25315 | H39: 0 | I39: 空 | J39: 空 | K39: 空 | L39: 空 | M39: 空 | N39: 空 | O39: 空 | P39: 空 | Q39: 商人 | R39: 6级 | S39: 6级 | T39: 6级 | U39: 6级 | V39: 6级 | W39: 空 | X39: 空 | Y39: 6级 | Z39: 6级 | AA39: 6级 | AB39: 6级 | AC39: 6级 | AD39: 6级 | AE39: 空 | AF39: 空 | AG39: =AH39+AI39+AJ39 -> 1 | AJ39: 1 | AK39: 是 | AL39: =MIN(AL38+6,18)-COUNTIF(I39:P39,"<>空")+COUNTIF(I39:P39,"历练")+COUNTIF(I39:P39,"营地")*2+COUNTIF(I39:P39,"塔1")*5 -> 18 | AM39: =MIN(AM38+6,18)-COUNTIF(Q39:X39,"<>空")+COUNTIF(Q39:X39,"历练")+COUNTIF(Q39:X39,"营地")*2+COUNTIF(Q39:X39,"塔1")*5 -> 12 | AN39: =MIN(AN38+6,18)-COUNTIF(Y39:AF39,"<>空")+COUNTIF(Y39:AF39,"历练")+COUNTIF(Y39:AF39,"营地")*2+COUNTIF(Y39:AF39,"塔1")*5 -> 12 | AO39: 草3 | AP39: 4 | AQ39: =AP39-AV12 -> 0 | AR39: =AQ39*AP12*0.8 -> 0 | AS39: =AQ39*AQ12 -> 0
A40: 46221 | B40: 1600 | D40: =(SUM(粮草!A40:X40)+AG40*10*IF(AK40="是",$BB$4,$BB$3)) -> 960 | E40: =SUM($B$4:B40)+SUM($C$4:C40)-SUM($D$4:D40) -> 3564 | F40: =SUM(经验!A40:X40) -> 360 | G40: =SUM($F$4:F40)+SUM($H$4:H40) -> 25675 | H40: 0 | I40: 空 | J40: 空 | K40: 空 | L40: 空 | M40: 空 | N40: 空 | O40: 空 | P40: 空 | Q40: 6级 | R40: 6级 | S40: 6级 | T40: 6级 | U40: 6级 | V40: 6级 | W40: 空 | X40: 空 | Y40: 空 | Z40: 空 | AA40: 空 | AB40: 空 | AC40: 空 | AD40: 空 | AE40: 空 | AF40: 空 | AG40: =AH40+AI40+AJ40 -> 0 | AK40: 是 | AL40: =MIN(AL39+6,18)-COUNTIF(I40:P40,"<>空")+COUNTIF(I40:P40,"历练")+COUNTIF(I40:P40,"营地")*2+COUNTIF(I40:P40,"塔1")*5 -> 18 | AM40: =MIN(AM39+6,18)-COUNTIF(Q40:X40,"<>空")+COUNTIF(Q40:X40,"历练")+COUNTIF(Q40:X40,"营地")*2+COUNTIF(Q40:X40,"塔1")*5 -> 12 | AN40: =MIN(AN39+6,18)-COUNTIF(Y40:AF40,"<>空")+COUNTIF(Y40:AF40,"历练")+COUNTIF(Y40:AF40,"营地")*2+COUNTIF(Y40:AF40,"塔1")*5 -> 18 | AO40: 草4 | AP40: 3 | AQ40: =AP40-AV13 -> 0 | AR40: =AQ40*AP13*0.8 -> 0 | AS40: =AQ40*AQ13 -> 0
...

Sheet 瞭望塔
B1: 瞭望塔坐标
B2: x | C2: y | D2: 等级 | E2: buff | F2: 行动 | G2: 粮草 | H2: 积分 | I2: 说明
A3: 塔1 | B3: 35 | C3: 11 | D3: 1 | E3: 迅疾 | F3: 5 | I3: 5次行动不消耗次数
A4: 塔1 | B4: 29 | C4: 15 | D4: 1 | E4: 兵粮 | F4: 5 | G4: 0.6 | I4: 5次行动消耗60%粮草
A5: 塔2 | B5: 27 | C5: 8 | D5: 2 | E5: 战勋 | F5: 8 | H5: 1.4 | I5: 8次行动1.4倍积分
A6: 塔2 | B6: 22 | C6: 15 | D6: 2 | E6: 迅疾 | F6: 8 | I6: 8次行动不消耗次数
A7: 塔3 | B7: 24 | C7: 27 | D7: 3 | E7: 兵粮 | F7: 10 | G7: 0.6 | I7: 10次行动消耗60%粮草
A8: 塔3 | B8: 38 | C8: 31 | D8: 3 | E8: 战勋 | F8: 10 | H8: 1.4 | I8: 10次行动1.4倍积分

Sheet 6.15
A1: 6.15 | D1: 18 | G1: 18 | J1: 9
C2: 1队 | F2: 2队 | I2: 3队 | N2: 1级 | O2: 150 | P2: 35
A3: 5720 | C3: 操作流 | D3: 粮草 | E3: 特殊 | F3: 操作流 | G3: 粮草 | H3: 特殊 | I3: 操作流 | J3: 粮草 | K3: 特殊 | N3: 2级 | O3: 160 | P3: 40
B4: 1 | C4: 飞雷神 | D4: 0 | F4: 跳6 | G4: 60 | I4: 商人 | J4: 50 | N4: 3级 | O4: 170 | P4: 45
A5: =D29+G29+J29 -> 4450 | B5: 2 | C5: 跳4 | D5: 40 | F5: 历练 | G5: 50 | I5: 2级 | J5: 160 | N5: 4级 | O5: 180 | P5: 50
B6: 3 | C6: 3级 | D6: 170 | E6: 18 | F6: 跳15 | G6: 150 | I6: 传送1 | J6: 10 | N6: 5级 | O6: 190 | P6: 55
A7: =A3-A5 -> 1270 | B7: 4 | C7: 3级 | D7: 170 | E7: 17 | F7: 传送1 | G7: 10 | I7: 3级 | J7: 170 | N7: 6级 | O7: 200 | P7: 60
B8: 5 | C8: 3级 | D8: 170 | E8: 16 | I8: 3级 | J8: 170 | N8: 草1 | O8: 150 | P8: 35
B9: 6 | C9: 营地 | D9: -250 | E9: 17 | I9: 3级 | J9: 170 | N9: 草2 | O9: 150 | P9: 40
B10: 7 | C10: 3级 | D10: 170 | E10: 16 | I10: 跳1 | J10: 10 | N10: 草3 | O10: 150 | P10: 45
B11: 8 | C11: 3级 | D11: 170 | E11: 15 | I11: 3级 | J11: 170 | N11: 草4 | O11: 150 | P11: 50
B12: 9 | C12: 3级 | D12: 170 | E12: 14 | I12: 商人 | J12: 50 | N12: 草5 | O12: 150 | P12: 55
B13: 10 | C13: 3级 | D13: 170 | E13: 13 | I13: 3级 | J13: 170 | N13: 草6 | O13: 150 | P13: 60
B14: 11 | C14: 商人 | D14: 50 | E14: 12 | I14: 3级 | J14: 170 | N14: 遗迹 | O14: 150 | P14: 40
B15: 12 | C15: 3级 | D15: 170 | E15: 11 | N15: 商人 | O15: 50 | P15: 30
B16: 13 | C16: 3级 | D16: 170 | E16: 10 | N16: 营地 | O16: -250 | P16: 0
B17: 14 | C17: 3级 | D17: 170 | E17: 9 | N17: 大卦 | O17: 250 | P17: 300
B18: 15 | C18: 3级卦 | D18: 170 | E18: 8 | N18: 3级卦 | O18: 170 | P18: 45
B19: 16 | C19: 跳2 | D19: 20 | N19: 巨卦 | O19: 250 | P19: 400
B20: 17 | C20: 3级 | D20: 170 | E20: 7 | N20: 大boss | O20: 250 | P20: 1000
B21: 18 | C21: 草2 | D21: 150 | E21: 6 | N21: 中boss | O21: 250 | P21: 500
B22: 19 | C22: 3级 | D22: 170 | E22: 5 | N22: 4级卦 | O22: 180 | P22: 50
B23: 20 | C23: 3级 | D23: 170 | E23: 4 | N23: 塔1 | O23: 160 | P23: 35
B24: 21 | C24: 3级 | D24: 170 | E24: 3 | N24: 塔2 | O24: 150 | P24: 40
B25: 22 | C25: 3级 | D25: 170 | E25: 2 | N25: 塔3 | O25: 150 | P25: 45
B26: 23 | C26: 草2 | D26: 150 | E26: 1 | N26: 空 | O26: 0 | P26: 0
B27: 24 | N27: 历练 | O27: 50 | P27: 520
B28: 25
D29: =SUM(D4:D28) -> 2880 | G29: =SUM(G4:G28) -> 270 | J29: =SUM(J4:J28) -> 1300
D30: 0 | G30: 18 | J30: 0

Sheet 6.16
A1: {=MID(CELL("filename",A1),FIND("]",CELL("filename",A1))+1,255)} -> 6.16 | B1: 起始行动 | D1: 18 | G1: 15 | J1: 13 | O1: 粮草 | P1: 经验 | Q1: 行动
A2: 起始粮草 | C2: 1队 | F2: 2队 | I2: 3队 | N2: 1级 | O2: 150 | P2: 35 | Q2: 1
A3: =5720+1600 -> 7320 | C3: 操作流 | D3: 粮草 | E3: 行动 | F3: 操作流 | G3: 粮草 | H3: 行动 | I3: 操作流 | J3: 粮草 | K3: 行动 | N3: 2级 | O3: 160 | P3: 40 | Q3: 1
A4: 消耗粮草 | B4: 1 | C4: 跳8 | D4: =IF(LEFT(C4,1)="跳",RIGHT(C4,LEN(C4)-1)*10,IFERROR(INDEX($O$2:$O$27, MATCH(C4, $N$2:$N$27, 0)), 0)) -> 80 | E4: =IFERROR(INDEX($Q$2:$Q$27,MATCH(C4,$N$2:$N$27,0)),0) -> 0 | G4: =IF(LEFT(F4,1)="跳",RIGHT(F4,LEN(F4)-1)*10,IFERROR(INDEX($O$2:$O$27, MATCH(F4, $N$2:$N$27, 0)), 0)) -> 0 | H4: =IFERROR(INDEX($Q$2:$Q$27,MATCH(F4,$N$2:$N$27,0)),0) -> 0 | I4: 商人 | J4: =IF(LEFT(I4,1)="跳",RIGHT(I4,LEN(I4)-1)*10,IFERROR(INDEX($O$2:$O$27, MATCH(I4, $N$2:$N$27, 0)), 0)) -> 50 | K4: =IFERROR(INDEX($Q$2:$Q$27,MATCH(I4,$N$2:$N$27,0)),0) -> 1 | N4: 3级 | O4: 170 | P4: 45 | Q4: 1
A5: =D29+G29+J29 -> 4560 | B5: 2 | C5: 3级 | D5: =IF(LEFT(C5,1)="跳",RIGHT(C5,LEN(C5)-1)*10,IFERROR(INDEX($O$2:$O$27, MATCH(C5, $N$2:$N$27, 0)), 0)) -> 170 | E5: =IFERROR(INDEX($Q$2:$Q$27,MATCH(C5,$N$2:$N$27,0)),0) -> 1 | G5: =IF(LEFT(F5,1)="跳",RIGHT(F5,LEN(F5)-1)*10,IFERROR(INDEX($O$2:$O$27, MATCH(F5, $N$2:$N$27, 0)), 0)) -> 0 | H5: =IFERROR(INDEX($Q$2:$Q$27,MATCH(F5,$N$2:$N$27,0)),0) -> 0 | I5: 2级 | J5: =IF(LEFT(I5,1)="跳",RIGHT(I5,LEN(I5)-1)*10,IFERROR(INDEX($O$2:$O$27, MATCH(I5, $N$2:$N$27, 0)), 0)) -> 160 | K5: =IFERROR(INDEX($Q$2:$Q$27,MATCH(I5,$N$2:$N$27,0)),0) -> 1 | N5: 4级 | O5: 180 | P5: 50 | Q5: 1
A6: 剩余粮草 | B6: 3 | C6: 3级 | D6: =IF(LEFT(C6,1)="跳",RIGHT(C6,LEN(C6)-1)*10,IFERROR(INDEX($O$2:$O$27, MATCH(C6, $N$2:$N$27, 0)), 0)) -> 170 | E6: =IFERROR(INDEX($Q$2:$Q$27,MATCH(C6,$N$2:$N$27,0)),0) -> 1 | G6: =IF(LEFT(F6,1)="跳",RIGHT(F6,LEN(F6)-1)*10,IFERROR(INDEX($O$2:$O$27, MATCH(F6, $N$2:$N$27, 0)), 0)) -> 0 | H6: =IFERROR(INDEX($Q$2:$Q$27,MATCH(F6,$N$2:$N$27,0)),0) -> 0 | I6: 跳1 | J6: =IF(LEFT(I6,1)="跳",RIGHT(I6,LEN(I6)-1)*10,IFERROR(INDEX($O$2:$O$27, MATCH(I6, $N$2:$N$27, 0)), 0)) -> 10 | K6: =IFERROR(INDEX($Q$2:$Q$27,MATCH(I6,$N$2:$N$27,0)),0) -> 0 | N6: 5级 | O6: 190 | P6: 55 | Q6: 1
A7: =A3-A5 -> 2760 | B7: 4 | C7: 3级 | D7: =IF(LEFT(C7,1)="跳",RIGHT(C7,LEN(C7)-1)*10,IFERROR(INDEX($O$2:$O$27, MATCH(C7, $N$2:$N$27, 0)), 0)) -> 170 | E7: =IFERROR(INDEX($Q$2:$Q$27,MATCH(C7,$N$2:$N$27,0)),0) -> 1 | G7: =IF(LEFT(F7,1)="跳",RIGHT(F7,LEN(F7)-1)*10,IFERROR(INDEX($O$2:$O$27, MATCH(F7, $N$2:$N$27, 0)), 0)) -> 0 | H7: =IFERROR(INDEX($Q$2:$Q$27,MATCH(F7,$N$2:$N$27,0)),0) -> 0 | I7: 3级 | J7: =IF(LEFT(I7,1)="跳",RIGHT(I7,LEN(I7)-1)*10,IFERROR(INDEX($O$2:$O$27, MATCH(I7, $N$2:$N$27, 0)), 0)) -> 170 | K7: =IFERROR(INDEX($Q$2:$Q$27,MATCH(I7,$N$2:$N$27,0)),0) -> 1 | N7: 6级 | O7: 200 | P7: 60 | Q7: 1
B8: 5 | C8: 3级 | D8: =IF(LEFT(C8,1)="跳",RIGHT(C8,LEN(C8)-1)*10,IFERROR(INDEX($O$2:$O$27, MATCH(C8, $N$2:$N$27, 0)), 0)) -> 170 | E8: =IFERROR(INDEX($Q$2:$Q$27,MATCH(C8,$N$2:$N$27,0)),0) -> 1 | G8: =IF(LEFT(F8,1)="跳",RIGHT(F8,LEN(F8)-1)*10,IFERROR(INDEX($O$2:$O$27, MATCH(F8, $N$2:$N$27, 0)), 0)) -> 0 | H8: =IFERROR(INDEX($Q$2:$Q$27,MATCH(F8,$N$2:$N$27,0)),0) -> 0 | I8: 3级 | J8: =IF(LEFT(I8,1)="跳",RIGHT(I8,LEN(I8)-1)*10,IFERROR(INDEX($O$2:$O$27, MATCH(I8, $N$2:$N$27, 0)), 0)) -> 170 | K8: =IFERROR(INDEX($Q$2:$Q$27,MATCH(I8,$N$2:$N$27,0)),0) -> 1 | N8: 草1 | O8: 150 | P8: 35 | Q8: 1
B9: 6 | C9: 商人 | D9: =IF(LEFT(C9,1)="跳",RIGHT(C9,LEN(C9)-1)*10,IFERROR(INDEX($O$2:$O$27, MATCH(C9, $N$2:$N$27, 0)), 0)) -> 50 | E9: =IFERROR(INDEX($Q$2:$Q$27,MATCH(C9,$N$2:$N$27,0)),0) -> 1 | G9: =IF(LEFT(F9,1)="跳",RIGHT(F9,LEN(F9)-1)*10,IFERROR(INDEX($O$2:$O$27, MATCH(F9, $N$2:$N$27, 0)), 0)) -> 0 | H9: =IFERROR(INDEX($Q$2:$Q$27,MATCH(F9,$N$2:$N$27,0)),0) -> 0 | J9: =IF(LEFT(I9,1)="跳",RIGHT(I9,LEN(I9)-1)*10,IFERROR(INDEX($O$2:$O$27, MATCH(I9, $N$2:$N$27, 0)), 0)) -> 0 | K9: =IFERROR(INDEX($Q$2:$Q$27,MATCH(I9,$N$2:$N$27,0)),0) -> 0 | N9: 草2 | O9: 150 | P9: 40 | Q9: 1
B10: 7 | C10: 3级 | D10: =IF(LEFT(C10,1)="跳",RIGHT(C10,LEN(C10)-1)*10,IFERROR(INDEX($O$2:$O$27, MATCH(C10, $N$2:$N$27, 0)), 0)) -> 170 | E10: =IFERROR(INDEX($Q$2:$Q$27,MATCH(C10,$N$2:$N$27,0)),0) -> 1 | G10: =IF(LEFT(F10,1)="跳",RIGHT(F10,LEN(F10)-1)*10,IFERROR(INDEX($O$2:$O$27, MATCH(F10, $N$2:$N$27, 0)), 0)) -> 0 | H10: =IFERROR(INDEX($Q$2:$Q$27,MATCH(F10,$N$2:$N$27,0)),0) -> 0 | J10: =IF(LEFT(I10,1)="跳",RIGHT(I10,LEN(I10)-1)*10,IFERROR(INDEX($O$2:$O$27, MATCH(I10, $N$2:$N$27, 0)), 0)) -> 0 | K10: =IFERROR(INDEX($Q$2:$Q$27,MATCH(I10,$N$2:$N$27,0)),0) -> 0 | N10: 草3 | O10: 150 | P10: 45 | Q10: 1
B11: 8 | C11: 3级 | D11: =IF(LEFT(C11,1)="跳",RIGHT(C11,LEN(C11)-1)*10,IFERROR(INDEX($O$2:$O$27, MATCH(C11, $N$2:$N$27, 0)), 0)) -> 170 | E11: =IFERROR(INDEX($Q$2:$Q$27,MATCH(C11,$N$2:$N$27,0)),0) -> 1 | G11: =IF(LEFT(F11,1)="跳",RIGHT(F11,LEN(F11)-1)*10,IFERROR(INDEX($O$2:$O$27, MATCH(F11, $N$2:$N$27, 0)), 0)) -> 0 | H11: =IFERROR(INDEX($Q$2:$Q$27,MATCH(F11,$N$2:$N$27,0)),0) -> 0 | I11: 3级 | J11: =IF(LEFT(I11,1)="跳",RIGHT(I11,LEN(I11)-1)*10,IFERROR(INDEX($O$2:$O$27, MATCH(I11, $N$2:$N$27, 0)), 0)) -> 170 | K11: =IFERROR(INDEX($Q$2:$Q$27,MATCH(I11,$N$2:$N$27,0)),0) -> 1 | N11: 草4 | O11: 150 | P11: 50 | Q11: 1
B12: 9 | C12: 3级 | D12: =IF(LEFT(C12,1)="跳",RIGHT(C12,LEN(C12)-1)*10,IFERROR(INDEX($O$2:$O$27, MATCH(C12, $N$2:$N$27, 0)), 0)) -> 170 | E12: =IFERROR(INDEX($Q$2:$Q$27,MATCH(C12,$N$2:$N$27,0)),0) -> 1 | G12: =IF(LEFT(F12,1)="跳",RIGHT(F12,LEN(F12)-1)*10,IFERROR(INDEX($O$2:$O$27, MATCH(F12, $N$2:$N$27, 0)), 0)) -> 0 | H12: =IFERROR(INDEX($Q$2:$Q$27,MATCH(F12,$N$2:$N$27,0)),0) -> 0 | I12: 商人 | J12: =IF(LEFT(I12,1)="跳",RIGHT(I12,LEN(I12)-1)*10,IFERROR(INDEX($O$2:$O$27, MATCH(I12, $N$2:$N$27, 0)), 0)) -> 50 | K12: =IFERROR(INDEX($Q$2:$Q$27,MATCH(I12,$N$2:$N$27,0)),0) -> 1 | N12: 草5 | O12: 150 | P12: 55 | Q12: 1
B13: 10 | C13: 3级卦 | D13: =IF(LEFT(C13,1)="跳",RIGHT(C13,LEN(C13)-1)*10,IFERROR(INDEX($O$2:$O$27, MATCH(C13, $N$2:$N$27, 0)), 0)) -> 170 | E13: =IFERROR(INDEX($Q$2:$Q$27,MATCH(C13,$N$2:$N$27,0)),0) -> 1 | G13: =IF(LEFT(F13,1)="跳",RIGHT(F13,LEN(F13)-1)*10,IFERROR(INDEX($O$2:$O$27, MATCH(F13, $N$2:$N$27, 0)), 0)) -> 0 | H13: =IFERROR(INDEX($Q$2:$Q$27,MATCH(F13,$N$2:$N$27,0)),0) -> 0 | I13: 3级 | J13: =IF(LEFT(I13,1)="跳",RIGHT(I13,LEN(I13)-1)*10,IFERROR(INDEX($O$2:$O$27, MATCH(I13, $N$2:$N$27, 0)), 0)) -> 170 | K13: =IFERROR(INDEX($Q$2:$Q$27,MATCH(I13,$N$2:$N$27,0)),0) -> 1 | N13: 草6 | O13: 150 | P13: 60 | Q13: 1
B14: 11 | C14: 跳2 | D14: =IF(LEFT(C14,1)="跳",RIGHT(C14,LEN(C14)-1)*10,IFERROR(INDEX($O$2:$O$27, MATCH(C14, $N$2:$N$27, 0)), 0)) -> 20 | E14: =IFERROR(INDEX($Q$2:$Q$27,MATCH(C14,$N$2:$N$27,0)),0) -> 0 | G14: =IF(LEFT(F14,1)="跳",RIGHT(F14,LEN(F14)-1)*10,IFERROR(INDEX($O$2:$O$27, MATCH(F14, $N$2:$N$27, 0)), 0)) -> 0 | H14: =IFERROR(INDEX($Q$2:$Q$27,MATCH(F14,$N$2:$N$27,0)),0) -> 0 | I14: 3级 | J14: =IF(LEFT(I14,1)="跳",RIGHT(I14,LEN(I14)-1)*10,IFERROR(INDEX($O$2:$O$27, MATCH(I14, $N$2:$N$27, 0)), 0)) -> 170 | K14: =IFERROR(INDEX($Q$2:$Q$27,MATCH(I14,$N$2:$N$27,0)),0) -> 1 | N14: 遗迹 | O14: 150 | P14: 40 | Q14: 1
B15: 12 | C15: 3级 | D15: =IF(LEFT(C15,1)="跳",RIGHT(C15,LEN(C15)-1)*10,IFERROR(INDEX($O$2:$O$27, MATCH(C15, $N$2:$N$27, 0)), 0)) -> 170 | E15: =IFERROR(INDEX($Q$2:$Q$27,MATCH(C15,$N$2:$N$27,0)),0) -> 1 | G15: =IF(LEFT(F15,1)="跳",RIGHT(F15,LEN(F15)-1)*10,IFERROR(INDEX($O$2:$O$27, MATCH(F15, $N$2:$N$27, 0)), 0)) -> 0 | H15: =IFERROR(INDEX($Q$2:$Q$27,MATCH(F15,$N$2:$N$27,0)),0) -> 0 | I15: 3级卦 | J15: =IF(LEFT(I15,1)="跳",RIGHT(I15,LEN(I15)-1)*10,IFERROR(INDEX($O$2:$O$27, MATCH(I15, $N$2:$N$27, 0)), 0)) -> 170 | K15: =IFERROR(INDEX($Q$2:$Q$27,MATCH(I15,$N$2:$N$27,0)),0) -> 1 | N15: 商人 | O15: 50 | P15: 30 | Q15: 1
B16: 13 | C16: 草2 | D16: =IF(LEFT(C16,1)="跳",RIGHT(C16,LEN(C16)-1)*10,IFERROR(INDEX($O$2:$O$27, MATCH(C16, $N$2:$N$27, 0)), 0)) -> 150 | E16: =IFERROR(INDEX($Q$2:$Q$27,MATCH(C16,$N$2:$N$27,0)),0) -> 1 | G16: =IF(LEFT(F16,1)="跳",RIGHT(F16,LEN(F16)-1)*10,IFERROR(INDEX($O$2:$O$27, MATCH(F16, $N$2:$N$27, 0)), 0)) -> 0 | H16: =IFERROR(INDEX($Q$2:$Q$27,MATCH(F16,$N$2:$N$27,0)),0) -> 0 | I16: 跳1 | J16: =IF(LEFT(I16,1)="跳",RIGHT(I16,LEN(I16)-1)*10,IFERROR(INDEX($O$2:$O$27, MATCH(I16, $N$2:$N$27, 0)), 0)) -> 10 | K16: =IFERROR(INDEX($Q$2:$Q$27,MATCH(I16,$N$2:$N$27,0)),0) -> 0 | N16: 营地 | O16: -250 | P16: 0 | Q16: -1
B17: 14 | C17: 3级 | D17: =IF(LEFT(C17,1)="跳",RIGHT(C17,LEN(C17)-1)*10,IFERROR(INDEX($O$2:$O$27, MATCH(C17, $N$2:$N$27, 0)), 0)) -> 170 | E17: =IFERROR(INDEX($Q$2:$Q$27,MATCH(C17,$N$2:$N$27,0)),0) -> 1 | G17: =IF(LEFT(F17,1)="跳",RIGHT(F17,LEN(F17)-1)*10,IFERROR(INDEX($O$2:$O$27, MATCH(F17, $N$2:$N$27, 0)), 0)) -> 0 | H17: =IFERROR(INDEX($Q$2:$Q$27,MATCH(F17,$N$2:$N$27,0)),0) -> 0 | I17: 3级 | J17: =IF(LEFT(I17,1)="跳",RIGHT(I17,LEN(I17)-1)*10,IFERROR(INDEX($O$2:$O$27, MATCH(I17, $N$2:$N$27, 0)), 0)) -> 170 | K17: =IFERROR(INDEX($Q$2:$Q$27,MATCH(I17,$N$2:$N$27,0)),0) -> 1 | N17: 大卦 | O17: 250 | P17: 300 | Q17: 1
B18: 15 | C18: 3级 | D18: =IF(LEFT(C18,1)="跳",RIGHT(C18,LEN(C18)-1)*10,IFERROR(INDEX($O$2:$O$27, MATCH(C18, $N$2:$N$27, 0)), 0)) -> 170 | E18: =IFERROR(INDEX($Q$2:$Q$27,MATCH(C18,$N$2:$N$27,0)),0) -> 1 | G18: =IF(LEFT(F18,1)="跳",RIGHT(F18,LEN(F18)-1)*10,IFERROR(INDEX($O$2:$O$27, MATCH(F18, $N$2:$N$27, 0)), 0)) -> 0 | H18: =IFERROR(INDEX($Q$2:$Q$27,MATCH(F18,$N$2:$N$27,0)),0) -> 0 | I18: 3级 | J18: =IF(LEFT(I18,1)="跳",RIGHT(I18,LEN(I18)-1)*10,IFERROR(INDEX($O$2:$O$27, MATCH(I18, $N$2:$N$27, 0)), 0)) -> 170 | K18: =IFERROR(INDEX($Q$2:$Q$27,MATCH(I18,$N$2:$N$27,0)),0) -> 1 | N18: 3级卦 | O18: 170 | P18: 45 | Q18: 1
B19: 16 | C19: 3级 | D19: =IF(LEFT(C19,1)="跳",RIGHT(C19,LEN(C19)-1)*10,IFERROR(INDEX($O$2:$O$27, MATCH(C19, $N$2:$N$27, 0)), 0)) -> 170 | E19: =IFERROR(INDEX($Q$2:$Q$27,MATCH(C19,$N$2:$N$27,0)),0) -> 1 | G19: =IF(LEFT(F19,1)="跳",RIGHT(F19,LEN(F19)-1)*10,IFERROR(INDEX($O$2:$O$27, MATCH(F19, $N$2:$N$27, 0)), 0)) -> 0 | H19: =IFERROR(INDEX($Q$2:$Q$27,MATCH(F19,$N$2:$N$27,0)),0) -> 0 | I19: 3级 | J19: =IF(LEFT(I19,1)="跳",RIGHT(I19,LEN(I19)-1)*10,IFERROR(INDEX($O$2:$O$27, MATCH(I19, $N$2:$N$27, 0)), 0)) -> 170 | K19: =IFERROR(INDEX($Q$2:$Q$27,MATCH(I19,$N$2:$N$27,0)),0) -> 1 | N19: 巨卦 | O19: 250 | P19: 400 | Q19: 1
B20: 17 | C20: 3级 | D20: =IF(LEFT(C20,1)="跳",RIGHT(C20,LEN(C20)-1)*10,IFERROR(INDEX($O$2:$O$27, MATCH(C20, $N$2:$N$27, 0)), 0)) -> 170 | E20: =IFERROR(INDEX($Q$2:$Q$27,MATCH(C20,$N$2:$N$27,0)),0) -> 1 | G20: =IF(LEFT(F20,1)="跳",RIGHT(F20,LEN(F20)-1)*10,IFERROR(INDEX($O$2:$O$27, MATCH(F20, $N$2:$N$27, 0)), 0)) -> 0 | H20: =IFERROR(INDEX($Q$2:$Q$27,MATCH(F20,$N$2:$N$27,0)),0) -> 0 | I20: 营地 | J20: =IF(LEFT(I20,1)="跳",RIGHT(I20,LEN(I20)-1)*10,IFERROR(INDEX($O$2:$O$27, MATCH(I20, $N$2:$N$27, 0)), 0)) -> -250 | K20: =IFERROR(INDEX($Q$2:$Q$27,MATCH(I20,$N$2:$N$27,0)),0) -> -1 | N20: 大boss | O20: 250 | P20: 1000 | Q20: 1
B21: 18 | C21: 草2 | D21: =IF(LEFT(C21,1)="跳",RIGHT(C21,LEN(C21)-1)*10,IFERROR(INDEX($O$2:$O$27, MATCH(C21, $N$2:$N$27, 0)), 0)) -> 150 | E21: =IFERROR(INDEX($Q$2:$Q$27,MATCH(C21,$N$2:$N$27,0)),0) -> 1 | G21: =IF(LEFT(F21,1)="跳",RIGHT(F21,LEN(F21)-1)*10,IFERROR(INDEX($O$2:$O$27, MATCH(F21, $N$2:$N$27, 0)), 0)) -> 0 | H21: =IFERROR(INDEX($Q$2:$Q$27,MATCH(F21,$N$2:$N$27,0)),0) -> 0 | J21: =IF(LEFT(I21,1)="跳",RIGHT(I21,LEN(I21)-1)*10,IFERROR(INDEX($O$2:$O$27, MATCH(I21, $N$2:$N$27, 0)), 0)) -> 0 | K21: =IFERROR(INDEX($Q$2:$Q$27,MATCH(I21,$N$2:$N$27,0)),0) -> 0 | N21: 中boss | O21: 250 | P21: 500 | Q21: 1
B22: 19 | C22: 3级 | D22: =IF(LEFT(C22,1)="跳",RIGHT(C22,LEN(C22)-1)*10,IFERROR(INDEX($O$2:$O$27, MATCH(C22, $N$2:$N$27, 0)), 0)) -> 170 | E22: =IFERROR(INDEX($Q$2:$Q$27,MATCH(C22,$N$2:$N$27,0)),0) -> 1 | G22: =IF(LEFT(F22,1)="跳",RIGHT(F22,LEN(F22)-1)*10,IFERROR(INDEX($O$2:$O$27, MATCH(F22, $N$2:$N$27, 0)), 0)) -> 0 | H22: =IFERROR(INDEX($Q$2:$Q$27,MATCH(F22,$N$2:$N$27,0)),0) -> 0 | J22: =IF(LEFT(I22,1)="跳",RIGHT(I22,LEN(I22)-1)*10,IFERROR(INDEX($O$2:$O$27, MATCH(I22, $N$2:$N$27, 0)), 0)) -> 0 | K22: =IFERROR(INDEX($Q$2:$Q$27,MATCH(I22,$N$2:$N$27,0)),0) -> 0 | N22: 4级卦 | O22: 180 | P22: 50 | Q22: 1
B23: 20 | C23: 3级 | D23: =IF(LEFT(C23,1)="跳",RIGHT(C23,LEN(C23)-1)*10,IFERROR(INDEX($O$2:$O$27, MATCH(C23, $N$2:$N$27, 0)), 0)) -> 170 | E23: =IFERROR(INDEX($Q$2:$Q$27,MATCH(C23,$N$2:$N$27,0)),0) -> 1 | G23: =IF(LEFT(F23,1)="跳",RIGHT(F23,LEN(F23)-1)*10,IFERROR(INDEX($O$2:$O$27, MATCH(F23, $N$2:$N$27, 0)), 0)) -> 0 | H23: =IFERROR(INDEX($Q$2:$Q$27,MATCH(F23,$N$2:$N$27,0)),0) -> 0 | J23: =IF(LEFT(I23,1)="跳",RIGHT(I23,LEN(I23)-1)*10,IFERROR(INDEX($O$2:$O$27, MATCH(I23, $N$2:$N$27, 0)), 0)) -> 0 | K23: =IFERROR(INDEX($Q$2:$Q$27,MATCH(I23,$N$2:$N$27,0)),0) -> 0 | N23: 塔1 | O23: 160 | P23: 35 | Q23: 1
B24: 21 | D24: =IF(LEFT(C24,1)="跳",RIGHT(C24,LEN(C24)-1)*10,IFERROR(INDEX($O$2:$O$27, MATCH(C24, $N$2:$N$27, 0)), 0)) -> 0 | E24: =IFERROR(INDEX($Q$2:$Q$27,MATCH(C24,$N$2:$N$27,0)),0) -> 0 | G24: =IF(LEFT(F24,1)="跳",RIGHT(F24,LEN(F24)-1)*10,IFERROR(INDEX($O$2:$O$27, MATCH(F24, $N$2:$N$27, 0)), 0)) -> 0 | H24: =IFERROR(INDEX($Q$2:$Q$27,MATCH(F24,$N$2:$N$27,0)),0) -> 0 | J24: =IF(LEFT(I24,1)="跳",RIGHT(I24,LEN(I24)-1)*10,IFERROR(INDEX($O$2:$O$27, MATCH(I24, $N$2:$N$27, 0)), 0)) -> 0 | K24: =IFERROR(INDEX($Q$2:$Q$27,MATCH(I24,$N$2:$N$27,0)),0) -> 0 | N24: 塔2 | O24: 150 | P24: 40 | Q24: 1
B25: 22 | D25: =IF(LEFT(C25,1)="跳",RIGHT(C25,LEN(C25)-1)*10,IFERROR(INDEX($O$2:$O$27, MATCH(C25, $N$2:$N$27, 0)), 0)) -> 0 | E25: =IFERROR(INDEX($Q$2:$Q$27,MATCH(C25,$N$2:$N$27,0)),0) -> 0 | G25: =IF(LEFT(F25,1)="跳",RIGHT(F25,LEN(F25)-1)*10,IFERROR(INDEX($O$2:$O$27, MATCH(F25, $N$2:$N$27, 0)), 0)) -> 0 | H25: =IFERROR(INDEX($Q$2:$Q$27,MATCH(F25,$N$2:$N$27,0)),0) -> 0 | J25: =IF(LEFT(I25,1)="跳",RIGHT(I25,LEN(I25)-1)*10,IFERROR(INDEX($O$2:$O$27, MATCH(I25, $N$2:$N$27, 0)), 0)) -> 0 | K25: =IFERROR(INDEX($Q$2:$Q$27,MATCH(I25,$N$2:$N$27,0)),0) -> 0 | N25: 塔3 | O25: 150 | P25: 45 | Q25: 1
B26: 23 | D26: =IF(LEFT(C26,1)="跳",RIGHT(C26,LEN(C26)-1)*10,IFERROR(INDEX($O$2:$O$27, MATCH(C26, $N$2:$N$27, 0)), 0)) -> 0 | E26: =IFERROR(INDEX($Q$2:$Q$27,MATCH(C26,$N$2:$N$27,0)),0) -> 0 | G26: =IF(LEFT(F26,1)="跳",RIGHT(F26,LEN(F26)-1)*10,IFERROR(INDEX($O$2:$O$27, MATCH(F26, $N$2:$N$27, 0)), 0)) -> 0 | H26: =IFERROR(INDEX($Q$2:$Q$27,MATCH(F26,$N$2:$N$27,0)),0) -> 0 | J26: =IF(LEFT(I26,1)="跳",RIGHT(I26,LEN(I26)-1)*10,IFERROR(INDEX($O$2:$O$27, MATCH(I26, $N$2:$N$27, 0)), 0)) -> 0 | K26: =IFERROR(INDEX($Q$2:$Q$27,MATCH(I26,$N$2:$N$27,0)),0) -> 0 | N26: 空 | O26: 0 | P26: 0 | Q26: 0
B27: 24 | D27: =IF(LEFT(C27,1)="跳",RIGHT(C27,LEN(C27)-1)*10,IFERROR(INDEX($O$2:$O$27, MATCH(C27, $N$2:$N$27, 0)), 0)) -> 0 | E27: =IFERROR(INDEX($Q$2:$Q$27,MATCH(C27,$N$2:$N$27,0)),0) -> 0 | G27: =IF(LEFT(F27,1)="跳",RIGHT(F27,LEN(F27)-1)*10,IFERROR(INDEX($O$2:$O$27, MATCH(F27, $N$2:$N$27, 0)), 0)) -> 0 | H27: =IFERROR(INDEX($Q$2:$Q$27,MATCH(F27,$N$2:$N$27,0)),0) -> 0 | J27: =IF(LEFT(I27,1)="跳",RIGHT(I27,LEN(I27)-1)*10,IFERROR(INDEX($O$2:$O$27, MATCH(I27, $N$2:$N$27, 0)), 0)) -> 0 | K27: =IFERROR(INDEX($Q$2:$Q$27,MATCH(I27,$N$2:$N$27,0)),0) -> 0 | N27: 历练 | O27: 50 | P27: 520 | Q27: 0
B28: 25 | D28: =IF(LEFT(C28,1)="跳",RIGHT(C28,LEN(C28)-1)*10,IFERROR(INDEX($O$2:$O$27, MATCH(C28, $N$2:$N$27, 0)), 0)) -> 0 | E28: =IFERROR(INDEX($Q$2:$Q$27,MATCH(C28,$N$2:$N$27,0)),0) -> 0 | G28: =IF(LEFT(F28,1)="跳",RIGHT(F28,LEN(F28)-1)*10,IFERROR(INDEX($O$2:$O$27, MATCH(F28, $N$2:$N$27, 0)), 0)) -> 0 | H28: =IFERROR(INDEX($Q$2:$Q$27,MATCH(F28,$N$2:$N$27,0)),0) -> 0 | J28: =IF(LEFT(I28,1)="跳",RIGHT(I28,LEN(I28)-1)*10,IFERROR(INDEX($O$2:$O$27, MATCH(I28, $N$2:$N$27, 0)), 0)) -> 0 | K28: =IFERROR(INDEX($Q$2:$Q$27,MATCH(I28,$N$2:$N$27,0)),0) -> 0
B29: 小计 | D29: =SUM(D4:D28) -> 3000 | E29: =SUM(E4:E28) -> 18 | G29: =SUM(G4:G28) -> 0 | H29: =SUM(H4:H28) -> 0 | J29: =SUM(J4:J28) -> 1560 | K29: =SUM(K4:K28) -> 11
B30: 结束行动 | D30: =D1-E29 -> 0 | G30: =G1-H29 -> 15 | J30: =J1-K29 -> 2

Sheet 6.17
A1: {=MID(CELL("filename",A1),FIND("]",CELL("filename",A1))+1,255)} -> 6.17 | B1: 起始行动 | D1: =MIN(18,'6.16'!D30+6) -> 6 | G1: =MIN(18,'6.16'!G30+6) -> 18 | J1: =MIN(18,'6.16'!J30+6) -> 8 | O1: 粮草 | P1: 经验 | Q1: 行动
A2: 起始粮草 | C2: 1队 | F2: 2队 | I2: 3队 | N2: 1级 | O2: 150 | P2: 35 | Q2: 1
A3: ='6.16'!A7+1600 -> 4360 | C3: 操作流 | D3: 粮草 | E3: 行动 | F3: 操作流 | G3: 粮草 | H3: 行动 | I3: 操作流 | J3: 粮草 | K3: 行动 | N3: 2级 | O3: 160 | P3: 40 | Q3: 1
