Workbook

Sheet 7.0.3
A1: =(_xlfn.DAYS(TODAY(),A4)+2)/((_xlfn.DAYS(A94,A4))+1) -> 0.032967033 | I1: 工作区 | AM1: 使用方法：按自己规划的路线，将下表中的地块名复制粘贴至工作区。初次使用传送门，当天跳步次数+5。重复使用传送门，当天跳步次数+1
A2: version 7.0.2 | B2: 八卦前亏 | C2: =SUM(亏损!A4:X94)+SUM(AG4:AG14)*10 -> 29595.546 | D2: 合计经验 | F2: =SUM(F4:F94)+SUM(H4:H94) -> 65110 | I2: 队伍一 火 | K2: 步数 | L2: =COUNTIF(I4:P94,"<>空") -> 433 | M2: (不算跳步和传送) | Q2: 队伍二 雷 | S2: 步数 | T2: =COUNTIF(Q4:X94,"<>空") -> 543 | U2: (不算跳步和传送) | Y2: 队伍三 | AA2: 总步数 | AB2: =COUNTIF(Y4:AF94,"<>空") -> 99 | AC2: (不算跳步和传送) | AG2: =SUM(AG4:AG94) -> 13 | AH2: =SUM(AH4:AH94) -> 1 | AI2: =SUM(AI4:AI94) -> 7 | AJ2: =SUM(AJ4:AJ94) -> 5 | AK2: 八卦全开 | AS2: 总地块 | AT2: =SUM(AT4:AT29) -> 1075 | AV2: 总经验 | AW2: =SUM(AU4:AW29)+7000 -> 65110 | AY2: 粮草系数
A3: 日期 | B3: 获得粮草 | C3: 种植粮草 | D3: 消耗粮草 | E3: 剩余粮草 | F3: 获得经验 | G3: 累计经验 | H3: 任务经验 | I3: 1 | J3: 2 | K3: 3 | L3: 4 | M3: 5 | N3: 6 | O3: 7 | P3: 8 | Q3: 1 | R3: 2 | S3: 3 | T3: 4 | U3: 5 | V3: 6 | W3: 7 | X3: 8 | Y3: 1 | Z3: 2 | AA3: 3 | AB3: 4 | AC3: 5 | AD3: 6 | AE3: 7 | AF3: 8 | AG3: 跳步次数 | AH3: 1队跳步 | AI3: 2队跳步 | AJ3: 3队跳步 | AM3: 地块 | AN3: 粮草 | AO3: 经验 | AP3: 八卦前亏损 | AQ3: 一队地块 | AR3: 二队地块 | AS3: 三队地块 | AT3: 总地块 | AU3: 一队经验 | AV3: 二队经验 | AW3: 三队经验 | AX3: 八卦前 | AY3: 1
A4: 44638 | B4: 800 | C4: 6000 | D4: =(SUM(粮草!A4:X4)+AG4*10)*IF(AK4="是",$AY$4,$AY$3) -> 2750 | E4: =SUM($B$4:B4)+SUM($C$4:C4)-SUM($D$4:D4) -> 4050 | F4: =SUM(经验!A4:X4) -> 1230 | G4: =SUM($F$4:F4)+SUM($H$4:H4) -> 1230 | H4: 0 | I4: 1级 | J4: 1级 | K4: 1级 | L4: 1级 | M4: 1级 | N4: 商人 | O4: 空 | P4: 空 | Q4: 1级 | R4: 1级 | S4: 营地 | T4: 2级 | U4: 2级 | V4: 2级 | W4: 2级 | X4: 2级 | Y4: 2级 | Z4: 遗迹 | AA4: 2级 | AB4: 2级 | AC4: 历练 | AD4: 2级 | AE4: 2级 | AF4: 空 | AG4: =AH4+AI4+AJ4 -> 0 | AK4: 否 | AM4: 1级 | AN4: 150 | AO4: 35 | AP4: 44.222109 | AQ4: =COUNTIF($I$4:$P$94,AM4) -> 5 | AR4: =COUNTIF($Q$4:$X$94,AM4) -> 3 | AS4: =COUNTIF($Y$4:$AF$94,AM4) -> 0 | AT4: =AQ4+AR4+AS4 -> 8 | AU4: =AQ4*$AO4 -> 175 | AV4: =AR4*$AO4 -> 105 | AW4: =AS4*$AO4 -> 0 | AX4: 八卦后 | AY4: 0.8 | BA4: =AN4*0.8 -> 120
A5: 44639 | B5: 1600 | D5: =(SUM(粮草!A5:X5)+AG5*10)*IF(AK5="是",$AY$4,$AY$3)-50 -> 2970 | E5: =SUM($B$4:B5)+SUM($C$4:C5)-SUM($D$4:D5) -> 2680 | F5: =SUM(经验!A5:X5) -> 895 | G5: =SUM($F$4:F5)+SUM($H$4:H5) -> 2625 | H5: 500 | I5: 2级 | J5: 2级 | K5: 2级 | L5: 2级 | M5: 2级 | N5: 商人 | O5: 空 | P5: 空 | Q5: 2级 | R5: 2级 | S5: 2级 | T5: 2级 | U5: 2级 | V5: 2级 | W5: 空 | X5: 空 | Y5: 4级 | Z5: 遗迹 | AA5: 4级 | AB5: 大卦 | AC5: 3级 | AD5: 3级 | AE5: 空 | AF5: 空 | AG5: =AH5+AI5+AJ5 -> 11 | AI5: 6 | AJ5: 5 | AK5: 否 | AM5: 2级 | AN5: 160 | AO5: 40 | AP5: 39.110982 | AQ5: =COUNTIF($I$4:$P$94,AM5) -> 26 | AR5: =COUNTIF($Q$4:$X$94,AM5) -> 21 | AS5: =COUNTIF($Y$4:$AF$94,AM5) -> 5 | AT5: =AQ5+AR5+AS5 -> 52 | AU5: =AQ5*$AO5 -> 1040 | AV5: =AR5*$AO5 -> 840 | AW5: =AS5*$AO5 -> 200 | AX5: Note：开完八卦当天可能需要手动计算粮草 | BA5: =AN5*0.8 -> 128
A6: 44640 | B6: 1600 | D6: =(SUM(粮草!A6:X6)+AG6*10)*IF(AK6="是",$AY$4,$AY$3) -> 2380 | E6: =SUM($B$4:B6)+SUM($C$4:C6)-SUM($D$4:D6) -> 1900 | F6: =SUM(经验!A6:X6) -> 665 | G6: =SUM($F$4:F6)+SUM($H$4:H6) -> 3290 | H6: 0 | I6: 2级 | J6: 2级 | K6: 3级 | L6: 3级 | M6: 3级 | N6: 3级 | O6: 空 | P6: 空 | Q6: 3级 | R6: 3级 | S6: 小卦 | T6: 3级 | U6: 3级 | V6: 3级 | W6: 空 | X6: 空 | Y6: 3级 | Z6: 营地 | AA6: 3级 | AB6: 小卦 | AC6: 空 | AD6: 空 | AE6: 空 | AF6: 空 | AG6: =AH6+AI6+AJ6 -> 0 | AK6: 否 | AM6: 3级 | AN6: 170 | AO6: 45 | AP6: 34 | AQ6: =COUNTIF($I$4:$P$94,AM6) -> 74 | AR6: =COUNTIF($Q$4:$X$94,AM6) -> 152 | AS6: =COUNTIF($Y$4:$AF$94,AM6) -> 9 | AT6: =AQ6+AR6+AS6 -> 235 | AU6: =AQ6*$AO6 -> 3330 | AV6: =AR6*$AO6 -> 6840 | AW6: =AS6*$AO6 -> 405 | BA6: =AN6*0.8 -> 136
A7: 44641 | B7: 1600 | D7: =(SUM(粮草!A7:X7)+AG7*10)*IF(AK7="是",$AY$4,$AY$3) -> 2100 | E7: =SUM($B$4:B7)+SUM($C$4:C7)-SUM($D$4:D7) -> 1400 | F7: =SUM(经验!A7:X7) -> 695 | G7: =SUM($F$4:F7)+SUM($H$4:H7) -> 4185 | H7: 200 | I7: 小卦 | J7: 3级 | K7: 3级 | L7: 3级 | M7: 3级 | N7: 塔3 | O7: 空 | P7: 空 | Q7: 3级 | R7: 3级 | S7: 3级 | T7: 3级 | U7: 3级 | V7: 大卦 | W7: 空 | X7: 空 | Y7: 空 | Z7: 空 | AA7: 空 | AB7: 空 | AC7: 空 | AD7: 空 | AE7: 空 | AF7: 空 | AG7: =AH7+AI7+AJ7 -> 0 | AK7: 否 | AM7: 4级 | AN7: 180 | AO7: 50 | AP7: 36 | AQ7: =COUNTIF($I$4:$P$94,AM7) -> 109 | AR7: =COUNTIF($Q$4:$X$94,AM7) -> 76 | AS7: =COUNTIF($Y$4:$AF$94,AM7) -> 75 | AT7: =AQ7+AR7+AS7 -> 260 | AU7: =AQ7*$AO7 -> 5450 | AV7: =AR7*$AO7 -> 3800 | AW7: =AS7*$AO7 -> 3750 | BA7: =AN7*0.8 -> 144
A8: 44642 | B8: 1600 | D8: =(SUM(粮草!A8:X8)+AG8*10)*IF(AK8="是",$AY$4,$AY$3) -> 1960 | E8: =SUM($B$4:B8)+SUM($C$4:C8)-SUM($D$4:D8) -> 1040 | F8: =SUM(经验!A8:X8) -> 670 | G8: =SUM($F$4:F8)+SUM($H$4:H8) -> 4955 | H8: 100 | I8: 3级 | J8: 3级 | K8: 大卦 | L8: 3级 | M8: 3级 | N8: 商人 | O8: 空 | P8: 空 | Q8: 3级 | R8: 遗迹 | S8: 3级 | T8: 3级 | U8: 3级 | V8: 塔3 | W8: 空 | X8: 空 | Y8: 空 | Z8: 空 | AA8: 空 | AB8: 空 | AC8: 空 | AD8: 空 | AE8: 空 | AF8: 空 | AG8: =AH8+AI8+AJ8 -> 0 | AK8: 否 | AM8: 5级 | AN8: 190 | AO8: 55 | AP8: 38 | AQ8: =COUNTIF($I$4:$P$94,AM8) -> 98 | AR8: =COUNTIF($Q$4:$X$94,AM8) -> 140 | AS8: =COUNTIF($Y$4:$AF$94,AM8) -> 0 | AT8: =AQ8+AR8+AS8 -> 238 | AU8: =AQ8*$AO8 -> 5390 | AV8: =AR8*$AO8 -> 7700 | AW8: =AS8*$AO8 -> 0 | BA8: =AN8*0.8 -> 152
A9: 44643 | B9: 1600 | D9: =(SUM(粮草!A9:X9)+AG9*10)*IF(AK9="是",$AY$4,$AY$3)-68 -> 1972 | E9: =SUM($B$4:B9)+SUM($C$4:C9)-SUM($D$4:D9) -> 668 | F9: =SUM(经验!A9:X9) -> 540 | G9: =SUM($F$4:F9)+SUM($H$4:H9) -> 5695 | H9: 200 | I9: 3级 | J9: 3级 | K9: 3级 | L9: 3级 | M9: 小卦 | N9: 3级 | O9: 空 | P9: 空 | Q9: 3级 | R9: 3级 | S9: 3级 | T9: 3级 | U9: 小卦 | V9: 3级 | W9: 空 | X9: 空 | Y9: 空 | Z9: 空 | AA9: 空 | AB9: 空 | AC9: 空 | AD9: 空 | AE9: 空 | AF9: 空 | AG9: =AH9+AI9+AJ9 -> 0 | AK9: 否 | AM9: 6级 | AN9: 200 | AO9: 60 | AQ9: =COUNTIF($I$4:$P$94,AM9) -> 80 | AR9: =COUNTIF($Q$4:$X$94,AM9) -> 114 | AS9: =COUNTIF($Y$4:$AF$94,AM9) -> 0 | AT9: =AQ9+AR9+AS9 -> 194 | AU9: =AQ9*$AO9 -> 4800 | AV9: =AR9*$AO9 -> 6840 | AW9: =AS9*$AO9 -> 0 | BA9: =AN9*0.8 -> 160
A10: 44644 | B10: 1600 | D10: =(SUM(粮草!A10:X10)+AG10*10)*IF(AK10="是",$AY$4,$AY$3) -> 1616 | E10: =SUM($B$4:B10)+SUM($C$4:C10)-SUM($D$4:D10) -> 652 | F10: =SUM(经验!A10:X10) -> 540 | G10: =SUM($F$4:F10)+SUM($H$4:H10) -> 6235 | H10: 0 | I10: 3级 | J10: 3级 | K10: 3级 | L10: 塔3 | M10: 3级 | N10: 3级 | O10: 空 | P10: 空 | Q10: 3级 | R10: 3级 | S10: 3级 | T10: 3级 | U10: 3级 | V10: 3级 | W10: 空 | X10: 空 | Y10: 空 | Z10: 空 | AA10: 空 | AB10: 空 | AC10: 空 | AD10: 空 | AE10: 空 | AF10: 空 | AG10: =AH10+AI10+AJ10 -> 0 | AK10: 是 | AM10: 塔1 | AN10: 150 | AO10: 35 | AP10: 44.222109 | AQ10: =COUNTIF($I$4:$P$94,AM10) -> 0 | AR10: =COUNTIF($Q$4:$X$94,AM10) -> 0 | AS10: =COUNTIF($Y$4:$AF$94,AM10) -> 0 | AT10: =AQ10+AR10+AS10 -> 0 | AU10: =AQ10*$AO10 -> 0 | AV10: =AR10*$AO10 -> 0 | AW10: =AS10*$AO10 -> 0 | BA10: =AN10*0.8 -> 120
A11: 44645 | B11: 1600 | D11: =(SUM(粮草!A11:X11)+AG11*10)*IF(AK11="是",$AY$4,$AY$3) -> 1536 | E11: =SUM($B$4:B11)+SUM($C$4:C11)-SUM($D$4:D11) -> 716 | F11: =SUM(经验!A11:X11) -> 525 | G11: =SUM($F$4:F11)+SUM($H$4:H11) -> 6760 | H11: 0 | I11: 3级 | J11: 3级 | K11: 3级 | L11: 3级 | M11: 商人 | N11: 3级 | O11: 空 | P11: 空 | Q11: 3级 | R11: 3级 | S11: 3级 | T11: 3级 | U11: 3级 | V11: 3级 | W11: 空 | X11: 空 | Y11: 空 | Z11: 空 | AA11: 空 | AB11: 空 | AC11: 空 | AD11: 空 | AE11: 空 | AF11: 空 | AG11: =AH11+AI11+AJ11 -> 0 | AK11: 是 | AM11: 塔2 | AN11: 150 | AO11: 40 | AP11: 29.110982 | AQ11: =COUNTIF($I$4:$P$94,AM11) -> 2 | AR11: =COUNTIF($Q$4:$X$94,AM11) -> 1 | AS11: =COUNTIF($Y$4:$AF$94,AM11) -> 0 | AT11: =AQ11+AR11+AS11 -> 3 | AU11: =AQ11*$AO11 -> 80 | AV11: =AR11*$AO11 -> 40 | AW11: =AS11*$AO11 -> 0 | BA11: =AN11*0.8 -> 120
A12: 44646 | B12: 1600 | D12: =(SUM(粮草!A12:X12)+AG12*10)*IF(AK12="是",$AY$4,$AY$3) -> 1536 | E12: =SUM($B$4:B12)+SUM($C$4:C12)-SUM($D$4:D12) -> 780 | F12: =SUM(经验!A12:X12) -> 525 | G12: =SUM($F$4:F12)+SUM($H$4:H12) -> 7285 | H12: 0 | I12: 3级 | J12: 3级 | K12: 3级 | L12: 3级 | M12: 3级 | N12: 商人 | O12: 空 | P12: 空 | Q12: 3级 | R12: 3级 | S12: 3级 | T12: 3级 | U12: 3级 | V12: 3级 | W12: 空 | X12: 空 | Y12: 空 | Z12: 空 | AA12: 空 | AB12: 空 | AC12: 空 | AD12: 空 | AE12: 空 | AF12: 空 | AG12: =AH12+AI12+AJ12 -> 0 | AK12: 是 | AM12: 塔3 | AN12: 150 | AO12: 45 | AP12: 13.999855 | AQ12: =COUNTIF($I$4:$P$94,AM12) -> 3 | AR12: =COUNTIF($Q$4:$X$94,AM12) -> 3 | AS12: =COUNTIF($Y$4:$AF$94,AM12) -> 0 | AT12: =AQ12+AR12+AS12 -> 6 | AU12: =AQ12*$AO12 -> 135 | AV12: =AR12*$AO12 -> 135 | AW12: =AS12*$AO12 -> 0 | BA12: =AN12*0.8 -> 120
A13: 44647 | B13: 1600 | D13: =(SUM(粮草!A13:X13)+AG13*10)*IF(AK13="是",$AY$4,$AY$3) -> 1488 | E13: =SUM($B$4:B13)+SUM($C$4:C13)-SUM($D$4:D13) -> 892 | F13: =SUM(经验!A13:X13) -> 500 | G13: =SUM($F$4:F13)+SUM($H$4:H13) -> 7785 | H13: 0 | I13: 2级 | J13: 塔2 | K13: 2级 | L13: 2级 | M13: 2级 | N13: 商人 | O13: 空 | P13: 空 | Q13: 3级 | R13: 3级 | S13: 3级 | T13: 3级 | U13: 3级 | V13: 3级 | W13: 空 | X13: 空 | Y13: 空 | Z13: 空 | AA13: 空 | AB13: 空 | AC13: 空 | AD13: 空 | AE13: 空 | AF13: 空 | AG13: =AH13+AI13+AJ13 -> 0 | AK13: 是 | AM13: 塔4 | AN13: 150 | AO13: 50 | AQ13: =COUNTIF($I$4:$P$94,AM13) -> 2 | AR13: =COUNTIF($Q$4:$X$94,AM13) -> 2 | AS13: =COUNTIF($Y$4:$AF$94,AM13) -> 0 | AT13: =AQ13+AR13+AS13 -> 4 | AU13: =AQ13*$AO13 -> 100 | AV13: =AR13*$AO13 -> 100 | AW13: =AS13*$AO13 -> 0 | BA13: =AN13*0.8 -> 120
A14: 44648 | B14: 1600 | D14: =(SUM(粮草!A14:X14)+AG14*10)*IF(AK14="是",$AY$4,$AY$3) -> 1624 | E14: =SUM($B$4:B14)+SUM($C$4:C14)-SUM($D$4:D14) -> 868 | F14: =SUM(经验!A14:X14) -> 535 | G14: =SUM($F$4:F14)+SUM($H$4:H14) -> 8620 | H14: 300 | I14: 2级 | J14: 3级 | K14: 3级 | L14: 3级 | M14: 3级 | N14: 3级 | O14: 空 | P14: 空 | Q14: 3级 | R14: 3级 | S14: 3级 | T14: 3级 | U14: 3级 | V14: 3级 | W14: 空 | X14: 空 | Y14: 空 | Z14: 空 | AA14: 空 | AB14: 空 | AC14: 空 | AD14: 空 | AE14: 空 | AF14: 空 | AG14: =AH14+AI14+AJ14 -> 0 | AK14: 是 | AM14: 塔5 | AN14: 150 | AO14: 55 | AQ14: =COUNTIF($I$4:$P$94,AM14) -> 1 | AR14: =COUNTIF($Q$4:$X$94,AM14) -> 2 | AS14: =COUNTIF($Y$4:$AF$94,AM14) -> 0 | AT14: =AQ14+AR14+AS14 -> 3 | AU14: =AQ14*$AO14 -> 55 | AV14: =AR14*$AO14 -> 110 | AW14: =AS14*$AO14 -> 0 | BA14: =AN14*0.8 -> 120
A15: 44649 | B15: 1600 | D15: =(SUM(粮草!A15:X15)+AG15*10)*IF(AK15="是",$AY$4,$AY$3) -> 1536 | E15: =SUM($B$4:B15)+SUM($C$4:C15)-SUM($D$4:D15) -> 932 | F15: =SUM(经验!A15:X15) -> 530 | G15: =SUM($F$4:F15)+SUM($H$4:H15) -> 9150 | H15: 0 | I15: 3级 | J15: 3级 | K15: 3级 | L15: 塔2 | M15: 3级 | N15: 3级 | O15: 空 | P15: 空 | Q15: 商人 | R15: 3级 | S15: 3级 | T15: 3级 | U15: 4级 | V15: 4级 | W15: 空 | X15: 空 | Y15: 空 | Z15: 空 | AA15: 空 | AB15: 空 | AC15: 空 | AD15: 空 | AE15: 空 | AF15: 空 | AG15: =AH15+AI15+AJ15 -> 0 | AK15: 是 | AM15: 塔6 | AN15: 150 | AO15: 60 | AQ15: =COUNTIF($I$4:$P$94,AM15) -> 1 | AR15: =COUNTIF($Q$4:$X$94,AM15) -> 0 | AS15: =COUNTIF($Y$4:$AF$94,AM15) -> 0 | AT15: =AQ15+AR15+AS15 -> 1 | AU15: =AQ15*$AO15 -> 60 | AV15: =AR15*$AO15 -> 0 | AW15: =AS15*$AO15 -> 0 | BA15: =AN15*0.8 -> 120
A16: 44650 | B16: 1600 | D16: =(SUM(粮草!A16:X16)+AG16*10)*IF(AK16="是",$AY$4,$AY$3) -> 1552 | E16: =SUM($B$4:B16)+SUM($C$4:C16)-SUM($D$4:D16) -> 980 | F16: =SUM(经验!A16:X16) -> 545 | G16: =SUM($F$4:F16)+SUM($H$4:H16) -> 9895 | H16: 200 | I16: 商人 | J16: 3级 | K16: 3级 | L16: 3级 | M16: 3级 | N16: 3级 | O16: 空 | P16: 空 | Q16: 塔3 | R16: 3级 | S16: 4级 | T16: 4级 | U16: 4级 | V16: 4级 | W16: 空 | X16: 空 | Y16: 空 | Z16: 空 | AA16: 空 | AB16: 空 | AC16: 空 | AD16: 空 | AE16: 空 | AF16: 空 | AG16: =AH16+AI16+AJ16 -> 0 | AK16: 是 | AM16: 遗迹 | AN16: 150 | AO16: 35 | AP16: 44.222109 | AQ16: =COUNTIF($I$4:$P$94,AM16) -> 0 | AR16: =COUNTIF($Q$4:$X$94,AM16) -> 1 | AS16: =COUNTIF($Y$4:$AF$94,AM16) -> 2 | AT16: =AQ16+AR16+AS16 -> 3 | AU16: =AQ16*$AO16 -> 0 | AV16: =AR16*$AO16 -> 35 | AW16: =AS16*$AO16 -> 70 | BA16: =AN16*0.8 -> 120
A17: 44651 | B17: 1600 | D17: =(SUM(粮草!A17:X17)+AG17*10)*IF(AK17="是",$AY$4,$AY$3) -> 1576 | E17: =SUM($B$4:B17)+SUM($C$4:C17)-SUM($D$4:D17) -> 1004 | F17: =SUM(经验!A17:X17) -> 550 | G17: =SUM($F$4:F17)+SUM($H$4:H17) -> 10445 | H17: 0 | I17: 3级 | J17: 3级 | K17: 3级 | L17: 3级 | M17: 3级 | N17: 3级 | O17: 空 | P17: 空 | Q17: 4级 | R17: 4级 | S17: 4级 | T17: 4级 | U17: 商人 | V17: 4级 | W17: 空 | X17: 空 | Y17: 空 | Z17: 空 | AA17: 空 | AB17: 空 | AC17: 空 | AD17: 空 | AE17: 空 | AF17: 空 | AG17: =AH17+AI17+AJ17 -> 0 | AK17: 是 | AM17: 商人 | AN17: 50 | AO17: 30 | AP17: 10 | AQ17: =COUNTIF($I$4:$P$94,AM17) -> 20 | AR17: =COUNTIF($Q$4:$X$94,AM17) -> 15 | AS17: =COUNTIF($Y$4:$AF$94,AM17) -> 3 | AT17: =AQ17+AR17+AS17 -> 38 | AU17: =AQ17*$AO17 -> 600 | AV17: =AR17*$AO17 -> 450 | AW17: =AS17*$AO17 -> 90 | BA17: =AN17*0.8 -> 40
A18: 44652 | B18: 1600 | D18: =(SUM(粮草!A18:X18)+AG18*10)*IF(AK18="是",$AY$4,$AY$3) -> 1664 | E18: =SUM($B$4:B18)+SUM($C$4:C18)-SUM($D$4:D18) -> 940 | F18: =SUM(经验!A18:X18) -> 620 | G18: =SUM($F$4:F18)+SUM($H$4:H18) -> 11065 | H18: 0 | I18: 3级 | J18: 3级 | K18: 3级 | L18: 3级 | M18: 3级 | N18: 3级 | O18: 空 | P18: 空 | Q18: 4级 | R18: 4级 | S18: 4级 | T18: 4级 | U18: 4级 | V18: 4级 | W18: 营地+ | X18: 4级 | Y18: 空 | Z18: 空 | AA18: 空 | AB18: 空 | AC18: 空 | AD18: 空 | AE18: 空 | AF18: 空 | AG18: =AH18+AI18+AJ18 -> 0 | AK18: 是 | AL18: 八卦前 | AM18: 营地 | AN18: -150 | AO18: 0 | AP18: 10 | AQ18: =COUNTIF($I$4:$P$94,AM18) -> 0 | AR18: =COUNTIF($Q$4:$X$94,AM18) -> 1 | AS18: =COUNTIF($Y$4:$AF$94,AM18) -> 1 | AT18: =AQ18+AR18+AS18 -> 2 | AU18: =AQ18*$AO18 -> 0 | AV18: =AR18*$AO18 -> 0 | AW18: =AS18*$AO18 -> 0 | BA18: =AN18*0.8 -> -120
A19: 44653 | B19: 1600 | D19: =(SUM(粮草!A19:X19)+AG19*10)*IF(AK19="是",$AY$4,$AY$3) -> 1584 | E19: =SUM($B$4:B19)+SUM($C$4:C19)-SUM($D$4:D19) -> 956 | F19: =SUM(经验!A19:X19) -> 555 | G19: =SUM($F$4:F19)+SUM($H$4:H19) -> 11620 | H19: 0 | I19: 3级 | J19: 3级 | K19: 商人 | L19: 3级 | M19: 3级 | N19: 3级 | O19: 空 | P19: 空 | Q19: 4级 | R19: 4级 | S19: 4级 | T19: 4级 | U19: 4级 | V19: 4级 | W19: 空 | X19: 空 | Y19: 空 | Z19: 空 | AA19: 空 | AB19: 空 | AC19: 空 | AD19: 空 | AE19: 空 | AF19: 空 | AG19: =AH19+AI19+AJ19 -> 0 | AK19: 是 | AM19: 大卦 | AN19: 250 | AO19: 200 | AQ19: =COUNTIF($I$4:$P$94,AM19) -> 1 | AR19: =COUNTIF($Q$4:$X$94,AM19) -> 1 | AS19: =COUNTIF($Y$4:$AF$94,AM19) -> 1 | AT19: =AQ19+AR19+AS19 -> 3 | AU19: =AQ19*$AO19 -> 200 | AV19: =AR19*$AO19 -> 200 | AW19: =AS19*$AO19 -> 200 | BA19: =AN19*0.8 -> 200
A20: 44654 | B20: 1600 | D20: =(SUM(粮草!A20:X20)+AG20*10)*IF(AK20="是",$AY$4,$AY$3) -> 1568 | E20: =SUM($B$4:B20)+SUM($C$4:C20)-SUM($D$4:D20) -> 988 | F20: =SUM(经验!A20:X20) -> 605 | G20: =SUM($F$4:F20)+SUM($H$4:H20) -> 12225 | H20: 0 | I20: 商人 | J20: 3级 | K20: 3级 | L20: 3级 | M20: 3级 | N20: 3级 | O20: 营地+ | P20: 4级 | Q20: 4级 | R20: 4级 | S20: 4级 | T20: 4级 | U20: 4级 | V20: 4级 | W20: 空 | X20: 空 | Y20: 空 | Z20: 空 | AA20: 空 | AB20: 空 | AC20: 空 | AD20: 空 | AE20: 空 | AF20: 空 | AG20: =AH20+AI20+AJ20 -> 0 | AK20: 是 | AM20: 小卦 | AN20: 170 | AO20: 45 | AQ20: =COUNTIF($I$4:$P$94,AM20) -> 2 | AR20: =COUNTIF($Q$4:$X$94,AM20) -> 2 | AS20: =COUNTIF($Y$4:$AF$94,AM20) -> 1 | AT20: =AQ20+AR20+AS20 -> 5 | AU20: =AQ20*$AO20 -> 90 | AV20: =AR20*$AO20 -> 90 | AW20: =AS20*$AO20 -> 45 | BA20: =AN20*0.8 -> 136
A21: 44655 | B21: 1600 | D21: =(SUM(粮草!A21:X21)+AG21*10)*IF(AK21="是",$AY$4,$AY$3) -> 1680 | E21: =SUM($B$4:B21)+SUM($C$4:C21)-SUM($D$4:D21) -> 908 | F21: =SUM(经验!A21:X21) -> 585 | G21: =SUM($F$4:F21)+SUM($H$4:H21) -> 13010 | H21: 200 | I21: 3级 | J21: 3级 | K21: 3级 | L21: 4级 | M21: 4级 | N21: 4级 | O21: 空 | P21: 空 | Q21: 4级 | R21: 4级 | S21: 4级 | T21: 塔4 | U21: 4级 | V21: 4级 | W21: 空 | X21: 空 | Y21: 空 | Z21: 空 | AA21: 空 | AB21: 空 | AC21: 空 | AD21: 空 | AE21: 空 | AF21: 空 | AG21: =AH21+AI21+AJ21 -> 0 | AK21: 是 | AM21: 小boss | AN21: 250 | AO21: 200 | AQ21: =COUNTIF($I$4:$P$94,AM21) -> 0 | AR21: =COUNTIF($Q$4:$X$94,AM21) -> 0 | AS21: =COUNTIF($Y$4:$AF$94,AM21) -> 0 | AT21: =AQ21+AR21+AS21 -> 0 | AU21: =AQ21*$AO21 -> 0 | AV21: =AR21*$AO21 -> 0 | AW21: =AS21*$AO21 -> 0 | BA21: =AN21*0.8 -> 200
A22: 44656 | B22: 1600 | D22: =(SUM(粮草!A22:X22)+AG22*10)*IF(AK22="是",$AY$4,$AY$3) -> 1760 | E22: =SUM($B$4:B22)+SUM($C$4:C22)-SUM($D$4:D22) -> 748 | F22: =SUM(经验!A22:X22) -> 620 | G22: =SUM($F$4:F22)+SUM($H$4:H22) -> 13730 | H22: 100 | I22: 4级 | J22: 4级 | K22: 4级 | L22: 4级 | M22: 4级 | N22: 4级 | O22: 空 | P22: 空 | Q22: 4级 | R22: 4级 | S22: 5级 | T22: 5级 | U22: 5级 | V22: 5级 | W22: 空 | X22: 空 | Y22: 空 | Z22: 空 | AA22: 空 | AB22: 空 | AC22: 空 | AD22: 空 | AE22: 空 | AF22: 空 | AG22: =AH22+AI22+AJ22 -> 0 | AK22: 是 | AM22: 大boss | AN22: 250 | AO22: 1000 | AQ22: =COUNTIF($I$4:$P$94,AM22) -> 1 | AR22: =COUNTIF($Q$4:$X$94,AM22) -> 1 | AS22: =COUNTIF($Y$4:$AF$94,AM22) -> 0 | AT22: =AQ22+AR22+AS22 -> 2 | AU22: =AQ22*$AO22 -> 1000 | AV22: =AR22*$AO22 -> 1000 | AW22: =AS22*$AO22 -> 0 | BA22: =AN22*0.8 -> 200
A23: 44657 | B23: 1600 | D23: =(SUM(粮草!A23:X23)+AG23*10)*IF(AK23="是",$AY$4,$AY$3) -> 1672 | E23: =SUM($B$4:B23)+SUM($C$4:C23)-SUM($D$4:D23) -> 676 | F23: =SUM(经验!A23:X23) -> 610 | G23: =SUM($F$4:F23)+SUM($H$4:H23) -> 14540 | H23: 200 | I23: 商人 | J23: 4级 | K23: 4级 | L23: 4级 | M23: 4级 | N23: 4级 | O23: 空 | P23: 空 | Q23: 5级 | R23: 5级 | S23: 5级 | T23: 5级 | U23: 5级 | V23: 5级 | W23: 空 | X23: 空 | Y23: 空 | Z23: 空 | AA23: 空 | AB23: 空 | AC23: 空 | AD23: 空 | AE23: 空 | AF23: 空 | AG23: =AH23+AI23+AJ23 -> 0 | AK23: 是 | AM23: 中boss | AN23: 250 | AO23: 500 | AQ23: =COUNTIF($I$4:$P$94,AM23) -> 1 | AR23: =COUNTIF($Q$4:$X$94,AM23) -> 1 | AS23: =COUNTIF($Y$4:$AF$94,AM23) -> 0 | AT23: =AQ23+AR23+AS23 -> 2 | AU23: =AQ23*$AO23 -> 500 | AV23: =AR23*$AO23 -> 500 | AW23: =AS23*$AO23 -> 0 | BA23: =AN23*0.8 -> 200
A24: 44658 | B24: 1600 | D24: =(SUM(粮草!A24:X24)+AG24*10)*IF(AK24="是",$AY$4,$AY$3) -> 1664 | E24: =SUM($B$4:B24)+SUM($C$4:C24)-SUM($D$4:D24) -> 612 | F24: =SUM(经验!A24:X24) -> 605 | G24: =SUM($F$4:F24)+SUM($H$4:H24) -> 15145 | H24: 0 | I24: 4级 | J24: 4级 | K24: 4级 | L24: 4级 | M24: 4级 | N24: 4级 | O24: 空 | P24: 空 | Q24: 5级 | R24: 5级 | S24: 5级 | T24: 5级 | U24: 商人 | V24: 5级 | W24: 空 | X24: 空 | Y24: 空 | Z24: 空 | AA24: 空 | AB24: 空 | AC24: 空 | AD24: 空 | AE24: 空 | AF24: 空 | AG24: =AH24+AI24+AJ24 -> 0 | AK24: 是 | AM24: 奈良 | AN24: 160 | AO24: 40 | AP24: 39.110982 | AQ24: =COUNTIF($I$4:$P$94,AM24) -> 0 | AR24: =COUNTIF($Q$4:$X$94,AM24) -> 0 | AS24: =COUNTIF($Y$4:$AF$94,AM24) -> 0 | AT24: =AQ24+AR24+AS24 -> 0 | AU24: =AQ24*$AO24 -> 0 | AV24: =AR24*$AO24 -> 0 | AW24: =AS24*$AO24 -> 0 | BA24: =AN24*0.8 -> 128
A25: 44659 | B25: 1600 | D25: =(SUM(粮草!A25:X25)+AG25*10)*IF(AK25="是",$AY$4,$AY$3) -> 1792 | E25: =SUM($B$4:B25)+SUM($C$4:C25)-SUM($D$4:D25) -> 420 | F25: =SUM(经验!A25:X25) -> 640 | G25: =SUM($F$4:F25)+SUM($H$4:H25) -> 15785 | H25: 0 | I25: 4级 | J25: 4级 | K25: 4级 | L25: 4级 | M25: 4级 | N25: 6级 | O25: 空 | P25: 空 | Q25: 5级 | R25: 5级 | S25: 5级 | T25: 5级 | U25: 5级 | V25: 5级 | W25: 空 | X25: 空 | Y25: 空 | Z25: 空 | AA25: 空 | AB25: 空 | AC25: 空 | AD25: 空 | AE25: 空 | AF25: 空 | AG25: =AH25+AI25+AJ25 -> 0 | AK25: 是 | AM25: 山中 | AN25: 160 | AO25: 40 | AP25: 39.110982 | AQ25: =COUNTIF($I$4:$P$94,AM25) -> 0 | AR25: =COUNTIF($Q$4:$X$94,AM25) -> 0 | AS25: =COUNTIF($Y$4:$AF$94,AM25) -> 0 | AT25: =AQ25+AR25+AS25 -> 0 | AU25: =AQ25*$AO25 -> 0 | AV25: =AR25*$AO25 -> 0 | AW25: =AS25*$AO25 -> 0 | BA25: =AN25*0.8 -> 128
A26: 44660 | B26: 1600 | D26: =(SUM(粮草!A26:X26)+AG26*10)*IF(AK26="是",$AY$4,$AY$3) -> 1872 | E26: =SUM($B$4:B26)+SUM($C$4:C26)-SUM($D$4:D26) -> 148 | F26: =SUM(经验!A26:X26) -> 690 | G26: =SUM($F$4:F26)+SUM($H$4:H26) -> 16475 | H26: 0 | I26: 6级 | J26: 6级 | K26: 6级 | L26: 6级 | M26: 6级 | N26: 6级 | O26: 空 | P26: 空 | Q26: 5级 | R26: 5级 | S26: 5级 | T26: 5级 | U26: 5级 | V26: 5级 | W26: 空 | X26: 空 | Y26: 空 | Z26: 空 | AA26: 空 | AB26: 空 | AC26: 空 | AD26: 空 | AE26: 空 | AF26: 空 | AG26: =AH26+AI26+AJ26 -> 0 | AK26: 是 | AM26: 秋道 | AN26: 150 | AO26: 35 | AP26: 44.222109 | AQ26: =COUNTIF($I$4:$P$94,AM26) -> 0 | AR26: =COUNTIF($Q$4:$X$94,AM26) -> 0 | AS26: =COUNTIF($Y$4:$AF$94,AM26) -> 0 | AT26: =AQ26+AR26+AS26 -> 0 | AU26: =AQ26*$AO26 -> 0 | AV26: =AR26*$AO26 -> 0 | AW26: =AS26*$AO26 -> 0 | BA26: =AN26*0.8 -> 120
A27: 44661 | B27: 1600 | D27: =(SUM(粮草!A27:X27)+AG27*10)*IF(AK27="是",$AY$4,$AY$3) -> 1720 | E27: =SUM($B$4:B27)+SUM($C$4:C27)-SUM($D$4:D27) -> 28 | F27: =SUM(经验!A27:X27) -> 695 | G27: =SUM($F$4:F27)+SUM($H$4:H27) -> 17170 | H27: 0 | I27: 6级 | J27: 6级 | K27: 6级 | L27: 6级 | M27: 6级 | N27: 6级 | O27: 营地+ | P27: 6级 | Q27: 5级 | R27: 5级 | S27: 5级 | T27: 5级 | U27: 5级 | V27: 空 | W27: 空 | X27: 空 | Y27: 空 | Z27: 空 | AA27: 空 | AB27: 空 | AC27: 空 | AD27: 空 | AE27: 空 | AF27: 空 | AG27: =AH27+AI27+AJ27 -> 0 | AK27: 是 | AM27: 空 | AN27: 0 | AO27: 0 | AP27: 0 | AU27: =AQ27*$AO27 -> 0 | AV27: =AR27*$AO27 -> 0 | AW27: =AS27*$AO27 -> 0 | BA27: =AN27*0.8 -> 0
A28: 44662 | B28: 1600 | D28: =(SUM(粮草!A28:X28)+AG28*10)*IF(AK28="是",$AY$4,$AY$3) -> 1568 | E28: =SUM($B$4:B28)+SUM($C$4:C28)-SUM($D$4:D28) -> 60 | F28: =SUM(经验!A28:X28) -> 580 | G28: =SUM($F$4:F28)+SUM($H$4:H28) -> 17950 | H28: 200 | I28: 6级 | J28: 6级 | K28: 6级 | L28: 6级 | M28: 6级 | N28: 6级 | O28: 空 | P28: 空 | Q28: 5级 | R28: 5级 | S28: 5级 | T28: 5级 | U28: 空 | V28: 空 | W28: 空 | X28: 空 | Y28: 空 | Z28: 空 | AA28: 空 | AB28: 空 | AC28: 空 | AD28: 空 | AE28: 空 | AF28: 空 | AG28: =AH28+AI28+AJ28 -> 0 | AK28: 是 | AL28: 八卦后 | AM28: 营地+ | AN28: -200 | AO28: 0 | AQ28: =COUNTIF($I$4:$P$94,AM28) -> 6 | AR28: =COUNTIF($Q$4:$X$94,AM28) -> 6 | AS28: =COUNTIF($Y$4:$AF$94,AM28) -> 1 | AT28: =AQ28+AR28+AS28 -> 13 | AU28: =AQ28*$AO28 -> 0 | AV28: =AR28*$AO28 -> 0 | AW28: =AS28*$AO28 -> 0 | BA28: =AN28*0.8 -> -160
A29: 44663 | B29: 1600 | D29: =(SUM(粮草!A29:X29)+AG29*10)*IF(AK29="是",$AY$4,$AY$3) -> 1536 | E29: =SUM($B$4:B29)+SUM($C$4:C29)-SUM($D$4:D29) -> 124 | F29: =SUM(经验!A29:X29) -> 580 | G29: =SUM($F$4:F29)+SUM($H$4:H29) -> 18630 | H29: 100 | I29: 6级 | J29: 6级 | K29: 6级 | L29: 6级 | M29: 6级 | N29: 6级 | O29: 空 | P29: 空 | Q29: 5级 | R29: 5级 | S29: 塔5 | T29: 5级 | U29: 空 | V29: 空 | W29: 空 | X29: 空 | Y29: 空 | Z29: 空 | AA29: 空 | AB29: 空 | AC29: 空 | AD29: 空 | AE29: 空 | AF29: 空 | AG29: =AH29+AI29+AJ29 -> 0 | AK29: 是 | AM29: 历练 | AN29: 50 | AO29: 520 | AQ29: =COUNTIF($I$4:$P$94,AM29) -> 1 | AR29: =COUNTIF($Q$4:$X$94,AM29) -> 1 | AS29: =COUNTIF($Y$4:$AF$94,AM29) -> 1 | AT29: =AQ29+AR29+AS29 -> 3 | AU29: =AQ29*$AO29 -> 520 | AV29: =AR29*$AO29 -> 520 | AW29: =AS29*$AO29 -> 520 | BA29: =AN29*0.8 -> 40
A30: 44664 | B30: 1600 | D30: =(SUM(粮草!A30:X30)+AG30*10)*IF(AK30="是",$AY$4,$AY$3) -> 1720 | E30: =SUM($B$4:B30)+SUM($C$4:C30)-SUM($D$4:D30) -> 4 | F30: =SUM(经验!A30:X30) -> 635 | G30: =SUM($F$4:F30)+SUM($H$4:H30) -> 19465 | H30: 200 | I30: 6级 | J30: 6级 | K30: 6级 | L30: 6级 | M30: 6级 | N30: 6级 | O30: 空 | P30: 空 | Q30: 5级 | R30: 5级 | S30: 5级 | T30: 5级 | U30: 5级 | V30: 空 | W30: 空 | X30: 空 | Y30: 空 | Z30: 空 | AA30: 空 | AB30: 空 | AC30: 空 | AD30: 空 | AE30: 空 | AF30: 空 | AG30: =AH30+AI30+AJ30 -> 0 | AK30: 是
A31: 44665 | B31: 1600 | D31: =(SUM(粮草!A31:X31)+AG31*10)*IF(AK31="是",$AY$4,$AY$3) -> 1560 | E31: =SUM($B$4:B31)+SUM($C$4:C31)-SUM($D$4:D31) -> 44 | F31: =SUM(经验!A31:X31) -> 635 | G31: =SUM($F$4:F31)+SUM($H$4:H31) -> 20100 | H31: 0 | I31: 6级 | J31: 6级 | K31: 6级 | L31: 6级 | M31: 6级 | N31: 6级 | O31: 空 | P31: 空 | Q31: 5级 | R31: 营地+ | S31: 5级 | T31: 5级 | U31: 5级 | V31: 5级 | W31: 空 | X31: 空 | Y31: 空 | Z31: 空 | AA31: 空 | AB31: 空 | AC31: 空 | AD31: 空 | AE31: 空 | AF31: 空 | AG31: =AH31+AI31+AJ31 -> 0 | AK31: 是
A32: 44666 | B32: 1600 | D32: =(SUM(粮草!A32:X32)+AG32*10)*IF(AK32="是",$AY$4,$AY$3) -> 1568 | E32: =SUM($B$4:B32)+SUM($C$4:C32)-SUM($D$4:D32) -> 76 | F32: =SUM(经验!A32:X32) -> 580 | G32: =SUM($F$4:F32)+SUM($H$4:H32) -> 20680 | H32: 0 | I32: 6级 | J32: 6级 | K32: 6级 | L32: 6级 | M32: 6级 | N32: 6级 | O32: 空 | P32: 空 | Q32: 5级 | R32: 5级 | S32: 5级 | T32: 5级 | U32: 空 | V32: 空 | W32: 空 | X32: 空 | Y32: 空 | Z32: 空 | AA32: 空 | AB32: 空 | AC32: 空 | AD32: 空 | AE32: 空 | AF32: 空 | AG32: =AH32+AI32+AJ32 -> 0 | AK32: 是
A33: 44667 | B33: 1600 | D33: =(SUM(粮草!A33:X33)+AG33*10)*IF(AK33="是",$AY$4,$AY$3) -> 1568 | E33: =SUM($B$4:B33)+SUM($C$4:C33)-SUM($D$4:D33) -> 108 | F33: =SUM(经验!A33:X33) -> 580 | G33: =SUM($F$4:F33)+SUM($H$4:H33) -> 21260 | H33: 0 | I33: 6级 | J33: 6级 | K33: 6级 | L33: 6级 | M33: 6级 | N33: 6级 | O33: 空 | P33: 空 | Q33: 5级 | R33: 5级 | S33: 5级 | T33: 5级 | U33: 空 | V33: 空 | W33: 空 | X33: 空 | Y33: 空 | Z33: 空 | AA33: 空 | AB33: 空 | AC33: 空 | AD33: 空 | AE33: 空 | AF33: 空 | AG33: =AH33+AI33+AJ33 -> 0 | AK33: 是
A34: 44668 | B34: 1600 | D34: =(SUM(粮草!A34:X34)+AG34*10)*IF(AK34="是",$AY$4,$AY$3) -> 1568 | E34: =SUM($B$4:B34)+SUM($C$4:C34)-SUM($D$4:D34) -> 140 | F34: =SUM(经验!A34:X34) -> 580 | G34: =SUM($F$4:F34)+SUM($H$4:H34) -> 21840 | H34: 0 | I34: 6级 | J34: 6级 | K34: 6级 | L34: 6级 | M34: 6级 | N34: 6级 | O34: 空 | P34: 空 | Q34: 5级 | R34: 5级 | S34: 5级 | T34: 5级 | U34: 空 | V34: 空 | W34: 空 | X34: 空 | Y34: 空 | Z34: 空 | AA34: 空 | AB34: 空 | AC34: 空 | AD34: 空 | AE34: 空 | AF34: 空 | AG34: =AH34+AI34+AJ34 -> 0 | AK34: 是
A35: 44669 | B35: 1600 | D35: =(SUM(粮草!A35:X35)+AG35*10)*IF(AK35="是",$AY$4,$AY$3) -> 1592 | E35: =SUM($B$4:B35)+SUM($C$4:C35)-SUM($D$4:D35) -> 148 | F35: =SUM(经验!A35:X35) -> 1510 | G35: =SUM($F$4:F35)+SUM($H$4:H35) -> 23550 | H35: 200 | I35: 大boss | J35: 6级 | K35: 6级 | L35: 6级 | M35: 空 | N35: 空 | O35: 空 | P35: 空 | Q35: 5级 | R35: 5级 | S35: 5级 | T35: 5级 | U35: 5级 | V35: 5级 | W35: 空 | X35: 空 | Y35: 空 | Z35: 空 | AA35: 空 | AB35: 空 | AC35: 空 | AD35: 空 | AE35: 空 | AF35: 空 | AG35: =AH35+AI35+AJ35 -> 0 | AK35: 是
A36: 44670 | B36: 1600 | D36: =(SUM(粮草!A36:X36)+AG36*10)*IF(AK36="是",$AY$4,$AY$3) -> 1592 | E36: =SUM($B$4:B36)+SUM($C$4:C36)-SUM($D$4:D36) -> 156 | F36: =SUM(经验!A36:X36) -> 1090 | G36: =SUM($F$4:F36)+SUM($H$4:H36) -> 24740 | H36: 100 | I36: 6级 | J36: 6级 | K36: 6级 | L36: 6级 | M36: 空 | N36: 空 | O36: 空 | P36: 空 | Q36: 5级 | R36: 5级 | S36: 5级 | T36: 5级 | U36: 5级 | V36: 历练 | W36: 5级 | X36: 空 | Y36: 空 | Z36: 空 | AA36: 空 | AB36: 空 | AC36: 空 | AD36: 空 | AE36: 空 | AF36: 空 | AG36: =AH36+AI36+AJ36 -> 0 | AK36: 是
A37: 44671 | B37: 1600 | D37: =(SUM(粮草!A37:X37)+AG37*10)*IF(AK37="是",$AY$4,$AY$3) -> 1712 | E37: =SUM($B$4:B37)+SUM($C$4:C37)-SUM($D$4:D37) -> 44 | F37: =SUM(经验!A37:X37) -> 630 | G37: =SUM($F$4:F37)+SUM($H$4:H37) -> 25570 | H37: 200 | I37: 6级 | J37: 6级 | K37: 6级 | L37: 6级 | M37: 6级 | N37: 空 | O37: 空 | P37: 空 | Q37: 5级 | R37: 5级 | S37: 5级 | T37: 5级 | U37: 5级 | V37: 5级 | W37: 空 | X37: 空 | Y37: 空 | Z37: 空 | AA37: 空 | AB37: 空 | AC37: 空 | AD37: 空 | AE37: 空 | AF37: 空 | AG37: =AH37+AI37+AJ37 -> 0 | AK37: 是
A38: 44672 | B38: 1600 | D38: =(SUM(粮草!A38:X38)+AG38*10)*IF(AK38="是",$AY$4,$AY$3) -> 1552 | E38: =SUM($B$4:B38)+SUM($C$4:C38)-SUM($D$4:D38) -> 92 | F38: =SUM(经验!A38:X38) -> 570 | G38: =SUM($F$4:F38)+SUM($H$4:H38) -> 26140 | H38: 0 | I38: 6级 | J38: 6级 | K38: 6级 | L38: 6级 | M38: 空 | N38: 空 | O38: 空 | P38: 空 | Q38: 5级 | R38: 5级 | S38: 5级 | T38: 5级 | U38: 5级 | V38: 5级 | W38: 空 | X38: 空 | Y38: 空 | Z38: 空 | AA38: 空 | AB38: 空 | AC38: 空 | AD38: 空 | AE38: 空 | AF38: 空 | AG38: =AH38+AI38+AJ38 -> 0 | AK38: 是
A39: 44673 | B39: 1600 | D39: =(SUM(粮草!A39:X39)+AG39*10)*IF(AK39="是",$AY$4,$AY$3) -> 1640 | E39: =SUM($B$4:B39)+SUM($C$4:C39)-SUM($D$4:D39) -> 52 | F39: =SUM(经验!A39:X39) -> 630 | G39: =SUM($F$4:F39)+SUM($H$4:H39) -> 26770 | H39: 0 | I39: 6级 | J39: 6级 | K39: 塔6 | L39: 6级 | M39: 6级 | N39: 空 | O39: 空 | P39: 空 | Q39: 5级 | R39: 5级 | S39: 5级 | T39: 5级 | U39: 5级 | V39: 塔5 | W39: 空 | X39: 空 | Y39: 空 | Z39: 空 | AA39: 空 | AB39: 空 | AC39: 空 | AD39: 空 | AE39: 空 | AF39: 空 | AG39: =AH39+AI39+AJ39 -> 0 | AK39: 是 | AM39: 2级194
A40: 44674 | B40: 1600 | D40: =(SUM(粮草!A40:X40)+AG40*10)*IF(AK40="是",$AY$4,$AY$3) -> 1544 | E40: =SUM($B$4:B40)+SUM($C$4:C40)-SUM($D$4:D40) -> 108 | F40: =SUM(经验!A40:X40) -> 625 | G40: =SUM($F$4:F40)+SUM($H$4:H40) -> 27395 | H40: 0 | I40: 6级 | J40: 6级 | K40: 6级 | L40: 营地+ | M40: 6级 | N40: 5级 | O40: 空 | P40: 空 | Q40: 5级 | R40: 5级 | S40: 5级 | T40: 5级 | U40: 5级 | V40: 5级 | W40: 空 | X40: 空 | Y40: 空 | Z40: 空 | AA40: 空 | AB40: 空 | AC40: 空 | AD40: 空 | AE40: 空 | AF40: 空 | AG40: =AH40+AI40+AJ40 -> 0 | AK40: 是 | AM40: 3级349
...

Sheet 粮草
A2: 队伍一 风 | C2: 步数 | D2: =COUNTIF(A4:H94,"<>空") -> 728 | E2: (不算跳步和传送) | I2: 队伍二 雷 | K2: 步数 | L2: =COUNTIF(I4:P94,"<>空") -> 728 | M2: (不算跳步和传送) | Q2: 队伍三 | S2: 总步数 | T2: =COUNTIF(Q4:X94,"<>空") -> 728 | U2: (不算跳步和传送)
A3: 1 | B3: 2 | C3: 3 | D3: 4 | E3: 5 | F3: 6 | G3: 7 | H3: 8 | I3: 1 | J3: 2 | K3: 3 | L3: 4 | M3: 5 | N3: 6 | O3: 7 | P3: 8 | Q3: 1 | R3: 2 | S3: 3 | T3: 4 | U3: 5 | V3: 6 | W3: 7 | X3: 8
A4: =(VLOOKUP('7.0.3'!I4,'7.0.3'!$AM$4:$AO$55,2,FALSE))*IF('7.0.3'!AK$4="是",'7.0.3'!$AY$4,'7.0.3'!$AY$3) -> 150 | B4: =(VLOOKUP('7.0.3'!J4,'7.0.3'!$AM$4:$AO$55,2,FALSE))*IF('7.0.3'!AL$4="是",'7.0.3'!$AY$4,'7.0.3'!$AY$3) -> 150 | C4: =(VLOOKUP('7.0.3'!K4,'7.0.3'!$AM$4:$AO$55,2,FALSE))*IF('7.0.3'!AM$4="是",'7.0.3'!$AY$4,'7.0.3'!$AY$3) -> 150 | D4: =(VLOOKUP('7.0.3'!L4,'7.0.3'!$AM$4:$AO$55,2,FALSE))*IF('7.0.3'!AN$4="是",'7.0.3'!$AY$4,'7.0.3'!$AY$3) -> 150 | E4: =(VLOOKUP('7.0.3'!M4,'7.0.3'!$AM$4:$AO$55,2,FALSE))*IF('7.0.3'!AO$4="是",'7.0.3'!$AY$4,'7.0.3'!$AY$3) -> 150 | F4: =(VLOOKUP('7.0.3'!N4,'7.0.3'!$AM$4:$AO$55,2,FALSE))*IF('7.0.3'!AQ$4="是",'7.0.3'!$AY$4,'7.0.3'!$AY$3) -> 50 | G4: =(VLOOKUP('7.0.3'!O4,'7.0.3'!$AM$4:$AO$55,2,FALSE))*IF('7.0.3'!AR$4="是",'7.0.3'!$AY$4,'7.0.3'!$AY$3) -> 0 | H4: =(VLOOKUP('7.0.3'!P4,'7.0.3'!$AM$4:$AO$55,2,FALSE))*IF('7.0.3'!AS$4="是",'7.0.3'!$AY$4,'7.0.3'!$AY$3) -> 0 | I4: =(VLOOKUP('7.0.3'!Q4,'7.0.3'!$AM$4:$AO$55,2,FALSE))*IF('7.0.3'!AT$4="是",'7.0.3'!$AY$4,'7.0.3'!$AY$3) -> 150 | J4: =(VLOOKUP('7.0.3'!R4,'7.0.3'!$AM$4:$AO$55,2,FALSE))*IF('7.0.3'!AU$4="是",'7.0.3'!$AY$4,'7.0.3'!$AY$3) -> 150 | K4: =(VLOOKUP('7.0.3'!S4,'7.0.3'!$AM$4:$AO$55,2,FALSE))*IF('7.0.3'!AV$4="是",'7.0.3'!$AY$4,'7.0.3'!$AY$3) -> -150 | L4: =(VLOOKUP('7.0.3'!T4,'7.0.3'!$AM$4:$AO$55,2,FALSE))*IF('7.0.3'!AW$4="是",'7.0.3'!$AY$4,'7.0.3'!$AY$3) -> 160 | M4: =(VLOOKUP('7.0.3'!U4,'7.0.3'!$AM$4:$AO$55,2,FALSE))*IF('7.0.3'!AX$4="是",'7.0.3'!$AY$4,'7.0.3'!$AY$3) -> 160 | ... X4: =(VLOOKUP('7.0.3'!AF4,'7.0.3'!$AM$4:$AO$55,2,FALSE))*IF('7.0.3'!BI$4="是",'7.0.3'!$AY$4,'7.0.3'!$AY$3) -> 0
A5: =(VLOOKUP('7.0.3'!I5,'7.0.3'!$AM$4:$AO$55,2,FALSE))*IF('7.0.3'!AK$4="是",'7.0.3'!$AY$4,'7.0.3'!$AY$3) -> 160 | B5: =(VLOOKUP('7.0.3'!J5,'7.0.3'!$AM$4:$AO$55,2,FALSE))*IF('7.0.3'!AL$4="是",'7.0.3'!$AY$4,'7.0.3'!$AY$3) -> 160 | C5: =(VLOOKUP('7.0.3'!K5,'7.0.3'!$AM$4:$AO$55,2,FALSE))*IF('7.0.3'!AM$4="是",'7.0.3'!$AY$4,'7.0.3'!$AY$3) -> 160 | D5: =(VLOOKUP('7.0.3'!L5,'7.0.3'!$AM$4:$AO$55,2,FALSE))*IF('7.0.3'!AN$4="是",'7.0.3'!$AY$4,'7.0.3'!$AY$3) -> 160 | E5: =(VLOOKUP('7.0.3'!M5,'7.0.3'!$AM$4:$AO$55,2,FALSE))*IF('7.0.3'!AO$4="是",'7.0.3'!$AY$4,'7.0.3'!$AY$3) -> 160 | F5: =(VLOOKUP('7.0.3'!N5,'7.0.3'!$AM$4:$AO$55,2,FALSE))*IF('7.0.3'!AQ$4="是",'7.0.3'!$AY$4,'7.0.3'!$AY$3) -> 50 | G5: =(VLOOKUP('7.0.3'!O5,'7.0.3'!$AM$4:$AO$55,2,FALSE))*IF('7.0.3'!AR$4="是",'7.0.3'!$AY$4,'7.0.3'!$AY$3) -> 0 | H5: =(VLOOKUP('7.0.3'!P5,'7.0.3'!$AM$4:$AO$55,2,FALSE))*IF('7.0.3'!AS$4="是",'7.0.3'!$AY$4,'7.0.3'!$AY$3) -> 0 | I5: =(VLOOKUP('7.0.3'!Q5,'7.0.3'!$AM$4:$AO$55,2,FALSE))*IF('7.0.3'!AT$4="是",'7.0.3'!$AY$4,'7.0.3'!$AY$3) -> 160 | J5: =(VLOOKUP('7.0.3'!R5,'7.0.3'!$AM$4:$AO$55,2,FALSE))*IF('7.0.3'!AU$4="是",'7.0.3'!$AY$4,'7.0.3'!$AY$3) -> 160 | K5: =(VLOOKUP('7.0.3'!S5,'7.0.3'!$AM$4:$AO$55,2,FALSE))*IF('7.0.3'!AV$4="是",'7.0.3'!$AY$4,'7.0.3'!$AY$3) -> 160 | L5: =(VLOOKUP('7.0.3'!T5,'7.0.3'!$AM$4:$AO$55,2,FALSE))*IF('7.0.3'!AW$4="是",'7.0.3'!$AY$4,'7.0.3'!$AY$3) -> 160 | M5: =(VLOOKUP('7.0.3'!U5,'7.0.3'!$AM$4:$AO$55,2,FALSE))*IF('7.0.3'!AX$4="是",'7.0.3'!$AY$4,'7.0.3'!$AY$3) -> 160 | ... X5: =(VLOOKUP('7.0.3'!AF5,'7.0.3'!$AM$4:$AO$55,2,FALSE))*IF('7.0.3'!BI$4="是",'7.0.3'!$AY$4,'7.0.3'!$AY$3) -> 0
A6: =(VLOOKUP('7.0.3'!I6,'7.0.3'!$AM$4:$AO$55,2,FALSE))*IF('7.0.3'!AK$4="是",'7.0.3'!$AY$4,'7.0.3'!$AY$3) -> 160 | B6: =(VLOOKUP('7.0.3'!J6,'7.0.3'!$AM$4:$AO$55,2,FALSE))*IF('7.0.3'!AL$4="是",'7.0.3'!$AY$4,'7.0.3'!$AY$3) -> 160 | C6: =(VLOOKUP('7.0.3'!K6,'7.0.3'!$AM$4:$AO$55,2,FALSE))*IF('7.0.3'!AM$4="是",'7.0.3'!$AY$4,'7.0.3'!$AY$3) -> 170 | D6: =(VLOOKUP('7.0.3'!L6,'7.0.3'!$AM$4:$AO$55,2,FALSE))*IF('7.0.3'!AN$4="是",'7.0.3'!$AY$4,'7.0.3'!$AY$3) -> 170 | E6: =(VLOOKUP('7.0.3'!M6,'7.0.3'!$AM$4:$AO$55,2,FALSE))*IF('7.0.3'!AO$4="是",'7.0.3'!$AY$4,'7.0.3'!$AY$3) -> 170 | F6: =(VLOOKUP('7.0.3'!N6,'7.0.3'!$AM$4:$AO$55,2,FALSE))*IF('7.0.3'!AQ$4="是",'7.0.3'!$AY$4,'7.0.3'!$AY$3) -> 170 | G6: =(VLOOKUP('7.0.3'!O6,'7.0.3'!$AM$4:$AO$55,2,FALSE))*IF('7.0.3'!AR$4="是",'7.0.3'!$AY$4,'7.0.3'!$AY$3) -> 0 | H6: =(VLOOKUP('7.0.3'!P6,'7.0.3'!$AM$4:$AO$55,2,FALSE))*IF('7.0.3'!AS$4="是",'7.0.3'!$AY$4,'7.0.3'!$AY$3) -> 0 | I6: =(VLOOKUP('7.0.3'!Q6,'7.0.3'!$AM$4:$AO$55,2,FALSE))*IF('7.0.3'!AT$4="是",'7.0.3'!$AY$4,'7.0.3'!$AY$3) -> 170 | J6: =(VLOOKUP('7.0.3'!R6,'7.0.3'!$AM$4:$AO$55,2,FALSE))*IF('7.0.3'!AU$4="是",'7.0.3'!$AY$4,'7.0.3'!$AY$3) -> 170 | K6: =(VLOOKUP('7.0.3'!S6,'7.0.3'!$AM$4:$AO$55,2,FALSE))*IF('7.0.3'!AV$4="是",'7.0.3'!$AY$4,'7.0.3'!$AY$3) -> 170 | L6: =(VLOOKUP('7.0.3'!T6,'7.0.3'!$AM$4:$AO$55,2,FALSE))*IF('7.0.3'!AW$4="是",'7.0.3'!$AY$4,'7.0.3'!$AY$3) -> 170 | M6: =(VLOOKUP('7.0.3'!U6,'7.0.3'!$AM$4:$AO$55,2,FALSE))*IF('7.0.3'!AX$4="是",'7.0.3'!$AY$4,'7.0.3'!$AY$3) -> 170 | ... X6: =(VLOOKUP('7.0.3'!AF6,'7.0.3'!$AM$4:$AO$55,2,FALSE))*IF('7.0.3'!BI$4="是",'7.0.3'!$AY$4,'7.0.3'!$AY$3) -> 0
A7: =(VLOOKUP('7.0.3'!I7,'7.0.3'!$AM$4:$AO$55,2,FALSE))*IF('7.0.3'!AK$4="是",'7.0.3'!$AY$4,'7.0.3'!$AY$3) -> 170 | B7: =(VLOOKUP('7.0.3'!J7,'7.0.3'!$AM$4:$AO$55,2,FALSE))*IF('7.0.3'!AL$4="是",'7.0.3'!$AY$4,'7.0.3'!$AY$3) -> 170 | C7: =(VLOOKUP('7.0.3'!K7,'7.0.3'!$AM$4:$AO$55,2,FALSE))*IF('7.0.3'!AM$4="是",'7.0.3'!$AY$4,'7.0.3'!$AY$3) -> 170 | D7: =(VLOOKUP('7.0.3'!L7,'7.0.3'!$AM$4:$AO$55,2,FALSE))*IF('7.0.3'!AN$4="是",'7.0.3'!$AY$4,'7.0.3'!$AY$3) -> 170 | E7: =(VLOOKUP('7.0.3'!M7,'7.0.3'!$AM$4:$AO$55,2,FALSE))*IF('7.0.3'!AO$4="是",'7.0.3'!$AY$4,'7.0.3'!$AY$3) -> 170 | F7: =(VLOOKUP('7.0.3'!N7,'7.0.3'!$AM$4:$AO$55,2,FALSE))*IF('7.0.3'!AQ$4="是",'7.0.3'!$AY$4,'7.0.3'!$AY$3) -> 150 | G7: =(VLOOKUP('7.0.3'!O7,'7.0.3'!$AM$4:$AO$55,2,FALSE))*IF('7.0.3'!AR$4="是",'7.0.3'!$AY$4,'7.0.3'!$AY$3) -> 0 | H7: =(VLOOKUP('7.0.3'!P7,'7.0.3'!$AM$4:$AO$55,2,FALSE))*IF('7.0.3'!AS$4="是",'7.0.3'!$AY$4,'7.0.3'!$AY$3) -> 0 | I7: =(VLOOKUP('7.0.3'!Q7,'7.0.3'!$AM$4:$AO$55,2,FALSE))*IF('7.0.3'!AT$4="是",'7.0.3'!$AY$4,'7.0.3'!$AY$3) -> 170 | J7: =(VLOOKUP('7.0.3'!R7,'7.0.3'!$AM$4:$AO$55,2,FALSE))*IF('7.0.3'!AU$4="是",'7.0.3'!$AY$4,'7.0.3'!$AY$3) -> 170 | K7: =(VLOOKUP('7.0.3'!S7,'7.0.3'!$AM$4:$AO$55,2,FALSE))*IF('7.0.3'!AV$4="是",'7.0.3'!$AY$4,'7.0.3'!$AY$3) -> 170 | L7: =(VLOOKUP('7.0.3'!T7,'7.0.3'!$AM$4:$AO$55,2,FALSE))*IF('7.0.3'!AW$4="是",'7.0.3'!$AY$4,'7.0.3'!$AY$3) -> 170 | M7: =(VLOOKUP('7.0.3'!U7,'7.0.3'!$AM$4:$AO$55,2,FALSE))*IF('7.0.3'!AX$4="是",'7.0.3'!$AY$4,'7.0.3'!$AY$3) -> 170 | ... X7: =(VLOOKUP('7.0.3'!AF7,'7.0.3'!$AM$4:$AO$55,2,FALSE))*IF('7.0.3'!BI$4="是",'7.0.3'!$AY$4,'7.0.3'!$AY$3) -> 0
A8: =(VLOOKUP('7.0.3'!I8,'7.0.3'!$AM$4:$AO$55,2,FALSE))*IF('7.0.3'!AK$4="是",'7.0.3'!$AY$4,'7.0.3'!$AY$3) -> 170 | B8: =(VLOOKUP('7.0.3'!J8,'7.0.3'!$AM$4:$AO$55,2,FALSE))*IF('7.0.3'!AL$4="是",'7.0.3'!$AY$4,'7.0.3'!$AY$3) -> 170 | C8: =(VLOOKUP('7.0.3'!K8,'7.0.3'!$AM$4:$AO$55,2,FALSE))*IF('7.0.3'!AM$4="是",'7.0.3'!$AY$4,'7.0.3'!$AY$3) -> 250 | D8: =(VLOOKUP('7.0.3'!L8,'7.0.3'!$AM$4:$AO$55,2,FALSE))*IF('7.0.3'!AN$4="是",'7.0.3'!$AY$4,'7.0.3'!$AY$3) -> 170 | E8: =(VLOOKUP('7.0.3'!M8,'7.0.3'!$AM$4:$AO$55,2,FALSE))*IF('7.0.3'!AO$4="是",'7.0.3'!$AY$4,'7.0.3'!$AY$3) -> 170 | F8: =(VLOOKUP('7.0.3'!N8,'7.0.3'!$AM$4:$AO$55,2,FALSE))*IF('7.0.3'!AQ$4="是",'7.0.3'!$AY$4,'7.0.3'!$AY$3) -> 50 | G8: =(VLOOKUP('7.0.3'!O8,'7.0.3'!$AM$4:$AO$55,2,FALSE))*IF('7.0.3'!AR$4="是",'7.0.3'!$AY$4,'7.0.3'!$AY$3) -> 0 | H8: =(VLOOKUP('7.0.3'!P8,'7.0.3'!$AM$4:$AO$55,2,FALSE))*IF('7.0.3'!AS$4="是",'7.0.3'!$AY$4,'7.0.3'!$AY$3) -> 0 | I8: =(VLOOKUP('7.0.3'!Q8,'7.0.3'!$AM$4:$AO$55,2,FALSE))*IF('7.0.3'!AT$4="是",'7.0.3'!$AY$4,'7.0.3'!$AY$3) -> 170 | J8: =(VLOOKUP('7.0.3'!R8,'7.0.3'!$AM$4:$AO$55,2,FALSE))*IF('7.0.3'!AU$4="是",'7.0.3'!$AY$4,'7.0.3'!$AY$3) -> 150 | K8: =(VLOOKUP('7.0.3'!S8,'7.0.3'!$AM$4:$AO$55,2,FALSE))*IF('7.0.3'!AV$4="是",'7.0.3'!$AY$4,'7.0.3'!$AY$3) -> 170 | L8: =(VLOOKUP('7.0.3'!T8,'7.0.3'!$AM$4:$AO$55,2,FALSE))*IF('7.0.3'!AW$4="是",'7.0.3'!$AY$4,'7.0.3'!$AY$3) -> 170 | M8: =(VLOOKUP('7.0.3'!U8,'7.0.3'!$AM$4:$AO$55,2,FALSE))*IF('7.0.3'!AX$4="是",'7.0.3'!$AY$4,'7.0.3'!$AY$3) -> 170 | ... X8: =(VLOOKUP('7.0.3'!AF8,'7.0.3'!$AM$4:$AO$55,2,FALSE))*IF('7.0.3'!BI$4="是",'7.0.3'!$AY$4,'7.0.3'!$AY$3) -> 0
A9: =(VLOOKUP('7.0.3'!I9,'7.0.3'!$AM$4:$AO$55,2,FALSE))*IF('7.0.3'!AK$4="是",'7.0.3'!$AY$4,'7.0.3'!$AY$3) -> 170 | B9: =(VLOOKUP('7.0.3'!J9,'7.0.3'!$AM$4:$AO$55,2,FALSE))*IF('7.0.3'!AL$4="是",'7.0.3'!$AY$4,'7.0.3'!$AY$3) -> 170 | C9: =(VLOOKUP('7.0.3'!K9,'7.0.3'!$AM$4:$AO$55,2,FALSE))*IF('7.0.3'!AM$4="是",'7.0.3'!$AY$4,'7.0.3'!$AY$3) -> 170 | D9: =(VLOOKUP('7.0.3'!L9,'7.0.3'!$AM$4:$AO$55,2,FALSE))*IF('7.0.3'!AN$4="是",'7.0.3'!$AY$4,'7.0.3'!$AY$3) -> 170 | E9: =(VLOOKUP('7.0.3'!M9,'7.0.3'!$AM$4:$AO$55,2,FALSE))*IF('7.0.3'!AO$4="是",'7.0.3'!$AY$4,'7.0.3'!$AY$3) -> 170 | F9: =(VLOOKUP('7.0.3'!N9,'7.0.3'!$AM$4:$AO$55,2,FALSE))*IF('7.0.3'!AQ$4="是",'7.0.3'!$AY$4,'7.0.3'!$AY$3) -> 170 | G9: =(VLOOKUP('7.0.3'!O9,'7.0.3'!$AM$4:$AO$55,2,FALSE))*IF('7.0.3'!AR$4="是",'7.0.3'!$AY$4,'7.0.3'!$AY$3) -> 0 | H9: =(VLOOKUP('7.0.3'!P9,'7.0.3'!$AM$4:$AO$55,2,FALSE))*IF('7.0.3'!AS$4="是",'7.0.3'!$AY$4,'7.0.3'!$AY$3) -> 0 | I9: =(VLOOKUP('7.0.3'!Q9,'7.0.3'!$AM$4:$AO$55,2,FALSE))*IF('7.0.3'!AT$4="是",'7.0.3'!$AY$4,'7.0.3'!$AY$3) -> 170 | J9: =(VLOOKUP('7.0.3'!R9,'7.0.3'!$AM$4:$AO$55,2,FALSE))*IF('7.0.3'!AU$4="是",'7.0.3'!$AY$4,'7.0.3'!$AY$3) -> 170 | K9: =(VLOOKUP('7.0.3'!S9,'7.0.3'!$AM$4:$AO$55,2,FALSE))*IF('7.0.3'!AV$4="是",'7.0.3'!$AY$4,'7.0.3'!$AY$3) -> 170 | L9: =(VLOOKUP('7.0.3'!T9,'7.0.3'!$AM$4:$AO$55,2,FALSE))*IF('7.0.3'!AW$4="是",'7.0.3'!$AY$4,'7.0.3'!$AY$3) -> 170 | M9: =(VLOOKUP('7.0.3'!U9,'7.0.3'!$AM$4:$AO$55,2,FALSE))*IF('7.0.3'!AX$4="是",'7.0.3'!$AY$4,'7.0.3'!$AY$3) -> 170 | ... X9: =(VLOOKUP('7.0.3'!AF9,'7.0.3'!$AM$4:$AO$55,2,FALSE))*IF('7.0.3'!BI$4="是",'7.0.3'!$AY$4,'7.0.3'!$AY$3) -> 0
A10: =(VLOOKUP('7.0.3'!I10,'7.0.3'!$AM$4:$AO$55,2,FALSE))*IF('7.0.3'!AK$4="是",'7.0.3'!$AY$4,'7.0.3'!$AY$3) -> 170 | B10: =(VLOOKUP('7.0.3'!J10,'7.0.3'!$AM$4:$AO$55,2,FALSE))*IF('7.0.3'!AL$4="是",'7.0.3'!$AY$4,'7.0.3'!$AY$3) -> 170 | C10: =(VLOOKUP('7.0.3'!K10,'7.0.3'!$AM$4:$AO$55,2,FALSE))*IF('7.0.3'!AM$4="是",'7.0.3'!$AY$4,'7.0.3'!$AY$3) -> 170 | D10: =(VLOOKUP('7.0.3'!L10,'7.0.3'!$AM$4:$AO$55,2,FALSE))*IF('7.0.3'!AN$4="是",'7.0.3'!$AY$4,'7.0.3'!$AY$3) -> 150 | E10: =(VLOOKUP('7.0.3'!M10,'7.0.3'!$AM$4:$AO$55,2,FALSE))*IF('7.0.3'!AO$4="是",'7.0.3'!$AY$4,'7.0.3'!$AY$3) -> 170 | F10: =(VLOOKUP('7.0.3'!N10,'7.0.3'!$AM$4:$AO$55,2,FALSE))*IF('7.0.3'!AQ$4="是",'7.0.3'!$AY$4,'7.0.3'!$AY$3) -> 170 | G10: =(VLOOKUP('7.0.3'!O10,'7.0.3'!$AM$4:$AO$55,2,FALSE))*IF('7.0.3'!AR$4="是",'7.0.3'!$AY$4,'7.0.3'!$AY$3) -> 0 | H10: =(VLOOKUP('7.0.3'!P10,'7.0.3'!$AM$4:$AO$55,2,FALSE))*IF('7.0.3'!AS$4="是",'7.0.3'!$AY$4,'7.0.3'!$AY$3) -> 0 | I10: =(VLOOKUP('7.0.3'!Q10,'7.0.3'!$AM$4:$AO$55,2,FALSE))*IF('7.0.3'!AT$4="是",'7.0.3'!$AY$4,'7.0.3'!$AY$3) -> 170 | J10: =(VLOOKUP('7.0.3'!R10,'7.0.3'!$AM$4:$AO$55,2,FALSE))*IF('7.0.3'!AU$4="是",'7.0.3'!$AY$4,'7.0.3'!$AY$3) -> 170 | K10: =(VLOOKUP('7.0.3'!S10,'7.0.3'!$AM$4:$AO$55,2,FALSE))*IF('7.0.3'!AV$4="是",'7.0.3'!$AY$4,'7.0.3'!$AY$3) -> 170 | L10: =(VLOOKUP('7.0.3'!T10,'7.0.3'!$AM$4:$AO$55,2,FALSE))*IF('7.0.3'!AW$4="是",'7.0.3'!$AY$4,'7.0.3'!$AY$3) -> 170 | M10: =(VLOOKUP('7.0.3'!U10,'7.0.3'!$AM$4:$AO$55,2,FALSE))*IF('7.0.3'!AX$4="是",'7.0.3'!$AY$4,'7.0.3'!$AY$3) -> 170 | ... X10: =(VLOOKUP('7.0.3'!AF10,'7.0.3'!$AM$4:$AO$55,2,FALSE))*IF('7.0.3'!BI$4="是",'7.0.3'!$AY$4,'7.0.3'!$AY$3) -> 0
A11: =(VLOOKUP('7.0.3'!I11,'7.0.3'!$AM$4:$AO$55,2,FALSE))*IF('7.0.3'!AK$4="是",'7.0.3'!$AY$4,'7.0.3'!$AY$3) -> 170 | B11: =(VLOOKUP('7.0.3'!J11,'7.0.3'!$AM$4:$AO$55,2,FALSE))*IF('7.0.3'!AL$4="是",'7.0.3'!$AY$4,'7.0.3'!$AY$3) -> 170 | C11: =(VLOOKUP('7.0.3'!K11,'7.0.3'!$AM$4:$AO$55,2,FALSE))*IF('7.0.3'!AM$4="是",'7.0.3'!$AY$4,'7.0.3'!$AY$3) -> 170 | D11: =(VLOOKUP('7.0.3'!L11,'7.0.3'!$AM$4:$AO$55,2,FALSE))*IF('7.0.3'!AN$4="是",'7.0.3'!$AY$4,'7.0.3'!$AY$3) -> 170 | E11: =(VLOOKUP('7.0.3'!M11,'7.0.3'!$AM$4:$AO$55,2,FALSE))*IF('7.0.3'!AO$4="是",'7.0.3'!$AY$4,'7.0.3'!$AY$3) -> 50 | F11: =(VLOOKUP('7.0.3'!N11,'7.0.3'!$AM$4:$AO$55,2,FALSE))*IF('7.0.3'!AQ$4="是",'7.0.3'!$AY$4,'7.0.3'!$AY$3) -> 170 | G11: =(VLOOKUP('7.0.3'!O11,'7.0.3'!$AM$4:$AO$55,2,FALSE))*IF('7.0.3'!AR$4="是",'7.0.3'!$AY$4,'7.0.3'!$AY$3) -> 0 | H11: =(VLOOKUP('7.0.3'!P11,'7.0.3'!$AM$4:$AO$55,2,FALSE))*IF('7.0.3'!AS$4="是",'7.0.3'!$AY$4,'7.0.3'!$AY$3) -> 0 | I11: =(VLOOKUP('7.0.3'!Q11,'7.0.3'!$AM$4:$AO$55,2,FALSE))*IF('7.0.3'!AT$4="是",'7.0.3'!$AY$4,'7.0.3'!$AY$3) -> 170 | J11: =(VLOOKUP('7.0.3'!R11,'7.0.3'!$AM$4:$AO$55,2,FALSE))*IF('7.0.3'!AU$4="是",'7.0.3'!$AY$4,'7.0.3'!$AY$3) -> 170 | K11: =(VLOOKUP('7.0.3'!S11,'7.0.3'!$AM$4:$AO$55,2,FALSE))*IF('7.0.3'!AV$4="是",'7.0.3'!$AY$4,'7.0.3'!$AY$3) -> 170 | L11: =(VLOOKUP('7.0.3'!T11,'7.0.3'!$AM$4:$AO$55,2,FALSE))*IF('7.0.3'!AW$4="是",'7.0.3'!$AY$4,'7.0.3'!$AY$3) -> 170 | M11: =(VLOOKUP('7.0.3'!U11,'7.0.3'!$AM$4:$AO$55,2,FALSE))*IF('7.0.3'!AX$4="是",'7.0.3'!$AY$4,'7.0.3'!$AY$3) -> 170 | ... X11: =(VLOOKUP('7.0.3'!AF11,'7.0.3'!$AM$4:$AO$55,2,FALSE))*IF('7.0.3'!BI$4="是",'7.0.3'!$AY$4,'7.0.3'!$AY$3) -> 0
A12: =(VLOOKUP('7.0.3'!I12,'7.0.3'!$AM$4:$AO$55,2,FALSE))*IF('7.0.3'!AK$4="是",'7.0.3'!$AY$4,'7.0.3'!$AY$3) -> 170 | B12: =(VLOOKUP('7.0.3'!J12,'7.0.3'!$AM$4:$AO$55,2,FALSE))*IF('7.0.3'!AL$4="是",'7.0.3'!$AY$4,'7.0.3'!$AY$3) -> 170 | C12: =(VLOOKUP('7.0.3'!K12,'7.0.3'!$AM$4:$AO$55,2,FALSE))*IF('7.0.3'!AM$4="是",'7.0.3'!$AY$4,'7.0.3'!$AY$3) -> 170 | D12: =(VLOOKUP('7.0.3'!L12,'7.0.3'!$AM$4:$AO$55,2,FALSE))*IF('7.0.3'!AN$4="是",'7.0.3'!$AY$4,'7.0.3'!$AY$3) -> 170 | E12: =(VLOOKUP('7.0.3'!M12,'7.0.3'!$AM$4:$AO$55,2,FALSE))*IF('7.0.3'!AO$4="是",'7.0.3'!$AY$4,'7.0.3'!$AY$3) -> 170 | F12: =(VLOOKUP('7.0.3'!N12,'7.0.3'!$AM$4:$AO$55,2,FALSE))*IF('7.0.3'!AQ$4="是",'7.0.3'!$AY$4,'7.0.3'!$AY$3) -> 50 | G12: =(VLOOKUP('7.0.3'!O12,'7.0.3'!$AM$4:$AO$55,2,FALSE))*IF('7.0.3'!AR$4="是",'7.0.3'!$AY$4,'7.0.3'!$AY$3) -> 0 | H12: =(VLOOKUP('7.0.3'!P12,'7.0.3'!$AM$4:$AO$55,2,FALSE))*IF('7.0.3'!AS$4="是",'7.0.3'!$AY$4,'7.0.3'!$AY$3) -> 0 | I12: =(VLOOKUP('7.0.3'!Q12,'7.0.3'!$AM$4:$AO$55,2,FALSE))*IF('7.0.3'!AT$4="是",'7.0.3'!$AY$4,'7.0.3'!$AY$3) -> 170 | J12: =(VLOOKUP('7.0.3'!R12,'7.0.3'!$AM$4:$AO$55,2,FALSE))*IF('7.0.3'!AU$4="是",'7.0.3'!$AY$4,'7.0.3'!$AY$3) -> 170 | K12: =(VLOOKUP('7.0.3'!S12,'7.0.3'!$AM$4:$AO$55,2,FALSE))*IF('7.0.3'!AV$4="是",'7.0.3'!$AY$4,'7.0.3'!$AY$3) -> 170 | L12: =(VLOOKUP('7.0.3'!T12,'7.0.3'!$AM$4:$AO$55,2,FALSE))*IF('7.0.3'!AW$4="是",'7.0.3'!$AY$4,'7.0.3'!$AY$3) -> 170 | M12: =(VLOOKUP('7.0.3'!U12,'7.0.3'!$AM$4:$AO$55,2,FALSE))*IF('7.0.3'!AX$4="是",'7.0.3'!$AY$4,'7.0.3'!$AY$3) -> 170 | ... X12: =(VLOOKUP('7.0.3'!AF12,'7.0.3'!$AM$4:$AO$55,2,FALSE))*IF('7.0.3'!BI$4="是",'7.0.3'!$AY$4,'7.0.3'!$AY$3) -> 0
A13: =(VLOOKUP('7.0.3'!I13,'7.0.3'!$AM$4:$AO$55,2,FALSE))*IF('7.0.3'!AK$4="是",'7.0.3'!$AY$4,'7.0.3'!$AY$3) -> 160 | B13: =(VLOOKUP('7.0.3'!J13,'7.0.3'!$AM$4:$AO$55,2,FALSE))*IF('7.0.3'!AL$4="是",'7.0.3'!$AY$4,'7.0.3'!$AY$3) -> 150 | C13: =(VLOOKUP('7.0.3'!K13,'7.0.3'!$AM$4:$AO$55,2,FALSE))*IF('7.0.3'!AM$4="是",'7.0.3'!$AY$4,'7.0.3'!$AY$3) -> 160 | D13: =(VLOOKUP('7.0.3'!L13,'7.0.3'!$AM$4:$AO$55,2,FALSE))*IF('7.0.3'!AN$4="是",'7.0.3'!$AY$4,'7.0.3'!$AY$3) -> 160 | E13: =(VLOOKUP('7.0.3'!M13,'7.0.3'!$AM$4:$AO$55,2,FALSE))*IF('7.0.3'!AO$4="是",'7.0.3'!$AY$4,'7.0.3'!$AY$3) -> 160 | F13: =(VLOOKUP('7.0.3'!N13,'7.0.3'!$AM$4:$AO$55,2,FALSE))*IF('7.0.3'!AQ$4="是",'7.0.3'!$AY$4,'7.0.3'!$AY$3) -> 50 | G13: =(VLOOKUP('7.0.3'!O13,'7.0.3'!$AM$4:$AO$55,2,FALSE))*IF('7.0.3'!AR$4="是",'7.0.3'!$AY$4,'7.0.3'!$AY$3) -> 0 | H13: =(VLOOKUP('7.0.3'!P13,'7.0.3'!$AM$4:$AO$55,2,FALSE))*IF('7.0.3'!AS$4="是",'7.0.3'!$AY$4,'7.0.3'!$AY$3) -> 0 | I13: =(VLOOKUP('7.0.3'!Q13,'7.0.3'!$AM$4:$AO$55,2,FALSE))*IF('7.0.3'!AT$4="是",'7.0.3'!$AY$4,'7.0.3'!$AY$3) -> 170 | J13: =(VLOOKUP('7.0.3'!R13,'7.0.3'!$AM$4:$AO$55,2,FALSE))*IF('7.0.3'!AU$4="是",'7.0.3'!$AY$4,'7.0.3'!$AY$3) -> 170 | K13: =(VLOOKUP('7.0.3'!S13,'7.0.3'!$AM$4:$AO$55,2,FALSE))*IF('7.0.3'!AV$4="是",'7.0.3'!$AY$4,'7.0.3'!$AY$3) -> 170 | L13: =(VLOOKUP('7.0.3'!T13,'7.0.3'!$AM$4:$AO$55,2,FALSE))*IF('7.0.3'!AW$4="是",'7.0.3'!$AY$4,'7.0.3'!$AY$3) -> 170 | M13: =(VLOOKUP('7.0.3'!U13,'7.0.3'!$AM$4:$AO$55,2,FALSE))*IF('7.0.3'!AX$4="是",'7.0.3'!$AY$4,'7.0.3'!$AY$3) -> 170 | ... X13: =(VLOOKUP('7.0.3'!AF13,'7.0.3'!$AM$4:$AO$55,2,FALSE))*IF('7.0.3'!BI$4="是",'7.0.3'!$AY$4,'7.0.3'!$AY$3) -> 0
A14: =(VLOOKUP('7.0.3'!I14,'7.0.3'!$AM$4:$AO$55,2,FALSE))*IF('7.0.3'!AK$4="是",'7.0.3'!$AY$4,'7.0.3'!$AY$3) -> 160 | B14: =(VLOOKUP('7.0.3'!J14,'7.0.3'!$AM$4:$AO$55,2,FALSE))*IF('7.0.3'!AL$4="是",'7.0.3'!$AY$4,'7.0.3'!$AY$3) -> 170 | C14: =(VLOOKUP('7.0.3'!K14,'7.0.3'!$AM$4:$AO$55,2,FALSE))*IF('7.0.3'!AM$4="是",'7.0.3'!$AY$4,'7.0.3'!$AY$3) -> 170 | D14: =(VLOOKUP('7.0.3'!L14,'7.0.3'!$AM$4:$AO$55,2,FALSE))*IF('7.0.3'!AN$4="是",'7.0.3'!$AY$4,'7.0.3'!$AY$3) -> 170 | E14: =(VLOOKUP('7.0.3'!M14,'7.0.3'!$AM$4:$AO$55,2,FALSE))*IF('7.0.3'!AO$4="是",'7.0.3'!$AY$4,'7.0.3'!$AY$3) -> 170 | F14: =(VLOOKUP('7.0.3'!N14,'7.0.3'!$AM$4:$AO$55,2,FALSE))*IF('7.0.3'!AQ$4="是",'7.0.3'!$AY$4,'7.0.3'!$AY$3) -> 170 | G14: =(VLOOKUP('7.0.3'!O14,'7.0.3'!$AM$4:$AO$55,2,FALSE))*IF('7.0.3'!AR$4="是",'7.0.3'!$AY$4,'7.0.3'!$AY$3) -> 0 | H14: =(VLOOKUP('7.0.3'!P14,'7.0.3'!$AM$4:$AO$55,2,FALSE))*IF('7.0.3'!AS$4="是",'7.0.3'!$AY$4,'7.0.3'!$AY$3) -> 0 | I14: =(VLOOKUP('7.0.3'!Q14,'7.0.3'!$AM$4:$AO$55,2,FALSE))*IF('7.0.3'!AT$4="是",'7.0.3'!$AY$4,'7.0.3'!$AY$3) -> 170 | J14: =(VLOOKUP('7.0.3'!R14,'7.0.3'!$AM$4:$AO$55,2,FALSE))*IF('7.0.3'!AU$4="是",'7.0.3'!$AY$4,'7.0.3'!$AY$3) -> 170 | K14: =(VLOOKUP('7.0.3'!S14,'7.0.3'!$AM$4:$AO$55,2,FALSE))*IF('7.0.3'!AV$4="是",'7.0.3'!$AY$4,'7.0.3'!$AY$3) -> 170 | L14: =(VLOOKUP('7.0.3'!T14,'7.0.3'!$AM$4:$AO$55,2,FALSE))*IF('7.0.3'!AW$4="是",'7.0.3'!$AY$4,'7.0.3'!$AY$3) -> 170 | M14: =(VLOOKUP('7.0.3'!U14,'7.0.3'!$AM$4:$AO$55,2,FALSE))*IF('7.0.3'!AX$4="是",'7.0.3'!$AY$4,'7.0.3'!$AY$3) -> 170 | ... X14: =(VLOOKUP('7.0.3'!AF14,'7.0.3'!$AM$4:$AO$55,2,FALSE))*IF('7.0.3'!BI$4="是",'7.0.3'!$AY$4,'7.0.3'!$AY$3) -> 0
A15: =(VLOOKUP('7.0.3'!I15,'7.0.3'!$AM$4:$AO$55,2,FALSE))*IF('7.0.3'!AK$4="是",'7.0.3'!$AY$4,'7.0.3'!$AY$3) -> 170 | B15: =(VLOOKUP('7.0.3'!J15,'7.0.3'!$AM$4:$AO$55,2,FALSE))*IF('7.0.3'!AL$4="是",'7.0.3'!$AY$4,'7.0.3'!$AY$3) -> 170 | C15: =(VLOOKUP('7.0.3'!K15,'7.0.3'!$AM$4:$AO$55,2,FALSE))*IF('7.0.3'!AM$4="是",'7.0.3'!$AY$4,'7.0.3'!$AY$3) -> 170 | D15: =(VLOOKUP('7.0.3'!L15,'7.0.3'!$AM$4:$AO$55,2,FALSE))*IF('7.0.3'!AN$4="是",'7.0.3'!$AY$4,'7.0.3'!$AY$3) -> 150 | E15: =(VLOOKUP('7.0.3'!M15,'7.0.3'!$AM$4:$AO$55,2,FALSE))*IF('7.0.3'!AO$4="是",'7.0.3'!$AY$4,'7.0.3'!$AY$3) -> 170 | F15: =(VLOOKUP('7.0.3'!N15,'7.0.3'!$AM$4:$AO$55,2,FALSE))*IF('7.0.3'!AQ$4="是",'7.0.3'!$AY$4,'7.0.3'!$AY$3) -> 170 | G15: =(VLOOKUP('7.0.3'!O15,'7.0.3'!$AM$4:$AO$55,2,FALSE))*IF('7.0.3'!AR$4="是",'7.0.3'!$AY$4,'7.0.3'!$AY$3) -> 0 | H15: =(VLOOKUP('7.0.3'!P15,'7.0.3'!$AM$4:$AO$55,2,FALSE))*IF('7.0.3'!AS$4="是",'7.0.3'!$AY$4,'7.0.3'!$AY$3) -> 0 | I15: =(VLOOKUP('7.0.3'!Q15,'7.0.3'!$AM$4:$AO$55,2,FALSE))*IF('7.0.3'!AT$4="是",'7.0.3'!$AY$4,'7.0.3'!$AY$3) -> 50 | J15: =(VLOOKUP('7.0.3'!R15,'7.0.3'!$AM$4:$AO$55,2,FALSE))*IF('7.0.3'!AU$4="是",'7.0.3'!$AY$4,'7.0.3'!$AY$3) -> 170 | K15: =(VLOOKUP('7.0.3'!S15,'7.0.3'!$AM$4:$AO$55,2,FALSE))*IF('7.0.3'!AV$4="是",'7.0.3'!$AY$4,'7.0.3'!$AY$3) -> 170 | L15: =(VLOOKUP('7.0.3'!T15,'7.0.3'!$AM$4:$AO$55,2,FALSE))*IF('7.0.3'!AW$4="是",'7.0.3'!$AY$4,'7.0.3'!$AY$3) -> 170 | M15: =(VLOOKUP('7.0.3'!U15,'7.0.3'!$AM$4:$AO$55,2,FALSE))*IF('7.0.3'!AX$4="是",'7.0.3'!$AY$4,'7.0.3'!$AY$3) -> 180 | ... X15: =(VLOOKUP('7.0.3'!AF15,'7.0.3'!$AM$4:$AO$55,2,FALSE))*IF('7.0.3'!BI$4="是",'7.0.3'!$AY$4,'7.0.3'!$AY$3) -> 0
... A94: =(VLOOKUP('7.0.3'!I94,'7.0.3'!$AM$4:$AO$55,2,FALSE))*IF('7.0.3'!AK$4="是",'7.0.3'!$AY$4,'7.0.3'!$AY$3) -> 160 | B94: =(VLOOKUP('7.0.3'!J94,'7.0.3'!$AM$4:$AO$55,2,FALSE))*IF('7.0.3'!AL$4="是",'7.0.3'!$AY$4,'7.0.3'!$AY$3) -> 160 | C94: =(VLOOKUP('7.0.3'!K94,'7.0.3'!$AM$4:$AO$55,2,FALSE))*IF('7.0.3'!AM$4="是",'7.0.3'!$AY$4,'7.0.3'!$AY$3) -> 50 | D94: =(VLOOKUP('7.0.3'!L94,'7.0.3'!$AM$4:$AO$55,2,FALSE))*IF('7.0.3'!AN$4="是",'7.0.3'!$AY$4,'7.0.3'!$AY$3) -> 160 | E94: =(VLOOKUP('7.0.3'!M94,'7.0.3'!$AM$4:$AO$55,2,FALSE))*IF('7.0.3'!AO$4="是",'7.0.3'!$AY$4,'7.0.3'!$AY$3) -> 160 | F94: =(VLOOKUP('7.0.3'!N94,'7.0.3'!$AM$4:$AO$55,2,FALSE))*IF('7.0.3'!AQ$4="是",'7.0.3'!$AY$4,'7.0.3'!$AY$3) -> 50 | G94: =(VLOOKUP('7.0.3'!O94,'7.0.3'!$AM$4:$AO$55,2,FALSE))*IF('7.0.3'!AR$4="是",'7.0.3'!$AY$4,'7.0.3'!$AY$3) -> 0 | H94: =(VLOOKUP('7.0.3'!P94,'7.0.3'!$AM$4:$AO$55,2,FALSE))*IF('7.0.3'!AS$4="是",'7.0.3'!$AY$4,'7.0.3'!$AY$3) -> 0 | I94: =(VLOOKUP('7.0.3'!Q94,'7.0.3'!$AM$4:$AO$55,2,FALSE))*IF('7.0.3'!AT$4="是",'7.0.3'!$AY$4,'7.0.3'!$AY$3) -> 50 | J94: =(VLOOKUP('7.0.3'!R94,'7.0.3'!$AM$4:$AO$55,2,FALSE))*IF('7.0.3'!AU$4="是",'7.0.3'!$AY$4,'7.0.3'!$AY$3) -> 160 | K94: =(VLOOKUP('7.0.3'!S94,'7.0.3'!$AM$4:$AO$55,2,FALSE))*IF('7.0.3'!AV$4="是",'7.0.3'!$AY$4,'7.0.3'!$AY$3) -> 160 | L94: =(VLOOKUP('7.0.3'!T94,'7.0.3'!$AM$4:$AO$55,2,FALSE))*IF('7.0.3'!AW$4="是",'7.0.3'!$AY$4,'7.0.3'!$AY$3) -> 160 | M94: =(VLOOKUP('7.0.3'!U94,'7.0.3'!$AM$4:$AO$55,2,FALSE))*IF('7.0.3'!AX$4="是",'7.0.3'!$AY$4,'7.0.3'!$AY$3) -> 150 | ... X94: =(VLOOKUP('7.0.3'!AF94,'7.0.3'!$AM$4:$AO$55,2,FALSE))*IF('7.0.3'!BI$4="是",'7.0.3'!$AY$4,'7.0.3'!$AY$3) -> 0

Sheet 经验
A2: 队伍一 风 | C2: 步数 | D2: =COUNTIF(A4:H94,"<>空") -> 728 | E2: (不算跳步和传送) | I2: 队伍二 雷 | K2: 步数 | L2: =COUNTIF(I4:P94,"<>空") -> 728 | M2: (不算跳步和传送) | Q2: 队伍三 | S2: 总步数 | T2: =COUNTIF(Q4:X94,"<>空") -> 728 | U2: (不算跳步和传送)
A3: 1 | B3: 2 | C3: 3 | D3: 4 | E3: 5 | F3: 6 | G3: 7 | H3: 8 | I3: 1 | J3: 2 | K3: 3 | L3: 4 | M3: 5 | N3: 6 | O3: 7 | P3: 8 | Q3: 1 | R3: 2 | S3: 3 | T3: 4 | U3: 5 | V3: 6 | W3: 7 | X3: 8
A4: =(VLOOKUP('7.0.3'!I4,'7.0.3'!$AM$4:$AO$55,3,FALSE)) -> 35 | B4: =(VLOOKUP('7.0.3'!J4,'7.0.3'!$AM$4:$AO$55,3,FALSE)) -> 35 | C4: =(VLOOKUP('7.0.3'!K4,'7.0.3'!$AM$4:$AO$55,3,FALSE)) -> 35 | D4: =(VLOOKUP('7.0.3'!L4,'7.0.3'!$AM$4:$AO$55,3,FALSE)) -> 35 | E4: =(VLOOKUP('7.0.3'!M4,'7.0.3'!$AM$4:$AO$55,3,FALSE)) -> 35 | F4: =(VLOOKUP('7.0.3'!N4,'7.0.3'!$AM$4:$AO$55,3,FALSE)) -> 30 | G4: =(VLOOKUP('7.0.3'!O4,'7.0.3'!$AM$4:$AO$55,3,FALSE)) -> 0 | H4: =(VLOOKUP('7.0.3'!P4,'7.0.3'!$AM$4:$AO$55,3,FALSE)) -> 0 | ... X4: =(VLOOKUP('7.0.3'!AF4,'7.0.3'!$AM$4:$AO$55,3,FALSE)) -> 0
A5: =(VLOOKUP('7.0.3'!I5,'7.0.3'!$AM$4:$AO$55,3,FALSE)) -> 40 | B5: =(VLOOKUP('7.0.3'!J5,'7.0.3'!$AM$4:$AO$55,3,FALSE)) -> 40 | C5: =(VLOOKUP('7.0.3'!K5,'7.0.3'!$AM$4:$AO$55,3,FALSE)) -> 40 | D5: =(VLOOKUP('7.0.3'!L5,'7.0.3'!$AM$4:$AO$55,3,FALSE)) -> 40 | E5: =(VLOOKUP('7.0.3'!M5,'7.0.3'!$AM$4:$AO$55,3,FALSE)) -> 40 | F5: =(VLOOKUP('7.0.3'!N5,'7.0.3'!$AM$4:$AO$55,3,FALSE)) -> 30 | G5: =(VLOOKUP('7.0.3'!O5,'7.0.3'!$AM$4:$AO$55,3,FALSE)) -> 0 | H5: =(VLOOKUP('7.0.3'!P5,'7.0.3'!$AM$4:$AO$55,3,FALSE)) -> 0 | ... X5: =(VLOOKUP('7.0.3'!AF5,'7.0.3'!$AM$4:$AO$55,3,FALSE)) -> 0
A6: =(VLOOKUP('7.0.3'!I6,'7.0.3'!$AM$4:$AO$55,3,FALSE)) -> 40 | B6: =(VLOOKUP('7.0.3'!J6,'7.0.3'!$AM$4:$AO$55,3,FALSE)) -> 40 | C6: =(VLOOKUP('7.0.3'!K6,'7.0.3'!$AM$4:$AO$55,3,FALSE)) -> 45 | D6: =(VLOOKUP('7.0.3'!L6,'7.0.3'!$AM$4:$AO$55,3,FALSE)) -> 45 | E6: =(VLOOKUP('7.0.3'!M6,'7.0.3'!$AM$4:$AO$55,3,FALSE)) -> 45 | F6: =(VLOOKUP('7.0.3'!N6,'7.0.3'!$AM$4:$AO$55,3,FALSE)) -> 45 | G6: =(VLOOKUP('7.0.3'!O6,'7.0.3'!$AM$4:$AO$55,3,FALSE)) -> 0 | H6: =(VLOOKUP('7.0.3'!P6,'7.0.3'!$AM$4:$AO$55,3,FALSE)) -> 0 | ... X6: =(VLOOKUP('7.0.3'!AF6,'7.0.3'!$AM$4:$AO$55,3,FALSE)) -> 0
A7: =(VLOOKUP('7.0.3'!I7,'7.0.3'!$AM$4:$AO$55,3,FALSE)) -> 45 | B7: =(VLOOKUP('7.0.3'!J7,'7.0.3'!$AM$4:$AO$55,3,FALSE)) -> 45 | C7: =(VLOOKUP('7.0.3'!K7,'7.0.3'!$AM$4:$AO$55,3,FALSE)) -> 45 | D7: =(VLOOKUP('7.0.3'!L7,'7.0.3'!$AM$4:$AO$55,3,FALSE)) -> 45 | E7: =(VLOOKUP('7.0.3'!M7,'7.0.3'!$AM$4:$AO$55,3,FALSE)) -> 45 | F7: =(VLOOKUP('7.0.3'!N7,'7.0.3'!$AM$4:$AO$55,3,FALSE)) -> 45 | G7: =(VLOOKUP('7.0.3'!O7,'7.0.3'!$AM$4:$AO$55,3,FALSE)) -> 0 | H7: =(VLOOKUP('7.0.3'!P7,'7.0.3'!$AM$4:$AO$55,3,FALSE)) -> 0 | ... X7: =(VLOOKUP('7.0.3'!AF7,'7.0.3'!$AM$4:$AO$55,3,FALSE)) -> 0
A8: =(VLOOKUP('7.0.3'!I8,'7.0.3'!$AM$4:$AO$55,3,FALSE)) -> 45 | B8: =(VLOOKUP('7.0.3'!J8,'7.0.3'!$AM$4:$AO$55,3,FALSE)) -> 45 | C8: =(VLOOKUP('7.0.3'!K8,'7.0.3'!$AM$4:$AO$55,3,FALSE)) -> 200 | D8: =(VLOOKUP('7.0.3'!L8,'7.0.3'!$AM$4:$AO$55,3,FALSE)) -> 45 | E8: =(VLOOKUP('7.0.3'!M8,'7.0.3'!$AM$4:$AO$55,3,FALSE)) -> 45 | F8: =(VLOOKUP('7.0.3'!N8,'7.0.3'!$AM$4:$AO$55,3,FALSE)) -> 30 | G8: =(VLOOKUP('7.0.3'!O8,'7.0.3'!$AM$4:$AO$55,3,FALSE)) -> 0 | H8: =(VLOOKUP('7.0.3'!P8,'7.0.3'!$AM$4:$AO$55,3,FALSE)) -> 0 | ... X8: =(VLOOKUP('7.0.3'!AF8,'7.0.3'!$AM$4:$AO$55,3,FALSE)) -> 0
A9: =(VLOOKUP('7.0.3'!I9,'7.0.3'!$AM$4:$AO$55,3,FALSE)) -> 45 | B9: =(VLOOKUP('7.0.3'!J9,'7.0.3'!$AM$4:$AO$55,3,FALSE)) -> 45 | C9: =(VLOOKUP('7.0.3'!K9,'7.0.3'!$AM$4:$AO$55,3,FALSE)) -> 45 | D9: =(VLOOKUP('7.0.3'!L9,'7.0.3'!$AM$4:$AO$55,3,FALSE)) -> 45 | E9: =(VLOOKUP('7.0.3'!M9,'7.0.3'!$AM$4:$AO$55,3,FALSE)) -> 45 | F9: =(VLOOKUP('7.0.3'!N9,'7.0.3'!$AM$4:$AO$55,3,FALSE)) -> 45 | G9: =(VLOOKUP('7.0.3'!O9,'7.0.3'!$AM$4:$AO$55,3,FALSE)) -> 0 | H9: =(VLOOKUP('7.0.3'!P9,'7.0.3'!$AM$4:$AO$55,3,FALSE)) -> 0 | ... X9: =(VLOOKUP('7.0.3'!AF9,'7.0.3'!$AM$4:$AO$55,3,FALSE)) -> 0
A10: =(VLOOKUP('7.0.3'!I10,'7.0.3'!$AM$4:$AO$55,3,FALSE)) -> 45 | B10: =(VLOOKUP('7.0.3'!J10,'7.0.3'!$AM$4:$AO$55,3,FALSE)) -> 45 | C10: =(VLOOKUP('7.0.3'!K10,'7.0.3'!$AM$4:$AO$55,3,FALSE)) -> 45 | D10: =(VLOOKUP('7.0.3'!L10,'7.0.3'!$AM$4:$AO$55,3,FALSE)) -> 45 | E10: =(VLOOKUP('7.0.3'!M10,'7.0.3'!$AM$4:$AO$55,3,FALSE)) -> 45 | F10: =(VLOOKUP('7.0.3'!N10,'7.0.3'!$AM$4:$AO$55,3,FALSE)) -> 45 | G10: =(VLOOKUP('7.0.3'!O10,'7.0.3'!$AM$4:$AO$55,3,FALSE)) -> 0 | H10: =(VLOOKUP('7.0.3'!P10,'7.0.3'!$AM$4:$AO$55,3,FALSE)) -> 0 | ... X10: =(VLOOKUP('7.0.3'!AF10,'7.0.3'!$AM$4:$AO$55,3,FALSE)) -> 0
A11: =(VLOOKUP('7.0.3'!I11,'7.0.3'!$AM$4:$AO$55,3,FALSE)) -> 45 | B11: =(VLOOKUP('7.0.3'!J11,'7.0.3'!$AM$4:$AO$55,3,FALSE)) -> 45 | C11: =(VLOOKUP('7.0.3'!K11,'7.0.3'!$AM$4:$AO$55,3,FALSE)) -> 45 | D11: =(VLOOKUP('7.0.3'!L11,'7.0.3'!$AM$4:$AO$55,3,FALSE)) -> 45 | E11: =(VLOOKUP('7.0.3'!M11,'7.0.3'!$AM$4:$AO$55,3,FALSE)) -> 30 | F11: =(VLOOKUP('7.0.3'!N11,'7.0.3'!$AM$4:$AO$55,3,FALSE)) -> 45 | G11: =(VLOOKUP('7.0.3'!O11,'7.0.3'!$AM$4:$AO$55,3,FALSE)) -> 0 | H11: =(VLOOKUP('7.0.3'!P11,'7.0.3'!$AM$4:$AO$55,3,FALSE)) -> 0 | ... X11: =(VLOOKUP('7.0.3'!AF11,'7.0.3'!$AM$4:$AO$55,3,FALSE)) -> 0
A12: =(VLOOKUP('7.0.3'!I12,'7.0.3'!$AM$4:$AO$55,3,FALSE)) -> 45 | B12: =(VLOOKUP('7.0.3'!J12,'7.0.3'!$AM$4:$AO$55,3,FALSE)) -> 45 | C12: =(VLOOKUP('7.0.3'!K12,'7.0.3'!$AM$4:$AO$55,3,FALSE)) -> 45 | D12: =(VLOOKUP('7.0.3'!L12,'7.0.3'!$AM$4:$AO$55,3,FALSE)) -> 45 | E12: =(VLOOKUP('7.0.3'!M12,'7.0.3'!$AM$4:$AO$55,3,FALSE)) -> 45 | F12: =(VLOOKUP('7.0.3'!N12,'7.0.3'!$AM$4:$AO$55,3,FALSE)) -> 30 | G12: =(VLOOKUP('7.0.3'!O12,'7.0.3'!$AM$4:$AO$55,3,FALSE)) -> 0 | H12: =(VLOOKUP('7.0.3'!P12,'7.0.3'!$AM$4:$AO$55,3,FALSE)) -> 0 | ... X12: =(VLOOKUP('7.0.3'!AF12,'7.0.3'!$AM$4:$AO$55,3,FALSE)) -> 0
A13: =(VLOOKUP('7.0.3'!I13,'7.0.3'!$AM$4:$AO$55,3,FALSE)) -> 40 | B13: =(VLOOKUP('7.0.3'!J13,'7.0.3'!$AM$4:$AO$55,3,FALSE)) -> 40 | C13: =(VLOOKUP('7.0.3'!K13,'7.0.3'!$AM$4:$AO$55,3,FALSE)) -> 40 | D13: =(VLOOKUP('7.0.3'!L13,'7.0.3'!$AM$4:$AO$55,3,FALSE)) -> 40 | E13: =(VLOOKUP('7.0.3'!M13,'7.0.3'!$AM$4:$AO$55,3,FALSE)) -> 40 | F13: =(VLOOKUP('7.0.3'!N13,'7.0.3'!$AM$4:$AO$55,3,FALSE)) -> 30 | G13: =(VLOOKUP('7.0.3'!O13,'7.0.3'!$AM$4:$AO$55,3,FALSE)) -> 0 | H13: =(VLOOKUP('7.0.3'!P13,'7.0.3'!$AM$4:$AO$55,3,FALSE)) -> 0 | ... X13: =(VLOOKUP('7.0.3'!AF13,'7.0.3'!$AM$4:$AO$55,3,FALSE)) -> 0
A14: =(VLOOKUP('7.0.3'!I14,'7.0.3'!$AM$4:$AO$55,3,FALSE)) -> 40 | B14: =(VLOOKUP('7.0.3'!J14,'7.0.3'!$AM$4:$AO$55,3,FALSE)) -> 45 | C14: =(VLOOKUP('7.0.3'!K14,'7.0.3'!$AM$4:$AO$55,3,FALSE)) -> 45 | D14: =(VLOOKUP('7.0.3'!L14,'7.0.3'!$AM$4:$AO$55,3,FALSE)) -> 45 | E14: =(VLOOKUP('7.0.3'!M14,'7.0.3'!$AM$4:$AO$55,3,FALSE)) -> 45 | F14: =(VLOOKUP('7.0.3'!N14,'7.0.3'!$AM$4:$AO$55,3,FALSE)) -> 45 | G14: =(VLOOKUP('7.0.3'!O14,'7.0.3'!$AM$4:$AO$55,3,FALSE)) -> 0 | H14: =(VLOOKUP('7.0.3'!P14,'7.0.3'!$AM$4:$AO$55,3,FALSE)) -> 0 | ... X14: =(VLOOKUP('7.0.3'!AF14,'7.0.3'!$AM$4:$AO$55,3,FALSE)) -> 0
A15: =(VLOOKUP('7.0.3'!I15,'7.0.3'!$AM$4:$AO$55,3,FALSE)) -> 45 | B15: =(VLOOKUP('7.0.3'!J15,'7.0.3'!$AM$4:$AO$55,3,FALSE)) -> 45 | C15: =(VLOOKUP('7.0.3'!K15,'7.0.3'!$AM$4:$AO$55,3,FALSE)) -> 45 | D15: =(VLOOKUP('7.0.3'!L15,'7.0.3'!$AM$4:$AO$55,3,FALSE)) -> 40 | E15: =(VLOOKUP('7.0.3'!M15,'7.0.3'!$AM$4:$AO$55,3,FALSE)) -> 45 | F15: =(VLOOKUP('7.0.3'!N15,'7.0.3'!$AM$4:$AO$55,3,FALSE)) -> 45 | G15: =(VLOOKUP('7.0.3'!O15,'7.0.3'!$AM$4:$AO$55,3,FALSE)) -> 0 | H15: =(VLOOKUP('7.0.3'!P15,'7.0.3'!$AM$4:$AO$55,3,FALSE)) -> 0 | ... X15: =(VLOOKUP('7.0.3'!AF15,'7.0.3'!$AM$4:$AO$55,3,FALSE)) -> 0
... A94: =(VLOOKUP('7.0.3'!I94,'7.0.3'!$AM$4:$AO$55,3,FALSE)) -> 40 | B94: =(VLOOKUP('7.0.3'!J94,'7.0.3'!$AM$4:$AO$55,3,FALSE)) -> 40 | C94: =(VLOOKUP('7.0.3'!K94,'7.0.3'!$AM$4:$AO$55,3,FALSE)) -> 30 | D94: =(VLOOKUP('7.0.3'!L94,'7.0.3'!$AM$4:$AO$55,3,FALSE)) -> 40 | E94: =(VLOOKUP('7.0.3'!M94,'7.0.3'!$AM$4:$AO$55,3,FALSE)) -> 40 | F94: =(VLOOKUP('7.0.3'!N94,'7.0.3'!$AM$4:$AO$55,3,FALSE)) -> 30 | G94: =(VLOOKUP('7.0.3'!O94,'7.0.3'!$AM$4:$AO$55,3,FALSE)) -> 0 | H94: =(VLOOKUP('7.0.3'!P94,'7.0.3'!$AM$4:$AO$55,3,FALSE)) -> 0 | ... X94: =(VLOOKUP('7.0.3'!AF94,'7.0.3'!$AM$4:$AO$55,3,FALSE)) -> 0

Sheet 亏损
A2: 队伍一 风 | C2: 步数 | D2: =COUNTIF(A4:H94,"<>空") -> 728 | E2: (不算跳步和传送) | I2: 队伍二 雷 | K2: 步数 | L2: =COUNTIF(I4:P94,"<>空") -> 728 | M2: (不算跳步和传送) | Q2: 队伍三 | S2: 总步数 | T2: =COUNTIF(Q4:X94,"<>空") -> 728 | U2: (不算跳步和传送)
A3: 1 | B3: 2 | C3: 3 | D3: 4 | E3: 5 | F3: 6 | G3: 7 | H3: 8 | I3: 1 | J3: 2 | K3: 3 | L3: 4 | M3: 5 | N3: 6 | O3: 7 | P3: 8 | Q3: 1 | R3: 2 | S3: 3 | T3: 4 | U3: 5 | V3: 6 | W3: 7 | X3: 8
A4: =(VLOOKUP('7.0.3'!I4,'7.0.3'!$AM$4:$AP$55,4,FALSE)) -> 44.222109 | B4: =(VLOOKUP('7.0.3'!J4,'7.0.3'!$AM$4:$AP$55,4,FALSE)) -> 44.222109 | C4: =(VLOOKUP('7.0.3'!K4,'7.0.3'!$AM$4:$AP$55,4,FALSE)) -> 44.222109 | D4: =(VLOOKUP('7.0.3'!L4,'7.0.3'!$AM$4:$AP$55,4,FALSE)) -> 44.222109 | E4: =(VLOOKUP('7.0.3'!M4,'7.0.3'!$AM$4:$AP$55,4,FALSE)) -> 44.222109 | F4: =(VLOOKUP('7.0.3'!N4,'7.0.3'!$AM$4:$AP$55,4,FALSE)) -> 10 | G4: =(VLOOKUP('7.0.3'!O4,'7.0.3'!$AM$4:$AP$55,4,FALSE)) -> 0 | H4: =(VLOOKUP('7.0.3'!P4,'7.0.3'!$AM$4:$AP$55,4,FALSE)) -> 0 | ... X4: =(VLOOKUP('7.0.3'!AF4,'7.0.3'!$AM$4:$AP$55,4,FALSE)) -> 0
A5: =(VLOOKUP('7.0.3'!I5,'7.0.3'!$AM$4:$AP$55,4,FALSE)) -> 39.110982 | B5: =(VLOOKUP('7.0.3'!J5,'7.0.3'!$AM$4:$AP$55,4,FALSE)) -> 39.110982 | C5: =(VLOOKUP('7.0.3'!K5,'7.0.3'!$AM$4:$AP$55,4,FALSE)) -> 39.110982 | D5: =(VLOOKUP('7.0.3'!L5,'7.0.3'!$AM$4:$AP$55,4,FALSE)) -> 39.110982 | E5: =(VLOOKUP('7.0.3'!M5,'7.0.3'!$AM$4:$AP$55,4,FALSE)) -> 39.110982 | F5: =(VLOOKUP('7.0.3'!N5,'7.0.3'!$AM$4:$AP$55,4,FALSE)) -> 10 | G5: =(VLOOKUP('7.0.3'!O5,'7.0.3'!$AM$4:$AP$55,4,FALSE)) -> 0 | H5: =(VLOOKUP('7.0.3'!P5,'7.0.3'!$AM$4:$AP$55,4,FALSE)) -> 0 | ... X5: =(VLOOKUP('7.0.3'!AF5,'7.0.3'!$AM$4:$AP$55,4,FALSE)) -> 0
A6: =(VLOOKUP('7.0.3'!I6,'7.0.3'!$AM$4:$AP$55,4,FALSE)) -> 39.110982 | B6: =(VLOOKUP('7.0.3'!J6,'7.0.3'!$AM$4:$AP$55,4,FALSE)) -> 39.110982 | C6: =(VLOOKUP('7.0.3'!K6,'7.0.3'!$AM$4:$AP$55,4,FALSE)) -> 34 | D6: =(VLOOKUP('7.0.3'!L6,'7.0.3'!$AM$4:$AP$55,4,FALSE)) -> 34 | E6: =(VLOOKUP('7.0.3'!M6,'7.0.3'!$AM$4:$AP$55,4,FALSE)) -> 34 | F6: =(VLOOKUP('7.0.3'!N6,'7.0.3'!$AM$4:$AP$55,4,FALSE)) -> 34 | G6: =(VLOOKUP('7.0.3'!O6,'7.0.3'!$AM$4:$AP$55,4,FALSE)) -> 0 | H6: =(VLOOKUP('7.0.3'!P6,'7.0.3'!$AM$4:$AP$55,4,FALSE)) -> 0 | ... X6: =(VLOOKUP('7.0.3'!AF6,'7.0.3'!$AM$4:$AP$55,4,FALSE)) -> 0
A7: =(VLOOKUP('7.0.3'!I7,'7.0.3'!$AM$4:$AP$55,4,FALSE)) -> 0 | B7: =(VLOOKUP('7.0.3'!J7,'7.0.3'!$AM$4:$AP$55,4,FALSE)) -> 34 | C7: =(VLOOKUP('7.0.3'!K7,'7.0.3'!$AM$4:$AP$55,4,FALSE)) -> 34 | D7: =(VLOOKUP('7.0.3'!L7,'7.0.3'!$AM$4:$AP$55,4,FALSE)) -> 34 | E7: =(VLOOKUP('7.0.3'!M7,'7.0.3'!$AM$4:$AP$55,4,FALSE)) -> 34 | F7: =(VLOOKUP('7.0.3'!N7,'7.0.3'!$AM$4:$AP$55,4,FALSE)) -> 13.999855 | G7: =(VLOOKUP('7.0.3'!O7,'7.0.3'!$AM$4:$AP$55,4,FALSE)) -> 0 | H7: =(VLOOKUP('7.0.3'!P7,'7.0.3'!$AM$4:$AP$55,4,FALSE)) -> 0 | ... X7: =(VLOOKUP('7.0.3'!AF7,'7.0.3'!$AM$4:$AP$55,4,FALSE)) -> 0
A8: =(VLOOKUP('7.0.3'!I8,'7.0.3'!$AM$4:$AP$55,4,FALSE)) -> 34 | B8: =(VLOOKUP('7.0.3'!J8,'7.0.3'!$AM$4:$AP$55,4,FALSE)) -> 34 | C8: =(VLOOKUP('7.0.3'!K8,'7.0.3'!$AM$4:$AP$55,4,FALSE)) -> 0 | D8: =(VLOOKUP('7.0.3'!L8,'7.0.3'!$AM$4:$AP$55,4,FALSE)) -> 34 | E8: =(VLOOKUP('7.0.3'!M8,'7.0.3'!$AM$4:$AP$55,4,FALSE)) -> 34 | F8: =(VLOOKUP('7.0.3'!N8,'7.0.3'!$AM$4:$AP$55,4,FALSE)) -> 10 | G8: =(VLOOKUP('7.0.3'!O8,'7.0.3'!$AM$4:$AP$55,4,FALSE)) -> 0 | H8: =(VLOOKUP('7.0.3'!P8,'7.0.3'!$AM$4:$AP$55,4,FALSE)) -> 0 | ... X8: =(VLOOKUP('7.0.3'!AF8,'7.0.3'!$AM$4:$AP$55,4,FALSE)) -> 0
