Workbook

Sheet 20.03
A1: =(_xlfn.DAYS(TODAY(),A4)+2)/((_xlfn.DAYS(A93,A4))+1) -> 0.022222222 | I1: 工作区
B2: 八卦前亏 | C2: =SUM(D4:D15) -> 23390 | D2: 合计经验 | F2: =SUM(F4:F93)+SUM(H4:H93) -> 24080 | I2: 队伍一 火 | K2: 步数 | L2: =COUNTIF(I4:P93,"<>空") -> 92 | M2: (不算跳步和传送) | Q2: 队伍二 雷 | S2: 步数 | T2: =COUNTIF(Q4:X93,"<>空") -> 109 | U2: (不算跳步和传送) | Y2: 队伍三 | AA2: 总步数 | AB2: =COUNTIF(Y4:AF93,"<>空") -> 124 | AC2: (不算跳步和传送) | AG2: =SUM(AG4:AG93) -> 41 | AH2: =SUM(AH4:AH93) -> 12 | AI2: =SUM(AI4:AI93) -> 11 | AJ2: =SUM(AJ4:AJ93) -> 18 | AK2: 八卦全开 | AU2: 总地块 | AV2: =SUM(AV4:AV29) -> 325 | AW2: 剩余粮草 | AX2: =AR47 -> 12 | AY2: 总经验 | AZ2: =SUM(AX4:AZ29)+7000 -> 24080 | BB2: 粮草系数
A3: 日期 | B3: 获得粮草 | C3: 粮草调整 | D3: 消耗粮草 | E3: 剩余粮草 | F3: 获得经验 | G3: 累计经验 | H3: 任务经验 | I3: 1 | J3: 2 | K3: 3 | L3: 4 | M3: 5 | N3: 6 | O3: 7 | P3: 8 | Q3: 1 | R3: 2 | S3: 3 | T3: 4 | U3: 5 | V3: 6 | W3: 7 | X3: 8 | Y3: 1 | Z3: 2 | AA3: 3 | AB3: 4 | AC3: 5 | AD3: 6 | AE3: 7 | AF3: 8 | AG3: 跳步次数 | AH3: 1队跳步 | AI3: 2队跳步 | AJ3: 3队跳步 | AL3: 1队剩步 | AM3: 2队剩步 | AN3: 3队剩步 | AO3: 地块 | AP3: 粮草 | AQ3: 经验 | AR3: 八卦前亏损 | AS3: 一队地块 | AT3: 二队地块 | AU3: 三队地块 | AV3: 总地块 | AX3: 一队经验 | AY3: 二队经验 | AZ3: 三队经验 | BA3: 八卦前 | BB3: 1
A4: 45821 | B4: 800 | C4: 6000 | D4: =(SUM(粮草!A4:X4)+AG4*10*IF(AK4="是",$BB$4,$BB$3)) -> 1700 | E4: =SUM($B$4:B4)+SUM($C$4:C4)-SUM($D$4:D4) -> 5100 | F4: =SUM(经验!A4:X4) -> 420 | G4: =SUM($F$4:F4)+SUM($H$4:H4) -> 920 | H4: 500 | I4: 1级 | J4: 1级 | K4: 1级 | L4: 1级 | M4: 1级 | N4: 商人 | O4: 空 | P4: 空 | Q4: 1级 | R4: 1级 | S4: 1级 | T4: 塔2 | U4: 1级 | V4: 1级 | W4: 空 | X4: 空 | Y4: 空 | Z4: 空 | AA4: 空 | AB4: 空 | AC4: 空 | AD4: 空 | AE4: 空 | AF4: 空 | AG4: =AH4+AI4+AJ4 -> 0 | AK4: 否 | AL4: =6-COUNTIF(I4:P4,"<>空") -> 0 | AM4: =6-COUNTIF(Q4:X4,"<>空") -> 0 | AN4: =6-COUNTIF(Y4:AF4,"<>空") -> 6 | AO4: 1级 | AP4: 150 | AQ4: 35 | AR4: 44.222109 | AS4: =COUNTIF($I$4:$P$93,AO4) -> 11 | AT4: =COUNTIF($Q$4:$X$93,AO4) -> 7 | AU4: =COUNTIF($Y$4:$AF$93,AO4) -> 0 | AV4: =AS4+AT4+AU4 -> 18 | AW4: 30 | AX4: =AS4*$AQ4 -> 385 | AY4: =AT4*$AQ4 -> 245 | AZ4: =AU4*$AQ4 -> 0 | BA4: 八卦后 | BB4: 0.8 | BD4: =AP4*0.8 -> 120
A5: 45822 | B5: 1600 | D5: =(SUM(粮草!A5:X5)+AG5*10*IF(AK5="是",$BB$4,$BB$3)) -> 1620 | E5: =SUM($B$4:B5)+SUM($C$4:C5)-SUM($D$4:D5) -> 5080 | F5: =SUM(经验!A5:X5) -> 500 | G5: =SUM($F$4:F5)+SUM($H$4:H5) -> 1420 | H5: 0 | I5: 空 | J5: 空 | K5: 空 | L5: 空 | M5: 空 | N5: 空 | O5: 空 | P5: 空 | Q5: 商人 | R5: 1级 | S5: 1级 | T5: 2级 | U5: 2级 | V5: 商人 | W5: 空 | X5: 空 | Y5: 2级 | Z5: 2级 | AA5: 塔2 | AB5: 2级 | AC5: 营地 | AD5: 2级 | AE5: 塔3 | AF5: 3级 | AG5: =AH5+AI5+AJ5 -> 4 | AJ5: 4 | AK5: 否 | AL5: =MIN(AL4+6,18)-COUNTIF(I5:P5,"<>空")+COUNTIF(I5:P5,"历练")+COUNTIF(I5:P5,"营地")*2 -> 6 | AM5: =MIN(AM4+6,18)-COUNTIF(Q5:X5,"<>空")+COUNTIF(Q5:X5,"历练")+COUNTIF(Q5:X5,"营地")*2 -> 0 | AN5: =MIN(AN4+6,18)-COUNTIF(Y5:AF5,"<>空")+COUNTIF(Y5:AF5,"历练")+COUNTIF(Y5:AF5,"营地")*2 -> 6 | AO5: 2级 | AP5: 160 | AQ5: 40 | AR5: 39.110982 | AS5: =COUNTIF($I$4:$P$93,AO5) -> 7 | AT5: =COUNTIF($Q$4:$X$93,AO5) -> 25 | AU5: =COUNTIF($Y$4:$AF$93,AO5) -> 7 | AV5: =AS5+AT5+AU5 -> 39 | AW5: 54 | AX5: =AS5*$AQ5 -> 280 | AY5: =AT5*$AQ5 -> 1000 | AZ5: =AU5*$AQ5 -> 280 | BA5: Note：开完八卦当天可能需要手动计算粮草 | BD5: =AP5*0.8 -> 128
A6: 45823 | B6: 1600 | D6: =(SUM(粮草!A6:X6)+AG6*10*IF(AK6="是",$BB$4,$BB$3)) -> 2200 | E6: =SUM($B$4:B6)+SUM($C$4:C6)-SUM($D$4:D6) -> 4480 | F6: =SUM(经验!A6:X6) -> 590 | G6: =SUM($F$4:F6)+SUM($H$4:H6) -> 2010 | H6: 0 | I6: 空 | J6: 空 | K6: 空 | L6: 空 | M6: 空 | N6: 空 | O6: 空 | P6: 空 | Q6: 2级 | R6: 2级 | S6: 2级 | T6: 2级 | U6: 2级 | V6: 商人 | W6: 空 | X6: 空 | Y6: 塔2 | Z6: 3级 | AA6: 4级 | AB6: 3级 | AC6: 3级 | AD6: 3级 | AE6: 3级 | AF6: 3级卦 | AG6: =AH6+AI6+AJ6 -> 0 | AK6: 否 | AL6: =MIN(AL5+6,18)-COUNTIF(I6:P6,"<>空")+COUNTIF(I6:P6,"历练")+COUNTIF(I6:P6,"营地")*2 -> 12 | AM6: =MIN(AM5+6,18)-COUNTIF(Q6:X6,"<>空")+COUNTIF(Q6:X6,"历练")+COUNTIF(Q6:X6,"营地")*2 -> 0 | AN6: =MIN(AN5+6,18)-COUNTIF(Y6:AF6,"<>空")+COUNTIF(Y6:AF6,"历练")+COUNTIF(Y6:AF6,"营地")*2 -> 4 | AO6: 3级 | AP6: 170 | AQ6: 45 | AR6: 34 | AS6: =COUNTIF($I$4:$P$93,AO6) -> 0 | AT6: =COUNTIF($Q$4:$X$93,AO6) -> 14 | AU6: =COUNTIF($Y$4:$AF$93,AO6) -> 49 | AV6: =AS6+AT6+AU6 -> 63 | AW6: 180 | AX6: =AS6*$AQ6 -> 0 | AY6: =AT6*$AQ6 -> 630 | AZ6: =AU6*$AQ6 -> 2205 | BD6: =AP6*0.8 -> 136
A7: 45824 | B7: 1600 | D7: =(SUM(粮草!A7:X7)+AG7*10*IF(AK7="是",$BB$4,$BB$3)) -> 2350 | E7: =SUM($B$4:B7)+SUM($C$4:C7)-SUM($D$4:D7) -> 3730 | F7: =SUM(经验!A7:X7) -> 620 | G7: =SUM($F$4:F7)+SUM($H$4:H7) -> 2830 | H7: 200 | I7: 空 | J7: 空 | K7: 空 | L7: 空 | M7: 空 | N7: 空 | O7: 空 | P7: 空 | Q7: 2级 | R7: 2级 | S7: 3级卦 | T7: 3级 | U7: 3级 | V7: 塔2 | W7: 空 | X7: 空 | Y7: 3级 | Z7: 3级 | AA7: 3级 | AB7: 3级 | AC7: 3级 | AD7: 塔2 | AE7: 4级 | AF7: 4级 | AG7: =AH7+AI7+AJ7 -> 1 | AJ7: 1 | AK7: 否 | AL7: =MIN(AL6+6,18)-COUNTIF(I7:P7,"<>空")+COUNTIF(I7:P7,"历练")+COUNTIF(I7:P7,"营地")*2 -> 18 | AM7: =MIN(AM6+6,18)-COUNTIF(Q7:X7,"<>空")+COUNTIF(Q7:X7,"历练")+COUNTIF(Q7:X7,"营地")*2 -> 0 | AN7: =MIN(AN6+6,18)-COUNTIF(Y7:AF7,"<>空")+COUNTIF(Y7:AF7,"历练")+COUNTIF(Y7:AF7,"营地")*2 -> 2 | AO7: 4级 | AP7: 180 | AQ7: 50 | AR7: 36 | AS7: =COUNTIF($I$4:$P$93,AO7) -> 10 | AT7: =COUNTIF($Q$4:$X$93,AO7) -> 11 | AU7: =COUNTIF($Y$4:$AF$93,AO7) -> 30 | AV7: =AS7+AT7+AU7 -> 51 | AW7: 104 | AX7: =AS7*$AQ7 -> 500 | AY7: =AT7*$AQ7 -> 550 | AZ7: =AU7*$AQ7 -> 1500 | BD7: =AP7*0.8 -> 144
A8: 45825 | B8: 1600 | D8: =(SUM(粮草!A8:X8)+AG8*10*IF(AK8="是",$BB$4,$BB$3)) -> 2260 | E8: =SUM($B$4:B8)+SUM($C$4:C8)-SUM($D$4:D8) -> 3070 | F8: =SUM(经验!A8:X8) -> 880 | G8: =SUM($F$4:F8)+SUM($H$4:H8) -> 4010 | H8: 300 | I8: 空 | J8: 空 | K8: 空 | L8: 空 | M8: 空 | N8: 空 | O8: 空 | P8: 空 | Q8: 3级 | R8: 商人 | S8: 3级 | T8: 3级 | U8: 3级 | V8: 商人 | W8: 空 | X8: 空 | Y8: 大卦 | Z8: 塔2 | AA8: 4级 | AB8: 4级 | AC8: 4级 | AD8: 4级 | AE8: 4级 | AF8: 4级 | AG8: =AH8+AI8+AJ8 -> 0 | AK8: 否 | AL8: =MIN(AL7+6,18)-COUNTIF(I8:P8,"<>空")+COUNTIF(I8:P8,"历练")+COUNTIF(I8:P8,"营地")*2 -> 18 | AM8: =MIN(AM7+6,18)-COUNTIF(Q8:X8,"<>空")+COUNTIF(Q8:X8,"历练")+COUNTIF(Q8:X8,"营地")*2 -> 0 | AN8: =MIN(AN7+6,18)-COUNTIF(Y8:AF8,"<>空")+COUNTIF(Y8:AF8,"历练")+COUNTIF(Y8:AF8,"营地")*2 -> 0 | AO8: 5级 | AP8: 190 | AQ8: 55 | AR8: 38 | AS8: =COUNTIF($I$4:$P$93,AO8) -> 41 | AT8: =COUNTIF($Q$4:$X$93,AO8) -> 7 | AU8: =COUNTIF($Y$4:$AF$93,AO8) -> 3 | AV8: =AS8+AT8+AU8 -> 51 | AW8: 31 | AX8: =AS8*$AQ8 -> 2255 | AY8: =AT8*$AQ8 -> 385 | AZ8: =AU8*$AQ8 -> 165 | BD8: =AP8*0.8 -> 152
A9: 45826 | B9: 1600 | D9: =(SUM(粮草!A9:X9)+AG9*10*IF(AK9="是",$BB$4,$BB$3)) -> 1520 | E9: =SUM($B$4:B9)+SUM($C$4:C9)-SUM($D$4:D9) -> 3150 | F9: =SUM(经验!A9:X9) -> 660 | G9: =SUM($F$4:F9)+SUM($H$4:H9) -> 4670 | H9: 0 | I9: 空 | J9: 空 | K9: 空 | L9: 空 | M9: 空 | N9: 空 | O9: 空 | P9: 空 | Q9: 3级 | R9: 3级 | S9: 3级卦 | T9: 空 | U9: 空 | V9: 空 | W9: 空 | X9: 空 | Y9: 4级 | Z9: 4级 | AA9: 4级 | AB9: 大卦 | AC9: 3级 | AD9: 商人 | AE9: 空 | AF9: 空 | AG9: =AH9+AI9+AJ9 -> 0 | AK9: 否 | AL9: =MIN(AL8+6,18)-COUNTIF(I9:P9,"<>空")+COUNTIF(I9:P9,"历练")+COUNTIF(I9:P9,"营地")*2 -> 18 | AM9: =MIN(AM8+6,18)-COUNTIF(Q9:X9,"<>空")+COUNTIF(Q9:X9,"历练")+COUNTIF(Q9:X9,"营地")*2 -> 3 | AN9: =MIN(AN8+6,18)-COUNTIF(Y9:AF9,"<>空")+COUNTIF(Y9:AF9,"历练")+COUNTIF(Y9:AF9,"营地")*2 -> 0 | AO9: 6级 | AP9: 200 | AQ9: 60 | AS9: =COUNTIF($I$4:$P$93,AO9) -> 8 | AT9: =COUNTIF($Q$4:$X$93,AO9) -> 19 | AU9: =COUNTIF($Y$4:$AF$93,AO9) -> 6 | AV9: =AS9+AT9+AU9 -> 33 | AW9: 98 | AX9: =AS9*$AQ9 -> 480 | AY9: =AT9*$AQ9 -> 1140 | AZ9: =AU9*$AQ9 -> 360 | BD9: =AP9*0.8 -> 160
A10: 45827 | B10: 1600 | D10: =(SUM(粮草!A10:X10)+AG10*10*IF(AK10="是",$BB$4,$BB$3)) -> 1000 | E10: =SUM($B$4:B10)+SUM($C$4:C10)-SUM($D$4:D10) -> 3750 | F10: =SUM(经验!A10:X10) -> 265 | G10: =SUM($F$4:F10)+SUM($H$4:H10) -> 4935 | H10: 0 | I10: 空 | J10: 空 | K10: 空 | L10: 空 | M10: 空 | N10: 空 | O10: 空 | P10: 空 | Q10: 空 | R10: 空 | S10: 空 | T10: 空 | U10: 空 | V10: 空 | W10: 空 | X10: 空 | Y10: 3级 | Z10: 3级 | AA10: 3级 | AB10: 塔2 | AC10: 3级 | AD10: 3级 | AE10: 空 | AF10: 空 | AG10: =AH10+AI10+AJ10 -> 0 | AK10: 否 | AL10: =MIN(AL9+6,18)-COUNTIF(I10:P10,"<>空")+COUNTIF(I10:P10,"历练")+COUNTIF(I10:P10,"营地")*2 -> 18 | AM10: =MIN(AM9+6,18)-COUNTIF(Q10:X10,"<>空")+COUNTIF(Q10:X10,"历练")+COUNTIF(Q10:X10,"营地")*2 -> 9 | AN10: =MIN(AN9+6,18)-COUNTIF(Y10:AF10,"<>空")+COUNTIF(Y10:AF10,"历练")+COUNTIF(Y10:AF10,"营地")*2 -> 0 | AO10: 塔1 | AP10: 150 | AQ10: 35 | AR10: 44.222109 | AS10: =COUNTIF($I$4:$P$93,AO10) -> 0 | AT10: =COUNTIF($Q$4:$X$93,AO10) -> 0 | AU10: =COUNTIF($Y$4:$AF$93,AO10) -> 0 | AV10: =AS10+AT10+AU10 -> 0 | AW10: 0 | AX10: =AS10*$AQ10 -> 0 | AY10: =AT10*$AQ10 -> 0 | AZ10: =AU10*$AQ10 -> 0 | BD10: =AP10*0.8 -> 120
A11: 45828 | B11: 1600 | D11: =(SUM(粮草!A11:X11)+AG11*10*IF(AK11="是",$BB$4,$BB$3)) -> 1180 | E11: =SUM($B$4:B11)+SUM($C$4:C11)-SUM($D$4:D11) -> 4170 | F11: =SUM(经验!A11:X11) -> 565 | G11: =SUM($F$4:F11)+SUM($H$4:H11) -> 5500 | H11: 0 | I11: 空 | J11: 空 | K11: 空 | L11: 空 | M11: 空 | N11: 空 | O11: 空 | P11: 空 | Q11: 6级 | R11: 空 | S11: 空 | T11: 空 | U11: 空 | V11: 空 | W11: 空 | X11: 空 | Y11: 3级 | Z11: 3级 | AA11: 塔2 | AB11: 大卦 | AC11: 商人 | AD11: 3级 | AE11: 空 | AF11: 空 | AG11: =AH11+AI11+AJ11 -> 2 | AJ11: 2 | AK11: 否 | AL11: =MIN(AL10+6,18)-COUNTIF(I11:P11,"<>空")+COUNTIF(I11:P11,"历练")+COUNTIF(I11:P11,"营地")*2 -> 18 | AM11: =MIN(AM10+6,18)-COUNTIF(Q11:X11,"<>空")+COUNTIF(Q11:X11,"历练")+COUNTIF(Q11:X11,"营地")*2 -> 14 | AN11: =MIN(AN10+6,18)-COUNTIF(Y11:AF11,"<>空")+COUNTIF(Y11:AF11,"历练")+COUNTIF(Y11:AF11,"营地")*2 -> 0 | AO11: 塔2 | AP11: 150 | AQ11: 40 | AR11: 29.110982 | AS11: =COUNTIF($I$4:$P$93,AO11) -> 3 | AT11: =COUNTIF($Q$4:$X$93,AO11) -> 6 | AU11: =COUNTIF($Y$4:$AF$93,AO11) -> 11 | AV11: =AS11+AT11+AU11 -> 20 | AW11: 2 | AX11: =AS11*$AQ11 -> 120 | AY11: =AT11*$AQ11 -> 240 | AZ11: =AU11*$AQ11 -> 440 | BD11: =AP11*0.8 -> 120
A12: 45829 | B12: 1600 | C12: 360 | D12: =(SUM(粮草!A12:X12)+AG12*10*IF(AK12="是",$BB$4,$BB$3)) -> 2460 | E12: =SUM($B$4:B12)+SUM($C$4:C12)-SUM($D$4:D12) -> 3670 | F12: =SUM(经验!A12:X12) -> 735 | G12: =SUM($F$4:F12)+SUM($H$4:H12) -> 6235 | H12: 0 | I12: 空 | J12: 空 | K12: 空 | L12: 空 | M12: 空 | N12: 空 | O12: 空 | P12: 空 | Q12: 6级 | R12: 6级 | S12: 6级 | T12: 6级 | U12: 6级 | V12: 6级 | W12: 6级 | X12: 6级 | Y12: 3级 | Z12: 塔2 | AA12: 3级卦 | AB12: 商人 | AC12: 塔4 | AD12: 3级 | AE12: 空 | AF12: 空 | AG12: =AH12+AI12+AJ12 -> 0 | AK12: 否 | AL12: =MIN(AL11+6,18)-COUNTIF(I12:P12,"<>空")+COUNTIF(I12:P12,"历练")+COUNTIF(I12:P12,"营地")*2 -> 18 | AM12: =MIN(AM11+6,18)-COUNTIF(Q12:X12,"<>空")+COUNTIF(Q12:X12,"历练")+COUNTIF(Q12:X12,"营地")*2 -> 10 | AN12: =MIN(AN11+6,18)-COUNTIF(Y12:AF12,"<>空")+COUNTIF(Y12:AF12,"历练")+COUNTIF(Y12:AF12,"营地")*2 -> 0 | AO12: 塔3 | AP12: 150 | AQ12: 45 | AR12: 13.999855 | AS12: =COUNTIF($I$4:$P$93,AO12) -> 0 | AT12: =COUNTIF($Q$4:$X$93,AO12) -> 0 | AU12: =COUNTIF($Y$4:$AF$93,AO12) -> 1 | AV12: =AS12+AT12+AU12 -> 1 | AW12: 5 | AX12: =AS12*$AQ12 -> 0 | AY12: =AT12*$AQ12 -> 0 | AZ12: =AU12*$AQ12 -> 45 | BD12: =AP12*0.8 -> 120
A13: 45830 | B13: 1600 | C13: -200 | D13: =(SUM(粮草!A13:X13)+AG13*10*IF(AK13="是",$BB$4,$BB$3)) -> 2492 | E13: =SUM($B$4:B13)+SUM($C$4:C13)-SUM($D$4:D13) -> 2578 | F13: =SUM(经验!A13:X13) -> 935 | G13: =SUM($F$4:F13)+SUM($H$4:H13) -> 7170 | H13: 0 | I13: 1级 | J13: 塔2 | K13: 1级 | L13: 商人 | M13: 1级 | N13: 1级 | O13: 塔2 | P13: 1级 | Q13: 营地 | R13: 6级 | S13: 6级 | T13: 6级 | U13: 6级 | V13: 3级 | W13: 3级 | X13: 3级 | Y13: 3级 | Z13: 3级 | AA13: 3级 | AB13: 塔4 | AC13: 3级 | AD13: 3级卦 | AE13: 空 | AF13: 空 | AG13: =AH13+AI13+AJ13 -> 3 | AI13: 3 | AK13: 是 | AL13: =MIN(AL12+6,18)-COUNTIF(I13:P13,"<>空")+COUNTIF(I13:P13,"历练")+COUNTIF(I13:P13,"营地")*2 -> 10 | AM13: =MIN(AM12+6,18)-COUNTIF(Q13:X13,"<>空")+COUNTIF(Q13:X13,"历练")+COUNTIF(Q13:X13,"营地")*2 -> 10 | AN13: =MIN(AN12+6,18)-COUNTIF(Y13:AF13,"<>空")+COUNTIF(Y13:AF13,"历练")+COUNTIF(Y13:AF13,"营地")*2 -> 0 | AO13: 塔4 | AP13: 150 | AQ13: 50 | AS13: =COUNTIF($I$4:$P$93,AO13) -> 0 | AT13: =COUNTIF($Q$4:$X$93,AO13) -> 0 | AU13: =COUNTIF($Y$4:$AF$93,AO13) -> 2 | AV13: =AS13+AT13+AU13 -> 2 | AW13: 1 | AX13: =AS13*$AQ13 -> 0 | AY13: =AT13*$AQ13 -> 0 | AZ13: =AU13*$AQ13 -> 100 | BD13: =AP13*0.8 -> 120
A14: 45831 | B14: 1600 | C14: 40 | D14: =(SUM(粮草!A14:X14)+AG14*10*IF(AK14="是",$BB$4,$BB$3)) -> 2072 | E14: =SUM($B$4:B14)+SUM($C$4:C14)-SUM($D$4:D14) -> 2146 | F14: =SUM(经验!A14:X14) -> 905 | G14: =SUM($F$4:F14)+SUM($H$4:H14) -> 8375 | H14: 300 | I14: 1级 | J14: 2级 | K14: 2级 | L14: 商人 | M14: 2级 | N14: 2级 | O14: 营地 | P14: 4级 | Q14: 3级 | R14: 3级 | S14: 3级 | T14: 营地 | U14: 6级 | V14: 6级 | W14: 6级 | X14: 6级 | Y14: 3级 | Z14: 5级 | AA14: 5级 | AB14: 5级 | AC14: 3级 | AD14: 空 | AE14: 空 | AF14: 空 | AG14: =AH14+AI14+AJ14 -> 0 | AK14: 是 | AL14: =MIN(AL13+6,18)-COUNTIF(I14:P14,"<>空")+COUNTIF(I14:P14,"历练")+COUNTIF(I14:P14,"营地")*2 -> 10 | AM14: =MIN(AM13+6,18)-COUNTIF(Q14:X14,"<>空")+COUNTIF(Q14:X14,"历练")+COUNTIF(Q14:X14,"营地")*2 -> 10 | AN14: =MIN(AN13+6,18)-COUNTIF(Y14:AF14,"<>空")+COUNTIF(Y14:AF14,"历练")+COUNTIF(Y14:AF14,"营地")*2 -> 1 | AO14: 塔5 | AP14: 150 | AQ14: 55 | AS14: =COUNTIF($I$4:$P$93,AO14) -> 0 | AT14: =COUNTIF($Q$4:$X$93,AO14) -> 0 | AU14: =COUNTIF($Y$4:$AF$93,AO14) -> 0 | AV14: =AS14+AT14+AU14 -> 0 | AW14: 0 | AX14: =AS14*$AQ14 -> 0 | AY14: =AT14*$AQ14 -> 0 | AZ14: =AU14*$AQ14 -> 0 | BD14: =AP14*0.8 -> 120
A15: 45832 | B15: 1600 | D15: =(SUM(粮草!A15:X15)+AG15*10*IF(AK15="是",$BB$4,$BB$3)) -> 2536 | E15: =SUM($B$4:B15)+SUM($C$4:C15)-SUM($D$4:D15) -> 1210 | F15: =SUM(经验!A15:X15) -> 1075 | G15: =SUM($F$4:F15)+SUM($H$4:H15) -> 9450 | H15: 0 | I15: 4级 | J15: 4级 | K15: 商人 | L15: 4级 | M15: 4级 | N15: 4级 | O15: 4级 | P15: 4级 | Q15: 4级 | R15: 5级 | S15: 5级 | T15: 5级 | U15: 营地 | V15: 5级 | W15: 5级 | X15: 5级 | Y15: 3级 | Z15: 营地 | AA15: 3级 | AB15: 3级 | AC15: 3级 | AD15: 3级 | AE15: 3级 | AF15: 3级 | AG15: =AH15+AI15+AJ15 -> 0 | AK15: 是 | AL15: =MIN(AL14+6,18)-COUNTIF(I15:P15,"<>空")+COUNTIF(I15:P15,"历练")+COUNTIF(I15:P15,"营地")*2 -> 8 | AM15: =MIN(AM14+6,18)-COUNTIF(Q15:X15,"<>空")+COUNTIF(Q15:X15,"历练")+COUNTIF(Q15:X15,"营地")*2 -> 10 | AN15: =MIN(AN14+6,18)-COUNTIF(Y15:AF15,"<>空")+COUNTIF(Y15:AF15,"历练")+COUNTIF(Y15:AF15,"营地")*2 -> 1 | AO15: 塔6 | AP15: 150 | AQ15: 60 | AS15: =COUNTIF($I$4:$P$93,AO15) -> 0 | AT15: =COUNTIF($Q$4:$X$93,AO15) -> 0 | AU15: =COUNTIF($Y$4:$AF$93,AO15) -> 0 | AV15: =AS15+AT15+AU15 -> 0 | AW15: 0 | AX15: =AS15*$AQ15 -> 0 | AY15: =AT15*$AQ15 -> 0 | AZ15: =AU15*$AQ15 -> 0 | BD15: =AP15*0.8 -> 120
A16: 45833 | B16: 1600 | C16: 40 | D16: =(SUM(粮草!A16:X16)+AG16*10*IF(AK16="是",$BB$4,$BB$3)) -> 2608 | E16: =SUM($B$4:B16)+SUM($C$4:C16)-SUM($D$4:D16) -> 242 | F16: =SUM(经验!A16:X16) -> 2040 | G16: =SUM($F$4:F16)+SUM($H$4:H16) -> 11690 | H16: 200 | I16: 营地 | J16: 4级 | K16: 4级 | L16: 6级 | M16: 6级 | N16: 6级 | O16: 大boss | P16: 5级 | Q16: 5级 | R16: 4级 | S16: 6级 | T16: 6级 | U16: 4级 | V16: 4级 | W16: 4级 | X16: 商人 | Y16: 塔2 | Z16: 2级 | AA16: 2级 | AB16: 3级 | AC16: 3级 | AD16: 3级 | AE16: 3级 | AF16: 营地 | AG16: =AH16+AI16+AJ16 -> 0 | AK16: 是 | AL16: =MIN(AL15+6,18)-COUNTIF(I16:P16,"<>空")+COUNTIF(I16:P16,"历练")+COUNTIF(I16:P16,"营地")*2 -> 8 | AM16: =MIN(AM15+6,18)-COUNTIF(Q16:X16,"<>空")+COUNTIF(Q16:X16,"历练")+COUNTIF(Q16:X16,"营地")*2 -> 8 | AN16: =MIN(AN15+6,18)-COUNTIF(Y16:AF16,"<>空")+COUNTIF(Y16:AF16,"历练")+COUNTIF(Y16:AF16,"营地")*2 -> 1 | AO16: 遗迹 | AP16: 150 | AQ16: 40 | AR16: 29.110982 | AS16: =COUNTIF($I$4:$P$93,AO16) -> 0 | AT16: =COUNTIF($Q$4:$X$93,AO16) -> 0 | AU16: =COUNTIF($Y$4:$AF$93,AO16) -> 0 | AV16: =AS16+AT16+AU16 -> 0 | AW16: 0 | AX16: =AS16*$AQ16 -> 0 | AY16: =AT16*$AQ16 -> 0 | AZ16: =AU16*$AQ16 -> 0 | BD16: =AP16*0.8 -> 120
A17: 45834 | B17: 1600 | D17: =(SUM(粮草!A17:X17)+AG17*10*IF(AK17="是",$BB$4,$BB$3)) -> 1528 | E17: =SUM($B$4:B17)+SUM($C$4:C17)-SUM($D$4:D17) -> 314 | F17: =SUM(经验!A17:X17) -> 725 | G17: =SUM($F$4:F17)+SUM($H$4:H17) -> 12415 | H17: 0 | I17: 5级 | J17: 5级 | K17: 5级 | L17: 5级 | M17: 5级 | N17: 5级 | O17: 5级 | P17: 营地 | Q17: 4级 | R17: 4级 | S17: 4级 | T17: 4级 | U17: 塔2 | V17: 4级 | W17: 4级 | X17: 营地 | Y17: 空 | Z17: 空 | AA17: 空 | AB17: 空 | AC17: 空 | AD17: 空 | AE17: 空 | AF17: 空 | AG17: =AH17+AI17+AJ17 -> 0 | AK17: 是 | AL17: =MIN(AL16+6,18)-COUNTIF(I17:P17,"<>空")+COUNTIF(I17:P17,"历练")+COUNTIF(I17:P17,"营地")*2 -> 8 | AM17: =MIN(AM16+6,18)-COUNTIF(Q17:X17,"<>空")+COUNTIF(Q17:X17,"历练")+COUNTIF(Q17:X17,"营地")*2 -> 8 | AN17: =MIN(AN16+6,18)-COUNTIF(Y17:AF17,"<>空")+COUNTIF(Y17:AF17,"历练")+COUNTIF(Y17:AF17,"营地")*2 -> 7 | AO17: 商人 | AP17: 50 | AQ17: 30 | AR17: 10 | AS17: =COUNTIF($I$4:$P$93,AO17) -> 5 | AT17: =COUNTIF($Q$4:$X$93,AO17) -> 13 | AU17: =COUNTIF($Y$4:$AF$93,AO17) -> 3 | AV17: =AS17+AT17+AU17 -> 21 | AW17: 34 | AX17: =AS17*$AQ17 -> 150 | AY17: =AT17*$AQ17 -> 390 | AZ17: =AU17*$AQ17 -> 90 | BD17: =AP17*0.8 -> 40
A18: 45835 | B18: 1600 | D18: =(SUM(粮草!A18:X18)+AG18*10*IF(AK18="是",$BB$4,$BB$3)) -> 920 | E18: =SUM($B$4:B18)+SUM($C$4:C18)-SUM($D$4:D18) -> 994 | F18: =SUM(经验!A18:X18) -> 330 | G18: =SUM($F$4:F18)+SUM($H$4:H18) -> 12745 | H18: 0 | I18: 5级 | J18: 5级 | K18: 5级 | L18: 5级 | M18: 5级 | N18: 5级 | O18: 空 | P18: 空 | Q18: 空 | R18: 空 | S18: 空 | T18: 空 | U18: 空 | V18: 空 | W18: 空 | X18: 空 | Y18: 空 | Z18: 空 | AA18: 空 | AB18: 空 | AC18: 空 | AD18: 空 | AE18: 空 | AF18: 空 | AG18: =AH18+AI18+AJ18 -> 1 | AH18: 1 | AK18: 是 | AL18: =MIN(AL17+6,18)-COUNTIF(I18:P18,"<>空")+COUNTIF(I18:P18,"历练")+COUNTIF(I18:P18,"营地")*2 -> 8 | AM18: =MIN(AM17+6,18)-COUNTIF(Q18:X18,"<>空")+COUNTIF(Q18:X18,"历练")+COUNTIF(Q18:X18,"营地")*2 -> 14 | AN18: =MIN(AN17+6,18)-COUNTIF(Y18:AF18,"<>空")+COUNTIF(Y18:AF18,"历练")+COUNTIF(Y18:AF18,"营地")*2 -> 13 | AO18: 营地 | AP18: -150 | AQ18: 0 | AR18: 10 | AS18: =COUNTIF($I$4:$P$93,AO18) -> 5 | AT18: =COUNTIF($Q$4:$X$93,AO18) -> 4 | AU18: =COUNTIF($Y$4:$AF$93,AO18) -> 6 | AV18: =AS18+AT18+AU18 -> 15 | AW18: 15 | AX18: =AS18*$AQ18 -> 0 | AY18: =AT18*$AQ18 -> 0 | AZ18: =AU18*$AQ18 -> 0 | BD18: =AP18*0.8 -> -120
A19: 45836 | B19: 1600 | D19: =(SUM(粮草!A19:X19)+AG19*10*IF(AK19="是",$BB$4,$BB$3)) -> 1872 | E19: =SUM($B$4:B19)+SUM($C$4:C19)-SUM($D$4:D19) -> 722 | F19: =SUM(经验!A19:X19) -> 650 | G19: =SUM($F$4:F19)+SUM($H$4:H19) -> 13395 | H19: 0 | I19: 5级 | J19: 5级 | K19: 5级 | L19: 5级 | M19: 5级 | N19: 5级 | O19: 空 | P19: 空 | Q19: 空 | R19: 空 | S19: 空 | T19: 空 | U19: 空 | V19: 空 | W19: 空 | X19: 空 | Y19: 3级 | Z19: 4级 | AA19: 3级 | AB19: 3级 | AC19: 3级 | AD19: 3级 | AE19: 3级 | AF19: 空 | AG19: =AH19+AI19+AJ19 -> 0 | AK19: 是 | AL19: =MIN(AL18+6,18)-COUNTIF(I19:P19,"<>空")+COUNTIF(I19:P19,"历练")+COUNTIF(I19:P19,"营地")*2 -> 8 | AM19: =MIN(AM18+6,18)-COUNTIF(Q19:X19,"<>空")+COUNTIF(Q19:X19,"历练")+COUNTIF(Q19:X19,"营地")*2 -> 18 | AN19: =MIN(AN18+6,18)-COUNTIF(Y19:AF19,"<>空")+COUNTIF(Y19:AF19,"历练")+COUNTIF(Y19:AF19,"营地")*2 -> 11 | AO19: 大卦 | AP19: 250 | AQ19: 300 | AS19: =COUNTIF($I$4:$P$93,AO19) -> 0 | AT19: =COUNTIF($Q$4:$X$93,AO19) -> 0 | AU19: =COUNTIF($Y$4:$AF$93,AO19) -> 3 | AV19: =AS19+AT19+AU19 -> 3 | AW19: 3 | AX19: =AS19*$AQ19 -> 0 | AY19: =AT19*$AQ19 -> 0 | AZ19: =AU19*$AQ19 -> 900 | BD19: =AP19*0.8 -> 200
A20: 45837 | B20: 1600 | D20: =(SUM(粮草!A20:X20)+AG20*10*IF(AK20="是",$BB$4,$BB$3)) -> 1702 | E20: =SUM($B$4:B20)+SUM($C$4:C20)-SUM($D$4:D20) -> 620 | F20: =SUM(经验!A20:X20) -> 660 | G20: =SUM($F$4:F20)+SUM($H$4:H20) -> 14055 | H20: 0 | I20: 5级 | J20: 5级 | K20: 5级 | L20: 5级 | M20: 5级 | N20: 5级 | O20: 空 | P20: 空 | Q20: 空 | R20: 空 | S20: 空 | T20: 空 | U20: 空 | V20: 空 | W20: 空 | X20: 空 | Y20: 3级 | Z20: 3级 | AA20: 3级 | AB20: 3级 | AC20: 营地 | AD20: 4级 | AE20: 4级 | AF20: 4级 | AG20: =AH20+AI20+AJ20 -> 3 | AJ20: 3 | AK20: 是 | AL20: =MIN(AL19+6,18)-COUNTIF(I20:P20,"<>空")+COUNTIF(I20:P20,"历练")+COUNTIF(I20:P20,"营地")*2 -> 8 | AM20: =MIN(AM19+6,18)-COUNTIF(Q20:X20,"<>空")+COUNTIF(Q20:X20,"历练")+COUNTIF(Q20:X20,"营地")*2 -> 18 | AN20: =MIN(AN19+6,18)-COUNTIF(Y20:AF20,"<>空")+COUNTIF(Y20:AF20,"历练")+COUNTIF(Y20:AF20,"营地")*2 -> 11 | AO20: 3级卦 | AP20: 170 | AQ20: 45 | AS20: =COUNTIF($I$4:$P$93,AO20) -> 0 | AT20: =COUNTIF($Q$4:$X$93,AO20) -> 2 | AU20: =COUNTIF($Y$4:$AF$93,AO20) -> 3 | AV20: =AS20+AT20+AU20 -> 5 | AW20: 5 | AX20: =AS20*$AQ20 -> 0 | AY20: =AT20*$AQ20 -> 90 | AZ20: =AU20*$AQ20 -> 135 | BD20: =AP20*0.8 -> 136
A21: 45838 | B21: 1600 | D21: =(SUM(粮草!A21:X21)+AG21*10*IF(AK21="是",$BB$4,$BB$3)) -> 1414 | E21: =SUM($B$4:B21)+SUM($C$4:C21)-SUM($D$4:D21) -> 806 | F21: =SUM(经验!A21:X21) -> 565 | G21: =SUM($F$4:F21)+SUM($H$4:H21) -> 14820 | H21: 200 | I21: 5级 | J21: 营地 | K21: 5级 | L21: 5级 | M21: 5级 | N21: 5级 | O21: 空 | P21: 空 | Q21: 空 | R21: 空 | S21: 空 | T21: 空 | U21: 空 | V21: 空 | W21: 空 | X21: 空 | Y21: 4级 | Z21: 4级 | AA21: 4级 | AB21: 4级 | AC21: 4级 | AD21: 塔2 | AE21: 空 | AF21: 空 | AG21: =AH21+AI21+AJ21 -> 3 | AH21: 3 | AK21: 是 | AL21: =MIN(AL20+6,18)-COUNTIF(I21:P21,"<>空")+COUNTIF(I21:P21,"历练")+COUNTIF(I21:P21,"营地")*2 -> 10 | AM21: =MIN(AM20+6,18)-COUNTIF(Q21:X21,"<>空")+COUNTIF(Q21:X21,"历练")+COUNTIF(Q21:X21,"营地")*2 -> 18 | AN21: =MIN(AN20+6,18)-COUNTIF(Y21:AF21,"<>空")+COUNTIF(Y21:AF21,"历练")+COUNTIF(Y21:AF21,"营地")*2 -> 11 | AO21: 巨卦 | AP21: 250 | AQ21: 400 | AS21: =COUNTIF($I$4:$P$93,AO21) -> 0 | AT21: =COUNTIF($Q$4:$X$93,AO21) -> 0 | AU21: =COUNTIF($Y$4:$AF$93,AO21) -> 0 | AV21: =AS21+AT21+AU21 -> 0 | AW21: 0 | AX21: =AS21*$AQ21 -> 0 | AY21: =AT21*$AQ21 -> 0 | AZ21: =AU21*$AQ21 -> 0 | BD21: =AP21*0.8 -> 200
A22: 45839 | B22: 1600 | D22: =(SUM(粮草!A22:X22)+AG22*10*IF(AK22="是",$BB$4,$BB$3)) -> 1422 | E22: =SUM($B$4:B22)+SUM($C$4:C22)-SUM($D$4:D22) -> 984 | F22: =SUM(经验!A22:X22) -> 580 | G22: =SUM($F$4:F22)+SUM($H$4:H22) -> 15500 | H22: 100 | I22: 5级 | J22: 5级 | K22: 5级 | L22: 5级 | M22: 5级 | N22: 5级 | O22: 空 | P22: 空 | Q22: 空 | R22: 空 | S22: 空 | T22: 空 | U22: 空 | V22: 空 | W22: 空 | X22: 空 | Y22: 4级 | Z22: 4级 | AA22: 4级 | AB22: 营地 | AC22: 4级 | AD22: 4级 | AE22: 空 | AF22: 空 | AG22: =AH22+AI22+AJ22 -> 0 | AK22: 是 | AL22: =MIN(AL21+6,18)-COUNTIF(I22:P22,"<>空")+COUNTIF(I22:P22,"历练")+COUNTIF(I22:P22,"营地")*2 -> 10 | AM22: =MIN(AM21+6,18)-COUNTIF(Q22:X22,"<>空")+COUNTIF(Q22:X22,"历练")+COUNTIF(Q22:X22,"营地")*2 -> 18 | AN22: =MIN(AN21+6,18)-COUNTIF(Y22:AF22,"<>空")+COUNTIF(Y22:AF22,"历练")+COUNTIF(Y22:AF22,"营地")*2 -> 13 | AO22: 大boss | AP22: 250 | AQ22: 1000 | AS22: =COUNTIF($I$4:$P$93,AO22) -> 1 | AT22: =COUNTIF($Q$4:$X$93,AO22) -> 0 | AU22: =COUNTIF($Y$4:$AF$93,AO22) -> 0 | AV22: =AS22+AT22+AU22 -> 1 | AW22: 1 | AX22: =AS22*$AQ22 -> 1000 | AY22: =AT22*$AQ22 -> 0 | AZ22: =AU22*$AQ22 -> 0 | BD22: =AP22*0.8 -> 200
A23: 45840 | B23: 1600 | D23: =(SUM(粮草!A23:X23)+AG23*10*IF(AK23="是",$BB$4,$BB$3)) -> 1864 | E23: =SUM($B$4:B23)+SUM($C$4:C23)-SUM($D$4:D23) -> 720 | F23: =SUM(经验!A23:X23) -> 1100 | G23: =SUM($F$4:F23)+SUM($H$4:H23) -> 16800 | H23: 200 | I23: 5级 | J23: 5级 | K23: 5级 | L23: 5级 | M23: 中boss | N23: 6级 | O23: 空 | P23: 空 | Q23: 空 | R23: 空 | S23: 空 | T23: 空 | U23: 空 | V23: 空 | W23: 空 | X23: 空 | Y23: 4级 | Z23: 4级 | AA23: 4级 | AB23: 4级 | AC23: 6级 | AD23: 6级 | AE23: 空 | AF23: 空 | AG23: =AH23+AI23+AJ23 -> 0 | AK23: 是 | AL23: =MIN(AL22+6,18)-COUNTIF(I23:P23,"<>空")+COUNTIF(I23:P23,"历练")+COUNTIF(I23:P23,"营地")*2 -> 10 | AM23: =MIN(AM22+6,18)-COUNTIF(Q23:X23,"<>空")+COUNTIF(Q23:X23,"历练")+COUNTIF(Q23:X23,"营地")*2 -> 18 | AN23: =MIN(AN22+6,18)-COUNTIF(Y23:AF23,"<>空")+COUNTIF(Y23:AF23,"历练")+COUNTIF(Y23:AF23,"营地")*2 -> 12 | AO23: 中boss | AP23: 250 | AQ23: 500 | AS23: =COUNTIF($I$4:$P$93,AO23) -> 1 | AT23: =COUNTIF($Q$4:$X$93,AO23) -> 0 | AU23: =COUNTIF($Y$4:$AF$93,AO23) -> 0 | AV23: =AS23+AT23+AU23 -> 1 | AW23: 0 | AX23: =AS23*$AQ23 -> 500 | AY23: =AT23*$AQ23 -> 0 | AZ23: =AU23*$AQ23 -> 0 | BD23: =AP23*0.8 -> 200
A24: 45841 | B24: 1600 | D24: =(SUM(粮草!A24:X24)+AG24*10*IF(AK24="是",$BB$4,$BB$3)) -> 860 | E24: =SUM($B$4:B24)+SUM($C$4:C24)-SUM($D$4:D24) -> 1460 | F24: =SUM(经验!A24:X24) -> 480 | G24: =SUM($F$4:F24)+SUM($H$4:H24) -> 17280 | H24: 0 | I24: 6级 | J24: 6级 | K24: 6级 | L24: 6级 | M24: 营地 | N24: 空 | O24: 空 | P24: 空 | Q24: 空 | R24: 空 | S24: 空 | T24: 空 | U24: 空 | V24: 空 | W24: 空 | X24: 空 | Y24: 6级 | Z24: 6级 | AA24: 6级 | AB24: 6级 | AC24: 营地 | AD24: 空 | AE24: 空 | AF24: 空 | AG24: =AH24+AI24+AJ24 -> 0 | AK24: 是 | AL24: =MIN(AL23+6,18)-COUNTIF(I24:P24,"<>空")+COUNTIF(I24:P24,"历练")+COUNTIF(I24:P24,"营地")*2 -> 13 | AM24: =MIN(AM23+6,18)-COUNTIF(Q24:X24,"<>空")+COUNTIF(Q24:X24,"历练")+COUNTIF(Q24:X24,"营地")*2 -> 18 | AN24: =MIN(AN23+6,18)-COUNTIF(Y24:AF24,"<>空")+COUNTIF(Y24:AF24,"历练")+COUNTIF(Y24:AF24,"营地")*2 -> 15 | AO24: 4级卦 | AP24: 180 | AQ24: 50 | AR24: 39.110982 | AS24: =COUNTIF($I$4:$P$93,AO24) -> 0 | AT24: =COUNTIF($Q$4:$X$93,AO24) -> 0 | AU24: =COUNTIF($Y$4:$AF$93,AO24) -> 0 | AV24: =AS24+AT24+AU24 -> 0 | AW24: 0 | AX24: =AS24*$AQ24 -> 0 | AY24: =AT24*$AQ24 -> 0 | AZ24: =AU24*$AQ24 -> 0 | BD24: =AP24*0.8 -> 144
A25: 45842 | B25: 1600 | D25: =(SUM(粮草!A25:X25)+AG25*10*IF(AK25="是",$BB$4,$BB$3)) -> 0 | E25: =SUM($B$4:B25)+SUM($C$4:C25)-SUM($D$4:D25) -> 3060 | F25: =SUM(经验!A25:X25) -> 0 | G25: =SUM($F$4:F25)+SUM($H$4:H25) -> 17280 | H25: 0 | I25: 空 | J25: 空 | K25: 空 | L25: 空 | M25: 空 | N25: 空 | O25: 空 | P25: 空 | Q25: 空 | R25: 空 | S25: 空 | T25: 空 | U25: 空 | V25: 空 | W25: 空 | X25: 空 | Y25: 空 | Z25: 空 | AA25: 空 | AB25: 空 | AC25: 空 | AD25: 空 | AE25: 空 | AF25: 空 | AG25: =AH25+AI25+AJ25 -> 0 | AK25: 是 | AL25: =MIN(AL24+6,18)-COUNTIF(I25:P25,"<>空")+COUNTIF(I25:P25,"历练")+COUNTIF(I25:P25,"营地")*2 -> 18 | AM25: =MIN(AM24+6,18)-COUNTIF(Q25:X25,"<>空")+COUNTIF(Q25:X25,"历练")+COUNTIF(Q25:X25,"营地")*2 -> 18 | AN25: =MIN(AN24+6,18)-COUNTIF(Y25:AF25,"<>空")+COUNTIF(Y25:AF25,"历练")+COUNTIF(Y25:AF25,"营地")*2 -> 18 | AO25: 山中 | AP25: 160 | AQ25: 40 | AR25: 39.110982 | AS25: =COUNTIF($I$4:$P$93,AO25) -> 0 | AT25: =COUNTIF($Q$4:$X$93,AO25) -> 0 | AU25: =COUNTIF($Y$4:$AF$93,AO25) -> 0 | AV25: =AS25+AT25+AU25 -> 0 | AW25: 0 | AX25: =AS25*$AQ25 -> 0 | AY25: =AT25*$AQ25 -> 0 | AZ25: =AU25*$AQ25 -> 0 | BD25: =AP25*0.8 -> 128
A26: 45843 | B26: 1600 | D26: =(SUM(粮草!A26:X26)+AG26*10*IF(AK26="是",$BB$4,$BB$3)) -> 240 | E26: =SUM($B$4:B26)+SUM($C$4:C26)-SUM($D$4:D26) -> 4420 | F26: =SUM(经验!A26:X26) -> 80 | G26: =SUM($F$4:F26)+SUM($H$4:H26) -> 17360 | H26: 0 | I26: 空 | J26: 空 | K26: 空 | L26: 空 | M26: 空 | N26: 空 | O26: 空 | P26: 空 | Q26: 塔2 | R26: 空 | S26: 空 | T26: 空 | U26: 空 | V26: 空 | W26: 空 | X26: 空 | Y26: 塔2 | Z26: 空 | AA26: 空 | AB26: 空 | AC26: 空 | AD26: 空 | AE26: 空 | AF26: 空 | AG26: =AH26+AI26+AJ26 -> 0 | AK26: 是 | AL26: =MIN(AL25+6,18)-COUNTIF(I26:P26,"<>空")+COUNTIF(I26:P26,"历练")+COUNTIF(I26:P26,"营地")*2 -> 18 | AM26: =MIN(AM25+6,18)-COUNTIF(Q26:X26,"<>空")+COUNTIF(Q26:X26,"历练")+COUNTIF(Q26:X26,"营地")*2 -> 17 | AN26: =MIN(AN25+6,18)-COUNTIF(Y26:AF26,"<>空")+COUNTIF(Y26:AF26,"历练")+COUNTIF(Y26:AF26,"营地")*2 -> 17 | AO26: 秋道 | AP26: 150 | AQ26: 35 | AR26: 44.222109 | AS26: =COUNTIF($I$4:$P$93,AO26) -> 0 | AT26: =COUNTIF($Q$4:$X$93,AO26) -> 0 | AU26: =COUNTIF($Y$4:$AF$93,AO26) -> 0 | AV26: =AS26+AT26+AU26 -> 0 | AW26: 0 | AX26: =AS26*$AQ26 -> 0 | AY26: =AT26*$AQ26 -> 0 | AZ26: =AU26*$AQ26 -> 0 | BD26: =AP26*0.8 -> 120
A27: 45844 | B27: 1600 | D27: =(SUM(粮草!A27:X27)+AG27*10*IF(AK27="是",$BB$4,$BB$3)) -> 1472 | E27: =SUM($B$4:B27)+SUM($C$4:C27)-SUM($D$4:D27) -> 4548 | F27: =SUM(经验!A27:X27) -> 480 | G27: =SUM($F$4:F27)+SUM($H$4:H27) -> 17840 | H27: 0 | I27: 空 | J27: 2级 | K27: 商人 | L27: 2级 | M27: 2级 | N27: 空 | O27: 空 | P27: 空 | Q27: 商人 | R27: 2级 | S27: 塔2 | T27: 2级 | U27: 商人 | V27: 2级 | W27: 空 | X27: 商人 | Y27: 2级 | Z27: 塔2 | AA27: 空 | AB27: 空 | AC27: 空 | AD27: 空 | AE27: 空 | AF27: 空 | AG27: =AH27+AI27+AJ27 -> 22 | AH27: 8 | AI27: 6 | AJ27: 8 | AK27: 是 | AL27: =MIN(AL26+6,18)-COUNTIF(I27:P27,"<>空")+COUNTIF(I27:P27,"历练")+COUNTIF(I27:P27,"营地")*2 -> 14 | AM27: =MIN(AM26+6,18)-COUNTIF(Q27:X27,"<>空")+COUNTIF(Q27:X27,"历练")+COUNTIF(Q27:X27,"营地")*2 -> 11 | AN27: =MIN(AN26+6,18)-COUNTIF(Y27:AF27,"<>空")+COUNTIF(Y27:AF27,"历练")+COUNTIF(Y27:AF27,"营地")*2 -> 16 | AO27: 空 | AP27: 0 | AQ27: 0 | AR27: 0 | AX27: =AS27*$AQ27 -> 0 | AY27: =AT27*$AQ27 -> 0 | AZ27: =AU27*$AQ27 -> 0 | BD27: =AP27*0.8 -> 0
A28: 45845 | B28: 1600 | C28: 40 | D28: =(SUM(粮草!A28:X28)+AG28*10*IF(AK28="是",$BB$4,$BB$3)) -> 808 | E28: =SUM($B$4:B28)+SUM($C$4:C28)-SUM($D$4:D28) -> 5380 | F28: =SUM(经验!A28:X28) -> 270 | G28: =SUM($F$4:F28)+SUM($H$4:H28) -> 18310 | H28: 200 | I28: 塔2 | J28: 空 | K28: 空 | L28: 空 | M28: 空 | N28: 空 | O28: 空 | P28: 空 | Q28: 塔2 | R28: 2级 | S28: 2级 | T28: 商人 | U28: 2级 | V28: 2级 | W28: 空 | X28: 空 | Y28: 空 | Z28: 空 | AA28: 空 | AB28: 空 | AC28: 空 | AD28: 空 | AE28: 空 | AF28: 空 | AG28: =AH28+AI28+AJ28 -> 2 | AI28: 2 | AK28: 是 | AL28: =MIN(AL27+6,18)-COUNTIF(I28:P28,"<>空")+COUNTIF(I28:P28,"历练")+COUNTIF(I28:P28,"营地")*2 -> 17 | AM28: =MIN(AM27+6,18)-COUNTIF(Q28:X28,"<>空")+COUNTIF(Q28:X28,"历练")+COUNTIF(Q28:X28,"营地")*2 -> 11 | AN28: =MIN(AN27+6,18)-COUNTIF(Y28:AF28,"<>空")+COUNTIF(Y28:AF28,"历练")+COUNTIF(Y28:AF28,"营地")*2 -> 18 | AO28: 作废 | AP28: 0 | AQ28: 0 | AS28: =COUNTIF($I$4:$P$93,AO28) -> 0 | AT28: =COUNTIF($Q$4:$X$93,AO28) -> 0 | AU28: =COUNTIF($Y$4:$AF$93,AO28) -> 0 | AV28: =AS28+AT28+AU28 -> 0 | AW28: 0 | AX28: =AS28*$AQ28 -> 0 | AY28: =AT28*$AQ28 -> 0 | AZ28: =AU28*$AQ28 -> 0 | BD28: =AP28*0.8 -> 0
A29: 45846 | B29: 1600 | D29: =(SUM(粮草!A29:X29)+AG29*10*IF(AK29="是",$BB$4,$BB$3)) -> 592 | E29: =SUM($B$4:B29)+SUM($C$4:C29)-SUM($D$4:D29) -> 6388 | F29: =SUM(经验!A29:X29) -> 710 | G29: =SUM($F$4:F29)+SUM($H$4:H29) -> 19120 | H29: 100 | I29: 空 | J29: 空 | K29: 空 | L29: 空 | M29: 空 | N29: 空 | O29: 空 | P29: 空 | Q29: 2级 | R29: 商人 | S29: 2级 | T29: 2级 | U29: 历练 | V29: 2级 | W29: 空 | X29: 空 | Y29: 空 | Z29: 空 | AA29: 空 | AB29: 空 | AC29: 空 | AD29: 空 | AE29: 空 | AF29: 空 | AG29: =AH29+AI29+AJ29 -> 0 | AK29: 是 | AL29: =MIN(AL28+6,18)-COUNTIF(I29:P29,"<>空")+COUNTIF(I29:P29,"历练")+COUNTIF(I29:P29,"营地")*2 -> 18 | AM29: =MIN(AM28+6,18)-COUNTIF(Q29:X29,"<>空")+COUNTIF(Q29:X29,"历练")+COUNTIF(Q29:X29,"营地")*2 -> 12 | AN29: =MIN(AN28+6,18)-COUNTIF(Y29:AF29,"<>空")+COUNTIF(Y29:AF29,"历练")+COUNTIF(Y29:AF29,"营地")*2 -> 18 | AO29: 历练 | AP29: 50 | AQ29: 520 | AS29: =COUNTIF($I$4:$P$93,AO29) -> 0 | AT29: =COUNTIF($Q$4:$X$93,AO29) -> 1 | AU29: =COUNTIF($Y$4:$AF$93,AO29) -> 0 | AV29: =AS29+AT29+AU29 -> 1 | AW29: 1 | AX29: =AS29*$AQ29 -> 0 | AY29: =AT29*$AQ29 -> 520 | AZ29: =AU29*$AQ29 -> 0 | BD29: =AP29*0.8 -> 40
A30: 45847 | B30: 1600 | D30: =(SUM(粮草!A30:X30)+AG30*10*IF(AK30="是",$BB$4,$BB$3)) -> 720 | E30: =SUM($B$4:B30)+SUM($C$4:C30)-SUM($D$4:D30) -> 7268 | F30: =SUM(经验!A30:X30) -> 260 | G30: =SUM($F$4:F30)+SUM($H$4:H30) -> 19580 | H30: 200 | I30: 空 | J30: 空 | K30: 空 | L30: 空 | M30: 空 | N30: 空 | O30: 空 | P30: 空 | Q30: 2级 | R30: 商人 | S30: 2级 | T30: 2级 | U30: 2级 | V30: 2级 | W30: 商人 | X30: 空 | Y30: 空 | Z30: 空 | AA30: 空 | AB30: 空 | AC30: 空 | AD30: 空 | AE30: 空 | AF30: 空 | AG30: =AH30+AI30+AJ30 -> 0 | AK30: 是 | AL30: =MIN(AL29+6,18)-COUNTIF(I30:P30,"<>空")+COUNTIF(I30:P30,"历练")+COUNTIF(I30:P30,"营地")*2 -> 18 | AM30: =MIN(AM29+6,18)-COUNTIF(Q30:X30,"<>空")+COUNTIF(Q30:X30,"历练")+COUNTIF(Q30:X30,"营地")*2 -> 11 | AN30: =MIN(AN29+6,18)-COUNTIF(Y30:AF30,"<>空")+COUNTIF(Y30:AF30,"历练")+COUNTIF(Y30:AF30,"营地")*2 -> 18
A31: 45848 | B31: 1600 | D31: =(SUM(粮草!A31:X31)+AG31*10*IF(AK31="是",$BB$4,$BB$3)) -> 0 | E31: =SUM($B$4:B31)+SUM($C$4:C31)-SUM($D$4:D31) -> 8868 | F31: =SUM(经验!A31:X31) -> 0 | G31: =SUM($F$4:F31)+SUM($H$4:H31) -> 19580 | H31: 0 | I31: 空 | J31: 空 | K31: 空 | L31: 空 | M31: 空 | N31: 空 | O31: 空 | P31: 空 | Q31: 空 | R31: 空 | S31: 空 | T31: 空 | U31: 空 | V31: 空 | W31: 空 | X31: 空 | Y31: 空 | Z31: 空 | AA31: 空 | AB31: 空 | AC31: 空 | AD31: 空 | AE31: 空 | AF31: 空 | AG31: =AH31+AI31+AJ31 -> 0 | AK31: 是 | AL31: =MIN(AL30+6,18)-COUNTIF(I31:P31,"<>空")+COUNTIF(I31:P31,"历练")+COUNTIF(I31:P31,"营地")*2 -> 18 | AM31: =MIN(AM30+6,18)-COUNTIF(Q31:X31,"<>空")+COUNTIF(Q31:X31,"历练")+COUNTIF(Q31:X31,"营地")*2 -> 17 | AN31: =MIN(AN30+6,18)-COUNTIF(Y31:AF31,"<>空")+COUNTIF(Y31:AF31,"历练")+COUNTIF(Y31:AF31,"营地")*2 -> 18
A32: 45849 | B32: 1600 | D32: =(SUM(粮草!A32:X32)+AG32*10*IF(AK32="是",$BB$4,$BB$3)) -> 0 | E32: =SUM($B$4:B32)+SUM($C$4:C32)-SUM($D$4:D32) -> 10468 | F32: =SUM(经验!A32:X32) -> 0 | G32: =SUM($F$4:F32)+SUM($H$4:H32) -> 19580 | H32: 0 | I32: 空 | J32: 空 | K32: 空 | L32: 空 | M32: 空 | N32: 空 | O32: 空 | P32: 空 | Q32: 空 | R32: 空 | S32: 空 | T32: 空 | U32: 空 | V32: 空 | W32: 空 | X32: 空 | Y32: 空 | Z32: 空 | AA32: 空 | AB32: 空 | AC32: 空 | AD32: 空 | AE32: 空 | AF32: 空 | AG32: =AH32+AI32+AJ32 -> 0 | AK32: 是 | AL32: =MIN(AL31+6,18)-COUNTIF(I32:P32,"<>空")+COUNTIF(I32:P32,"历练")+COUNTIF(I32:P32,"营地")*2 -> 18 | AM32: =MIN(AM31+6,18)-COUNTIF(Q32:X32,"<>空")+COUNTIF(Q32:X32,"历练")+COUNTIF(Q32:X32,"营地")*2 -> 18 | AN32: =MIN(AN31+6,18)-COUNTIF(Y32:AF32,"<>空")+COUNTIF(Y32:AF32,"历练")+COUNTIF(Y32:AF32,"营地")*2 -> 18 | AO32: 地块统计 | AP32: 应占领 | AQ32: 缺少 | AR32: 粮草 | AS32: 分数
A33: 45850 | B33: 1600 | D33: =(SUM(粮草!A33:X33)+AG33*10*IF(AK33="是",$BB$4,$BB$3)) -> 0 | E33: =SUM($B$4:B33)+SUM($C$4:C33)-SUM($D$4:D33) -> 12068 | F33: =SUM(经验!A33:X33) -> 0 | G33: =SUM($F$4:F33)+SUM($H$4:H33) -> 19580 | H33: 0 | I33: 空 | J33: 空 | K33: 空 | L33: 空 | M33: 空 | N33: 空 | O33: 空 | P33: 空 | Q33: 空 | R33: 空 | S33: 空 | T33: 空 | U33: 空 | V33: 空 | W33: 空 | X33: 空 | Y33: 空 | Z33: 空 | AA33: 空 | AB33: 空 | AC33: 空 | AD33: 空 | AE33: 空 | AF33: 空 | AG33: =AH33+AI33+AJ33 -> 0 | AK33: 是 | AL33: =MIN(AL32+6,18)-COUNTIF(I33:P33,"<>空")+COUNTIF(I33:P33,"历练")+COUNTIF(I33:P33,"营地")*2 -> 18 | AM33: =MIN(AM32+6,18)-COUNTIF(Q33:X33,"<>空")+COUNTIF(Q33:X33,"历练")+COUNTIF(Q33:X33,"营地")*2 -> 18 | AN33: =MIN(AN32+6,18)-COUNTIF(Y33:AF33,"<>空")+COUNTIF(Y33:AF33,"历练")+COUNTIF(Y33:AF33,"营地")*2 -> 18 | AO33: 3级 | AP33: 211 | AQ33: =AP33-AV6 -> 148 | AR33: =AQ33*AP6*0.8 -> 20128 | AS33: =AQ33*AQ6 -> 6660
A34: 45851 | B34: 1600 | D34: =(SUM(粮草!A34:X34)+AG34*10*IF(AK34="是",$BB$4,$BB$3)) -> 0 | E34: =SUM($B$4:B34)+SUM($C$4:C34)-SUM($D$4:D34) -> 13668 | F34: =SUM(经验!A34:X34) -> 0 | G34: =SUM($F$4:F34)+SUM($H$4:H34) -> 19580 | H34: 0 | I34: 空 | J34: 空 | K34: 空 | L34: 空 | M34: 空 | N34: 空 | O34: 空 | P34: 空 | Q34: 空 | R34: 空 | S34: 空 | T34: 空 | U34: 空 | V34: 空 | W34: 空 | X34: 空 | Y34: 空 | Z34: 空 | AA34: 空 | AB34: 空 | AC34: 空 | AD34: 空 | AE34: 空 | AF34: 空 | AG34: =AH34+AI34+AJ34 -> 0 | AK34: 是 | AL34: =MIN(AL33+6,18)-COUNTIF(I34:P34,"<>空")+COUNTIF(I34:P34,"历练")+COUNTIF(I34:P34,"营地")*2 -> 18 | AM34: =MIN(AM33+6,18)-COUNTIF(Q34:X34,"<>空")+COUNTIF(Q34:X34,"历练")+COUNTIF(Q34:X34,"营地")*2 -> 18 | AN34: =MIN(AN33+6,18)-COUNTIF(Y34:AF34,"<>空")+COUNTIF(Y34:AF34,"历练")+COUNTIF(Y34:AF34,"营地")*2 -> 18 | AO34: 4级 | AP34: 274 | AQ34: =AP34-AV7 -> 223 | AR34: =AQ34*AP7*0.8 -> 32112 | AS34: =AQ34*AQ7 -> 11150
A35: 45852 | B35: 1600 | D35: =(SUM(粮草!A35:X35)+AG35*10*IF(AK35="是",$BB$4,$BB$3)) -> 0 | E35: =SUM($B$4:B35)+SUM($C$4:C35)-SUM($D$4:D35) -> 15268 | F35: =SUM(经验!A35:X35) -> 0 | G35: =SUM($F$4:F35)+SUM($H$4:H35) -> 19780 | H35: 200 | I35: 空 | J35: 空 | K35: 空 | L35: 空 | M35: 空 | N35: 空 | O35: 空 | P35: 空 | Q35: 空 | R35: 空 | S35: 空 | T35: 空 | U35: 空 | V35: 空 | W35: 空 | X35: 空 | Y35: 空 | Z35: 空 | AA35: 空 | AB35: 空 | AC35: 空 | AD35: 空 | AE35: 空 | AF35: 空 | AG35: =AH35+AI35+AJ35 -> 0 | AK35: 是 | AL35: =MIN(AL34+6,18)-COUNTIF(I35:P35,"<>空")+COUNTIF(I35:P35,"历练")+COUNTIF(I35:P35,"营地")*2 -> 18 | AM35: =MIN(AM34+6,18)-COUNTIF(Q35:X35,"<>空")+COUNTIF(Q35:X35,"历练")+COUNTIF(Q35:X35,"营地")*2 -> 18 | AN35: =MIN(AN34+6,18)-COUNTIF(Y35:AF35,"<>空")+COUNTIF(Y35:AF35,"历练")+COUNTIF(Y35:AF35,"营地")*2 -> 18 | AO35: 5级 | AP35: 234 | AQ35: =AP35-AV8 -> 183 | AR35: =AQ35*AP8*0.8 -> 27816 | AS35: =AQ35*AQ8 -> 10065
A36: 45853 | B36: 1600 | D36: =(SUM(粮草!A36:X36)+AG36*10*IF(AK36="是",$BB$4,$BB$3)) -> 0 | E36: =SUM($B$4:B36)+SUM($C$4:C36)-SUM($D$4:D36) -> 16868 | F36: =SUM(经验!A36:X36) -> 0 | G36: =SUM($F$4:F36)+SUM($H$4:H36) -> 19880 | H36: 100 | I36: 空 | J36: 空 | K36: 空 | L36: 空 | M36: 空 | N36: 空 | O36: 空 | P36: 空 | Q36: 空 | R36: 空 | S36: 空 | T36: 空 | U36: 空 | V36: 空 | W36: 空 | X36: 空 | Y36: 空 | Z36: 空 | AA36: 空 | AB36: 空 | AC36: 空 | AD36: 空 | AE36: 空 | AF36: 空 | AG36: =AH36+AI36+AJ36 -> 0 | AK36: 是 | AL36: =MIN(AL35+6,18)-COUNTIF(I36:P36,"<>空")+COUNTIF(I36:P36,"历练")+COUNTIF(I36:P36,"营地")*2 -> 18 | AM36: =MIN(AM35+6,18)-COUNTIF(Q36:X36,"<>空")+COUNTIF(Q36:X36,"历练")+COUNTIF(Q36:X36,"营地")*2 -> 18 | AN36: =MIN(AN35+6,18)-COUNTIF(Y36:AF36,"<>空")+COUNTIF(Y36:AF36,"历练")+COUNTIF(Y36:AF36,"营地")*2 -> 18 | AO36: 6级 | AP36: 193 | AQ36: =AP36-AV9 -> 160 | AR36: =AQ36*AP9*0.8 -> 25600 | AS36: =AQ36*AQ9 -> 9600
A37: 45854 | B37: 1600 | D37: =(SUM(粮草!A37:X37)+AG37*10*IF(AK37="是",$BB$4,$BB$3)) -> 0 | E37: =SUM($B$4:B37)+SUM($C$4:C37)-SUM($D$4:D37) -> 18468 | F37: =SUM(经验!A37:X37) -> 0 | G37: =SUM($F$4:F37)+SUM($H$4:H37) -> 20080 | H37: 200 | I37: 空 | J37: 空 | K37: 空 | L37: 空 | M37: 空 | N37: 空 | O37: 空 | P37: 空 | Q37: 空 | R37: 空 | S37: 空 | T37: 空 | U37: 空 | V37: 空 | W37: 空 | X37: 空 | Y37: 空 | Z37: 空 | AA37: 空 | AB37: 空 | AC37: 空 | AD37: 空 | AE37: 空 | AF37: 空 | AG37: =AH37+AI37+AJ37 -> 0 | AK37: 是 | AL37: =MIN(AL36+6,18)-COUNTIF(I37:P37,"<>空")+COUNTIF(I37:P37,"历练")+COUNTIF(I37:P37,"营地")*2 -> 18 | AM37: =MIN(AM36+6,18)-COUNTIF(Q37:X37,"<>空")+COUNTIF(Q37:X37,"历练")+COUNTIF(Q37:X37,"营地")*2 -> 18 | AN37: =MIN(AN36+6,18)-COUNTIF(Y37:AF37,"<>空")+COUNTIF(Y37:AF37,"历练")+COUNTIF(Y37:AF37,"营地")*2 -> 18 | AO37: 商人 | AP37: 39 | AQ37: =AP37-AV17 -> 18 | AR37: =AQ37*AP17*0.8 -> 720 | AS37: =AQ37*AQ17 -> 540
A38: 45855 | B38: 1600 | D38: =(SUM(粮草!A38:X38)+AG38*10*IF(AK38="是",$BB$4,$BB$3)) -> 0 | E38: =SUM($B$4:B38)+SUM($C$4:C38)-SUM($D$4:D38) -> 20068 | F38: =SUM(经验!A38:X38) -> 0 | G38: =SUM($F$4:F38)+SUM($H$4:H38) -> 20080 | H38: 0 | I38: 空 | J38: 空 | K38: 空 | L38: 空 | M38: 空 | N38: 空 | O38: 空 | P38: 空 | Q38: 空 | R38: 空 | S38: 空 | T38: 空 | U38: 空 | V38: 空 | W38: 空 | X38: 空 | Y38: 空 | Z38: 空 | AA38: 空 | AB38: 空 | AC38: 空 | AD38: 空 | AE38: 空 | AF38: 空 | AG38: =AH38+AI38+AJ38 -> 0 | AK38: 是 | AL38: =MIN(AL37+6,18)-COUNTIF(I38:P38,"<>空")+COUNTIF(I38:P38,"历练")+COUNTIF(I38:P38,"营地")*2 -> 18 | AM38: =MIN(AM37+6,18)-COUNTIF(Q38:X38,"<>空")+COUNTIF(Q38:X38,"历练")+COUNTIF(Q38:X38,"营地")*2 -> 18 | AN38: =MIN(AN37+6,18)-COUNTIF(Y38:AF38,"<>空")+COUNTIF(Y38:AF38,"历练")+COUNTIF(Y38:AF38,"营地")*2 -> 18 | AO38: 塔2 | AP38: 20 | AQ38: =AP38-AV11 -> 0 | AR38: =AQ38*AP11*0.8 -> 0 | AS38: =AQ38*AQ11 -> 0
A39: 45856 | B39: 1600 | D39: =(SUM(粮草!A39:X39)+AG39*10*IF(AK39="是",$BB$4,$BB$3)) -> 0 | E39: =SUM($B$4:B39)+SUM($C$4:C39)-SUM($D$4:D39) -> 21668 | F39: =SUM(经验!A39:X39) -> 0 | G39: =SUM($F$4:F39)+SUM($H$4:H39) -> 20080 | H39: 0 | I39: 空 | J39: 空 | K39: 空 | L39: 空 | M39: 空 | N39: 空 | O39: 空 | P39: 空 | Q39: 空 | R39: 空 | S39: 空 | T39: 空 | U39: 空 | V39: 空 | W39: 空 | X39: 空 | Y39: 空 | Z39: 空 | AA39: 空 | AB39: 空 | AC39: 空 | AD39: 空 | AE39: 空 | AF39: 空 | AG39: =AH39+AI39+AJ39 -> 0 | AK39: 是 | AL39: =MIN(AL38+6,18)-COUNTIF(I39:P39,"<>空")+COUNTIF(I39:P39,"历练")+COUNTIF(I39:P39,"营地")*2 -> 18 | AM39: =MIN(AM38+6,18)-COUNTIF(Q39:X39,"<>空")+COUNTIF(Q39:X39,"历练")+COUNTIF(Q39:X39,"营地")*2 -> 18 | AN39: =MIN(AN38+6,18)-COUNTIF(Y39:AF39,"<>空")+COUNTIF(Y39:AF39,"历练")+COUNTIF(Y39:AF39,"营地")*2 -> 18 | AO39: 塔3 | AP39: 6 | AQ39: =AP39-AV12 -> 5 | AR39: =AQ39*AP12*0.8 -> 600 | AS39: =AQ39*AQ12 -> 225
A40: 45857 | B40: 1600 | D40: =(SUM(粮草!A40:X40)+AG40*10*IF(AK40="是",$BB$4,$BB$3)) -> 0 | E40: =SUM($B$4:B40)+SUM($C$4:C40)-SUM($D$4:D40) -> 23268 | F40: =SUM(经验!A40:X40) -> 0 | G40: =SUM($F$4:F40)+SUM($H$4:H40) -> 20080 | H40: 0 | I40: 空 | J40: 空 | K40: 空 | L40: 空 | M40: 空 | N40: 空 | O40: 空 | P40: 空 | Q40: 空 | R40: 空 | S40: 空 | T40: 空 | U40: 空 | V40: 空 | W40: 空 | X40: 空 | Y40: 空 | Z40: 空 | AA40: 空 | AB40: 空 | AC40: 空 | AD40: 空 | AE40: 空 | AF40: 空 | AG40: =AH40+AI40+AJ40 -> 0 | AK40: 是 | AL40: =MIN(AL39+6,18)-COUNTIF(I40:P40,"<>空")+COUNTIF(I40:P40,"历练")+COUNTIF(I40:P40,"营地")*2 -> 18 | AM40: =MIN(AM39+6,18)-COUNTIF(Q40:X40,"<>空")+COUNTIF(Q40:X40,"历练")+COUNTIF(Q40:X40,"营地")*2 -> 18 | AN40: =MIN(AN39+6,18)-COUNTIF(Y40:AF40,"<>空")+COUNTIF(Y40:AF40,"历练")+COUNTIF(Y40:AF40,"营地")*2 -> 18 | AO40: 塔4 | AP40: 3 | AQ40: =AP40-AV13 -> 1 | AR40: =AQ40*AP13*0.8 -> 120 | AS40: =AQ40*AQ13 -> 50
...

Sheet 粮草
A2: 队伍一 风 | C2: 步数 | D2: =COUNTIF(A4:H94,"<>空") -> 728 | E2: (不算跳步和传送) | I2: 队伍二 雷 | K2: 步数 | L2: =COUNTIF(I4:P94,"<>空") -> 728 | M2: (不算跳步和传送) | Q2: 队伍三 | S2: 总步数 | T2: =COUNTIF(Q4:X94,"<>空") -> 728 | U2: (不算跳步和传送) | Y2: 粮草调整
A3: 1 | B3: 2 | C3: 3 | D3: 4 | E3: 5 | F3: 6 | G3: 7 | H3: 8 | I3: 1 | J3: 2 | K3: 3 | L3: 4 | M3: 5 | N3: 6 | O3: 7 | P3: 8 | Q3: 1 | R3: 2 | S3: 3 | T3: 4 | U3: 5 | V3: 6 | W3: 7 | X3: 8
A4: =IF(ISNUMBER(SEARCH("营",'20.03'!I4)),(-$Y4+50*IF('20.03'!$AK4="是",'20.03'!$BB$4,'20.03'!$BB$3)),(VLOOKUP('20.03'!I4,'20.03'!$AO$4:$AQ$55,2,FALSE))*IF('20.03'!$AK4="是",'20.03'!$BB$4,'20.03'!$BB$3)) -> 150 | B4: =IF(ISNUMBER(SEARCH("营",'20.03'!J4)),(-$Y4+50*IF('20.03'!$AK4="是",'20.03'!$BB$4,'20.03'!$BB$3)),(VLOOKUP('20.03'!J4,'20.03'!$AO$4:$AQ$55,2,FALSE))*IF('20.03'!$AK4="是",'20.03'!$BB$4,'20.03'!$BB$3)) -> 150 | C4: =IF(ISNUMBER(SEARCH("营",'20.03'!K4)),(-$Y4+50*IF('20.03'!$AK4="是",'20.03'!$BB$4,'20.03'!$BB$3)),(VLOOKUP('20.03'!K4,'20.03'!$AO$4:$AQ$55,2,FALSE))*IF('20.03'!$AK4="是",'20.03'!$BB$4,'20.03'!$BB$3)) -> 150 | D4: =IF(ISNUMBER(SEARCH("营",'20.03'!L4)),(-$Y4+50*IF('20.03'!$AK4="是",'20.03'!$BB$4,'20.03'!$BB$3)),(VLOOKUP('20.03'!L4,'20.03'!$AO$4:$AQ$55,2,FALSE))*IF('20.03'!$AK4="是",'20.03'!$BB$4,'20.03'!$BB$3)) -> 150 | E4: =IF(ISNUMBER(SEARCH("营",'20.03'!M4)),(-$Y4+50*IF('20.03'!$AK4="是",'20.03'!$BB$4,'20.03'!$BB$3)),(VLOOKUP('20.03'!M4,'20.03'!$AO$4:$AQ$55,2,FALSE))*IF('20.03'!$AK4="是",'20.03'!$BB$4,'20.03'!$BB$3)) -> 150 | F4: =IF(ISNUMBER(SEARCH("营",'20.03'!N4)),(-$Y4+50*IF('20.03'!$AK4="是",'20.03'!$BB$4,'20.03'!$BB$3)),(VLOOKUP('20.03'!N4,'20.03'!$AO$4:$AQ$55,2,FALSE))*IF('20.03'!$AK4="是",'20.03'!$BB$4,'20.03'!$BB$3)) -> 50 | G4: =IF(ISNUMBER(SEARCH("营",'20.03'!O4)),(-$Y4+50*IF('20.03'!$AK4="是",'20.03'!$BB$4,'20.03'!$BB$3)),(VLOOKUP('20.03'!O4,'20.03'!$AO$4:$AQ$55,2,FALSE))*IF('20.03'!$AK4="是",'20.03'!$BB$4,'20.03'!$BB$3)) -> 0 | H4: =IF(ISNUMBER(SEARCH("营",'20.03'!P4)),(-$Y4+50*IF('20.03'!$AK4="是",'20.03'!$BB$4,'20.03'!$BB$3)),(VLOOKUP('20.03'!P4,'20.03'!$AO$4:$AQ$55,2,FALSE))*IF('20.03'!$AK4="是",'20.03'!$BB$4,'20.03'!$BB$3)) -> 0 | ... X4: =IF(ISNUMBER(SEARCH("营",'20.03'!AF4)),(-$Y4+50*IF('20.03'!$AK4="是",'20.03'!$BB$4,'20.03'!$BB$3)),(VLOOKUP('20.03'!AF4,'20.03'!$AO$4:$AQ$55,2,FALSE))*IF('20.03'!$AK4="是",'20.03'!$BB$4,'20.03'!$BB$3)) -> 0 | Y4: 300 | Z4: 45821
A5: =IF(ISNUMBER(SEARCH("营",'20.03'!I5)),(-$Y5+50*IF('20.03'!$AK5="是",'20.03'!$BB$4,'20.03'!$BB$3)),(VLOOKUP('20.03'!I5,'20.03'!$AO$4:$AQ$55,2,FALSE))*IF('20.03'!$AK5="是",'20.03'!$BB$4,'20.03'!$BB$3)) -> 0 | B5: =IF(ISNUMBER(SEARCH("营",'20.03'!J5)),(-$Y5+50*IF('20.03'!$AK5="是",'20.03'!$BB$4,'20.03'!$BB$3)),(VLOOKUP('20.03'!J5,'20.03'!$AO$4:$AQ$55,2,FALSE))*IF('20.03'!$AK5="是",'20.03'!$BB$4,'20.03'!$BB$3)) -> 0 | C5: =IF(ISNUMBER(SEARCH("营",'20.03'!K5)),(-$Y5+50*IF('20.03'!$AK5="是",'20.03'!$BB$4,'20.03'!$BB$3)),(VLOOKUP('20.03'!K5,'20.03'!$AO$4:$AQ$55,2,FALSE))*IF('20.03'!$AK5="是",'20.03'!$BB$4,'20.03'!$BB$3)) -> 0 | D5: =IF(ISNUMBER(SEARCH("营",'20.03'!L5)),(-$Y5+50*IF('20.03'!$AK5="是",'20.03'!$BB$4,'20.03'!$BB$3)),(VLOOKUP('20.03'!L5,'20.03'!$AO$4:$AQ$55,2,FALSE))*IF('20.03'!$AK5="是",'20.03'!$BB$4,'20.03'!$BB$3)) -> 0 | E5: =IF(ISNUMBER(SEARCH("营",'20.03'!M5)),(-$Y5+50*IF('20.03'!$AK5="是",'20.03'!$BB$4,'20.03'!$BB$3)),(VLOOKUP('20.03'!M5,'20.03'!$AO$4:$AQ$55,2,FALSE))*IF('20.03'!$AK5="是",'20.03'!$BB$4,'20.03'!$BB$3)) -> 0 | F5: =IF(ISNUMBER(SEARCH("营",'20.03'!N5)),(-$Y5+50*IF('20.03'!$AK5="是",'20.03'!$BB$4,'20.03'!$BB$3)),(VLOOKUP('20.03'!N5,'20.03'!$AO$4:$AQ$55,2,FALSE))*IF('20.03'!$AK5="是",'20.03'!$BB$4,'20.03'!$BB$3)) -> 0 | G5: =IF(ISNUMBER(SEARCH("营",'20.03'!O5)),(-$Y5+50*IF('20.03'!$AK5="是",'20.03'!$BB$4,'20.03'!$BB$3)),(VLOOKUP('20.03'!O5,'20.03'!$AO$4:$AQ$55,2,FALSE))*IF('20.03'!$AK5="是",'20.03'!$BB$4,'20.03'!$BB$3)) -> 0 | H5: =IF(ISNUMBER(SEARCH("营",'20.03'!P5)),(-$Y5+50*IF('20.03'!$AK5="是",'20.03'!$BB$4,'20.03'!$BB$3)),(VLOOKUP('20.03'!P5,'20.03'!$AO$4:$AQ$55,2,FALSE))*IF('20.03'!$AK5="是",'20.03'!$BB$4,'20.03'!$BB$3)) -> 0 | ... X5: =IF(ISNUMBER(SEARCH("营",'20.03'!AF5)),(-$Y5+50*IF('20.03'!$AK5="是",'20.03'!$BB$4,'20.03'!$BB$3)),(VLOOKUP('20.03'!AF5,'20.03'!$AO$4:$AQ$55,2,FALSE))*IF('20.03'!$AK5="是",'20.03'!$BB$4,'20.03'!$BB$3)) -> 170 | Y5: 300 | Z5: 45822
A6: =IF(ISNUMBER(SEARCH("营",'20.03'!I6)),(-$Y6+50*IF('20.03'!$AK6="是",'20.03'!$BB$4,'20.03'!$BB$3)),(VLOOKUP('20.03'!I6,'20.03'!$AO$4:$AQ$55,2,FALSE))*IF('20.03'!$AK6="是",'20.03'!$BB$4,'20.03'!$BB$3)) -> 0 | B6: =IF(ISNUMBER(SEARCH("营",'20.03'!J6)),(-$Y6+50*IF('20.03'!$AK6="是",'20.03'!$BB$4,'20.03'!$BB$3)),(VLOOKUP('20.03'!J6,'20.03'!$AO$4:$AQ$55,2,FALSE))*IF('20.03'!$AK6="是",'20.03'!$BB$4,'20.03'!$BB$3)) -> 0 | C6: =IF(ISNUMBER(SEARCH("营",'20.03'!K6)),(-$Y6+50*IF('20.03'!$AK6="是",'20.03'!$BB$4,'20.03'!$BB$3)),(VLOOKUP('20.03'!K6,'20.03'!$AO$4:$AQ$55,2,FALSE))*IF('20.03'!$AK6="是",'20.03'!$BB$4,'20.03'!$BB$3)) -> 0 | D6: =IF(ISNUMBER(SEARCH("营",'20.03'!L6)),(-$Y6+50*IF('20.03'!$AK6="是",'20.03'!$BB$4,'20.03'!$BB$3)),(VLOOKUP('20.03'!L6,'20.03'!$AO$4:$AQ$55,2,FALSE))*IF('20.03'!$AK6="是",'20.03'!$BB$4,'20.03'!$BB$3)) -> 0 | E6: =IF(ISNUMBER(SEARCH("营",'20.03'!M6)),(-$Y6+50*IF('20.03'!$AK6="是",'20.03'!$BB$4,'20.03'!$BB$3)),(VLOOKUP('20.03'!M6,'20.03'!$AO$4:$AQ$55,2,FALSE))*IF('20.03'!$AK6="是",'20.03'!$BB$4,'20.03'!$BB$3)) -> 0 | F6: =IF(ISNUMBER(SEARCH("营",'20.03'!N6)),(-$Y6+50*IF('20.03'!$AK6="是",'20.03'!$BB$4,'20.03'!$BB$3)),(VLOOKUP('20.03'!N6,'20.03'!$AO$4:$AQ$55,2,FALSE))*IF('20.03'!$AK6="是",'20.03'!$BB$4,'20.03'!$BB$3)) -> 0 | G6: =IF(ISNUMBER(SEARCH("营",'20.03'!O6)),(-$Y6+50*IF('20.03'!$AK6="是",'20.03'!$BB$4,'20.03'!$BB$3)),(VLOOKUP('20.03'!O6,'20.03'!$AO$4:$AQ$55,2,FALSE))*IF('20.03'!$AK6="是",'20.03'!$BB$4,'20.03'!$BB$3)) -> 0 | H6: =IF(ISNUMBER(SEARCH("营",'20.03'!P6)),(-$Y6+50*IF('20.03'!$AK6="是",'20.03'!$BB$4,'20.03'!$BB$3)),(VLOOKUP('20.03'!P6,'20.03'!$AO$4:$AQ$55,2,FALSE))*IF('20.03'!$AK6="是",'20.03'!$BB$4,'20.03'!$BB$3)) -> 0 | ... X6: =IF(ISNUMBER(SEARCH("营",'20.03'!AF6)),(-$Y6+50*IF('20.03'!$AK6="是",'20.03'!$BB$4,'20.03'!$BB$3)),(VLOOKUP('20.03'!AF6,'20.03'!$AO$4:$AQ$55,2,FALSE))*IF('20.03'!$AK6="是",'20.03'!$BB$4,'20.03'!$BB$3)) -> 170 | Y6: 300 | Z6: 45823
A7: =IF(ISNUMBER(SEARCH("营",'20.03'!I7)),(-$Y7+50*IF('20.03'!$AK7="是",'20.03'!$BB$4,'20.03'!$BB$3)),(VLOOKUP('20.03'!I7,'20.03'!$AO$4:$AQ$55,2,FALSE))*IF('20.03'!$AK7="是",'20.03'!$BB$4,'20.03'!$BB$3)) -> 0 | B7: =IF(ISNUMBER(SEARCH("营",'20.03'!J7)),(-$Y7+50*IF('20.03'!$AK7="是",'20.03'!$BB$4,'20.03'!$BB$3)),(VLOOKUP('20.03'!J7,'20.03'!$AO$4:$AQ$55,2,FALSE))*IF('20.03'!$AK7="是",'20.03'!$BB$4,'20.03'!$BB$3)) -> 0 | C7: =IF(ISNUMBER(SEARCH("营",'20.03'!K7)),(-$Y7+50*IF('20.03'!$AK7="是",'20.03'!$BB$4,'20.03'!$BB$3)),(VLOOKUP('20.03'!K7,'20.03'!$AO$4:$AQ$55,2,FALSE))*IF('20.03'!$AK7="是",'20.03'!$BB$4,'20.03'!$BB$3)) -> 0 | D7: =IF(ISNUMBER(SEARCH("营",'20.03'!L7)),(-$Y7+50*IF('20.03'!$AK7="是",'20.03'!$BB$4,'20.03'!$BB$3)),(VLOOKUP('20.03'!L7,'20.03'!$AO$4:$AQ$55,2,FALSE))*IF('20.03'!$AK7="是",'20.03'!$BB$4,'20.03'!$BB$3)) -> 0 | E7: =IF(ISNUMBER(SEARCH("营",'20.03'!M7)),(-$Y7+50*IF('20.03'!$AK7="是",'20.03'!$BB$4,'20.03'!$BB$3)),(VLOOKUP('20.03'!M7,'20.03'!$AO$4:$AQ$55,2,FALSE))*IF('20.03'!$AK7="是",'20.03'!$BB$4,'20.03'!$BB$3)) -> 0 | F7: =IF(ISNUMBER(SEARCH("营",'20.03'!N7)),(-$Y7+50*IF('20.03'!$AK7="是",'20.03'!$BB$4,'20.03'!$BB$3)),(VLOOKUP('20.03'!N7,'20.03'!$AO$4:$AQ$55,2,FALSE))*IF('20.03'!$AK7="是",'20.03'!$BB$4,'20.03'!$BB$3)) -> 0 | G7: =IF(ISNUMBER(SEARCH("营",'20.03'!O7)),(-$Y7+50*IF('20.03'!$AK7="是",'20.03'!$BB$4,'20.03'!$BB$3)),(VLOOKUP('20.03'!O7,'20.03'!$AO$4:$AQ$55,2,FALSE))*IF('20.03'!$AK7="是",'20.03'!$BB$4,'20.03'!$BB$3)) -> 0 | H7: =IF(ISNUMBER(SEARCH("营",'20.03'!P7)),(-$Y7+50*IF('20.03'!$AK7="是",'20.03'!$BB$4,'20.03'!$BB$3)),(VLOOKUP('20.03'!P7,'20.03'!$AO$4:$AQ$55,2,FALSE))*IF('20.03'!$AK7="是",'20.03'!$BB$4,'20.03'!$BB$3)) -> 0 | ... X7: =IF(ISNUMBER(SEARCH("营",'20.03'!AF7)),(-$Y7+50*IF('20.03'!$AK7="是",'20.03'!$BB$4,'20.03'!$BB$3)),(VLOOKUP('20.03'!AF7,'20.03'!$AO$4:$AQ$55,2,FALSE))*IF('20.03'!$AK7="是",'20.03'!$BB$4,'20.03'!$BB$3)) -> 180 | Y7: 300 | Z7: 45824
A8: =IF(ISNUMBER(SEARCH("营",'20.03'!I8)),(-$Y8+50*IF('20.03'!$AK8="是",'20.03'!$BB$4,'20.03'!$BB$3)),(VLOOKUP('20.03'!I8,'20.03'!$AO$4:$AQ$55,2,FALSE))*IF('20.03'!$AK8="是",'20.03'!$BB$4,'20.03'!$BB$3)) -> 0 | B8: =IF(ISNUMBER(SEARCH("营",'20.03'!J8)),(-$Y8+50*IF('20.03'!$AK8="是",'20.03'!$BB$4,'20.03'!$BB$3)),(VLOOKUP('20.03'!J8,'20.03'!$AO$4:$AQ$55,2,FALSE))*IF('20.03'!$AK8="是",'20.03'!$BB$4,'20.03'!$BB$3)) -> 0 | C8: =IF(ISNUMBER(SEARCH("营",'20.03'!K8)),(-$Y8+50*IF('20.03'!$AK8="是",'20.03'!$BB$4,'20.03'!$BB$3)),(VLOOKUP('20.03'!K8,'20.03'!$AO$4:$AQ$55,2,FALSE))*IF('20.03'!$AK8="是",'20.03'!$BB$4,'20.03'!$BB$3)) -> 0 | D8: =IF(ISNUMBER(SEARCH("营",'20.03'!L8)),(-$Y8+50*IF('20.03'!$AK8="是",'20.03'!$BB$4,'20.03'!$BB$3)),(VLOOKUP('20.03'!L8,'20.03'!$AO$4:$AQ$55,2,FALSE))*IF('20.03'!$AK8="是",'20.03'!$BB$4,'20.03'!$BB$3)) -> 0 | E8: =IF(ISNUMBER(SEARCH("营",'20.03'!M8)),(-$Y8+50*IF('20.03'!$AK8="是",'20.03'!$BB$4,'20.03'!$BB$3)),(VLOOKUP('20.03'!M8,'20.03'!$AO$4:$AQ$55,2,FALSE))*IF('20.03'!$AK8="是",'20.03'!$BB$4,'20.03'!$BB$3)) -> 0 | F8: =IF(ISNUMBER(SEARCH("营",'20.03'!N8)),(-$Y8+50*IF('20.03'!$AK8="是",'20.03'!$BB$4,'20.03'!$BB$3)),(VLOOKUP('20.03'!N8,'20.03'!$AO$4:$AQ$55,2,FALSE))*IF('20.03'!$AK8="是",'20.03'!$BB$4,'20.03'!$BB$3)) -> 0 | G8: =IF(ISNUMBER(SEARCH("营",'20.03'!O8)),(-$Y8+50*IF('20.03'!$AK8="是",'20.03'!$BB$4,'20.03'!$BB$3)),(VLOOKUP('20.03'!O8,'20.03'!$AO$4:$AQ$55,2,FALSE))*IF('20.03'!$AK8="是",'20.03'!$BB$4,'20.03'!$BB$3)) -> 0 | H8: =IF(ISNUMBER(SEARCH("营",'20.03'!P8)),(-$Y8+50*IF('20.03'!$AK8="是",'20.03'!$BB$4,'20.03'!$BB$3)),(VLOOKUP('20.03'!P8,'20.03'!$AO$4:$AQ$55,2,FALSE))*IF('20.03'!$AK8="是",'20.03'!$BB$4,'20.03'!$BB$3)) -> 0 | ... X8: =IF(ISNUMBER(SEARCH("营",'20.03'!AF8)),(-$Y8+50*IF('20.03'!$AK8="是",'20.03'!$BB$4,'20.03'!$BB$3)),(VLOOKUP('20.03'!AF8,'20.03'!$AO$4:$AQ$55,2,FALSE))*IF('20.03'!$AK8="是",'20.03'!$BB$4,'20.03'!$BB$3)) -> 180 | Y8: 300 | Z8: 45825
A9: =IF(ISNUMBER(SEARCH("营",'20.03'!I9)),(-$Y9+50*IF('20.03'!$AK9="是",'20.03'!$BB$4,'20.03'!$BB$3)),(VLOOKUP('20.03'!I9,'20.03'!$AO$4:$AQ$55,2,FALSE))*IF('20.03'!$AK9="是",'20.03'!$BB$4,'20.03'!$BB$3)) -> 0 | B9: =IF(ISNUMBER(SEARCH("营",'20.03'!J9)),(-$Y9+50*IF('20.03'!$AK9="是",'20.03'!$BB$4,'20.03'!$BB$3)),(VLOOKUP('20.03'!J9,'20.03'!$AO$4:$AQ$55,2,FALSE))*IF('20.03'!$AK9="是",'20.03'!$BB$4,'20.03'!$BB$3)) -> 0 | C9: =IF(ISNUMBER(SEARCH("营",'20.03'!K9)),(-$Y9+50*IF('20.03'!$AK9="是",'20.03'!$BB$4,'20.03'!$BB$3)),(VLOOKUP('20.03'!K9,'20.03'!$AO$4:$AQ$55,2,FALSE))*IF('20.03'!$AK9="是",'20.03'!$BB$4,'20.03'!$BB$3)) -> 0 | D9: =IF(ISNUMBER(SEARCH("营",'20.03'!L9)),(-$Y9+50*IF('20.03'!$AK9="是",'20.03'!$BB$4,'20.03'!$BB$3)),(VLOOKUP('20.03'!L9,'20.03'!$AO$4:$AQ$55,2,FALSE))*IF('20.03'!$AK9="是",'20.03'!$BB$4,'20.03'!$BB$3)) -> 0 | E9: =IF(ISNUMBER(SEARCH("营",'20.03'!M9)),(-$Y9+50*IF('20.03'!$AK9="是",'20.03'!$BB$4,'20.03'!$BB$3)),(VLOOKUP('20.03'!M9,'20.03'!$AO$4:$AQ$55,2,FALSE))*IF('20.03'!$AK9="是",'20.03'!$BB$4,'20.03'!$BB$3)) -> 0 | F9: =IF(ISNUMBER(SEARCH("营",'20.03'!N9)),(-$Y9+50*IF('20.03'!$AK9="是",'20.03'!$BB$4,'20.03'!$BB$3)),(VLOOKUP('20.03'!N9,'20.03'!$AO$4:$AQ$55,2,FALSE))*IF('20.03'!$AK9="是",'20.03'!$BB$4,'20.03'!$BB$3)) -> 0 | G9: =IF(ISNUMBER(SEARCH("营",'20.03'!O9)),(-$Y9+50*IF('20.03'!$AK9="是",'20.03'!$BB$4,'20.03'!$BB$3)),(VLOOKUP('20.03'!O9,'20.03'!$AO$4:$AQ$55,2,FALSE))*IF('20.03'!$AK9="是",'20.03'!$BB$4,'20.03'!$BB$3)) -> 0 | H9: =IF(ISNUMBER(SEARCH("营",'20.03'!P9)),(-$Y9+50*IF('20.03'!$AK9="是",'20.03'!$BB$4,'20.03'!$BB$3)),(VLOOKUP('20.03'!P9,'20.03'!$AO$4:$AQ$55,2,FALSE))*IF('20.03'!$AK9="是",'20.03'!$BB$4,'20.03'!$BB$3)) -> 0 | ... X9: =IF(ISNUMBER(SEARCH("营",'20.03'!AF9)),(-$Y9+50*IF('20.03'!$AK9="是",'20.03'!$BB$4,'20.03'!$BB$3)),(VLOOKUP('20.03'!AF9,'20.03'!$AO$4:$AQ$55,2,FALSE))*IF('20.03'!$AK9="是",'20.03'!$BB$4,'20.03'!$BB$3)) -> 0 | Y9: 300 | Z9: 45826
A10: =IF(ISNUMBER(SEARCH("营",'20.03'!I10)),(-$Y10+50*IF('20.03'!$AK10="是",'20.03'!$BB$4,'20.03'!$BB$3)),(VLOOKUP('20.03'!I10,'20.03'!$AO$4:$AQ$55,2,FALSE))*IF('20.03'!$AK10="是",'20.03'!$BB$4,'20.03'!$BB$3)) -> 0 | B10: =IF(ISNUMBER(SEARCH("营",'20.03'!J10)),(-$Y10+50*IF('20.03'!$AK10="是",'20.03'!$BB$4,'20.03'!$BB$3)),(VLOOKUP('20.03'!J10,'20.03'!$AO$4:$AQ$55,2,FALSE))*IF('20.03'!$AK10="是",'20.03'!$BB$4,'20.03'!$BB$3)) -> 0 | C10: =IF(ISNUMBER(SEARCH("营",'20.03'!K10)),(-$Y10+50*IF('20.03'!$AK10="是",'20.03'!$BB$4,'20.03'!$BB$3)),(VLOOKUP('20.03'!K10,'20.03'!$AO$4:$AQ$55,2,FALSE))*IF('20.03'!$AK10="是",'20.03'!$BB$4,'20.03'!$BB$3)) -> 0 | D10: =IF(ISNUMBER(SEARCH("营",'20.03'!L10)),(-$Y10+50*IF('20.03'!$AK10="是",'20.03'!$BB$4,'20.03'!$BB$3)),(VLOOKUP('20.03'!L10,'20.03'!$AO$4:$AQ$55,2,FALSE))*IF('20.03'!$AK10="是",'20.03'!$BB$4,'20.03'!$BB$3)) -> 0 | E10: =IF(ISNUMBER(SEARCH("营",'20.03'!M10)),(-$Y10+50*IF('20.03'!$AK10="是",'20.03'!$BB$4,'20.03'!$BB$3)),(VLOOKUP('20.03'!M10,'20.03'!$AO$4:$AQ$55,2,FALSE))*IF('20.03'!$AK10="是",'20.03'!$BB$4,'20.03'!$BB$3)) -> 0 | F10: =IF(ISNUMBER(SEARCH("营",'20.03'!N10)),(-$Y10+50*IF('20.03'!$AK10="是",'20.03'!$BB$4,'20.03'!$BB$3)),(VLOOKUP('20.03'!N10,'20.03'!$AO$4:$AQ$55,2,FALSE))*IF('20.03'!$AK10="是",'20.03'!$BB$4,'20.03'!$BB$3)) -> 0 | G10: =IF(ISNUMBER(SEARCH("营",'20.03'!O10)),(-$Y10+50*IF('20.03'!$AK10="是",'20.03'!$BB$4,'20.03'!$BB$3)),(VLOOKUP('20.03'!O10,'20.03'!$AO$4:$AQ$55,2,FALSE))*IF('20.03'!$AK10="是",'20.03'!$BB$4,'20.03'!$BB$3)) -> 0 | H10: =IF(ISNUMBER(SEARCH("营",'20.03'!P10)),(-$Y10+50*IF('20.03'!$AK10="是",'20.03'!$BB$4,'20.03'!$BB$3)),(VLOOKUP('20.03'!P10,'20.03'!$AO$4:$AQ$55,2,FALSE))*IF('20.03'!$AK10="是",'20.03'!$BB$4,'20.03'!$BB$3)) -> 0 | ... X10: =IF(ISNUMBER(SEARCH("营",'20.03'!AF10)),(-$Y10+50*IF('20.03'!$AK10="是",'20.03'!$BB$4,'20.03'!$BB$3)),(VLOOKUP('20.03'!AF10,'20.03'!$AO$4:$AQ$55,2,FALSE))*IF('20.03'!$AK10="是",'20.03'!$BB$4,'20.03'!$BB$3)) -> 0 | Y10: 300 | Z10: 45827
A11: =IF(ISNUMBER(SEARCH("营",'20.03'!I11)),(-$Y11+50*IF('20.03'!$AK11="是",'20.03'!$BB$4,'20.03'!$BB$3)),(VLOOKUP('20.03'!I11,'20.03'!$AO$4:$AQ$55,2,FALSE))*IF('20.03'!$AK11="是",'20.03'!$BB$4,'20.03'!$BB$3)) -> 0 | B11: =IF(ISNUMBER(SEARCH("营",'20.03'!J11)),(-$Y11+50*IF('20.03'!$AK11="是",'20.03'!$BB$4,'20.03'!$BB$3)),(VLOOKUP('20.03'!J11,'20.03'!$AO$4:$AQ$55,2,FALSE))*IF('20.03'!$AK11="是",'20.03'!$BB$4,'20.03'!$BB$3)) -> 0 | C11: =IF(ISNUMBER(SEARCH("营",'20.03'!K11)),(-$Y11+50*IF('20.03'!$AK11="是",'20.03'!$BB$4,'20.03'!$BB$3)),(VLOOKUP('20.03'!K11,'20.03'!$AO$4:$AQ$55,2,FALSE))*IF('20.03'!$AK11="是",'20.03'!$BB$4,'20.03'!$BB$3)) -> 0 | D11: =IF(ISNUMBER(SEARCH("营",'20.03'!L11)),(-$Y11+50*IF('20.03'!$AK11="是",'20.03'!$BB$4,'20.03'!$BB$3)),(VLOOKUP('20.03'!L11,'20.03'!$AO$4:$AQ$55,2,FALSE))*IF('20.03'!$AK11="是",'20.03'!$BB$4,'20.03'!$BB$3)) -> 0 | E11: =IF(ISNUMBER(SEARCH("营",'20.03'!M11)),(-$Y11+50*IF('20.03'!$AK11="是",'20.03'!$BB$4,'20.03'!$BB$3)),(VLOOKUP('20.03'!M11,'20.03'!$AO$4:$AQ$55,2,FALSE))*IF('20.03'!$AK11="是",'20.03'!$BB$4,'20.03'!$BB$3)) -> 0 | F11: =IF(ISNUMBER(SEARCH("营",'20.03'!N11)),(-$Y11+50*IF('20.03'!$AK11="是",'20.03'!$BB$4,'20.03'!$BB$3)),(VLOOKUP('20.03'!N11,'20.03'!$AO$4:$AQ$55,2,FALSE))*IF('20.03'!$AK11="是",'20.03'!$BB$4,'20.03'!$BB$3)) -> 0 | G11: =IF(ISNUMBER(SEARCH("营",'20.03'!O11)),(-$Y11+50*IF('20.03'!$AK11="是",'20.03'!$BB$4,'20.03'!$BB$3)),(VLOOKUP('20.03'!O11,'20.03'!$AO$4:$AQ$55,2,FALSE))*IF('20.03'!$AK11="是",'20.03'!$BB$4,'20.03'!$BB$3)) -> 0 | H11: =IF(ISNUMBER(SEARCH("营",'20.03'!P11)),(-$Y11+50*IF('20.03'!$AK11="是",'20.03'!$BB$4,'20.03'!$BB$3)),(VLOOKUP('20.03'!P11,'20.03'!$AO$4:$AQ$55,2,FALSE))*IF('20.03'!$AK11="是",'20.03'!$BB$4,'20.03'!$BB$3)) -> 0 | ... X11: =IF(ISNUMBER(SEARCH("营",'20.03'!AF11)),(-$Y11+50*IF('20.03'!$AK11="是",'20.03'!$BB$4,'20.03'!$BB$3)),(VLOOKUP('20.03'!AF11,'20.03'!$AO$4:$AQ$55,2,FALSE))*IF('20.03'!$AK11="是",'20.03'!$BB$4,'20.03'!$BB$3)) -> 0 | Y11: 300 | Z11: 45828
A12: =IF(ISNUMBER(SEARCH("营",'20.03'!I12)),(-$Y12+50*IF('20.03'!$AK12="是",'20.03'!$BB$4,'20.03'!$BB$3)),(VLOOKUP('20.03'!I12,'20.03'!$AO$4:$AQ$55,2,FALSE))*IF('20.03'!$AK12="是",'20.03'!$BB$4,'20.03'!$BB$3)) -> 0 | B12: =IF(ISNUMBER(SEARCH("营",'20.03'!J12)),(-$Y12+50*IF('20.03'!$AK12="是",'20.03'!$BB$4,'20.03'!$BB$3)),(VLOOKUP('20.03'!J12,'20.03'!$AO$4:$AQ$55,2,FALSE))*IF('20.03'!$AK12="是",'20.03'!$BB$4,'20.03'!$BB$3)) -> 0 | C12: =IF(ISNUMBER(SEARCH("营",'20.03'!K12)),(-$Y12+50*IF('20.03'!$AK12="是",'20.03'!$BB$4,'20.03'!$BB$3)),(VLOOKUP('20.03'!K12,'20.03'!$AO$4:$AQ$55,2,FALSE))*IF('20.03'!$AK12="是",'20.03'!$BB$4,'20.03'!$BB$3)) -> 0 | D12: =IF(ISNUMBER(SEARCH("营",'20.03'!L12)),(-$Y12+50*IF('20.03'!$AK12="是",'20.03'!$BB$4,'20.03'!$BB$3)),(VLOOKUP('20.03'!L12,'20.03'!$AO$4:$AQ$55,2,FALSE))*IF('20.03'!$AK12="是",'20.03'!$BB$4,'20.03'!$BB$3)) -> 0 | E12: =IF(ISNUMBER(SEARCH("营",'20.03'!M12)),(-$Y12+50*IF('20.03'!$AK12="是",'20.03'!$BB$4,'20.03'!$BB$3)),(VLOOKUP('20.03'!M12,'20.03'!$AO$4:$AQ$55,2,FALSE))*IF('20.03'!$AK12="是",'20.03'!$BB$4,'20.03'!$BB$3)) -> 0 | F12: =IF(ISNUMBER(SEARCH("营",'20.03'!N12)),(-$Y12+50*IF('20.03'!$AK12="是",'20.03'!$BB$4,'20.03'!$BB$3)),(VLOOKUP('20.03'!N12,'20.03'!$AO$4:$AQ$55,2,FALSE))*IF('20.03'!$AK12="是",'20.03'!$BB$4,'20.03'!$BB$3)) -> 0 | G12: =IF(ISNUMBER(SEARCH("营",'20.03'!O12)),(-$Y12+50*IF('20.03'!$AK12="是",'20.03'!$BB$4,'20.03'!$BB$3)),(VLOOKUP('20.03'!O12,'20.03'!$AO$4:$AQ$55,2,FALSE))*IF('20.03'!$AK12="是",'20.03'!$BB$4,'20.03'!$BB$3)) -> 0 | H12: =IF(ISNUMBER(SEARCH("营",'20.03'!P12)),(-$Y12+50*IF('20.03'!$AK12="是",'20.03'!$BB$4,'20.03'!$BB$3)),(VLOOKUP('20.03'!P12,'20.03'!$AO$4:$AQ$55,2,FALSE))*IF('20.03'!$AK12="是",'20.03'!$BB$4,'20.03'!$BB$3)) -> 0 | ... X12: =IF(ISNUMBER(SEARCH("营",'20.03'!AF12)),(-$Y12+50*IF('20.03'!$AK12="是",'20.03'!$BB$4,'20.03'!$BB$3)),(VLOOKUP('20.03'!AF12,'20.03'!$AO$4:$AQ$55,2,FALSE))*IF('20.03'!$AK12="是",'20.03'!$BB$4,'20.03'!$BB$3)) -> 0 | Y12: 300 | Z12: 45829
A13: =IF(ISNUMBER(SEARCH("营",'20.03'!I13)),(-$Y13+50*IF('20.03'!$AK13="是",'20.03'!$BB$4,'20.03'!$BB$3)),(VLOOKUP('20.03'!I13,'20.03'!$AO$4:$AQ$55,2,FALSE))*IF('20.03'!$AK13="是",'20.03'!$BB$4,'20.03'!$BB$3)) -> 120 | B13: =IF(ISNUMBER(SEARCH("营",'20.03'!J13)),(-$Y13+50*IF('20.03'!$AK13="是",'20.03'!$BB$4,'20.03'!$BB$3)),(VLOOKUP('20.03'!J13,'20.03'!$AO$4:$AQ$55,2,FALSE))*IF('20.03'!$AK13="是",'20.03'!$BB$4,'20.03'!$BB$3)) -> 120 | C13: =IF(ISNUMBER(SEARCH("营",'20.03'!K13)),(-$Y13+50*IF('20.03'!$AK13="是",'20.03'!$BB$4,'20.03'!$BB$3)),(VLOOKUP('20.03'!K13,'20.03'!$AO$4:$AQ$55,2,FALSE))*IF('20.03'!$AK13="是",'20.03'!$BB$4,'20.03'!$BB$3)) -> 120 | D13: =IF(ISNUMBER(SEARCH("营",'20.03'!L13)),(-$Y13+50*IF('20.03'!$AK13="是",'20.03'!$BB$4,'20.03'!$BB$3)),(VLOOKUP('20.03'!L13,'20.03'!$AO$4:$AQ$55,2,FALSE))*IF('20.03'!$AK13="是",'20.03'!$BB$4,'20.03'!$BB$3)) -> 40 | E13: =IF(ISNUMBER(SEARCH("营",'20.03'!M13)),(-$Y13+50*IF('20.03'!$AK13="是",'20.03'!$BB$4,'20.03'!$BB$3)),(VLOOKUP('20.03'!M13,'20.03'!$AO$4:$AQ$55,2,FALSE))*IF('20.03'!$AK13="是",'20.03'!$BB$4,'20.03'!$BB$3)) -> 120 | F13: =IF(ISNUMBER(SEARCH("营",'20.03'!N13)),(-$Y13+50*IF('20.03'!$AK13="是",'20.03'!$BB$4,'20.03'!$BB$3)),(VLOOKUP('20.03'!N13,'20.03'!$AO$4:$AQ$55,2,FALSE))*IF('20.03'!$AK13="是",'20.03'!$BB$4,'20.03'!$BB$3)) -> 120 | G13: =IF(ISNUMBER(SEARCH("营",'20.03'!O13)),(-$Y13+50*IF('20.03'!$AK13="是",'20.03'!$BB$4,'20.03'!$BB$3)),(VLOOKUP('20.03'!O13,'20.03'!$AO$4:$AQ$55,2,FALSE))*IF('20.03'!$AK13="是",'20.03'!$BB$4,'20.03'!$BB$3)) -> 120 | H13: =IF(ISNUMBER(SEARCH("营",'20.03'!P13)),(-$Y13+50*IF('20.03'!$AK13="是",'20.03'!$BB$4,'20.03'!$BB$3)),(VLOOKUP('20.03'!P13,'20.03'!$AO$4:$AQ$55,2,FALSE))*IF('20.03'!$AK13="是",'20.03'!$BB$4,'20.03'!$BB$3)) -> 120 | ... X13: =IF(ISNUMBER(SEARCH("营",'20.03'!AF13)),(-$Y13+50*IF('20.03'!$AK13="是",'20.03'!$BB$4,'20.03'!$BB$3)),(VLOOKUP('20.03'!AF13,'20.03'!$AO$4:$AQ$55,2,FALSE))*IF('20.03'!$AK13="是",'20.03'!$BB$4,'20.03'!$BB$3)) -> 0 | Y13: 300 | Z13: 45830
