Workbook

Sheet 102 5.1.00
A1: =(_xlfn.DAYS(TODAY(),A4)+2)/((_xlfn.DAYS(A94,A4))+1) -> #NAME? | I1: 工作区 | AM1: 使用方法：按自己规划的路线，将下表中的地块名复制粘贴至工作区。初次使用传送门，当天跳步次数+5。重复使用传送门，当天跳步次数+1
A2: version 6.0.00 | D2: 合计经验 | F2: =SUM(F4:F94)+SUM(H4:H94) -> 63295 | I2: 队伍一 火 | K2: 步数 | L2: =COUNTIF(I4:P94,"<>空") -> 562 | M2: (不算跳步和传送) | Q2: 队伍二 雷 | S2: 步数 | T2: =COUNTIF(Q4:X94,"<>空") -> 494 | U2: (不算跳步和传送) | Y2: 队伍三 | AA2: 总步数 | AB2: =COUNTIF(Y4:AF94,"<>空") -> 18 | AC2: (不算跳步和传送) | AG2: =SUM(AG4:AG94) -> -3.4 | AH2: =SUM(AH4:AH94) -> 0 | AI2: =SUM(AI4:AI94) -> 0 | AJ2: =SUM(AJ4:AJ94) -> 0 | AK2: 八卦全开 | AX2: 粮草系数
A3: 日期 | B3: 获得粮草 | C3: 种植粮草 | D3: 消耗粮草 | E3: 剩余粮草 | F3: 获得经验 | G3: 累计经验 | H3: 任务经验 | I3: 1 | J3: 2 | K3: 3 | L3: 4 | M3: 5 | N3: 6 | O3: 7 | P3: 8 | Q3: 1 | R3: 2 | S3: 3 | T3: 4 | U3: 5 | V3: 6 | W3: 7 | X3: 8 | Y3: 1 | Z3: 2 | AA3: 3 | AB3: 4 | AC3: 5 | AD3: 6 | AE3: 7 | AF3: 8 | AG3: 跳步次数 | AH3: 1队跳步 | AI3: 2队跳步 | AJ3: 3队跳步 | AM3: 地块 | AN3: 粮草 | AO3: 经验 | AP3: 一队地块 | AQ3: 二队地块 | AR3: 三队地块 | AS3: 总地块 | AT3: 一队经验 | AU3: 二队经验 | AV3: 三队经验 | AW3: 八卦前 | AX3: 1
A4: 44547 | B4: 6800 | D4: =(SUM(粮草!A4:X4)+AG4*10)*IF(AK4="是",$AX$4,$AX$3) -> 750 | E4: =SUM($B$4:B4)+SUM($C$4:C4)-SUM($D$4:D4) -> 6050 | F4: =SUM(经验!A4:X4) -> 175 | G4: =SUM($F$4:F4)+SUM($H$4:H4) -> 175 | H4: 0 | I4: 1级 | J4: 1级 | K4: 1级 | L4: 1级 | M4: 1级 | N4: 空 | O4: 空 | P4: 空 | Q4: 空 | R4: 空 | S4: 空 | T4: 空 | U4: 空 | V4: 空 | W4: 空 | X4: 空 | Y4: 空 | Z4: 空 | AA4: 空 | AB4: 空 | AC4: 空 | AD4: 空 | AE4: 空 | AF4: 空 | AG4: 0 | AK4: 否 | AM4: 1级 | AN4: 150 | AO4: 35 | AP4: =COUNTIF($I$4:$P$94,AM4) -> 12 | AQ4: =COUNTIF($Q$4:$X$94,AM4) -> 2 | AR4: =COUNTIF($Y$4:$AF$94,AM4) -> 13 | AS4: =AP4+AQ4+AR4 -> 27 | AT4: =AP4*$AO4 -> 420 | AU4: =AQ4*$AO4 -> 70 | AV4: =AR4*$AO4 -> 455 | AW4: 八卦后 | AX4: 0.8 | AZ4: =AN4*0.8 -> 120
A5: 44548 | B5: 1600 | D5: =(SUM(粮草!A5:X5)+AG5*10)*IF(AK5="是",$AX$4,$AX$3) -> 1520 | E5: =SUM($B$4:B5)+SUM($C$4:C5)-SUM($D$4:D5) -> 6130 | F5: =SUM(经验!A5:X5) -> 395 | G5: =SUM($F$4:F5)+SUM($H$4:H5) -> 1070 | H5: 500 | I5: 1级 | J5: 1级 | K5: 1级 | L5: 1级 | M5: 1级 | N5: 营地 | O5: 1级 | P5: 1级 | Q5: 1级 | R5: 1级 | S5: 2级 | T5: 2级 | U5: 空 | V5: 空 | W5: 空 | X5: 空 | Y5: 空 | Z5: 空 | AA5: 空 | AB5: 空 | AC5: 空 | AD5: 空 | AE5: 空 | AF5: 空 | AG5: 0 | AK5: 否 | AM5: 2级 | AN5: 160 | AO5: 40 | AP5: =COUNTIF($I$4:$P$94,AM5) -> 12 | AQ5: =COUNTIF($Q$4:$X$94,AM5) -> 40 | AR5: =COUNTIF($Y$4:$AF$94,AM5) -> 0 | AS5: =AP5+AQ5+AR5 -> 52 | AT5: =AP5*$AO5 -> 480 | AU5: =AQ5*$AO5 -> 1600 | AV5: =AR5*$AO5 -> 0 | AW5: Note：开完八卦当天可能需要手动计算粮草 | AZ5: =AN5*0.8 -> 128
A6: 44549 | B6: 1600 | D6: =(SUM(粮草!A6:X6)+AG6*10)*IF(AK6="是",$AX$4,$AX$3) -> 1490 | E6: =SUM($B$4:B6)+SUM($C$4:C6)-SUM($D$4:D6) -> 6240 | F6: =SUM(经验!A6:X6) -> 390 | G6: =SUM($F$4:F6)+SUM($H$4:H6) -> 1460 | H6: 0 | I6: 2级 | J6: 2级 | K6: 2级 | L6: 2级 | M6: 2级 | N6: 2级 | O6: 空 | P6: 空 | Q6: 2级 | R6: 商人 | S6: 2级 | T6: 2级 | U6: 空 | V6: 空 | W6: 空 | X6: 空 | Y6: 空 | Z6: 空 | AA6: 空 | AB6: 空 | AC6: 空 | AD6: 空 | AE6: 空 | AF6: 空 | AG6: 0 | AK6: 否 | AM6: 3级 | AN6: 170 | AO6: 45 | AP6: =COUNTIF($I$4:$P$94,AM6) -> 120 | AQ6: =COUNTIF($Q$4:$X$94,AM6) -> 97 | AR6: =COUNTIF($Y$4:$AF$94,AM6) -> 0 | AS6: =AP6+AQ6+AR6 -> 217 | AT6: =AP6*$AO6 -> 5400 | AU6: =AQ6*$AO6 -> 4365 | AV6: =AR6*$AO6 -> 0 | AZ6: =AN6*0.8 -> 136
A7: 44550 | B7: 1600 | D7: =(SUM(粮草!A7:X7)+AG7*10)*IF(AK7="是",$AX$4,$AX$3) -> 2000 | E7: =SUM($B$4:B7)+SUM($C$4:C7)-SUM($D$4:D7) -> 5840 | F7: =SUM(经验!A7:X7) -> 525 | G7: =SUM($F$4:F7)+SUM($H$4:H7) -> 2185 | H7: 200 | I7: 塔2 | J7: 3级 | K7: 艮震坤离坎乾 | L7: 3级 | M7: 3级 | N7: 3级 | O7: 空 | P7: 空 | Q7: 2级 | R7: 2级 | S7: 3级 | T7: 3级 | U7: 艮震坤离坎乾 | V7: 3级 | W7: 空 | X7: 空 | Y7: 空 | Z7: 空 | AA7: 空 | AB7: 空 | AC7: 空 | AD7: 空 | AE7: 空 | AF7: 空 | AG7: 0 | AK7: 否 | AM7: 4级 | AN7: 180 | AO7: 50 | AP7: =COUNTIF($I$4:$P$94,AM7) -> 45 | AQ7: =COUNTIF($Q$4:$X$94,AM7) -> 218 | AR7: =COUNTIF($Y$4:$AF$94,AM7) -> 0 | AS7: =AP7+AQ7+AR7 -> 263 | AT7: =AP7*$AO7 -> 2250 | AU7: =AQ7*$AO7 -> 10900 | AV7: =AR7*$AO7 -> 0 | AZ7: =AN7*0.8 -> 144
A8: 44551 | B8: 1600 | D8: =(SUM(粮草!A8:X8)+AG8*10)*IF(AK8="是",$AX$4,$AX$3) -> 1820 | E8: =SUM($B$4:B8)+SUM($C$4:C8)-SUM($D$4:D8) -> 5620 | F8: =SUM(经验!A8:X8) -> 555 | G8: =SUM($F$4:F8)+SUM($H$4:H8) -> 2840 | H8: 100 | I8: 3级 | J8: 商人 | K8: 3级 | L8: 3级 | M8: 艮震坤离坎乾 | N8: 3级 | O8: 空 | P8: 空 | Q8: 3级 | R8: 3级 | S8: 3级 | T8: 3级 | U8: 商人 | V8: 3级 | W8: 营地 | X8: 3级 | Y8: 空 | Z8: 空 | AA8: 空 | AB8: 空 | AC8: 空 | AD8: 空 | AE8: 空 | AF8: 空 | AG8: 0 | AK8: 否 | AM8: 5级 | AN8: 190 | AO8: 55 | AP8: =COUNTIF($I$4:$P$94,AM8) -> 142 | AQ8: =COUNTIF($Q$4:$X$94,AM8) -> 95 | AR8: =COUNTIF($Y$4:$AF$94,AM8) -> 0 | AS8: =AP8+AQ8+AR8 -> 237 | AT8: =AP8*$AO8 -> 7810 | AU8: =AQ8*$AO8 -> 5225 | AV8: =AR8*$AO8 -> 0 | AZ8: =AN8*0.8 -> 152
A9: 44552 | B9: 1600 | D9: =(SUM(粮草!A9:X9)+AG9*10)*IF(AK9="是",$AX$4,$AX$3) -> 1950 | E9: =SUM($B$4:B9)+SUM($C$4:C9)-SUM($D$4:D9) -> 5270 | F9: =SUM(经验!A9:X9) -> 545 | G9: =SUM($F$4:F9)+SUM($H$4:H9) -> 3585 | H9: 200 | I9: 3级 | J9: 4级 | K9: 3级 | L9: 3级 | M9: 营地 | N9: 3级 | O9: 3级 | P9: 空 | Q9: 3级 | R9: 3级 | S9: 3级 | T9: 3级 | U9: 艮震坤离坎乾 | V9: 3级 | W9: 空 | X9: 空 | Y9: 空 | Z9: 空 | AA9: 空 | AB9: 空 | AC9: 空 | AD9: 空 | AE9: 空 | AF9: 空 | AG9: 5 | AK9: 否 | AM9: 6级 | AN9: 200 | AO9: 60 | AP9: =COUNTIF($I$4:$P$94,AM9) -> 194 | AQ9: =COUNTIF($Q$4:$X$94,AM9) -> 0 | AR9: =COUNTIF($Y$4:$AF$94,AM9) -> 0 | AS9: =AP9+AQ9+AR9 -> 194 | AT9: =AP9*$AO9 -> 11640 | AU9: =AQ9*$AO9 -> 0 | AV9: =AR9*$AO9 -> 0 | AZ9: =AN9*0.8 -> 160
A10: 44553 | B10: 1600 | D10: =(SUM(粮草!A10:X10)+AG10*10)*IF(AK10="是",$AX$4,$AX$3) -> 1680 | E10: =SUM($B$4:B10)+SUM($C$4:C10)-SUM($D$4:D10) -> 5190 | F10: =SUM(经验!A10:X10) -> 465 | G10: =SUM($F$4:F10)+SUM($H$4:H10) -> 4050 | H10: 0 | I10: 3级 | J10: 艮震坤离坎乾 | K10: 3级 | L10: 3级 | M10: 3级 | N10: 商人 | O10: 空 | P10: 空 | Q10: 3级 | R10: 商人 | S10: 3级 | T10: 3级 | U10: 3级 | V10: 空 | W10: 空 | X10: 空 | Y10: 空 | Z10: 空 | AA10: 空 | AB10: 空 | AC10: 空 | AD10: 空 | AE10: 空 | AF10: 空 | AG10: 5 | AK10: 否 | AM10: 塔1 | AN10: 150 | AO10: 35 | AP10: =COUNTIF($I$4:$P$94,AM10) -> 0 | AQ10: =COUNTIF($Q$4:$X$94,AM10) -> 0 | AR10: =COUNTIF($Y$4:$AF$94,AM10) -> 1 | AS10: =AP10+AQ10+AR10 -> 1 | AT10: =AP10*$AO10 -> 0 | AU10: =AQ10*$AO10 -> 0 | AV10: =AR10*$AO10 -> 35 | AZ10: =AN10*0.8 -> 120
A11: 44554 | B11: 1600 | D11: =(SUM(粮草!A11:X11)+AG11*10)*IF(AK11="是",$AX$4,$AX$3) -> 2080 | E11: =SUM($B$4:B11)+SUM($C$4:C11)-SUM($D$4:D11) -> 4710 | F11: =SUM(经验!A11:X11) -> 835 | G11: =SUM($F$4:F11)+SUM($H$4:H11) -> 4885 | H11: 0 | I11: 3级 | J11: 3级 | K11: 3级 | L11: 离巽 | M11: 3级 | N11: 3级 | O11: 空 | P11: 空 | Q11: 3级 | R11: 3级 | S11: 商人 | T11: 3级 | U11: 3级 | V11: 离巽 | W11: 空 | X11: 空 | Y11: 空 | Z11: 空 | AA11: 空 | AB11: 空 | AC11: 空 | AD11: 空 | AE11: 空 | AF11: 空 | AG11: 0 | AK11: 否 | AM11: 塔2 | AN11: 150 | AO11: 40 | AP11: =COUNTIF($I$4:$P$94,AM11) -> 2 | AQ11: =COUNTIF($Q$4:$X$94,AM11) -> 2 | AR11: =COUNTIF($Y$4:$AF$94,AM11) -> 0 | AS11: =AP11+AQ11+AR11 -> 4 | AT11: =AP11*$AO11 -> 80 | AU11: =AQ11*$AO11 -> 80 | AV11: =AR11*$AO11 -> 0 | AZ11: =AN11*0.8 -> 120
A12: 44555 | B12: 1600 | D12: =(SUM(粮草!A12:X12)+AG12*10)*IF(AK12="是",$AX$4,$AX$3) -> 1826 | E12: =SUM($B$4:B12)+SUM($C$4:C12)-SUM($D$4:D12) -> 4484 | F12: =SUM(经验!A12:X12) -> 555 | G12: =SUM($F$4:F12)+SUM($H$4:H12) -> 5440 | H12: 0 | I12: 3级 | J12: 3级 | K12: 3级 | L12: 3级 | M12: 艮震坤离坎乾 | N12: 3级 | O12: 空 | P12: 空 | Q12: 3级 | R12: 3级 | S12: 3级 | T12: 4级 | U12: 4级 | V12: 4级 | W12: 空 | X12: 空 | Y12: 空 | Z12: 空 | AA12: 空 | AB12: 空 | AC12: 空 | AD12: 空 | AE12: 空 | AF12: 空 | AG12: -24.4 | AK12: 否 | AM12: 塔3 | AN12: 150 | AO12: 45 | AP12: =COUNTIF($I$4:$P$94,AM12) -> 2 | AQ12: =COUNTIF($Q$4:$X$94,AM12) -> 4 | AR12: =COUNTIF($Y$4:$AF$94,AM12) -> 0 | AS12: =AP12+AQ12+AR12 -> 6 | AT12: =AP12*$AO12 -> 90 | AU12: =AQ12*$AO12 -> 180 | AV12: =AR12*$AO12 -> 0 | AZ12: =AN12*0.8 -> 120
A13: 44556 | B13: 1600 | D13: =(SUM(粮草!A13:X13)+AG13*10)*IF(AK13="是",$AX$4,$AX$3) -> 1568 | E13: =SUM($B$4:B13)+SUM($C$4:C13)-SUM($D$4:D13) -> 4516 | F13: =SUM(经验!A13:X13) -> 550 | G13: =SUM($F$4:F13)+SUM($H$4:H13) -> 5990 | H13: 0 | I13: 3级 | J13: 3级 | K13: 商人 | L13: 3级 | M13: 3级 | N13: 塔2 | O13: 空 | P13: 空 | Q13: 4级 | R13: 4级 | S13: 4级 | T13: 4级 | U13: 4级 | V13: 4级 | W13: 空 | X13: 空 | Y13: 空 | Z13: 空 | AA13: 空 | AB13: 空 | AC13: 空 | AD13: 空 | AE13: 空 | AF13: 空 | AG13: 0 | AK13: 是 | AM13: 塔4 | AN13: 150 | AO13: 50 | AP13: =COUNTIF($I$4:$P$94,AM13) -> 0 | AQ13: =COUNTIF($Q$4:$X$94,AM13) -> 3 | AR13: =COUNTIF($Y$4:$AF$94,AM13) -> 0 | AS13: =AP13+AQ13+AR13 -> 3 | AT13: =AP13*$AO13 -> 0 | AU13: =AQ13*$AO13 -> 150 | AV13: =AR13*$AO13 -> 0 | AZ13: =AN13*0.8 -> 120
A14: 44557 | B14: 1600 | D14: =(SUM(粮草!A14:X14)+AG14*10)*IF(AK14="是",$AX$4,$AX$3) -> 1576 | E14: =SUM($B$4:B14)+SUM($C$4:C14)-SUM($D$4:D14) -> 4540 | F14: =SUM(经验!A14:X14) -> 550 | G14: =SUM($F$4:F14)+SUM($H$4:H14) -> 6840 | H14: 300 | I14: 3级 | J14: 3级 | K14: 3级 | L14: 3级 | M14: 3级 | N14: 3级 | O14: 空 | P14: 空 | Q14: 商人 | R14: 4级 | S14: 4级 | T14: 4级 | U14: 4级 | V14: 4级 | W14: 空 | X14: 空 | Y14: 空 | Z14: 空 | AA14: 空 | AB14: 空 | AC14: 空 | AD14: 空 | AE14: 空 | AF14: 空 | AG14: 0 | AK14: 是 | AM14: 塔5 | AN14: 150 | AO14: 55 | AP14: =COUNTIF($I$4:$P$94,AM14) -> 2 | AQ14: =COUNTIF($Q$4:$X$94,AM14) -> 1 | AR14: =COUNTIF($Y$4:$AF$94,AM14) -> 0 | AS14: =AP14+AQ14+AR14 -> 3 | AT14: =AP14*$AO14 -> 110 | AU14: =AQ14*$AO14 -> 55 | AV14: =AR14*$AO14 -> 0 | AZ14: =AN14*0.8 -> 120
A15: 44558 | B15: 1600 | D15: =(SUM(粮草!A15:X15)+AG15*10)*IF(AK15="是",$AX$4,$AX$3) -> 1680 | E15: =SUM($B$4:B15)+SUM($C$4:C15)-SUM($D$4:D15) -> 4460 | F15: =SUM(经验!A15:X15) -> 570 | G15: =SUM($F$4:F15)+SUM($H$4:H15) -> 7410 | H15: 0 | I15: 3级 | J15: 3级 | K15: 3级 | L15: 3级 | M15: 3级 | N15: 3级 | O15: 空 | P15: 空 | Q15: 4级 | R15: 4级 | S15: 4级 | T15: 4级 | U15: 4级 | V15: 4级 | W15: 空 | X15: 空 | Y15: 空 | Z15: 空 | AA15: 空 | AB15: 空 | AC15: 空 | AD15: 空 | AE15: 空 | AF15: 空 | AG15: 0 | AK15: 是 | AM15: 塔6 | AN15: 150 | AO15: 60 | AP15: =COUNTIF($I$4:$P$94,AM15) -> 1 | AQ15: =COUNTIF($Q$4:$X$94,AM15) -> 0 | AR15: =COUNTIF($Y$4:$AF$94,AM15) -> 0 | AS15: =AP15+AQ15+AR15 -> 1 | AT15: =AP15*$AO15 -> 60 | AU15: =AQ15*$AO15 -> 0 | AV15: =AR15*$AO15 -> 0 | AZ15: =AN15*0.8 -> 120
A16: 44559 | B16: 1600 | D16: =(SUM(粮草!A16:X16)+AG16*10)*IF(AK16="是",$AX$4,$AX$3) -> 1584 | E16: =SUM($B$4:B16)+SUM($C$4:C16)-SUM($D$4:D16) -> 4476 | F16: =SUM(经验!A16:X16) -> 555 | G16: =SUM($F$4:F16)+SUM($H$4:H16) -> 8165 | H16: 200 | I16: 3级 | J16: 3级 | K16: 3级 | L16: 3级 | M16: 商人 | N16: 3级 | O16: 空 | P16: 空 | Q16: 4级 | R16: 4级 | S16: 4级 | T16: 4级 | U16: 4级 | V16: 4级 | W16: 空 | X16: 空 | Y16: 空 | Z16: 空 | AA16: 空 | AB16: 空 | AC16: 空 | AD16: 空 | AE16: 空 | AF16: 空 | AG16: 0 | AK16: 是 | AM16: 遗迹 | AN16: 150 | AO16: 35 | AP16: =COUNTIF($I$4:$P$94,AM16) -> 0 | AQ16: =COUNTIF($Q$4:$X$94,AM16) -> 0 | AR16: =COUNTIF($Y$4:$AF$94,AM16) -> 0 | AS16: =AP16+AQ16+AR16 -> 0 | AT16: =AP16*$AO16 -> 0 | AU16: =AQ16*$AO16 -> 0 | AV16: =AR16*$AO16 -> 0 | AZ16: =AN16*0.8 -> 120
A17: 44560 | B17: 1600 | D17: =(SUM(粮草!A17:X17)+AG17*10)*IF(AK17="是",$AX$4,$AX$3) -> 1680 | E17: =SUM($B$4:B17)+SUM($C$4:C17)-SUM($D$4:D17) -> 4396 | F17: =SUM(经验!A17:X17) -> 570 | G17: =SUM($F$4:F17)+SUM($H$4:H17) -> 8735 | H17: 0 | I17: 3级 | J17: 3级 | K17: 3级 | L17: 3级 | M17: 3级 | N17: 3级 | O17: 空 | P17: 空 | Q17: 4级 | R17: 4级 | S17: 4级 | T17: 4级 | U17: 4级 | V17: 4级 | W17: 空 | X17: 空 | Y17: 空 | Z17: 空 | AA17: 空 | AB17: 空 | AC17: 空 | AD17: 空 | AE17: 空 | AF17: 空 | AG17: 0 | AK17: 是 | AM17: 商人 | AN17: 50 | AO17: 30 | AP17: =COUNTIF($I$4:$P$94,AM17) -> 13 | AQ17: =COUNTIF($Q$4:$X$94,AM17) -> 22 | AR17: =COUNTIF($Y$4:$AF$94,AM17) -> 4 | AS17: =AP17+AQ17+AR17 -> 39 | AT17: =AP17*$AO17 -> 390 | AU17: =AQ17*$AO17 -> 660 | AV17: =AR17*$AO17 -> 120 | AZ17: =AN17*0.8 -> 40
A18: 44561 | B18: 1600 | D18: =(SUM(粮草!A18:X18)+AG18*10)*IF(AK18="是",$AX$4,$AX$3) -> 1664 | E18: =SUM($B$4:B18)+SUM($C$4:C18)-SUM($D$4:D18) -> 4332 | F18: =SUM(经验!A18:X18) -> 620 | G18: =SUM($F$4:F18)+SUM($H$4:H18) -> 9355 | H18: 0 | I18: 3级 | J18: 3级 | K18: 3级 | L18: 3级 | M18: 3级 | N18: 3级 | O18: 空 | P18: 空 | Q18: 4级 | R18: 4级 | S18: 4级 | T18: 4级 | U18: 营地+ | V18: 4级 | W18: 4级 | X18: 4级 | Y18: 空 | Z18: 空 | AA18: 空 | AB18: 空 | AC18: 空 | AD18: 空 | AE18: 空 | AF18: 空 | AG18: 0 | AK18: 是 | AL18: 八卦前 | AM18: 营地 | AN18: -150 | AO18: 0 | AP18: =COUNTIF($I$4:$P$94,AM18) -> 2 | AQ18: =COUNTIF($Q$4:$X$94,AM18) -> 1 | AR18: =COUNTIF($Y$4:$AF$94,AM18) -> 0 | AS18: =AP18+AQ18+AR18 -> 3 | AT18: =AP18*$AO18 -> 0 | AU18: =AQ18*$AO18 -> 0 | AV18: =AR18*$AO18 -> 0 | AZ18: =AN18*0.8 -> -120
A19: 44562 | B19: 1600 | D19: =(SUM(粮草!A19:X19)+AG19*10)*IF(AK19="是",$AX$4,$AX$3) -> 1528 | E19: =SUM($B$4:B19)+SUM($C$4:C19)-SUM($D$4:D19) -> 4404 | F19: =SUM(经验!A19:X19) -> 530 | G19: =SUM($F$4:F19)+SUM($H$4:H19) -> 9885 | H19: 0 | I19: 商人 | J19: 3级 | K19: 3级 | L19: 3级 | M19: 3级 | N19: 3级 | O19: 空 | P19: 空 | Q19: 塔3 | R19: 3级 | S19: 3级 | T19: 3级 | U19: 3级 | V19: 4级 | W19: 空 | X19: 空 | Y19: 空 | Z19: 空 | AA19: 空 | AB19: 空 | AC19: 空 | AD19: 空 | AE19: 空 | AF19: 空 | AG19: 0 | AK19: 是 | AM19: 离巽 | AN19: 250 | AO19: 200 | AP19: =COUNTIF($I$4:$P$94,AM19) -> 1 | AQ19: =COUNTIF($Q$4:$X$94,AM19) -> 1 | AR19: =COUNTIF($Y$4:$AF$94,AM19) -> 0 | AS19: =AP19+AQ19+AR19 -> 2 | AT19: =AP19*$AO19 -> 200 | AU19: =AQ19*$AO19 -> 200 | AV19: =AR19*$AO19 -> 0 | AZ19: =AN19*0.8 -> 200
A20: 44563 | B20: 1600 | D20: =(SUM(粮草!A20:X20)+AG20*10)*IF(AK20="是",$AX$4,$AX$3) -> 1672 | E20: =SUM($B$4:B20)+SUM($C$4:C20)-SUM($D$4:D20) -> 4332 | F20: =SUM(经验!A20:X20) -> 570 | G20: =SUM($F$4:F20)+SUM($H$4:H20) -> 10455 | H20: 0 | I20: 3级 | J20: 塔3 | K20: 3级 | L20: 3级 | M20: 3级 | N20: 3级 | O20: 空 | P20: 空 | Q20: 4级 | R20: 4级 | S20: 4级 | T20: 4级 | U20: 4级 | V20: 4级 | W20: 空 | X20: 空 | Y20: 空 | Z20: 空 | AA20: 空 | AB20: 空 | AC20: 空 | AD20: 空 | AE20: 空 | AF20: 空 | AG20: 1 | AK20: 是 | AM20: 艮震坤离坎乾 | AN20: 170 | AO20: 45 | AP20: =COUNTIF($I$4:$P$94,AM20) -> 4 | AQ20: =COUNTIF($Q$4:$X$94,AM20) -> 2 | AR20: =COUNTIF($Y$4:$AF$94,AM20) -> 0 | AS20: =AP20+AQ20+AR20 -> 6 | AT20: =AP20*$AO20 -> 180 | AU20: =AQ20*$AO20 -> 90 | AV20: =AR20*$AO20 -> 0 | AZ20: =AN20*0.8 -> 136
A21: 44564 | B21: 1600 | D21: =(SUM(粮草!A21:X21)+AG21*10)*IF(AK21="是",$AX$4,$AX$3) -> 1496 | E21: =SUM($B$4:B21)+SUM($C$4:C21)-SUM($D$4:D21) -> 4436 | F21: =SUM(经验!A21:X21) -> 540 | G21: =SUM($F$4:F21)+SUM($H$4:H21) -> 11195 | H21: 200 | I21: 3级 | J21: 商人 | K21: 3级 | L21: 3级 | M21: 3级 | N21: 4级 | O21: 空 | P21: 空 | Q21: 4级 | R21: 4级 | S21: 4级 | T21: 4级 | U21: 商人 | V21: 4级 | W21: 空 | X21: 空 | Y21: 空 | Z21: 空 | AA21: 空 | AB21: 空 | AC21: 空 | AD21: 空 | AE21: 空 | AF21: 空 | AG21: 1 | AK21: 是 | AM21: 小boss | AN21: 250 | AO21: 200 | AP21: =COUNTIF($I$4:$P$94,AM21) -> 0 | AQ21: =COUNTIF($Q$4:$X$94,AM21) -> 0 | AR21: =COUNTIF($Y$4:$AF$94,AM21) -> 0 | AS21: =AP21+AQ21+AR21 -> 0 | AT21: =AP21*$AO21 -> 0 | AU21: =AQ21*$AO21 -> 0 | AV21: =AR21*$AO21 -> 0 | AZ21: =AN21*0.8 -> 200
A22: 44565 | B22: 1600 | D22: =(SUM(粮草!A22:X22)+AG22*10)*IF(AK22="是",$AX$4,$AX$3) -> 1704 | E22: =SUM($B$4:B22)+SUM($C$4:C22)-SUM($D$4:D22) -> 4332 | F22: =SUM(经验!A22:X22) -> 585 | G22: =SUM($F$4:F22)+SUM($H$4:H22) -> 11880 | H22: 100 | I22: 4级 | J22: 4级 | K22: 4级 | L22: 3级 | M22: 3级 | N22: 3级 | O22: 空 | P22: 空 | Q22: 4级 | R22: 4级 | S22: 4级 | T22: 4级 | U22: 4级 | V22: 4级 | W22: 空 | X22: 空 | Y22: 空 | Z22: 空 | AA22: 空 | AB22: 空 | AC22: 空 | AD22: 空 | AE22: 空 | AF22: 空 | AG22: 0 | AK22: 是 | AM22: 大boss | AN22: 250 | AO22: 1000 | AP22: =COUNTIF($I$4:$P$94,AM22) -> 2 | AQ22: =COUNTIF($Q$4:$X$94,AM22) -> 0 | AR22: =COUNTIF($Y$4:$AF$94,AM22) -> 0 | AS22: =AP22+AQ22+AR22 -> 2 | AT22: =AP22*$AO22 -> 2000 | AU22: =AQ22*$AO22 -> 0 | AV22: =AR22*$AO22 -> 0 | AZ22: =AN22*0.8 -> 200
A23: 44566 | B23: 1600 | D23: =(SUM(粮草!A23:X23)+AG23*10)*IF(AK23="是",$AX$4,$AX$3) -> 1656 | E23: =SUM($B$4:B23)+SUM($C$4:C23)-SUM($D$4:D23) -> 4276 | F23: =SUM(经验!A23:X23) -> 615 | G23: =SUM($F$4:F23)+SUM($H$4:H23) -> 12695 | H23: 200 | I23: 3级 | J23: 3级 | K23: 3级 | L23: 3级 | M23: 3级 | N23: 营地+ | O23: 3级 | P23: 3级 | Q23: 4级 | R23: 4级 | S23: 4级 | T23: 4级 | U23: 4级 | V23: 4级 | W23: 空 | X23: 空 | Y23: 空 | Z23: 空 | AA23: 空 | AB23: 空 | AC23: 空 | AD23: 空 | AE23: 空 | AF23: 空 | AG23: 0 | AK23: 是 | AM23: 中boss | AN23: 250 | AO23: 500 | AP23: =COUNTIF($I$4:$P$94,AM23) -> 1 | AQ23: =COUNTIF($Q$4:$X$94,AM23) -> 1 | AR23: =COUNTIF($Y$4:$AF$94,AM23) -> 0 | AS23: =AP23+AQ23+AR23 -> 2 | AT23: =AP23*$AO23 -> 500 | AU23: =AQ23*$AO23 -> 500 | AV23: =AR23*$AO23 -> 0 | AZ23: =AN23*0.8 -> 200
A24: 44567 | B24: 1600 | D24: =(SUM(粮草!A24:X24)+AG24*10)*IF(AK24="是",$AX$4,$AX$3) -> 1688 | E24: =SUM($B$4:B24)+SUM($C$4:C24)-SUM($D$4:D24) -> 4188 | F24: =SUM(经验!A24:X24) -> 575 | G24: =SUM($F$4:F24)+SUM($H$4:H24) -> 13270 | H24: 0 | I24: 3级 | J24: 3级 | K24: 3级 | L24: 3级 | M24: 3级 | N24: 4级 | O24: 空 | P24: 空 | Q24: 4级 | R24: 4级 | S24: 4级 | T24: 4级 | U24: 4级 | V24: 4级 | W24: 空 | X24: 空 | Y24: 空 | Z24: 空 | AA24: 空 | AB24: 空 | AC24: 空 | AD24: 空 | AE24: 空 | AF24: 空 | AG24: 0 | AK24: 是 | AM24: 奈良 | AN24: 160 | AO24: 40 | AP24: =COUNTIF($I$4:$P$94,AM24) -> 0 | AQ24: =COUNTIF($Q$4:$X$94,AM24) -> 0 | AR24: =COUNTIF($Y$4:$AF$94,AM24) -> 0 | AS24: =AP24+AQ24+AR24 -> 0 | AT24: =AP24*$AO24 -> 0 | AU24: =AQ24*$AO24 -> 0 | AV24: =AR24*$AO24 -> 0 | AZ24: =AN24*0.8 -> 128
A25: 44568 | B25: 1600 | D25: =(SUM(粮草!A25:X25)+AG25*10)*IF(AK25="是",$AX$4,$AX$3) -> 1624 | E25: =SUM($B$4:B25)+SUM($C$4:C25)-SUM($D$4:D25) -> 4164 | F25: =SUM(经验!A25:X25) -> 580 | G25: =SUM($F$4:F25)+SUM($H$4:H25) -> 13850 | H25: 0 | I25: 商人 | J25: 4级 | K25: 4级 | L25: 4级 | M25: 4级 | N25: 4级 | O25: 空 | P25: 空 | Q25: 4级 | R25: 4级 | S25: 4级 | T25: 4级 | U25: 4级 | V25: 4级 | W25: 空 | X25: 空 | Y25: 空 | Z25: 空 | AA25: 空 | AB25: 空 | AC25: 空 | AD25: 空 | AE25: 空 | AF25: 空 | AG25: 0 | AK25: 是 | AM25: 山中 | AN25: 160 | AO25: 40 | AP25: =COUNTIF($I$4:$P$94,AM25) -> 0 | AQ25: =COUNTIF($Q$4:$X$94,AM25) -> 0 | AR25: =COUNTIF($Y$4:$AF$94,AM25) -> 0 | AS25: =AP25+AQ25+AR25 -> 0 | AT25: =AP25*$AO25 -> 0 | AU25: =AQ25*$AO25 -> 0 | AV25: =AR25*$AO25 -> 0 | AZ25: =AN25*0.8 -> 128
A26: 44569 | B26: 1600 | D26: =(SUM(粮草!A26:X26)+AG26*10)*IF(AK26="是",$AX$4,$AX$3) -> 1728 | E26: =SUM($B$4:B26)+SUM($C$4:C26)-SUM($D$4:D26) -> 4036 | F26: =SUM(经验!A26:X26) -> 600 | G26: =SUM($F$4:F26)+SUM($H$4:H26) -> 14450 | H26: 0 | I26: 4级 | J26: 4级 | K26: 4级 | L26: 4级 | M26: 4级 | N26: 4级 | O26: 空 | P26: 空 | Q26: 4级 | R26: 4级 | S26: 4级 | T26: 4级 | U26: 4级 | V26: 4级 | W26: 空 | X26: 空 | Y26: 空 | Z26: 空 | AA26: 空 | AB26: 空 | AC26: 空 | AD26: 空 | AE26: 空 | AF26: 空 | AG26: 0 | AK26: 是 | AM26: 秋道 | AN26: 150 | AO26: 35 | AP26: =COUNTIF($I$4:$P$94,AM26) -> 0 | AQ26: =COUNTIF($Q$4:$X$94,AM26) -> 0 | AR26: =COUNTIF($Y$4:$AF$94,AM26) -> 0 | AS26: =AP26+AQ26+AR26 -> 0 | AT26: =AP26*$AO26 -> 0 | AU26: =AQ26*$AO26 -> 0 | AV26: =AR26*$AO26 -> 0 | AZ26: =AN26*0.8 -> 120
A27: 44570 | B27: 1600 | D27: =(SUM(粮草!A27:X27)+AG27*10)*IF(AK27="是",$AX$4,$AX$3) -> 1760 | E27: =SUM($B$4:B27)+SUM($C$4:C27)-SUM($D$4:D27) -> 3876 | F27: =SUM(经验!A27:X27) -> 620 | G27: =SUM($F$4:F27)+SUM($H$4:H27) -> 15070 | H27: 0 | I27: 4级 | J27: 4级 | K27: 5级 | L27: 5级 | M27: 5级 | N27: 5级 | O27: 空 | P27: 空 | Q27: 4级 | R27: 4级 | S27: 4级 | T27: 4级 | U27: 4级 | V27: 4级 | W27: 空 | X27: 空 | Y27: 空 | Z27: 空 | AA27: 空 | AB27: 空 | AC27: 空 | AD27: 空 | AE27: 空 | AF27: 空 | AG27: 0 | AK27: 是 | AM27: 空 | AN27: 0 | AO27: 0 | AT27: =AP27*$AO27 -> 0 | AU27: =AQ27*$AO27 -> 0 | AV27: =AR27*$AO27 -> 0 | AZ27: =AN27*0.8 -> 0
A28: 44571 | B28: 1600 | D28: =(SUM(粮草!A28:X28)+AG28*10)*IF(AK28="是",$AX$4,$AX$3) -> 1560 | E28: =SUM($B$4:B28)+SUM($C$4:C28)-SUM($D$4:D28) -> 3916 | F28: =SUM(经验!A28:X28) -> 585 | G28: =SUM($F$4:F28)+SUM($H$4:H28) -> 15855 | H28: 200 | I28: 5级 | J28: 5级 | K28: 商人 | L28: 5级 | M28: 5级 | N28: 5级 | O28: 空 | P28: 空 | Q28: 4级 | R28: 4级 | S28: 4级 | T28: 4级 | U28: 4级 | V28: 商人 | W28: 空 | X28: 空 | Y28: 空 | Z28: 空 | AA28: 空 | AB28: 空 | AC28: 空 | AD28: 空 | AE28: 空 | AF28: 空 | AG28: 0 | AK28: 是 | AL28: 八卦后 | AM28: 营地+ | AN28: -200 | AO28: 0 | AP28: =COUNTIF($I$4:$P$94,AM28) -> 7 | AQ28: =COUNTIF($Q$4:$X$94,AM28) -> 5 | AR28: =COUNTIF($Y$4:$AF$94,AM28) -> 0 | AS28: =AP28+AQ28+AR28 -> 12 | AT28: =AP28*$AO28 -> 0 | AU28: =AQ28*$AO28 -> 0 | AV28: =AR28*$AO28 -> 0 | AZ28: =AN28*0.8 -> -160
A29: 44572 | B29: 1600 | D29: =(SUM(粮草!A29:X29)+AG29*10)*IF(AK29="是",$AX$4,$AX$3) -> 1760 | E29: =SUM($B$4:B29)+SUM($C$4:C29)-SUM($D$4:D29) -> 3756 | F29: =SUM(经验!A29:X29) -> 620 | G29: =SUM($F$4:F29)+SUM($H$4:H29) -> 16575 | H29: 100 | I29: 5级 | J29: 5级 | K29: 5级 | L29: 5级 | M29: 5级 | N29: 5级 | O29: 空 | P29: 空 | Q29: 4级 | R29: 4级 | S29: 4级 | T29: 4级 | U29: 3级 | V29: 3级 | W29: 空 | X29: 空 | Y29: 空 | Z29: 空 | AA29: 空 | AB29: 空 | AC29: 空 | AD29: 空 | AE29: 空 | AF29: 空 | AG29: 0 | AK29: 是 | AR29: 总地块 | AS29: =SUM(AS4:AS28) -> 1074 | AU29: 总经验 | AV29: =SUM(AT4:AV28)+7000 -> 63295
A30: 44573 | B30: 1600 | D30: =(SUM(粮草!A30:X30)+AG30*10)*IF(AK30="是",$AX$4,$AX$3) -> 1768 | E30: =SUM($B$4:B30)+SUM($C$4:C30)-SUM($D$4:D30) -> 3588 | F30: =SUM(经验!A30:X30) -> 620 | G30: =SUM($F$4:F30)+SUM($H$4:H30) -> 17395 | H30: 200 | I30: 5级 | J30: 5级 | K30: 5级 | L30: 5级 | M30: 5级 | N30: 5级 | O30: 空 | P30: 空 | Q30: 3级 | R30: 3级 | S30: 4级 | T30: 4级 | U30: 4级 | V30: 4级 | W30: 空 | X30: 空 | Y30: 空 | Z30: 空 | AA30: 空 | AB30: 空 | AC30: 空 | AD30: 空 | AE30: 空 | AF30: 空 | AG30: 1 | AK30: 是
A31: 44574 | B31: 1600 | D31: =(SUM(粮草!A31:X31)+AG31*10)*IF(AK31="是",$AX$4,$AX$3) -> 1760 | E31: =SUM($B$4:B31)+SUM($C$4:C31)-SUM($D$4:D31) -> 3428 | F31: =SUM(经验!A31:X31) -> 680 | G31: =SUM($F$4:F31)+SUM($H$4:H31) -> 18075 | H31: 0 | I31: 5级 | J31: 5级 | K31: 5级 | L31: 5级 | M31: 5级 | N31: 5级 | O31: 空 | P31: 空 | Q31: 4级 | R31: 4级 | S31: 4级 | T31: 营地+ | U31: 4级 | V31: 4级 | W31: 4级 | X31: 4级 | Y31: 空 | Z31: 空 | AA31: 空 | AB31: 空 | AC31: 空 | AD31: 空 | AE31: 空 | AF31: 空 | AG31: 0 | AK31: 是
A32: 44575 | B32: 1600 | D32: =(SUM(粮草!A32:X32)+AG32*10)*IF(AK32="是",$AX$4,$AX$3) -> 1680 | E32: =SUM($B$4:B32)+SUM($C$4:C32)-SUM($D$4:D32) -> 3348 | F32: =SUM(经验!A32:X32) -> 615 | G32: =SUM($F$4:F32)+SUM($H$4:H32) -> 18690 | H32: 0 | I32: 5级 | J32: 5级 | K32: 5级 | L32: 5级 | M32: 5级 | N32: 6级 | O32: 空 | P32: 空 | Q32: 4级 | R32: 4级 | S32: 4级 | T32: 4级 | U32: 4级 | V32: 商人 | W32: 空 | X32: 空 | Y32: 空 | Z32: 空 | AA32: 空 | AB32: 空 | AC32: 空 | AD32: 空 | AE32: 空 | AF32: 空 | AG32: 0 | AK32: 是
A33: 44576 | B33: 1600 | D33: =(SUM(粮草!A33:X33)+AG33*10)*IF(AK33="是",$AX$4,$AX$3) -> 1824 | E33: =SUM($B$4:B33)+SUM($C$4:C33)-SUM($D$4:D33) -> 3124 | F33: =SUM(经验!A33:X33) -> 660 | G33: =SUM($F$4:F33)+SUM($H$4:H33) -> 19350 | H33: 0 | I33: 6级 | J33: 6级 | K33: 6级 | L33: 6级 | M33: 6级 | N33: 6级 | O33: 空 | P33: 空 | Q33: 4级 | R33: 4级 | S33: 4级 | T33: 4级 | U33: 4级 | V33: 4级 | W33: 空 | X33: 空 | Y33: 空 | Z33: 空 | AA33: 空 | AB33: 空 | AC33: 空 | AD33: 空 | AE33: 空 | AF33: 空 | AG33: 0 | AK33: 是
A34: 44577 | B34: 1600 | D34: =(SUM(粮草!A34:X34)+AG34*10)*IF(AK34="是",$AX$4,$AX$3) -> 1800 | E34: =SUM($B$4:B34)+SUM($C$4:C34)-SUM($D$4:D34) -> 2924 | F34: =SUM(经验!A34:X34) -> 720 | G34: =SUM($F$4:F34)+SUM($H$4:H34) -> 20070 | H34: 0 | I34: 6级 | J34: 6级 | K34: 6级 | L34: 6级 | M34: 6级 | N34: 6级 | O34: 营地+ | P34: 6级 | Q34: 塔4 | R34: 4级 | S34: 4级 | T34: 4级 | U34: 4级 | V34: 4级 | W34: 空 | X34: 空 | Y34: 空 | Z34: 空 | AA34: 空 | AB34: 空 | AC34: 空 | AD34: 空 | AE34: 空 | AF34: 空 | AG34: 0 | AK34: 是
A35: 44578 | B35: 1600 | D35: =(SUM(粮草!A35:X35)+AG35*10)*IF(AK35="是",$AX$4,$AX$3) -> 1840 | E35: =SUM($B$4:B35)+SUM($C$4:C35)-SUM($D$4:D35) -> 2684 | F35: =SUM(经验!A35:X35) -> 670 | G35: =SUM($F$4:F35)+SUM($H$4:H35) -> 20940 | H35: 200 | I35: 6级 | J35: 6级 | K35: 6级 | L35: 6级 | M35: 6级 | N35: 6级 | O35: 空 | P35: 空 | Q35: 4级 | R35: 4级 | S35: 4级 | T35: 4级 | U35: 5级 | V35: 5级 | W35: 空 | X35: 空 | Y35: 空 | Z35: 空 | AA35: 空 | AB35: 空 | AC35: 空 | AD35: 空 | AE35: 空 | AF35: 空 | AG35: 0 | AK35: 是
A36: 44579 | B36: 1600 | D36: =(SUM(粮草!A36:X36)+AG36*10)*IF(AK36="是",$AX$4,$AX$3) -> 1872 | E36: =SUM($B$4:B36)+SUM($C$4:C36)-SUM($D$4:D36) -> 2412 | F36: =SUM(经验!A36:X36) -> 690 | G36: =SUM($F$4:F36)+SUM($H$4:H36) -> 21730 | H36: 100 | I36: 6级 | J36: 6级 | K36: 6级 | L36: 6级 | M36: 6级 | N36: 6级 | O36: 空 | P36: 空 | Q36: 5级 | R36: 5级 | S36: 5级 | T36: 5级 | U36: 5级 | V36: 5级 | W36: 空 | X36: 空 | Y36: 空 | Z36: 空 | AA36: 空 | AB36: 空 | AC36: 空 | AD36: 空 | AE36: 空 | AF36: 空 | AG36: 0 | AK36: 是
A37: 44580 | B37: 1600 | D37: =(SUM(粮草!A37:X37)+AG37*10)*IF(AK37="是",$AX$4,$AX$3) -> 1872 | E37: =SUM($B$4:B37)+SUM($C$4:C37)-SUM($D$4:D37) -> 2140 | F37: =SUM(经验!A37:X37) -> 690 | G37: =SUM($F$4:F37)+SUM($H$4:H37) -> 22620 | H37: 200 | I37: 6级 | J37: 6级 | K37: 6级 | L37: 6级 | M37: 6级 | N37: 6级 | O37: 空 | P37: 空 | Q37: 5级 | R37: 5级 | S37: 5级 | T37: 5级 | U37: 5级 | V37: 5级 | W37: 空 | X37: 空 | Y37: 空 | Z37: 空 | AA37: 空 | AB37: 空 | AC37: 空 | AD37: 空 | AE37: 空 | AF37: 空 | AG37: 0 | AK37: 是
A38: 44581 | B38: 1600 | D38: =(SUM(粮草!A38:X38)+AG38*10)*IF(AK38="是",$AX$4,$AX$3) -> 1872 | E38: =SUM($B$4:B38)+SUM($C$4:C38)-SUM($D$4:D38) -> 1868 | F38: =SUM(经验!A38:X38) -> 690 | G38: =SUM($F$4:F38)+SUM($H$4:H38) -> 23310 | H38: 0 | I38: 6级 | J38: 6级 | K38: 6级 | L38: 6级 | M38: 6级 | N38: 6级 | O38: 空 | P38: 空 | Q38: 5级 | R38: 5级 | S38: 5级 | T38: 5级 | U38: 5级 | V38: 5级 | W38: 空 | X38: 空 | Y38: 空 | Z38: 空 | AA38: 空 | AB38: 空 | AC38: 空 | AD38: 空 | AE38: 空 | AF38: 空 | AG38: 0 | AK38: 是
A39: 44582 | B39: 1600 | D39: =(SUM(粮草!A39:X39)+AG39*10)*IF(AK39="是",$AX$4,$AX$3) -> 1960 | E39: =SUM($B$4:B39)+SUM($C$4:C39)-SUM($D$4:D39) -> 1508 | F39: =SUM(经验!A39:X39) -> 2075 | G39: =SUM($F$4:F39)+SUM($H$4:H39) -> 25385 | H39: 0 | I39: 6级 | J39: 6级 | K39: 大boss | L39: 6级 | M39: 6级 | N39: 6级 | O39: 空 | P39: 空 | Q39: 5级 | R39: 5级 | S39: 中boss | T39: 5级 | U39: 5级 | V39: 5级 | W39: 空 | X39: 空 | Y39: 空 | Z39: 空 | AA39: 空 | AB39: 空 | AC39: 空 | AD39: 空 | AE39: 空 | AF39: 空 | AG39: 0 | AK39: 是
A40: 44583 | B40: 1600 | D40: =(SUM(粮草!A40:X40)+AG40*10)*IF(AK40="是",$AX$4,$AX$3) -> 1872 | E40: =SUM($B$4:B40)+SUM($C$4:C40)-SUM($D$4:D40) -> 1236 | F40: =SUM(经验!A40:X40) -> 690 | G40: =SUM($F$4:F40)+SUM($H$4:H40) -> 26075 | H40: 0 | I40: 6级 | J40: 6级 | K40: 6级 | L40: 6级 | M40: 6级 | N40: 6级 | O40: 空 | P40: 空 | Q40: 5级 | R40: 5级 | S40: 5级 | T40: 5级 | U40: 5级 | V40: 5级 | W40: 空 | X40: 空 | Y40: 空 | Z40: 空 | AA40: 空 | AB40: 空 | AC40: 空 | AD40: 空 | AE40: 空 | AF40: 空 | AG40: 0 | AK40: 是
...

Sheet 粮草
A2: 队伍一 风 | C2: 步数 | D2: =COUNTIF(A4:H94,"<>空") -> 728 | E2: (不算跳步和传送) | I2: 队伍二 雷 | K2: 步数 | L2: =COUNTIF(I4:P94,"<>空") -> 728 | M2: (不算跳步和传送) | Q2: 队伍三 | S2: 总步数 | T2: =COUNTIF(Q4:X94,"<>空") -> 728 | U2: (不算跳步和传送)
A3: 1 | B3: 2 | C3: 3 | D3: 4 | E3: 5 | F3: 6 | G3: 7 | H3: 8 | I3: 1 | J3: 2 | K3: 3 | L3: 4 | M3: 5 | N3: 6 | O3: 7 | P3: 8 | Q3: 1 | R3: 2 | S3: 3 | T3: 4 | U3: 5 | V3: 6 | W3: 7 | X3: 8
A4: =(VLOOKUP('102 5.1.00'!I4,'102 5.1.00'!$AM$4:$AO$55,2,FALSE))*IF('102 5.1.00'!AK$4="是",'102 5.1.00'!$AX$4,'102 5.1.00'!$AX$3) -> 150 | B4: =(VLOOKUP('102 5.1.00'!J4,'102 5.1.00'!$AM$4:$AO$55,2,FALSE))*IF('102 5.1.00'!AL$4="是",'102 5.1.00'!$AX$4,'102 5.1.00'!$AX$3) -> 150 | C4: =(VLOOKUP('102 5.1.00'!K4,'102 5.1.00'!$AM$4:$AO$55,2,FALSE))*IF('102 5.1.00'!AM$4="是",'102 5.1.00'!$AX$4,'102 5.1.00'!$AX$3) -> 150 | D4: =(VLOOKUP('102 5.1.00'!L4,'102 5.1.00'!$AM$4:$AO$55,2,FALSE))*IF('102 5.1.00'!AN$4="是",'102 5.1.00'!$AX$4,'102 5.1.00'!$AX$3) -> 150 | E4: =(VLOOKUP('102 5.1.00'!M4,'102 5.1.00'!$AM$4:$AO$55,2,FALSE))*IF('102 5.1.00'!AO$4="是",'102 5.1.00'!$AX$4,'102 5.1.00'!$AX$3) -> 150 | F4: =(VLOOKUP('102 5.1.00'!N4,'102 5.1.00'!$AM$4:$AO$55,2,FALSE))*IF('102 5.1.00'!AP$4="是",'102 5.1.00'!$AX$4,'102 5.1.00'!$AX$3) -> 0 | G4: =(VLOOKUP('102 5.1.00'!O4,'102 5.1.00'!$AM$4:$AO$55,2,FALSE))*IF('102 5.1.00'!AQ$4="是",'102 5.1.00'!$AX$4,'102 5.1.00'!$AX$3) -> 0 | H4: =(VLOOKUP('102 5.1.00'!P4,'102 5.1.00'!$AM$4:$AO$55,2,FALSE))*IF('102 5.1.00'!AR$4="是",'102 5.1.00'!$AX$4,'102 5.1.00'!$AX$3) -> 0 | ... X4: =(VLOOKUP('102 5.1.00'!AF4,'102 5.1.00'!$AM$4:$AO$55,2,FALSE))*IF('102 5.1.00'!BH$4="是",'102 5.1.00'!$AX$4,'102 5.1.00'!$AX$3) -> 0
A5: =(VLOOKUP('102 5.1.00'!I5,'102 5.1.00'!$AM$4:$AO$55,2,FALSE))*IF('102 5.1.00'!AK$4="是",'102 5.1.00'!$AX$4,'102 5.1.00'!$AX$3) -> 150 | B5: =(VLOOKUP('102 5.1.00'!J5,'102 5.1.00'!$AM$4:$AO$55,2,FALSE))*IF('102 5.1.00'!AL$4="是",'102 5.1.00'!$AX$4,'102 5.1.00'!$AX$3) -> 150 | C5: =(VLOOKUP('102 5.1.00'!K5,'102 5.1.00'!$AM$4:$AO$55,2,FALSE))*IF('102 5.1.00'!AM$4="是",'102 5.1.00'!$AX$4,'102 5.1.00'!$AX$3) -> 150 | D5: =(VLOOKUP('102 5.1.00'!L5,'102 5.1.00'!$AM$4:$AO$55,2,FALSE))*IF('102 5.1.00'!AN$4="是",'102 5.1.00'!$AX$4,'102 5.1.00'!$AX$3) -> 150 | E5: =(VLOOKUP('102 5.1.00'!M5,'102 5.1.00'!$AM$4:$AO$55,2,FALSE))*IF('102 5.1.00'!AO$4="是",'102 5.1.00'!$AX$4,'102 5.1.00'!$AX$3) -> 150 | F5: =(VLOOKUP('102 5.1.00'!N5,'102 5.1.00'!$AM$4:$AO$55,2,FALSE))*IF('102 5.1.00'!AP$4="是",'102 5.1.00'!$AX$4,'102 5.1.00'!$AX$3) -> -150 | G5: =(VLOOKUP('102 5.1.00'!O5,'102 5.1.00'!$AM$4:$AO$55,2,FALSE))*IF('102 5.1.00'!AQ$4="是",'102 5.1.00'!$AX$4,'102 5.1.00'!$AX$3) -> 150 | H5: =(VLOOKUP('102 5.1.00'!P5,'102 5.1.00'!$AM$4:$AO$55,2,FALSE))*IF('102 5.1.00'!AR$4="是",'102 5.1.00'!$AX$4,'102 5.1.00'!$AX$3) -> 150 | ... X5: =(VLOOKUP('102 5.1.00'!AF5,'102 5.1.00'!$AM$4:$AO$55,2,FALSE))*IF('102 5.1.00'!BH$4="是",'102 5.1.00'!$AX$4,'102 5.1.00'!$AX$3) -> 0
A6: =(VLOOKUP('102 5.1.00'!I6,'102 5.1.00'!$AM$4:$AO$55,2,FALSE))*IF('102 5.1.00'!AK$4="是",'102 5.1.00'!$AX$4,'102 5.1.00'!$AX$3) -> 160 | B6: =(VLOOKUP('102 5.1.00'!J6,'102 5.1.00'!$AM$4:$AO$55,2,FALSE))*IF('102 5.1.00'!AL$4="是",'102 5.1.00'!$AX$4,'102 5.1.00'!$AX$3) -> 160 | C6: =(VLOOKUP('102 5.1.00'!K6,'102 5.1.00'!$AM$4:$AO$55,2,FALSE))*IF('102 5.1.00'!AM$4="是",'102 5.1.00'!$AX$4,'102 5.1.00'!$AX$3) -> 160 | D6: =(VLOOKUP('102 5.1.00'!L6,'102 5.1.00'!$AM$4:$AO$55,2,FALSE))*IF('102 5.1.00'!AN$4="是",'102 5.1.00'!$AX$4,'102 5.1.00'!$AX$3) -> 160 | E6: =(VLOOKUP('102 5.1.00'!M6,'102 5.1.00'!$AM$4:$AO$55,2,FALSE))*IF('102 5.1.00'!AO$4="是",'102 5.1.00'!$AX$4,'102 5.1.00'!$AX$3) -> 160 | F6: =(VLOOKUP('102 5.1.00'!N6,'102 5.1.00'!$AM$4:$AO$55,2,FALSE))*IF('102 5.1.00'!AP$4="是",'102 5.1.00'!$AX$4,'102 5.1.00'!$AX$3) -> 160 | G6: =(VLOOKUP('102 5.1.00'!O6,'102 5.1.00'!$AM$4:$AO$55,2,FALSE))*IF('102 5.1.00'!AQ$4="是",'102 5.1.00'!$AX$4,'102 5.1.00'!$AX$3) -> 0 | H6: =(VLOOKUP('102 5.1.00'!P6,'102 5.1.00'!$AM$4:$AO$55,2,FALSE))*IF('102 5.1.00'!AR$4="是",'102 5.1.00'!$AX$4,'102 5.1.00'!$AX$3) -> 0 | ... X6: =(VLOOKUP('102 5.1.00'!AF6,'102 5.1.00'!$AM$4:$AO$55,2,FALSE))*IF('102 5.1.00'!BH$4="是",'102 5.1.00'!$AX$4,'102 5.1.00'!$AX$3) -> 0
A7: =(VLOOKUP('102 5.1.00'!I7,'102 5.1.00'!$AM$4:$AO$55,2,FALSE))*IF('102 5.1.00'!AK$4="是",'102 5.1.00'!$AX$4,'102 5.1.00'!$AX$3) -> 150 | B7: =(VLOOKUP('102 5.1.00'!J7,'102 5.1.00'!$AM$4:$AO$55,2,FALSE))*IF('102 5.1.00'!AL$4="是",'102 5.1.00'!$AX$4,'102 5.1.00'!$AX$3) -> 170 | C7: =(VLOOKUP('102 5.1.00'!K7,'102 5.1.00'!$AM$4:$AO$55,2,FALSE))*IF('102 5.1.00'!AM$4="是",'102 5.1.00'!$AX$4,'102 5.1.00'!$AX$3) -> 170 | D7: =(VLOOKUP('102 5.1.00'!L7,'102 5.1.00'!$AM$4:$AO$55,2,FALSE))*IF('102 5.1.00'!AN$4="是",'102 5.1.00'!$AX$4,'102 5.1.00'!$AX$3) -> 170 | E7: =(VLOOKUP('102 5.1.00'!M7,'102 5.1.00'!$AM$4:$AO$55,2,FALSE))*IF('102 5.1.00'!AO$4="是",'102 5.1.00'!$AX$4,'102 5.1.00'!$AX$3) -> 170 | F7: =(VLOOKUP('102 5.1.00'!N7,'102 5.1.00'!$AM$4:$AO$55,2,FALSE))*IF('102 5.1.00'!AP$4="是",'102 5.1.00'!$AX$4,'102 5.1.00'!$AX$3) -> 170 | G7: =(VLOOKUP('102 5.1.00'!O7,'102 5.1.00'!$AM$4:$AO$55,2,FALSE))*IF('102 5.1.00'!AQ$4="是",'102 5.1.00'!$AX$4,'102 5.1.00'!$AX$3) -> 0 | H7: =(VLOOKUP('102 5.1.00'!P7,'102 5.1.00'!$AM$4:$AO$55,2,FALSE))*IF('102 5.1.00'!AR$4="是",'102 5.1.00'!$AX$4,'102 5.1.00'!$AX$3) -> 0 | ... X7: =(VLOOKUP('102 5.1.00'!AF7,'102 5.1.00'!$AM$4:$AO$55,2,FALSE))*IF('102 5.1.00'!BH$4="是",'102 5.1.00'!$AX$4,'102 5.1.00'!$AX$3) -> 0
A8: =(VLOOKUP('102 5.1.00'!I8,'102 5.1.00'!$AM$4:$AO$55,2,FALSE))*IF('102 5.1.00'!AK$4="是",'102 5.1.00'!$AX$4,'102 5.1.00'!$AX$3) -> 170 | B8: =(VLOOKUP('102 5.1.00'!J8,'102 5.1.00'!$AM$4:$AO$55,2,FALSE))*IF('102 5.1.00'!AL$4="是",'102 5.1.00'!$AX$4,'102 5.1.00'!$AX$3) -> 50 | C8: =(VLOOKUP('102 5.1.00'!K8,'102 5.1.00'!$AM$4:$AO$55,2,FALSE))*IF('102 5.1.00'!AM$4="是",'102 5.1.00'!$AX$4,'102 5.1.00'!$AX$3) -> 170 | D8: =(VLOOKUP('102 5.1.00'!L8,'102 5.1.00'!$AM$4:$AO$55,2,FALSE))*IF('102 5.1.00'!AN$4="是",'102 5.1.00'!$AX$4,'102 5.1.00'!$AX$3) -> 170 | E8: =(VLOOKUP('102 5.1.00'!M8,'102 5.1.00'!$AM$4:$AO$55,2,FALSE))*IF('102 5.1.00'!AO$4="是",'102 5.1.00'!$AX$4,'102 5.1.00'!$AX$3) -> 170 | F8: =(VLOOKUP('102 5.1.00'!N8,'102 5.1.00'!$AM$4:$AO$55,2,FALSE))*IF('102 5.1.00'!AP$4="是",'102 5.1.00'!$AX$4,'102 5.1.00'!$AX$3) -> 170 | G8: =(VLOOKUP('102 5.1.00'!O8,'102 5.1.00'!$AM$4:$AO$55,2,FALSE))*IF('102 5.1.00'!AQ$4="是",'102 5.1.00'!$AX$4,'102 5.1.00'!$AX$3) -> 0 | H8: =(VLOOKUP('102 5.1.00'!P8,'102 5.1.00'!$AM$4:$AO$55,2,FALSE))*IF('102 5.1.00'!AR$4="是",'102 5.1.00'!$AX$4,'102 5.1.00'!$AX$3) -> 0 | ... X8: =(VLOOKUP('102 5.1.00'!AF8,'102 5.1.00'!$AM$4:$AO$55,2,FALSE))*IF('102 5.1.00'!BH$4="是",'102 5.1.00'!$AX$4,'102 5.1.00'!$AX$3) -> 0
A9: =(VLOOKUP('102 5.1.00'!I9,'102 5.1.00'!$AM$4:$AO$55,2,FALSE))*IF('102 5.1.00'!AK$4="是",'102 5.1.00'!$AX$4,'102 5.1.00'!$AX$3) -> 170 | B9: =(VLOOKUP('102 5.1.00'!J9,'102 5.1.00'!$AM$4:$AO$55,2,FALSE))*IF('102 5.1.00'!AL$4="是",'102 5.1.00'!$AX$4,'102 5.1.00'!$AX$3) -> 180 | C9: =(VLOOKUP('102 5.1.00'!K9,'102 5.1.00'!$AM$4:$AO$55,2,FALSE))*IF('102 5.1.00'!AM$4="是",'102 5.1.00'!$AX$4,'102 5.1.00'!$AX$3) -> 170 | D9: =(VLOOKUP('102 5.1.00'!L9,'102 5.1.00'!$AM$4:$AO$55,2,FALSE))*IF('102 5.1.00'!AN$4="是",'102 5.1.00'!$AX$4,'102 5.1.00'!$AX$3) -> 170 | E9: =(VLOOKUP('102 5.1.00'!M9,'102 5.1.00'!$AM$4:$AO$55,2,FALSE))*IF('102 5.1.00'!AO$4="是",'102 5.1.00'!$AX$4,'102 5.1.00'!$AX$3) -> -150 | F9: =(VLOOKUP('102 5.1.00'!N9,'102 5.1.00'!$AM$4:$AO$55,2,FALSE))*IF('102 5.1.00'!AP$4="是",'102 5.1.00'!$AX$4,'102 5.1.00'!$AX$3) -> 170 | G9: =(VLOOKUP('102 5.1.00'!O9,'102 5.1.00'!$AM$4:$AO$55,2,FALSE))*IF('102 5.1.00'!AQ$4="是",'102 5.1.00'!$AX$4,'102 5.1.00'!$AX$3) -> 170 | H9: =(VLOOKUP('102 5.1.00'!P9,'102 5.1.00'!$AM$4:$AO$55,2,FALSE))*IF('102 5.1.00'!AR$4="是",'102 5.1.00'!$AX$4,'102 5.1.00'!$AX$3) -> 0 | ... X9: =(VLOOKUP('102 5.1.00'!AF9,'102 5.1.00'!$AM$4:$AO$55,2,FALSE))*IF('102 5.1.00'!BH$4="是",'102 5.1.00'!$AX$4,'102 5.1.00'!$AX$3) -> 0
A10: =(VLOOKUP('102 5.1.00'!I10,'102 5.1.00'!$AM$4:$AO$55,2,FALSE))*IF('102 5.1.00'!AK$4="是",'102 5.1.00'!$AX$4,'102 5.1.00'!$AX$3) -> 170 | B10: =(VLOOKUP('102 5.1.00'!J10,'102 5.1.00'!$AM$4:$AO$55,2,FALSE))*IF('102 5.1.00'!AL$4="是",'102 5.1.00'!$AX$4,'102 5.1.00'!$AX$3) -> 170 | C10: =(VLOOKUP('102 5.1.00'!K10,'102 5.1.00'!$AM$4:$AO$55,2,FALSE))*IF('102 5.1.00'!AM$4="是",'102 5.1.00'!$AX$4,'102 5.1.00'!$AX$3) -> 170 | D10: =(VLOOKUP('102 5.1.00'!L10,'102 5.1.00'!$AM$4:$AO$55,2,FALSE))*IF('102 5.1.00'!AN$4="是",'102 5.1.00'!$AX$4,'102 5.1.00'!$AX$3) -> 170 | E10: =(VLOOKUP('102 5.1.00'!M10,'102 5.1.00'!$AM$4:$AO$55,2,FALSE))*IF('102 5.1.00'!AO$4="是",'102 5.1.00'!$AX$4,'102 5.1.00'!$AX$3) -> 170 | F10: =(VLOOKUP('102 5.1.00'!N10,'102 5.1.00'!$AM$4:$AO$55,2,FALSE))*IF('102 5.1.00'!AP$4="是",'102 5.1.00'!$AX$4,'102 5.1.00'!$AX$3) -> 50 | G10: =(VLOOKUP('102 5.1.00'!O10,'102 5.1.00'!$AM$4:$AO$55,2,FALSE))*IF('102 5.1.00'!AQ$4="是",'102 5.1.00'!$AX$4,'102 5.1.00'!$AX$3) -> 0 | H10: =(VLOOKUP('102 5.1.00'!P10,'102 5.1.00'!$AM$4:$AO$55,2,FALSE))*IF('102 5.1.00'!AR$4="是",'102 5.1.00'!$AX$4,'102 5.1.00'!$AX$3) -> 0 | ... X10: =(VLOOKUP('102 5.1.00'!AF10,'102 5.1.00'!$AM$4:$AO$55,2,FALSE))*IF('102 5.1.00'!BH$4="是",'102 5.1.00'!$AX$4,'102 5.1.00'!$AX$3) -> 0
A11: =(VLOOKUP('102 5.1.00'!I11,'102 5.1.00'!$AM$4:$AO$55,2,FALSE))*IF('102 5.1.00'!AK$4="是",'102 5.1.00'!$AX$4,'102 5.1.00'!$AX$3) -> 170 | B11: =(VLOOKUP('102 5.1.00'!J11,'102 5.1.00'!$AM$4:$AO$55,2,FALSE))*IF('102 5.1.00'!AL$4="是",'102 5.1.00'!$AX$4,'102 5.1.00'!$AX$3) -> 170 | C11: =(VLOOKUP('102 5.1.00'!K11,'102 5.1.00'!$AM$4:$AO$55,2,FALSE))*IF('102 5.1.00'!AM$4="是",'102 5.1.00'!$AX$4,'102 5.1.00'!$AX$3) -> 170 | D11: =(VLOOKUP('102 5.1.00'!L11,'102 5.1.00'!$AM$4:$AO$55,2,FALSE))*IF('102 5.1.00'!AN$4="是",'102 5.1.00'!$AX$4,'102 5.1.00'!$AX$3) -> 250 | E11: =(VLOOKUP('102 5.1.00'!M11,'102 5.1.00'!$AM$4:$AO$55,2,FALSE))*IF('102 5.1.00'!AO$4="是",'102 5.1.00'!$AX$4,'102 5.1.00'!$AX$3) -> 170 | F11: =(VLOOKUP('102 5.1.00'!N11,'102 5.1.00'!$AM$4:$AO$55,2,FALSE))*IF('102 5.1.00'!AP$4="是",'102 5.1.00'!$AX$4,'102 5.1.00'!$AX$3) -> 170 | G11: =(VLOOKUP('102 5.1.00'!O11,'102 5.1.00'!$AM$4:$AO$55,2,FALSE))*IF('102 5.1.00'!AQ$4="是",'102 5.1.00'!$AX$4,'102 5.1.00'!$AX$3) -> 0 | H11: =(VLOOKUP('102 5.1.00'!P11,'102 5.1.00'!$AM$4:$AO$55,2,FALSE))*IF('102 5.1.00'!AR$4="是",'102 5.1.00'!$AX$4,'102 5.1.00'!$AX$3) -> 0 | ... X11: =(VLOOKUP('102 5.1.00'!AF11,'102 5.1.00'!$AM$4:$AO$55,2,FALSE))*IF('102 5.1.00'!BH$4="是",'102 5.1.00'!$AX$4,'102 5.1.00'!$AX$3) -> 0
A12: =(VLOOKUP('102 5.1.00'!I12,'102 5.1.00'!$AM$4:$AO$55,2,FALSE))*IF('102 5.1.00'!AK$4="是",'102 5.1.00'!$AX$4,'102 5.1.00'!$AX$3) -> 170 | B12: =(VLOOKUP('102 5.1.00'!J12,'102 5.1.00'!$AM$4:$AO$55,2,FALSE))*IF('102 5.1.00'!AL$4="是",'102 5.1.00'!$AX$4,'102 5.1.00'!$AX$3) -> 170 | C12: =(VLOOKUP('102 5.1.00'!K12,'102 5.1.00'!$AM$4:$AO$55,2,FALSE))*IF('102 5.1.00'!AM$4="是",'102 5.1.00'!$AX$4,'102 5.1.00'!$AX$3) -> 170 | D12: =(VLOOKUP('102 5.1.00'!L12,'102 5.1.00'!$AM$4:$AO$55,2,FALSE))*IF('102 5.1.00'!AN$4="是",'102 5.1.00'!$AX$4,'102 5.1.00'!$AX$3) -> 170 | E12: =(VLOOKUP('102 5.1.00'!M12,'102 5.1.00'!$AM$4:$AO$55,2,FALSE))*IF('102 5.1.00'!AO$4="是",'102 5.1.00'!$AX$4,'102 5.1.00'!$AX$3) -> 170 | F12: =(VLOOKUP('102 5.1.00'!N12,'102 5.1.00'!$AM$4:$AO$55,2,FALSE))*IF('102 5.1.00'!AP$4="是",'102 5.1.00'!$AX$4,'102 5.1.00'!$AX$3) -> 170 | G12: =(VLOOKUP('102 5.1.00'!O12,'102 5.1.00'!$AM$4:$AO$55,2,FALSE))*IF('102 5.1.00'!AQ$4="是",'102 5.1.00'!$AX$4,'102 5.1.00'!$AX$3) -> 0 | H12: =(VLOOKUP('102 5.1.00'!P12,'102 5.1.00'!$AM$4:$AO$55,2,FALSE))*IF('102 5.1.00'!AR$4="是",'102 5.1.00'!$AX$4,'102 5.1.00'!$AX$3) -> 0 | ... X12: =(VLOOKUP('102 5.1.00'!AF12,'102 5.1.00'!$AM$4:$AO$55,2,FALSE))*IF('102 5.1.00'!BH$4="是",'102 5.1.00'!$AX$4,'102 5.1.00'!$AX$3) -> 0
A13: =(VLOOKUP('102 5.1.00'!I13,'102 5.1.00'!$AM$4:$AO$55,2,FALSE))*IF('102 5.1.00'!AK$4="是",'102 5.1.00'!$AX$4,'102 5.1.00'!$AX$3) -> 170 | B13: =(VLOOKUP('102 5.1.00'!J13,'102 5.1.00'!$AM$4:$AO$55,2,FALSE))*IF('102 5.1.00'!AL$4="是",'102 5.1.00'!$AX$4,'102 5.1.00'!$AX$3) -> 170 | C13: =(VLOOKUP('102 5.1.00'!K13,'102 5.1.00'!$AM$4:$AO$55,2,FALSE))*IF('102 5.1.00'!AM$4="是",'102 5.1.00'!$AX$4,'102 5.1.00'!$AX$3) -> 50 | D13: =(VLOOKUP('102 5.1.00'!L13,'102 5.1.00'!$AM$4:$AO$55,2,FALSE))*IF('102 5.1.00'!AN$4="是",'102 5.1.00'!$AX$4,'102 5.1.00'!$AX$3) -> 170 | E13: =(VLOOKUP('102 5.1.00'!M13,'102 5.1.00'!$AM$4:$AO$55,2,FALSE))*IF('102 5.1.00'!AO$4="是",'102 5.1.00'!$AX$4,'102 5.1.00'!$AX$3) -> 170 | F13: =(VLOOKUP('102 5.1.00'!N13,'102 5.1.00'!$AM$4:$AO$55,2,FALSE))*IF('102 5.1.00'!AP$4="是",'102 5.1.00'!$AX$4,'102 5.1.00'!$AX$3) -> 150 | G13: =(VLOOKUP('102 5.1.00'!O13,'102 5.1.00'!$AM$4:$AO$55,2,FALSE))*IF('102 5.1.00'!AQ$4="是",'102 5.1.00'!$AX$4,'102 5.1.00'!$AX$3) -> 0 | H13: =(VLOOKUP('102 5.1.00'!P13,'102 5.1.00'!$AM$4:$AO$55,2,FALSE))*IF('102 5.1.00'!AR$4="是",'102 5.1.00'!$AX$4,'102 5.1.00'!$AX$3) -> 0 | ... X13: =(VLOOKUP('102 5.1.00'!AF13,'102 5.1.00'!$AM$4:$AO$55,2,FALSE))*IF('102 5.1.00'!BH$4="是",'102 5.1.00'!$AX$4,'102 5.1.00'!$AX$3) -> 0
A14: =(VLOOKUP('102 5.1.00'!I14,'102 5.1.00'!$AM$4:$AO$55,2,FALSE))*IF('102 5.1.00'!AK$4="是",'102 5.1.00'!$AX$4,'102 5.1.00'!$AX$3) -> 170 | B14: =(VLOOKUP('102 5.1.00'!J14,'102 5.1.00'!$AM$4:$AO$55,2,FALSE))*IF('102 5.1.00'!AL$4="是",'102 5.1.00'!$AX$4,'102 5.1.00'!$AX$3) -> 170 | C14: =(VLOOKUP('102 5.1.00'!K14,'102 5.1.00'!$AM$4:$AO$55,2,FALSE))*IF('102 5.1.00'!AM$4="是",'102 5.1.00'!$AX$4,'102 5.1.00'!$AX$3) -> 170 | D14: =(VLOOKUP('102 5.1.00'!L14,'102 5.1.00'!$AM$4:$AO$55,2,FALSE))*IF('102 5.1.00'!AN$4="是",'102 5.1.00'!$AX$4,'102 5.1.00'!$AX$3) -> 170 | E14: =(VLOOKUP('102 5.1.00'!M14,'102 5.1.00'!$AM$4:$AO$55,2,FALSE))*IF('102 5.1.00'!AO$4="是",'102 5.1.00'!$AX$4,'102 5.1.00'!$AX$3) -> 170 | F14: =(VLOOKUP('102 5.1.00'!N14,'102 5.1.00'!$AM$4:$AO$55,2,FALSE))*IF('102 5.1.00'!AP$4="是",'102 5.1.00'!$AX$4,'102 5.1.00'!$AX$3) -> 170 | G14: =(VLOOKUP('102 5.1.00'!O14,'102 5.1.00'!$AM$4:$AO$55,2,FALSE))*IF('102 5.1.00'!AQ$4="是",'102 5.1.00'!$AX$4,'102 5.1.00'!$AX$3) -> 0 | H14: =(VLOOKUP('102 5.1.00'!P14,'102 5.1.00'!$AM$4:$AO$55,2,FALSE))*IF('102 5.1.00'!AR$4="是",'102 5.1.00'!$AX$4,'102 5.1.00'!$AX$3) -> 0 | ... X14: =(VLOOKUP('102 5.1.00'!AF14,'102 5.1.00'!$AM$4:$AO$55,2,FALSE))*IF('102 5.1.00'!BH$4="是",'102 5.1.00'!$AX$4,'102 5.1.00'!$AX$3) -> 0
A15: =(VLOOKUP('102 5.1.00'!I15,'102 5.1.00'!$AM$4:$AO$55,2,FALSE))*IF('102 5.1.00'!AK$4="是",'102 5.1.00'!$AX$4,'102 5.1.00'!$AX$3) -> 170 | B15: =(VLOOKUP('102 5.1.00'!J15,'102 5.1.00'!$AM$4:$AO$55,2,FALSE))*IF('102 5.1.00'!AL$4="是",'102 5.1.00'!$AX$4,'102 5.1.00'!$AX$3) -> 170 | C15: =(VLOOKUP('102 5.1.00'!K15,'102 5.1.00'!$AM$4:$AO$55,2,FALSE))*IF('102 5.1.00'!AM$4="是",'102 5.1.00'!$AX$4,'102 5.1.00'!$AX$3) -> 170 | D15: =(VLOOKUP('102 5.1.00'!L15,'102 5.1.00'!$AM$4:$AO$55,2,FALSE))*IF('102 5.1.00'!AN$4="是",'102 5.1.00'!$AX$4,'102 5.1.00'!$AX$3) -> 170 | E15: =(VLOOKUP('102 5.1.00'!M15,'102 5.1.00'!$AM$4:$AO$55,2,FALSE))*IF('102 5.1.00'!AO$4="是",'102 5.1.00'!$AX$4,'102 5.1.00'!$AX$3) -> 170 | F15: =(VLOOKUP('102 5.1.00'!N15,'102 5.1.00'!$AM$4:$AO$55,2,FALSE))*IF('102 5.1.00'!AP$4="是",'102 5.1.00'!$AX$4,'102 5.1.00'!$AX$3) -> 170 | G15: =(VLOOKUP('102 5.1.00'!O15,'102 5.1.00'!$AM$4:$AO$55,2,FALSE))*IF('102 5.1.00'!AQ$4="是",'102 5.1.00'!$AX$4,'102 5.1.00'!$AX$3) -> 0 | H15: =(VLOOKUP('102 5.1.00'!P15,'102 5.1.00'!$AM$4:$AO$55,2,FALSE))*IF('102 5.1.00'!AR$4="是",'102 5.1.00'!$AX$4,'102 5.1.00'!$AX$3) -> 0 | ... X15: =(VLOOKUP('102 5.1.00'!AF15,'102 5.1.00'!$AM$4:$AO$55,2,FALSE))*IF('102 5.1.00'!BH$4="是",'102 5.1.00'!$AX$4,'102 5.1.00'!$AX$3) -> 0
... A94: =(VLOOKUP('102 5.1.00'!I94,'102 5.1.00'!$AM$4:$AO$55,2,FALSE))*IF('102 5.1.00'!AK$4="是",'102 5.1.00'!$AX$4,'102 5.1.00'!$AX$3) -> 50 | B94: =(VLOOKUP('102 5.1.00'!J94,'102 5.1.00'!$AM$4:$AO$55,2,FALSE))*IF('102 5.1.00'!AL$4="是",'102 5.1.00'!$AX$4,'102 5.1.00'!$AX$3) -> 160 | C94: =(VLOOKUP('102 5.1.00'!K94,'102 5.1.00'!$AM$4:$AO$55,2,FALSE))*IF('102 5.1.00'!AM$4="是",'102 5.1.00'!$AX$4,'102 5.1.00'!$AX$3) -> -200 | D94: =(VLOOKUP('102 5.1.00'!L94,'102 5.1.00'!$AM$4:$AO$55,2,FALSE))*IF('102 5.1.00'!AN$4="是",'102 5.1.00'!$AX$4,'102 5.1.00'!$AX$3) -> 160 | E94: =(VLOOKUP('102 5.1.00'!M94,'102 5.1.00'!$AM$4:$AO$55,2,FALSE))*IF('102 5.1.00'!AO$4="是",'102 5.1.00'!$AX$4,'102 5.1.00'!$AX$3) -> 160 | F94: =(VLOOKUP('102 5.1.00'!N94,'102 5.1.00'!$AM$4:$AO$55,2,FALSE))*IF('102 5.1.00'!AP$4="是",'102 5.1.00'!$AX$4,'102 5.1.00'!$AX$3) -> 160 | G94: =(VLOOKUP('102 5.1.00'!O94,'102 5.1.00'!$AM$4:$AO$55,2,FALSE))*IF('102 5.1.00'!AQ$4="是",'102 5.1.00'!$AX$4,'102 5.1.00'!$AX$3) -> 160 | H94: =(VLOOKUP('102 5.1.00'!P94,'102 5.1.00'!$AM$4:$AO$55,2,FALSE))*IF('102 5.1.00'!AR$4="是",'102 5.1.00'!$AX$4,'102 5.1.00'!$AX$3) -> 50 | ... X94: =(VLOOKUP('102 5.1.00'!AF94,'102 5.1.00'!$AM$4:$AO$55,2,FALSE))*IF('102 5.1.00'!BH$4="是",'102 5.1.00'!$AX$4,'102 5.1.00'!$AX$3) -> 0

Sheet 经验
A2: 队伍一 风 | C2: 步数 | D2: =COUNTIF(A4:H94,"<>空") -> 728 | E2: (不算跳步和传送) | I2: 队伍二 雷 | K2: 步数 | L2: =COUNTIF(I4:P94,"<>空") -> 728 | M2: (不算跳步和传送) | Q2: 队伍三 | S2: 总步数 | T2: =COUNTIF(Q4:X94,"<>空") -> 728 | U2: (不算跳步和传送)
A3: 1 | B3: 2 | C3: 3 | D3: 4 | E3: 5 | F3: 6 | G3: 7 | H3: 8 | I3: 1 | J3: 2 | K3: 3 | L3: 4 | M3: 5 | N3: 6 | O3: 7 | P3: 8 | Q3: 1 | R3: 2 | S3: 3 | T3: 4 | U3: 5 | V3: 6 | W3: 7 | X3: 8
A4: =(VLOOKUP('102 5.1.00'!I4,'102 5.1.00'!$AM$4:$AO$55,3,FALSE)) -> 35 | B4: =(VLOOKUP('102 5.1.00'!J4,'102 5.1.00'!$AM$4:$AO$55,3,FALSE)) -> 35 | C4: =(VLOOKUP('102 5.1.00'!K4,'102 5.1.00'!$AM$4:$AO$55,3,FALSE)) -> 35 | D4: =(VLOOKUP('102 5.1.00'!L4,'102 5.1.00'!$AM$4:$AO$55,3,FALSE)) -> 35 | E4: =(VLOOKUP('102 5.1.00'!M4,'102 5.1.00'!$AM$4:$AO$55,3,FALSE)) -> 35 | F4: =(VLOOKUP('102 5.1.00'!N4,'102 5.1.00'!$AM$4:$AO$55,3,FALSE)) -> 0 | G4: =(VLOOKUP('102 5.1.00'!O4,'102 5.1.00'!$AM$4:$AO$55,3,FALSE)) -> 0 | H4: =(VLOOKUP('102 5.1.00'!P4,'102 5.1.00'!$AM$4:$AO$55,3,FALSE)) -> 0 | ... X4: =(VLOOKUP('102 5.1.00'!AF4,'102 5.1.00'!$AM$4:$AO$55,3,FALSE)) -> 0
A5: =(VLOOKUP('102 5.1.00'!I5,'102 5.1.00'!$AM$4:$AO$55,3,FALSE)) -> 35 | B5: =(VLOOKUP('102 5.1.00'!J5,'102 5.1.00'!$AM$4:$AO$55,3,FALSE)) -> 35 | C5: =(VLOOKUP('102 5.1.00'!K5,'102 5.1.00'!$AM$4:$AO$55,3,FALSE)) -> 35 | D5: =(VLOOKUP('102 5.1.00'!L5,'102 5.1.00'!$AM$4:$AO$55,3,FALSE)) -> 35 | E5: =(VLOOKUP('102 5.1.00'!M5,'102 5.1.00'!$AM$4:$AO$55,3,FALSE)) -> 35 | F5: =(VLOOKUP('102 5.1.00'!N5,'102 5.1.00'!$AM$4:$AO$55,3,FALSE)) -> 0 | G5: =(VLOOKUP('102 5.1.00'!O5,'102 5.1.00'!$AM$4:$AO$55,3,FALSE)) -> 35 | H5: =(VLOOKUP('102 5.1.00'!P5,'102 5.1.00'!$AM$4:$AO$55,3,FALSE)) -> 35 | ... X5: =(VLOOKUP('102 5.1.00'!AF5,'102 5.1.00'!$AM$4:$AO$55,3,FALSE)) -> 0
A6: =(VLOOKUP('102 5.1.00'!I6,'102 5.1.00'!$AM$4:$AO$55,3,FALSE)) -> 40 | B6: =(VLOOKUP('102 5.1.00'!J6,'102 5.1.00'!$AM$4:$AO$55,3,FALSE)) -> 40 | C6: =(VLOOKUP('102 5.1.00'!K6,'102 5.1.00'!$AM$4:$AO$55,3,FALSE)) -> 40 | D6: =(VLOOKUP('102 5.1.00'!L6,'102 5.1.00'!$AM$4:$AO$55,3,FALSE)) -> 40 | E6: =(VLOOKUP('102 5.1.00'!M6,'102 5.1.00'!$AM$4:$AO$55,3,FALSE)) -> 40 | F6: =(VLOOKUP('102 5.1.00'!N6,'102 5.1.00'!$AM$4:$AO$55,3,FALSE)) -> 40 | G6: =(VLOOKUP('102 5.1.00'!O6,'102 5.1.00'!$AM$4:$AO$55,3,FALSE)) -> 0 | H6: =(VLOOKUP('102 5.1.00'!P6,'102 5.1.00'!$AM$4:$AO$55,3,FALSE)) -> 0 | ... X6: =(VLOOKUP('102 5.1.00'!AF6,'102 5.1.00'!$AM$4:$AO$55,3,FALSE)) -> 0
A7: =(VLOOKUP('102 5.1.00'!I7,'102 5.1.00'!$AM$4:$AO$55,3,FALSE)) -> 40 | B7: =(VLOOKUP('102 5.1.00'!J7,'102 5.1.00'!$AM$4:$AO$55,3,FALSE)) -> 45 | C7: =(VLOOKUP('102 5.1.00'!K7,'102 5.1.00'!$AM$4:$AO$55,3,FALSE)) -> 45 | D7: =(VLOOKUP('102 5.1.00'!L7,'102 5.1.00'!$AM$4:$AO$55,3,FALSE)) -> 45 | E7: =(VLOOKUP('102 5.1.00'!M7,'102 5.1.00'!$AM$4:$AO$55,3,FALSE)) -> 45 | F7: =(VLOOKUP('102 5.1.00'!N7,'102 5.1.00'!$AM$4:$AO$55,3,FALSE)) -> 45 | G7: =(VLOOKUP('102 5.1.00'!O7,'102 5.1.00'!$AM$4:$AO$55,3,FALSE)) -> 0 | H7: =(VLOOKUP('102 5.1.00'!P7,'102 5.1.00'!$AM$4:$AO$55,3,FALSE)) -> 0 | ... X7: =(VLOOKUP('102 5.1.00'!AF7,'102 5.1.00'!$AM$4:$AO$55,3,FALSE)) -> 0
A8: =(VLOOKUP('102 5.1.00'!I8,'102 5.1.00'!$AM$4:$AO$55,3,FALSE)) -> 45 | B8: =(VLOOKUP('102 5.1.00'!J8,'102 5.1.00'!$AM$4:$AO$55,3,FALSE)) -> 30 | C8: =(VLOOKUP('102 5.1.00'!K8,'102 5.1.00'!$AM$4:$AO$55,3,FALSE)) -> 45 | D8: =(VLOOKUP('102 5.1.00'!L8,'102 5.1.00'!$AM$4:$AO$55,3,FALSE)) -> 45 | E8: =(VLOOKUP('102 5.1.00'!M8,'102 5.1.00'!$AM$4:$AO$55,3,FALSE)) -> 45 | F8: =(VLOOKUP('102 5.1.00'!N8,'102 5.1.00'!$AM$4:$AO$55,3,FALSE)) -> 45 | G8: =(VLOOKUP('102 5.1.00'!O8,'102 5.1.00'!$AM$4:$AO$55,3,FALSE)) -> 0 | H8: =(VLOOKUP('102 5.1.00'!P8,'102 5.1.00'!$AM$4:$AO$55,3,FALSE)) -> 0 | ... X8: =(VLOOKUP('102 5.1.00'!AF8,'102 5.1.00'!$AM$4:$AO$55,3,FALSE)) -> 0
A9: =(VLOOKUP('102 5.1.00'!I9,'102 5.1.00'!$AM$4:$AO$55,3,FALSE)) -> 45 | B9: =(VLOOKUP('102 5.1.00'!J9,'102 5.1.00'!$AM$4:$AO$55,3,FALSE)) -> 50 | C9: =(VLOOKUP('102 5.1.00'!K9,'102 5.1.00'!$AM$4:$AO$55,3,FALSE)) -> 45 | D9: =(VLOOKUP('102 5.1.00'!L9,'102 5.1.00'!$AM$4:$AO$55,3,FALSE)) -> 45 | E9: =(VLOOKUP('102 5.1.00'!M9,'102 5.1.00'!$AM$4:$AO$55,3,FALSE)) -> 0 | F9: =(VLOOKUP('102 5.1.00'!N9,'102 5.1.00'!$AM$4:$AO$55,3,FALSE)) -> 45 | G9: =(VLOOKUP('102 5.1.00'!O9,'102 5.1.00'!$AM$4:$AO$55,3,FALSE)) -> 45 | H9: =(VLOOKUP('102 5.1.00'!P9,'102 5.1.00'!$AM$4:$AO$55,3,FALSE)) -> 0 | ... X9: =(VLOOKUP('102 5.1.00'!AF9,'102 5.1.00'!$AM$4:$AO$55,3,FALSE)) -> 0
A10: =(VLOOKUP('102 5.1.00'!I10,'102 5.1.00'!$AM$4:$AO$55,3,FALSE)) -> 45 | B10: =(VLOOKUP('102 5.1.00'!J10,'102 5.1.00'!$AM$4:$AO$55,3,FALSE)) -> 45 | C10: =(VLOOKUP('102 5.1.00'!K10,'102 5.1.00'!$AM$4:$AO$55,3,FALSE)) -> 45 | D10: =(VLOOKUP('102 5.1.00'!L10,'102 5.1.00'!$AM$4:$AO$55,3,FALSE)) -> 45 | E10: =(VLOOKUP('102 5.1.00'!M10,'102 5.1.00'!$AM$4:$AO$55,3,FALSE)) -> 45 | F10: =(VLOOKUP('102 5.1.00'!N10,'102 5.1.00'!$AM$4:$AO$55,3,FALSE)) -> 30 | G10: =(VLOOKUP('102 5.1.00'!O10,'102 5.1.00'!$AM$4:$AO$55,3,FALSE)) -> 0 | H10: =(VLOOKUP('102 5.1.00'!P10,'102 5.1.00'!$AM$4:$AO$55,3,FALSE)) -> 0 | ... X10: =(VLOOKUP('102 5.1.00'!AF10,'102 5.1.00'!$AM$4:$AO$55,3,FALSE)) -> 0
A11: =(VLOOKUP('102 5.1.00'!I11,'102 5.1.00'!$AM$4:$AO$55,3,FALSE)) -> 45 | B11: =(VLOOKUP('102 5.1.00'!J11,'102 5.1.00'!$AM$4:$AO$55,3,FALSE)) -> 45 | C11: =(VLOOKUP('102 5.1.00'!K11,'102 5.1.00'!$AM$4:$AO$55,3,FALSE)) -> 45 | D11: =(VLOOKUP('102 5.1.00'!L11,'102 5.1.00'!$AM$4:$AO$55,3,FALSE)) -> 200 | E11: =(VLOOKUP('102 5.1.00'!M11,'102 5.1.00'!$AM$4:$AO$55,3,FALSE)) -> 45 | F11: =(VLOOKUP('102 5.1.00'!N11,'102 5.1.00'!$AM$4:$AO$55,3,FALSE)) -> 45 | G11: =(VLOOKUP('102 5.1.00'!O11,'102 5.1.00'!$AM$4:$AO$55,3,FALSE)) -> 0 | H11: =(VLOOKUP('102 5.1.00'!P11,'102 5.1.00'!$AM$4:$AO$55,3,FALSE)) -> 0 | ... X11: =(VLOOKUP('102 5.1.00'!AF11,'102 5.1.00'!$AM$4:$AO$55,3,FALSE)) -> 0
A12: =(VLOOKUP('102 5.1.00'!I12,'102 5.1.00'!$AM$4:$AO$55,3,FALSE)) -> 45 | B12: =(VLOOKUP('102 5.1.00'!J12,'102 5.1.00'!$AM$4:$AO$55,3,FALSE)) -> 45 | C12: =(VLOOKUP('102 5.1.00'!K12,'102 5.1.00'!$AM$4:$AO$55,3,FALSE)) -> 45 | D12: =(VLOOKUP('102 5.1.00'!L12,'102 5.1.00'!$AM$4:$AO$55,3,FALSE)) -> 45 | E12: =(VLOOKUP('102 5.1.00'!M12,'102 5.1.00'!$AM$4:$AO$55,3,FALSE)) -> 45 | F12: =(VLOOKUP('102 5.1.00'!N12,'102 5.1.00'!$AM$4:$AO$55,3,FALSE)) -> 45 | G12: =(VLOOKUP('102 5.1.00'!O12,'102 5.1.00'!$AM$4:$AO$55,3,FALSE)) -> 0 | H12: =(VLOOKUP('102 5.1.00'!P12,'102 5.1.00'!$AM$4:$AO$55,3,FALSE)) -> 0 | ... X12: =(VLOOKUP('102 5.1.00'!AF12,'102 5.1.00'!$AM$4:$AO$55,3,FALSE)) -> 0
A13: =(VLOOKUP('102 5.1.00'!I13,'102 5.1.00'!$AM$4:$AO$55,3,FALSE)) -> 45 | B13: =(VLOOKUP('102 5.1.00'!J13,'102 5.1.00'!$AM$4:$AO$55,3,FALSE)) -> 45 | C13: =(VLOOKUP('102 5.1.00'!K13,'102 5.1.00'!$AM$4:$AO$55,3,FALSE)) -> 30 | D13: =(VLOOKUP('102 5.1.00'!L13,'102 5.1.00'!$AM$4:$AO$55,3,FALSE)) -> 45 | E13: =(VLOOKUP('102 5.1.00'!M13,'102 5.1.00'!$AM$4:$AO$55,3,FALSE)) -> 45 | F13: =(VLOOKUP('102 5.1.00'!N13,'102 5.1.00'!$AM$4:$AO$55,3,FALSE)) -> 40 | G13: =(VLOOKUP('102 5.1.00'!O13,'102 5.1.00'!$AM$4:$AO$55,3,FALSE)) -> 0 | H13: =(VLOOKUP('102 5.1.00'!P13,'102 5.1.00'!$AM$4:$AO$55,3,FALSE)) -> 0 | ... X13: =(VLOOKUP('102 5.1.00'!AF13,'102 5.1.00'!$AM$4:$AO$55,3,FALSE)) -> 0
A14: =(VLOOKUP('102 5.1.00'!I14,'102 5.1.00'!$AM$4:$AO$55,3,FALSE)) -> 45 | B14: =(VLOOKUP('102 5.1.00'!J14,'102 5.1.00'!$AM$4:$AO$55,3,FALSE)) -> 45 | C14: =(VLOOKUP('102 5.1.00'!K14,'102 5.1.00'!$AM$4:$AO$55,3,FALSE)) -> 45 | D14: =(VLOOKUP('102 5.1.00'!L14,'102 5.1.00'!$AM$4:$AO$55,3,FALSE)) -> 45 | E14: =(VLOOKUP('102 5.1.00'!M14,'102 5.1.00'!$AM$4:$AO$55,3,FALSE)) -> 45 | F14: =(VLOOKUP('102 5.1.00'!N14,'102 5.1.00'!$AM$4:$AO$55,3,FALSE)) -> 45 | G14: =(VLOOKUP('102 5.1.00'!O14,'102 5.1.00'!$AM$4:$AO$55,3,FALSE)) -> 0 | H14: =(VLOOKUP('102 5.1.00'!P14,'102 5.1.00'!$AM$4:$AO$55,3,FALSE)) -> 0 | ... X14: =(VLOOKUP('102 5.1.00'!AF14,'102 5.1.00'!$AM$4:$AO$55,3,FALSE)) -> 0
A15: =(VLOOKUP('102 5.1.00'!I15,'102 5.1.00'!$AM$4:$AO$55,3,FALSE)) -> 45 | B15: =(VLOOKUP('102 5.1.00'!J15,'102 5.1.00'!$AM$4:$AO$55,3,FALSE)) -> 45 | C15: =(VLOOKUP('102 5.1.00'!K15,'102 5.1.00'!$AM$4:$AO$55,3,FALSE)) -> 45 | D15: =(VLOOKUP('102 5.1.00'!L15,'102 5.1.00'!$AM$4:$AO$55,3,FALSE)) -> 45 | E15: =(VLOOKUP('102 5.1.00'!M15,'102 5.1.00'!$AM$4:$AO$55,3,FALSE)) -> 45 | F15: =(VLOOKUP('102 5.1.00'!N15,'102 5.1.00'!$AM$4:$AO$55,3,FALSE)) -> 45 | G15: =(VLOOKUP('102 5.1.00'!O15,'102 5.1.00'!$AM$4:$AO$55,3,FALSE)) -> 0 | H15: =(VLOOKUP('102 5.1.00'!P15,'102 5.1.00'!$AM$4:$AO$55,3,FALSE)) -> 0 | ... X15: =(VLOOKUP('102 5.1.00'!AF15,'102 5.1.00'!$AM$4:$AO$55,3,FALSE)) -> 0
... A94: =(VLOOKUP('102 5.1.00'!I94,'102 5.1.00'!$AM$4:$AO$55,3,FALSE)) -> 30 | B94: =(VLOOKUP('102 5.1.00'!J94,'102 5.1.00'!$AM$4:$AO$55,3,FALSE)) -> 40 | C94: =(VLOOKUP('102 5.1.00'!K94,'102 5.1.00'!$AM$4:$AO$55,3,FALSE)) -> 0 | D94: =(VLOOKUP('102 5.1.00'!L94,'102 5.1.00'!$AM$4:$AO$55,3,FALSE)) -> 40 | E94: =(VLOOKUP('102 5.1.00'!M94,'102 5.1.00'!$AM$4:$AO$55,3,FALSE)) -> 40 | F94: =(VLOOKUP('102 5.1.00'!N94,'102 5.1.00'!$AM$4:$AO$55,3,FALSE)) -> 40 | G94: =(VLOOKUP('102 5.1.00'!O94,'102 5.1.00'!$AM$4:$AO$55,3,FALSE)) -> 40 | H94: =(VLOOKUP('102 5.1.00'!P94,'102 5.1.00'!$AM$4:$AO$55,3,FALSE)) -> 30 | ... X94: =(VLOOKUP('102 5.1.00'!AF94,'102 5.1.00'!$AM$4:$AO$55,3,FALSE)) -> 0
