Workbook

Sheet 102.5.1.05qq test
A1: =(_xlfn.DAYS(TODAY(),A4)+2)/((_xlfn.DAYS(A94,A4))+1) -> 8.989011 | H1: 工作区 | AL1: 使用方法：按自己规划的路线，将下表中的地块名复制粘贴至工作区。初次使用传送门，当天跳步次数+5。重复使用传送门，当天跳步次数+1
A2: version 5.1.05qq | C2: 合计经验 | E2: =SUM(E4:E94)+SUM(G4:G94) -> 61465 | H2: 队伍一 风 | J2: 步数 | K2: =COUNTIF(H4:O94,"<>空")-3 -> 553 | L2: (不算跳步和传送) | P2: 队伍二 雷 | R2: 步数 | S2: =COUNTIF(P4:W94,"<>空") -> 470 | T2: (不算跳步和传送) | X2: 队伍三 | Z2: 总步数 | AA2: =COUNTIF(X4:AE94,"<>空") -> 0 | AB2: (不算跳步和传送) | AF2: =SUM(AF4:AF94) -> 33 | AG2: =SUM(AG4:AG94) -> 14 | AH2: =SUM(AH4:AH94) -> 19 | AI2: =SUM(AI4:AI94) -> 0 | AJ2: 八卦全开 | AW2: 粮草系数
A3: 日期 | B3: 获得粮草 | C3: 消耗粮草 | D3: 剩余粮草 | E3: 获得经验 | F3: 累计经验 | G3: 任务经验 | H3: 1 | I3: 2 | J3: 3 | K3: 4 | L3: 5 | M3: 6 | N3: 7 | O3: 8 | P3: 1 | Q3: 2 | R3: 3 | S3: 4 | T3: 5 | U3: 6 | V3: 7 | W3: 8 | X3: 1 | Y3: 2 | Z3: 3 | AA3: 4 | AB3: 5 | AC3: 6 | AD3: 7 | AE3: 8 | AF3: 跳步次数 | AG3: 1队跳步 | AH3: 2队跳步 | AI3: 3队跳步 | AL3: 地块 | AM3: 粮草 | AN3: 经验 | AO3: 一队地块 | AP3: 二队地块 | AQ3: 三队地块 | AR3: 总地块 | AS3: 一队经验 | AT3: 二队经验 | AU3: 三队经验 | AV3: 八卦前 | AW3: 1
A4: 44456 | B4: 800 | C4: {=(SUM(VLOOKUP(H4:AE4,$AL$4:$AN$44,2,FALSE))+AF4*10)*IF(AJ4="是",$AW$4,$AW$3)} -> 750 | D4: =SUM($B$4:B4)-SUM($C$4:C4) -> 50 | E4: {=SUM(VLOOKUP(H4:AE4,$AL$4:$AN$44,3,FALSE))} -> 175 | F4: =SUM($E$4:E4)+SUM($G$4:G4) -> 175 | G4: 0 | H4: 1级 | I4: 1级 | J4: 1级 | K4: 1级 | L4: 1级 | M4: 空 | N4: 空 | O4: 空 | P4: 空 | Q4: 空 | R4: 空 | S4: 空 | T4: 空 | U4: 空 | V4: 空 | W4: 空 | X4: 空 | Y4: 空 | Z4: 空 | AA4: 空 | AB4: 空 | AC4: 空 | AD4: 空 | AE4: 空 | AF4: 0 | AJ4: 否 | AL4: 1级 | AM4: 150 | AN4: 35 | AO4: =COUNTIF($H$4:$O$94,AL4) -> 14 | AP4: =COUNTIF($P$4:$W$94,AL4) -> 10 | AQ4: =COUNTIF($X$4:$AE$94,AL4) -> 0 | AR4: =AO4+AP4+AQ4 -> 24 | AS4: =AO4*$AN4 -> 490 | AT4: =AP4*$AN4 -> 350 | AU4: =AQ4*$AN4 -> 0 | AV4: 八卦后 | AW4: 0.8 | AY4: =AM4*0.8 -> 120
A5: 44457 | B5: 1600 | C5: {=(SUM(VLOOKUP(H5:AE5,$AL$4:$AN$44,2,FALSE))+AF5*10)*IF(AJ5="是",$AW$4,$AW$3)} -> 900 | D5: =SUM($B$4:B5)-SUM($C$4:C5) -> 750 | E5: {=SUM(VLOOKUP(H5:AE5,$AL$4:$AN$44,3,FALSE))} -> 210 | F5: =SUM($E$4:E5)+SUM($G$4:G5) -> 885 | G5: 500 | H5: 1级 | I5: 1级 | J5: 1级 | K5: 1级 | L5: 1级 | M5: 1级 | N5: 空 | O5: 空 | P5: 空 | Q5: 空 | R5: 空 | S5: 空 | T5: 空 | U5: 空 | V5: 空 | W5: 空 | X5: 空 | Y5: 空 | Z5: 空 | AA5: 空 | AB5: 空 | AC5: 空 | AD5: 空 | AE5: 空 | AF5: 0 | AJ5: 否 | AL5: 2级 | AM5: 160 | AN5: 40 | AO5: =COUNTIF($H$4:$O$94,AL5) -> 20 | AP5: =COUNTIF($P$4:$W$94,AL5) -> 11 | AQ5: =COUNTIF($X$4:$AE$94,AL5) -> 0 | AR5: =AO5+AP5+AQ5 -> 31 | AS5: =AO5*$AN5 -> 800 | AT5: =AP5*$AN5 -> 440 | AU5: =AQ5*$AN5 -> 0 | AV5: Note：开完八卦当天可能需要手动计算粮草 | AY5: =AM5*0.8 -> 128
A6: 44458 | B6: 1600 | C6: {=(SUM(VLOOKUP(H6:AE6,$AL$4:$AN$44,2,FALSE))+AF6*10)*IF(AJ6="是",$AW$4,$AW$3)} -> 760 | D6: =SUM($B$4:B6)-SUM($C$4:C6) -> 1590 | E6: {=SUM(VLOOKUP(H6:AE6,$AL$4:$AN$44,3,FALSE))} -> 205 | F6: =SUM($E$4:E6)+SUM($G$4:G6) -> 1090 | G6: 0 | H6: 1级 | I6: 1级 | J6: 商人 | K6: 1级 | L6: 2级 | M6: 商人 | N6: 空 | O6: 空 | P6: 空 | Q6: 空 | R6: 空 | S6: 空 | T6: 空 | U6: 空 | V6: 空 | W6: 空 | X6: 空 | Y6: 空 | Z6: 空 | AA6: 空 | AB6: 空 | AC6: 空 | AD6: 空 | AE6: 空 | AF6: 5 | AG6: 5 | AJ6: 否 | AL6: 3级 | AM6: 170 | AN6: 45 | AO6: =COUNTIF($H$4:$O$94,AL6) -> 105 | AP6: =COUNTIF($P$4:$W$94,AL6) -> 84 | AQ6: =COUNTIF($X$4:$AE$94,AL6) -> 0 | AR6: =AO6+AP6+AQ6 -> 189 | AS6: =AO6*$AN6 -> 4725 | AT6: =AP6*$AN6 -> 3780 | AU6: =AQ6*$AN6 -> 0 | AY6: =AM6*0.8 -> 136
A7: 44459 | B7: 1600 | C7: {=(SUM(VLOOKUP(H7:AE7,$AL$4:$AN$44,2,FALSE))+AF7*10)*IF(AJ7="是",$AW$4,$AW$3)} -> 970 | D7: =SUM($B$4:B7)-SUM($C$4:C7) -> 2220 | E7: {=SUM(VLOOKUP(H7:AE7,$AL$4:$AN$44,3,FALSE))} -> 250 | F7: =SUM($E$4:E7)+SUM($G$4:G7) -> 1640 | G7: 300 | H7: 2级 | I7: 2级 | J7: 塔2 | K7: 2级 | L7: 3级 | M7: 3级 | N7: 空 | O7: 空 | P7: 空 | Q7: 空 | R7: 空 | S7: 空 | T7: 空 | U7: 空 | V7: 空 | W7: 空 | X7: 空 | Y7: 空 | Z7: 空 | AA7: 空 | AB7: 空 | AC7: 空 | AD7: 空 | AE7: 空 | AF7: 0 | AJ7: 否 | AL7: 4级 | AM7: 180 | AN7: 50 | AO7: =COUNTIF($H$4:$O$94,AL7) -> 137 | AP7: =COUNTIF($P$4:$W$94,AL7) -> 130 | AQ7: =COUNTIF($X$4:$AE$94,AL7) -> 0 | AR7: =AO7+AP7+AQ7 -> 267 | AS7: =AO7*$AN7 -> 6850 | AT7: =AP7*$AN7 -> 6500 | AU7: =AQ7*$AN7 -> 0 | AY7: =AM7*0.8 -> 144
A8: 44460 | B8: 1600 | C8: {=(SUM(VLOOKUP(H8:AE8,$AL$4:$AN$44,2,FALSE))+AF8*10)*IF(AJ8="是",$AW$4,$AW$3)} -> 1030 | D8: =SUM($B$4:B8)-SUM($C$4:C8) -> 2790 | E8: {=SUM(VLOOKUP(H8:AE8,$AL$4:$AN$44,3,FALSE))} -> 270 | F8: =SUM($E$4:E8)+SUM($G$4:G8) -> 1910 | G8: 0 | H8: 3级 | I8: 3级 | J8: 艮震巽坎乾 | K8: 3级 | L8: 3级 | M8: 3级 | N8: 空 | O8: 空 | P8: 空 | Q8: 空 | R8: 空 | S8: 空 | T8: 空 | U8: 空 | V8: 空 | W8: 空 | X8: 空 | Y8: 空 | Z8: 空 | AA8: 空 | AB8: 空 | AC8: 空 | AD8: 空 | AE8: 空 | AF8: 1 | AG8: 1 | AJ8: 否 | AL8: 5级 | AM8: 190 | AN8: 55 | AO8: =COUNTIF($H$4:$O$94,AL8) -> 116 | AP8: =COUNTIF($P$4:$W$94,AL8) -> 120 | AQ8: =COUNTIF($X$4:$AE$94,AL8) -> 0 | AR8: =AO8+AP8+AQ8 -> 236 | AS8: =AO8*$AN8 -> 6380 | AT8: =AP8*$AN8 -> 6600 | AU8: =AQ8*$AN8 -> 0 | AY8: =AM8*0.8 -> 152
A9: 44461 | B9: 1600 | C9: {=(SUM(VLOOKUP(H9:AE9,$AL$4:$AN$44,2,FALSE))+AF9*10)*IF(AJ9="是",$AW$4,$AW$3)} -> 1020 | D9: =SUM($B$4:B9)-SUM($C$4:C9) -> 3370 | E9: {=SUM(VLOOKUP(H9:AE9,$AL$4:$AN$44,3,FALSE))} -> 270 | F9: =SUM($E$4:E9)+SUM($G$4:G9) -> 2380 | G9: 200 | H9: 3级 | I9: 3级 | J9: 3级 | K9: 3级 | L9: 3级 | M9: 3级 | N9: 空 | O9: 空 | P9: 空 | Q9: 空 | R9: 空 | S9: 空 | T9: 空 | U9: 空 | V9: 空 | W9: 空 | X9: 空 | Y9: 空 | Z9: 空 | AA9: 空 | AB9: 空 | AC9: 空 | AD9: 空 | AE9: 空 | AF9: 0 | AJ9: 否 | AL9: 6级 | AM9: 200 | AN9: 60 | AO9: =COUNTIF($H$4:$O$94,AL9) -> 118 | AP9: =COUNTIF($P$4:$W$94,AL9) -> 76 | AQ9: =COUNTIF($X$4:$AE$94,AL9) -> 0 | AR9: =AO9+AP9+AQ9 -> 194 | AS9: =AO9*$AN9 -> 7080 | AT9: =AP9*$AN9 -> 4560 | AU9: =AQ9*$AN9 -> 0 | AY9: =AM9*0.8 -> 160
A10: 44462 | B10: 1600 | C10: {=(SUM(VLOOKUP(H10:AE10,$AL$4:$AN$44,2,FALSE))+AF10*10)*IF(AJ10="是",$AW$4,$AW$3)} -> 870 | D10: =SUM($B$4:B10)-SUM($C$4:C10) -> 4100 | E10: {=SUM(VLOOKUP(H10:AE10,$AL$4:$AN$44,3,FALSE))} -> 245 | F10: =SUM($E$4:E10)+SUM($G$4:G10) -> 2625 | G10: 0 | H10: 塔2 | I10: 2级 | J10: 3级 | K10: 3级 | L10: 商人 | M10: 3级 | N10: 空 | O10: 空 | P10: 空 | Q10: 空 | R10: 空 | S10: 空 | T10: 空 | U10: 空 | V10: 空 | W10: 空 | X10: 空 | Y10: 空 | Z10: 空 | AA10: 空 | AB10: 空 | AC10: 空 | AD10: 空 | AE10: 空 | AF10: 0 | AJ10: 否 | AL10: 塔1 | AM10: 150 | AN10: 35 | AO10: =COUNTIF($H$4:$O$94,AL10) -> 0 | AP10: =COUNTIF($P$4:$W$94,AL10) -> 0 | AQ10: =COUNTIF($X$4:$AE$94,AL10) -> 0 | AR10: =AO10+AP10+AQ10 -> 0 | AS10: =AO10*$AN10 -> 0 | AT10: =AP10*$AN10 -> 0 | AU10: =AQ10*$AN10 -> 0 | AY10: =AM10*0.8 -> 120
A11: 44463 | B11: 1600 | C11: {=(SUM(VLOOKUP(H11:AE11,$AL$4:$AN$44,2,FALSE))+AF11*10)*IF(AJ11="是",$AW$4,$AW$3)} -> 1170 | D11: =SUM($B$4:B11)-SUM($C$4:C11) -> 4530 | E11: {=SUM(VLOOKUP(H11:AE11,$AL$4:$AN$44,3,FALSE))} -> 470 | F11: =SUM($E$4:E11)+SUM($G$4:G11) -> 3095 | G11: 0 | H11: 艮震巽坎乾 | I11: 3级 | J11: 3级 | K11: 营地 | L11: 3级 | M11: 离兑坤 | N11: 3级 | O11: 3级 | P11: 空 | Q11: 空 | R11: 空 | S11: 空 | T11: 空 | U11: 空 | V11: 空 | W11: 空 | X11: 空 | Y11: 空 | Z11: 空 | AA11: 空 | AB11: 空 | AC11: 空 | AD11: 空 | AE11: 空 | AF11: 5 | AG11: 5 | AJ11: 否 | AL11: 塔2 | AM11: 150 | AN11: 40 | AO11: =COUNTIF($H$4:$O$94,AL11) -> 5 | AP11: =COUNTIF($P$4:$W$94,AL11) -> 1 | AQ11: =COUNTIF($X$4:$AE$94,AL11) -> 0 | AR11: =AO11+AP11+AQ11 -> 6 | AS11: =AO11*$AN11 -> 200 | AT11: =AP11*$AN11 -> 40 | AU11: =AQ11*$AN11 -> 0 | AY11: =AM11*0.8 -> 120
A12: 44464 | B12: 1600 | C12: {=(SUM(VLOOKUP(H12:AE12,$AL$4:$AN$44,2,FALSE))+AF12*10)*IF(AJ12="是",$AW$4,$AW$3)} -> 1020 | D12: =SUM($B$4:B12)-SUM($C$4:C12) -> 5110 | E12: {=SUM(VLOOKUP(H12:AE12,$AL$4:$AN$44,3,FALSE))} -> 270 | F12: =SUM($E$4:E12)+SUM($G$4:G12) -> 3365 | G12: 0 | H12: 3级 | I12: 3级 | J12: 3级 | K12: 3级 | L12: 3级 | M12: 3级 | N12: 空 | O12: 空 | P12: 空 | Q12: 空 | R12: 空 | S12: 空 | T12: 空 | U12: 空 | V12: 空 | W12: 空 | X12: 空 | Y12: 空 | Z12: 空 | AA12: 空 | AB12: 空 | AC12: 空 | AD12: 空 | AE12: 空 | AF12: 0 | AJ12: 否 | AL12: 塔3 | AM12: 150 | AN12: 45 | AO12: =COUNTIF($H$4:$O$94,AL12) -> 4 | AP12: =COUNTIF($P$4:$W$94,AL12) -> 2 | AQ12: =COUNTIF($X$4:$AE$94,AL12) -> 0 | AR12: =AO12+AP12+AQ12 -> 6 | AS12: =AO12*$AN12 -> 180 | AT12: =AP12*$AN12 -> 90 | AU12: =AQ12*$AN12 -> 0 | AY12: =AM12*0.8 -> 120
A13: 44465 | B13: 1600 | C13: {=(SUM(VLOOKUP(H13:AE13,$AL$4:$AN$44,2,FALSE))+AF13*10)*IF(AJ13="是",$AW$4,$AW$3)} -> 1100 | D13: =SUM($B$4:B13)-SUM($C$4:C13) -> 5610 | E13: {=SUM(VLOOKUP(H13:AE13,$AL$4:$AN$44,3,FALSE))} -> 425 | F13: =SUM($E$4:E13)+SUM($G$4:G13) -> 3790 | G13: 0 | H13: 艮震巽坎乾 | I13: 3级 | J13: 3级 | K13: 3级 | L13: 3级 | M13: 离兑坤 | N13: 空 | O13: 空 | P13: 空 | Q13: 空 | R13: 空 | S13: 空 | T13: 空 | U13: 空 | V13: 空 | W13: 空 | X13: 空 | Y13: 空 | Z13: 空 | AA13: 空 | AB13: 空 | AC13: 空 | AD13: 空 | AE13: 空 | AF13: 0 | AJ13: 否 | AL13: 塔4 | AM13: 150 | AN13: 50 | AO13: =COUNTIF($H$4:$O$94,AL13) -> 1 | AP13: =COUNTIF($P$4:$W$94,AL13) -> 3 | AQ13: =COUNTIF($X$4:$AE$94,AL13) -> 0 | AR13: =AO13+AP13+AQ13 -> 4 | AS13: =AO13*$AN13 -> 50 | AT13: =AP13*$AN13 -> 150 | AU13: =AQ13*$AN13 -> 0 | AY13: =AM13*0.8 -> 120
A14: 44466 | B14: 1600 | C14: {=(SUM(VLOOKUP(H14:AE14,$AL$4:$AN$44,2,FALSE))+AF14*10)*IF(AJ14="是",$AW$4,$AW$3)} -> 890 | D14: =SUM($B$4:B14)-SUM($C$4:C14) -> 6320 | E14: {=SUM(VLOOKUP(H14:AE14,$AL$4:$AN$44,3,FALSE))} -> 250 | F14: =SUM($E$4:E14)+SUM($G$4:G14) -> 4340 | G14: 300 | H14: 3级 | I14: 3级 | J14: 商人 | K14: 3级 | L14: 3级 | M14: 2级 | N14: 空 | O14: 空 | P14: 空 | Q14: 空 | R14: 空 | S14: 空 | T14: 空 | U14: 空 | V14: 空 | W14: 空 | X14: 空 | Y14: 空 | Z14: 空 | AA14: 空 | AB14: 空 | AC14: 空 | AD14: 空 | AE14: 空 | AF14: 0 | AJ14: 否 | AL14: 塔5 | AM14: 150 | AN14: 55 | AO14: =COUNTIF($H$4:$O$94,AL14) -> 1 | AP14: =COUNTIF($P$4:$W$94,AL14) -> 2 | AQ14: =COUNTIF($X$4:$AE$94,AL14) -> 0 | AR14: =AO14+AP14+AQ14 -> 3 | AS14: =AO14*$AN14 -> 55 | AT14: =AP14*$AN14 -> 110 | AU14: =AQ14*$AN14 -> 0 | AY14: =AM14*0.8 -> 120
A15: 44467 | B15: 1600 | C15: {=(SUM(VLOOKUP(H15:AE15,$AL$4:$AN$44,2,FALSE))+AF15*10)*IF(AJ15="是",$AW$4,$AW$3)} -> 970 | D15: =SUM($B$4:B15)-SUM($C$4:C15) -> 6950 | E15: {=SUM(VLOOKUP(H15:AE15,$AL$4:$AN$44,3,FALSE))} -> 250 | F15: =SUM($E$4:E15)+SUM($G$4:G15) -> 4590 | G15: 0 | H15: 2级 | I15: 2级 | J15: 2级 | K15: 塔2 | L15: 3级 | M15: 艮震巽坎乾 | N15: 空 | O15: 空 | P15: 空 | Q15: 空 | R15: 空 | S15: 空 | T15: 空 | U15: 空 | V15: 空 | W15: 空 | X15: 空 | Y15: 空 | Z15: 空 | AA15: 空 | AB15: 空 | AC15: 空 | AD15: 空 | AE15: 空 | AF15: 0 | AJ15: 否 | AL15: 塔6 | AM15: 150 | AN15: 60 | AO15: =COUNTIF($H$4:$O$94,AL15) -> 1 | AP15: =COUNTIF($P$4:$W$94,AL15) -> 0 | AQ15: =COUNTIF($X$4:$AE$94,AL15) -> 0 | AR15: =AO15+AP15+AQ15 -> 1 | AS15: =AO15*$AN15 -> 60 | AT15: =AP15*$AN15 -> 0 | AU15: =AQ15*$AN15 -> 0 | AY15: =AM15*0.8 -> 120
A16: 44468 | B16: 1600 | C16: {=(SUM(VLOOKUP(H16:AE16,$AL$4:$AN$44,2,FALSE))+AF16*10)*IF(AJ16="是",$AW$4,$AW$3)} -> 1000 | D16: =SUM($B$4:B16)-SUM($C$4:C16) -> 7550 | E16: {=SUM(VLOOKUP(H16:AE16,$AL$4:$AN$44,3,FALSE))} -> 270 | F16: =SUM($E$4:E16)+SUM($G$4:G16) -> 5060 | G16: 200 | H16: 3级 | I16: 3级 | J16: 3级 | K16: 塔3 | L16: 3级 | M16: 3级 | N16: 空 | O16: 空 | P16: 空 | Q16: 空 | R16: 空 | S16: 空 | T16: 空 | U16: 空 | V16: 空 | W16: 空 | X16: 空 | Y16: 空 | Z16: 空 | AA16: 空 | AB16: 空 | AC16: 空 | AD16: 空 | AE16: 空 | AF16: 0 | AJ16: 否 | AL16: 遗迹 | AM16: 150 | AN16: 35 | AO16: =COUNTIF($H$4:$O$94,AL16) -> 0 | AP16: =COUNTIF($P$4:$W$94,AL16) -> 2 | AQ16: =COUNTIF($X$4:$AE$94,AL16) -> 0 | AR16: =AO16+AP16+AQ16 -> 2 | AS16: =AO16*$AN16 -> 0 | AT16: =AP16*$AN16 -> 70 | AU16: =AQ16*$AN16 -> 0 | AY16: =AM16*0.8 -> 120
A17: 44469 | B17: 1600 | C17: {=(SUM(VLOOKUP(H17:AE17,$AL$4:$AN$44,2,FALSE))+AF17*10)*IF(AJ17="是",$AW$4,$AW$3)} -> 1110 | D17: =SUM($B$4:B17)-SUM($C$4:C17) -> 8040 | E17: {=SUM(VLOOKUP(H17:AE17,$AL$4:$AN$44,3,FALSE))} -> 425 | F17: =SUM($E$4:E17)+SUM($G$4:G17) -> 5485 | G17: 0 | H17: 离兑坤 | I17: 3级 | J17: 3级 | K17: 3级 | L17: 3级 | M17: 3级 | N17: 空 | O17: 空 | P17: 空 | Q17: 空 | R17: 空 | S17: 空 | T17: 空 | U17: 空 | V17: 空 | W17: 空 | X17: 空 | Y17: 空 | Z17: 空 | AA17: 空 | AB17: 空 | AC17: 空 | AD17: 空 | AE17: 空 | AF17: 1 | AG17: 1 | AJ17: 否 | AK17: 5470 | AL17: 商人 | AM17: 50 | AN17: 30 | AO17: =COUNTIF($H$4:$O$94,AL17) -> 18 | AP17: =COUNTIF($P$4:$W$94,AL17) -> 18 | AQ17: =COUNTIF($X$4:$AE$94,AL17) -> 0 | AR17: =AO17+AP17+AQ17 -> 36 | AS17: =AO17*$AN17 -> 540 | AT17: =AP17*$AN17 -> 540 | AU17: =AQ17*$AN17 -> 0 | AY17: =AM17*0.8 -> 40
A18: 44470 | B18: 1600 | C18: {=(SUM(VLOOKUP(H18:AE18,$AL$4:$AN$44,2,FALSE))+AF18*10)*IF(AJ18="是",$AW$4,$AW$3)-232} -> 1488 | D18: =SUM($B$4:B18)-SUM($C$4:C18) -> 8152 | E18: {=SUM(VLOOKUP(H18:AE18,$AL$4:$AN$44,3,FALSE))} -> 460 | F18: =SUM($E$4:E18)+SUM($G$4:G18) -> 5945 | G18: 0 | H18: 商人 | I18: 3级 | J18: 3级 | K18: 艮震巽坎乾 | L18: 3级 | M18: 3级 | N18: 空 | O18: 空 | P18: 遗迹 | Q18: 1级 | R18: 商人 | S18: 1级 | T18: 1级 | U18: 1级 | V18: 空 | W18: 空 | X18: 空 | Y18: 空 | Z18: 空 | AA18: 空 | AB18: 空 | AC18: 空 | AD18: 空 | AE18: 空 | AF18: 2 | AH18: 2 | AJ18: 否 | AK18: 5950 | AL18: 营地 | AM18: -150 | AN18: 0 | AO18: =COUNTIF($H$4:$O$94,AL18) -> 1 | AP18: =COUNTIF($P$4:$W$94,AL18) -> 0 | AQ18: =COUNTIF($X$4:$AE$94,AL18) -> 0 | AR18: =AO18+AP18+AQ18 -> 1 | AS18: =AO18*$AN18 -> 0 | AT18: =AP18*$AN18 -> 0 | AU18: =AQ18*$AN18 -> 0 | AY18: =AM18*0.8 -> -120
A19: 44471 | B19: 1600 | C19: {=(SUM(VLOOKUP(H19:AE19,$AL$4:$AN$44,2,FALSE))+AF19*10)*IF(AJ19="是",$AW$4,$AW$3)} -> 1304 | D19: =SUM($B$4:B19)-SUM($C$4:C19) -> 8448 | E19: {=SUM(VLOOKUP(H19:AE19,$AL$4:$AN$44,3,FALSE))} -> 490 | F19: =SUM($E$4:E19)+SUM($G$4:G19) -> 6435 | G19: 0 | H19: 3级 | I19: 塔2 | J19: 3级 | K19: 3级 | L19: 商人 | M19: 3级 | N19: 空 | O19: 空 | P19: 1级 | Q19: 1级 | R19: 1级 | S19: 商人 | T19: 1级 | U19: 营地+ | V19: 1级 | W19: 1级 | X19: 空 | Y19: 空 | Z19: 空 | AA19: 空 | AB19: 空 | AC19: 空 | AD19: 空 | AE19: 空 | AF19: 0 | AJ19: 是 | AL19: 离兑坤 | AM19: 250 | AN19: 200 | AO19: =COUNTIF($H$4:$O$94,AL19) -> 3 | AP19: =COUNTIF($P$4:$W$94,AL19) -> 0 | AQ19: =COUNTIF($X$4:$AE$94,AL19) -> 0 | AR19: =AO19+AP19+AQ19 -> 3 | AS19: =AO19*$AN19 -> 600 | AT19: =AP19*$AN19 -> 0 | AU19: =AQ19*$AN19 -> 0 | AY19: =AM19*0.8 -> 200
A20: 44472 | B20: 1600 | C20: {=(SUM(VLOOKUP(H20:AE20,$AL$4:$AN$44,2,FALSE))+AF20*10)*IF(AJ20="是",$AW$4,$AW$3)} -> 1536 | D20: =SUM($B$4:B20)-SUM($C$4:C20) -> 8512 | E20: {=SUM(VLOOKUP(H20:AE20,$AL$4:$AN$44,3,FALSE))} -> 500 | F20: =SUM($E$4:E20)+SUM($G$4:G20) -> 6935 | G20: 0 | H20: 3级 | I20: 3级 | J20: 3级 | K20: 3级 | L20: 3级 | M20: 3级 | N20: 空 | O20: 空 | P20: 2级 | Q20: 2级 | R20: 2级 | S20: 2级 | T20: 2级 | U20: 商人 | V20: 空 | W20: 空 | X20: 空 | Y20: 空 | Z20: 空 | AA20: 空 | AB20: 空 | AC20: 空 | AD20: 空 | AE20: 空 | AF20: 5 | AH20: 5 | AJ20: 是 | AL20: 艮震巽坎乾 | AM20: 170 | AN20: 45 | AO20: =COUNTIF($H$4:$O$94,AL20) -> 5 | AP20: =COUNTIF($P$4:$W$94,AL20) -> 0 | AQ20: =COUNTIF($X$4:$AE$94,AL20) -> 0 | AR20: =AO20+AP20+AQ20 -> 5 | AS20: =AO20*$AN20 -> 225 | AT20: =AP20*$AN20 -> 0 | AU20: =AQ20*$AN20 -> 0 | AY20: =AM20*0.8 -> 136
A21: 44473 | B21: 1600 | C21: {=(SUM(VLOOKUP(H21:AE21,$AL$4:$AN$44,2,FALSE))+AF21*10)*IF(AJ21="是",$AW$4,$AW$3)} -> 1552 | D21: =SUM($B$4:B21)-SUM($C$4:C21) -> 8560 | E21: {=SUM(VLOOKUP(H21:AE21,$AL$4:$AN$44,3,FALSE))} -> 505 | F21: =SUM($E$4:E21)+SUM($G$4:G21) -> 7640 | G21: 200 | H21: 塔3 | I21: 3级 | J21: 3级 | K21: 3级 | L21: 3级 | M21: 2级 | N21: 空 | O21: 空 | P21: 2级 | Q21: 2级 | R21: 2级 | S21: 塔2 | T21: 2级 | U21: 2级 | V21: 空 | W21: 空 | X21: 空 | Y21: 空 | Z21: 空 | AA21: 空 | AB21: 空 | AC21: 空 | AD21: 空 | AE21: 空 | AF21: 0 | AJ21: 是 | AL21: 小boss | AM21: 250 | AN21: 200 | AO21: =COUNTIF($H$4:$O$94,AL21) -> 0 | AP21: =COUNTIF($P$4:$W$94,AL21) -> 0 | AQ21: =COUNTIF($X$4:$AE$94,AL21) -> 0 | AR21: =AO21+AP21+AQ21 -> 0 | AS21: =AO21*$AN21 -> 0 | AT21: =AP21*$AN21 -> 0 | AU21: =AQ21*$AN21 -> 0 | AY21: =AM21*0.8 -> 200
A22: 44474 | B22: 1600 | C22: {=(SUM(VLOOKUP(H22:AE22,$AL$4:$AN$44,2,FALSE))+AF22*10)*IF(AJ22="是",$AW$4,$AW$3)} -> 1488 | D22: =SUM($B$4:B22)-SUM($C$4:C22) -> 8672 | E22: {=SUM(VLOOKUP(H22:AE22,$AL$4:$AN$44,3,FALSE))} -> 545 | F22: =SUM($E$4:E22)+SUM($G$4:G22) -> 8285 | G22: 100 | H22: 商人 | I22: 2级 | J22: 2级 | K22: 2级 | L22: 2级 | M22: 2级 | N22: 空 | O22: 空 | P22: 营地+ | Q22: 3级 | R22: 3级 | S22: 3级 | T22: 3级 | U22: 3级 | V22: 3级 | W22: 3级 | X22: 空 | Y22: 空 | Z22: 空 | AA22: 空 | AB22: 空 | AC22: 空 | AD22: 空 | AE22: 空 | AF22: 2 | AH22: 2 | AJ22: 是 | AL22: 大boss | AM22: 250 | AN22: 1000 | AO22: =COUNTIF($H$4:$O$94,AL22) -> 1 | AP22: =COUNTIF($P$4:$W$94,AL22) -> 1 | AQ22: =COUNTIF($X$4:$AE$94,AL22) -> 0 | AR22: =AO22+AP22+AQ22 -> 2 | AS22: =AO22*$AN22 -> 1000 | AT22: =AP22*$AN22 -> 1000 | AU22: =AQ22*$AN22 -> 0 | AY22: =AM22*0.8 -> 200
A23: 44475 | B23: 1600 | C23: {=(SUM(VLOOKUP(H23:AE23,$AL$4:$AN$44,2,FALSE))+AF23*10)*IF(AJ23="是",$AW$4,$AW$3)} -> 1392 | D23: =SUM($B$4:B23)-SUM($C$4:C23) -> 8880 | E23: {=SUM(VLOOKUP(H23:AE23,$AL$4:$AN$44,3,FALSE))} -> 485 | F23: =SUM($E$4:E23)+SUM($G$4:G23) -> 8970 | G23: 200 | H23: 商人 | I23: 2级 | J23: 塔2 | K23: 2级 | L23: 2级 | M23: 2级 | N23: 空 | O23: 空 | P23: 3级 | Q23: 3级 | R23: 3级 | S23: 商人 | T23: 3级 | U23: 3级 | V23: 空 | W23: 空 | X23: 空 | Y23: 空 | Z23: 空 | AA23: 空 | AB23: 空 | AC23: 空 | AD23: 空 | AE23: 空 | AF23: 0 | AJ23: 是 | AL23: 中boss | AM23: 250 | AN23: 500 | AO23: =COUNTIF($H$4:$O$94,AL23) -> 1 | AP23: =COUNTIF($P$4:$W$94,AL23) -> 1 | AQ23: =COUNTIF($X$4:$AE$94,AL23) -> 0 | AR23: =AO23+AP23+AQ23 -> 2 | AS23: =AO23*$AN23 -> 500 | AT23: =AP23*$AN23 -> 500 | AU23: =AQ23*$AN23 -> 0 | AY23: =AM23*0.8 -> 200
A24: 44476 | B24: 1600 | C24: {=(SUM(VLOOKUP(H24:AE24,$AL$4:$AN$44,2,FALSE))+AF24*10)*IF(AJ24="是",$AW$4,$AW$3)} -> 1552 | D24: =SUM($B$4:B24)-SUM($C$4:C24) -> 8928 | E24: {=SUM(VLOOKUP(H24:AE24,$AL$4:$AN$44,3,FALSE))} -> 530 | F24: =SUM($E$4:E24)+SUM($G$4:G24) -> 9500 | G24: 0 | H24: 商人 | I24: 2级 | J24: 3级 | K24: 3级 | L24: 3级 | M24: 3级 | N24: 空 | O24: 空 | P24: 3级 | Q24: 3级 | R24: 3级 | S24: 3级 | T24: 4级 | U24: 4级 | V24: 空 | W24: 空 | X24: 空 | Y24: 空 | Z24: 空 | AA24: 空 | AB24: 空 | AC24: 空 | AD24: 空 | AE24: 空 | AF24: 1 | AG24: 1 | AJ24: 是 | AL24: 奈良 | AM24: 160 | AN24: 40 | AO24: =COUNTIF($H$4:$O$94,AL24) -> 0 | AP24: =COUNTIF($P$4:$W$94,AL24) -> 0 | AQ24: =COUNTIF($X$4:$AE$94,AL24) -> 0 | AR24: =AO24+AP24+AQ24 -> 0 | AS24: =AO24*$AN24 -> 0 | AT24: =AP24*$AN24 -> 0 | AU24: =AQ24*$AN24 -> 0 | AY24: =AM24*0.8 -> 128
A25: 44477 | B25: 1600 | C25: {=(SUM(VLOOKUP(H25:AE25,$AL$4:$AN$44,2,FALSE))+AF25*10)*IF(AJ25="是",$AW$4,$AW$3)} -> 1568 | D25: =SUM($B$4:B25)-SUM($C$4:C25) -> 8960 | E25: {=SUM(VLOOKUP(H25:AE25,$AL$4:$AN$44,3,FALSE))} -> 605 | F25: =SUM($E$4:E25)+SUM($G$4:G25) -> 10105 | G25: 0 | H25: 3级 | I25: 商人 | J25: 3级 | K25: 3级 | L25: 3级 | M25: 3级 | N25: 空 | O25: 空 | P25: 营地+ | Q25: 4级 | R25: 4级 | S25: 4级 | T25: 4级 | U25: 4级 | V25: 4级 | W25: 4级 | X25: 空 | Y25: 空 | Z25: 空 | AA25: 空 | AB25: 空 | AC25: 空 | AD25: 空 | AE25: 空 | AF25: 0 | AJ25: 是 | AL25: 山中 | AM25: 160 | AN25: 40 | AO25: =COUNTIF($H$4:$O$94,AL25) -> 0 | AP25: =COUNTIF($P$4:$W$94,AL25) -> 0 | AQ25: =COUNTIF($X$4:$AE$94,AL25) -> 0 | AR25: =AO25+AP25+AQ25 -> 0 | AS25: =AO25*$AN25 -> 0 | AT25: =AP25*$AN25 -> 0 | AU25: =AQ25*$AN25 -> 0 | AY25: =AM25*0.8 -> 128
A26: 44478 | B26: 1600 | C26: {=(SUM(VLOOKUP(H26:AE26,$AL$4:$AN$44,2,FALSE))+AF26*10)*IF(AJ26="是",$AW$4,$AW$3)} -> 1576 | D26: =SUM($B$4:B26)-SUM($C$4:C26) -> 8984 | E26: {=SUM(VLOOKUP(H26:AE26,$AL$4:$AN$44,3,FALSE))} -> 605 | F26: =SUM($E$4:E26)+SUM($G$4:G26) -> 10710 | G26: 0 | H26: 3级 | I26: 3级 | J26: 营地+ | K26: 3级 | L26: 3级 | M26: 3级 | N26: 4级 | O26: 4级 | P26: 4级 | Q26: 4级 | R26: 4级 | S26: 商人 | T26: 4级 | U26: 4级 | V26: 空 | W26: 空 | X26: 空 | Y26: 空 | Z26: 空 | AA26: 空 | AB26: 空 | AC26: 空 | AD26: 空 | AE26: 空 | AF26: 1 | AG26: 1 | AJ26: 是 | AL26: 秋道 | AM26: 150 | AN26: 35 | AO26: =COUNTIF($H$4:$O$94,AL26) -> 0 | AP26: =COUNTIF($P$4:$W$94,AL26) -> 0 | AQ26: =COUNTIF($X$4:$AE$94,AL26) -> 0 | AR26: =AO26+AP26+AQ26 -> 0 | AS26: =AO26*$AN26 -> 0 | AT26: =AP26*$AN26 -> 0 | AU26: =AQ26*$AN26 -> 0 | AY26: =AM26*0.8 -> 120
A27: 44479 | B27: 1600 | C27: {=(SUM(VLOOKUP(H27:AE27,$AL$4:$AN$44,2,FALSE))+AF27*10)*IF(AJ27="是",$AW$4,$AW$3)} -> 1704 | D27: =SUM($B$4:B27)-SUM($C$4:C27) -> 8880 | E27: {=SUM(VLOOKUP(H27:AE27,$AL$4:$AN$44,3,FALSE))} -> 585 | F27: =SUM($E$4:E27)+SUM($G$4:G27) -> 11295 | G27: 0 | H27: 4级 | I27: 4级 | J27: 4级 | K27: 3级 | L27: 3级 | M27: 3级 | N27: 空 | O27: 空 | P27: 4级 | Q27: 4级 | R27: 4级 | S27: 4级 | T27: 4级 | U27: 4级 | V27: 空 | W27: 空 | X27: 空 | Y27: 空 | Z27: 空 | AA27: 空 | AB27: 空 | AC27: 空 | AD27: 空 | AE27: 空 | AF27: 0 | AJ27: 是 | AL27: 空 | AM27: 0 | AN27: 0 | AS27: =AO27*$AN27 -> 0 | AT27: =AP27*$AN27 -> 0 | AU27: =AQ27*$AN27 -> 0 | AY27: =AM27*0.8 -> 0
A28: 44480 | B28: 1600 | C28: {=(SUM(VLOOKUP(H28:AE28,$AL$4:$AN$44,2,FALSE))+AF28*10)*IF(AJ28="是",$AW$4,$AW$3)} -> 1664 | D28: =SUM($B$4:B28)-SUM($C$4:C28) -> 8816 | E28: {=SUM(VLOOKUP(H28:AE28,$AL$4:$AN$44,3,FALSE))} -> 620 | F28: =SUM($E$4:E28)+SUM($G$4:G28) -> 12115 | G28: 200 | H28: 3级 | I28: 3级 | J28: 3级 | K28: 3级 | L28: 3级 | M28: 3级 | N28: 空 | O28: 空 | P28: 4级 | Q28: 4级 | R28: 4级 | S28: 营地+ | T28: 4级 | U28: 4级 | V28: 4级 | W28: 4级 | X28: 空 | Y28: 空 | Z28: 空 | AA28: 空 | AB28: 空 | AC28: 空 | AD28: 空 | AE28: 空 | AF28: 0 | AJ28: 是 | AK28: 八卦后 | AL28: 营地+ | AM28: -200 | AN28: 0 | AO28: =COUNTIF($H$4:$O$94,AL28) -> 5 | AP28: =COUNTIF($P$4:$W$94,AL28) -> 9 | AQ28: =COUNTIF($X$4:$AE$94,AL28) -> 0 | AR28: =AO28+AP28+AQ28 -> 14 | AS28: =AO28*$AN28 -> 0 | AT28: =AP28*$AN28 -> 0 | AU28: =AQ28*$AN28 -> 0 | AY28: =AM28*0.8 -> -160
A29: 44481 | B29: 1600 | C29: {=(SUM(VLOOKUP(H29:AE29,$AL$4:$AN$44,2,FALSE))+AF29*10)*IF(AJ29="是",$AW$4,$AW$3)} -> 1568 | D29: =SUM($B$4:B29)-SUM($C$4:C29) -> 8848 | E29: {=SUM(VLOOKUP(H29:AE29,$AL$4:$AN$44,3,FALSE))} -> 555 | F29: =SUM($E$4:E29)+SUM($G$4:G29) -> 12770 | G29: 100 | H29: 3级 | I29: 3级 | J29: 商人 | K29: 3级 | L29: 3级 | M29: 塔3 | N29: 空 | O29: 空 | P29: 4级 | Q29: 4级 | R29: 4级 | S29: 4级 | T29: 4级 | U29: 4级 | V29: 空 | W29: 空 | X29: 空 | Y29: 空 | Z29: 空 | AA29: 空 | AB29: 空 | AC29: 空 | AD29: 空 | AE29: 空 | AF29: 0 | AJ29: 是 | AQ29: 总地块 | AR29: =SUM(AR4:AR28) -> 1026 | AT29: 总经验 | AU29: =SUM(AS4:AU28)+7000 -> 61465
A30: 44482 | B30: 1600 | C30: {=(SUM(VLOOKUP(H30:AE30,$AL$4:$AN$44,2,FALSE))+AF30*10)*IF(AJ30="是",$AW$4,$AW$3)} -> 1584 | D30: =SUM($B$4:B30)-SUM($C$4:C30) -> 8864 | E30: {=SUM(VLOOKUP(H30:AE30,$AL$4:$AN$44,3,FALSE))} -> 555 | F30: =SUM($E$4:E30)+SUM($G$4:G30) -> 13525 | G30: 200 | H30: 3级 | I30: 3级 | J30: 3级 | K30: 3级 | L30: 3级 | M30: 商人 | N30: 空 | O30: 空 | P30: 4级 | Q30: 4级 | R30: 4级 | S30: 4级 | T30: 4级 | U30: 4级 | V30: 空 | W30: 空 | X30: 空 | Y30: 空 | Z30: 空 | AA30: 空 | AB30: 空 | AC30: 空 | AD30: 空 | AE30: 空 | AF30: 0 | AJ30: 是
A31: 44483 | B31: 1600 | C31: {=(SUM(VLOOKUP(H31:AE31,$AL$4:$AN$44,2,FALSE))+AF31*10)*IF(AJ31="是",$AW$4,$AW$3)} -> 1680 | D31: =SUM($B$4:B31)-SUM($C$4:C31) -> 8784 | E31: {=SUM(VLOOKUP(H31:AE31,$AL$4:$AN$44,3,FALSE))} -> 570 | F31: =SUM($E$4:E31)+SUM($G$4:G31) -> 14095 | G31: 0 | H31: 3级 | I31: 3级 | J31: 3级 | K31: 3级 | L31: 3级 | M31: 3级 | N31: 空 | O31: 空 | P31: 4级 | Q31: 4级 | R31: 4级 | S31: 4级 | T31: 4级 | U31: 4级 | V31: 空 | W31: 空 | X31: 空 | Y31: 空 | Z31: 空 | AA31: 空 | AB31: 空 | AC31: 空 | AD31: 空 | AE31: 空 | AF31: 0 | AJ31: 是
A32: 44484 | B32: 1600 | C32: {=(SUM(VLOOKUP(H32:AE32,$AL$4:$AN$44,2,FALSE))+AF32*10)*IF(AJ32="是",$AW$4,$AW$3)} -> 1608 | D32: =SUM($B$4:B32)-SUM($C$4:C32) -> 8776 | E32: {=SUM(VLOOKUP(H32:AE32,$AL$4:$AN$44,3,FALSE))} -> 570 | F32: =SUM($E$4:E32)+SUM($G$4:G32) -> 14665 | G32: 0 | H32: 3级 | I32: 3级 | J32: 3级 | K32: 4级 | L32: 4级 | M32: 4级 | N32: 空 | O32: 空 | P32: 4级 | Q32: 4级 | R32: 商人 | S32: 4级 | T32: 4级 | U32: 5级 | V32: 空 | W32: 空 | X32: 空 | Y32: 空 | Z32: 空 | AA32: 空 | AB32: 空 | AC32: 空 | AD32: 空 | AE32: 空 | AF32: 0 | AJ32: 是
A33: 44485 | B33: 1600 | C33: {=(SUM(VLOOKUP(H33:AE33,$AL$4:$AN$44,2,FALSE))+AF33*10)*IF(AJ33="是",$AW$4,$AW$3)} -> 1728 | D33: =SUM($B$4:B33)-SUM($C$4:C33) -> 8648 | E33: {=SUM(VLOOKUP(H33:AE33,$AL$4:$AN$44,3,FALSE))} -> 600 | F33: =SUM($E$4:E33)+SUM($G$4:G33) -> 15265 | G33: 0 | H33: 4级 | I33: 4级 | J33: 4级 | K33: 4级 | L33: 4级 | M33: 4级 | N33: 空 | O33: 空 | P33: 4级 | Q33: 4级 | R33: 4级 | S33: 4级 | T33: 4级 | U33: 4级 | V33: 空 | W33: 空 | X33: 空 | Y33: 空 | Z33: 空 | AA33: 空 | AB33: 空 | AC33: 空 | AD33: 空 | AE33: 空 | AF33: 0 | AJ33: 是
A34: 44486 | B34: 1600 | C34: {=(SUM(VLOOKUP(H34:AE34,$AL$4:$AN$44,2,FALSE))+AF34*10)*IF(AJ34="是",$AW$4,$AW$3)} -> 1728 | D34: =SUM($B$4:B34)-SUM($C$4:C34) -> 8520 | E34: {=SUM(VLOOKUP(H34:AE34,$AL$4:$AN$44,3,FALSE))} -> 600 | F34: =SUM($E$4:E34)+SUM($G$4:G34) -> 15865 | G34: 0 | H34: 4级 | I34: 4级 | J34: 4级 | K34: 4级 | L34: 4级 | M34: 4级 | N34: 空 | O34: 空 | P34: 4级 | Q34: 4级 | R34: 4级 | S34: 4级 | T34: 4级 | U34: 4级 | V34: 空 | W34: 空 | X34: 空 | Y34: 空 | Z34: 空 | AA34: 空 | AB34: 空 | AC34: 空 | AD34: 空 | AE34: 空 | AF34: 0 | AJ34: 是
A35: 44487 | B35: 1600 | C35: {=(SUM(VLOOKUP(H35:AE35,$AL$4:$AN$44,2,FALSE))+AF35*10)*IF(AJ35="是",$AW$4,$AW$3)} -> 1624 | D35: =SUM($B$4:B35)-SUM($C$4:C35) -> 8496 | E35: {=SUM(VLOOKUP(H35:AE35,$AL$4:$AN$44,3,FALSE))} -> 580 | F35: =SUM($E$4:E35)+SUM($G$4:G35) -> 16645 | G35: 200 | H35: 4级 | I35: 4级 | J35: 4级 | K35: 4级 | L35: 4级 | M35: 商人 | N35: 空 | O35: 空 | P35: 4级 | Q35: 4级 | R35: 4级 | S35: 4级 | T35: 4级 | U35: 4级 | V35: 空 | W35: 空 | X35: 空 | Y35: 空 | Z35: 空 | AA35: 空 | AB35: 空 | AC35: 空 | AD35: 空 | AE35: 空 | AF35: 0 | AJ35: 是
A36: 44488 | B36: 1600 | C36: {=(SUM(VLOOKUP(H36:AE36,$AL$4:$AN$44,2,FALSE))+AF36*10)*IF(AJ36="是",$AW$4,$AW$3)} -> 1600 | D36: =SUM($B$4:B36)-SUM($C$4:C36) -> 8496 | E36: {=SUM(VLOOKUP(H36:AE36,$AL$4:$AN$44,3,FALSE))} -> 580 | F36: =SUM($E$4:E36)+SUM($G$4:G36) -> 17325 | G36: 100 | H36: 4级 | I36: 4级 | J36: 4级 | K36: 4级 | L36: 4级 | M36: 4级 | N36: 空 | O36: 空 | P36: 商人 | Q36: 4级 | R36: 4级 | S36: 4级 | T36: 塔4 | U36: 4级 | V36: 空 | W36: 空 | X36: 空 | Y36: 空 | Z36: 空 | AA36: 空 | AB36: 空 | AC36: 空 | AD36: 空 | AE36: 空 | AF36: 0 | AJ36: 是
A37: 44489 | B37: 1600 | C37: {=(SUM(VLOOKUP(H37:AE37,$AL$4:$AN$44,2,FALSE))+AF37*10)*IF(AJ37="是",$AW$4,$AW$3)} -> 1728 | D37: =SUM($B$4:B37)-SUM($C$4:C37) -> 8368 | E37: {=SUM(VLOOKUP(H37:AE37,$AL$4:$AN$44,3,FALSE))} -> 600 | F37: =SUM($E$4:E37)+SUM($G$4:G37) -> 18125 | G37: 200 | H37: 4级 | I37: 4级 | J37: 4级 | K37: 4级 | L37: 4级 | M37: 4级 | N37: 空 | O37: 空 | P37: 4级 | Q37: 4级 | R37: 4级 | S37: 4级 | T37: 4级 | U37: 4级 | V37: 空 | W37: 空 | X37: 空 | Y37: 空 | Z37: 空 | AA37: 空 | AB37: 空 | AC37: 空 | AD37: 空 | AE37: 空 | AF37: 0 | AJ37: 是 | AL37: 6级地194块 | AN37: 6 | AO37: 194
A38: 44490 | B38: 1600 | C38: {=(SUM(VLOOKUP(H38:AE38,$AL$4:$AN$44,2,FALSE))+AF38*10)*IF(AJ38="是",$AW$4,$AW$3)} -> 1728 | D38: =SUM($B$4:B38)-SUM($C$4:C38) -> 8240 | E38: {=SUM(VLOOKUP(H38:AE38,$AL$4:$AN$44,3,FALSE))} -> 600 | F38: =SUM($E$4:E38)+SUM($G$4:G38) -> 18725 | G38: 0 | H38: 4级 | I38: 4级 | J38: 4级 | K38: 4级 | L38: 4级 | M38: 4级 | N38: 空 | O38: 空 | P38: 4级 | Q38: 4级 | R38: 4级 | S38: 4级 | T38: 4级 | U38: 4级 | V38: 空 | W38: 空 | X38: 空 | Y38: 空 | Z38: 空 | AA38: 空 | AB38: 空 | AC38: 空 | AD38: 空 | AE38: 空 | AF38: 0 | AJ38: 是 | AL38: 5级地237块 | AN38: 5 | AO38: 236
A39: 44491 | B39: 1600 | C39: {=(SUM(VLOOKUP(H39:AE39,$AL$4:$AN$44,2,FALSE))+AF39*10)*IF(AJ39="是",$AW$4,$AW$3)} -> 1632 | D39: =SUM($B$4:B39)-SUM($C$4:C39) -> 8208 | E39: {=SUM(VLOOKUP(H39:AE39,$AL$4:$AN$44,3,FALSE))} -> 600 | F39: =SUM($E$4:E39)+SUM($G$4:G39) -> 19325 | G39: 0 | H39: 4级 | I39: 塔4 | J39: 4级 | K39: 4级 | L39: 商人 | M39: 4级 | N39: 空 | O39: 空 | P39: 4级 | Q39: 5级 | R39: 5级 | S39: 4级 | T39: 5级 | U39: 5级 | V39: 空 | W39: 空 | X39: 空 | Y39: 空 | Z39: 空 | AA39: 空 | AB39: 空 | AC39: 空 | AD39: 空 | AE39: 空 | AF39: 0 | AJ39: 是 | AL39: 4级地272块 | AN39: 4 | AO39: 269
A40: 44492 | B40: 1600 | C40: {=(SUM(VLOOKUP(H40:AE40,$AL$4:$AN$44,2,FALSE))+AF40*10)*IF(AJ40="是",$AW$4,$AW$3)} -> 1808 | D40: =SUM($B$4:B40)-SUM($C$4:C40) -> 8000 | E40: {=SUM(VLOOKUP(H40:AE40,$AL$4:$AN$44,3,FALSE))} -> 1125 | F40: =SUM($E$4:E40)+SUM($G$4:G40) -> 20450 | G40: 0 | H40: 4级 | I40: 4级 | J40: 4级 | K40: 4级 | L40: 4级 | M40: 4级 | N40: 营地+ | O40: 4级 | P40: 5级 | Q40: 5级 | R40: 5级 | S40: 中boss | T40: 5级 | U40: 5级 | V40: 空 | W40: 空 | X40: 空 | Y40: 空 | Z40: 空 | AA40: 空 | AB40: 空 | AC40: 空 | AD40: 空 | AE40: 空 | AF40: 0 | AJ40: 是 | AL40: 3级地358块 | AN40: 3 | AO40: 358
...

Sheet 102.5.1.05
A1: =(_xlfn.DAYS(TODAY(),A4)+2)/((_xlfn.DAYS(A94,A4))+1) -> 8.989011 | H1: 工作区 | AL1: 使用方法：按自己规划的路线，将下表中的地块名复制粘贴至工作区。初次使用传送门，当天跳步次数+5。重复使用传送门，当天跳步次数+1
A2: version 5.1.05 | C2: 合计经验 | E2: =SUM(E4:E94)+SUM(G4:G94) -> 61405 | H2: 队伍一 风 | J2: 步数 | K2: =COUNTIF(H18:O94,"<>空")-3 -> 221 | L2: (不算跳步和传送) | P2: 队伍二 雷 | R2: 步数 | S2: =COUNTIF(P4:W94,"<>空") -> 303 | T2: (不算跳步和传送) | X2: 队伍三 | Z2: 总步数 | AA2: =COUNTIF(X4:AE94,"<>空") -> 412 | AB2: (不算跳步和传送) | AF2: =SUM(AF4:AF94) -> 50 | AG2: =SUM(AG4:AG94) -> 17 | AH2: =SUM(AH4:AH94) -> 25 | AI2: =SUM(AI4:AI94) -> 8 | AJ2: 八卦全开 | AW2: 粮草系数
A3: 日期 | B3: 获得粮草 | C3: 消耗粮草 | D3: 剩余粮草 | E3: 获得经验 | F3: 累计经验 | G3: 任务经验 | H3: 1 | I3: 2 | J3: 3 | K3: 4 | L3: 5 | M3: 6 | N3: 7 | O3: 8 | P3: 1 | Q3: 2 | R3: 3 | S3: 4 | T3: 5 | U3: 6 | V3: 7 | W3: 8 | X3: 1 | Y3: 2 | Z3: 3 | AA3: 4 | AB3: 5 | AC3: 6 | AD3: 7 | AE3: 8 | AF3: 跳步次数 | AG3: 1队跳步 | AH3: 2队跳步 | AI3: 3队跳步 | AL3: 地块 | AM3: 粮草 | AN3: 经验 | AO3: 一队地块 | AP3: 二队地块 | AQ3: 三队地块 | AR3: 总地块 | AS3: 一队经验 | AT3: 二队经验 | AU3: 三队经验 | AV3: 八卦前 | AW3: 1
A4: 44456 | B4: 800 | C4: {=(SUM(VLOOKUP(H4:AE4,$AL$4:$AN$44,2,FALSE))+AF4*10)*IF(AJ4="是",$AW$4,$AW$3)} -> 750 | D4: =SUM($B$4:B4)-SUM($C$4:C4) -> 50 | E4: {=SUM(VLOOKUP(H4:AE4,$AL$4:$AN$44,3,FALSE))} -> 175 | F4: =SUM($E$4:E4)+SUM($G$4:G4) -> 175 | G4: 0 | H4: 1级 | I4: 1级 | J4: 1级 | K4: 1级 | L4: 1级 | M4: 空 | N4: 空 | O4: 空 | P4: 空 | Q4: 空 | R4: 空 | S4: 空 | T4: 空 | U4: 空 | V4: 空 | W4: 空 | X4: 空 | Y4: 空 | Z4: 空 | AA4: 空 | AB4: 空 | AC4: 空 | AD4: 空 | AE4: 空 | AF4: 0 | AJ4: 否 | AL4: 1级 | AM4: 150 | AN4: 35 | AO4: =COUNTIF($H$4:$O$94,AL4) -> 14 | AP4: =COUNTIF($P$4:$W$94,AL4) -> 0 | AQ4: =COUNTIF($X$4:$AE$94,AL4) -> 12 | AR4: =AO4+AP4+AQ4 -> 26 | AS4: =AO4*$AN4 -> 490 | AT4: =AP4*$AN4 -> 0 | AU4: =AQ4*$AN4 -> 420 | AV4: 八卦后 | AW4: 0.8 | AY4: =AM4*0.8 -> 120
A5: 44457 | B5: 1600 | C5: {=(SUM(VLOOKUP(H5:AE5,$AL$4:$AN$44,2,FALSE))+AF5*10)*IF(AJ5="是",$AW$4,$AW$3)} -> 900 | D5: =SUM($B$4:B5)-SUM($C$4:C5) -> 750 | E5: {=SUM(VLOOKUP(H5:AE5,$AL$4:$AN$44,3,FALSE))} -> 210 | F5: =SUM($E$4:E5)+SUM($G$4:G5) -> 885 | G5: 500 | H5: 1级 | I5: 1级 | J5: 1级 | K5: 1级 | L5: 1级 | M5: 1级 | N5: 空 | O5: 空 | P5: 空 | Q5: 空 | R5: 空 | S5: 空 | T5: 空 | U5: 空 | V5: 空 | W5: 空 | X5: 空 | Y5: 空 | Z5: 空 | AA5: 空 | AB5: 空 | AC5: 空 | AD5: 空 | AE5: 空 | AF5: 0 | AJ5: 否 | AL5: 2级 | AM5: 160 | AN5: 40 | AO5: =COUNTIF($H$4:$O$94,AL5) -> 17 | AP5: =COUNTIF($P$4:$W$94,AL5) -> 1 | AQ5: =COUNTIF($X$4:$AE$94,AL5) -> 9 | AR5: =AO5+AP5+AQ5 -> 27 | AS5: =AO5*$AN5 -> 680 | AT5: =AP5*$AN5 -> 40 | AU5: =AQ5*$AN5 -> 360 | AV5: Note：开完八卦当天可能需要手动计算粮草 | AY5: =AM5*0.8 -> 128
A6: 44458 | B6: 1600 | C6: {=(SUM(VLOOKUP(H6:AE6,$AL$4:$AN$44,2,FALSE))+AF6*10)*IF(AJ6="是",$AW$4,$AW$3)} -> 980 | D6: =SUM($B$4:B6)-SUM($C$4:C6) -> 1370 | E6: {=SUM(VLOOKUP(H6:AE6,$AL$4:$AN$44,3,FALSE))} -> 225 | F6: =SUM($E$4:E6)+SUM($G$4:G6) -> 1110 | G6: 0 | H6: 1级 | I6: 1级 | J6: 1级 | K6: 2级 | L6: 2级 | M6: 2级 | N6: 空 | O6: 空 | P6: 空 | Q6: 空 | R6: 空 | S6: 空 | T6: 空 | U6: 空 | V6: 空 | W6: 空 | X6: 空 | Y6: 空 | Z6: 空 | AA6: 空 | AB6: 空 | AC6: 空 | AD6: 空 | AE6: 空 | AF6: 5 | AG6: 5 | AJ6: 否 | AL6: 3级 | AM6: 170 | AN6: 45 | AO6: =COUNTIF($H$4:$O$94,AL6) -> 136 | AP6: =COUNTIF($P$4:$W$94,AL6) -> 44 | AQ6: =COUNTIF($X$4:$AE$94,AL6) -> 10 | AR6: =AO6+AP6+AQ6 -> 190 | AS6: =AO6*$AN6 -> 6120 | AT6: =AP6*$AN6 -> 1980 | AU6: =AQ6*$AN6 -> 450 | AY6: =AM6*0.8 -> 136
A7: 44459 | B7: 1600 | C7: {=(SUM(VLOOKUP(H7:AE7,$AL$4:$AN$44,2,FALSE))+AF7*10)*IF(AJ7="是",$AW$4,$AW$3)} -> 990 | D7: =SUM($B$4:B7)-SUM($C$4:C7) -> 1980 | E7: {=SUM(VLOOKUP(H7:AE7,$AL$4:$AN$44,3,FALSE))} -> 260 | F7: =SUM($E$4:E7)+SUM($G$4:G7) -> 1570 | G7: 200 | H7: 塔2 | I7: 2级 | J7: 3级 | K7: 3级 | L7: 3级 | M7: 3级 | N7: 空 | O7: 空 | P7: 空 | Q7: 空 | R7: 空 | S7: 空 | T7: 空 | U7: 空 | V7: 空 | W7: 空 | X7: 空 | Y7: 空 | Z7: 空 | AA7: 空 | AB7: 空 | AC7: 空 | AD7: 空 | AE7: 空 | AF7: 0 | AJ7: 否 | AL7: 4级 | AM7: 180 | AN7: 50 | AO7: =COUNTIF($H$4:$O$94,AL7) -> 111 | AP7: =COUNTIF($P$4:$W$94,AL7) -> 45 | AQ7: =COUNTIF($X$4:$AE$94,AL7) -> 113 | AR7: =AO7+AP7+AQ7 -> 269 | AS7: =AO7*$AN7 -> 5550 | AT7: =AP7*$AN7 -> 2250 | AU7: =AQ7*$AN7 -> 5650 | AY7: =AM7*0.8 -> 144
A8: 44460 | B8: 1600 | C8: {=(SUM(VLOOKUP(H8:AE8,$AL$4:$AN$44,2,FALSE))+AF8*10)*IF(AJ8="是",$AW$4,$AW$3)} -> 1030 | D8: =SUM($B$4:B8)-SUM($C$4:C8) -> 2550 | E8: {=SUM(VLOOKUP(H8:AE8,$AL$4:$AN$44,3,FALSE))} -> 270 | F8: =SUM($E$4:E8)+SUM($G$4:G8) -> 1940 | G8: 100 | H8: 艮震巽坎乾 | I8: 3级 | J8: 3级 | K8: 3级 | L8: 3级 | M8: 3级 | N8: 空 | O8: 空 | P8: 空 | Q8: 空 | R8: 空 | S8: 空 | T8: 空 | U8: 空 | V8: 空 | W8: 空 | X8: 空 | Y8: 空 | Z8: 空 | AA8: 空 | AB8: 空 | AC8: 空 | AD8: 空 | AE8: 空 | AF8: 1 | AG8: 1 | AJ8: 否 | AL8: 5级 | AM8: 190 | AN8: 55 | AO8: =COUNTIF($H$4:$O$94,AL8) -> 0 | AP8: =COUNTIF($P$4:$W$94,AL8) -> 112 | AQ8: =COUNTIF($X$4:$AE$94,AL8) -> 124 | AR8: =AO8+AP8+AQ8 -> 236 | AS8: =AO8*$AN8 -> 0 | AT8: =AP8*$AN8 -> 6160 | AU8: =AQ8*$AN8 -> 6820 | AY8: =AM8*0.8 -> 152
A9: 44461 | B9: 1600 | C9: {=(SUM(VLOOKUP(H9:AE9,$AL$4:$AN$44,2,FALSE))+AF9*10)*IF(AJ9="是",$AW$4,$AW$3)} -> 1040 | D9: =SUM($B$4:B9)-SUM($C$4:C9) -> 3110 | E9: {=SUM(VLOOKUP(H9:AE9,$AL$4:$AN$44,3,FALSE))} -> 315 | F9: =SUM($E$4:E9)+SUM($G$4:G9) -> 2455 | G9: 200 | H9: 3级 | I9: 3级 | J9: 3级 | K9: 3级 | L9: 3级 | M9: 营地 | N9: 3级 | O9: 3级 | P9: 空 | Q9: 空 | R9: 空 | S9: 空 | T9: 空 | U9: 空 | V9: 空 | W9: 空 | X9: 空 | Y9: 空 | Z9: 空 | AA9: 空 | AB9: 空 | AC9: 空 | AD9: 空 | AE9: 空 | AF9: 0 | AJ9: 否 | AL9: 6级 | AM9: 200 | AN9: 60 | AO9: =COUNTIF($H$4:$O$94,AL9) -> 0 | AP9: =COUNTIF($P$4:$W$94,AL9) -> 76 | AQ9: =COUNTIF($X$4:$AE$94,AL9) -> 118 | AR9: =AO9+AP9+AQ9 -> 194 | AS9: =AO9*$AN9 -> 0 | AT9: =AP9*$AN9 -> 4560 | AU9: =AQ9*$AN9 -> 7080 | AY9: =AM9*0.8 -> 160
A10: 44462 | B10: 1600 | C10: {=(SUM(VLOOKUP(H10:AE10,$AL$4:$AN$44,2,FALSE))+AF10*10)*IF(AJ10="是",$AW$4,$AW$3)} -> 890 | D10: =SUM($B$4:B10)-SUM($C$4:C10) -> 3820 | E10: {=SUM(VLOOKUP(H10:AE10,$AL$4:$AN$44,3,FALSE))} -> 250 | F10: =SUM($E$4:E10)+SUM($G$4:G10) -> 2705 | G10: 0 | H10: 2级 | I10: 3级 | J10: 3级 | K10: 商人 | L10: 3级 | M10: 艮震巽坎乾 | N10: 空 | O10: 空 | P10: 空 | Q10: 空 | R10: 空 | S10: 空 | T10: 空 | U10: 空 | V10: 空 | W10: 空 | X10: 空 | Y10: 空 | Z10: 空 | AA10: 空 | AB10: 空 | AC10: 空 | AD10: 空 | AE10: 空 | AF10: 0 | AJ10: 否 | AL10: 塔1 | AM10: 150 | AN10: 35 | AO10: =COUNTIF($H$4:$O$94,AL10) -> 0 | AP10: =COUNTIF($P$4:$W$94,AL10) -> 0 | AQ10: =COUNTIF($X$4:$AE$94,AL10) -> 0 | AR10: =AO10+AP10+AQ10 -> 0 | AS10: =AO10*$AN10 -> 0 | AT10: =AP10*$AN10 -> 0 | AU10: =AQ10*$AN10 -> 0 | AY10: =AM10*0.8 -> 120
A11: 44463 | B11: 1600 | C11: {=(SUM(VLOOKUP(H11:AE11,$AL$4:$AN$44,2,FALSE))+AF11*10)*IF(AJ11="是",$AW$4,$AW$3)} -> 1180 | D11: =SUM($B$4:B11)-SUM($C$4:C11) -> 4240 | E11: {=SUM(VLOOKUP(H11:AE11,$AL$4:$AN$44,3,FALSE))} -> 425 | F11: =SUM($E$4:E11)+SUM($G$4:G11) -> 3130 | G11: 0 | H11: 3级 | I11: 离兑坤 | J11: 3级 | K11: 3级 | L11: 3级 | M11: 3级 | N11: 空 | O11: 空 | P11: 空 | Q11: 空 | R11: 空 | S11: 空 | T11: 空 | U11: 空 | V11: 空 | W11: 空 | X11: 空 | Y11: 空 | Z11: 空 | AA11: 空 | AB11: 空 | AC11: 空 | AD11: 空 | AE11: 空 | AF11: 8 | AG11: 8 | AJ11: 否 | AL11: 塔2 | AM11: 150 | AN11: 40 | AO11: =COUNTIF($H$4:$O$94,AL11) -> 4 | AP11: =COUNTIF($P$4:$W$94,AL11) -> 0 | AQ11: =COUNTIF($X$4:$AE$94,AL11) -> 1 | AR11: =AO11+AP11+AQ11 -> 5 | AS11: =AO11*$AN11 -> 160 | AT11: =AP11*$AN11 -> 0 | AU11: =AQ11*$AN11 -> 40 | AY11: =AM11*0.8 -> 120
A12: 44464 | B12: 1600 | C12: {=(SUM(VLOOKUP(H12:AE12,$AL$4:$AN$44,2,FALSE))+AF12*10)*IF(AJ12="是",$AW$4,$AW$3)} -> 1020 | D12: =SUM($B$4:B12)-SUM($C$4:C12) -> 4820 | E12: {=SUM(VLOOKUP(H12:AE12,$AL$4:$AN$44,3,FALSE))} -> 270 | F12: =SUM($E$4:E12)+SUM($G$4:G12) -> 3400 | G12: 0 | H12: 3级 | I12: 3级 | J12: 3级 | K12: 3级 | L12: 艮震巽坎乾 | M12: 3级 | N12: 空 | O12: 空 | P12: 空 | Q12: 空 | R12: 空 | S12: 空 | T12: 空 | U12: 空 | V12: 空 | W12: 空 | X12: 空 | Y12: 空 | Z12: 空 | AA12: 空 | AB12: 空 | AC12: 空 | AD12: 空 | AE12: 空 | AF12: 0 | AJ12: 否 | AL12: 塔3 | AM12: 150 | AN12: 45 | AO12: =COUNTIF($H$4:$O$94,AL12) -> 2 | AP12: =COUNTIF($P$4:$W$94,AL12) -> 2 | AQ12: =COUNTIF($X$4:$AE$94,AL12) -> 1 | AR12: =AO12+AP12+AQ12 -> 5 | AS12: =AO12*$AN12 -> 90 | AT12: =AP12*$AN12 -> 90 | AU12: =AQ12*$AN12 -> 45 | AY12: =AM12*0.8 -> 120
A13: 44465 | B13: 1600 | C13: {=(SUM(VLOOKUP(H13:AE13,$AL$4:$AN$44,2,FALSE))+AF13*10)*IF(AJ13="是",$AW$4,$AW$3)} -> 1100 | D13: =SUM($B$4:B13)-SUM($C$4:C13) -> 5320 | E13: {=SUM(VLOOKUP(H13:AE13,$AL$4:$AN$44,3,FALSE))} -> 425 | F13: =SUM($E$4:E13)+SUM($G$4:G13) -> 3825 | G13: 0 | H13: 3级 | I13: 3级 | J13: 3级 | K13: 离兑坤 | L13: 3级 | M13: 3级 | N13: 空 | O13: 空 | P13: 空 | Q13: 空 | R13: 空 | S13: 空 | T13: 空 | U13: 空 | V13: 空 | W13: 空 | X13: 空 | Y13: 空 | Z13: 空 | AA13: 空 | AB13: 空 | AC13: 空 | AD13: 空 | AE13: 空 | AF13: 0 | AJ13: 否 | AL13: 塔4 | AM13: 150 | AN13: 50 | AO13: =COUNTIF($H$4:$O$94,AL13) -> 1 | AP13: =COUNTIF($P$4:$W$94,AL13) -> 2 | AQ13: =COUNTIF($X$4:$AE$94,AL13) -> 1 | AR13: =AO13+AP13+AQ13 -> 4 | AS13: =AO13*$AN13 -> 50 | AT13: =AP13*$AN13 -> 100 | AU13: =AQ13*$AN13 -> 50 | AY13: =AM13*0.8 -> 120
A14: 44466 | B14: 1600 | C14: {=(SUM(VLOOKUP(H14:AE14,$AL$4:$AN$44,2,FALSE))+AF14*10)*IF(AJ14="是",$AW$4,$AW$3)} -> 900 | D14: =SUM($B$4:B14)-SUM($C$4:C14) -> 6020 | E14: {=SUM(VLOOKUP(H14:AE14,$AL$4:$AN$44,3,FALSE))} -> 255 | F14: =SUM($E$4:E14)+SUM($G$4:G14) -> 4380 | G14: 300 | H14: 商人 | I14: 3级 | J14: 3级 | K14: 3级 | L14: 3级 | M14: 3级 | N14: 空 | O14: 空 | P14: 空 | Q14: 空 | R14: 空 | S14: 空 | T14: 空 | U14: 空 | V14: 空 | W14: 空 | X14: 空 | Y14: 空 | Z14: 空 | AA14: 空 | AB14: 空 | AC14: 空 | AD14: 空 | AE14: 空 | AF14: 0 | AJ14: 否 | AL14: 塔5 | AM14: 150 | AN14: 55 | AO14: =COUNTIF($H$4:$O$94,AL14) -> 0 | AP14: =COUNTIF($P$4:$W$94,AL14) -> 2 | AQ14: =COUNTIF($X$4:$AE$94,AL14) -> 1 | AR14: =AO14+AP14+AQ14 -> 3 | AS14: =AO14*$AN14 -> 0 | AT14: =AP14*$AN14 -> 110 | AU14: =AQ14*$AN14 -> 55 | AY14: =AM14*0.8 -> 120
A15: 44467 | B15: 1600 | C15: {=(SUM(VLOOKUP(H15:AE15,$AL$4:$AN$44,2,FALSE))+AF15*10)*IF(AJ15="是",$AW$4,$AW$3)} -> 1020 | D15: =SUM($B$4:B15)-SUM($C$4:C15) -> 6600 | E15: {=SUM(VLOOKUP(H15:AE15,$AL$4:$AN$44,3,FALSE))} -> 270 | F15: =SUM($E$4:E15)+SUM($G$4:G15) -> 4650 | G15: 0 | H15: 3级 | I15: 3级 | J15: 3级 | K15: 3级 | L15: 艮震巽坎乾 | M15: 3级 | N15: 空 | O15: 空 | P15: 空 | Q15: 空 | R15: 空 | S15: 空 | T15: 空 | U15: 空 | V15: 空 | W15: 空 | X15: 空 | Y15: 空 | Z15: 空 | AA15: 空 | AB15: 空 | AC15: 空 | AD15: 空 | AE15: 空 | AF15: 0 | AJ15: 否 | AL15: 塔6 | AM15: 150 | AN15: 60 | AO15: =COUNTIF($H$4:$O$94,AL15) -> 0 | AP15: =COUNTIF($P$4:$W$94,AL15) -> 0 | AQ15: =COUNTIF($X$4:$AE$94,AL15) -> 1 | AR15: =AO15+AP15+AQ15 -> 1 | AS15: =AO15*$AN15 -> 0 | AT15: =AP15*$AN15 -> 0 | AU15: =AQ15*$AN15 -> 60 | AY15: =AM15*0.8 -> 120
A16: 44468 | B16: 1600 | C16: {=(SUM(VLOOKUP(H16:AE16,$AL$4:$AN$44,2,FALSE))+AF16*10)*IF(AJ16="是",$AW$4,$AW$3)} -> 1080 | D16: =SUM($B$4:B16)-SUM($C$4:C16) -> 7120 | E16: {=SUM(VLOOKUP(H16:AE16,$AL$4:$AN$44,3,FALSE))} -> 425 | F16: =SUM($E$4:E16)+SUM($G$4:G16) -> 5275 | G16: 200 | H16: 3级 | I16: 3级 | J16: 塔3 | K16: 3级 | L16: 3级 | M16: 离兑坤 | N16: 空 | O16: 空 | P16: 空 | Q16: 空 | R16: 空 | S16: 空 | T16: 空 | U16: 空 | V16: 空 | W16: 空 | X16: 空 | Y16: 空 | Z16: 空 | AA16: 空 | AB16: 空 | AC16: 空 | AD16: 空 | AE16: 空 | AF16: 0 | AJ16: 否 | AL16: 遗迹 | AM16: 150 | AN16: 35 | AO16: =COUNTIF($H$4:$O$94,AL16) -> 0 | AP16: =COUNTIF($P$4:$W$94,AL16) -> 0 | AQ16: =COUNTIF($X$4:$AE$94,AL16) -> 0 | AR16: =AO16+AP16+AQ16 -> 0 | AS16: =AO16*$AN16 -> 0 | AT16: =AP16*$AN16 -> 0 | AU16: =AQ16*$AN16 -> 0 | AY16: =AM16*0.8 -> 120
A17: 44469 | B17: 1600 | C17: {=(SUM(VLOOKUP(H17:AE17,$AL$4:$AN$44,2,FALSE))+AF17*10)*IF(AJ17="是",$AW$4,$AW$3)} -> 1030 | D17: =SUM($B$4:B17)-SUM($C$4:C17) -> 7690 | E17: {=SUM(VLOOKUP(H17:AE17,$AL$4:$AN$44,3,FALSE))} -> 270 | F17: =SUM($E$4:E17)+SUM($G$4:G17) -> 5545 | G17: 0 | H17: 3级 | I17: 3级 | J17: 3级 | K17: 3级 | L17: 3级 | M17: 3级 | N17: 空 | O17: 空 | P17: 空 | Q17: 空 | R17: 空 | S17: 空 | T17: 空 | U17: 空 | V17: 空 | W17: 空 | X17: 空 | Y17: 空 | Z17: 空 | AA17: 空 | AB17: 空 | AC17: 空 | AD17: 空 | AE17: 空 | AF17: 1 | AG17: 1 | AJ17: 否 | AL17: 商人 | AM17: 50 | AN17: 30 | AO17: =COUNTIF($H$4:$O$94,AL17) -> 13 | AP17: =COUNTIF($P$4:$W$94,AL17) -> 13 | AQ17: =COUNTIF($X$4:$AE$94,AL17) -> 10 | AR17: =AO17+AP17+AQ17 -> 36 | AS17: =AO17*$AN17 -> 390 | AT17: =AP17*$AN17 -> 390 | AU17: =AQ17*$AN17 -> 300 | AY17: =AM17*0.8 -> 40
A18: 44470 | B18: 1600 | C18: {=(SUM(VLOOKUP(H18:AE18,$AL$4:$AN$44,2,FALSE))+AF18*10)*IF(AJ18="是",$AW$4,$AW$3)-402} -> 2118 | D18: =SUM($B$4:B18)-SUM($C$4:C18) -> 7172 | E18: {=SUM(VLOOKUP(H18:AE18,$AL$4:$AN$44,3,FALSE))} -> 685 | F18: =SUM($E$4:E18)+SUM($G$4:G18) -> 6230 | G18: 0 | H18: 3级 | I18: 3级 | J18: 艮震巽坎乾 | K18: 3级 | L18: 3级 | M18: 商人 | N18: 空 | O18: 空 | P18: 商人 | Q18: 商人 | R18: 3级 | S18: 3级 | T18: 商人 | U18: 3级 | V18: 空 | W18: 空 | X18: 1级 | Y18: 1级 | Z18: 1级 | AA18: 商人 | AB18: 1级 | AC18: 1级 | AD18: 空 | AE18: 空 | AF18: 16 | AH18: 15 | AI18: 1 | AJ18: 否 | AK18: 八卦前 | AL18: 营地 | AM18: -150 | AN18: 0 | AO18: =COUNTIF($H$4:$O$94,AL18) -> 1 | AP18: =COUNTIF($P$4:$W$94,AL18) -> 0 | AQ18: =COUNTIF($X$4:$AE$94,AL18) -> 0 | AR18: =AO18+AP18+AQ18 -> 1 | AS18: =AO18*$AN18 -> 0 | AT18: =AP18*$AN18 -> 0 | AU18: =AQ18*$AN18 -> 0 | AY18: =AM18*0.8 -> -120
A19: 44471 | B19: 1600 | C19: {=(SUM(VLOOKUP(H19:AE19,$AL$4:$AN$44,2,FALSE))+AF19*10)*IF(AJ19="是",$AW$4,$AW$3)} -> 2280 | D19: =SUM($B$4:B19)-SUM($C$4:C19) -> 6492 | E19: {=SUM(VLOOKUP(H19:AE19,$AL$4:$AN$44,3,FALSE))} -> 745 | F19: =SUM($E$4:E19)+SUM($G$4:G19) -> 6975 | G19: 0 | H19: 3级 | I19: 3级 | J19: 3级 | K19: 3级 | L19: 3级 | M19: 3级 | N19: 空 | O19: 空 | P19: 3级 | Q19: 3级 | R19: 3级 | S19: 3级 | T19: 3级 | U19: 3级 | V19: 空 | W19: 空 | X19: 1级 | Y19: 1级 | Z19: 1级 | AA19: 1级 | AB19: 商人 | AC19: 1级 | AD19: 空 | AE19: 空 | AF19: 1 | AH19: 1 | AJ19: 是 | AL19: 离兑坤 | AM19: 250 | AN19: 200 | AO19: =COUNTIF($H$4:$O$94,AL19) -> 3 | AP19: =COUNTIF($P$4:$W$94,AL19) -> 0 | AQ19: =COUNTIF($X$4:$AE$94,AL19) -> 0 | AR19: =AO19+AP19+AQ19 -> 3 | AS19: =AO19*$AN19 -> 600 | AT19: =AP19*$AN19 -> 0 | AU19: =AQ19*$AN19 -> 0 | AY19: =AM19*0.8 -> 200
A20: 44472 | B20: 1600 | C20: {=(SUM(VLOOKUP(H20:AE20,$AL$4:$AN$44,2,FALSE))+AF20*10)*IF(AJ20="是",$AW$4,$AW$3)} -> 2160 | D20: =SUM($B$4:B20)-SUM($C$4:C20) -> 5932 | E20: {=SUM(VLOOKUP(H20:AE20,$AL$4:$AN$44,3,FALSE))} -> 815 | F20: =SUM($E$4:E20)+SUM($G$4:G20) -> 7790 | G20: 0 | H20: 塔2 | I20: 3级 | J20: 3级 | K20: 商人 | L20: 3级 | M20: 3级 | N20: 空 | O20: 空 | P20: 营地+ | Q20: 2级 | R20: 商人 | S20: 3级 | T20: 3级 | U20: 塔3 | V20: 3级 | W20: 3级 | X20: 营地+ | Y20: 1级 | Z20: 1级 | AA20: 2级 | AB20: 2级 | AC20: 奈良 | AD20: 2级 | AE20: 2级 | AF20: 8 | AH20: 3 | AI20: 5 | AJ20: 是 | AL20: 艮震巽坎乾 | AM20: 170 | AN20: 45 | AO20: =COUNTIF($H$4:$O$94,AL20) -> 5 | AP20: =COUNTIF($P$4:$W$94,AL20) -> 0 | AQ20: =COUNTIF($X$4:$AE$94,AL20) -> 0 | AR20: =AO20+AP20+AQ20 -> 5 | AS20: =AO20*$AN20 -> 225 | AT20: =AP20*$AN20 -> 0 | AU20: =AQ20*$AN20 -> 0 | AY20: =AM20*0.8 -> 136
A21: 44473 | B21: 1600 | C21: {=(SUM(VLOOKUP(H21:AE21,$AL$4:$AN$44,2,FALSE))+AF21*10)*IF(AJ21="是",$AW$4,$AW$3)} -> 2120 | D21: =SUM($B$4:B21)-SUM($C$4:C21) -> 5412 | E21: {=SUM(VLOOKUP(H21:AE21,$AL$4:$AN$44,3,FALSE))} -> 735 | F21: =SUM($E$4:E21)+SUM($G$4:G21) -> 8725 | G21: 200 | H21: 3级 | I21: 3级 | J21: 3级 | K21: 3级 | L21: 2级 | M21: 商人 | N21: 空 | O21: 空 | P21: 3级 | Q21: 3级 | R21: 3级 | S21: 商人 | T21: 3级 | U21: 3级 | V21: 空 | W21: 空 | X21: 商人 | Y21: 2级 | Z21: 2级 | AA21: 2级 | AB21: 塔2 | AC21: 2级 | AD21: 空 | AE21: 空 | AF21: 2 | AH21: 2 | AJ21: 是 | AL21: 小boss | AM21: 250 | AN21: 200 | AO21: =COUNTIF($H$4:$O$94,AL21) -> 0 | AP21: =COUNTIF($P$4:$W$94,AL21) -> 0 | AQ21: =COUNTIF($X$4:$AE$94,AL21) -> 0 | AR21: =AO21+AP21+AQ21 -> 0 | AS21: =AO21*$AN21 -> 0 | AT21: =AP21*$AN21 -> 0 | AU21: =AQ21*$AN21 -> 0 | AY21: =AM21*0.8 -> 200
A22: 44474 | B22: 1600 | C22: {=(SUM(VLOOKUP(H22:AE22,$AL$4:$AN$44,2,FALSE))+AF22*10)*IF(AJ22="是",$AW$4,$AW$3)} -> 2208 | D22: =SUM($B$4:B22)-SUM($C$4:C22) -> 4804 | E22: {=SUM(VLOOKUP(H22:AE22,$AL$4:$AN$44,3,FALSE))} -> 795 | F22: =SUM($E$4:E22)+SUM($G$4:G22) -> 9620 | G22: 100 | H22: 2级 | I22: 2级 | J22: 2级 | K22: 2级 | L22: 2级 | M22: 商人 | N22: 空 | O22: 空 | P22: 3级 | Q22: 3级 | R22: 3级 | S22: 商人 | T22: 3级 | U22: 3级 | V22: 空 | W22: 空 | X22: 2级 | Y22: 营地+ | Z22: 3级 | AA22: 3级 | AB22: 3级 | AC22: 3级 | AD22: 3级 | AE22: 3级 | AF22: 3 | AH22: 1 | AI22: 2 | AJ22: 是 | AL22: 大boss | AM22: 250 | AN22: 1000 | AO22: =COUNTIF($H$4:$O$94,AL22) -> 0 | AP22: =COUNTIF($P$4:$W$94,AL22) -> 1 | AQ22: =COUNTIF($X$4:$AE$94,AL22) -> 1 | AR22: =AO22+AP22+AQ22 -> 2 | AS22: =AO22*$AN22 -> 0 | AT22: =AP22*$AN22 -> 1000 | AU22: =AQ22*$AN22 -> 1000 | AY22: =AM22*0.8 -> 200
A23: 44475 | B23: 1600 | C23: {=(SUM(VLOOKUP(H23:AE23,$AL$4:$AN$44,2,FALSE))+AF23*10)*IF(AJ23="是",$AW$4,$AW$3)} -> 1832 | D23: =SUM($B$4:B23)-SUM($C$4:C23) -> 4572 | E23: {=SUM(VLOOKUP(H23:AE23,$AL$4:$AN$44,3,FALSE))} -> 695 | F23: =SUM($E$4:E23)+SUM($G$4:G23) -> 10515 | G23: 200 | H23: 2级 | I23: 塔2 | J23: 2级 | K23: 2级 | L23: 2级 | M23: 商人 | N23: 空 | O23: 空 | P23: 3级 | Q23: 3级 | R23: 商人 | S23: 3级 | T23: 3级 | U23: 3级 | V23: 空 | W23: 空 | X23: 营地+ | Y23: 3级 | Z23: 3级 | AA23: 商人 | AB23: 3级 | AC23: 3级 | AD23: 空 | AE23: 空 | AF23: 2 | AH23: 2 | AJ23: 是 | AL23: 中boss | AM23: 250 | AN23: 500 | AO23: =COUNTIF($H$4:$O$94,AL23) -> 0 | AP23: =COUNTIF($P$4:$W$94,AL23) -> 0 | AQ23: =COUNTIF($X$4:$AE$94,AL23) -> 2 | AR23: =AO23+AP23+AQ23 -> 2 | AS23: =AO23*$AN23 -> 0 | AT23: =AP23*$AN23 -> 0 | AU23: =AQ23*$AN23 -> 1000 | AY23: =AM23*0.8 -> 200
A24: 44476 | B24: 1600 | C24: {=(SUM(VLOOKUP(H24:AE24,$AL$4:$AN$44,2,FALSE))+AF24*10)*IF(AJ24="是",$AW$4,$AW$3)} -> 2168 | D24: =SUM($B$4:B24)-SUM($C$4:C24) -> 4004 | E24: {=SUM(VLOOKUP(H24:AE24,$AL$4:$AN$44,3,FALSE))} -> 720 | F24: =SUM($E$4:E24)+SUM($G$4:G24) -> 11235 | G24: 0 | H24: 2级 | I24: 2级 | J24: 3级 | K24: 塔2 | L24: 3级 | M24: 3级 | N24: 空 | O24: 空 | P24: 3级 | Q24: 3级 | R24: 3级 | S24: 3级 | T24: 3级 | U24: 3级 | V24: 空 | W24: 空 | X24: 4级 | Y24: 4级 | Z24: 4级 | AA24: 塔3 | AB24: 空 | AC24: 空 | AD24: 空 | AE24: 空 | AF24: 2 | AG24: 1 | AH24: 1 | AJ24: 是 | AL24: 奈良 | AM24: 160 | AN24: 40 | AO24: =COUNTIF($H$4:$O$94,AL24) -> 0 | AP24: =COUNTIF($P$4:$W$94,AL24) -> 0 | AQ24: =COUNTIF($X$4:$AE$94,AL24) -> 1 | AR24: =AO24+AP24+AQ24 -> 1 | AS24: =AO24*$AN24 -> 0 | AT24: =AP24*$AN24 -> 0 | AU24: =AQ24*$AN24 -> 40 | AY24: =AM24*0.8 -> 128
A25: 44477 | B25: 1600 | C25: {=(SUM(VLOOKUP(H25:AE25,$AL$4:$AN$44,2,FALSE))+AF25*10)*IF(AJ25="是",$AW$4,$AW$3)} -> 2136 | D25: =SUM($B$4:B25)-SUM($C$4:C25) -> 3468 | E25: {=SUM(VLOOKUP(H25:AE25,$AL$4:$AN$44,3,FALSE))} -> 740 | F25: =SUM($E$4:E25)+SUM($G$4:G25) -> 11975 | G25: 0 | H25: 3级 | I25: 商人 | J25: 3级 | K25: 3级 | L25: 3级 | M25: 3级 | N25: 空 | O25: 空 | P25: 3级 | Q25: 4级 | R25: 3级 | S25: 3级 | T25: 空 | U25: 空 | V25: 空 | W25: 空 | X25: 4级 | Y25: 4级 | Z25: 4级 | AA25: 4级 | AB25: 4级 | AC25: 4级 | AD25: 空 | AE25: 空 | AF25: 0 | AJ25: 是 | AL25: 山中 | AM25: 160 | AN25: 40 | AO25: =COUNTIF($H$4:$O$94,AL25) -> 0 | AP25: =COUNTIF($P$4:$W$94,AL25) -> 0 | AQ25: =COUNTIF($X$4:$AE$94,AL25) -> 0 | AR25: =AO25+AP25+AQ25 -> 0 | AS25: =AO25*$AN25 -> 0 | AT25: =AP25*$AN25 -> 0 | AU25: =AQ25*$AN25 -> 0 | AY25: =AM25*0.8 -> 128
A26: 44478 | B26: 1600 | C26: {=(SUM(VLOOKUP(H26:AE26,$AL$4:$AN$44,2,FALSE))+AF26*10)*IF(AJ26="是",$AW$4,$AW$3)} -> 1824 | D26: =SUM($B$4:B26)-SUM($C$4:C26) -> 3244 | E26: {=SUM(VLOOKUP(H26:AE26,$AL$4:$AN$44,3,FALSE))} -> 740 | F26: =SUM($E$4:E26)+SUM($G$4:G26) -> 12715 | G26: 0 | H26: 3级 | I26: 3级 | J26: 营地+ | K26: 3级 | L26: 3级 | M26: 3级 | N26: 3级 | O26: 3级 | P26: 商人 | Q26: 3级 | R26: 营地+ | S26: 4级 | T26: 空 | U26: 空 | V26: 空 | W26: 空 | X26: 4级 | Y26: 4级 | Z26: 4级 | AA26: 4级 | AB26: 4级 | AC26: 4级 | AD26: 空 | AE26: 空 | AF26: 1 | AG26: 1 | AJ26: 是 | AL26: 秋道 | AM26: 150 | AN26: 35 | AO26: =COUNTIF($H$4:$O$94,AL26) -> 0 | AP26: =COUNTIF($P$4:$W$94,AL26) -> 0 | AQ26: =COUNTIF($X$4:$AE$94,AL26) -> 0 | AR26: =AO26+AP26+AQ26 -> 0 | AS26: =AO26*$AN26 -> 0 | AT26: =AP26*$AN26 -> 0 | AU26: =AQ26*$AN26 -> 0 | AY26: =AM26*0.8 -> 120
A27: 44479 | B27: 1600 | C27: {=(SUM(VLOOKUP(H27:AE27,$AL$4:$AN$44,2,FALSE))+AF27*10)*IF(AJ27="是",$AW$4,$AW$3)} -> 2256 | D27: =SUM($B$4:B27)-SUM($C$4:C27) -> 2588 | E27: {=SUM(VLOOKUP(H27:AE27,$AL$4:$AN$44,3,FALSE))} -> 770 | F27: =SUM($E$4:E27)+SUM($G$4:G27) -> 13485 | G27: 0 | H27: 3级 | I27: 3级 | J27: 3级 | K27: 3级 | L27: 3级 | M27: 3级 | N27: 空 | O27: 空 | P27: 4级 | Q27: 4级 | R27: 4级 | S27: 4级 | T27: 空 | U27: 空 | V27: 空 | W27: 空 | X27: 4级 | Y27: 4级 | Z27: 4级 | AA27: 4级 | AB27: 4级 | AC27: 4级 | AD27: 空 | AE27: 空 | AF27: 0 | AJ27: 是 | AL27: 空 | AM27: 0 | AN27: 0 | AS27: =AO27*$AN27 -> 0 | AT27: =AP27*$AN27 -> 0 | AU27: =AQ27*$AN27 -> 0 | AY27: =AM27*0.8 -> 0
A28: 44480 | B28: 1600 | C28: {=(SUM(VLOOKUP(H28:AE28,$AL$4:$AN$44,2,FALSE))+AF28*10)*IF(AJ28="是",$AW$4,$AW$3)} -> 2256 | D28: =SUM($B$4:B28)-SUM($C$4:C28) -> 1932 | E28: {=SUM(VLOOKUP(H28:AE28,$AL$4:$AN$44,3,FALSE))} -> 770 | F28: =SUM($E$4:E28)+SUM($G$4:G28) -> 14455 | G28: 200 | H28: 3级 | I28: 3级 | J28: 3级 | K28: 3级 | L28: 3级 | M28: 3级 | N28: 空 | O28: 空 | P28: 4级 | Q28: 4级 | R28: 4级 | S28: 4级 | T28: 空 | U28: 空 | V28: 空 | W28: 空 | X28: 4级 | Y28: 4级 | Z28: 4级 | AA28: 4级 | AB28: 4级 | AC28: 4级 | AD28: 空 | AE28: 空 | AF28: 0 | AJ28: 是 | AK28: 八卦后 | AL28: 营地+ | AM28: -200 | AN28: 0 | AO28: =COUNTIF($H$4:$O$94,AL28) -> 2 | AP28: =COUNTIF($P$4:$W$94,AL28) -> 5 | AQ28: =COUNTIF($X$4:$AE$94,AL28) -> 7 | AR28: =AO28+AP28+AQ28 -> 14 | AS28: =AO28*$AN28 -> 0 | AT28: =AP28*$AN28 -> 0 | AU28: =AQ28*$AN28 -> 0 | AY28: =AM28*0.8 -> -160
A29: 44481 | B29: 1600 | C29: {=(SUM(VLOOKUP(H29:AE29,$AL$4:$AN$44,2,FALSE))+AF29*10)*IF(AJ29="是",$AW$4,$AW$3)} -> 2192 | D29: =SUM($B$4:B29)-SUM($C$4:C29) -> 1340 | E29: {=SUM(VLOOKUP(H29:AE29,$AL$4:$AN$44,3,FALSE))} -> 775 | F29: =SUM($E$4:E29)+SUM($G$4:G29) -> 15330 | G29: 100 | H29: 3级 | I29: 3级 | J29: 商人 | K29: 3级 | L29: 3级 | M29: 3级 | N29: 空 | O29: 空 | P29: 4级 | Q29: 4级 | R29: 4级 | S29: 4级 | T29: 空 | U29: 空 | V29: 空 | W29: 空 | X29: 4级 | Y29: 4级 | Z29: 5级 | AA29: 5级 | AB29: 5级 | AC29: 5级 | AD29: 空 | AE29: 空 | AF29: 0 | AJ29: 是 | AQ29: 总地块 | AR29: =SUM(AR4:AR28) -> 1024 | AT29: 总经验 | AU29: =SUM(AS4:AU28)+7000 -> 61405
A30: 44482 | B30: 1600 | C30: {=(SUM(VLOOKUP(H30:AE30,$AL$4:$AN$44,2,FALSE))+AF30*10)*IF(AJ30="是",$AW$4,$AW$3)} -> 2256 | D30: =SUM($B$4:B30)-SUM($C$4:C30) -> 684 | E30: {=SUM(VLOOKUP(H30:AE30,$AL$4:$AN$44,3,FALSE))} -> 795 | F30: =SUM($E$4:E30)+SUM($G$4:G30) -> 16325 | G30: 200 | H30: 3级 | I30: 3级 | J30: 3级 | K30: 3级 | L30: 塔3 | M30: 3级 | N30: 空 | O30: 空 | P30: 塔4 | Q30: 4级 | R30: 4级 | S30: 3级 | T30: 空 | U30: 空 | V30: 空 | W30: 空 | X30: 5级 | Y30: 5级 | Z30: 5级 | AA30: 5级 | AB30: 5级 | AC30: 5级 | AD30: 空 | AE30: 空 | AF30: 0 | AJ30: 是
A31: 44483 | B31: 1600 | C31: {=(SUM(VLOOKUP(H31:AE31,$AL$4:$AN$44,2,FALSE))+AF31*10)*IF(AJ31="是",$AW$4,$AW$3)} -> 2144 | D31: =SUM($B$4:B31)-SUM($C$4:C31) -> 140 | E31: {=SUM(VLOOKUP(H31:AE31,$AL$4:$AN$44,3,FALSE))} -> 1205 | F31: =SUM($E$4:E31)+SUM($G$4:G31) -> 17530 | G31: 0 | H31: 3级 | I31: 商人 | J31: 3级 | K31: 3级 | L31: 4级 | M31: 4级 | N31: 空 | O31: 空 | P31: 3级 | Q31: 3级 | R31: 商人 | S31: 3级 | T31: 空 | U31: 空 | V31: 空 | W31: 空 | X31: 5级 | Y31: 5级 | Z31: 中boss | AA31: 5级 | AB31: 5级 | AC31: 5级 | AD31: 空 | AE31: 空 | AF31: 0 | AJ31: 是
A32: 44484 | B32: 1600 | C32: {=(SUM(VLOOKUP(H32:AE32,$AL$4:$AN$44,2,FALSE))+AF32*10)*IF(AJ32="是",$AW$4,$AW$3)} -> 1616 | D32: =SUM($B$4:B32)-SUM($C$4:C32) -> 124 | E32: {=SUM(VLOOKUP(H32:AE32,$AL$4:$AN$44,3,FALSE))} -> 570 | F32: =SUM($E$4:E32)+SUM($G$4:G32) -> 18100 | G32: 0 | H32: 4级 | I32: 空 | J32: 空 | K32: 空 | L32: 空 | M32: 空 | N32: 空 | O32: 空 | P32: 3级 | Q32: 3级 | R32: 4级 | S32: 4级 | T32: 空 | U32: 空 | V32: 空 | W32: 空 | X32: 5级 | Y32: 5级 | Z32: 5级 | AA32: 5级 | AB32: 5级 | AC32: 5级 | AD32: 空 | AE32: 空 | AF32: 0 | AJ32: 是
A33: 44485 | B33: 1600 | C33: {=(SUM(VLOOKUP(H33:AE33,$AL$4:$AN$44,2,FALSE))+AF33*10)*IF(AJ33="是",$AW$4,$AW$3)} -> 1640 | D33: =SUM($B$4:B33)-SUM($C$4:C33) -> 84 | E33: {=SUM(VLOOKUP(H33:AE33,$AL$4:$AN$44,3,FALSE))} -> 660 | F33: =SUM($E$4:E33)+SUM($G$4:G33) -> 18760 | G33: 0 | H33: 4级 | I33: 4级 | J33: 空 | K33: 空 | L33: 空 | M33: 空 | N33: 空 | O33: 空 | P33: 塔3 | Q33: 4级 | R33: 4级 | S33: 商人 | T33: 空 | U33: 空 | V33: 空 | W33: 空 | X33: 5级 | Y33: 营地+ | Z33: 5级 | AA33: 5级 | AB33: 5级 | AC33: 5级 | AD33: 5级 | AE33: 5级 | AF33: 0 | AJ33: 是
A34: 44486 | B34: 1600 | C34: {=(SUM(VLOOKUP(H34:AE34,$AL$4:$AN$44,2,FALSE))+AF34*10)*IF(AJ34="是",$AW$4,$AW$3)} -> 1600 | D34: =SUM($B$4:B34)-SUM($C$4:C34) -> 84 | E34: {=SUM(VLOOKUP(H34:AE34,$AL$4:$AN$44,3,FALSE))} -> 580 | F34: =SUM($E$4:E34)+SUM($G$4:G34) -> 19340 | G34: 0 | H34: 4级 | I34: 空 | J34: 空 | K34: 空 | L34: 空 | M34: 空 | N34: 空 | O34: 空 | P34: 4级 | Q34: 4级 | R34: 4级 | S34: 4级 | T34: 空 | U34: 空 | V34: 空 | W34: 空 | X34: 5级 | Y34: 5级 | Z34: 塔5 | AA34: 5级 | AB34: 5级 | AC34: 5级 | AD34: 空 | AE34: 空 | AF34: 0 | AJ34: 是
A35: 44487 | B35: 1600 | C35: {=(SUM(VLOOKUP(H35:AE35,$AL$4:$AN$44,2,FALSE))+AF35*10)*IF(AJ35="是",$AW$4,$AW$3)} -> 1664 | D35: =SUM($B$4:B35)-SUM($C$4:C35) -> 20 | E35: {=SUM(VLOOKUP(H35:AE35,$AL$4:$AN$44,3,FALSE))} -> 600 | F35: =SUM($E$4:E35)+SUM($G$4:G35) -> 20140 | G35: 200 | H35: 4级 | I35: 空 | J35: 空 | K35: 空 | L35: 空 | M35: 空 | N35: 空 | O35: 空 | P35: 4级 | Q35: 4级 | R35: 4级 | S35: 4级 | T35: 空 | U35: 空 | V35: 空 | W35: 空 | X35: 5级 | Y35: 5级 | Z35: 6级 | AA35: 6级 | AB35: 6级 | AC35: 6级 | AD35: 空 | AE35: 空 | AF35: 0 | AJ35: 是
A36: 44488 | B36: 1600 | C36: {=(SUM(VLOOKUP(H36:AE36,$AL$4:$AN$44,2,FALSE))+AF36*10)*IF(AJ36="是",$AW$4,$AW$3)} -> 1536 | D36: =SUM($B$4:B36)-SUM($C$4:C36) -> 84 | E36: {=SUM(VLOOKUP(H36:AE36,$AL$4:$AN$44,3,FALSE))} -> 560 | F36: =SUM($E$4:E36)+SUM($G$4:G36) -> 20800 | G36: 100 | H36: 空 | I36: 空 | J36: 空 | K36: 空 | L36: 空 | M36: 空 | N36: 空 | O36: 空 | P36: 4级 | Q36: 4级 | R36: 4级 | S36: 4级 | T36: 空 | U36: 空 | V36: 空 | W36: 空 | X36: 6级 | Y36: 6级 | Z36: 6级 | AA36: 6级 | AB36: 6级 | AC36: 6级 | AD36: 空 | AE36: 空 | AF36: 0 | AJ36: 是
A37: 44489 | B37: 1600 | C37: {=(SUM(VLOOKUP(H37:AE37,$AL$4:$AN$44,2,FALSE))+AF37*10)*IF(AJ37="是",$AW$4,$AW$3)} -> 1680 | D37: =SUM($B$4:B37)-SUM($C$4:C37) -> 4 | E37: {=SUM(VLOOKUP(H37:AE37,$AL$4:$AN$44,3,FALSE))} -> 610 | F37: =SUM($E$4:E37)+SUM($G$4:G37) -> 21610 | G37: 200 | H37: 4级 | I37: 空 | J37: 空 | K37: 空 | L37: 空 | M37: 空 | N37: 空 | O37: 空 | P37: 4级 | Q37: 4级 | R37: 4级 | S37: 4级 | T37: 空 | U37: 空 | V37: 空 | W37: 空 | X37: 6级 | Y37: 6级 | Z37: 6级 | AA37: 6级 | AB37: 6级 | AC37: 6级 | AD37: 空 | AE37: 空 | AF37: 0 | AJ37: 是 | AL37: 6级地194块 | AN37: 6 | AO37: 194
A38: 44490 | B38: 1600 | C38: {=(SUM(VLOOKUP(H38:AE38,$AL$4:$AN$44,2,FALSE))+AF38*10)*IF(AJ38="是",$AW$4,$AW$3)} -> 1544 | D38: =SUM($B$4:B38)-SUM($C$4:C38) -> 60 | E38: {=SUM(VLOOKUP(H38:AE38,$AL$4:$AN$44,3,FALSE))} -> 565 | F38: =SUM($E$4:E38)+SUM($G$4:G38) -> 22175 | G38: 0 | H38: 空 | I38: 空 | J38: 空 | K38: 空 | L38: 空 | M38: 空 | N38: 空 | O38: 空 | P38: 4级 | Q38: 4级 | R38: 4级 | S38: 5级 | T38: 空 | U38: 空 | V38: 空 | W38: 空 | X38: 6级 | Y38: 6级 | Z38: 6级 | AA38: 6级 | AB38: 6级 | AC38: 6级 | AD38: 空 | AE38: 空 | AF38: 0 | AJ38: 是 | AL38: 5级地237块 | AN38: 5 | AO38: 236
A39: 44491 | B39: 1600 | C39: {=(SUM(VLOOKUP(H39:AE39,$AL$4:$AN$44,2,FALSE))+AF39*10)*IF(AJ39="是",$AW$4,$AW$3)} -> 1552 | D39: =SUM($B$4:B39)-SUM($C$4:C39) -> 108 | E39: {=SUM(VLOOKUP(H39:AE39,$AL$4:$AN$44,3,FALSE))} -> 1500 | F39: =SUM($E$4:E39)+SUM($G$4:G39) -> 23675 | G39: 0 | H39: 空 | I39: 空 | J39: 空 | K39: 空 | L39: 空 | M39: 空 | N39: 空 | O39: 空 | P39: 塔4 | Q39: 4级 | R39: 4级 | S39: 4级 | T39: 空 | U39: 空 | V39: 空 | W39: 空 | X39: 6级 | Y39: 6级 | Z39: 6级 | AA39: 大boss | AB39: 6级 | AC39: 6级 | AD39: 空 | AE39: 空 | AF39: 0 | AJ39: 是 | AL39: 4级地272块 | AN39: 4 | AO39: 269
A40: 44492 | B40: 1600 | C40: {=(SUM(VLOOKUP(H40:AE40,$AL$4:$AN$44,2,FALSE))+AF40*10)*IF(AJ40="是",$AW$4,$AW$3)} -> 1688 | D40: =SUM($B$4:B40)-SUM($C$4:C40) -> 20 | E40: {=SUM(VLOOKUP(H40:AE40,$AL$4:$AN$44,3,FALSE))} -> 615 | F40: =SUM($E$4:E40)+SUM($G$4:G40) -> 24290 | G40: 0 | H40: 4级 | I40: 空 | J40: 空 | K40: 空 | L40: 空 | M40: 空 | N40: 空 | O40: 空 | P40: 4级 | Q40: 4级 | R40: 4级 | S40: 5级 | T40: 空 | U40: 空 | V40: 空 | W40: 空 | X40: 6级 | Y40: 6级 | Z40: 6级 | AA40: 6级 | AB40: 6级 | AC40: 6级 | AD40: 空 | AE40: 空 | AF40: 0 | AJ40: 是 | AL40: 3级地358块 | AN40: 3 | AO40: 358
...

Sheet 102.5.1.04
A1: =(_xlfn.DAYS(TODAY(),A4)+2)/((_xlfn.DAYS(A94,A4))+1) -> 8.989011 | H1: 工作区 | AL1: 使用方法：按自己规划的路线，将下表中的地块名复制粘贴至工作区。初次使用传送门，当天跳步次数+5。重复使用传送门，当天跳步次数+1
A2: version 1.20 | C2: 合计经验 | E2: =SUM(E4:E94)+SUM(G4:G94) -> 61375 | H2: 队伍一 风 | J2: 步数 | K2: =COUNTIF(H4:O94,"<>空") -> 309 | L2: (不算跳步和传送) | P2: 队伍二 雷 | R2: 步数 | S2: =COUNTIF(P4:W94,"<>空") -> 302 | T2: (不算跳步和传送) | X2: 队伍三 | Z2: 总步数 | AA2: =COUNTIF(X4:AE94,"<>空") -> 412 | AB2: (不算跳步和传送) | AF2: =SUM(AF4:AF94) -> 46 | AG2: =SUM(AG4:AG94) -> 14 | AH2: =SUM(AH4:AH94) -> 24 | AI2: =SUM(AI4:AI94) -> 8 | AJ2: 八卦全开 | AW2: 粮草系数
A3: 日期 | B3: 获得粮草 | C3: 消耗粮草 | D3: 剩余粮草 | E3: 获得经验 | F3: 累计经验 | G3: 任务经验 | H3: 1 | I3: 2 | J3: 3 | K3: 4 | L3: 5 | M3: 6 | N3: 7 | O3: 8 | P3: 1 | Q3: 2 | R3: 3 | S3: 4 | T3: 5 | U3: 6 | V3: 7 | W3: 8 | X3: 1 | Y3: 2 | Z3: 3 | AA3: 4 | AB3: 5 | AC3: 6 | AD3: 7 | AE3: 8 | AF3: 跳步次数 | AG3: 1队跳步 | AH3: 2队跳步 | AI3: 3队跳步 | AL3: 地块 | AM3: 粮草 | AN3: 经验 | AO3: 一队地块 | AP3: 二队地块 | AQ3: 三队地块 | AR3: 总地块 | AS3: 一队经验 | AT3: 二队经验 | AU3: 三队经验 | AV3: 八卦前 | AW3: 1
A4: 44456 | B4: 800 | C4: {=(SUM(VLOOKUP(H4:AE4,$AL$4:$AN$44,2,FALSE))+AF4*10)*IF(AJ4="是",$AW$4,$AW$3)} -> 750 | D4: =SUM($B$4:B4)-SUM($C$4:C4) -> 50 | E4: {=SUM(VLOOKUP(H4:AE4,$AL$4:$AN$44,3,FALSE))} -> 175 | F4: =SUM($E$4:E4)+SUM($G$4:G4) -> 175 | G4: 0 | H4: 1级 | I4: 1级 | J4: 1级 | K4: 1级 | L4: 1级 | M4: 空 | N4: 空 | O4: 空 | P4: 空 | Q4: 空 | R4: 空 | S4: 空 | T4: 空 | U4: 空 | V4: 空 | W4: 空 | X4: 空 | Y4: 空 | Z4: 空 | AA4: 空 | AB4: 空 | AC4: 空 | AD4: 空 | AE4: 空 | AF4: 0 | AJ4: 否 | AL4: 1级 | AM4: 150 | AN4: 35 | AO4: =COUNTIF($H$4:$O$94,AL4) -> 14 | AP4: =COUNTIF($P$4:$W$94,AL4) -> 0 | AQ4: =COUNTIF($X$4:$AE$94,AL4) -> 12 | AR4: =AO4+AP4+AQ4 -> 26 | AS4: =AO4*$AN4 -> 490 | AT4: =AP4*$AN4 -> 0 | AU4: =AQ4*$AN4 -> 420 | AV4: 八卦后 | AW4: 0.8 | AY4: =AM4*0.8 -> 120
A5: 44457 | B5: 1600 | C5: {=(SUM(VLOOKUP(H5:AE5,$AL$4:$AN$44,2,FALSE))+AF5*10)*IF(AJ5="是",$AW$4,$AW$3)} -> 900 | D5: =SUM($B$4:B5)-SUM($C$4:C5) -> 750 | E5: {=SUM(VLOOKUP(H5:AE5,$AL$4:$AN$44,3,FALSE))} -> 210 | F5: =SUM($E$4:E5)+SUM($G$4:G5) -> 885 | G5: 500 | H5: 1级 | I5: 1级 | J5: 1级 | K5: 1级 | L5: 1级 | M5: 1级 | N5: 空 | O5: 空 | P5: 空 | Q5: 空 | R5: 空 | S5: 空 | T5: 空 | U5: 空 | V5: 空 | W5: 空 | X5: 空 | Y5: 空 | Z5: 空 | AA5: 空 | AB5: 空 | AC5: 空 | AD5: 空 | AE5: 空 | AF5: 0 | AJ5: 否 | AL5: 2级 | AM5: 160 | AN5: 40 | AO5: =COUNTIF($H$4:$O$94,AL5) -> 16 | AP5: =COUNTIF($P$4:$W$94,AL5) -> 1 | AQ5: =COUNTIF($X$4:$AE$94,AL5) -> 9 | AR5: =AO5+AP5+AQ5 -> 26 | AS5: =AO5*$AN5 -> 640 | AT5: =AP5*$AN5 -> 40 | AU5: =AQ5*$AN5 -> 360 | AV5: Note：开完八卦当天可能需要手动计算粮草 | AY5: =AM5*0.8 -> 128
A6: 44458 | B6: 1600 | C6: {=(SUM(VLOOKUP(H6:AE6,$AL$4:$AN$44,2,FALSE))+AF6*10)*IF(AJ6="是",$AW$4,$AW$3)} -> 980 | D6: =SUM($B$4:B6)-SUM($C$4:C6) -> 1370 | E6: {=SUM(VLOOKUP(H6:AE6,$AL$4:$AN$44,3,FALSE))} -> 225 | F6: =SUM($E$4:E6)+SUM($G$4:G6) -> 1110 | G6: 0 | H6: 1级 | I6: 1级 | J6: 1级 | K6: 2级 | L6: 2级 | M6: 2级 | N6: 空 | O6: 空 | P6: 空 | Q6: 空 | R6: 空 | S6: 空 | T6: 空 | U6: 空 | V6: 空 | W6: 空 | X6: 空 | Y6: 空 | Z6: 空 | AA6: 空 | AB6: 空 | AC6: 空 | AD6: 空 | AE6: 空 | AF6: 5 | AG6: 5 | AJ6: 否 | AL6: 3级 | AM6: 170 | AN6: 45 | AO6: =COUNTIF($H$4:$O$94,AL6) -> 136 | AP6: =COUNTIF($P$4:$W$94,AL6) -> 44 | AQ6: =COUNTIF($X$4:$AE$94,AL6) -> 10 | AR6: =AO6+AP6+AQ6 -> 190 | AS6: =AO6*$AN6 -> 6120 | AT6: =AP6*$AN6 -> 1980 | AU6: =AQ6*$AN6 -> 450 | AY6: =AM6*0.8 -> 136
A7: 44459 | B7: 1600 | C7: {=(SUM(VLOOKUP(H7:AE7,$AL$4:$AN$44,2,FALSE))+AF7*10)*IF(AJ7="是",$AW$4,$AW$3)} -> 990 | D7: =SUM($B$4:B7)-SUM($C$4:C7) -> 1980 | E7: {=SUM(VLOOKUP(H7:AE7,$AL$4:$AN$44,3,FALSE))} -> 260 | F7: =SUM($E$4:E7)+SUM($G$4:G7) -> 1570 | G7: 200 | H7: 塔2 | I7: 2级 | J7: 3级 | K7: 3级 | L7: 3级 | M7: 3级 | N7: 空 | O7: 空 | P7: 空 | Q7: 空 | R7: 空 | S7: 空 | T7: 空 | U7: 空 | V7: 空 | W7: 空 | X7: 空 | Y7: 空 | Z7: 空 | AA7: 空 | AB7: 空 | AC7: 空 | AD7: 空 | AE7: 空 | AF7: 0 | AJ7: 否 | AL7: 4级 | AM7: 180 | AN7: 50 | AO7: =COUNTIF($H$4:$O$94,AL7) -> 111 | AP7: =COUNTIF($P$4:$W$94,AL7) -> 45 | AQ7: =COUNTIF($X$4:$AE$94,AL7) -> 113 | AR7: =AO7+AP7+AQ7 -> 269 | AS7: =AO7*$AN7 -> 5550 | AT7: =AP7*$AN7 -> 2250 | AU7: =AQ7*$AN7 -> 5650 | AY7: =AM7*0.8 -> 144
