Workbook

Sheet 17.01
A1: =(_xlfn.DAYS(TODAY(),A4)+2)/((_xlfn.DAYS(A93,A4))+1) -> 0.022222222 | I1: 工作区 | AM1: 使用方法：按自己规划的路线，将下表中的地块名复制粘贴至工作区。初次使用传送门，当天跳步次数+5。重复使用传送门，当天跳步次数+1
A2: 17.01 | B2: 八卦前亏 | C2: =SUM(亏损!A4:X93)+SUM(AG4:AG14)*10 -> 8495.991 | D2: 合计经验 | F2: =SUM(F4:F93)+SUM(H4:H93) -> 23280 | I2: 队伍一 火 | K2: 步数 | L2: =COUNTIF(I4:P93,"<>空") -> 29 | M2: (不算跳步和传送) | Q2: 队伍二 雷 | S2: 步数 | T2: =COUNTIF(Q4:X93,"<>空") -> 196 | U2: (不算跳步和传送) | Y2: 队伍三 | AA2: 总步数 | AB2: =COUNTIF(Y4:AF93,"<>空") -> 93 | AC2: (不算跳步和传送) | AG2: =SUM(AG4:AG93) -> 56 | AH2: =SUM(AH4:AH93) -> 0 | AI2: =SUM(AI4:AI93) -> 29 | AJ2: =SUM(AJ4:AJ93) -> 27 | AK2: 八卦全开 | AS2: 总地块 | AT2: =SUM(AT4:AT29) -> 318 | AV2: 总经验 | AW2: =SUM(AU4:AW29)+7000 -> 23280 | AY2: 粮草系数
A3: 日期 | B3: 获得粮草 | C3: 粮草调整 | D3: 消耗粮草 | E3: 剩余粮草 | F3: 获得经验 | G3: 累计经验 | H3: 任务经验 | I3: 1 | J3: 2 | K3: 3 | L3: 4 | M3: 5 | N3: 6 | O3: 7 | P3: 8 | Q3: 1 | R3: 2 | S3: 3 | T3: 4 | U3: 5 | V3: 6 | W3: 7 | X3: 8 | Y3: 1 | Z3: 2 | AA3: 3 | AB3: 4 | AC3: 5 | AD3: 6 | AE3: 7 | AF3: 8 | AG3: 跳步次数 | AH3: 1队跳步 | AI3: 2队跳步 | AJ3: 3队跳步 | AM3: 地块 | AN3: 粮草 | AO3: 经验 | AP3: 八卦前亏损 | AQ3: 一队地块 | AR3: 二队地块 | AS3: 三队地块 | AT3: 总地块 | AU3: 一队经验 | AV3: 二队经验 | AW3: 三队经验 | AX3: 八卦前 | AY3: 1
A4: 45548 | B4: 800 | C4: 4800 | D4: =(SUM(粮草!A4:X4)+AG4*10*IF(AK4="是",$AY$4,$AY$3)) -> 2000 | E4: =SUM($B$4:B4)+SUM($C$4:C4)-SUM($D$4:D4) -> 3600 | F4: =SUM(经验!A4:X4) -> 485 | G4: =SUM($F$4:F4)+SUM($H$4:H4) -> 985 | H4: 500 | I4: 1级 | J4: 1级 | K4: 1级 | L4: 空 | M4: 空 | N4: 空 | O4: 空 | P4: 空 | Q4: 1级 | R4: 1级 | S4: 商人 | T4: 1级 | U4: 1级 | V4: 1级 | W4: 空 | X4: 空 | Y4: 1级 | Z4: 1级 | AA4: 1级 | AB4: 1级 | AC4: 1级 | AD4: 空 | AE4: 空 | AF4: 空 | AG4: =AH4+AI4+AJ4 -> 0 | AK4: 否 | AM4: 1级 | AN4: 150 | AO4: 35 | AP4: 44.222109 | AQ4: =COUNTIF($I$4:$P$93,AM4) -> 9 | AR4: =COUNTIF($Q$4:$X$93,AM4) -> 8 | AS4: =COUNTIF($Y$4:$AF$93,AM4) -> 13 | AT4: =AQ4+AR4+AS4 -> 30 | AU4: =AQ4*$AO4 -> 315 | AV4: =AR4*$AO4 -> 280 | AW4: =AS4*$AO4 -> 455 | AX4: 八卦后 | AY4: 0.8 | BA4: =AN4*0.8 -> 120
A5: 45549 | B5: 1600 | C5: 1200 | D5: =(SUM(粮草!A5:X5)+AG5*10*IF(AK5="是",$AY$4,$AY$3)) -> 1150 | E5: =SUM($B$4:B5)+SUM($C$4:C5)-SUM($D$4:D5) -> 5250 | F5: =SUM(经验!A5:X5) -> 305 | G5: =SUM($F$4:F5)+SUM($H$4:H5) -> 1290 | H5: 0 | I5: 空 | J5: 空 | K5: 空 | L5: 空 | M5: 空 | N5: 空 | O5: 空 | P5: 空 | Q5: 1级 | R5: 商人 | S5: 空 | T5: 空 | U5: 空 | V5: 空 | W5: 空 | X5: 空 | Y5: 商人 | Z5: 1级 | AA5: 1级 | AB5: 1级 | AC5: 1级 | AD5: 1级 | AE5: 1级 | AF5: 空 | AG5: =AH5+AI5+AJ5 -> 0 | AK5: 否 | AM5: 2级 | AN5: 160 | AO5: 40 | AP5: 39.110982 | AQ5: =COUNTIF($I$4:$P$93,AM5) -> 14 | AR5: =COUNTIF($Q$4:$X$93,AM5) -> 8 | AS5: =COUNTIF($Y$4:$AF$93,AM5) -> 16 | AT5: =AQ5+AR5+AS5 -> 38 | AU5: =AQ5*$AO5 -> 560 | AV5: =AR5*$AO5 -> 320 | AW5: =AS5*$AO5 -> 640 | AX5: Note：开完八卦当天可能需要手动计算粮草 | BA5: =AN5*0.8 -> 128
A6: 45550 | B6: 1600 | D6: =(SUM(粮草!A6:X6)+AG6*10*IF(AK6="是",$AY$4,$AY$3)) -> 2240 | E6: =SUM($B$4:B6)+SUM($C$4:C6)-SUM($D$4:D6) -> 4610 | F6: =SUM(经验!A6:X6) -> 595 | G6: =SUM($F$4:F6)+SUM($H$4:H6) -> 1885 | H6: 0 | I6: 空 | J6: 空 | K6: 空 | L6: 空 | M6: 空 | N6: 空 | O6: 空 | P6: 空 | Q6: 3级卦 | R6: 3级 | S6: 3级 | T6: 3级 | U6: 3级 | V6: 3级 | W6: 3级 | X6: 3级 | Y6: 商人 | Z6: 1级 | AA6: 1级 | AB6: 3级 | AC6: 3级 | AD6: 3级 | AE6: 空 | AF6: 空 | AG6: =AH6+AI6+AJ6 -> 2 | AI6: 1 | AJ6: 1 | AK6: 否 | AM6: 3级 | AN6: 170 | AO6: 45 | AP6: 34 | AQ6: =COUNTIF($I$4:$P$93,AM6) -> 0 | AR6: =COUNTIF($Q$4:$X$93,AM6) -> 59 | AS6: =COUNTIF($Y$4:$AF$93,AM6) -> 50 | AT6: =AQ6+AR6+AS6 -> 109 | AU6: =AQ6*$AO6 -> 0 | AV6: =AR6*$AO6 -> 2655 | AW6: =AS6*$AO6 -> 2250 | BA6: =AN6*0.8 -> 136
A7: 45551 | B7: 1600 | D7: =(SUM(粮草!A7:X7)+AG7*10*IF(AK7="是",$AY$4,$AY$3)) -> 2330 | E7: =SUM($B$4:B7)+SUM($C$4:C7)-SUM($D$4:D7) -> 3880 | F7: =SUM(经验!A7:X7) -> 870 | G7: =SUM($F$4:F7)+SUM($H$4:H7) -> 2955 | H7: 200 | I7: 空 | J7: 空 | K7: 空 | L7: 空 | M7: 空 | N7: 空 | O7: 空 | P7: 空 | Q7: 塔3 | R7: 3级 | S7: 3级 | T7: 3级 | U7: 大卦 | V7: 3级 | W7: 3级 | X7: 3级 | Y7: 3级 | Z7: 商人 | AA7: 3级 | AB7: 3级 | AC7: 3级 | AD7: 3级 | AE7: 空 | AF7: 空 | AG7: =AH7+AI7+AJ7 -> 1 | AI7: 1 | AK7: 否 | AM7: 4级 | AN7: 180 | AO7: 50 | AP7: 36 | AQ7: =COUNTIF($I$4:$P$93,AM7) -> 0 | AR7: =COUNTIF($Q$4:$X$93,AM7) -> 27 | AS7: =COUNTIF($Y$4:$AF$93,AM7) -> 0 | AT7: =AQ7+AR7+AS7 -> 27 | AU7: =AQ7*$AO7 -> 0 | AV7: =AR7*$AO7 -> 1350 | AW7: =AS7*$AO7 -> 0 | BA7: =AN7*0.8 -> 144
A8: 45552 | B8: 1600 | D8: =(SUM(粮草!A8:X8)+AG8*10*IF(AK8="是",$AY$4,$AY$3)) -> 1860 | E8: =SUM($B$4:B8)+SUM($C$4:C8)-SUM($D$4:D8) -> 3620 | F8: =SUM(经验!A8:X8) -> 735 | G8: =SUM($F$4:F8)+SUM($H$4:H8) -> 3790 | H8: 100 | I8: 空 | J8: 空 | K8: 空 | L8: 空 | M8: 空 | N8: 空 | O8: 空 | P8: 空 | Q8: 3级 | R8: 3级 | S8: 3级 | T8: 商人 | U8: 3级 | V8: 3级 | W8: 空 | X8: 空 | Y8: 3级 | Z8: 3级 | AA8: 3级 | AB8: 大卦 | AC8: 3级 | AD8: 空 | AE8: 空 | AF8: 空 | AG8: =AH8+AI8+AJ8 -> 3 | AJ8: 3 | AK8: 否 | AM8: 5级 | AN8: 190 | AO8: 55 | AP8: 38 | AQ8: =COUNTIF($I$4:$P$93,AM8) -> 0 | AR8: =COUNTIF($Q$4:$X$93,AM8) -> 10 | AS8: =COUNTIF($Y$4:$AF$93,AM8) -> 0 | AT8: =AQ8+AR8+AS8 -> 10 | AU8: =AQ8*$AO8 -> 0 | AV8: =AR8*$AO8 -> 550 | AW8: =AS8*$AO8 -> 0 | BA8: =AN8*0.8 -> 152
A9: 45553 | B9: 1600 | D9: =(SUM(粮草!A9:X9)+AG9*10*IF(AK9="是",$AY$4,$AY$3)) -> 1980 | E9: =SUM($B$4:B9)+SUM($C$4:C9)-SUM($D$4:D9) -> 3240 | F9: =SUM(经验!A9:X9) -> 550 | G9: =SUM($F$4:F9)+SUM($H$4:H9) -> 4540 | H9: 200 | I9: 空 | J9: 空 | K9: 空 | L9: 空 | M9: 空 | N9: 空 | O9: 空 | P9: 空 | Q9: 3级卦 | R9: 4级 | S9: 4级 | T9: 4级 | U9: 4级 | V9: 4级 | W9: 空 | X9: 空 | Y9: 3级 | Z9: 3级 | AA9: 3级 | AB9: 3级 | AC9: 商人 | AD9: 3级 | AE9: 空 | AF9: 空 | AG9: =AH9+AI9+AJ9 -> 1 | AI9: 1 | AK9: 否 | AM9: 6级 | AN9: 200 | AO9: 60 | AQ9: =COUNTIF($I$4:$P$93,AM9) -> 0 | AR9: =COUNTIF($Q$4:$X$93,AM9) -> 54 | AS9: =COUNTIF($Y$4:$AF$93,AM9) -> 0 | AT9: =AQ9+AR9+AS9 -> 54 | AU9: =AQ9*$AO9 -> 0 | AV9: =AR9*$AO9 -> 3240 | AW9: =AS9*$AO9 -> 0 | BA9: =AN9*0.8 -> 160
A10: 45554 | B10: 1600 | D10: =(SUM(粮草!A10:X10)+AG10*10*IF(AK10="是",$AY$4,$AY$3)) -> 2090 | E10: =SUM($B$4:B10)+SUM($C$4:C10)-SUM($D$4:D10) -> 2750 | F10: =SUM(经验!A10:X10) -> 555 | G10: =SUM($F$4:F10)+SUM($H$4:H10) -> 5095 | H10: 0 | I10: 空 | J10: 空 | K10: 空 | L10: 空 | M10: 空 | N10: 空 | O10: 空 | P10: 空 | Q10: 塔4 | R10: 4级 | S10: 4级 | T10: 3级 | U10: 3级 | V10: 3级 | W10: 空 | X10: 空 | Y10: 3级 | Z10: 3级 | AA10: 3级 | AB10: 3级 | AC10: 3级 | AD10: 3级 | AE10: 空 | AF10: 空 | AG10: =AH10+AI10+AJ10 -> 5 | AI10: 5 | AK10: 否 | AM10: 塔1 | AN10: 150 | AO10: 35 | AP10: 44.222109 | AQ10: =COUNTIF($I$4:$P$93,AM10) -> 0 | AR10: =COUNTIF($Q$4:$X$93,AM10) -> 0 | AS10: =COUNTIF($Y$4:$AF$93,AM10) -> 0 | AT10: =AQ10+AR10+AS10 -> 0 | AU10: =AQ10*$AO10 -> 0 | AV10: =AR10*$AO10 -> 0 | AW10: =AS10*$AO10 -> 0 | BA10: =AN10*0.8 -> 120
A11: 45555 | B11: 1600 | D11: =(SUM(粮草!A11:X11)+AG11*10*IF(AK11="是",$AY$4,$AY$3)) -> 1980 | E11: =SUM($B$4:B11)+SUM($C$4:C11)-SUM($D$4:D11) -> 2370 | F11: =SUM(经验!A11:X11) -> 575 | G11: =SUM($F$4:F11)+SUM($H$4:H11) -> 5670 | H11: 0 | I11: 空 | J11: 空 | K11: 空 | L11: 空 | M11: 空 | N11: 空 | O11: 空 | P11: 空 | Q11: 3级卦 | R11: 3级 | S11: 1级 | T11: 3级 | U11: 营地 | V11: 3级 | W11: 3级 | X11: 3级 | Y11: 3级 | Z11: 3级 | AA11: 3级 | AB11: 3级 | AC11: 3级 | AD11: 3级 | AE11: 空 | AF11: 空 | AG11: =AH11+AI11+AJ11 -> 4 | AI11: 4 | AK11: 否 | AM11: 塔2 | AN11: 150 | AO11: 40 | AP11: 29.110982 | AQ11: =COUNTIF($I$4:$P$93,AM11) -> 0 | AR11: =COUNTIF($Q$4:$X$93,AM11) -> 0 | AS11: =COUNTIF($Y$4:$AF$93,AM11) -> 1 | AT11: =AQ11+AR11+AS11 -> 1 | AU11: =AQ11*$AO11 -> 0 | AV11: =AR11*$AO11 -> 0 | AW11: =AS11*$AO11 -> 40 | BA11: =AN11*0.8 -> 120
A12: 45556 | B12: 1600 | D12: =(SUM(粮草!A12:X12)+AG12*10*IF(AK12="是",$AY$4,$AY$3)) -> 1900 | E12: =SUM($B$4:B12)+SUM($C$4:C12)-SUM($D$4:D12) -> 2070 | F12: =SUM(经验!A12:X12) -> 525 | G12: =SUM($F$4:F12)+SUM($H$4:H12) -> 6195 | H12: 0 | I12: 空 | J12: 空 | K12: 空 | L12: 空 | M12: 空 | N12: 空 | O12: 空 | P12: 空 | Q12: 3级 | R12: 3级 | S12: 塔3 | T12: 3级 | U12: 3级 | V12: 3级卦 | W12: 空 | X12: 空 | Y12: 3级 | Z12: 商人 | AA12: 3级 | AB12: 3级 | AC12: 3级 | AD12: 3级 | AE12: 空 | AF12: 空 | AG12: =AH12+AI12+AJ12 -> 0 | AK12: 否 | AM12: 塔3 | AN12: 150 | AO12: 45 | AP12: 13.999855 | AQ12: =COUNTIF($I$4:$P$93,AM12) -> 0 | AR12: =COUNTIF($Q$4:$X$93,AM12) -> 4 | AS12: =COUNTIF($Y$4:$AF$93,AM12) -> 0 | AT12: =AQ12+AR12+AS12 -> 4 | AU12: =AQ12*$AO12 -> 0 | AV12: =AR12*$AO12 -> 180 | AW12: =AS12*$AO12 -> 0 | BA12: =AN12*0.8 -> 120
A13: 45557 | B13: 1600 | D13: =(SUM(粮草!A13:X13)+AG13*10*IF(AK13="是",$AY$4,$AY$3)) -> 1240 | E13: =SUM($B$4:B13)+SUM($C$4:C13)-SUM($D$4:D13) -> 2430 | F13: =SUM(经验!A13:X13) -> 580 | G13: =SUM($F$4:F13)+SUM($H$4:H13) -> 6775 | H13: 0 | I13: 空 | J13: 空 | K13: 空 | L13: 空 | M13: 空 | N13: 空 | O13: 空 | P13: 空 | Q13: 4级 | R13: 商人 | S13: 4级 | T13: 4级 | U13: 4级 | V13: 4级 | W13: 空 | X13: 空 | Y13: 大卦 | Z13: 空 | AA13: 空 | AB13: 空 | AC13: 空 | AD13: 空 | AE13: 空 | AF13: 空 | AG13: =AH13+AI13+AJ13 -> 4 | AI13: 4 | AK13: 否 | AM13: 塔4 | AN13: 150 | AO13: 50 | AQ13: =COUNTIF($I$4:$P$93,AM13) -> 0 | AR13: =COUNTIF($Q$4:$X$93,AM13) -> 1 | AS13: =COUNTIF($Y$4:$AF$93,AM13) -> 0 | AT13: =AQ13+AR13+AS13 -> 1 | AU13: =AQ13*$AO13 -> 0 | AV13: =AR13*$AO13 -> 50 | AW13: =AS13*$AO13 -> 0 | BA13: =AN13*0.8 -> 120
A14: 45558 | B14: 1600 | D14: =(SUM(粮草!A14:X14)+AG14*10*IF(AK14="是",$AY$4,$AY$3)) -> 1970 | E14: =SUM($B$4:B14)+SUM($C$4:C14)-SUM($D$4:D14) -> 2060 | F14: =SUM(经验!A14:X14) -> 550 | G14: =SUM($F$4:F14)+SUM($H$4:H14) -> 7625 | H14: 300 | I14: 空 | J14: 空 | K14: 空 | L14: 空 | M14: 空 | N14: 空 | O14: 空 | P14: 空 | Q14: 4级 | R14: 4级 | S14: 4级 | T14: 4级 | U14: 4级 | V14: 商人 | W14: 空 | X14: 空 | Y14: 3级 | Z14: 3级 | AA14: 3级 | AB14: 3级 | AC14: 3级 | AD14: 3级 | AE14: 空 | AF14: 空 | AG14: =AH14+AI14+AJ14 -> 0 | AK14: 否 | AM14: 塔5 | AN14: 150 | AO14: 55 | AQ14: =COUNTIF($I$4:$P$93,AM14) -> 0 | AR14: =COUNTIF($Q$4:$X$93,AM14) -> 0 | AS14: =COUNTIF($Y$4:$AF$93,AM14) -> 0 | AT14: =AQ14+AR14+AS14 -> 0 | AU14: =AQ14*$AO14 -> 0 | AV14: =AR14*$AO14 -> 0 | AW14: =AS14*$AO14 -> 0 | BA14: =AN14*0.8 -> 120
A15: 45559 | B15: 1600 | C15: 384 | D15: =(SUM(粮草!A15:X15)+AG15*10*IF(AK15="是",$AY$4,$AY$3)) -> 1930 | E15: =SUM($B$4:B15)+SUM($C$4:C15)-SUM($D$4:D15) -> 2114 | F15: =SUM(经验!A15:X15) -> 530 | G15: =SUM($F$4:F15)+SUM($H$4:H15) -> 8155 | H15: 0 | I15: 空 | J15: 空 | K15: 空 | L15: 空 | M15: 空 | N15: 空 | O15: 空 | P15: 空 | Q15: 4级 | R15: 3级 | S15: 3级 | T15: 3级 | U15: 3级 | V15: 3级 | W15: 空 | X15: 空 | Y15: 3级 | Z15: 3级 | AA15: 3级 | AB15: 3级 | AC15: 商人 | AD15: 3级 | AE15: 空 | AF15: 空 | AG15: =AH15+AI15+AJ15 -> 0 | AK15: 否 | AM15: 塔6 | AN15: 150 | AO15: 60 | AQ15: =COUNTIF($I$4:$P$93,AM15) -> 0 | AR15: =COUNTIF($Q$4:$X$93,AM15) -> 0 | AS15: =COUNTIF($Y$4:$AF$93,AM15) -> 0 | AT15: =AQ15+AR15+AS15 -> 0 | AU15: =AQ15*$AO15 -> 0 | AV15: =AR15*$AO15 -> 0 | AW15: =AS15*$AO15 -> 0 | BA15: =AN15*0.8 -> 120
A16: 45560 | B16: 1600 | C16: -34 | D16: =(SUM(粮草!A16:X16)+AG16*10*IF(AK16="是",$AY$4,$AY$3)) -> 1412 | E16: =SUM($B$4:B16)+SUM($C$4:C16)-SUM($D$4:D16) -> 2268 | F16: =SUM(经验!A16:X16) -> 560 | G16: =SUM($F$4:F16)+SUM($H$4:H16) -> 8915 | H16: 200 | I16: 空 | J16: 空 | K16: 空 | L16: 空 | M16: 空 | N16: 空 | O16: 空 | P16: 空 | Q16: 3级卦 | R16: 3级 | S16: 3级 | T16: 3级 | U16: 商人 | V16: 3级 | W16: 空 | X16: 空 | Y16: 3级 | Z16: 3级 | AA16: 3级 | AB16: 营地 | AC16: 3级 | AD16: 3级 | AE16: 2级 | AF16: 2级 | AG16: =AH16+AI16+AJ16 -> 2 | AJ16: 2 | AK16: 是 | AM16: 遗迹 | AN16: 150 | AO16: 35 | AP16: 44.222109 | AQ16: =COUNTIF($I$4:$P$93,AM16) -> 0 | AR16: =COUNTIF($Q$4:$X$93,AM16) -> 0 | AS16: =COUNTIF($Y$4:$AF$93,AM16) -> 0 | AT16: =AQ16+AR16+AS16 -> 0 | AU16: =AQ16*$AO16 -> 0 | AV16: =AR16*$AO16 -> 0 | AW16: =AS16*$AO16 -> 0 | BA16: =AN16*0.8 -> 120
A17: 45561 | B17: 1600 | D17: =(SUM(粮草!A17:X17)+AG17*10*IF(AK17="是",$AY$4,$AY$3)) -> 1400 | E17: =SUM($B$4:B17)+SUM($C$4:C17)-SUM($D$4:D17) -> 2468 | F17: =SUM(经验!A17:X17) -> 485 | G17: =SUM($F$4:F17)+SUM($H$4:H17) -> 9400 | H17: 0 | I17: 空 | J17: 空 | K17: 空 | L17: 空 | M17: 空 | N17: 空 | O17: 空 | P17: 空 | Q17: 3级 | R17: 3级 | S17: 3级 | T17: 3级 | U17: 3级 | V17: 商人 | W17: 空 | X17: 空 | Y17: 2级 | Z17: 2级 | AA17: 商人 | AB17: 2级 | AC17: 2级 | AD17: 2级 | AE17: 空 | AF17: 空 | AG17: =AH17+AI17+AJ17 -> 0 | AK17: 是 | AM17: 商人 | AN17: 50 | AO17: 30 | AP17: 10 | AQ17: =COUNTIF($I$4:$P$93,AM17) -> 5 | AR17: =COUNTIF($Q$4:$X$93,AM17) -> 11 | AS17: =COUNTIF($Y$4:$AF$93,AM17) -> 9 | AT17: =AQ17+AR17+AS17 -> 25 | AU17: =AQ17*$AO17 -> 150 | AV17: =AR17*$AO17 -> 330 | AW17: =AS17*$AO17 -> 270 | BA17: =AN17*0.8 -> 40
A18: 45562 | B18: 1600 | D18: =(SUM(粮草!A18:X18)+AG18*10*IF(AK18="是",$AY$4,$AY$3)) -> 1388 | E18: =SUM($B$4:B18)+SUM($C$4:C18)-SUM($D$4:D18) -> 2680 | F18: =SUM(经验!A18:X18) -> 540 | G18: =SUM($F$4:F18)+SUM($H$4:H18) -> 9940 | H18: 0 | I18: 空 | J18: 空 | K18: 空 | L18: 空 | M18: 空 | N18: 空 | O18: 空 | P18: 空 | Q18: 3级 | R18: 3级 | S18: 3级 | T18: 3级 | U18: 3级 | V18: 塔3 | W18: 空 | X18: 空 | Y18: 2级 | Z18: 2级 | AA18: 2级 | AB18: 2级 | AC18: 2级 | AD18: 2级 | AE18: 营地 | AF18: 商人 | AG18: =AH18+AI18+AJ18 -> 5 | AJ18: 5 | AK18: 是 | AM18: 营地 | AN18: -150 | AO18: 0 | AP18: 10 | AQ18: =COUNTIF($I$4:$P$93,AM18) -> 1 | AR18: =COUNTIF($Q$4:$X$93,AM18) -> 6 | AS18: =COUNTIF($Y$4:$AF$93,AM18) -> 2 | AT18: =AQ18+AR18+AS18 -> 9 | AU18: =AQ18*$AO18 -> 0 | AV18: =AR18*$AO18 -> 0 | AW18: =AS18*$AO18 -> 0 | BA18: =AN18*0.8 -> -120
A19: 45563 | B19: 1600 | D19: =(SUM(粮草!A19:X19)+AG19*10*IF(AK19="是",$AY$4,$AY$3)) -> 816 | E19: =SUM($B$4:B19)+SUM($C$4:C19)-SUM($D$4:D19) -> 3464 | F19: =SUM(经验!A19:X19) -> 270 | G19: =SUM($F$4:F19)+SUM($H$4:H19) -> 10210 | H19: 0 | I19: 空 | J19: 空 | K19: 空 | L19: 空 | M19: 空 | N19: 空 | O19: 空 | P19: 空 | Q19: 3级 | R19: 3级 | S19: 3级 | T19: 3级 | U19: 3级 | V19: 3级 | W19: 空 | X19: 空 | Y19: 空 | Z19: 空 | AA19: 空 | AB19: 空 | AC19: 空 | AD19: 空 | AE19: 空 | AF19: 空 | AG19: =AH19+AI19+AJ19 -> 0 | AK19: 是 | AM19: 大卦 | AN19: 250 | AO19: 300 | AQ19: =COUNTIF($I$4:$P$93,AM19) -> 0 | AR19: =COUNTIF($Q$4:$X$93,AM19) -> 1 | AS19: =COUNTIF($Y$4:$AF$93,AM19) -> 2 | AT19: =AQ19+AR19+AS19 -> 3 | AU19: =AQ19*$AO19 -> 0 | AV19: =AR19*$AO19 -> 300 | AW19: =AS19*$AO19 -> 600 | BA19: =AN19*0.8 -> 200
A20: 45564 | B20: 1600 | D20: =(SUM(粮草!A20:X20)+AG20*10*IF(AK20="是",$AY$4,$AY$3)) -> 936 | E20: =SUM($B$4:B20)+SUM($C$4:C20)-SUM($D$4:D20) -> 4128 | F20: =SUM(经验!A20:X20) -> 345 | G20: =SUM($F$4:F20)+SUM($H$4:H20) -> 10555 | H20: 0 | I20: 空 | J20: 空 | K20: 空 | L20: 空 | M20: 空 | N20: 空 | O20: 空 | P20: 空 | Q20: 3级 | R20: 6级 | S20: 6级 | T20: 6级 | U20: 6级 | V20: 6级 | W20: 空 | X20: 空 | Y20: 空 | Z20: 空 | AA20: 空 | AB20: 空 | AC20: 空 | AD20: 空 | AE20: 空 | AF20: 空 | AG20: =AH20+AI20+AJ20 -> 0 | AK20: 是 | AM20: 3级卦 | AN20: 170 | AO20: 45 | AQ20: =COUNTIF($I$4:$P$93,AM20) -> 0 | AR20: =COUNTIF($Q$4:$X$93,AM20) -> 5 | AS20: =COUNTIF($Y$4:$AF$93,AM20) -> 0 | AT20: =AQ20+AR20+AS20 -> 5 | AU20: =AQ20*$AO20 -> 0 | AV20: =AR20*$AO20 -> 225 | AW20: =AS20*$AO20 -> 0 | BA20: =AN20*0.8 -> 136
A21: 45565 | B21: 1600 | D21: =(SUM(粮草!A21:X21)+AG21*10*IF(AK21="是",$AY$4,$AY$3)) -> 960 | E21: =SUM($B$4:B21)+SUM($C$4:C21)-SUM($D$4:D21) -> 4768 | F21: =SUM(经验!A21:X21) -> 360 | G21: =SUM($F$4:F21)+SUM($H$4:H21) -> 11115 | H21: 200 | I21: 空 | J21: 空 | K21: 空 | L21: 空 | M21: 空 | N21: 空 | O21: 空 | P21: 空 | Q21: 6级 | R21: 6级 | S21: 6级 | T21: 6级 | U21: 6级 | V21: 6级 | W21: 空 | X21: 空 | Y21: 空 | Z21: 空 | AA21: 空 | AB21: 空 | AC21: 空 | AD21: 空 | AE21: 空 | AF21: 空 | AG21: =AH21+AI21+AJ21 -> 0 | AK21: 是 | AM21: 巨卦 | AN21: 250 | AO21: 400 | AQ21: =COUNTIF($I$4:$P$93,AM21) -> 0 | AR21: =COUNTIF($Q$4:$X$93,AM21) -> 0 | AS21: =COUNTIF($Y$4:$AF$93,AM21) -> 0 | AT21: =AQ21+AR21+AS21 -> 0 | AU21: =AQ21*$AO21 -> 0 | AV21: =AR21*$AO21 -> 0 | AW21: =AS21*$AO21 -> 0 | BA21: =AN21*0.8 -> 200
A22: 45566 | B22: 1600 | D22: =(SUM(粮草!A22:X22)+AG22*10*IF(AK22="是",$AY$4,$AY$3)) -> 960 | E22: =SUM($B$4:B22)+SUM($C$4:C22)-SUM($D$4:D22) -> 5408 | F22: =SUM(经验!A22:X22) -> 360 | G22: =SUM($F$4:F22)+SUM($H$4:H22) -> 11575 | H22: 100 | I22: 空 | J22: 空 | K22: 空 | L22: 空 | M22: 空 | N22: 空 | O22: 空 | P22: 空 | Q22: 6级 | R22: 6级 | S22: 6级 | T22: 6级 | U22: 6级 | V22: 6级 | W22: 空 | X22: 空 | Y22: 空 | Z22: 空 | AA22: 空 | AB22: 空 | AC22: 空 | AD22: 空 | AE22: 空 | AF22: 空 | AG22: =AH22+AI22+AJ22 -> 0 | AK22: 是 | AM22: 大boss | AN22: 250 | AO22: 1000 | AQ22: =COUNTIF($I$4:$P$93,AM22) -> 0 | AR22: =COUNTIF($Q$4:$X$93,AM22) -> 1 | AS22: =COUNTIF($Y$4:$AF$93,AM22) -> 0 | AT22: =AQ22+AR22+AS22 -> 1 | AU22: =AQ22*$AO22 -> 0 | AV22: =AR22*$AO22 -> 1000 | AW22: =AS22*$AO22 -> 0 | BA22: =AN22*0.8 -> 200
A23: 45567 | B23: 1600 | D23: =(SUM(粮草!A23:X23)+AG23*10*IF(AK23="是",$AY$4,$AY$3)) -> 678 | E23: =SUM($B$4:B23)+SUM($C$4:C23)-SUM($D$4:D23) -> 6330 | F23: =SUM(经验!A23:X23) -> 330 | G23: =SUM($F$4:F23)+SUM($H$4:H23) -> 12105 | H23: 200 | I23: 空 | J23: 空 | K23: 空 | L23: 空 | M23: 空 | N23: 空 | O23: 空 | P23: 空 | Q23: 塔3 | R23: 3级 | S23: 商人 | T23: 3级 | U23: 3级 | V23: 营地 | W23: 6级 | X23: 6级 | Y23: 空 | Z23: 空 | AA23: 空 | AB23: 空 | AC23: 空 | AD23: 空 | AE23: 空 | AF23: 空 | AG23: =AH23+AI23+AJ23 -> 0 | AK23: 是 | AM23: 中boss | AN23: 250 | AO23: 500 | AQ23: =COUNTIF($I$4:$P$93,AM23) -> 0 | AR23: =COUNTIF($Q$4:$X$93,AM23) -> 0 | AS23: =COUNTIF($Y$4:$AF$93,AM23) -> 0 | AT23: =AQ23+AR23+AS23 -> 0 | AU23: =AQ23*$AO23 -> 0 | AV23: =AR23*$AO23 -> 0 | AW23: =AS23*$AO23 -> 0 | BA23: =AN23*0.8 -> 200
A24: 45568 | B24: 1600 | D24: =(SUM(粮草!A24:X24)+AG24*10*IF(AK24="是",$AY$4,$AY$3)) -> 960 | E24: =SUM($B$4:B24)+SUM($C$4:C24)-SUM($D$4:D24) -> 6970 | F24: =SUM(经验!A24:X24) -> 360 | G24: =SUM($F$4:F24)+SUM($H$4:H24) -> 12465 | H24: 0 | I24: 空 | J24: 空 | K24: 空 | L24: 空 | M24: 空 | N24: 空 | O24: 空 | P24: 空 | Q24: 6级 | R24: 6级 | S24: 6级 | T24: 6级 | U24: 6级 | V24: 6级 | W24: 空 | X24: 空 | Y24: 空 | Z24: 空 | AA24: 空 | AB24: 空 | AC24: 空 | AD24: 空 | AE24: 空 | AF24: 空 | AG24: =AH24+AI24+AJ24 -> 0 | AK24: 是 | AM24: 4级卦 | AN24: 180 | AO24: 50 | AP24: 39.110982 | AQ24: =COUNTIF($I$4:$P$93,AM24) -> 0 | AR24: =COUNTIF($Q$4:$X$93,AM24) -> 0 | AS24: =COUNTIF($Y$4:$AF$93,AM24) -> 0 | AT24: =AQ24+AR24+AS24 -> 0 | AU24: =AQ24*$AO24 -> 0 | AV24: =AR24*$AO24 -> 0 | AW24: =AS24*$AO24 -> 0 | BA24: =AN24*0.8 -> 144
A25: 45569 | B25: 1600 | D25: =(SUM(粮草!A25:X25)+AG25*10*IF(AK25="是",$AY$4,$AY$3)) -> 1000 | E25: =SUM($B$4:B25)+SUM($C$4:C25)-SUM($D$4:D25) -> 7570 | F25: =SUM(经验!A25:X25) -> 1300 | G25: =SUM($F$4:F25)+SUM($H$4:H25) -> 13765 | H25: 0 | I25: 空 | J25: 空 | K25: 空 | L25: 空 | M25: 空 | N25: 空 | O25: 空 | P25: 空 | Q25: 大boss | R25: 6级 | S25: 6级 | T25: 6级 | U25: 6级 | V25: 6级 | W25: 空 | X25: 空 | Y25: 空 | Z25: 空 | AA25: 空 | AB25: 空 | AC25: 空 | AD25: 空 | AE25: 空 | AF25: 空 | AG25: =AH25+AI25+AJ25 -> 0 | AK25: 是 | AM25: 山中 | AN25: 160 | AO25: 40 | AP25: 39.110982 | AQ25: =COUNTIF($I$4:$P$93,AM25) -> 0 | AR25: =COUNTIF($Q$4:$X$93,AM25) -> 0 | AS25: =COUNTIF($Y$4:$AF$93,AM25) -> 0 | AT25: =AQ25+AR25+AS25 -> 0 | AU25: =AQ25*$AO25 -> 0 | AV25: =AR25*$AO25 -> 0 | AW25: =AS25*$AO25 -> 0 | BA25: =AN25*0.8 -> 128
A26: 45570 | B26: 1600 | D26: =(SUM(粮草!A26:X26)+AG26*10*IF(AK26="是",$AY$4,$AY$3)) -> 976 | E26: =SUM($B$4:B26)+SUM($C$4:C26)-SUM($D$4:D26) -> 8194 | F26: =SUM(经验!A26:X26) -> 360 | G26: =SUM($F$4:F26)+SUM($H$4:H26) -> 14125 | H26: 0 | I26: 空 | J26: 空 | K26: 空 | L26: 空 | M26: 空 | N26: 空 | O26: 空 | P26: 空 | Q26: 6级 | R26: 6级 | S26: 6级 | T26: 6级 | U26: 6级 | V26: 6级 | W26: 空 | X26: 空 | Y26: 空 | Z26: 空 | AA26: 空 | AB26: 空 | AC26: 空 | AD26: 空 | AE26: 空 | AF26: 空 | AG26: =AH26+AI26+AJ26 -> 2 | AI26: 2 | AK26: 是 | AM26: 秋道 | AN26: 150 | AO26: 35 | AP26: 44.222109 | AQ26: =COUNTIF($I$4:$P$93,AM26) -> 0 | AR26: =COUNTIF($Q$4:$X$93,AM26) -> 0 | AS26: =COUNTIF($Y$4:$AF$93,AM26) -> 0 | AT26: =AQ26+AR26+AS26 -> 0 | AU26: =AQ26*$AO26 -> 0 | AV26: =AR26*$AO26 -> 0 | AW26: =AS26*$AO26 -> 0 | BA26: =AN26*0.8 -> 120
A27: 45571 | B27: 1600 | D27: =(SUM(粮草!A27:X27)+AG27*10*IF(AK27="是",$AY$4,$AY$3)) -> 840 | E27: =SUM($B$4:B27)+SUM($C$4:C27)-SUM($D$4:D27) -> 8954 | F27: =SUM(经验!A27:X27) -> 330 | G27: =SUM($F$4:F27)+SUM($H$4:H27) -> 14455 | H27: 0 | I27: 空 | J27: 空 | K27: 空 | L27: 空 | M27: 空 | N27: 空 | O27: 空 | P27: 空 | Q27: 6级 | R27: 商人 | S27: 6级 | T27: 6级 | U27: 6级 | V27: 6级 | W27: 空 | X27: 空 | Y27: 空 | Z27: 空 | AA27: 空 | AB27: 空 | AC27: 空 | AD27: 空 | AE27: 空 | AF27: 空 | AG27: =AH27+AI27+AJ27 -> 0 | AK27: 是 | AM27: 空 | AN27: 0 | AO27: 0 | AP27: 0 | AU27: =AQ27*$AO27 -> 0 | AV27: =AR27*$AO27 -> 0 | AW27: =AS27*$AO27 -> 0 | BA27: =AN27*0.8 -> 0
A28: 45572 | B28: 1600 | D28: =(SUM(粮草!A28:X28)+AG28*10*IF(AK28="是",$AY$4,$AY$3)) -> 910 | E28: =SUM($B$4:B28)+SUM($C$4:C28)-SUM($D$4:D28) -> 9644 | F28: =SUM(经验!A28:X28) -> 420 | G28: =SUM($F$4:F28)+SUM($H$4:H28) -> 15075 | H28: 200 | I28: 空 | J28: 空 | K28: 空 | L28: 空 | M28: 空 | N28: 空 | O28: 空 | P28: 空 | Q28: 6级 | R28: 6级 | S28: 6级 | T28: 营地 | U28: 6级 | V28: 6级 | W28: 6级 | X28: 6级 | Y28: 空 | Z28: 空 | AA28: 空 | AB28: 空 | AC28: 空 | AD28: 空 | AE28: 空 | AF28: 空 | AG28: =AH28+AI28+AJ28 -> 0 | AK28: 是 | AM28: 作废 | AN28: 0 | AO28: 0 | AQ28: =COUNTIF($I$4:$P$93,AM28) -> 0 | AR28: =COUNTIF($Q$4:$X$93,AM28) -> 0 | AS28: =COUNTIF($Y$4:$AF$93,AM28) -> 0 | AT28: =AQ28+AR28+AS28 -> 0 | AU28: =AQ28*$AO28 -> 0 | AV28: =AR28*$AO28 -> 0 | AW28: =AS28*$AO28 -> 0 | BA28: =AN28*0.8 -> 0
A29: 45573 | B29: 1600 | D29: =(SUM(粮草!A29:X29)+AG29*10*IF(AK29="是",$AY$4,$AY$3)) -> 968 | E29: =SUM($B$4:B29)+SUM($C$4:C29)-SUM($D$4:D29) -> 10276 | F29: =SUM(经验!A29:X29) -> 340 | G29: =SUM($F$4:F29)+SUM($H$4:H29) -> 15515 | H29: 100 | I29: 空 | J29: 空 | K29: 空 | L29: 空 | M29: 空 | N29: 空 | O29: 空 | P29: 空 | Q29: 6级 | R29: 6级 | S29: 6级 | T29: 6级 | U29: 6级 | V29: 2级 | W29: 空 | X29: 空 | Y29: 空 | Z29: 空 | AA29: 空 | AB29: 空 | AC29: 空 | AD29: 空 | AE29: 空 | AF29: 空 | AG29: =AH29+AI29+AJ29 -> 5 | AI29: 5 | AK29: 是 | AM29: 历练 | AN29: 50 | AO29: 520 | AQ29: =COUNTIF($I$4:$P$93,AM29) -> 0 | AR29: =COUNTIF($Q$4:$X$93,AM29) -> 1 | AS29: =COUNTIF($Y$4:$AF$93,AM29) -> 0 | AT29: =AQ29+AR29+AS29 -> 1 | AU29: =AQ29*$AO29 -> 0 | AV29: =AR29*$AO29 -> 520 | AW29: =AS29*$AO29 -> 0 | BA29: =AN29*0.8 -> 40
A30: 45574 | B30: 1600 | D30: =(SUM(粮草!A30:X30)+AG30*10*IF(AK30="是",$AY$4,$AY$3)) -> 784 | E30: =SUM($B$4:B30)+SUM($C$4:C30)-SUM($D$4:D30) -> 11092 | F30: =SUM(经验!A30:X30) -> 760 | G30: =SUM($F$4:F30)+SUM($H$4:H30) -> 16475 | H30: 200 | I30: 空 | J30: 空 | K30: 空 | L30: 空 | M30: 空 | N30: 空 | O30: 空 | P30: 空 | Q30: 1级 | R30: 2级 | S30: 历练 | T30: 2级 | U30: 商人 | V30: 2级 | W30: 5级 | X30: 空 | Y30: 空 | Z30: 空 | AA30: 空 | AB30: 空 | AC30: 空 | AD30: 空 | AE30: 空 | AF30: 空 | AG30: =AH30+AI30+AJ30 -> 6 | AI30: 6 | AK30: 是
A31: 45575 | B31: 1600 | D31: =(SUM(粮草!A31:X31)+AG31*10*IF(AK31="是",$AY$4,$AY$3)) -> 1568 | E31: =SUM($B$4:B31)+SUM($C$4:C31)-SUM($D$4:D31) -> 11124 | F31: =SUM(经验!A31:X31) -> 550 | G31: =SUM($F$4:F31)+SUM($H$4:H31) -> 17025 | H31: 0 | I31: 1级 | J31: 1级 | K31: 商人 | L31: 1级 | M31: 1级 | N31: 1级 | O31: 商人 | P31: 空 | Q31: 5级 | R31: 5级 | S31: 5级 | T31: 4级 | U31: 4级 | V31: 4级 | W31: 空 | X31: 空 | Y31: 空 | Z31: 空 | AA31: 空 | AB31: 空 | AC31: 空 | AD31: 空 | AE31: 空 | AF31: 空 | AG31: =AH31+AI31+AJ31 -> 0 | AK31: 是
A32: 45576 | B32: 1600 | C32: 40 | D32: =(SUM(粮草!A32:X32)+AG32*10*IF(AK32="是",$AY$4,$AY$3)) -> 1276 | E32: =SUM($B$4:B32)+SUM($C$4:C32)-SUM($D$4:D32) -> 11488 | F32: =SUM(经验!A32:X32) -> 585 | G32: =SUM($F$4:F32)+SUM($H$4:H32) -> 17610 | H32: 0 | I32: 2级 | J32: 2级 | K32: 2级 | L32: 商人 | M32: 2级 | N32: 2级 | O32: 营地 | P32: 空 | Q32: 4级 | R32: 营地 | S32: 4级 | T32: 4级 | U32: 4级 | V32: 4级 | W32: 4级 | X32: 5级 | Y32: 空 | Z32: 空 | AA32: 空 | AB32: 空 | AC32: 空 | AD32: 空 | AE32: 空 | AF32: 空 | AG32: =AH32+AI32+AJ32 -> 0 | AK32: 是 | AM32: 地块统计 | AN32: 应占领 | AO32: 缺少 | AP32: 粮草
A33: 45577 | B33: 1600 | D33: =(SUM(粮草!A33:X33)+AG33*10*IF(AK33="是",$AY$4,$AY$3)) -> 500 | E33: =SUM($B$4:B33)+SUM($C$4:C33)-SUM($D$4:D33) -> 12588 | F33: =SUM(经验!A33:X33) -> 335 | G33: =SUM($F$4:F33)+SUM($H$4:H33) -> 17945 | H33: 0 | I33: 空 | J33: 空 | K33: 空 | L33: 空 | M33: 空 | N33: 空 | O33: 空 | P33: 空 | Q33: 5级 | R33: 营地 | S33: 5级 | T33: 5级 | U33: 5级 | V33: 5级 | W33: 6级 | X33: 营地 | Y33: 空 | Z33: 空 | AA33: 空 | AB33: 空 | AC33: 空 | AD33: 空 | AE33: 空 | AF33: 空 | AG33: =AH33+AI33+AJ33 -> 0 | AK33: 是 | AM33: 3级 | AN33: 186 | AO33: =AN33-AT6 -> 77 | AP33: =AO33*AN6*0.8 -> 10472 | AQ33: =AO33*AO6 -> 3465
A34: 45578 | B34: 1600 | D34: =(SUM(粮草!A34:X34)+AG34*10*IF(AK34="是",$AY$4,$AY$3)) -> 0 | E34: =SUM($B$4:B34)+SUM($C$4:C34)-SUM($D$4:D34) -> 14188 | F34: =SUM(经验!A34:X34) -> 0 | G34: =SUM($F$4:F34)+SUM($H$4:H34) -> 17945 | H34: 0 | I34: 空 | J34: 空 | K34: 空 | L34: 空 | M34: 空 | N34: 空 | O34: 空 | P34: 空 | Q34: 空 | R34: 空 | S34: 空 | T34: 空 | U34: 空 | V34: 空 | W34: 空 | X34: 空 | Y34: 空 | Z34: 空 | AA34: 空 | AB34: 空 | AC34: 空 | AD34: 空 | AE34: 空 | AF34: 空 | AG34: =AH34+AI34+AJ34 -> 0 | AK34: 是 | AM34: 4级 | AN34: 276 | AO34: =AN34-AT7 -> 249 | AP34: =AO34*AN7*0.8 -> 35856 | AQ34: =AO34*AO7 -> 12450
A35: 45579 | B35: 1600 | D35: =(SUM(粮草!A35:X35)+AG35*10*IF(AK35="是",$AY$4,$AY$3)) -> 0 | E35: =SUM($B$4:B35)+SUM($C$4:C35)-SUM($D$4:D35) -> 15788 | F35: =SUM(经验!A35:X35) -> 0 | G35: =SUM($F$4:F35)+SUM($H$4:H35) -> 18145 | H35: 200 | I35: 空 | J35: 空 | K35: 空 | L35: 空 | M35: 空 | N35: 空 | O35: 空 | P35: 空 | Q35: 空 | R35: 空 | S35: 空 | T35: 空 | U35: 空 | V35: 空 | W35: 空 | X35: 空 | Y35: 空 | Z35: 空 | AA35: 空 | AB35: 空 | AC35: 空 | AD35: 空 | AE35: 空 | AF35: 空 | AG35: =AH35+AI35+AJ35 -> 0 | AK35: 是 | AM35: 5级 | AN35: 238 | AO35: =AN35-AT8 -> 228 | AP35: =AO35*AN8*0.8 -> 34656 | AQ35: =AO35*AO8 -> 12540
A36: 45580 | B36: 1600 | D36: =(SUM(粮草!A36:X36)+AG36*10*IF(AK36="是",$AY$4,$AY$3)) -> 0 | E36: =SUM($B$4:B36)+SUM($C$4:C36)-SUM($D$4:D36) -> 17388 | F36: =SUM(经验!A36:X36) -> 0 | G36: =SUM($F$4:F36)+SUM($H$4:H36) -> 18245 | H36: 100 | I36: 空 | J36: 空 | K36: 空 | L36: 空 | M36: 空 | N36: 空 | O36: 空 | P36: 空 | Q36: 空 | R36: 空 | S36: 空 | T36: 空 | U36: 空 | V36: 空 | W36: 空 | X36: 空 | Y36: 空 | Z36: 空 | AA36: 空 | AB36: 空 | AC36: 空 | AD36: 空 | AE36: 空 | AF36: 空 | AG36: =AH36+AI36+AJ36 -> 0 | AK36: 是 | AM36: 6级 | AN36: 190 | AO36: =AN36-AT9 -> 136 | AP36: =AO36*AN9*0.8 -> 21760 | AQ36: =AO36*AO9 -> 8160
A37: 45581 | B37: 1600 | D37: =(SUM(粮草!A37:X37)+AG37*10*IF(AK37="是",$AY$4,$AY$3)) -> 0 | E37: =SUM($B$4:B37)+SUM($C$4:C37)-SUM($D$4:D37) -> 18988 | F37: =SUM(经验!A37:X37) -> 0 | G37: =SUM($F$4:F37)+SUM($H$4:H37) -> 18445 | H37: 200 | I37: 空 | J37: 空 | K37: 空 | L37: 空 | M37: 空 | N37: 空 | O37: 空 | P37: 空 | Q37: 空 | R37: 空 | S37: 空 | T37: 空 | U37: 空 | V37: 空 | W37: 空 | X37: 空 | Y37: 空 | Z37: 空 | AA37: 空 | AB37: 空 | AC37: 空 | AD37: 空 | AE37: 空 | AF37: 空 | AG37: =AH37+AI37+AJ37 -> 0 | AK37: 是 | AM37: 商人 | AN37: 38 | AO37: =AN37-AT17 -> 13 | AP37: =AO37*AN17*0.8 -> 520 | AQ37: =AO37*AO17 -> 390
A38: 45582 | B38: 1600 | D38: =(SUM(粮草!A38:X38)+AG38*10*IF(AK38="是",$AY$4,$AY$3)) -> 0 | E38: =SUM($B$4:B38)+SUM($C$4:C38)-SUM($D$4:D38) -> 20588 | F38: =SUM(经验!A38:X38) -> 0 | G38: =SUM($F$4:F38)+SUM($H$4:H38) -> 18445 | H38: 0 | I38: 空 | J38: 空 | K38: 空 | L38: 空 | M38: 空 | N38: 空 | O38: 空 | P38: 空 | Q38: 空 | R38: 空 | S38: 空 | T38: 空 | U38: 空 | V38: 空 | W38: 空 | X38: 空 | Y38: 空 | Z38: 空 | AA38: 空 | AB38: 空 | AC38: 空 | AD38: 空 | AE38: 空 | AF38: 空 | AG38: =AH38+AI38+AJ38 -> 0 | AK38: 是 | AM38: 塔2 | AN38: 2 | AO38: =AN38-AT11 -> 1 | AP38: =AO38*AN11*0.8 -> 120 | AQ38: =AO38*AO11 -> 40
A39: 45583 | B39: 1600 | D39: =(SUM(粮草!A39:X39)+AG39*10*IF(AK39="是",$AY$4,$AY$3)) -> 0 | E39: =SUM($B$4:B39)+SUM($C$4:C39)-SUM($D$4:D39) -> 22188 | F39: =SUM(经验!A39:X39) -> 0 | G39: =SUM($F$4:F39)+SUM($H$4:H39) -> 18445 | H39: 0 | I39: 空 | J39: 空 | K39: 空 | L39: 空 | M39: 空 | N39: 空 | O39: 空 | P39: 空 | Q39: 空 | R39: 空 | S39: 空 | T39: 空 | U39: 空 | V39: 空 | W39: 空 | X39: 空 | Y39: 空 | Z39: 空 | AA39: 空 | AB39: 空 | AC39: 空 | AD39: 空 | AE39: 空 | AF39: 空 | AG39: =AH39+AI39+AJ39 -> 0 | AK39: 是 | AM39: 塔3 | AN39: 6 | AO39: =AN39-AT12 -> 2 | AP39: =AO39*AN12*0.8 -> 240 | AQ39: =AO39*AO12 -> 90
A40: 45584 | B40: 1600 | D40: =(SUM(粮草!A40:X40)+AG40*10*IF(AK40="是",$AY$4,$AY$3)) -> 0 | E40: =SUM($B$4:B40)+SUM($C$4:C40)-SUM($D$4:D40) -> 23788 | F40: =SUM(经验!A40:X40) -> 0 | G40: =SUM($F$4:F40)+SUM($H$4:H40) -> 18445 | H40: 0 | I40: 空 | J40: 空 | K40: 空 | L40: 空 | M40: 空 | N40: 空 | O40: 空 | P40: 空 | Q40: 空 | R40: 空 | S40: 空 | T40: 空 | U40: 空 | V40: 空 | W40: 空 | X40: 空 | Y40: 空 | Z40: 空 | AA40: 空 | AB40: 空 | AC40: 空 | AD40: 空 | AE40: 空 | AF40: 空 | AG40: =AH40+AI40+AJ40 -> 0 | AK40: 是 | AM40: 塔4 | AN40: 3 | AO40: =AN40-AT13 -> 2 | AP40: =AO40*AN13*0.8 -> 240 | AQ40: =AO40*AO13 -> 100
...

Sheet 粮草
A2: 队伍一 风 | C2: 步数 | D2: =COUNTIF(A4:H94,"<>空") -> 728 | E2: (不算跳步和传送) | I2: 队伍二 雷 | K2: 步数 | L2: =COUNTIF(I4:P94,"<>空") -> 728 | M2: (不算跳步和传送) | Q2: 队伍三 | S2: 总步数 | T2: =COUNTIF(Q4:X94,"<>空") -> 728 | U2: (不算跳步和传送) | Y2: 粮草调整
A3: 1 | B3: 2 | C3: 3 | D3: 4 | E3: 5 | F3: 6 | G3: 7 | H3: 8 | I3: 1 | J3: 2 | K3: 3 | L3: 4 | M3: 5 | N3: 6 | O3: 7 | P3: 8 | Q3: 1 | R3: 2 | S3: 3 | T3: 4 | U3: 5 | V3: 6 | W3: 7 | X3: 8
A4: =IF(ISNUMBER(SEARCH("营",'17.01'!I4)),(-$Y4+50*IF('17.01'!$AK4="是",'17.01'!$AY$4,'17.01'!$AY$3)),(VLOOKUP('17.01'!I4,'17.01'!$AM$4:$AO$55,2,FALSE))*IF('17.01'!$AK4="是",'17.01'!$AY$4,'17.01'!$AY$3)) -> 150 | B4: =IF(ISNUMBER(SEARCH("营",'17.01'!J4)),(-$Y4+50*IF('17.01'!$AK4="是",'17.01'!$AY$4,'17.01'!$AY$3)),(VLOOKUP('17.01'!J4,'17.01'!$AM$4:$AO$55,2,FALSE))*IF('17.01'!$AK4="是",'17.01'!$AY$4,'17.01'!$AY$3)) -> 150 | C4: =IF(ISNUMBER(SEARCH("营",'17.01'!K4)),(-$Y4+50*IF('17.01'!$AK4="是",'17.01'!$AY$4,'17.01'!$AY$3)),(VLOOKUP('17.01'!K4,'17.01'!$AM$4:$AO$55,2,FALSE))*IF('17.01'!$AK4="是",'17.01'!$AY$4,'17.01'!$AY$3)) -> 150 | D4: =IF(ISNUMBER(SEARCH("营",'17.01'!L4)),(-$Y4+50*IF('17.01'!$AK4="是",'17.01'!$AY$4,'17.01'!$AY$3)),(VLOOKUP('17.01'!L4,'17.01'!$AM$4:$AO$55,2,FALSE))*IF('17.01'!$AK4="是",'17.01'!$AY$4,'17.01'!$AY$3)) -> 0 | E4: =IF(ISNUMBER(SEARCH("营",'17.01'!M4)),(-$Y4+50*IF('17.01'!$AK4="是",'17.01'!$AY$4,'17.01'!$AY$3)),(VLOOKUP('17.01'!M4,'17.01'!$AM$4:$AO$55,2,FALSE))*IF('17.01'!$AK4="是",'17.01'!$AY$4,'17.01'!$AY$3)) -> 0 | F4: =IF(ISNUMBER(SEARCH("营",'17.01'!N4)),(-$Y4+50*IF('17.01'!$AK4="是",'17.01'!$AY$4,'17.01'!$AY$3)),(VLOOKUP('17.01'!N4,'17.01'!$AM$4:$AO$55,2,FALSE))*IF('17.01'!$AK4="是",'17.01'!$AY$4,'17.01'!$AY$3)) -> 0 | G4: =IF(ISNUMBER(SEARCH("营",'17.01'!O4)),(-$Y4+50*IF('17.01'!$AK4="是",'17.01'!$AY$4,'17.01'!$AY$3)),(VLOOKUP('17.01'!O4,'17.01'!$AM$4:$AO$55,2,FALSE))*IF('17.01'!$AK4="是",'17.01'!$AY$4,'17.01'!$AY$3)) -> 0 | H4: =IF(ISNUMBER(SEARCH("营",'17.01'!P4)),(-$Y4+50*IF('17.01'!$AK4="是",'17.01'!$AY$4,'17.01'!$AY$3)),(VLOOKUP('17.01'!P4,'17.01'!$AM$4:$AO$55,2,FALSE))*IF('17.01'!$AK4="是",'17.01'!$AY$4,'17.01'!$AY$3)) -> 0 | ... X4: =IF(ISNUMBER(SEARCH("营",'17.01'!AF4)),(-$Y4+50*IF('17.01'!$AK4="是",'17.01'!$AY$4,'17.01'!$AY$3)),(VLOOKUP('17.01'!AF4,'17.01'!$AM$4:$AO$55,2,FALSE))*IF('17.01'!$AK4="是",'17.01'!$AY$4,'17.01'!$AY$3)) -> 0 | Y4: 300
A5: =IF(ISNUMBER(SEARCH("营",'17.01'!I5)),(-$Y5+50*IF('17.01'!$AK5="是",'17.01'!$AY$4,'17.01'!$AY$3)),(VLOOKUP('17.01'!I5,'17.01'!$AM$4:$AO$55,2,FALSE))*IF('17.01'!$AK5="是",'17.01'!$AY$4,'17.01'!$AY$3)) -> 0 | B5: =IF(ISNUMBER(SEARCH("营",'17.01'!J5)),(-$Y5+50*IF('17.01'!$AK5="是",'17.01'!$AY$4,'17.01'!$AY$3)),(VLOOKUP('17.01'!J5,'17.01'!$AM$4:$AO$55,2,FALSE))*IF('17.01'!$AK5="是",'17.01'!$AY$4,'17.01'!$AY$3)) -> 0 | C5: =IF(ISNUMBER(SEARCH("营",'17.01'!K5)),(-$Y5+50*IF('17.01'!$AK5="是",'17.01'!$AY$4,'17.01'!$AY$3)),(VLOOKUP('17.01'!K5,'17.01'!$AM$4:$AO$55,2,FALSE))*IF('17.01'!$AK5="是",'17.01'!$AY$4,'17.01'!$AY$3)) -> 0 | D5: =IF(ISNUMBER(SEARCH("营",'17.01'!L5)),(-$Y5+50*IF('17.01'!$AK5="是",'17.01'!$AY$4,'17.01'!$AY$3)),(VLOOKUP('17.01'!L5,'17.01'!$AM$4:$AO$55,2,FALSE))*IF('17.01'!$AK5="是",'17.01'!$AY$4,'17.01'!$AY$3)) -> 0 | E5: =IF(ISNUMBER(SEARCH("营",'17.01'!M5)),(-$Y5+50*IF('17.01'!$AK5="是",'17.01'!$AY$4,'17.01'!$AY$3)),(VLOOKUP('17.01'!M5,'17.01'!$AM$4:$AO$55,2,FALSE))*IF('17.01'!$AK5="是",'17.01'!$AY$4,'17.01'!$AY$3)) -> 0 | F5: =IF(ISNUMBER(SEARCH("营",'17.01'!N5)),(-$Y5+50*IF('17.01'!$AK5="是",'17.01'!$AY$4,'17.01'!$AY$3)),(VLOOKUP('17.01'!N5,'17.01'!$AM$4:$AO$55,2,FALSE))*IF('17.01'!$AK5="是",'17.01'!$AY$4,'17.01'!$AY$3)) -> 0 | G5: =IF(ISNUMBER(SEARCH("营",'17.01'!O5)),(-$Y5+50*IF('17.01'!$AK5="是",'17.01'!$AY$4,'17.01'!$AY$3)),(VLOOKUP('17.01'!O5,'17.01'!$AM$4:$AO$55,2,FALSE))*IF('17.01'!$AK5="是",'17.01'!$AY$4,'17.01'!$AY$3)) -> 0 | H5: =IF(ISNUMBER(SEARCH("营",'17.01'!P5)),(-$Y5+50*IF('17.01'!$AK5="是",'17.01'!$AY$4,'17.01'!$AY$3)),(VLOOKUP('17.01'!P5,'17.01'!$AM$4:$AO$55,2,FALSE))*IF('17.01'!$AK5="是",'17.01'!$AY$4,'17.01'!$AY$3)) -> 0 | ... X5: =IF(ISNUMBER(SEARCH("营",'17.01'!AF5)),(-$Y5+50*IF('17.01'!$AK5="是",'17.01'!$AY$4,'17.01'!$AY$3)),(VLOOKUP('17.01'!AF5,'17.01'!$AM$4:$AO$55,2,FALSE))*IF('17.01'!$AK5="是",'17.01'!$AY$4,'17.01'!$AY$3)) -> 0 | Y5: 300
A6: =IF(ISNUMBER(SEARCH("营",'17.01'!I6)),(-$Y6+50*IF('17.01'!$AK6="是",'17.01'!$AY$4,'17.01'!$AY$3)),(VLOOKUP('17.01'!I6,'17.01'!$AM$4:$AO$55,2,FALSE))*IF('17.01'!$AK6="是",'17.01'!$AY$4,'17.01'!$AY$3)) -> 0 | B6: =IF(ISNUMBER(SEARCH("营",'17.01'!J6)),(-$Y6+50*IF('17.01'!$AK6="是",'17.01'!$AY$4,'17.01'!$AY$3)),(VLOOKUP('17.01'!J6,'17.01'!$AM$4:$AO$55,2,FALSE))*IF('17.01'!$AK6="是",'17.01'!$AY$4,'17.01'!$AY$3)) -> 0 | C6: =IF(ISNUMBER(SEARCH("营",'17.01'!K6)),(-$Y6+50*IF('17.01'!$AK6="是",'17.01'!$AY$4,'17.01'!$AY$3)),(VLOOKUP('17.01'!K6,'17.01'!$AM$4:$AO$55,2,FALSE))*IF('17.01'!$AK6="是",'17.01'!$AY$4,'17.01'!$AY$3)) -> 0 | D6: =IF(ISNUMBER(SEARCH("营",'17.01'!L6)),(-$Y6+50*IF('17.01'!$AK6="是",'17.01'!$AY$4,'17.01'!$AY$3)),(VLOOKUP('17.01'!L6,'17.01'!$AM$4:$AO$55,2,FALSE))*IF('17.01'!$AK6="是",'17.01'!$AY$4,'17.01'!$AY$3)) -> 0 | E6: =IF(ISNUMBER(SEARCH("营",'17.01'!M6)),(-$Y6+50*IF('17.01'!$AK6="是",'17.01'!$AY$4,'17.01'!$AY$3)),(VLOOKUP('17.01'!M6,'17.01'!$AM$4:$AO$55,2,FALSE))*IF('17.01'!$AK6="是",'17.01'!$AY$4,'17.01'!$AY$3)) -> 0 | F6: =IF(ISNUMBER(SEARCH("营",'17.01'!N6)),(-$Y6+50*IF('17.01'!$AK6="是",'17.01'!$AY$4,'17.01'!$AY$3)),(VLOOKUP('17.01'!N6,'17.01'!$AM$4:$AO$55,2,FALSE))*IF('17.01'!$AK6="是",'17.01'!$AY$4,'17.01'!$AY$3)) -> 0 | G6: =IF(ISNUMBER(SEARCH("营",'17.01'!O6)),(-$Y6+50*IF('17.01'!$AK6="是",'17.01'!$AY$4,'17.01'!$AY$3)),(VLOOKUP('17.01'!O6,'17.01'!$AM$4:$AO$55,2,FALSE))*IF('17.01'!$AK6="是",'17.01'!$AY$4,'17.01'!$AY$3)) -> 0 | H6: =IF(ISNUMBER(SEARCH("营",'17.01'!P6)),(-$Y6+50*IF('17.01'!$AK6="是",'17.01'!$AY$4,'17.01'!$AY$3)),(VLOOKUP('17.01'!P6,'17.01'!$AM$4:$AO$55,2,FALSE))*IF('17.01'!$AK6="是",'17.01'!$AY$4,'17.01'!$AY$3)) -> 0 | ... X6: =IF(ISNUMBER(SEARCH("营",'17.01'!AF6)),(-$Y6+50*IF('17.01'!$AK6="是",'17.01'!$AY$4,'17.01'!$AY$3)),(VLOOKUP('17.01'!AF6,'17.01'!$AM$4:$AO$55,2,FALSE))*IF('17.01'!$AK6="是",'17.01'!$AY$4,'17.01'!$AY$3)) -> 0 | Y6: 300
A7: =IF(ISNUMBER(SEARCH("营",'17.01'!I7)),(-$Y7+50*IF('17.01'!$AK7="是",'17.01'!$AY$4,'17.01'!$AY$3)),(VLOOKUP('17.01'!I7,'17.01'!$AM$4:$AO$55,2,FALSE))*IF('17.01'!$AK7="是",'17.01'!$AY$4,'17.01'!$AY$3)) -> 0 | B7: =IF(ISNUMBER(SEARCH("营",'17.01'!J7)),(-$Y7+50*IF('17.01'!$AK7="是",'17.01'!$AY$4,'17.01'!$AY$3)),(VLOOKUP('17.01'!J7,'17.01'!$AM$4:$AO$55,2,FALSE))*IF('17.01'!$AK7="是",'17.01'!$AY$4,'17.01'!$AY$3)) -> 0 | C7: =IF(ISNUMBER(SEARCH("营",'17.01'!K7)),(-$Y7+50*IF('17.01'!$AK7="是",'17.01'!$AY$4,'17.01'!$AY$3)),(VLOOKUP('17.01'!K7,'17.01'!$AM$4:$AO$55,2,FALSE))*IF('17.01'!$AK7="是",'17.01'!$AY$4,'17.01'!$AY$3)) -> 0 | D7: =IF(ISNUMBER(SEARCH("营",'17.01'!L7)),(-$Y7+50*IF('17.01'!$AK7="是",'17.01'!$AY$4,'17.01'!$AY$3)),(VLOOKUP('17.01'!L7,'17.01'!$AM$4:$AO$55,2,FALSE))*IF('17.01'!$AK7="是",'17.01'!$AY$4,'17.01'!$AY$3)) -> 0 | E7: =IF(ISNUMBER(SEARCH("营",'17.01'!M7)),(-$Y7+50*IF('17.01'!$AK7="是",'17.01'!$AY$4,'17.01'!$AY$3)),(VLOOKUP('17.01'!M7,'17.01'!$AM$4:$AO$55,2,FALSE))*IF('17.01'!$AK7="是",'17.01'!$AY$4,'17.01'!$AY$3)) -> 0 | F7: =IF(ISNUMBER(SEARCH("营",'17.01'!N7)),(-$Y7+50*IF('17.01'!$AK7="是",'17.01'!$AY$4,'17.01'!$AY$3)),(VLOOKUP('17.01'!N7,'17.01'!$AM$4:$AO$55,2,FALSE))*IF('17.01'!$AK7="是",'17.01'!$AY$4,'17.01'!$AY$3)) -> 0 | G7: =IF(ISNUMBER(SEARCH("营",'17.01'!O7)),(-$Y7+50*IF('17.01'!$AK7="是",'17.01'!$AY$4,'17.01'!$AY$3)),(VLOOKUP('17.01'!O7,'17.01'!$AM$4:$AO$55,2,FALSE))*IF('17.01'!$AK7="是",'17.01'!$AY$4,'17.01'!$AY$3)) -> 0 | H7: =IF(ISNUMBER(SEARCH("营",'17.01'!P7)),(-$Y7+50*IF('17.01'!$AK7="是",'17.01'!$AY$4,'17.01'!$AY$3)),(VLOOKUP('17.01'!P7,'17.01'!$AM$4:$AO$55,2,FALSE))*IF('17.01'!$AK7="是",'17.01'!$AY$4,'17.01'!$AY$3)) -> 0 | ... X7: =IF(ISNUMBER(SEARCH("营",'17.01'!AF7)),(-$Y7+50*IF('17.01'!$AK7="是",'17.01'!$AY$4,'17.01'!$AY$3)),(VLOOKUP('17.01'!AF7,'17.01'!$AM$4:$AO$55,2,FALSE))*IF('17.01'!$AK7="是",'17.01'!$AY$4,'17.01'!$AY$3)) -> 0 | Y7: 300
A8: =IF(ISNUMBER(SEARCH("营",'17.01'!I8)),(-$Y8+50*IF('17.01'!$AK8="是",'17.01'!$AY$4,'17.01'!$AY$3)),(VLOOKUP('17.01'!I8,'17.01'!$AM$4:$AO$55,2,FALSE))*IF('17.01'!$AK8="是",'17.01'!$AY$4,'17.01'!$AY$3)) -> 0 | B8: =IF(ISNUMBER(SEARCH("营",'17.01'!J8)),(-$Y8+50*IF('17.01'!$AK8="是",'17.01'!$AY$4,'17.01'!$AY$3)),(VLOOKUP('17.01'!J8,'17.01'!$AM$4:$AO$55,2,FALSE))*IF('17.01'!$AK8="是",'17.01'!$AY$4,'17.01'!$AY$3)) -> 0 | C8: =IF(ISNUMBER(SEARCH("营",'17.01'!K8)),(-$Y8+50*IF('17.01'!$AK8="是",'17.01'!$AY$4,'17.01'!$AY$3)),(VLOOKUP('17.01'!K8,'17.01'!$AM$4:$AO$55,2,FALSE))*IF('17.01'!$AK8="是",'17.01'!$AY$4,'17.01'!$AY$3)) -> 0 | D8: =IF(ISNUMBER(SEARCH("营",'17.01'!L8)),(-$Y8+50*IF('17.01'!$AK8="是",'17.01'!$AY$4,'17.01'!$AY$3)),(VLOOKUP('17.01'!L8,'17.01'!$AM$4:$AO$55,2,FALSE))*IF('17.01'!$AK8="是",'17.01'!$AY$4,'17.01'!$AY$3)) -> 0 | E8: =IF(ISNUMBER(SEARCH("营",'17.01'!M8)),(-$Y8+50*IF('17.01'!$AK8="是",'17.01'!$AY$4,'17.01'!$AY$3)),(VLOOKUP('17.01'!M8,'17.01'!$AM$4:$AO$55,2,FALSE))*IF('17.01'!$AK8="是",'17.01'!$AY$4,'17.01'!$AY$3)) -> 0 | F8: =IF(ISNUMBER(SEARCH("营",'17.01'!N8)),(-$Y8+50*IF('17.01'!$AK8="是",'17.01'!$AY$4,'17.01'!$AY$3)),(VLOOKUP('17.01'!N8,'17.01'!$AM$4:$AO$55,2,FALSE))*IF('17.01'!$AK8="是",'17.01'!$AY$4,'17.01'!$AY$3)) -> 0 | G8: =IF(ISNUMBER(SEARCH("营",'17.01'!O8)),(-$Y8+50*IF('17.01'!$AK8="是",'17.01'!$AY$4,'17.01'!$AY$3)),(VLOOKUP('17.01'!O8,'17.01'!$AM$4:$AO$55,2,FALSE))*IF('17.01'!$AK8="是",'17.01'!$AY$4,'17.01'!$AY$3)) -> 0 | H8: =IF(ISNUMBER(SEARCH("营",'17.01'!P8)),(-$Y8+50*IF('17.01'!$AK8="是",'17.01'!$AY$4,'17.01'!$AY$3)),(VLOOKUP('17.01'!P8,'17.01'!$AM$4:$AO$55,2,FALSE))*IF('17.01'!$AK8="是",'17.01'!$AY$4,'17.01'!$AY$3)) -> 0 | ... X8: =IF(ISNUMBER(SEARCH("营",'17.01'!AF8)),(-$Y8+50*IF('17.01'!$AK8="是",'17.01'!$AY$4,'17.01'!$AY$3)),(VLOOKUP('17.01'!AF8,'17.01'!$AM$4:$AO$55,2,FALSE))*IF('17.01'!$AK8="是",'17.01'!$AY$4,'17.01'!$AY$3)) -> 0 | Y8: 300
A9: =IF(ISNUMBER(SEARCH("营",'17.01'!I9)),(-$Y9+50*IF('17.01'!$AK9="是",'17.01'!$AY$4,'17.01'!$AY$3)),(VLOOKUP('17.01'!I9,'17.01'!$AM$4:$AO$55,2,FALSE))*IF('17.01'!$AK9="是",'17.01'!$AY$4,'17.01'!$AY$3)) -> 0 | B9: =IF(ISNUMBER(SEARCH("营",'17.01'!J9)),(-$Y9+50*IF('17.01'!$AK9="是",'17.01'!$AY$4,'17.01'!$AY$3)),(VLOOKUP('17.01'!J9,'17.01'!$AM$4:$AO$55,2,FALSE))*IF('17.01'!$AK9="是",'17.01'!$AY$4,'17.01'!$AY$3)) -> 0 | C9: =IF(ISNUMBER(SEARCH("营",'17.01'!K9)),(-$Y9+50*IF('17.01'!$AK9="是",'17.01'!$AY$4,'17.01'!$AY$3)),(VLOOKUP('17.01'!K9,'17.01'!$AM$4:$AO$55,2,FALSE))*IF('17.01'!$AK9="是",'17.01'!$AY$4,'17.01'!$AY$3)) -> 0 | D9: =IF(ISNUMBER(SEARCH("营",'17.01'!L9)),(-$Y9+50*IF('17.01'!$AK9="是",'17.01'!$AY$4,'17.01'!$AY$3)),(VLOOKUP('17.01'!L9,'17.01'!$AM$4:$AO$55,2,FALSE))*IF('17.01'!$AK9="是",'17.01'!$AY$4,'17.01'!$AY$3)) -> 0 | E9: =IF(ISNUMBER(SEARCH("营",'17.01'!M9)),(-$Y9+50*IF('17.01'!$AK9="是",'17.01'!$AY$4,'17.01'!$AY$3)),(VLOOKUP('17.01'!M9,'17.01'!$AM$4:$AO$55,2,FALSE))*IF('17.01'!$AK9="是",'17.01'!$AY$4,'17.01'!$AY$3)) -> 0 | F9: =IF(ISNUMBER(SEARCH("营",'17.01'!N9)),(-$Y9+50*IF('17.01'!$AK9="是",'17.01'!$AY$4,'17.01'!$AY$3)),(VLOOKUP('17.01'!N9,'17.01'!$AM$4:$AO$55,2,FALSE))*IF('17.01'!$AK9="是",'17.01'!$AY$4,'17.01'!$AY$3)) -> 0 | G9: =IF(ISNUMBER(SEARCH("营",'17.01'!O9)),(-$Y9+50*IF('17.01'!$AK9="是",'17.01'!$AY$4,'17.01'!$AY$3)),(VLOOKUP('17.01'!O9,'17.01'!$AM$4:$AO$55,2,FALSE))*IF('17.01'!$AK9="是",'17.01'!$AY$4,'17.01'!$AY$3)) -> 0 | H9: =IF(ISNUMBER(SEARCH("营",'17.01'!P9)),(-$Y9+50*IF('17.01'!$AK9="是",'17.01'!$AY$4,'17.01'!$AY$3)),(VLOOKUP('17.01'!P9,'17.01'!$AM$4:$AO$55,2,FALSE))*IF('17.01'!$AK9="是",'17.01'!$AY$4,'17.01'!$AY$3)) -> 0 | ... X9: =IF(ISNUMBER(SEARCH("营",'17.01'!AF9)),(-$Y9+50*IF('17.01'!$AK9="是",'17.01'!$AY$4,'17.01'!$AY$3)),(VLOOKUP('17.01'!AF9,'17.01'!$AM$4:$AO$55,2,FALSE))*IF('17.01'!$AK9="是",'17.01'!$AY$4,'17.01'!$AY$3)) -> 0 | Y9: 300
A10: =IF(ISNUMBER(SEARCH("营",'17.01'!I10)),(-$Y10+50*IF('17.01'!$AK10="是",'17.01'!$AY$4,'17.01'!$AY$3)),(VLOOKUP('17.01'!I10,'17.01'!$AM$4:$AO$55,2,FALSE))*IF('17.01'!$AK10="是",'17.01'!$AY$4,'17.01'!$AY$3)) -> 0 | B10: =IF(ISNUMBER(SEARCH("营",'17.01'!J10)),(-$Y10+50*IF('17.01'!$AK10="是",'17.01'!$AY$4,'17.01'!$AY$3)),(VLOOKUP('17.01'!J10,'17.01'!$AM$4:$AO$55,2,FALSE))*IF('17.01'!$AK10="是",'17.01'!$AY$4,'17.01'!$AY$3)) -> 0 | C10: =IF(ISNUMBER(SEARCH("营",'17.01'!K10)),(-$Y10+50*IF('17.01'!$AK10="是",'17.01'!$AY$4,'17.01'!$AY$3)),(VLOOKUP('17.01'!K10,'17.01'!$AM$4:$AO$55,2,FALSE))*IF('17.01'!$AK10="是",'17.01'!$AY$4,'17.01'!$AY$3)) -> 0 | D10: =IF(ISNUMBER(SEARCH("营",'17.01'!L10)),(-$Y10+50*IF('17.01'!$AK10="是",'17.01'!$AY$4,'17.01'!$AY$3)),(VLOOKUP('17.01'!L10,'17.01'!$AM$4:$AO$55,2,FALSE))*IF('17.01'!$AK10="是",'17.01'!$AY$4,'17.01'!$AY$3)) -> 0 | E10: =IF(ISNUMBER(SEARCH("营",'17.01'!M10)),(-$Y10+50*IF('17.01'!$AK10="是",'17.01'!$AY$4,'17.01'!$AY$3)),(VLOOKUP('17.01'!M10,'17.01'!$AM$4:$AO$55,2,FALSE))*IF('17.01'!$AK10="是",'17.01'!$AY$4,'17.01'!$AY$3)) -> 0 | F10: =IF(ISNUMBER(SEARCH("营",'17.01'!N10)),(-$Y10+50*IF('17.01'!$AK10="是",'17.01'!$AY$4,'17.01'!$AY$3)),(VLOOKUP('17.01'!N10,'17.01'!$AM$4:$AO$55,2,FALSE))*IF('17.01'!$AK10="是",'17.01'!$AY$4,'17.01'!$AY$3)) -> 0 | G10: =IF(ISNUMBER(SEARCH("营",'17.01'!O10)),(-$Y10+50*IF('17.01'!$AK10="是",'17.01'!$AY$4,'17.01'!$AY$3)),(VLOOKUP('17.01'!O10,'17.01'!$AM$4:$AO$55,2,FALSE))*IF('17.01'!$AK10="是",'17.01'!$AY$4,'17.01'!$AY$3)) -> 0 | H10: =IF(ISNUMBER(SEARCH("营",'17.01'!P10)),(-$Y10+50*IF('17.01'!$AK10="是",'17.01'!$AY$4,'17.01'!$AY$3)),(VLOOKUP('17.01'!P10,'17.01'!$AM$4:$AO$55,2,FALSE))*IF('17.01'!$AK10="是",'17.01'!$AY$4,'17.01'!$AY$3)) -> 0 | ... X10: =IF(ISNUMBER(SEARCH("营",'17.01'!AF10)),(-$Y10+50*IF('17.01'!$AK10="是",'17.01'!$AY$4,'17.01'!$AY$3)),(VLOOKUP('17.01'!AF10,'17.01'!$AM$4:$AO$55,2,FALSE))*IF('17.01'!$AK10="是",'17.01'!$AY$4,'17.01'!$AY$3)) -> 0 | Y10: 300
A11: =IF(ISNUMBER(SEARCH("营",'17.01'!I11)),(-$Y11+50*IF('17.01'!$AK11="是",'17.01'!$AY$4,'17.01'!$AY$3)),(VLOOKUP('17.01'!I11,'17.01'!$AM$4:$AO$55,2,FALSE))*IF('17.01'!$AK11="是",'17.01'!$AY$4,'17.01'!$AY$3)) -> 0 | B11: =IF(ISNUMBER(SEARCH("营",'17.01'!J11)),(-$Y11+50*IF('17.01'!$AK11="是",'17.01'!$AY$4,'17.01'!$AY$3)),(VLOOKUP('17.01'!J11,'17.01'!$AM$4:$AO$55,2,FALSE))*IF('17.01'!$AK11="是",'17.01'!$AY$4,'17.01'!$AY$3)) -> 0 | C11: =IF(ISNUMBER(SEARCH("营",'17.01'!K11)),(-$Y11+50*IF('17.01'!$AK11="是",'17.01'!$AY$4,'17.01'!$AY$3)),(VLOOKUP('17.01'!K11,'17.01'!$AM$4:$AO$55,2,FALSE))*IF('17.01'!$AK11="是",'17.01'!$AY$4,'17.01'!$AY$3)) -> 0 | D11: =IF(ISNUMBER(SEARCH("营",'17.01'!L11)),(-$Y11+50*IF('17.01'!$AK11="是",'17.01'!$AY$4,'17.01'!$AY$3)),(VLOOKUP('17.01'!L11,'17.01'!$AM$4:$AO$55,2,FALSE))*IF('17.01'!$AK11="是",'17.01'!$AY$4,'17.01'!$AY$3)) -> 0 | E11: =IF(ISNUMBER(SEARCH("营",'17.01'!M11)),(-$Y11+50*IF('17.01'!$AK11="是",'17.01'!$AY$4,'17.01'!$AY$3)),(VLOOKUP('17.01'!M11,'17.01'!$AM$4:$AO$55,2,FALSE))*IF('17.01'!$AK11="是",'17.01'!$AY$4,'17.01'!$AY$3)) -> 0 | F11: =IF(ISNUMBER(SEARCH("营",'17.01'!N11)),(-$Y11+50*IF('17.01'!$AK11="是",'17.01'!$AY$4,'17.01'!$AY$3)),(VLOOKUP('17.01'!N11,'17.01'!$AM$4:$AO$55,2,FALSE))*IF('17.01'!$AK11="是",'17.01'!$AY$4,'17.01'!$AY$3)) -> 0 | G11: =IF(ISNUMBER(SEARCH("营",'17.01'!O11)),(-$Y11+50*IF('17.01'!$AK11="是",'17.01'!$AY$4,'17.01'!$AY$3)),(VLOOKUP('17.01'!O11,'17.01'!$AM$4:$AO$55,2,FALSE))*IF('17.01'!$AK11="是",'17.01'!$AY$4,'17.01'!$AY$3)) -> 0 | H11: =IF(ISNUMBER(SEARCH("营",'17.01'!P11)),(-$Y11+50*IF('17.01'!$AK11="是",'17.01'!$AY$4,'17.01'!$AY$3)),(VLOOKUP('17.01'!P11,'17.01'!$AM$4:$AO$55,2,FALSE))*IF('17.01'!$AK11="是",'17.01'!$AY$4,'17.01'!$AY$3)) -> 0 | ... X11: =IF(ISNUMBER(SEARCH("营",'17.01'!AF11)),(-$Y11+50*IF('17.01'!$AK11="是",'17.01'!$AY$4,'17.01'!$AY$3)),(VLOOKUP('17.01'!AF11,'17.01'!$AM$4:$AO$55,2,FALSE))*IF('17.01'!$AK11="是",'17.01'!$AY$4,'17.01'!$AY$3)) -> 0 | Y11: 300
A12: =IF(ISNUMBER(SEARCH("营",'17.01'!I12)),(-$Y12+50*IF('17.01'!$AK12="是",'17.01'!$AY$4,'17.01'!$AY$3)),(VLOOKUP('17.01'!I12,'17.01'!$AM$4:$AO$55,2,FALSE))*IF('17.01'!$AK12="是",'17.01'!$AY$4,'17.01'!$AY$3)) -> 0 | B12: =IF(ISNUMBER(SEARCH("营",'17.01'!J12)),(-$Y12+50*IF('17.01'!$AK12="是",'17.01'!$AY$4,'17.01'!$AY$3)),(VLOOKUP('17.01'!J12,'17.01'!$AM$4:$AO$55,2,FALSE))*IF('17.01'!$AK12="是",'17.01'!$AY$4,'17.01'!$AY$3)) -> 0 | C12: =IF(ISNUMBER(SEARCH("营",'17.01'!K12)),(-$Y12+50*IF('17.01'!$AK12="是",'17.01'!$AY$4,'17.01'!$AY$3)),(VLOOKUP('17.01'!K12,'17.01'!$AM$4:$AO$55,2,FALSE))*IF('17.01'!$AK12="是",'17.01'!$AY$4,'17.01'!$AY$3)) -> 0 | D12: =IF(ISNUMBER(SEARCH("营",'17.01'!L12)),(-$Y12+50*IF('17.01'!$AK12="是",'17.01'!$AY$4,'17.01'!$AY$3)),(VLOOKUP('17.01'!L12,'17.01'!$AM$4:$AO$55,2,FALSE))*IF('17.01'!$AK12="是",'17.01'!$AY$4,'17.01'!$AY$3)) -> 0 | E12: =IF(ISNUMBER(SEARCH("营",'17.01'!M12)),(-$Y12+50*IF('17.01'!$AK12="是",'17.01'!$AY$4,'17.01'!$AY$3)),(VLOOKUP('17.01'!M12,'17.01'!$AM$4:$AO$55,2,FALSE))*IF('17.01'!$AK12="是",'17.01'!$AY$4,'17.01'!$AY$3)) -> 0 | F12: =IF(ISNUMBER(SEARCH("营",'17.01'!N12)),(-$Y12+50*IF('17.01'!$AK12="是",'17.01'!$AY$4,'17.01'!$AY$3)),(VLOOKUP('17.01'!N12,'17.01'!$AM$4:$AO$55,2,FALSE))*IF('17.01'!$AK12="是",'17.01'!$AY$4,'17.01'!$AY$3)) -> 0 | G12: =IF(ISNUMBER(SEARCH("营",'17.01'!O12)),(-$Y12+50*IF('17.01'!$AK12="是",'17.01'!$AY$4,'17.01'!$AY$3)),(VLOOKUP('17.01'!O12,'17.01'!$AM$4:$AO$55,2,FALSE))*IF('17.01'!$AK12="是",'17.01'!$AY$4,'17.01'!$AY$3)) -> 0 | H12: =IF(ISNUMBER(SEARCH("营",'17.01'!P12)),(-$Y12+50*IF('17.01'!$AK12="是",'17.01'!$AY$4,'17.01'!$AY$3)),(VLOOKUP('17.01'!P12,'17.01'!$AM$4:$AO$55,2,FALSE))*IF('17.01'!$AK12="是",'17.01'!$AY$4,'17.01'!$AY$3)) -> 0 | ... X12: =IF(ISNUMBER(SEARCH("营",'17.01'!AF12)),(-$Y12+50*IF('17.01'!$AK12="是",'17.01'!$AY$4,'17.01'!$AY$3)),(VLOOKUP('17.01'!AF12,'17.01'!$AM$4:$AO$55,2,FALSE))*IF('17.01'!$AK12="是",'17.01'!$AY$4,'17.01'!$AY$3)) -> 0 | Y12: 300
A13: =IF(ISNUMBER(SEARCH("营",'17.01'!I13)),(-$Y13+50*IF('17.01'!$AK13="是",'17.01'!$AY$4,'17.01'!$AY$3)),(VLOOKUP('17.01'!I13,'17.01'!$AM$4:$AO$55,2,FALSE))*IF('17.01'!$AK13="是",'17.01'!$AY$4,'17.01'!$AY$3)) -> 0 | B13: =IF(ISNUMBER(SEARCH("营",'17.01'!J13)),(-$Y13+50*IF('17.01'!$AK13="是",'17.01'!$AY$4,'17.01'!$AY$3)),(VLOOKUP('17.01'!J13,'17.01'!$AM$4:$AO$55,2,FALSE))*IF('17.01'!$AK13="是",'17.01'!$AY$4,'17.01'!$AY$3)) -> 0 | C13: =IF(ISNUMBER(SEARCH("营",'17.01'!K13)),(-$Y13+50*IF('17.01'!$AK13="是",'17.01'!$AY$4,'17.01'!$AY$3)),(VLOOKUP('17.01'!K13,'17.01'!$AM$4:$AO$55,2,FALSE))*IF('17.01'!$AK13="是",'17.01'!$AY$4,'17.01'!$AY$3)) -> 0 | D13: =IF(ISNUMBER(SEARCH("营",'17.01'!L13)),(-$Y13+50*IF('17.01'!$AK13="是",'17.01'!$AY$4,'17.01'!$AY$3)),(VLOOKUP('17.01'!L13,'17.01'!$AM$4:$AO$55,2,FALSE))*IF('17.01'!$AK13="是",'17.01'!$AY$4,'17.01'!$AY$3)) -> 0 | E13: =IF(ISNUMBER(SEARCH("营",'17.01'!M13)),(-$Y13+50*IF('17.01'!$AK13="是",'17.01'!$AY$4,'17.01'!$AY$3)),(VLOOKUP('17.01'!M13,'17.01'!$AM$4:$AO$55,2,FALSE))*IF('17.01'!$AK13="是",'17.01'!$AY$4,'17.01'!$AY$3)) -> 0 | F13: =IF(ISNUMBER(SEARCH("营",'17.01'!N13)),(-$Y13+50*IF('17.01'!$AK13="是",'17.01'!$AY$4,'17.01'!$AY$3)),(VLOOKUP('17.01'!N13,'17.01'!$AM$4:$AO$55,2,FALSE))*IF('17.01'!$AK13="是",'17.01'!$AY$4,'17.01'!$AY$3)) -> 0 | G13: =IF(ISNUMBER(SEARCH("营",'17.01'!O13)),(-$Y13+50*IF('17.01'!$AK13="是",'17.01'!$AY$4,'17.01'!$AY$3)),(VLOOKUP('17.01'!O13,'17.01'!$AM$4:$AO$55,2,FALSE))*IF('17.01'!$AK13="是",'17.01'!$AY$4,'17.01'!$AY$3)) -> 0 | H13: =IF(ISNUMBER(SEARCH("营",'17.01'!P13)),(-$Y13+50*IF('17.01'!$AK13="是",'17.01'!$AY$4,'17.01'!$AY$3)),(VLOOKUP('17.01'!P13,'17.01'!$AM$4:$AO$55,2,FALSE))*IF('17.01'!$AK13="是",'17.01'!$AY$4,'17.01'!$AY$3)) -> 0 | ... X13: =IF(ISNUMBER(SEARCH("营",'17.01'!AF13)),(-$Y13+50*IF('17.01'!$AK13="是",'17.01'!$AY$4,'17.01'!$AY$3)),(VLOOKUP('17.01'!AF13,'17.01'!$AM$4:$AO$55,2,FALSE))*IF('17.01'!$AK13="是",'17.01'!$AY$4,'17.01'!$AY$3)) -> 0 | Y13: 300
A14: =IF(ISNUMBER(SEARCH("营",'17.01'!I14)),(-$Y14+50*IF('17.01'!$AK14="是",'17.01'!$AY$4,'17.01'!$AY$3)),(VLOOKUP('17.01'!I14,'17.01'!$AM$4:$AO$55,2,FALSE))*IF('17.01'!$AK14="是",'17.01'!$AY$4,'17.01'!$AY$3)) -> 0 | B14: =IF(ISNUMBER(SEARCH("营",'17.01'!J14)),(-$Y14+50*IF('17.01'!$AK14="是",'17.01'!$AY$4,'17.01'!$AY$3)),(VLOOKUP('17.01'!J14,'17.01'!$AM$4:$AO$55,2,FALSE))*IF('17.01'!$AK14="是",'17.01'!$AY$4,'17.01'!$AY$3)) -> 0 | C14: =IF(ISNUMBER(SEARCH("营",'17.01'!K14)),(-$Y14+50*IF('17.01'!$AK14="是",'17.01'!$AY$4,'17.01'!$AY$3)),(VLOOKUP('17.01'!K14,'17.01'!$AM$4:$AO$55,2,FALSE))*IF('17.01'!$AK14="是",'17.01'!$AY$4,'17.01'!$AY$3)) -> 0 | D14: =IF(ISNUMBER(SEARCH("营",'17.01'!L14)),(-$Y14+50*IF('17.01'!$AK14="是",'17.01'!$AY$4,'17.01'!$AY$3)),(VLOOKUP('17.01'!L14,'17.01'!$AM$4:$AO$55,2,FALSE))*IF('17.01'!$AK14="是",'17.01'!$AY$4,'17.01'!$AY$3)) -> 0 | E14: =IF(ISNUMBER(SEARCH("营",'17.01'!M14)),(-$Y14+50*IF('17.01'!$AK14="是",'17.01'!$AY$4,'17.01'!$AY$3)),(VLOOKUP('17.01'!M14,'17.01'!$AM$4:$AO$55,2,FALSE))*IF('17.01'!$AK14="是",'17.01'!$AY$4,'17.01'!$AY$3)) -> 0 | F14: =IF(ISNUMBER(SEARCH("营",'17.01'!N14)),(-$Y14+50*IF('17.01'!$AK14="是",'17.01'!$AY$4,'17.01'!$AY$3)),(VLOOKUP('17.01'!N14,'17.01'!$AM$4:$AO$55,2,FALSE))*IF('17.01'!$AK14="是",'17.01'!$AY$4,'17.01'!$AY$3)) -> 0 | G14: =IF(ISNUMBER(SEARCH("营",'17.01'!O14)),(-$Y14+50*IF('17.01'!$AK14="是",'17.01'!$AY$4,'17.01'!$AY$3)),(VLOOKUP('17.01'!O14,'17.01'!$AM$4:$AO$55,2,FALSE))*IF('17.01'!$AK14="是",'17.01'!$AY$4,'17.01'!$AY$3)) -> 0 | H14: =IF(ISNUMBER(SEARCH("营",'17.01'!P14)),(-$Y14+50*IF('17.01'!$AK14="是",'17.01'!$AY$4,'17.01'!$AY$3)),(VLOOKUP('17.01'!P14,'17.01'!$AM$4:$AO$55,2,FALSE))*IF('17.01'!$AK14="是",'17.01'!$AY$4,'17.01'!$AY$3)) -> 0 | ... X14: =IF(ISNUMBER(SEARCH("营",'17.01'!AF14)),(-$Y14+50*IF('17.01'!$AK14="是",'17.01'!$AY$4,'17.01'!$AY$3)),(VLOOKUP('17.01'!AF14,'17.01'!$AM$4:$AO$55,2,FALSE))*IF('17.01'!$AK14="是",'17.01'!$AY$4,'17.01'!$AY$3)) -> 0 | Y14: 300
A15: =IF(ISNUMBER(SEARCH("营",'17.01'!I15)),(-$Y15+50*IF('17.01'!$AK15="是",'17.01'!$AY$4,'17.01'!$AY$3)),(VLOOKUP('17.01'!I15,'17.01'!$AM$4:$AO$55,2,FALSE))*IF('17.01'!$AK15="是",'17.01'!$AY$4,'17.01'!$AY$3)) -> 0 | B15: =IF(ISNUMBER(SEARCH("营",'17.01'!J15)),(-$Y15+50*IF('17.01'!$AK15="是",'17.01'!$AY$4,'17.01'!$AY$3)),(VLOOKUP('17.01'!J15,'17.01'!$AM$4:$AO$55,2,FALSE))*IF('17.01'!$AK15="是",'17.01'!$AY$4,'17.01'!$AY$3)) -> 0 | C15: =IF(ISNUMBER(SEARCH("营",'17.01'!K15)),(-$Y15+50*IF('17.01'!$AK15="是",'17.01'!$AY$4,'17.01'!$AY$3)),(VLOOKUP('17.01'!K15,'17.01'!$AM$4:$AO$55,2,FALSE))*IF('17.01'!$AK15="是",'17.01'!$AY$4,'17.01'!$AY$3)) -> 0 | D15: =IF(ISNUMBER(SEARCH("营",'17.01'!L15)),(-$Y15+50*IF('17.01'!$AK15="是",'17.01'!$AY$4,'17.01'!$AY$3)),(VLOOKUP('17.01'!L15,'17.01'!$AM$4:$AO$55,2,FALSE))*IF('17.01'!$AK15="是",'17.01'!$AY$4,'17.01'!$AY$3)) -> 0 | E15: =IF(ISNUMBER(SEARCH("营",'17.01'!M15)),(-$Y15+50*IF('17.01'!$AK15="是",'17.01'!$AY$4,'17.01'!$AY$3)),(VLOOKUP('17.01'!M15,'17.01'!$AM$4:$AO$55,2,FALSE))*IF('17.01'!$AK15="是",'17.01'!$AY$4,'17.01'!$AY$3)) -> 0 | F15: =IF(ISNUMBER(SEARCH("营",'17.01'!N15)),(-$Y15+50*IF('17.01'!$AK15="是",'17.01'!$AY$4,'17.01'!$AY$3)),(VLOOKUP('17.01'!N15,'17.01'!$AM$4:$AO$55,2,FALSE))*IF('17.01'!$AK15="是",'17.01'!$AY$4,'17.01'!$AY$3)) -> 0 | G15: =IF(ISNUMBER(SEARCH("营",'17.01'!O15)),(-$Y15+50*IF('17.01'!$AK15="是",'17.01'!$AY$4,'17.01'!$AY$3)),(VLOOKUP('17.01'!O15,'17.01'!$AM$4:$AO$55,2,FALSE))*IF('17.01'!$AK15="是",'17.01'!$AY$4,'17.01'!$AY$3)) -> 0 | H15: =IF(ISNUMBER(SEARCH("营",'17.01'!P15)),(-$Y15+50*IF('17.01'!$AK15="是",'17.01'!$AY$4,'17.01'!$AY$3)),(VLOOKUP('17.01'!P15,'17.01'!$AM$4:$AO$55,2,FALSE))*IF('17.01'!$AK15="是",'17.01'!$AY$4,'17.01'!$AY$3)) -> 0 | ... X15: =IF(ISNUMBER(SEARCH("营",'17.01'!AF15)),(-$Y15+50*IF('17.01'!$AK15="是",'17.01'!$AY$4,'17.01'!$AY$3)),(VLOOKUP('17.01'!AF15,'17.01'!$AM$4:$AO$55,2,FALSE))*IF('17.01'!$AK15="是",'17.01'!$AY$4,'17.01'!$AY$3)) -> 0 | Y15: 300
... A93: =IF(ISNUMBER(SEARCH("营",'17.01'!I93)),(-$Y93+50*IF('17.01'!$AK93="是",'17.01'!$AY$4,'17.01'!$AY$3)),(VLOOKUP('17.01'!I93,'17.01'!$AM$4:$AO$55,2,FALSE))*IF('17.01'!$AK93="是",'17.01'!$AY$4,'17.01'!$AY$3)) -> 0 | B93: =IF(ISNUMBER(SEARCH("营",'17.01'!J93)),(-$Y93+50*IF('17.01'!$AK93="是",'17.01'!$AY$4,'17.01'!$AY$3)),(VLOOKUP('17.01'!J93,'17.01'!$AM$4:$AO$55,2,FALSE))*IF('17.01'!$AK93="是",'17.01'!$AY$4,'17.01'!$AY$3)) -> 0 | C93: =IF(ISNUMBER(SEARCH("营",'17.01'!K93)),(-$Y93+50*IF('17.01'!$AK93="是",'17.01'!$AY$4,'17.01'!$AY$3)),(VLOOKUP('17.01'!K93,'17.01'!$AM$4:$AO$55,2,FALSE))*IF('17.01'!$AK93="是",'17.01'!$AY$4,'17.01'!$AY$3)) -> 0 | D93: =IF(ISNUMBER(SEARCH("营",'17.01'!L93)),(-$Y93+50*IF('17.01'!$AK93="是",'17.01'!$AY$4,'17.01'!$AY$3)),(VLOOKUP('17.01'!L93,'17.01'!$AM$4:$AO$55,2,FALSE))*IF('17.01'!$AK93="是",'17.01'!$AY$4,'17.01'!$AY$3)) -> 0 | E93: =IF(ISNUMBER(SEARCH("营",'17.01'!M93)),(-$Y93+50*IF('17.01'!$AK93="是",'17.01'!$AY$4,'17.01'!$AY$3)),(VLOOKUP('17.01'!M93,'17.01'!$AM$4:$AO$55,2,FALSE))*IF('17.01'!$AK93="是",'17.01'!$AY$4,'17.01'!$AY$3)) -> 0 | F93: =IF(ISNUMBER(SEARCH("营",'17.01'!N93)),(-$Y93+50*IF('17.01'!$AK93="是",'17.01'!$AY$4,'17.01'!$AY$3)),(VLOOKUP('17.01'!N93,'17.01'!$AM$4:$AO$55,2,FALSE))*IF('17.01'!$AK93="是",'17.01'!$AY$4,'17.01'!$AY$3)) -> 0 | G93: =IF(ISNUMBER(SEARCH("营",'17.01'!O93)),(-$Y93+50*IF('17.01'!$AK93="是",'17.01'!$AY$4,'17.01'!$AY$3)),(VLOOKUP('17.01'!O93,'17.01'!$AM$4:$AO$55,2,FALSE))*IF('17.01'!$AK93="是",'17.01'!$AY$4,'17.01'!$AY$3)) -> 0 | H93: =IF(ISNUMBER(SEARCH("营",'17.01'!P93)),(-$Y93+50*IF('17.01'!$AK93="是",'17.01'!$AY$4,'17.01'!$AY$3)),(VLOOKUP('17.01'!P93,'17.01'!$AM$4:$AO$55,2,FALSE))*IF('17.01'!$AK93="是",'17.01'!$AY$4,'17.01'!$AY$3)) -> 0 | ... X93: =IF(ISNUMBER(SEARCH("营",'17.01'!AF93)),(-$Y93+50*IF('17.01'!$AK93="是",'17.01'!$AY$4,'17.01'!$AY$3)),(VLOOKUP('17.01'!AF93,'17.01'!$AM$4:$AO$55,2,FALSE))*IF('17.01'!$AK93="是",'17.01'!$AY$4,'17.01'!$AY$3)) -> 0 | Y93: 100

Sheet 经验
A2: 队伍一 风 | C2: 步数 | D2: =COUNTIF(A4:H94,"<>空") -> 728 | E2: (不算跳步和传送) | I2: 队伍二 雷 | K2: 步数 | L2: =COUNTIF(I4:P94,"<>空") -> 728 | M2: (不算跳步和传送) | Q2: 队伍三 | S2: 总步数 | T2: =COUNTIF(Q4:X94,"<>空") -> 728 | U2: (不算跳步和传送)
A3: 1 | B3: 2 | C3: 3 | D3: 4 | E3: 5 | F3: 6 | G3: 7 | H3: 8 | I3: 1 | J3: 2 | K3: 3 | L3: 4 | M3: 5 | N3: 6 | O3: 7 | P3: 8 | Q3: 1 | R3: 2 | S3: 3 | T3: 4 | U3: 5 | V3: 6 | W3: 7 | X3: 8
A4: =(VLOOKUP('17.01'!I4,'17.01'!$AM$4:$AO$55,3,FALSE)) -> 35 | B4: =(VLOOKUP('17.01'!J4,'17.01'!$AM$4:$AO$55,3,FALSE)) -> 35 | C4: =(VLOOKUP('17.01'!K4,'17.01'!$AM$4:$AO$55,3,FALSE)) -> 35 | D4: =(VLOOKUP('17.01'!L4,'17.01'!$AM$4:$AO$55,3,FALSE)) -> 0 | E4: =(VLOOKUP('17.01'!M4,'17.01'!$AM$4:$AO$55,3,FALSE)) -> 0 | F4: =(VLOOKUP('17.01'!N4,'17.01'!$AM$4:$AO$55,3,FALSE)) -> 0 | G4: =(VLOOKUP('17.01'!O4,'17.01'!$AM$4:$AO$55,3,FALSE)) -> 0 | H4: =(VLOOKUP('17.01'!P4,'17.01'!$AM$4:$AO$55,3,FALSE)) -> 0 | ... X4: =(VLOOKUP('17.01'!AF4,'17.01'!$AM$4:$AO$55,3,FALSE)) -> 0
A5: =(VLOOKUP('17.01'!I5,'17.01'!$AM$4:$AO$55,3,FALSE)) -> 0 | B5: =(VLOOKUP('17.01'!J5,'17.01'!$AM$4:$AO$55,3,FALSE)) -> 0 | C5: =(VLOOKUP('17.01'!K5,'17.01'!$AM$4:$AO$55,3,FALSE)) -> 0 | D5: =(VLOOKUP('17.01'!L5,'17.01'!$AM$4:$AO$55,3,FALSE)) -> 0 | E5: =(VLOOKUP('17.01'!M5,'17.01'!$AM$4:$AO$55,3,FALSE)) -> 0 | F5: =(VLOOKUP('17.01'!N5,'17.01'!$AM$4:$AO$55,3,FALSE)) -> 0 | G5: =(VLOOKUP('17.01'!O5,'17.01'!$AM$4:$AO$55,3,FALSE)) -> 0 | H5: =(VLOOKUP('17.01'!P5,'17.01'!$AM$4:$AO$55,3,FALSE)) -> 0 | ... X5: =(VLOOKUP('17.01'!AF5,'17.01'!$AM$4:$AO$55,3,FALSE)) -> 0
A6: =(VLOOKUP('17.01'!I6,'17.01'!$AM$4:$AO$55,3,FALSE)) -> 0 | B6: =(VLOOKUP('17.01'!J6,'17.01'!$AM$4:$AO$55,3,FALSE)) -> 0 | C6: =(VLOOKUP('17.01'!K6,'17.01'!$AM$4:$AO$55,3,FALSE)) -> 0 | D6: =(VLOOKUP('17.01'!L6,'17.01'!$AM$4:$AO$55,3,FALSE)) -> 0 | E6: =(VLOOKUP('17.01'!M6,'17.01'!$AM$4:$AO$55,3,FALSE)) -> 0 | F6: =(VLOOKUP('17.01'!N6,'17.01'!$AM$4:$AO$55,3,FALSE)) -> 0 | G6: =(VLOOKUP('17.01'!O6,'17.01'!$AM$4:$AO$55,3,FALSE)) -> 0 | H6: =(VLOOKUP('17.01'!P6,'17.01'!$AM$4:$AO$55,3,FALSE)) -> 0 | ... X6: =(VLOOKUP('17.01'!AF6,'17.01'!$AM$4:$AO$55,3,FALSE)) -> 0
A7: =(VLOOKUP('17.01'!I7,'17.01'!$AM$4:$AO$55,3,FALSE)) -> 0 | B7: =(VLOOKUP('17.01'!J7,'17.01'!$AM$4:$AO$55,3,FALSE)) -> 0 | C7: =(VLOOKUP('17.01'!K7,'17.01'!$AM$4:$AO$55,3,FALSE)) -> 0 | D7: =(VLOOKUP('17.01'!L7,'17.01'!$AM$4:$AO$55,3,FALSE)) -> 0 | E7: =(VLOOKUP('17.01'!M7,'17.01'!$AM$4:$AO$55,3,FALSE)) -> 0 | F7: =(VLOOKUP('17.01'!N7,'17.01'!$AM$4:$AO$55,3,FALSE)) -> 0 | G7: =(VLOOKUP('17.01'!O7,'17.01'!$AM$4:$AO$55,3,FALSE)) -> 0 | H7: =(VLOOKUP('17.01'!P7,'17.01'!$AM$4:$AO$55,3,FALSE)) -> 0 | ... X7: =(VLOOKUP('17.01'!AF7,'17.01'!$AM$4:$AO$55,3,FALSE)) -> 0
A8: =(VLOOKUP('17.01'!I8,'17.01'!$AM$4:$AO$55,3,FALSE)) -> 0 | B8: =(VLOOKUP('17.01'!J8,'17.01'!$AM$4:$AO$55,3,FALSE)) -> 0 | C8: =(VLOOKUP('17.01'!K8,'17.01'!$AM$4:$AO$55,3,FALSE)) -> 0 | D8: =(VLOOKUP('17.01'!L8,'17.01'!$AM$4:$AO$55,3,FALSE)) -> 0 | E8: =(VLOOKUP('17.01'!M8,'17.01'!$AM$4:$AO$55,3,FALSE)) -> 0 | F8: =(VLOOKUP('17.01'!N8,'17.01'!$AM$4:$AO$55,3,FALSE)) -> 0 | G8: =(VLOOKUP('17.01'!O8,'17.01'!$AM$4:$AO$55,3,FALSE)) -> 0 | H8: =(VLOOKUP('17.01'!P8,'17.01'!$AM$4:$AO$55,3,FALSE)) -> 0 | ... X8: =(VLOOKUP('17.01'!AF8,'17.01'!$AM$4:$AO$55,3,FALSE)) -> 0
A9: =(VLOOKUP('17.01'!I9,'17.01'!$AM$4:$AO$55,3,FALSE)) -> 0 | B9: =(VLOOKUP('17.01'!J9,'17.01'!$AM$4:$AO$55,3,FALSE)) -> 0 | C9: =(VLOOKUP('17.01'!K9,'17.01'!$AM$4:$AO$55,3,FALSE)) -> 0 | D9: =(VLOOKUP('17.01'!L9,'17.01'!$AM$4:$AO$55,3,FALSE)) -> 0 | E9: =(VLOOKUP('17.01'!M9,'17.01'!$AM$4:$AO$55,3,FALSE)) -> 0 | F9: =(VLOOKUP('17.01'!N9,'17.01'!$AM$4:$AO$55,3,FALSE)) -> 0 | G9: =(VLOOKUP('17.01'!O9,'17.01'!$AM$4:$AO$55,3,FALSE)) -> 0 | H9: =(VLOOKUP('17.01'!P9,'17.01'!$AM$4:$AO$55,3,FALSE)) -> 0 | ... X9: =(VLOOKUP('17.01'!AF9,'17.01'!$AM$4:$AO$55,3,FALSE)) -> 0
A10: =(VLOOKUP('17.01'!I10,'17.01'!$AM$4:$AO$55,3,FALSE)) -> 0 | B10: =(VLOOKUP('17.01'!J10,'17.01'!$AM$4:$AO$55,3,FALSE)) -> 0 | C10: =(VLOOKUP('17.01'!K10,'17.01'!$AM$4:$AO$55,3,FALSE)) -> 0 | D10: =(VLOOKUP('17.01'!L10,'17.01'!$AM$4:$AO$55,3,FALSE)) -> 0 | E10: =(VLOOKUP('17.01'!M10,'17.01'!$AM$4:$AO$55,3,FALSE)) -> 0 | F10: =(VLOOKUP('17.01'!N10,'17.01'!$AM$4:$AO$55,3,FALSE)) -> 0 | G10: =(VLOOKUP('17.01'!O10,'17.01'!$AM$4:$AO$55,3,FALSE)) -> 0 | H10: =(VLOOKUP('17.01'!P10,'17.01'!$AM$4:$AO$55,3,FALSE)) -> 0 | ... X10: =(VLOOKUP('17.01'!AF10,'17.01'!$AM$4:$AO$55,3,FALSE)) -> 0
A11: =(VLOOKUP('17.01'!I11,'17.01'!$AM$4:$AO$55,3,FALSE)) -> 0 | B11: =(VLOOKUP('17.01'!J11,'17.01'!$AM$4:$AO$55,3,FALSE)) -> 0 | C11: =(VLOOKUP('17.01'!K11,'17.01'!$AM$4:$AO$55,3,FALSE)) -> 0 | D11: =(VLOOKUP('17.01'!L11,'17.01'!$AM$4:$AO$55,3,FALSE)) -> 0 | E11: =(VLOOKUP('17.01'!M11,'17.01'!$AM$4:$AO$55,3,FALSE)) -> 0 | F11: =(VLOOKUP('17.01'!N11,'17.01'!$AM$4:$AO$55,3,FALSE)) -> 0 | G11: =(VLOOKUP('17.01'!O11,'17.01'!$AM$4:$AO$55,3,FALSE)) -> 0 | H11: =(VLOOKUP('17.01'!P11,'17.01'!$AM$4:$AO$55,3,FALSE)) -> 0 | ... X11: =(VLOOKUP('17.01'!AF11,'17.01'!$AM$4:$AO$55,3,FALSE)) -> 0
A12: =(VLOOKUP('17.01'!I12,'17.01'!$AM$4:$AO$55,3,FALSE)) -> 0 | B12: =(VLOOKUP('17.01'!J12,'17.01'!$AM$4:$AO$55,3,FALSE)) -> 0 | C12: =(VLOOKUP('17.01'!K12,'17.01'!$AM$4:$AO$55,3,FALSE)) -> 0 | D12: =(VLOOKUP('17.01'!L12,'17.01'!$AM$4:$AO$55,3,FALSE)) -> 0 | E12: =(VLOOKUP('17.01'!M12,'17.01'!$AM$4:$AO$55,3,FALSE)) -> 0 | F12: =(VLOOKUP('17.01'!N12,'17.01'!$AM$4:$AO$55,3,FALSE)) -> 0 | G12: =(VLOOKUP('17.01'!O12,'17.01'!$AM$4:$AO$55,3,FALSE)) -> 0 | H12: =(VLOOKUP('17.01'!P12,'17.01'!$AM$4:$AO$55,3,FALSE)) -> 0 | ... X12: =(VLOOKUP('17.01'!AF12,'17.01'!$AM$4:$AO$55,3,FALSE)) -> 0
A13: =(VLOOKUP('17.01'!I13,'17.01'!$AM$4:$AO$55,3,FALSE)) -> 0 | B13: =(VLOOKUP('17.01'!J13,'17.01'!$AM$4:$AO$55,3,FALSE)) -> 0 | C13: =(VLOOKUP('17.01'!K13,'17.01'!$AM$4:$AO$55,3,FALSE)) -> 0 | D13: =(VLOOKUP('17.01'!L13,'17.01'!$AM$4:$AO$55,3,FALSE)) -> 0 | E13: =(VLOOKUP('17.01'!M13,'17.01'!$AM$4:$AO$55,3,FALSE)) -> 0 | F13: =(VLOOKUP('17.01'!N13,'17.01'!$AM$4:$AO$55,3,FALSE)) -> 0 | G13: =(VLOOKUP('17.01'!O13,'17.01'!$AM$4:$AO$55,3,FALSE)) -> 0 | H13: =(VLOOKUP('17.01'!P13,'17.01'!$AM$4:$AO$55,3,FALSE)) -> 0 | ... X13: =(VLOOKUP('17.01'!AF13,'17.01'!$AM$4:$AO$55,3,FALSE)) -> 0
