Workbook

Sheet 17.04
A1: =(_xlfn.DAYS(TODAY(),A4)+2)/((_xlfn.DAYS(A93,A4))+1) -> 0.066666667 | I1: 工作区 | AM1: 使用方法：按自己规划的路线，将下表中的地块名复制粘贴至工作区。初次使用传送门，当天跳步次数+5。重复使用传送门，当天跳步次数+1
A2: 17.04 | B2: 八卦前亏 | C2: =SUM(D4:D15) -> 23530 | D2: 合计经验 | F2: =SUM(F4:F93) -> 28115 | I2: 队伍一 火 | K2: 步数 | L2: =COUNTIF(I4:P93,"<>空") -> 29 | M2: (不算跳步和传送) | Q2: 队伍二 雷 | S2: 步数 | T2: =COUNTIF(Q4:X93,"<>空") -> 297 | U2: (不算跳步和传送) | Y2: 队伍三 | AA2: 总步数 | AB2: =COUNTIF(Y4:AF93,"<>空") -> 238 | AC2: (不算跳步和传送) | AG2: =SUM(AG4:AG93) -> 85 | AH2: =SUM(AH4:AH93) -> 0 | AI2: =SUM(AI4:AI93) -> 49 | AJ2: =SUM(AJ4:AJ93) -> 36 | AK2: 八卦全开 | AS2: 总地块 | AT2: =SUM(AT4:AT29) -> 564 | AV2: 总经验 | AW2: =SUM(AU4:AW29)+7000 -> 35115 | AY2: 粮草系数
A3: 日期 | B3: 获得粮草 | C3: 粮草调整 | D3: 消耗粮草 | E3: 剩余粮草 | F3: 获得经验 | G3: 累计经验 | H3: 任务经验 | I3: 1 | J3: 2 | K3: 3 | L3: 4 | M3: 5 | N3: 6 | O3: 7 | P3: 8 | Q3: 1 | R3: 2 | S3: 3 | T3: 4 | U3: 5 | V3: 6 | W3: 7 | X3: 8 | Y3: 1 | Z3: 2 | AA3: 3 | AB3: 4 | AC3: 5 | AD3: 6 | AE3: 7 | AF3: 8 | AG3: 跳步次数 | AH3: 1队跳步 | AI3: 2队跳步 | AJ3: 3队跳步 | AM3: 地块 | AN3: 粮草 | AO3: 经验 | AP3: 八卦前亏损 | AQ3: 一队地块 | AR3: 二队地块 | AS3: 三队地块 | AT3: 总地块 | AU3: 一队经验 | AV3: 二队经验 | AW3: 三队经验 | AX3: 八卦前 | AY3: 1
A4: 45548 | B4: 800 | C4: 4800 | D4: =(SUM(粮草!A4:X4)+AG4*10*IF(AK4="是",$AY$4,$AY$3)) -> 2050 | E4: =SUM($B$4:B4)+SUM($C$4:C4)-SUM($D$4:D4) -> 3550 | F4: =SUM(经验!A4:X4) -> 515 | G4: =SUM($F$4:F4)+SUM($H$4:H4) -> 1015 | H4: 500 | I4: 1级 | J4: 1级 | K4: 1级 | L4: 空 | M4: 空 | N4: 空 | O4: 空 | P4: 空 | Q4: 1级 | R4: 1级 | S4: 商人 | T4: 1级 | U4: 1级 | V4: 1级 | W4: 空 | X4: 空 | Y4: 1级 | Z4: 1级 | AA4: 1级 | AB4: 1级 | AC4: 1级 | AD4: 商人 | AE4: 空 | AF4: 空 | AG4: =AH4+AI4+AJ4 -> 0 | AK4: 否 | AM4: 1级 | AN4: 150 | AO4: 35 | AP4: 44.222109 | AQ4: =COUNTIF($I$4:$P$93,AM4) -> 9 | AR4: =COUNTIF($Q$4:$X$93,AM4) -> 7 | AS4: =COUNTIF($Y$4:$AF$93,AM4) -> 14 | AT4: =AQ4+AR4+AS4 -> 30 | AU4: =AQ4*$AO4 -> 315 | AV4: =AR4*$AO4 -> 245 | AW4: =AS4*$AO4 -> 490 | AX4: 八卦后 | AY4: 0.8 | BA4: =AN4*0.8 -> 120
A5: 45549 | B5: 1600 | C5: 1200 | D5: =(SUM(粮草!A5:X5)+AG5*10*IF(AK5="是",$AY$4,$AY$3)) -> 1100 | E5: =SUM($B$4:B5)+SUM($C$4:C5)-SUM($D$4:D5) -> 5250 | F5: =SUM(经验!A5:X5) -> 275 | G5: =SUM($F$4:F5)+SUM($H$4:H5) -> 1290 | H5: 0 | I5: 空 | J5: 空 | K5: 空 | L5: 空 | M5: 空 | N5: 空 | O5: 空 | P5: 空 | Q5: 1级 | R5: 商人 | S5: 空 | T5: 空 | U5: 空 | V5: 空 | W5: 空 | X5: 空 | Y5: 1级 | Z5: 1级 | AA5: 1级 | AB5: 1级 | AC5: 1级 | AD5: 1级 | AE5: 空 | AF5: 空 | AG5: =AH5+AI5+AJ5 -> 0 | AK5: 否 | AM5: 2级 | AN5: 160 | AO5: 40 | AP5: 39.110982 | AQ5: =COUNTIF($I$4:$P$93,AM5) -> 14 | AR5: =COUNTIF($Q$4:$X$93,AM5) -> 6 | AS5: =COUNTIF($Y$4:$AF$93,AM5) -> 34 | AT5: =AQ5+AR5+AS5 -> 54 | AU5: =AQ5*$AO5 -> 560 | AV5: =AR5*$AO5 -> 240 | AW5: =AS5*$AO5 -> 1360 | AX5: Note：开完八卦当天可能需要手动计算粮草 | BA5: =AN5*0.8 -> 128
A6: 45550 | B6: 1600 | D6: =(SUM(粮草!A6:X6)+AG6*10*IF(AK6="是",$AY$4,$AY$3)) -> 2080 | E6: =SUM($B$4:B6)+SUM($C$4:C6)-SUM($D$4:D6) -> 4770 | F6: =SUM(经验!A6:X6) -> 550 | G6: =SUM($F$4:F6)+SUM($H$4:H6) -> 1840 | H6: 0 | I6: 空 | J6: 空 | K6: 空 | L6: 空 | M6: 空 | N6: 空 | O6: 空 | P6: 空 | Q6: 3级 | R6: 3级 | S6: 3级 | T6: 3级 | U6: 3级 | V6: 3级 | W6: 3级 | X6: 空 | Y6: 商人 | Z6: 1级 | AA6: 1级 | AB6: 3级 | AC6: 3级卦 | AD6: 3级 | AE6: 空 | AF6: 空 | AG6: =AH6+AI6+AJ6 -> 3 | AI6: 2 | AJ6: 1 | AK6: 否 | AM6: 3级 | AN6: 170 | AO6: 45 | AP6: 34 | AQ6: =COUNTIF($I$4:$P$93,AM6) -> 0 | AR6: =COUNTIF($Q$4:$X$93,AM6) -> 89 | AS6: =COUNTIF($Y$4:$AF$93,AM6) -> 91 | AT6: =AQ6+AR6+AS6 -> 180 | AU6: =AQ6*$AO6 -> 0 | AV6: =AR6*$AO6 -> 4005 | AW6: =AS6*$AO6 -> 4095 | BA6: =AN6*0.8 -> 136
A7: 45551 | B7: 1600 | D7: =(SUM(粮草!A7:X7)+AG7*10*IF(AK7="是",$AY$4,$AY$3)) -> 2330 | E7: =SUM($B$4:B7)+SUM($C$4:C7)-SUM($D$4:D7) -> 4040 | F7: =SUM(经验!A7:X7) -> 870 | G7: =SUM($F$4:F7)+SUM($H$4:H7) -> 2910 | H7: 200 | I7: 空 | J7: 空 | K7: 空 | L7: 空 | M7: 空 | N7: 空 | O7: 空 | P7: 空 | Q7: 塔3 | R7: 3级 | S7: 3级 | T7: 3级 | U7: 大卦 | V7: 3级 | W7: 3级 | X7: 3级 | Y7: 3级 | Z7: 3级 | AA7: 商人 | AB7: 3级 | AC7: 3级 | AD7: 3级 | AE7: 空 | AF7: 空 | AG7: =AH7+AI7+AJ7 -> 1 | AI7: 1 | AK7: 否 | AM7: 4级 | AN7: 180 | AO7: 50 | AP7: 36 | AQ7: =COUNTIF($I$4:$P$93,AM7) -> 0 | AR7: =COUNTIF($Q$4:$X$93,AM7) -> 74 | AS7: =COUNTIF($Y$4:$AF$93,AM7) -> 30 | AT7: =AQ7+AR7+AS7 -> 104 | AU7: =AQ7*$AO7 -> 0 | AV7: =AR7*$AO7 -> 3700 | AW7: =AS7*$AO7 -> 1500 | BA7: =AN7*0.8 -> 144
A8: 45552 | B8: 1600 | D8: =(SUM(粮草!A8:X8)+AG8*10*IF(AK8="是",$AY$4,$AY$3)) -> 2030 | E8: =SUM($B$4:B8)+SUM($C$4:C8)-SUM($D$4:D8) -> 3610 | F8: =SUM(经验!A8:X8) -> 780 | G8: =SUM($F$4:F8)+SUM($H$4:H8) -> 3790 | H8: 100 | I8: 空 | J8: 空 | K8: 空 | L8: 空 | M8: 空 | N8: 空 | O8: 空 | P8: 空 | Q8: 3级 | R8: 3级 | S8: 3级 | T8: 商人 | U8: 3级 | V8: 3级 | W8: 空 | X8: 空 | Y8: 3级 | Z8: 3级 | AA8: 3级 | AB8: 3级 | AC8: 大卦 | AD8: 3级 | AE8: 空 | AF8: 空 | AG8: =AH8+AI8+AJ8 -> 3 | AJ8: 3 | AK8: 否 | AM8: 5级 | AN8: 190 | AO8: 55 | AP8: 38 | AQ8: =COUNTIF($I$4:$P$93,AM8) -> 0 | AR8: =COUNTIF($Q$4:$X$93,AM8) -> 30 | AS8: =COUNTIF($Y$4:$AF$93,AM8) -> 1 | AT8: =AQ8+AR8+AS8 -> 31 | AU8: =AQ8*$AO8 -> 0 | AV8: =AR8*$AO8 -> 1650 | AW8: =AS8*$AO8 -> 55 | BA8: =AN8*0.8 -> 152
A9: 45553 | B9: 1600 | D9: =(SUM(粮草!A9:X9)+AG9*10*IF(AK9="是",$AY$4,$AY$3)) -> 1980 | E9: =SUM($B$4:B9)+SUM($C$4:C9)-SUM($D$4:D9) -> 3230 | F9: =SUM(经验!A9:X9) -> 550 | G9: =SUM($F$4:F9)+SUM($H$4:H9) -> 4540 | H9: 200 | I9: 空 | J9: 空 | K9: 空 | L9: 空 | M9: 空 | N9: 空 | O9: 空 | P9: 空 | Q9: 3级卦 | R9: 4级 | S9: 4级 | T9: 4级 | U9: 4级 | V9: 4级 | W9: 空 | X9: 空 | Y9: 3级 | Z9: 3级 | AA9: 3级 | AB9: 3级 | AC9: 商人 | AD9: 3级 | AE9: 空 | AF9: 空 | AG9: =AH9+AI9+AJ9 -> 1 | AI9: 1 | AK9: 否 | AM9: 6级 | AN9: 200 | AO9: 60 | AQ9: =COUNTIF($I$4:$P$93,AM9) -> 0 | AR9: =COUNTIF($Q$4:$X$93,AM9) -> 55 | AS9: =COUNTIF($Y$4:$AF$93,AM9) -> 43 | AT9: =AQ9+AR9+AS9 -> 98 | AU9: =AQ9*$AO9 -> 0 | AV9: =AR9*$AO9 -> 3300 | AW9: =AS9*$AO9 -> 2580 | BA9: =AN9*0.8 -> 160
A10: 45554 | B10: 1600 | D10: =(SUM(粮草!A10:X10)+AG10*10*IF(AK10="是",$AY$4,$AY$3)) -> 2090 | E10: =SUM($B$4:B10)+SUM($C$4:C10)-SUM($D$4:D10) -> 2740 | F10: =SUM(经验!A10:X10) -> 555 | G10: =SUM($F$4:F10)+SUM($H$4:H10) -> 5095 | H10: 0 | I10: 空 | J10: 空 | K10: 空 | L10: 空 | M10: 空 | N10: 空 | O10: 空 | P10: 空 | Q10: 塔4 | R10: 4级 | S10: 4级 | T10: 3级 | U10: 3级 | V10: 3级 | W10: 空 | X10: 空 | Y10: 3级 | Z10: 3级 | AA10: 3级 | AB10: 3级 | AC10: 3级 | AD10: 3级 | AE10: 空 | AF10: 空 | AG10: =AH10+AI10+AJ10 -> 5 | AI10: 5 | AK10: 否 | AM10: 塔1 | AN10: 150 | AO10: 35 | AP10: 44.222109 | AQ10: =COUNTIF($I$4:$P$93,AM10) -> 0 | AR10: =COUNTIF($Q$4:$X$93,AM10) -> 0 | AS10: =COUNTIF($Y$4:$AF$93,AM10) -> 0 | AT10: =AQ10+AR10+AS10 -> 0 | AU10: =AQ10*$AO10 -> 0 | AV10: =AR10*$AO10 -> 0 | AW10: =AS10*$AO10 -> 0 | BA10: =AN10*0.8 -> 120
A11: 45555 | B11: 1600 | D11: =(SUM(粮草!A11:X11)+AG11*10*IF(AK11="是",$AY$4,$AY$3)) -> 1980 | E11: =SUM($B$4:B11)+SUM($C$4:C11)-SUM($D$4:D11) -> 2360 | F11: =SUM(经验!A11:X11) -> 575 | G11: =SUM($F$4:F11)+SUM($H$4:H11) -> 5670 | H11: 0 | I11: 空 | J11: 空 | K11: 空 | L11: 空 | M11: 空 | N11: 空 | O11: 空 | P11: 空 | Q11: 3级卦 | R11: 3级 | S11: 1级 | T11: 3级 | U11: 营地 | V11: 3级 | W11: 3级 | X11: 3级 | Y11: 3级 | Z11: 3级 | AA11: 3级 | AB11: 3级 | AC11: 3级 | AD11: 3级 | AE11: 空 | AF11: 空 | AG11: =AH11+AI11+AJ11 -> 4 | AI11: 4 | AK11: 否 | AM11: 塔2 | AN11: 150 | AO11: 40 | AP11: 29.110982 | AQ11: =COUNTIF($I$4:$P$93,AM11) -> 0 | AR11: =COUNTIF($Q$4:$X$93,AM11) -> 2 | AS11: =COUNTIF($Y$4:$AF$93,AM11) -> 0 | AT11: =AQ11+AR11+AS11 -> 2 | AU11: =AQ11*$AO11 -> 0 | AV11: =AR11*$AO11 -> 80 | AW11: =AS11*$AO11 -> 0 | BA11: =AN11*0.8 -> 120
A12: 45556 | B12: 1600 | D12: =(SUM(粮草!A12:X12)+AG12*10*IF(AK12="是",$AY$4,$AY$3)) -> 1900 | E12: =SUM($B$4:B12)+SUM($C$4:C12)-SUM($D$4:D12) -> 2060 | F12: =SUM(经验!A12:X12) -> 525 | G12: =SUM($F$4:F12)+SUM($H$4:H12) -> 6195 | H12: 0 | I12: 空 | J12: 空 | K12: 空 | L12: 空 | M12: 空 | N12: 空 | O12: 空 | P12: 空 | Q12: 3级 | R12: 3级 | S12: 塔3 | T12: 3级 | U12: 3级 | V12: 3级卦 | W12: 空 | X12: 空 | Y12: 3级 | Z12: 商人 | AA12: 3级 | AB12: 3级 | AC12: 3级 | AD12: 3级 | AE12: 空 | AF12: 空 | AG12: =AH12+AI12+AJ12 -> 0 | AK12: 否 | AM12: 塔3 | AN12: 150 | AO12: 45 | AP12: 13.999855 | AQ12: =COUNTIF($I$4:$P$93,AM12) -> 0 | AR12: =COUNTIF($Q$4:$X$93,AM12) -> 4 | AS12: =COUNTIF($Y$4:$AF$93,AM12) -> 1 | AT12: =AQ12+AR12+AS12 -> 5 | AU12: =AQ12*$AO12 -> 0 | AV12: =AR12*$AO12 -> 180 | AW12: =AS12*$AO12 -> 45 | BA12: =AN12*0.8 -> 120
A13: 45557 | B13: 1600 | D13: =(SUM(粮草!A13:X13)+AG13*10*IF(AK13="是",$AY$4,$AY$3)) -> 1240 | E13: =SUM($B$4:B13)+SUM($C$4:C13)-SUM($D$4:D13) -> 2420 | F13: =SUM(经验!A13:X13) -> 580 | G13: =SUM($F$4:F13)+SUM($H$4:H13) -> 6775 | H13: 0 | I13: 空 | J13: 空 | K13: 空 | L13: 空 | M13: 空 | N13: 空 | O13: 空 | P13: 空 | Q13: 4级 | R13: 商人 | S13: 4级 | T13: 4级 | U13: 4级 | V13: 4级 | W13: 空 | X13: 空 | Y13: 大卦 | Z13: 空 | AA13: 空 | AB13: 空 | AC13: 空 | AD13: 空 | AE13: 空 | AF13: 空 | AG13: =AH13+AI13+AJ13 -> 4 | AI13: 4 | AK13: 否 | AM13: 塔4 | AN13: 150 | AO13: 50 | AQ13: =COUNTIF($I$4:$P$93,AM13) -> 0 | AR13: =COUNTIF($Q$4:$X$93,AM13) -> 1 | AS13: =COUNTIF($Y$4:$AF$93,AM13) -> 0 | AT13: =AQ13+AR13+AS13 -> 1 | AU13: =AQ13*$AO13 -> 0 | AV13: =AR13*$AO13 -> 50 | AW13: =AS13*$AO13 -> 0 | BA13: =AN13*0.8 -> 120
A14: 45558 | B14: 1600 | C14: 520 | D14: =(SUM(粮草!A14:X14)+AG14*10*IF(AK14="是",$AY$4,$AY$3)) -> 2310 | E14: =SUM($B$4:B14)+SUM($C$4:C14)-SUM($D$4:D14) -> 2230 | F14: =SUM(经验!A14:X14) -> 640 | G14: =SUM($F$4:F14)+SUM($H$4:H14) -> 7715 | H14: 300 | I14: 空 | J14: 空 | K14: 空 | L14: 空 | M14: 空 | N14: 空 | O14: 空 | P14: 空 | Q14: 4级 | R14: 4级 | S14: 4级 | T14: 4级 | U14: 4级 | V14: 商人 | W14: 空 | X14: 空 | Y14: 3级 | Z14: 3级 | AA14: 3级 | AB14: 3级 | AC14: 3级 | AD14: 3级 | AE14: 3级 | AF14: 3级 | AG14: =AH14+AI14+AJ14 -> 0 | AK14: 否 | AM14: 塔5 | AN14: 150 | AO14: 55 | AQ14: =COUNTIF($I$4:$P$93,AM14) -> 0 | AR14: =COUNTIF($Q$4:$X$93,AM14) -> 0 | AS14: =COUNTIF($Y$4:$AF$93,AM14) -> 0 | AT14: =AQ14+AR14+AS14 -> 0 | AU14: =AQ14*$AO14 -> 0 | AV14: =AR14*$AO14 -> 0 | AW14: =AS14*$AO14 -> 0 | BA14: =AN14*0.8 -> 120
A15: 45559 | B15: 1600 | D15: =(SUM(粮草!A15:X15)+AG15*10*IF(AK15="是",$AY$4,$AY$3)) -> 2440 | E15: =SUM($B$4:B15)+SUM($C$4:C15)-SUM($D$4:D15) -> 1390 | F15: =SUM(经验!A15:X15) -> 665 | G15: =SUM($F$4:F15)+SUM($H$4:H15) -> 8380 | H15: 0 | I15: 空 | J15: 空 | K15: 空 | L15: 空 | M15: 空 | N15: 空 | O15: 空 | P15: 空 | Q15: 4级 | R15: 3级 | S15: 3级 | T15: 3级 | U15: 3级 | V15: 3级 | W15: 3级卦 | X15: 空 | Y15: 3级 | Z15: 3级 | AA15: 商人 | AB15: 3级 | AC15: 3级 | AD15: 3级 | AE15: 3级 | AF15: 3级 | AG15: =AH15+AI15+AJ15 -> 0 | AK15: 否 | AM15: 塔6 | AN15: 150 | AO15: 60 | AQ15: =COUNTIF($I$4:$P$93,AM15) -> 0 | AR15: =COUNTIF($Q$4:$X$93,AM15) -> 0 | AS15: =COUNTIF($Y$4:$AF$93,AM15) -> 0 | AT15: =AQ15+AR15+AS15 -> 0 | AU15: =AQ15*$AO15 -> 0 | AV15: =AR15*$AO15 -> 0 | AW15: =AS15*$AO15 -> 0 | BA15: =AN15*0.8 -> 120
A16: 45560 | B16: 1600 | D16: =(SUM(粮草!A16:X16)+AG16*10*IF(AK16="是",$AY$4,$AY$3)) -> 1580 | E16: =SUM($B$4:B16)+SUM($C$4:C16)-SUM($D$4:D16) -> 1410 | F16: =SUM(经验!A16:X16) -> 595 | G16: =SUM($F$4:F16)+SUM($H$4:H16) -> 9175 | H16: 200 | I16: 空 | J16: 空 | K16: 空 | L16: 空 | M16: 空 | N16: 空 | O16: 空 | P16: 空 | Q16: 3级 | R16: 3级 | S16: 3级 | T16: 4级 | U16: 4级 | V16: 4级 | W16: 空 | X16: 空 | Y16: 3级 | Z16: 3级 | AA16: 营地 | AB16: 3级 | AC16: 3级 | AD16: 3级 | AE16: 3级 | AF16: 2级 | AG16: =AH16+AI16+AJ16 -> 7 | AI16: 7 | AK16: 是 | AM16: 遗迹 | AN16: 150 | AO16: 35 | AP16: 44.222109 | AQ16: =COUNTIF($I$4:$P$93,AM16) -> 0 | AR16: =COUNTIF($Q$4:$X$93,AM16) -> 0 | AS16: =COUNTIF($Y$4:$AF$93,AM16) -> 0 | AT16: =AQ16+AR16+AS16 -> 0 | AU16: =AQ16*$AO16 -> 0 | AV16: =AR16*$AO16 -> 0 | AW16: =AS16*$AO16 -> 0 | BA16: =AN16*0.8 -> 120
A17: 45561 | B17: 1600 | D17: =(SUM(粮草!A17:X17)+AG17*10*IF(AK17="是",$AY$4,$AY$3)) -> 1556 | E17: =SUM($B$4:B17)+SUM($C$4:C17)-SUM($D$4:D17) -> 1454 | F17: =SUM(经验!A17:X17) -> 620 | G17: =SUM($F$4:F17)+SUM($H$4:H17) -> 9795 | H17: 0 | I17: 空 | J17: 空 | K17: 空 | L17: 空 | M17: 空 | N17: 空 | O17: 空 | P17: 空 | Q17: 4级 | R17: 4级 | S17: 营地 | T17: 4级 | U17: 4级 | V17: 4级 | W17: 4级 | X17: 4级 | Y17: 2级 | Z17: 2级 | AA17: 2级 | AB17: 商人 | AC17: 2级 | AD17: 2级 | AE17: 2级 | AF17: 空 | AG17: =AH17+AI17+AJ17 -> 0 | AK17: 是 | AM17: 商人 | AN17: 50 | AO17: 30 | AP17: 10 | AQ17: =COUNTIF($I$4:$P$93,AM17) -> 5 | AR17: =COUNTIF($Q$4:$X$93,AM17) -> 13 | AS17: =COUNTIF($Y$4:$AF$93,AM17) -> 16 | AT17: =AQ17+AR17+AS17 -> 34 | AU17: =AQ17*$AO17 -> 150 | AV17: =AR17*$AO17 -> 390 | AW17: =AS17*$AO17 -> 480 | BA17: =AN17*0.8 -> 40
A18: 45562 | B18: 1600 | D18: =(SUM(粮草!A18:X18)+AG18*10*IF(AK18="是",$AY$4,$AY$3)) -> 1460 | E18: =SUM($B$4:B18)+SUM($C$4:C18)-SUM($D$4:D18) -> 1594 | F18: =SUM(经验!A18:X18) -> 570 | G18: =SUM($F$4:F18)+SUM($H$4:H18) -> 10365 | H18: 0 | I18: 空 | J18: 空 | K18: 空 | L18: 空 | M18: 空 | N18: 空 | O18: 空 | P18: 空 | Q18: 4级 | R18: 4级 | S18: 4级 | T18: 4级 | U18: 4级 | V18: 4级 | W18: 空 | X18: 空 | Y18: 2级 | Z18: 2级 | AA18: 2级 | AB18: 2级 | AC18: 2级 | AD18: 2级 | AE18: 营地 | AF18: 商人 | AG18: =AH18+AI18+AJ18 -> 6 | AI18: 1 | AJ18: 5 | AK18: 是 | AM18: 营地 | AN18: -150 | AO18: 0 | AP18: 10 | AQ18: =COUNTIF($I$4:$P$93,AM18) -> 1 | AR18: =COUNTIF($Q$4:$X$93,AM18) -> 9 | AS18: =COUNTIF($Y$4:$AF$93,AM18) -> 5 | AT18: =AQ18+AR18+AS18 -> 15 | AU18: =AQ18*$AO18 -> 0 | AV18: =AR18*$AO18 -> 0 | AW18: =AS18*$AO18 -> 0 | BA18: =AN18*0.8 -> -120
A19: 45563 | B19: 1600 | D19: =(SUM(粮草!A19:X19)+AG19*10*IF(AK19="是",$AY$4,$AY$3)) -> 1568 | E19: =SUM($B$4:B19)+SUM($C$4:C19)-SUM($D$4:D19) -> 1626 | F19: =SUM(经验!A19:X19) -> 545 | G19: =SUM($F$4:F19)+SUM($H$4:H19) -> 10910 | H19: 0 | I19: 空 | J19: 空 | K19: 空 | L19: 空 | M19: 空 | N19: 空 | O19: 空 | P19: 空 | Q19: 4级 | R19: 4级 | S19: 4级 | T19: 5级 | U19: 5级 | V19: 5级 | W19: 空 | X19: 空 | Y19: 2级 | Z19: 2级 | AA19: 2级 | AB19: 2级 | AC19: 2级 | AD19: 商人 | AE19: 空 | AF19: 空 | AG19: =AH19+AI19+AJ19 -> 0 | AK19: 是 | AM19: 大卦 | AN19: 250 | AO19: 300 | AQ19: =COUNTIF($I$4:$P$93,AM19) -> 0 | AR19: =COUNTIF($Q$4:$X$93,AM19) -> 1 | AS19: =COUNTIF($Y$4:$AF$93,AM19) -> 2 | AT19: =AQ19+AR19+AS19 -> 3 | AU19: =AQ19*$AO19 -> 0 | AV19: =AR19*$AO19 -> 300 | AW19: =AS19*$AO19 -> 600 | BA19: =AN19*0.8 -> 200
A20: 45564 | B20: 1600 | D20: =(SUM(粮草!A20:X20)+AG20*10*IF(AK20="是",$AY$4,$AY$3)) -> 1462 | E20: =SUM($B$4:B20)+SUM($C$4:C20)-SUM($D$4:D20) -> 1764 | F20: =SUM(经验!A20:X20) -> 545 | G20: =SUM($F$4:F20)+SUM($H$4:H20) -> 11455 | H20: 0 | I20: 空 | J20: 空 | K20: 空 | L20: 空 | M20: 空 | N20: 空 | O20: 空 | P20: 空 | Q20: 5级 | R20: 5级 | S20: 营地 | T20: 5级 | U20: 5级 | V20: 4级 | W20: 2级 | X20: 空 | Y20: 2级 | Z20: 2级 | AA20: 2级 | AB20: 1级 | AC20: 2级 | AD20: 2级 | AE20: 空 | AF20: 空 | AG20: =AH20+AI20+AJ20 -> 4 | AJ20: 4 | AK20: 是 | AM20: 3级卦 | AN20: 170 | AO20: 45 | AQ20: =COUNTIF($I$4:$P$93,AM20) -> 0 | AR20: =COUNTIF($Q$4:$X$93,AM20) -> 4 | AS20: =COUNTIF($Y$4:$AF$93,AM20) -> 1 | AT20: =AQ20+AR20+AS20 -> 5 | AU20: =AQ20*$AO20 -> 0 | AV20: =AR20*$AO20 -> 180 | AW20: =AS20*$AO20 -> 45 | BA20: =AN20*0.8 -> 136
A21: 45565 | B21: 1600 | D21: =(SUM(粮草!A21:X21)+AG21*10*IF(AK21="是",$AY$4,$AY$3)) -> 1512 | E21: =SUM($B$4:B21)+SUM($C$4:C21)-SUM($D$4:D21) -> 1852 | F21: =SUM(经验!A21:X21) -> 530 | G21: =SUM($F$4:F21)+SUM($H$4:H21) -> 12185 | H21: 200 | I21: 空 | J21: 空 | K21: 空 | L21: 空 | M21: 空 | N21: 空 | O21: 空 | P21: 空 | Q21: 5级 | R21: 5级 | S21: 4级 | T21: 4级 | U21: 4级 | V21: 4级 | W21: 空 | X21: 空 | Y21: 2级 | Z21: 商人 | AA21: 2级 | AB21: 2级 | AC21: 2级 | AD21: 商人 | AE21: 空 | AF21: 空 | AG21: =AH21+AI21+AJ21 -> 5 | AJ21: 5 | AK21: 是 | AM21: 巨卦 | AN21: 250 | AO21: 400 | AQ21: =COUNTIF($I$4:$P$93,AM21) -> 0 | AR21: =COUNTIF($Q$4:$X$93,AM21) -> 0 | AS21: =COUNTIF($Y$4:$AF$93,AM21) -> 0 | AT21: =AQ21+AR21+AS21 -> 0 | AU21: =AQ21*$AO21 -> 0 | AV21: =AR21*$AO21 -> 0 | AW21: =AS21*$AO21 -> 0 | BA21: =AN21*0.8 -> 200
A22: 45566 | B22: 1600 | D22: =(SUM(粮草!A22:X22)+AG22*10*IF(AK22="是",$AY$4,$AY$3)) -> 1292 | E22: =SUM($B$4:B22)+SUM($C$4:C22)-SUM($D$4:D22) -> 2160 | F22: =SUM(经验!A22:X22) -> 590 | G22: =SUM($F$4:F22)+SUM($H$4:H22) -> 12875 | H22: 100 | I22: 空 | J22: 空 | K22: 空 | L22: 空 | M22: 空 | N22: 空 | O22: 空 | P22: 空 | Q22: 4级 | R22: 营地 | S22: 4级 | T22: 4级 | U22: 4级 | V22: 5级 | W22: 4级 | X22: 4级 | Y22: 2级 | Z22: 营地 | AA22: 2级 | AB22: 2级 | AC22: 5级 | AD22: 6级 | AE22: 空 | AF22: 空 | AG22: =AH22+AI22+AJ22 -> 0 | AK22: 是 | AM22: 大boss | AN22: 250 | AO22: 1000 | AQ22: =COUNTIF($I$4:$P$93,AM22) -> 0 | AR22: =COUNTIF($Q$4:$X$93,AM22) -> 1 | AS22: =COUNTIF($Y$4:$AF$93,AM22) -> 0 | AT22: =AQ22+AR22+AS22 -> 1 | AU22: =AQ22*$AO22 -> 0 | AV22: =AR22*$AO22 -> 1000 | AW22: =AS22*$AO22 -> 0 | BA22: =AN22*0.8 -> 200
A23: 45567 | B23: 1600 | D23: =(SUM(粮草!A23:X23)+AG23*10*IF(AK23="是",$AY$4,$AY$3)) -> 1806 | E23: =SUM($B$4:B23)+SUM($C$4:C23)-SUM($D$4:D23) -> 1954 | F23: =SUM(经验!A23:X23) -> 740 | G23: =SUM($F$4:F23)+SUM($H$4:H23) -> 13815 | H23: 200 | I23: 空 | J23: 空 | K23: 空 | L23: 空 | M23: 空 | N23: 空 | O23: 空 | P23: 空 | Q23: 4级 | R23: 5级 | S23: 5级 | T23: 营地 | U23: 5级 | V23: 5级 | W23: 5级 | X23: 5级 | Y23: 6级 | Z23: 6级 | AA23: 6级 | AB23: 6级 | AC23: 6级 | AD23: 6级 | AE23: 空 | AF23: 空 | AG23: =AH23+AI23+AJ23 -> 0 | AK23: 是 | AM23: 中boss | AN23: 250 | AO23: 500 | AQ23: =COUNTIF($I$4:$P$93,AM23) -> 0 | AR23: =COUNTIF($Q$4:$X$93,AM23) -> 0 | AS23: =COUNTIF($Y$4:$AF$93,AM23) -> 0 | AT23: =AQ23+AR23+AS23 -> 0 | AU23: =AQ23*$AO23 -> 0 | AV23: =AR23*$AO23 -> 0 | AW23: =AS23*$AO23 -> 0 | BA23: =AN23*0.8 -> 200
A24: 45568 | B24: 1600 | D24: =(SUM(粮草!A24:X24)+AG24*10*IF(AK24="是",$AY$4,$AY$3)) -> 1620 | E24: =SUM($B$4:B24)+SUM($C$4:C24)-SUM($D$4:D24) -> 1934 | F24: =SUM(经验!A24:X24) -> 755 | G24: =SUM($F$4:F24)+SUM($H$4:H24) -> 14570 | H24: 0 | I24: 空 | J24: 空 | K24: 空 | L24: 空 | M24: 空 | N24: 空 | O24: 空 | P24: 空 | Q24: 6级 | R24: 营地 | S24: 6级 | T24: 5级 | U24: 5级 | V24: 5级 | W24: 5级 | X24: 5级 | Y24: 6级 | Z24: 6级 | AA24: 营地 | AB24: 6级 | AC24: 6级 | AD24: 6级 | AE24: 6级 | AF24: 空 | AG24: =AH24+AI24+AJ24 -> 0 | AK24: 是 | AM24: 4级卦 | AN24: 180 | AO24: 50 | AP24: 39.110982 | AQ24: =COUNTIF($I$4:$P$93,AM24) -> 0 | AR24: =COUNTIF($Q$4:$X$93,AM24) -> 0 | AS24: =COUNTIF($Y$4:$AF$93,AM24) -> 0 | AT24: =AQ24+AR24+AS24 -> 0 | AU24: =AQ24*$AO24 -> 0 | AV24: =AR24*$AO24 -> 0 | AW24: =AS24*$AO24 -> 0 | BA24: =AN24*0.8 -> 144
A25: 45569 | B25: 1600 | D25: =(SUM(粮草!A25:X25)+AG25*10*IF(AK25="是",$AY$4,$AY$3)) -> 1806 | E25: =SUM($B$4:B25)+SUM($C$4:C25)-SUM($D$4:D25) -> 1728 | F25: =SUM(经验!A25:X25) -> 725 | G25: =SUM($F$4:F25)+SUM($H$4:H25) -> 15295 | H25: 0 | I25: 空 | J25: 空 | K25: 空 | L25: 空 | M25: 空 | N25: 空 | O25: 空 | P25: 空 | Q25: 5级 | R25: 5级 | S25: 4级 | T25: 4级 | U25: 5级 | V25: 4级 | W25: 营地 | X25: 4级 | Y25: 6级 | Z25: 6级 | AA25: 6级 | AB25: 6级 | AC25: 6级 | AD25: 6级 | AE25: 空 | AF25: 空 | AG25: =AH25+AI25+AJ25 -> 3 | AJ25: 3 | AK25: 是 | AM25: 山中 | AN25: 160 | AO25: 40 | AP25: 39.110982 | AQ25: =COUNTIF($I$4:$P$93,AM25) -> 0 | AR25: =COUNTIF($Q$4:$X$93,AM25) -> 0 | AS25: =COUNTIF($Y$4:$AF$93,AM25) -> 0 | AT25: =AQ25+AR25+AS25 -> 0 | AU25: =AQ25*$AO25 -> 0 | AV25: =AR25*$AO25 -> 0 | AW25: =AS25*$AO25 -> 0 | BA25: =AN25*0.8 -> 128
A26: 45570 | B26: 1600 | D26: =(SUM(粮草!A26:X26)+AG26*10*IF(AK26="是",$AY$4,$AY$3)) -> 1648 | E26: =SUM($B$4:B26)+SUM($C$4:C26)-SUM($D$4:D26) -> 1680 | F26: =SUM(经验!A26:X26) -> 625 | G26: =SUM($F$4:F26)+SUM($H$4:H26) -> 15920 | H26: 0 | I26: 空 | J26: 空 | K26: 空 | L26: 空 | M26: 空 | N26: 空 | O26: 空 | P26: 空 | Q26: 5级 | R26: 商人 | S26: 4级 | T26: 4级 | U26: 5级 | V26: 5级 | W26: 空 | X26: 空 | Y26: 6级 | Z26: 商人 | AA26: 6级 | AB26: 6级 | AC26: 6级 | AD26: 6级 | AE26: 空 | AF26: 空 | AG26: =AH26+AI26+AJ26 -> 3 | AJ26: 3 | AK26: 是 | AM26: 秋道 | AN26: 150 | AO26: 35 | AP26: 44.222109 | AQ26: =COUNTIF($I$4:$P$93,AM26) -> 0 | AR26: =COUNTIF($Q$4:$X$93,AM26) -> 0 | AS26: =COUNTIF($Y$4:$AF$93,AM26) -> 0 | AT26: =AQ26+AR26+AS26 -> 0 | AU26: =AQ26*$AO26 -> 0 | AV26: =AR26*$AO26 -> 0 | AW26: =AS26*$AO26 -> 0 | BA26: =AN26*0.8 -> 120
A27: 45571 | B27: 1600 | D27: =(SUM(粮草!A27:X27)+AG27*10*IF(AK27="是",$AY$4,$AY$3)) -> 1752 | E27: =SUM($B$4:B27)+SUM($C$4:C27)-SUM($D$4:D27) -> 1528 | F27: =SUM(经验!A27:X27) -> 635 | G27: =SUM($F$4:F27)+SUM($H$4:H27) -> 16555 | H27: 0 | I27: 空 | J27: 空 | K27: 空 | L27: 空 | M27: 空 | N27: 空 | O27: 空 | P27: 空 | Q27: 5级 | R27: 5级 | S27: 5级 | T27: 2级 | U27: 2级 | V27: 商人 | W27: 空 | X27: 空 | Y27: 6级 | Z27: 6级 | AA27: 6级 | AB27: 6级 | AC27: 6级 | AD27: 6级 | AE27: 空 | AF27: 空 | AG27: =AH27+AI27+AJ27 -> 5 | AI27: 5 | AK27: 是 | AM27: 空 | AN27: 0 | AO27: 0 | AP27: 0 | AU27: =AQ27*$AO27 -> 0 | AV27: =AR27*$AO27 -> 0 | AW27: =AS27*$AO27 -> 0 | BA27: =AN27*0.8 -> 0
A28: 45572 | B28: 1600 | D28: =(SUM(粮草!A28:X28)+AG28*10*IF(AK28="是",$AY$4,$AY$3)) -> 1960 | E28: =SUM($B$4:B28)+SUM($C$4:C28)-SUM($D$4:D28) -> 1168 | F28: =SUM(经验!A28:X28) -> 1220 | G28: =SUM($F$4:F28)+SUM($H$4:H28) -> 17975 | H28: 200 | I28: 空 | J28: 空 | K28: 空 | L28: 空 | M28: 空 | N28: 空 | O28: 空 | P28: 空 | Q28: 2级 | R28: 历练 | S28: 6级 | T28: 6级 | U28: 6级 | V28: 6级 | W28: 6级 | X28: 空 | Y28: 6级 | Z28: 6级 | AA28: 6级 | AB28: 6级 | AC28: 6级 | AD28: 6级 | AE28: 空 | AF28: 空 | AG28: =AH28+AI28+AJ28 -> 4 | AI28: 4 | AK28: 是 | AM28: 作废 | AN28: 0 | AO28: 0 | AQ28: =COUNTIF($I$4:$P$93,AM28) -> 0 | AR28: =COUNTIF($Q$4:$X$93,AM28) -> 0 | AS28: =COUNTIF($Y$4:$AF$93,AM28) -> 0 | AT28: =AQ28+AR28+AS28 -> 0 | AU28: =AQ28*$AO28 -> 0 | AV28: =AR28*$AO28 -> 0 | AW28: =AS28*$AO28 -> 0 | BA28: =AN28*0.8 -> 0
A29: 45573 | B29: 1600 | D29: =(SUM(粮草!A29:X29)+AG29*10*IF(AK29="是",$AY$4,$AY$3)) -> 1800 | E29: =SUM($B$4:B29)+SUM($C$4:C29)-SUM($D$4:D29) -> 968 | F29: =SUM(经验!A29:X29) -> 690 | G29: =SUM($F$4:F29)+SUM($H$4:H29) -> 18765 | H29: 100 | I29: 空 | J29: 空 | K29: 空 | L29: 空 | M29: 空 | N29: 空 | O29: 空 | P29: 空 | Q29: 6级 | R29: 6级 | S29: 6级 | T29: 6级 | U29: 商人 | V29: 6级 | W29: 空 | X29: 空 | Y29: 6级 | Z29: 6级 | AA29: 6级 | AB29: 6级 | AC29: 6级 | AD29: 6级 | AE29: 空 | AF29: 空 | AG29: =AH29+AI29+AJ29 -> 0 | AK29: 是 | AM29: 历练 | AN29: 50 | AO29: 520 | AQ29: =COUNTIF($I$4:$P$93,AM29) -> 0 | AR29: =COUNTIF($Q$4:$X$93,AM29) -> 1 | AS29: =COUNTIF($Y$4:$AF$93,AM29) -> 0 | AT29: =AQ29+AR29+AS29 -> 1 | AU29: =AQ29*$AO29 -> 0 | AV29: =AR29*$AO29 -> 520 | AW29: =AS29*$AO29 -> 0 | BA29: =AN29*0.8 -> 40
A30: 45574 | B30: 1600 | D30: =(SUM(粮草!A30:X30)+AG30*10*IF(AK30="是",$AY$4,$AY$3)) -> 1840 | E30: =SUM($B$4:B30)+SUM($C$4:C30)-SUM($D$4:D30) -> 728 | F30: =SUM(经验!A30:X30) -> 670 | G30: =SUM($F$4:F30)+SUM($H$4:H30) -> 19635 | H30: 200 | I30: 空 | J30: 空 | K30: 空 | L30: 空 | M30: 空 | N30: 空 | O30: 空 | P30: 空 | Q30: 6级 | R30: 6级 | S30: 6级 | T30: 6级 | U30: 6级 | V30: 6级 | W30: 空 | X30: 空 | Y30: 6级 | Z30: 4级 | AA30: 4级 | AB30: 4级 | AC30: 4级 | AD30: 4级 | AE30: 空 | AF30: 空 | AG30: =AH30+AI30+AJ30 -> 0 | AK30: 是
A31: 45575 | B31: 1600 | D31: =(SUM(粮草!A31:X31)+AG31*10*IF(AK31="是",$AY$4,$AY$3)) -> 1628 | E31: =SUM($B$4:B31)+SUM($C$4:C31)-SUM($D$4:D31) -> 700 | F31: =SUM(经验!A31:X31) -> 750 | G31: =SUM($F$4:F31)+SUM($H$4:H31) -> 20385 | H31: 0 | I31: 空 | J31: 空 | K31: 空 | L31: 空 | M31: 空 | N31: 空 | O31: 空 | P31: 空 | Q31: 6级 | R31: 6级 | S31: 6级 | T31: 6级 | U31: 6级 | V31: 6级 | W31: 营地 | X31: 6级 | Y31: 商人 | Z31: 4级 | AA31: 营地 | AB31: 4级 | AC31: 4级 | AD31: 4级 | AE31: 4级 | AF31: 4级 | AG31: =AH31+AI31+AJ31 -> 3 | AJ31: 3 | AK31: 是
A32: 45576 | B32: 1600 | D32: =(SUM(粮草!A32:X32)+AG32*10*IF(AK32="是",$AY$4,$AY$3)) -> 2296 | E32: =SUM($B$4:B32)+SUM($C$4:C32)-SUM($D$4:D32) -> 4 | F32: =SUM(经验!A32:X32) -> 1745 | G32: =SUM($F$4:F32)+SUM($H$4:H32) -> 22130 | H32: 0 | I32: 1级 | J32: 1级 | K32: 商人 | L32: 1级 | M32: 1级 | N32: 1级 | O32: 商人 | P32: 空 | Q32: 6级 | R32: 6级 | S32: 6级 | T32: 6级 | U32: 大boss | V32: 6级 | W32: 6级 | X32: 空 | Y32: 4级 | Z32: 4级 | AA32: 4级 | AB32: 空 | AC32: 空 | AD32: 空 | AE32: 空 | AF32: 空 | AG32: =AH32+AI32+AJ32 -> 3 | AI32: 3 | AK32: 是 | AM32: 地块统计 | AN32: 应占领 | AO32: 缺少 | AP32: 粮草 | AQ32: 经验
A33: 45577 | B33: 1600 | C33: 40 | D33: =(SUM(粮草!A33:X33)+AG33*10*IF(AK33="是",$AY$4,$AY$3)) -> 1636 | E33: =SUM($B$4:B33)+SUM($C$4:C33)-SUM($D$4:D33) -> 8 | F33: =SUM(经验!A33:X33) -> 725 | G33: =SUM($F$4:F33)+SUM($H$4:H33) -> 22855 | H33: 0 | I33: 2级 | J33: 2级 | K33: 2级 | L33: 商人 | M33: 2级 | N33: 2级 | O33: 营地 | P33: 空 | Q33: 6级 | R33: 6级 | S33: 6级 | T33: 6级 | U33: 6级 | V33: 6级 | W33: 营地 | X33: 3级 | Y33: 3级 | Z33: 3级 | AA33: 空 | AB33: 空 | AC33: 空 | AD33: 空 | AE33: 空 | AF33: 空 | AG33: =AH33+AI33+AJ33 -> 1 | AJ33: 1 | AK33: 是 | AM33: 3级 | AN33: 187 | AO33: =AN33-AT6 -> 7 | AP33: =AO33*AN6*0.8 -> 952 | AQ33: =AO33*AO6 -> 315
A34: 45578 | B34: 1600 | D34: =(SUM(粮草!A34:X34)+AG34*10*IF(AK34="是",$AY$4,$AY$3)) -> 1256 | E34: =SUM($B$4:B34)+SUM($C$4:C34)-SUM($D$4:D34) -> 352 | F34: =SUM(经验!A34:X34) -> 435 | G34: =SUM($F$4:F34)+SUM($H$4:H34) -> 23290 | H34: 0 | I34: 空 | J34: 空 | K34: 空 | L34: 空 | M34: 空 | N34: 空 | O34: 空 | P34: 空 | Q34: 3级 | R34: 商人 | S34: 3级 | T34: 塔3 | U34: 3级 | V34: 3级 | W34: 空 | X34: 空 | Y34: 3级 | Z34: 3级 | AA34: 3级 | AB34: 3级 | AC34: 空 | AD34: 空 | AE34: 空 | AF34: 空 | AG34: =AH34+AI34+AJ34 -> 1 | AJ34: 1 | AK34: 是 | AM34: 4级 | AN34: 276 | AO34: =AN34-AT7 -> 172 | AP34: =AO34*AN7*0.8 -> 24768 | AQ34: =AO34*AO7 -> 8600
A35: 45579 | B35: 1600 | D35: =(SUM(粮草!A35:X35)+AG35*10*IF(AK35="是",$AY$4,$AY$3)) -> 1680 | E35: =SUM($B$4:B35)+SUM($C$4:C35)-SUM($D$4:D35) -> 272 | F35: =SUM(经验!A35:X35) -> 615 | G35: =SUM($F$4:F35)+SUM($H$4:H35) -> 24105 | H35: 200 | I35: 空 | J35: 空 | K35: 空 | L35: 空 | M35: 空 | N35: 空 | O35: 空 | P35: 空 | Q35: 6级 | R35: 6级 | S35: 6级 | T35: 6级 | U35: 6级 | V35: 6级 | W35: 空 | X35: 空 | Y35: 3级 | Z35: 3级 | AA35: 3级 | AB35: 3级 | AC35: 3级 | AD35: 商人 | AE35: 空 | AF35: 空 | AG35: =AH35+AI35+AJ35 -> 0 | AK35: 是 | AM35: 5级 | AN35: 238 | AO35: =AN35-AT8 -> 207 | AP35: =AO35*AN8*0.8 -> 31464 | AQ35: =AO35*AO8 -> 11385
A36: 45580 | B36: 1600 | D36: =(SUM(粮草!A36:X36)+AG36*10*IF(AK36="是",$AY$4,$AY$3)) -> 1640 | E36: =SUM($B$4:B36)+SUM($C$4:C36)-SUM($D$4:D36) -> 232 | F36: =SUM(经验!A36:X36) -> 585 | G36: =SUM($F$4:F36)+SUM($H$4:H36) -> 24790 | H36: 100 | I36: 空 | J36: 空 | K36: 空 | L36: 空 | M36: 空 | N36: 空 | O36: 空 | P36: 空 | Q36: 6级 | R36: 6级 | S36: 6级 | T36: 6级 | U36: 6级 | V36: 6级 | W36: 空 | X36: 空 | Y36: 3级 | Z36: 3级 | AA36: 3级 | AB36: 3级 | AC36: 3级 | AD36: 空 | AE36: 空 | AF36: 空 | AG36: =AH36+AI36+AJ36 -> 0 | AK36: 是 | AM36: 6级 | AN36: 190 | AO36: =AN36-AT9 -> 92 | AP36: =AO36*AN9*0.8 -> 14720 | AQ36: =AO36*AO9 -> 5520
A37: 45581 | B37: 1600 | D37: =(SUM(粮草!A37:X37)+AG37*10*IF(AK37="是",$AY$4,$AY$3)) -> 1528 | E37: =SUM($B$4:B37)+SUM($C$4:C37)-SUM($D$4:D37) -> 304 | F37: =SUM(经验!A37:X37) -> 555 | G37: =SUM($F$4:F37)+SUM($H$4:H37) -> 25545 | H37: 200 | I37: 空 | J37: 空 | K37: 空 | L37: 空 | M37: 空 | N37: 空 | O37: 空 | P37: 空 | Q37: 6级 | R37: 6级 | S37: 6级 | T37: 6级 | U37: 6级 | V37: 6级 | W37: 空 | X37: 空 | Y37: 3级 | Z37: 4级 | AA37: 4级 | AB37: 4级 | AC37: 空 | AD37: 空 | AE37: 空 | AF37: 空 | AG37: =AH37+AI37+AJ37 -> 0 | AK37: 是 | AM37: 商人 | AN37: 39 | AO37: =AN37-AT17 -> 5 | AP37: =AO37*AN17*0.8 -> 200 | AQ37: =AO37*AO17 -> 150
A38: 45582 | B38: 1600 | D38: =(SUM(粮草!A38:X38)+AG38*10*IF(AK38="是",$AY$4,$AY$3)) -> 1536 | E38: =SUM($B$4:B38)+SUM($C$4:C38)-SUM($D$4:D38) -> 368 | F38: =SUM(经验!A38:X38) -> 520 | G38: =SUM($F$4:F38)+SUM($H$4:H38) -> 26065 | H38: 0 | I38: 空 | J38: 空 | K38: 空 | L38: 空 | M38: 空 | N38: 空 | O38: 空 | P38: 空 | Q38: 3级 | R38: 3级 | S38: 3级 | T38: 3级 | U38: 3级 | V38: 3级 | W38: 空 | X38: 空 | Y38: 4级 | Z38: 4级 | AA38: 4级 | AB38: 4级 | AC38: 4级 | AD38: 空 | AE38: 空 | AF38: 空 | AG38: =AH38+AI38+AJ38 -> 0 | AK38: 是 | AM38: 塔2 | AN38: 2 | AO38: =AN38-AT11 -> 0 | AP38: =AO38*AN11*0.8 -> 0 | AQ38: =AO38*AO11 -> 0
A39: 45583 | B39: 1600 | D39: =(SUM(粮草!A39:X39)+AG39*10*IF(AK39="是",$AY$4,$AY$3)) -> 1696 | E39: =SUM($B$4:B39)+SUM($C$4:C39)-SUM($D$4:D39) -> 272 | F39: =SUM(经验!A39:X39) -> 570 | G39: =SUM($F$4:F39)+SUM($H$4:H39) -> 26635 | H39: 0 | I39: 空 | J39: 空 | K39: 空 | L39: 空 | M39: 空 | N39: 空 | O39: 空 | P39: 空 | Q39: 3级 | R39: 3级 | S39: 3级 | T39: 3级 | U39: 3级 | V39: 3级 | W39: 空 | X39: 空 | Y39: 4级 | Z39: 4级 | AA39: 4级 | AB39: 4级 | AC39: 4级 | AD39: 4级 | AE39: 空 | AF39: 空 | AG39: =AH39+AI39+AJ39 -> 2 | AJ39: 2 | AK39: 是 | AM39: 塔3 | AN39: 5 | AO39: =AN39-AT12 -> 0 | AP39: =AO39*AN12*0.8 -> 0 | AQ39: =AO39*AO12 -> 0
A40: 45584 | B40: 1600 | D40: =(SUM(粮草!A40:X40)+AG40*10*IF(AK40="是",$AY$4,$AY$3)) -> 1504 | E40: =SUM($B$4:B40)+SUM($C$4:C40)-SUM($D$4:D40) -> 368 | F40: =SUM(经验!A40:X40) -> 505 | G40: =SUM($F$4:F40)+SUM($H$4:H40) -> 27140 | H40: 0 | I40: 空 | J40: 空 | K40: 空 | L40: 空 | M40: 空 | N40: 空 | O40: 空 | P40: 空 | Q40: 塔3 | R40: 3级 | S40: 3级 | T40: 3级 | U40: 3级 | V40: 3级 | W40: 空 | X40: 空 | Y40: 4级 | Z40: 4级 | AA40: 3级 | AB40: 3级 | AC40: 3级 | AD40: 空 | AE40: 空 | AF40: 空 | AG40: =AH40+AI40+AJ40 -> 1 | AJ40: 1 | AK40: 是 | AM40: 塔4 | AN40: 3 | AO40: =AN40-AT13 -> 2 | AP40: =AO40*AN13*0.8 -> 240 | AQ40: =AO40*AO13 -> 100
...

Sheet Sheet1
A1: 3级 | B1: 3级 | C1: 3级 | D1: 3级 | E1: 3级 | F1: 3级 | G1: 3级 | H1: 3级 | I1: =J1+K1+L1 -> 0 | M1: 否
A2: 3级 | B2: 3级 | C2: 商人 | D2: 3级 | E2: 3级 | F2: 3级 | G2: 3级 | H2: 3级 | I2: =J2+K2+L2 -> 0 | M2: 否
A3: 3级 | B3: 营地 | C3: 3级 | D3: 3级 | E3: 3级 | F3: 3级 | G3: 2级 | H3: 2级 | I3: =J3+K3+L3 -> 3 | K3: 3 | M3: 是
A4: 2级 | B4: 2级 | C4: 商人 | D4: 2级 | E4: 2级 | F4: 2级 | G4: 2级 | H4: 2级 | I4: =J4+K4+L4 -> 2 | K4: 2 | M4: 是
A5: 2级 | B5: 2级 | C5: 2级 | D5: 2级 | E5: 营地 | F5: 商人 | G5: 2级 | H5: 2级 | I5: =J5+K5+L5 -> 5 | L5: 5 | M5: 是
A6: 2级 | B6: 2级 | C6: 2级 | D6: 商人 | E6: 2级 | F6: 2级 | G6: 2级 | H6: 空 | I6: =J6+K6+L6 -> 5 | K6: 1 | L6: 4 | M6: 是
A7: 1级 | B7: 2级 | C7: 2级 | D7: 2级 | E7: 商人 | F7: 2级 | G7: 空 | H7: 空 | I7: =J7+K7+L7 -> 0 | M7: 是
A8: 2级 | B8: 2级 | C8: 商人 | D8: 2级 | E8: 营地 | F8: 2级 | G8: 2级 | H8: 5级 | I8: =J8+K8+L8 -> 5 | L8: 5 | M8: 是
A9: 6级 | B9: 6级 | C9: 6级 | D9: 6级 | E9: 6级 | F9: 6级 | G9: 空 | H9: 空 | I9: =J9+K9+L9 -> 0 | M9: 是
A10: 6级 | B10: 6级 | C10: 6级 | D10: 营地 | E10: 6级 | F10: 6级 | G10: 6级 | H10: 6级 | I10: =J10+K10+L10 -> 0 | M10: 是
A11: 6级 | B11: 6级 | C11: 6级 | D11: 6级 | E11: 6级 | F11: 6级 | G11: 空 | H11: 空 | I11: =J11+K11+L11 -> 3 | L11: 3 | M11: 是
A12: 6级 | B12: 商人 | C12: 6级 | D12: 6级 | E12: 6级 | F12: 6级 | G12: 空 | H12: 空 | I12: =J12+K12+L12 -> 3 | L12: 3 | M12: 是
A13: 6级 | B13: 6级 | C13: 6级 | D13: 6级 | E13: 6级 | F13: 6级 | G13: 空 | H13: 空 | I13: =J13+K13+L13 -> 0 | M13: 是
A14: 6级 | B14: 6级 | C14: 6级 | D14: 6级 | E14: 6级 | F14: 6级 | G14: 空 | H14: 空 | I14: =J14+K14+L14 -> 5 | K14: 5 | M14: 是
A15: 6级 | B15: 6级 | C15: 6级 | D15: 6级 | E15: 6级 | F15: 6级 | G15: 空 | H15: 空 | I15: =J15+K15+L15 -> 4 | K15: 4 | M15: 是
A16: 6级 | B16: 4级 | C16: 4级 | D16: 4级 | E16: 4级 | F16: 4级 | G16: 空 | H16: 空 | I16: =J16+K16+L16 -> 0 | M16: 是
A17: 商人 | B17: 4级 | C17: 营地 | D17: 4级 | E17: 4级 | F17: 4级 | G17: 4级 | H17: 4级 | I17: =J17+K17+L17 -> 3 | L17: 3 | M17: 是
A18: 4级 | B18: 4级 | C18: 4级 | D18: 3级 | E18: 3级 | F18: 空 | G18: 空 | H18: 空 | I18: =J18+K18+L18 -> 1 | L18: 1 | M18: 是
A19: 空 | B19: 空 | C19: 空 | D19: 空 | E19: 空 | F19: 空 | G19: 空 | H19: 空 | I19: =J19+K19+L19 -> 3 | K19: 3 | M19: 是
A20: 3级 | B20: 3级 | C20: 空 | D20: 空 | E20: 空 | F20: 空 | G20: 空 | H20: 空 | I20: =J20+K20+L20 -> 1 | L20: 1 | M20: 是
A21: 3级 | B21: 3级 | C21: 3级 | D21: 3级 | E21: 3级 | F21: 3级 | G21: 空 | H21: 空 | I21: =J21+K21+L21 -> 0 | M21: 是
A22: 3级 | B22: 3级 | C22: 3级 | D22: 商人 | E22: 3级 | F22: 3级 | G22: 空 | H22: 空 | I22: =J22+K22+L22 -> 0 | M22: 是
A23: 3级 | B23: 3级 | C23: 3级 | D23: 3级 | E23: 4级 | F23: 空 | G23: 空 | H23: 空 | I23: =J23+K23+L23 -> 0 | M23: 是
A24: 4级 | B24: 4级 | C24: 4级 | D24: 4级 | E24: 空 | F24: 空 | G24: 空 | H24: 空 | I24: =J24+K24+L24 -> 0 | M24: 是
A25: 4级 | B25: 4级 | C25: 4级 | D25: 4级 | E25: 4级 | F25: 4级 | G25: 空 | H25: 空 | I25: =J25+K25+L25 -> 2 | L25: 2 | M25: 是
A26: 4级 | B26: 4级 | C26: 4级 | D26: 4级 | E26: 4级 | F26: 3级 | G26: 空 | H26: 空 | I26: =J26+K26+L26 -> 2 | L26: 2 | M26: 是
A27: 3级 | B27: 3级 | C27: 3级 | D27: 3级 | E27: 3级 | F27: 塔3 | G27: 空 | H27: 空 | I27: =J27+K27+L27 -> 0 | M27: 是
A28: 3级 | B28: 3级 | C28: 3级 | D28: 3级 | E28: 商人 | F28: 3级 | G28: 空 | H28: 空 | I28: =J28+K28+L28 -> 0 | M28: 是
A29: 3级 | B29: 3级 | C29: 3级 | D29: 3级 | E29: 3级 | F29: 空 | G29: 空 | H29: 空 | I29: =J29+K29+L29 -> 1 | L29: 1 | M29: 是

Sheet 粮草
A2: 队伍一 风 | C2: 步数 | D2: =COUNTIF(A4:H94,"<>空") -> 728 | E2: (不算跳步和传送) | I2: 队伍二 雷 | K2: 步数 | L2: =COUNTIF(I4:P94,"<>空") -> 728 | M2: (不算跳步和传送) | Q2: 队伍三 | S2: 总步数 | T2: =COUNTIF(Q4:X94,"<>空") -> 728 | U2: (不算跳步和传送) | Y2: 粮草调整
A3: 1 | B3: 2 | C3: 3 | D3: 4 | E3: 5 | F3: 6 | G3: 7 | H3: 8 | I3: 1 | J3: 2 | K3: 3 | L3: 4 | M3: 5 | N3: 6 | O3: 7 | P3: 8 | Q3: 1 | R3: 2 | S3: 3 | T3: 4 | U3: 5 | V3: 6 | W3: 7 | X3: 8
A4: =IF(ISNUMBER(SEARCH("营",'17.04'!I4)),(-$Y4+50*IF('17.04'!$AK4="是",'17.04'!$AY$4,'17.04'!$AY$3)),(VLOOKUP('17.04'!I4,'17.04'!$AM$4:$AO$55,2,FALSE))*IF('17.04'!$AK4="是",'17.04'!$AY$4,'17.04'!$AY$3)) -> 150 | B4: =IF(ISNUMBER(SEARCH("营",'17.04'!J4)),(-$Y4+50*IF('17.04'!$AK4="是",'17.04'!$AY$4,'17.04'!$AY$3)),(VLOOKUP('17.04'!J4,'17.04'!$AM$4:$AO$55,2,FALSE))*IF('17.04'!$AK4="是",'17.04'!$AY$4,'17.04'!$AY$3)) -> 150 | C4: =IF(ISNUMBER(SEARCH("营",'17.04'!K4)),(-$Y4+50*IF('17.04'!$AK4="是",'17.04'!$AY$4,'17.04'!$AY$3)),(VLOOKUP('17.04'!K4,'17.04'!$AM$4:$AO$55,2,FALSE))*IF('17.04'!$AK4="是",'17.04'!$AY$4,'17.04'!$AY$3)) -> 150 | D4: =IF(ISNUMBER(SEARCH("营",'17.04'!L4)),(-$Y4+50*IF('17.04'!$AK4="是",'17.04'!$AY$4,'17.04'!$AY$3)),(VLOOKUP('17.04'!L4,'17.04'!$AM$4:$AO$55,2,FALSE))*IF('17.04'!$AK4="是",'17.04'!$AY$4,'17.04'!$AY$3)) -> 0 | E4: =IF(ISNUMBER(SEARCH("营",'17.04'!M4)),(-$Y4+50*IF('17.04'!$AK4="是",'17.04'!$AY$4,'17.04'!$AY$3)),(VLOOKUP('17.04'!M4,'17.04'!$AM$4:$AO$55,2,FALSE))*IF('17.04'!$AK4="是",'17.04'!$AY$4,'17.04'!$AY$3)) -> 0 | F4: =IF(ISNUMBER(SEARCH("营",'17.04'!N4)),(-$Y4+50*IF('17.04'!$AK4="是",'17.04'!$AY$4,'17.04'!$AY$3)),(VLOOKUP('17.04'!N4,'17.04'!$AM$4:$AO$55,2,FALSE))*IF('17.04'!$AK4="是",'17.04'!$AY$4,'17.04'!$AY$3)) -> 0 | G4: =IF(ISNUMBER(SEARCH("营",'17.04'!O4)),(-$Y4+50*IF('17.04'!$AK4="是",'17.04'!$AY$4,'17.04'!$AY$3)),(VLOOKUP('17.04'!O4,'17.04'!$AM$4:$AO$55,2,FALSE))*IF('17.04'!$AK4="是",'17.04'!$AY$4,'17.04'!$AY$3)) -> 0 | H4: =IF(ISNUMBER(SEARCH("营",'17.04'!P4)),(-$Y4+50*IF('17.04'!$AK4="是",'17.04'!$AY$4,'17.04'!$AY$3)),(VLOOKUP('17.04'!P4,'17.04'!$AM$4:$AO$55,2,FALSE))*IF('17.04'!$AK4="是",'17.04'!$AY$4,'17.04'!$AY$3)) -> 0 | ... X4: =IF(ISNUMBER(SEARCH("营",'17.04'!AF4)),(-$Y4+50*IF('17.04'!$AK4="是",'17.04'!$AY$4,'17.04'!$AY$3)),(VLOOKUP('17.04'!AF4,'17.04'!$AM$4:$AO$55,2,FALSE))*IF('17.04'!$AK4="是",'17.04'!$AY$4,'17.04'!$AY$3)) -> 0 | Y4: 300
A5: =IF(ISNUMBER(SEARCH("营",'17.04'!I5)),(-$Y5+50*IF('17.04'!$AK5="是",'17.04'!$AY$4,'17.04'!$AY$3)),(VLOOKUP('17.04'!I5,'17.04'!$AM$4:$AO$55,2,FALSE))*IF('17.04'!$AK5="是",'17.04'!$AY$4,'17.04'!$AY$3)) -> 0 | B5: =IF(ISNUMBER(SEARCH("营",'17.04'!J5)),(-$Y5+50*IF('17.04'!$AK5="是",'17.04'!$AY$4,'17.04'!$AY$3)),(VLOOKUP('17.04'!J5,'17.04'!$AM$4:$AO$55,2,FALSE))*IF('17.04'!$AK5="是",'17.04'!$AY$4,'17.04'!$AY$3)) -> 0 | C5: =IF(ISNUMBER(SEARCH("营",'17.04'!K5)),(-$Y5+50*IF('17.04'!$AK5="是",'17.04'!$AY$4,'17.04'!$AY$3)),(VLOOKUP('17.04'!K5,'17.04'!$AM$4:$AO$55,2,FALSE))*IF('17.04'!$AK5="是",'17.04'!$AY$4,'17.04'!$AY$3)) -> 0 | D5: =IF(ISNUMBER(SEARCH("营",'17.04'!L5)),(-$Y5+50*IF('17.04'!$AK5="是",'17.04'!$AY$4,'17.04'!$AY$3)),(VLOOKUP('17.04'!L5,'17.04'!$AM$4:$AO$55,2,FALSE))*IF('17.04'!$AK5="是",'17.04'!$AY$4,'17.04'!$AY$3)) -> 0 | E5: =IF(ISNUMBER(SEARCH("营",'17.04'!M5)),(-$Y5+50*IF('17.04'!$AK5="是",'17.04'!$AY$4,'17.04'!$AY$3)),(VLOOKUP('17.04'!M5,'17.04'!$AM$4:$AO$55,2,FALSE))*IF('17.04'!$AK5="是",'17.04'!$AY$4,'17.04'!$AY$3)) -> 0 | F5: =IF(ISNUMBER(SEARCH("营",'17.04'!N5)),(-$Y5+50*IF('17.04'!$AK5="是",'17.04'!$AY$4,'17.04'!$AY$3)),(VLOOKUP('17.04'!N5,'17.04'!$AM$4:$AO$55,2,FALSE))*IF('17.04'!$AK5="是",'17.04'!$AY$4,'17.04'!$AY$3)) -> 0 | G5: =IF(ISNUMBER(SEARCH("营",'17.04'!O5)),(-$Y5+50*IF('17.04'!$AK5="是",'17.04'!$AY$4,'17.04'!$AY$3)),(VLOOKUP('17.04'!O5,'17.04'!$AM$4:$AO$55,2,FALSE))*IF('17.04'!$AK5="是",'17.04'!$AY$4,'17.04'!$AY$3)) -> 0 | H5: =IF(ISNUMBER(SEARCH("营",'17.04'!P5)),(-$Y5+50*IF('17.04'!$AK5="是",'17.04'!$AY$4,'17.04'!$AY$3)),(VLOOKUP('17.04'!P5,'17.04'!$AM$4:$AO$55,2,FALSE))*IF('17.04'!$AK5="是",'17.04'!$AY$4,'17.04'!$AY$3)) -> 0 | ... X5: =IF(ISNUMBER(SEARCH("营",'17.04'!AF5)),(-$Y5+50*IF('17.04'!$AK5="是",'17.04'!$AY$4,'17.04'!$AY$3)),(VLOOKUP('17.04'!AF5,'17.04'!$AM$4:$AO$55,2,FALSE))*IF('17.04'!$AK5="是",'17.04'!$AY$4,'17.04'!$AY$3)) -> 0 | Y5: 300
A6: =IF(ISNUMBER(SEARCH("营",'17.04'!I6)),(-$Y6+50*IF('17.04'!$AK6="是",'17.04'!$AY$4,'17.04'!$AY$3)),(VLOOKUP('17.04'!I6,'17.04'!$AM$4:$AO$55,2,FALSE))*IF('17.04'!$AK6="是",'17.04'!$AY$4,'17.04'!$AY$3)) -> 0 | B6: =IF(ISNUMBER(SEARCH("营",'17.04'!J6)),(-$Y6+50*IF('17.04'!$AK6="是",'17.04'!$AY$4,'17.04'!$AY$3)),(VLOOKUP('17.04'!J6,'17.04'!$AM$4:$AO$55,2,FALSE))*IF('17.04'!$AK6="是",'17.04'!$AY$4,'17.04'!$AY$3)) -> 0 | C6: =IF(ISNUMBER(SEARCH("营",'17.04'!K6)),(-$Y6+50*IF('17.04'!$AK6="是",'17.04'!$AY$4,'17.04'!$AY$3)),(VLOOKUP('17.04'!K6,'17.04'!$AM$4:$AO$55,2,FALSE))*IF('17.04'!$AK6="是",'17.04'!$AY$4,'17.04'!$AY$3)) -> 0 | D6: =IF(ISNUMBER(SEARCH("营",'17.04'!L6)),(-$Y6+50*IF('17.04'!$AK6="是",'17.04'!$AY$4,'17.04'!$AY$3)),(VLOOKUP('17.04'!L6,'17.04'!$AM$4:$AO$55,2,FALSE))*IF('17.04'!$AK6="是",'17.04'!$AY$4,'17.04'!$AY$3)) -> 0 | E6: =IF(ISNUMBER(SEARCH("营",'17.04'!M6)),(-$Y6+50*IF('17.04'!$AK6="是",'17.04'!$AY$4,'17.04'!$AY$3)),(VLOOKUP('17.04'!M6,'17.04'!$AM$4:$AO$55,2,FALSE))*IF('17.04'!$AK6="是",'17.04'!$AY$4,'17.04'!$AY$3)) -> 0 | F6: =IF(ISNUMBER(SEARCH("营",'17.04'!N6)),(-$Y6+50*IF('17.04'!$AK6="是",'17.04'!$AY$4,'17.04'!$AY$3)),(VLOOKUP('17.04'!N6,'17.04'!$AM$4:$AO$55,2,FALSE))*IF('17.04'!$AK6="是",'17.04'!$AY$4,'17.04'!$AY$3)) -> 0 | G6: =IF(ISNUMBER(SEARCH("营",'17.04'!O6)),(-$Y6+50*IF('17.04'!$AK6="是",'17.04'!$AY$4,'17.04'!$AY$3)),(VLOOKUP('17.04'!O6,'17.04'!$AM$4:$AO$55,2,FALSE))*IF('17.04'!$AK6="是",'17.04'!$AY$4,'17.04'!$AY$3)) -> 0 | H6: =IF(ISNUMBER(SEARCH("营",'17.04'!P6)),(-$Y6+50*IF('17.04'!$AK6="是",'17.04'!$AY$4,'17.04'!$AY$3)),(VLOOKUP('17.04'!P6,'17.04'!$AM$4:$AO$55,2,FALSE))*IF('17.04'!$AK6="是",'17.04'!$AY$4,'17.04'!$AY$3)) -> 0 | ... X6: =IF(ISNUMBER(SEARCH("营",'17.04'!AF6)),(-$Y6+50*IF('17.04'!$AK6="是",'17.04'!$AY$4,'17.04'!$AY$3)),(VLOOKUP('17.04'!AF6,'17.04'!$AM$4:$AO$55,2,FALSE))*IF('17.04'!$AK6="是",'17.04'!$AY$4,'17.04'!$AY$3)) -> 0 | Y6: 300
A7: =IF(ISNUMBER(SEARCH("营",'17.04'!I7)),(-$Y7+50*IF('17.04'!$AK7="是",'17.04'!$AY$4,'17.04'!$AY$3)),(VLOOKUP('17.04'!I7,'17.04'!$AM$4:$AO$55,2,FALSE))*IF('17.04'!$AK7="是",'17.04'!$AY$4,'17.04'!$AY$3)) -> 0 | B7: =IF(ISNUMBER(SEARCH("营",'17.04'!J7)),(-$Y7+50*IF('17.04'!$AK7="是",'17.04'!$AY$4,'17.04'!$AY$3)),(VLOOKUP('17.04'!J7,'17.04'!$AM$4:$AO$55,2,FALSE))*IF('17.04'!$AK7="是",'17.04'!$AY$4,'17.04'!$AY$3)) -> 0 | C7: =IF(ISNUMBER(SEARCH("营",'17.04'!K7)),(-$Y7+50*IF('17.04'!$AK7="是",'17.04'!$AY$4,'17.04'!$AY$3)),(VLOOKUP('17.04'!K7,'17.04'!$AM$4:$AO$55,2,FALSE))*IF('17.04'!$AK7="是",'17.04'!$AY$4,'17.04'!$AY$3)) -> 0 | D7: =IF(ISNUMBER(SEARCH("营",'17.04'!L7)),(-$Y7+50*IF('17.04'!$AK7="是",'17.04'!$AY$4,'17.04'!$AY$3)),(VLOOKUP('17.04'!L7,'17.04'!$AM$4:$AO$55,2,FALSE))*IF('17.04'!$AK7="是",'17.04'!$AY$4,'17.04'!$AY$3)) -> 0 | E7: =IF(ISNUMBER(SEARCH("营",'17.04'!M7)),(-$Y7+50*IF('17.04'!$AK7="是",'17.04'!$AY$4,'17.04'!$AY$3)),(VLOOKUP('17.04'!M7,'17.04'!$AM$4:$AO$55,2,FALSE))*IF('17.04'!$AK7="是",'17.04'!$AY$4,'17.04'!$AY$3)) -> 0 | F7: =IF(ISNUMBER(SEARCH("营",'17.04'!N7)),(-$Y7+50*IF('17.04'!$AK7="是",'17.04'!$AY$4,'17.04'!$AY$3)),(VLOOKUP('17.04'!N7,'17.04'!$AM$4:$AO$55,2,FALSE))*IF('17.04'!$AK7="是",'17.04'!$AY$4,'17.04'!$AY$3)) -> 0 | G7: =IF(ISNUMBER(SEARCH("营",'17.04'!O7)),(-$Y7+50*IF('17.04'!$AK7="是",'17.04'!$AY$4,'17.04'!$AY$3)),(VLOOKUP('17.04'!O7,'17.04'!$AM$4:$AO$55,2,FALSE))*IF('17.04'!$AK7="是",'17.04'!$AY$4,'17.04'!$AY$3)) -> 0 | H7: =IF(ISNUMBER(SEARCH("营",'17.04'!P7)),(-$Y7+50*IF('17.04'!$AK7="是",'17.04'!$AY$4,'17.04'!$AY$3)),(VLOOKUP('17.04'!P7,'17.04'!$AM$4:$AO$55,2,FALSE))*IF('17.04'!$AK7="是",'17.04'!$AY$4,'17.04'!$AY$3)) -> 0 | ... X7: =IF(ISNUMBER(SEARCH("营",'17.04'!AF7)),(-$Y7+50*IF('17.04'!$AK7="是",'17.04'!$AY$4,'17.04'!$AY$3)),(VLOOKUP('17.04'!AF7,'17.04'!$AM$4:$AO$55,2,FALSE))*IF('17.04'!$AK7="是",'17.04'!$AY$4,'17.04'!$AY$3)) -> 0 | Y7: 300
A8: =IF(ISNUMBER(SEARCH("营",'17.04'!I8)),(-$Y8+50*IF('17.04'!$AK8="是",'17.04'!$AY$4,'17.04'!$AY$3)),(VLOOKUP('17.04'!I8,'17.04'!$AM$4:$AO$55,2,FALSE))*IF('17.04'!$AK8="是",'17.04'!$AY$4,'17.04'!$AY$3)) -> 0 | B8: =IF(ISNUMBER(SEARCH("营",'17.04'!J8)),(-$Y8+50*IF('17.04'!$AK8="是",'17.04'!$AY$4,'17.04'!$AY$3)),(VLOOKUP('17.04'!J8,'17.04'!$AM$4:$AO$55,2,FALSE))*IF('17.04'!$AK8="是",'17.04'!$AY$4,'17.04'!$AY$3)) -> 0 | C8: =IF(ISNUMBER(SEARCH("营",'17.04'!K8)),(-$Y8+50*IF('17.04'!$AK8="是",'17.04'!$AY$4,'17.04'!$AY$3)),(VLOOKUP('17.04'!K8,'17.04'!$AM$4:$AO$55,2,FALSE))*IF('17.04'!$AK8="是",'17.04'!$AY$4,'17.04'!$AY$3)) -> 0 | D8: =IF(ISNUMBER(SEARCH("营",'17.04'!L8)),(-$Y8+50*IF('17.04'!$AK8="是",'17.04'!$AY$4,'17.04'!$AY$3)),(VLOOKUP('17.04'!L8,'17.04'!$AM$4:$AO$55,2,FALSE))*IF('17.04'!$AK8="是",'17.04'!$AY$4,'17.04'!$AY$3)) -> 0 | E8: =IF(ISNUMBER(SEARCH("营",'17.04'!M8)),(-$Y8+50*IF('17.04'!$AK8="是",'17.04'!$AY$4,'17.04'!$AY$3)),(VLOOKUP('17.04'!M8,'17.04'!$AM$4:$AO$55,2,FALSE))*IF('17.04'!$AK8="是",'17.04'!$AY$4,'17.04'!$AY$3)) -> 0 | F8: =IF(ISNUMBER(SEARCH("营",'17.04'!N8)),(-$Y8+50*IF('17.04'!$AK8="是",'17.04'!$AY$4,'17.04'!$AY$3)),(VLOOKUP('17.04'!N8,'17.04'!$AM$4:$AO$55,2,FALSE))*IF('17.04'!$AK8="是",'17.04'!$AY$4,'17.04'!$AY$3)) -> 0 | G8: =IF(ISNUMBER(SEARCH("营",'17.04'!O8)),(-$Y8+50*IF('17.04'!$AK8="是",'17.04'!$AY$4,'17.04'!$AY$3)),(VLOOKUP('17.04'!O8,'17.04'!$AM$4:$AO$55,2,FALSE))*IF('17.04'!$AK8="是",'17.04'!$AY$4,'17.04'!$AY$3)) -> 0 | H8: =IF(ISNUMBER(SEARCH("营",'17.04'!P8)),(-$Y8+50*IF('17.04'!$AK8="是",'17.04'!$AY$4,'17.04'!$AY$3)),(VLOOKUP('17.04'!P8,'17.04'!$AM$4:$AO$55,2,FALSE))*IF('17.04'!$AK8="是",'17.04'!$AY$4,'17.04'!$AY$3)) -> 0 | ... X8: =IF(ISNUMBER(SEARCH("营",'17.04'!AF8)),(-$Y8+50*IF('17.04'!$AK8="是",'17.04'!$AY$4,'17.04'!$AY$3)),(VLOOKUP('17.04'!AF8,'17.04'!$AM$4:$AO$55,2,FALSE))*IF('17.04'!$AK8="是",'17.04'!$AY$4,'17.04'!$AY$3)) -> 0 | Y8: 300
A9: =IF(ISNUMBER(SEARCH("营",'17.04'!I9)),(-$Y9+50*IF('17.04'!$AK9="是",'17.04'!$AY$4,'17.04'!$AY$3)),(VLOOKUP('17.04'!I9,'17.04'!$AM$4:$AO$55,2,FALSE))*IF('17.04'!$AK9="是",'17.04'!$AY$4,'17.04'!$AY$3)) -> 0 | B9: =IF(ISNUMBER(SEARCH("营",'17.04'!J9)),(-$Y9+50*IF('17.04'!$AK9="是",'17.04'!$AY$4,'17.04'!$AY$3)),(VLOOKUP('17.04'!J9,'17.04'!$AM$4:$AO$55,2,FALSE))*IF('17.04'!$AK9="是",'17.04'!$AY$4,'17.04'!$AY$3)) -> 0 | C9: =IF(ISNUMBER(SEARCH("营",'17.04'!K9)),(-$Y9+50*IF('17.04'!$AK9="是",'17.04'!$AY$4,'17.04'!$AY$3)),(VLOOKUP('17.04'!K9,'17.04'!$AM$4:$AO$55,2,FALSE))*IF('17.04'!$AK9="是",'17.04'!$AY$4,'17.04'!$AY$3)) -> 0 | D9: =IF(ISNUMBER(SEARCH("营",'17.04'!L9)),(-$Y9+50*IF('17.04'!$AK9="是",'17.04'!$AY$4,'17.04'!$AY$3)),(VLOOKUP('17.04'!L9,'17.04'!$AM$4:$AO$55,2,FALSE))*IF('17.04'!$AK9="是",'17.04'!$AY$4,'17.04'!$AY$3)) -> 0 | E9: =IF(ISNUMBER(SEARCH("营",'17.04'!M9)),(-$Y9+50*IF('17.04'!$AK9="是",'17.04'!$AY$4,'17.04'!$AY$3)),(VLOOKUP('17.04'!M9,'17.04'!$AM$4:$AO$55,2,FALSE))*IF('17.04'!$AK9="是",'17.04'!$AY$4,'17.04'!$AY$3)) -> 0 | F9: =IF(ISNUMBER(SEARCH("营",'17.04'!N9)),(-$Y9+50*IF('17.04'!$AK9="是",'17.04'!$AY$4,'17.04'!$AY$3)),(VLOOKUP('17.04'!N9,'17.04'!$AM$4:$AO$55,2,FALSE))*IF('17.04'!$AK9="是",'17.04'!$AY$4,'17.04'!$AY$3)) -> 0 | G9: =IF(ISNUMBER(SEARCH("营",'17.04'!O9)),(-$Y9+50*IF('17.04'!$AK9="是",'17.04'!$AY$4,'17.04'!$AY$3)),(VLOOKUP('17.04'!O9,'17.04'!$AM$4:$AO$55,2,FALSE))*IF('17.04'!$AK9="是",'17.04'!$AY$4,'17.04'!$AY$3)) -> 0 | H9: =IF(ISNUMBER(SEARCH("营",'17.04'!P9)),(-$Y9+50*IF('17.04'!$AK9="是",'17.04'!$AY$4,'17.04'!$AY$3)),(VLOOKUP('17.04'!P9,'17.04'!$AM$4:$AO$55,2,FALSE))*IF('17.04'!$AK9="是",'17.04'!$AY$4,'17.04'!$AY$3)) -> 0 | ... X9: =IF(ISNUMBER(SEARCH("营",'17.04'!AF9)),(-$Y9+50*IF('17.04'!$AK9="是",'17.04'!$AY$4,'17.04'!$AY$3)),(VLOOKUP('17.04'!AF9,'17.04'!$AM$4:$AO$55,2,FALSE))*IF('17.04'!$AK9="是",'17.04'!$AY$4,'17.04'!$AY$3)) -> 0 | Y9: 300
A10: =IF(ISNUMBER(SEARCH("营",'17.04'!I10)),(-$Y10+50*IF('17.04'!$AK10="是",'17.04'!$AY$4,'17.04'!$AY$3)),(VLOOKUP('17.04'!I10,'17.04'!$AM$4:$AO$55,2,FALSE))*IF('17.04'!$AK10="是",'17.04'!$AY$4,'17.04'!$AY$3)) -> 0 | B10: =IF(ISNUMBER(SEARCH("营",'17.04'!J10)),(-$Y10+50*IF('17.04'!$AK10="是",'17.04'!$AY$4,'17.04'!$AY$3)),(VLOOKUP('17.04'!J10,'17.04'!$AM$4:$AO$55,2,FALSE))*IF('17.04'!$AK10="是",'17.04'!$AY$4,'17.04'!$AY$3)) -> 0 | C10: =IF(ISNUMBER(SEARCH("营",'17.04'!K10)),(-$Y10+50*IF('17.04'!$AK10="是",'17.04'!$AY$4,'17.04'!$AY$3)),(VLOOKUP('17.04'!K10,'17.04'!$AM$4:$AO$55,2,FALSE))*IF('17.04'!$AK10="是",'17.04'!$AY$4,'17.04'!$AY$3)) -> 0 | D10: =IF(ISNUMBER(SEARCH("营",'17.04'!L10)),(-$Y10+50*IF('17.04'!$AK10="是",'17.04'!$AY$4,'17.04'!$AY$3)),(VLOOKUP('17.04'!L10,'17.04'!$AM$4:$AO$55,2,FALSE))*IF('17.04'!$AK10="是",'17.04'!$AY$4,'17.04'!$AY$3)) -> 0 | E10: =IF(ISNUMBER(SEARCH("营",'17.04'!M10)),(-$Y10+50*IF('17.04'!$AK10="是",'17.04'!$AY$4,'17.04'!$AY$3)),(VLOOKUP('17.04'!M10,'17.04'!$AM$4:$AO$55,2,FALSE))*IF('17.04'!$AK10="是",'17.04'!$AY$4,'17.04'!$AY$3)) -> 0 | F10: =IF(ISNUMBER(SEARCH("营",'17.04'!N10)),(-$Y10+50*IF('17.04'!$AK10="是",'17.04'!$AY$4,'17.04'!$AY$3)),(VLOOKUP('17.04'!N10,'17.04'!$AM$4:$AO$55,2,FALSE))*IF('17.04'!$AK10="是",'17.04'!$AY$4,'17.04'!$AY$3)) -> 0 | G10: =IF(ISNUMBER(SEARCH("营",'17.04'!O10)),(-$Y10+50*IF('17.04'!$AK10="是",'17.04'!$AY$4,'17.04'!$AY$3)),(VLOOKUP('17.04'!O10,'17.04'!$AM$4:$AO$55,2,FALSE))*IF('17.04'!$AK10="是",'17.04'!$AY$4,'17.04'!$AY$3)) -> 0 | H10: =IF(ISNUMBER(SEARCH("营",'17.04'!P10)),(-$Y10+50*IF('17.04'!$AK10="是",'17.04'!$AY$4,'17.04'!$AY$3)),(VLOOKUP('17.04'!P10,'17.04'!$AM$4:$AO$55,2,FALSE))*IF('17.04'!$AK10="是",'17.04'!$AY$4,'17.04'!$AY$3)) -> 0 | ... X10: =IF(ISNUMBER(SEARCH("营",'17.04'!AF10)),(-$Y10+50*IF('17.04'!$AK10="是",'17.04'!$AY$4,'17.04'!$AY$3)),(VLOOKUP('17.04'!AF10,'17.04'!$AM$4:$AO$55,2,FALSE))*IF('17.04'!$AK10="是",'17.04'!$AY$4,'17.04'!$AY$3)) -> 0 | Y10: 300
A11: =IF(ISNUMBER(SEARCH("营",'17.04'!I11)),(-$Y11+50*IF('17.04'!$AK11="是",'17.04'!$AY$4,'17.04'!$AY$3)),(VLOOKUP('17.04'!I11,'17.04'!$AM$4:$AO$55,2,FALSE))*IF('17.04'!$AK11="是",'17.04'!$AY$4,'17.04'!$AY$3)) -> 0 | B11: =IF(ISNUMBER(SEARCH("营",'17.04'!J11)),(-$Y11+50*IF('17.04'!$AK11="是",'17.04'!$AY$4,'17.04'!$AY$3)),(VLOOKUP('17.04'!J11,'17.04'!$AM$4:$AO$55,2,FALSE))*IF('17.04'!$AK11="是",'17.04'!$AY$4,'17.04'!$AY$3)) -> 0 | C11: =IF(ISNUMBER(SEARCH("营",'17.04'!K11)),(-$Y11+50*IF('17.04'!$AK11="是",'17.04'!$AY$4,'17.04'!$AY$3)),(VLOOKUP('17.04'!K11,'17.04'!$AM$4:$AO$55,2,FALSE))*IF('17.04'!$AK11="是",'17.04'!$AY$4,'17.04'!$AY$3)) -> 0 | D11: =IF(ISNUMBER(SEARCH("营",'17.04'!L11)),(-$Y11+50*IF('17.04'!$AK11="是",'17.04'!$AY$4,'17.04'!$AY$3)),(VLOOKUP('17.04'!L11,'17.04'!$AM$4:$AO$55,2,FALSE))*IF('17.04'!$AK11="是",'17.04'!$AY$4,'17.04'!$AY$3)) -> 0 | E11: =IF(ISNUMBER(SEARCH("营",'17.04'!M11)),(-$Y11+50*IF('17.04'!$AK11="是",'17.04'!$AY$4,'17.04'!$AY$3)),(VLOOKUP('17.04'!M11,'17.04'!$AM$4:$AO$55,2,FALSE))*IF('17.04'!$AK11="是",'17.04'!$AY$4,'17.04'!$AY$3)) -> 0 | F11: =IF(ISNUMBER(SEARCH("营",'17.04'!N11)),(-$Y11+50*IF('17.04'!$AK11="是",'17.04'!$AY$4,'17.04'!$AY$3)),(VLOOKUP('17.04'!N11,'17.04'!$AM$4:$AO$55,2,FALSE))*IF('17.04'!$AK11="是",'17.04'!$AY$4,'17.04'!$AY$3)) -> 0 | G11: =IF(ISNUMBER(SEARCH("营",'17.04'!O11)),(-$Y11+50*IF('17.04'!$AK11="是",'17.04'!$AY$4,'17.04'!$AY$3)),(VLOOKUP('17.04'!O11,'17.04'!$AM$4:$AO$55,2,FALSE))*IF('17.04'!$AK11="是",'17.04'!$AY$4,'17.04'!$AY$3)) -> 0 | H11: =IF(ISNUMBER(SEARCH("营",'17.04'!P11)),(-$Y11+50*IF('17.04'!$AK11="是",'17.04'!$AY$4,'17.04'!$AY$3)),(VLOOKUP('17.04'!P11,'17.04'!$AM$4:$AO$55,2,FALSE))*IF('17.04'!$AK11="是",'17.04'!$AY$4,'17.04'!$AY$3)) -> 0 | ... X11: =IF(ISNUMBER(SEARCH("营",'17.04'!AF11)),(-$Y11+50*IF('17.04'!$AK11="是",'17.04'!$AY$4,'17.04'!$AY$3)),(VLOOKUP('17.04'!AF11,'17.04'!$AM$4:$AO$55,2,FALSE))*IF('17.04'!$AK11="是",'17.04'!$AY$4,'17.04'!$AY$3)) -> 0 | Y11: 300
A12: =IF(ISNUMBER(SEARCH("营",'17.04'!I12)),(-$Y12+50*IF('17.04'!$AK12="是",'17.04'!$AY$4,'17.04'!$AY$3)),(VLOOKUP('17.04'!I12,'17.04'!$AM$4:$AO$55,2,FALSE))*IF('17.04'!$AK12="是",'17.04'!$AY$4,'17.04'!$AY$3)) -> 0 | B12: =IF(ISNUMBER(SEARCH("营",'17.04'!J12)),(-$Y12+50*IF('17.04'!$AK12="是",'17.04'!$AY$4,'17.04'!$AY$3)),(VLOOKUP('17.04'!J12,'17.04'!$AM$4:$AO$55,2,FALSE))*IF('17.04'!$AK12="是",'17.04'!$AY$4,'17.04'!$AY$3)) -> 0 | C12: =IF(ISNUMBER(SEARCH("营",'17.04'!K12)),(-$Y12+50*IF('17.04'!$AK12="是",'17.04'!$AY$4,'17.04'!$AY$3)),(VLOOKUP('17.04'!K12,'17.04'!$AM$4:$AO$55,2,FALSE))*IF('17.04'!$AK12="是",'17.04'!$AY$4,'17.04'!$AY$3)) -> 0 | D12: =IF(ISNUMBER(SEARCH("营",'17.04'!L12)),(-$Y12+50*IF('17.04'!$AK12="是",'17.04'!$AY$4,'17.04'!$AY$3)),(VLOOKUP('17.04'!L12,'17.04'!$AM$4:$AO$55,2,FALSE))*IF('17.04'!$AK12="是",'17.04'!$AY$4,'17.04'!$AY$3)) -> 0 | E12: =IF(ISNUMBER(SEARCH("营",'17.04'!M12)),(-$Y12+50*IF('17.04'!$AK12="是",'17.04'!$AY$4,'17.04'!$AY$3)),(VLOOKUP('17.04'!M12,'17.04'!$AM$4:$AO$55,2,FALSE))*IF('17.04'!$AK12="是",'17.04'!$AY$4,'17.04'!$AY$3)) -> 0 | F12: =IF(ISNUMBER(SEARCH("营",'17.04'!N12)),(-$Y12+50*IF('17.04'!$AK12="是",'17.04'!$AY$4,'17.04'!$AY$3)),(VLOOKUP('17.04'!N12,'17.04'!$AM$4:$AO$55,2,FALSE))*IF('17.04'!$AK12="是",'17.04'!$AY$4,'17.04'!$AY$3)) -> 0 | G12: =IF(ISNUMBER(SEARCH("营",'17.04'!O12)),(-$Y12+50*IF('17.04'!$AK12="是",'17.04'!$AY$4,'17.04'!$AY$3)),(VLOOKUP('17.04'!O12,'17.04'!$AM$4:$AO$55,2,FALSE))*IF('17.04'!$AK12="是",'17.04'!$AY$4,'17.04'!$AY$3)) -> 0 | H12: =IF(ISNUMBER(SEARCH("营",'17.04'!P12)),(-$Y12+50*IF('17.04'!$AK12="是",'17.04'!$AY$4,'17.04'!$AY$3)),(VLOOKUP('17.04'!P12,'17.04'!$AM$4:$AO$55,2,FALSE))*IF('17.04'!$AK12="是",'17.04'!$AY$4,'17.04'!$AY$3)) -> 0 | ... X12: =IF(ISNUMBER(SEARCH("营",'17.04'!AF12)),(-$Y12+50*IF('17.04'!$AK12="是",'17.04'!$AY$4,'17.04'!$AY$3)),(VLOOKUP('17.04'!AF12,'17.04'!$AM$4:$AO$55,2,FALSE))*IF('17.04'!$AK12="是",'17.04'!$AY$4,'17.04'!$AY$3)) -> 0 | Y12: 300
A13: =IF(ISNUMBER(SEARCH("营",'17.04'!I13)),(-$Y13+50*IF('17.04'!$AK13="是",'17.04'!$AY$4,'17.04'!$AY$3)),(VLOOKUP('17.04'!I13,'17.04'!$AM$4:$AO$55,2,FALSE))*IF('17.04'!$AK13="是",'17.04'!$AY$4,'17.04'!$AY$3)) -> 0 | B13: =IF(ISNUMBER(SEARCH("营",'17.04'!J13)),(-$Y13+50*IF('17.04'!$AK13="是",'17.04'!$AY$4,'17.04'!$AY$3)),(VLOOKUP('17.04'!J13,'17.04'!$AM$4:$AO$55,2,FALSE))*IF('17.04'!$AK13="是",'17.04'!$AY$4,'17.04'!$AY$3)) -> 0 | C13: =IF(ISNUMBER(SEARCH("营",'17.04'!K13)),(-$Y13+50*IF('17.04'!$AK13="是",'17.04'!$AY$4,'17.04'!$AY$3)),(VLOOKUP('17.04'!K13,'17.04'!$AM$4:$AO$55,2,FALSE))*IF('17.04'!$AK13="是",'17.04'!$AY$4,'17.04'!$AY$3)) -> 0 | D13: =IF(ISNUMBER(SEARCH("营",'17.04'!L13)),(-$Y13+50*IF('17.04'!$AK13="是",'17.04'!$AY$4,'17.04'!$AY$3)),(VLOOKUP('17.04'!L13,'17.04'!$AM$4:$AO$55,2,FALSE))*IF('17.04'!$AK13="是",'17.04'!$AY$4,'17.04'!$AY$3)) -> 0 | E13: =IF(ISNUMBER(SEARCH("营",'17.04'!M13)),(-$Y13+50*IF('17.04'!$AK13="是",'17.04'!$AY$4,'17.04'!$AY$3)),(VLOOKUP('17.04'!M13,'17.04'!$AM$4:$AO$55,2,FALSE))*IF('17.04'!$AK13="是",'17.04'!$AY$4,'17.04'!$AY$3)) -> 0 | F13: =IF(ISNUMBER(SEARCH("营",'17.04'!N13)),(-$Y13+50*IF('17.04'!$AK13="是",'17.04'!$AY$4,'17.04'!$AY$3)),(VLOOKUP('17.04'!N13,'17.04'!$AM$4:$AO$55,2,FALSE))*IF('17.04'!$AK13="是",'17.04'!$AY$4,'17.04'!$AY$3)) -> 0 | G13: =IF(ISNUMBER(SEARCH("营",'17.04'!O13)),(-$Y13+50*IF('17.04'!$AK13="是",'17.04'!$AY$4,'17.04'!$AY$3)),(VLOOKUP('17.04'!O13,'17.04'!$AM$4:$AO$55,2,FALSE))*IF('17.04'!$AK13="是",'17.04'!$AY$4,'17.04'!$AY$3)) -> 0 | H13: =IF(ISNUMBER(SEARCH("营",'17.04'!P13)),(-$Y13+50*IF('17.04'!$AK13="是",'17.04'!$AY$4,'17.04'!$AY$3)),(VLOOKUP('17.04'!P13,'17.04'!$AM$4:$AO$55,2,FALSE))*IF('17.04'!$AK13="是",'17.04'!$AY$4,'17.04'!$AY$3)) -> 0 | ... X13: =IF(ISNUMBER(SEARCH("营",'17.04'!AF13)),(-$Y13+50*IF('17.04'!$AK13="是",'17.04'!$AY$4,'17.04'!$AY$3)),(VLOOKUP('17.04'!AF13,'17.04'!$AM$4:$AO$55,2,FALSE))*IF('17.04'!$AK13="是",'17.04'!$AY$4,'17.04'!$AY$3)) -> 0 | Y13: 300
A14: =IF(ISNUMBER(SEARCH("营",'17.04'!I14)),(-$Y14+50*IF('17.04'!$AK14="是",'17.04'!$AY$4,'17.04'!$AY$3)),(VLOOKUP('17.04'!I14,'17.04'!$AM$4:$AO$55,2,FALSE))*IF('17.04'!$AK14="是",'17.04'!$AY$4,'17.04'!$AY$3)) -> 0 | B14: =IF(ISNUMBER(SEARCH("营",'17.04'!J14)),(-$Y14+50*IF('17.04'!$AK14="是",'17.04'!$AY$4,'17.04'!$AY$3)),(VLOOKUP('17.04'!J14,'17.04'!$AM$4:$AO$55,2,FALSE))*IF('17.04'!$AK14="是",'17.04'!$AY$4,'17.04'!$AY$3)) -> 0 | C14: =IF(ISNUMBER(SEARCH("营",'17.04'!K14)),(-$Y14+50*IF('17.04'!$AK14="是",'17.04'!$AY$4,'17.04'!$AY$3)),(VLOOKUP('17.04'!K14,'17.04'!$AM$4:$AO$55,2,FALSE))*IF('17.04'!$AK14="是",'17.04'!$AY$4,'17.04'!$AY$3)) -> 0 | D14: =IF(ISNUMBER(SEARCH("营",'17.04'!L14)),(-$Y14+50*IF('17.04'!$AK14="是",'17.04'!$AY$4,'17.04'!$AY$3)),(VLOOKUP('17.04'!L14,'17.04'!$AM$4:$AO$55,2,FALSE))*IF('17.04'!$AK14="是",'17.04'!$AY$4,'17.04'!$AY$3)) -> 0 | E14: =IF(ISNUMBER(SEARCH("营",'17.04'!M14)),(-$Y14+50*IF('17.04'!$AK14="是",'17.04'!$AY$4,'17.04'!$AY$3)),(VLOOKUP('17.04'!M14,'17.04'!$AM$4:$AO$55,2,FALSE))*IF('17.04'!$AK14="是",'17.04'!$AY$4,'17.04'!$AY$3)) -> 0 | F14: =IF(ISNUMBER(SEARCH("营",'17.04'!N14)),(-$Y14+50*IF('17.04'!$AK14="是",'17.04'!$AY$4,'17.04'!$AY$3)),(VLOOKUP('17.04'!N14,'17.04'!$AM$4:$AO$55,2,FALSE))*IF('17.04'!$AK14="是",'17.04'!$AY$4,'17.04'!$AY$3)) -> 0 | G14: =IF(ISNUMBER(SEARCH("营",'17.04'!O14)),(-$Y14+50*IF('17.04'!$AK14="是",'17.04'!$AY$4,'17.04'!$AY$3)),(VLOOKUP('17.04'!O14,'17.04'!$AM$4:$AO$55,2,FALSE))*IF('17.04'!$AK14="是",'17.04'!$AY$4,'17.04'!$AY$3)) -> 0 | H14: =IF(ISNUMBER(SEARCH("营",'17.04'!P14)),(-$Y14+50*IF('17.04'!$AK14="是",'17.04'!$AY$4,'17.04'!$AY$3)),(VLOOKUP('17.04'!P14,'17.04'!$AM$4:$AO$55,2,FALSE))*IF('17.04'!$AK14="是",'17.04'!$AY$4,'17.04'!$AY$3)) -> 0 | ... X14: =IF(ISNUMBER(SEARCH("营",'17.04'!AF14)),(-$Y14+50*IF('17.04'!$AK14="是",'17.04'!$AY$4,'17.04'!$AY$3)),(VLOOKUP('17.04'!AF14,'17.04'!$AM$4:$AO$55,2,FALSE))*IF('17.04'!$AK14="是",'17.04'!$AY$4,'17.04'!$AY$3)) -> 170 | Y14: 300
A15: =IF(ISNUMBER(SEARCH("营",'17.04'!I15)),(-$Y15+50*IF('17.04'!$AK15="是",'17.04'!$AY$4,'17.04'!$AY$3)),(VLOOKUP('17.04'!I15,'17.04'!$AM$4:$AO$55,2,FALSE))*IF('17.04'!$AK15="是",'17.04'!$AY$4,'17.04'!$AY$3)) -> 0 | B15: =IF(ISNUMBER(SEARCH("营",'17.04'!J15)),(-$Y15+50*IF('17.04'!$AK15="是",'17.04'!$AY$4,'17.04'!$AY$3)),(VLOOKUP('17.04'!J15,'17.04'!$AM$4:$AO$55,2,FALSE))*IF('17.04'!$AK15="是",'17.04'!$AY$4,'17.04'!$AY$3)) -> 0 | C15: =IF(ISNUMBER(SEARCH("营",'17.04'!K15)),(-$Y15+50*IF('17.04'!$AK15="是",'17.04'!$AY$4,'17.04'!$AY$3)),(VLOOKUP('17.04'!K15,'17.04'!$AM$4:$AO$55,2,FALSE))*IF('17.04'!$AK15="是",'17.04'!$AY$4,'17.04'!$AY$3)) -> 0 | D15: =IF(ISNUMBER(SEARCH("营",'17.04'!L15)),(-$Y15+50*IF('17.04'!$AK15="是",'17.04'!$AY$4,'17.04'!$AY$3)),(VLOOKUP('17.04'!L15,'17.04'!$AM$4:$AO$55,2,FALSE))*IF('17.04'!$AK15="是",'17.04'!$AY$4,'17.04'!$AY$3)) -> 0 | E15: =IF(ISNUMBER(SEARCH("营",'17.04'!M15)),(-$Y15+50*IF('17.04'!$AK15="是",'17.04'!$AY$4,'17.04'!$AY$3)),(VLOOKUP('17.04'!M15,'17.04'!$AM$4:$AO$55,2,FALSE))*IF('17.04'!$AK15="是",'17.04'!$AY$4,'17.04'!$AY$3)) -> 0 | F15: =IF(ISNUMBER(SEARCH("营",'17.04'!N15)),(-$Y15+50*IF('17.04'!$AK15="是",'17.04'!$AY$4,'17.04'!$AY$3)),(VLOOKUP('17.04'!N15,'17.04'!$AM$4:$AO$55,2,FALSE))*IF('17.04'!$AK15="是",'17.04'!$AY$4,'17.04'!$AY$3)) -> 0 | G15: =IF(ISNUMBER(SEARCH("营",'17.04'!O15)),(-$Y15+50*IF('17.04'!$AK15="是",'17.04'!$AY$4,'17.04'!$AY$3)),(VLOOKUP('17.04'!O15,'17.04'!$AM$4:$AO$55,2,FALSE))*IF('17.04'!$AK15="是",'17.04'!$AY$4,'17.04'!$AY$3)) -> 0 | H15: =IF(ISNUMBER(SEARCH("营",'17.04'!P15)),(-$Y15+50*IF('17.04'!$AK15="是",'17.04'!$AY$4,'17.04'!$AY$3)),(VLOOKUP('17.04'!P15,'17.04'!$AM$4:$AO$55,2,FALSE))*IF('17.04'!$AK15="是",'17.04'!$AY$4,'17.04'!$AY$3)) -> 0 | ... X15: =IF(ISNUMBER(SEARCH("营",'17.04'!AF15)),(-$Y15+50*IF('17.04'!$AK15="是",'17.04'!$AY$4,'17.04'!$AY$3)),(VLOOKUP('17.04'!AF15,'17.04'!$AM$4:$AO$55,2,FALSE))*IF('17.04'!$AK15="是",'17.04'!$AY$4,'17.04'!$AY$3)) -> 170 | Y15: 300
... A93: =IF(ISNUMBER(SEARCH("营",'17.04'!I93)),(-$Y93+50*IF('17.04'!$AK93="是",'17.04'!$AY$4,'17.04'!$AY$3)),(VLOOKUP('17.04'!I93,'17.04'!$AM$4:$AO$55,2,FALSE))*IF('17.04'!$AK93="是",'17.04'!$AY$4,'17.04'!$AY$3)) -> 0 | B93: =IF(ISNUMBER(SEARCH("营",'17.04'!J93)),(-$Y93+50*IF('17.04'!$AK93="是",'17.04'!$AY$4,'17.04'!$AY$3)),(VLOOKUP('17.04'!J93,'17.04'!$AM$4:$AO$55,2,FALSE))*IF('17.04'!$AK93="是",'17.04'!$AY$4,'17.04'!$AY$3)) -> 0 | C93: =IF(ISNUMBER(SEARCH("营",'17.04'!K93)),(-$Y93+50*IF('17.04'!$AK93="是",'17.04'!$AY$4,'17.04'!$AY$3)),(VLOOKUP('17.04'!K93,'17.04'!$AM$4:$AO$55,2,FALSE))*IF('17.04'!$AK93="是",'17.04'!$AY$4,'17.04'!$AY$3)) -> 0 | D93: =IF(ISNUMBER(SEARCH("营",'17.04'!L93)),(-$Y93+50*IF('17.04'!$AK93="是",'17.04'!$AY$4,'17.04'!$AY$3)),(VLOOKUP('17.04'!L93,'17.04'!$AM$4:$AO$55,2,FALSE))*IF('17.04'!$AK93="是",'17.04'!$AY$4,'17.04'!$AY$3)) -> 0 | E93: =IF(ISNUMBER(SEARCH("营",'17.04'!M93)),(-$Y93+50*IF('17.04'!$AK93="是",'17.04'!$AY$4,'17.04'!$AY$3)),(VLOOKUP('17.04'!M93,'17.04'!$AM$4:$AO$55,2,FALSE))*IF('17.04'!$AK93="是",'17.04'!$AY$4,'17.04'!$AY$3)) -> 0 | F93: =IF(ISNUMBER(SEARCH("营",'17.04'!N93)),(-$Y93+50*IF('17.04'!$AK93="是",'17.04'!$AY$4,'17.04'!$AY$3)),(VLOOKUP('17.04'!N93,'17.04'!$AM$4:$AO$55,2,FALSE))*IF('17.04'!$AK93="是",'17.04'!$AY$4,'17.04'!$AY$3)) -> 0 | G93: =IF(ISNUMBER(SEARCH("营",'17.04'!O93)),(-$Y93+50*IF('17.04'!$AK93="是",'17.04'!$AY$4,'17.04'!$AY$3)),(VLOOKUP('17.04'!O93,'17.04'!$AM$4:$AO$55,2,FALSE))*IF('17.04'!$AK93="是",'17.04'!$AY$4,'17.04'!$AY$3)) -> 0 | H93: =IF(ISNUMBER(SEARCH("营",'17.04'!P93)),(-$Y93+50*IF('17.04'!$AK93="是",'17.04'!$AY$4,'17.04'!$AY$3)),(VLOOKUP('17.04'!P93,'17.04'!$AM$4:$AO$55,2,FALSE))*IF('17.04'!$AK93="是",'17.04'!$AY$4,'17.04'!$AY$3)) -> 0 | ... X93: =IF(ISNUMBER(SEARCH("营",'17.04'!AF93)),(-$Y93+50*IF('17.04'!$AK93="是",'17.04'!$AY$4,'17.04'!$AY$3)),(VLOOKUP('17.04'!AF93,'17.04'!$AM$4:$AO$55,2,FALSE))*IF('17.04'!$AK93="是",'17.04'!$AY$4,'17.04'!$AY$3)) -> 0 | Y93: 100

Sheet 经验
A2: 队伍一 风 | C2: 步数 | D2: =COUNTIF(A4:H94,"<>空") -> 728 | E2: (不算跳步和传送) | I2: 队伍二 雷 | K2: 步数 | L2: =COUNTIF(I4:P94,"<>空") -> 728 | M2: (不算跳步和传送) | Q2: 队伍三 | S2: 总步数 | T2: =COUNTIF(Q4:X94,"<>空") -> 728 | U2: (不算跳步和传送)
A3: 1 | B3: 2 | C3: 3 | D3: 4 | E3: 5 | F3: 6 | G3: 7 | H3: 8 | I3: 1 | J3: 2 | K3: 3 | L3: 4 | M3: 5 | N3: 6 | O3: 7 | P3: 8 | Q3: 1 | R3: 2 | S3: 3 | T3: 4 | U3: 5 | V3: 6 | W3: 7 | X3: 8
A4: =(VLOOKUP('17.04'!I4,'17.04'!$AM$4:$AO$55,3,FALSE)) -> 35 | B4: =(VLOOKUP('17.04'!J4,'17.04'!$AM$4:$AO$55,3,FALSE)) -> 35 | C4: =(VLOOKUP('17.04'!K4,'17.04'!$AM$4:$AO$55,3,FALSE)) -> 35 | D4: =(VLOOKUP('17.04'!L4,'17.04'!$AM$4:$AO$55,3,FALSE)) -> 0 | E4: =(VLOOKUP('17.04'!M4,'17.04'!$AM$4:$AO$55,3,FALSE)) -> 0 | F4: =(VLOOKUP('17.04'!N4,'17.04'!$AM$4:$AO$55,3,FALSE)) -> 0 | G4: =(VLOOKUP('17.04'!O4,'17.04'!$AM$4:$AO$55,3,FALSE)) -> 0 | H4: =(VLOOKUP('17.04'!P4,'17.04'!$AM$4:$AO$55,3,FALSE)) -> 0 | ... X4: =(VLOOKUP('17.04'!AF4,'17.04'!$AM$4:$AO$55,3,FALSE)) -> 0
A5: =(VLOOKUP('17.04'!I5,'17.04'!$AM$4:$AO$55,3,FALSE)) -> 0 | B5: =(VLOOKUP('17.04'!J5,'17.04'!$AM$4:$AO$55,3,FALSE)) -> 0 | C5: =(VLOOKUP('17.04'!K5,'17.04'!$AM$4:$AO$55,3,FALSE)) -> 0 | D5: =(VLOOKUP('17.04'!L5,'17.04'!$AM$4:$AO$55,3,FALSE)) -> 0 | E5: =(VLOOKUP('17.04'!M5,'17.04'!$AM$4:$AO$55,3,FALSE)) -> 0 | F5: =(VLOOKUP('17.04'!N5,'17.04'!$AM$4:$AO$55,3,FALSE)) -> 0 | G5: =(VLOOKUP('17.04'!O5,'17.04'!$AM$4:$AO$55,3,FALSE)) -> 0 | H5: =(VLOOKUP('17.04'!P5,'17.04'!$AM$4:$AO$55,3,FALSE)) -> 0 | ... X5: =(VLOOKUP('17.04'!AF5,'17.04'!$AM$4:$AO$55,3,FALSE)) -> 0
A6: =(VLOOKUP('17.04'!I6,'17.04'!$AM$4:$AO$55,3,FALSE)) -> 0 | B6: =(VLOOKUP('17.04'!J6,'17.04'!$AM$4:$AO$55,3,FALSE)) -> 0 | C6: =(VLOOKUP('17.04'!K6,'17.04'!$AM$4:$AO$55,3,FALSE)) -> 0 | D6: =(VLOOKUP('17.04'!L6,'17.04'!$AM$4:$AO$55,3,FALSE)) -> 0 | E6: =(VLOOKUP('17.04'!M6,'17.04'!$AM$4:$AO$55,3,FALSE)) -> 0 | F6: =(VLOOKUP('17.04'!N6,'17.04'!$AM$4:$AO$55,3,FALSE)) -> 0 | G6: =(VLOOKUP('17.04'!O6,'17.04'!$AM$4:$AO$55,3,FALSE)) -> 0 | H6: =(VLOOKUP('17.04'!P6,'17.04'!$AM$4:$AO$55,3,FALSE)) -> 0 | ... X6: =(VLOOKUP('17.04'!AF6,'17.04'!$AM$4:$AO$55,3,FALSE)) -> 0
A7: =(VLOOKUP('17.04'!I7,'17.04'!$AM$4:$AO$55,3,FALSE)) -> 0 | B7: =(VLOOKUP('17.04'!J7,'17.04'!$AM$4:$AO$55,3,FALSE)) -> 0 | C7: =(VLOOKUP('17.04'!K7,'17.04'!$AM$4:$AO$55,3,FALSE)) -> 0 | D7: =(VLOOKUP('17.04'!L7,'17.04'!$AM$4:$AO$55,3,FALSE)) -> 0 | E7: =(VLOOKUP('17.04'!M7,'17.04'!$AM$4:$AO$55,3,FALSE)) -> 0 | F7: =(VLOOKUP('17.04'!N7,'17.04'!$AM$4:$AO$55,3,FALSE)) -> 0 | G7: =(VLOOKUP('17.04'!O7,'17.04'!$AM$4:$AO$55,3,FALSE)) -> 0 | H7: =(VLOOKUP('17.04'!P7,'17.04'!$AM$4:$AO$55,3,FALSE)) -> 0 | ... X7: =(VLOOKUP('17.04'!AF7,'17.04'!$AM$4:$AO$55,3,FALSE)) -> 0
