Workbook

Sheet 18.04
A1: =(_xlfn.DAYS(TODAY(),A4)+2)/((_xlfn.DAYS(A93,A4))+1) -> 0.044444444 | I1: 工作区
A2: 18.04 | B2: 八卦前亏 | C2: =SUM(D4:D15) -> 24512 | D2: 合计经验 | F2: =SUM(F4:F93)+SUM(H4:H93) -> 64950 | I2: 队伍一 火 | K2: 步数 | L2: =COUNTIF(I4:P93,"<>空") -> 495 | M2: (不算跳步和传送) | Q2: 队伍二 雷 | S2: 步数 | T2: =COUNTIF(Q4:X93,"<>空") -> 473 | U2: (不算跳步和传送) | Y2: 队伍三 | AA2: 总步数 | AB2: =COUNTIF(Y4:AF93,"<>空") -> 101 | AC2: (不算跳步和传送) | AG2: =SUM(AG4:AG93) -> 58 | AH2: =SUM(AH4:AH93) -> 19 | AI2: =SUM(AI4:AI93) -> 25 | AJ2: =SUM(AJ4:AJ93) -> 14 | AK2: 八卦全开 | AS2: 总地块 | AT2: =SUM(AT4:AT29) -> 1069 | AU2: 剩余粮草 | AV2: =AP47 -> 2 | AW2: 总经验 | AX2: =SUM(AV4:AX29)+7000 -> 64950 | AZ2: 粮草系数
A3: 日期 | B3: 获得粮草 | C3: 粮草调整 | D3: 消耗粮草 | E3: 剩余粮草 | F3: 获得经验 | G3: 累计经验 | H3: 任务经验 | I3: 1 | J3: 2 | K3: 3 | L3: 4 | M3: 5 | N3: 6 | O3: 7 | P3: 8 | Q3: 1 | R3: 2 | S3: 3 | T3: 4 | U3: 5 | V3: 6 | W3: 7 | X3: 8 | Y3: 1 | Z3: 2 | AA3: 3 | AB3: 4 | AC3: 5 | AD3: 6 | AE3: 7 | AF3: 8 | AG3: 跳步次数 | AH3: 1队跳步 | AI3: 2队跳步 | AJ3: 3队跳步 | AM3: 地块 | AN3: 粮草 | AO3: 经验 | AP3: 八卦前亏损 | AQ3: 一队地块 | AR3: 二队地块 | AS3: 三队地块 | AT3: 总地块 | AV3: 一队经验 | AW3: 二队经验 | AX3: 三队经验 | AY3: 八卦前 | AZ3: 1
A4: 45639 | B4: 800 | C4: 4800 | D4: =(SUM(粮草!A4:X4)+AG4*10*IF(AK4="是",$AZ$4,$AZ$3)) -> 1550 | E4: =SUM($B$4:B4)+SUM($C$4:C4)-SUM($D$4:D4) -> 4050 | F4: =SUM(经验!A4:X4) -> 380 | G4: =SUM($F$4:F4)+SUM($H$4:H4) -> 880 | H4: 500 | I4: 1级 | J4: 1级 | K4: 1级 | L4: 1级 | M4: 1级 | N4: 空 | O4: 空 | P4: 空 | Q4: 商人 | R4: 1级 | S4: 1级 | T4: 1级 | U4: 1级 | V4: 1级 | W4: 空 | X4: 空 | Y4: 空 | Z4: 空 | AA4: 空 | AB4: 空 | AC4: 空 | AD4: 空 | AE4: 空 | AF4: 空 | AG4: =AH4+AI4+AJ4 -> 0 | AK4: 否 | AL4: =SUM(AI5:AJ10) -> 26 | AM4: 1级 | AN4: 150 | AO4: 35 | AP4: 44.222109 | AQ4: =COUNTIF($I$4:$P$93,AM4) -> 22 | AR4: =COUNTIF($Q$4:$X$93,AM4) -> 6 | AS4: =COUNTIF($Y$4:$AF$93,AM4) -> 1 | AT4: =AQ4+AR4+AS4 -> 29 | AU4: 30 | AV4: =AQ4*$AO4 -> 770 | AW4: =AR4*$AO4 -> 210 | AX4: =AS4*$AO4 -> 35 | AY4: 八卦后 | AZ4: 0.8 | BB4: =AN4*0.8 -> 120
A5: 45640 | B5: 1600 | C5: 1200 | D5: =(SUM(粮草!A5:X5)+AG5*10*IF(AK5="是",$AZ$4,$AZ$3)) -> 1690 | E5: =SUM($B$4:B5)+SUM($C$4:C5)-SUM($D$4:D5) -> 5160 | F5: =SUM(经验!A5:X5) -> 490 | G5: =SUM($F$4:F5)+SUM($H$4:H5) -> 1370 | H5: 0 | I5: 空 | J5: 空 | K5: 空 | L5: 空 | M5: 空 | N5: 空 | O5: 空 | P5: 空 | Q5: 1级 | R5: 2级 | S5: 2级 | T5: 2级 | U5: 2级 | V5: 2级 | W5: 空 | X5: 空 | Y5: 商人 | Z5: 1级 | AA5: 商人 | AB5: 2级 | AC5: 2级 | AD5: 2级 | AE5: 营地 | AF5: 2级 | AG5: =AH5+AI5+AJ5 -> 10 | AI5: 6 | AJ5: 4 | AK5: 否 | AM5: 2级 | AN5: 160 | AO5: 40 | AP5: 39.110982 | AQ5: =COUNTIF($I$4:$P$93,AM5) -> 20 | AR5: =COUNTIF($Q$4:$X$93,AM5) -> 11 | AS5: =COUNTIF($Y$4:$AF$93,AM5) -> 17 | AT5: =AQ5+AR5+AS5 -> 48 | AU5: 54 | AV5: =AQ5*$AO5 -> 800 | AW5: =AR5*$AO5 -> 440 | AX5: =AS5*$AO5 -> 680 | AY5: Note：开完八卦当天可能需要手动计算粮草 | BB5: =AN5*0.8 -> 128
A6: 45641 | B6: 1600 | D6: =(SUM(粮草!A6:X6)+AG6*10*IF(AK6="是",$AZ$4,$AZ$3)) -> 2010 | E6: =SUM($B$4:B6)+SUM($C$4:C6)-SUM($D$4:D6) -> 4750 | F6: =SUM(经验!A6:X6) -> 540 | G6: =SUM($F$4:F6)+SUM($H$4:H6) -> 1910 | H6: 0 | I6: 空 | J6: 空 | K6: 空 | L6: 空 | M6: 空 | N6: 空 | O6: 空 | P6: 空 | Q6: 2级 | R6: 商人 | S6: 2级 | T6: 2级 | U6: 塔2 | V6: 2级 | W6: 空 | X6: 空 | Y6: 2级 | Z6: 2级 | AA6: 商人 | AB6: 2级 | AC6: 2级 | AD6: 2级 | AE6: 2级 | AF6: 2级 | AG6: =AH6+AI6+AJ6 -> 0 | AI6: 0 | AK6: 否 | AM6: 3级 | AN6: 170 | AO6: 45 | AP6: 34 | AQ6: =COUNTIF($I$4:$P$93,AM6) -> 147 | AR6: =COUNTIF($Q$4:$X$93,AM6) -> 36 | AS6: =COUNTIF($Y$4:$AF$93,AM6) -> 22 | AT6: =AQ6+AR6+AS6 -> 205 | AU6: 180 | AV6: =AQ6*$AO6 -> 6615 | AW6: =AR6*$AO6 -> 1620 | AX6: =AS6*$AO6 -> 990 | BB6: =AN6*0.8 -> 136
A7: 45642 | B7: 1600 | D7: =(SUM(粮草!A7:X7)+AG7*10*IF(AK7="是",$AZ$4,$AZ$3)) -> 2350 | E7: =SUM($B$4:B7)+SUM($C$4:C7)-SUM($D$4:D7) -> 4000 | F7: =SUM(经验!A7:X7) -> 590 | G7: =SUM($F$4:F7)+SUM($H$4:H7) -> 2700 | H7: 200 | I7: 空 | J7: 空 | K7: 空 | L7: 空 | M7: 空 | N7: 空 | O7: 空 | P7: 空 | Q7: 2级 | R7: 2级 | S7: 3级 | T7: 3级 | U7: 3级 | V7: 3级 | W7: 空 | X7: 空 | Y7: 2级 | Z7: 2级 | AA7: 2级 | AB7: 2级 | AC7: 2级 | AD7: 2级 | AE7: 3级 | AF7: 3级 | AG7: =AH7+AI7+AJ7 -> 5 | AI7: 5 | AK7: 否 | AM7: 4级 | AN7: 180 | AO7: 50 | AP7: 36 | AQ7: =COUNTIF($I$4:$P$93,AM7) -> 256 | AR7: =COUNTIF($Q$4:$X$93,AM7) -> 12 | AS7: =COUNTIF($Y$4:$AF$93,AM7) -> 8 | AT7: =AQ7+AR7+AS7 -> 276 | AU7: 104 | AV7: =AQ7*$AO7 -> 12800 | AW7: =AR7*$AO7 -> 600 | AX7: =AS7*$AO7 -> 400 | BB7: =AN7*0.8 -> 144
A8: 45643 | B8: 1600 | D8: =(SUM(粮草!A8:X8)+AG8*10*IF(AK8="是",$AZ$4,$AZ$3)) -> 2590 | E8: =SUM($B$4:B8)+SUM($C$4:C8)-SUM($D$4:D8) -> 3010 | F8: =SUM(经验!A8:X8) -> 1140 | G8: =SUM($F$4:F8)+SUM($H$4:H8) -> 3940 | H8: 100 | I8: 空 | J8: 空 | K8: 空 | L8: 空 | M8: 空 | N8: 空 | O8: 空 | P8: 空 | Q8: 大卦 | R8: 3级 | S8: 3级 | T8: 3级 | U8: 3级 | V8: 3级 | W8: 空 | X8: 空 | Y8: 3级 | Z8: 大卦 | AA8: 3级 | AB8: 3级 | AC8: 3级 | AD8: 3级 | AE8: 3级卦 | AF8: 3级 | AG8: =AH8+AI8+AJ8 -> 5 | AI8: 5 | AK8: 否 | AM8: 5级 | AN8: 190 | AO8: 55 | AP8: 38 | AQ8: =COUNTIF($I$4:$P$93,AM8) -> 0 | AR8: =COUNTIF($Q$4:$X$93,AM8) -> 222 | AS8: =COUNTIF($Y$4:$AF$93,AM8) -> 12 | AT8: =AQ8+AR8+AS8 -> 234 | AU8: 31 | AV8: =AQ8*$AO8 -> 0 | AW8: =AR8*$AO8 -> 12210 | AX8: =AS8*$AO8 -> 660 | BB8: =AN8*0.8 -> 152
A9: 45644 | B9: 1600 | D9: =(SUM(粮草!A9:X9)+AG9*10*IF(AK9="是",$AZ$4,$AZ$3)) -> 1920 | E9: =SUM($B$4:B9)+SUM($C$4:C9)-SUM($D$4:D9) -> 2690 | F9: =SUM(经验!A9:X9) -> 525 | G9: =SUM($F$4:F9)+SUM($H$4:H9) -> 4665 | H9: 200 | I9: 空 | J9: 空 | K9: 空 | L9: 空 | M9: 空 | N9: 空 | O9: 空 | P9: 空 | Q9: 商人 | R9: 3级 | S9: 3级 | T9: 3级 | U9: 3级 | V9: 3级 | W9: 空 | X9: 空 | Y9: 3级 | Z9: 3级 | AA9: 3级 | AB9: 3级 | AC9: 3级 | AD9: 3级卦 | AE9: 空 | AF9: 空 | AG9: =AH9+AI9+AJ9 -> 0 | AK9: 否 | AM9: 6级 | AN9: 200 | AO9: 60 | AQ9: =COUNTIF($I$4:$P$93,AM9) -> 29 | AR9: =COUNTIF($Q$4:$X$93,AM9) -> 149 | AS9: =COUNTIF($Y$4:$AF$93,AM9) -> 13 | AT9: =AQ9+AR9+AS9 -> 191 | AU9: 98 | AV9: =AQ9*$AO9 -> 1740 | AW9: =AR9*$AO9 -> 8940 | AX9: =AS9*$AO9 -> 780 | BB9: =AN9*0.8 -> 160
A10: 45645 | B10: 1600 | D10: =(SUM(粮草!A10:X10)+AG10*10*IF(AK10="是",$AZ$4,$AZ$3)) -> 3150 | E10: =SUM($B$4:B10)+SUM($C$4:C10)-SUM($D$4:D10) -> 1140 | F10: =SUM(经验!A10:X10) -> 1060 | G10: =SUM($F$4:F10)+SUM($H$4:H10) -> 5725 | H10: 0 | I10: 1级 | J10: 1级 | K10: 1级 | L10: 1级 | M10: 商人 | N10: 1级 | O10: 1级 | P10: 1级 | Q10: 3级卦 | R10: 3级 | S10: 3级 | T10: 大卦 | U10: 3级 | V10: 3级 | W10: 空 | X10: 空 | Y10: 塔3 | Z10: 3级 | AA10: 商人 | AB10: 3级 | AC10: 3级 | AD10: 4级 | AE10: 空 | AF10: 空 | AG10: =AH10+AI10+AJ10 -> 6 | AI10: 3 | AJ10: 3 | AK10: 否 | AM10: 塔1 | AN10: 150 | AO10: 35 | AP10: 44.222109 | AQ10: =COUNTIF($I$4:$P$93,AM10) -> 0 | AR10: =COUNTIF($Q$4:$X$93,AM10) -> 0 | AS10: =COUNTIF($Y$4:$AF$93,AM10) -> 0 | AT10: =AQ10+AR10+AS10 -> 0 | AU10: 0 | AV10: =AQ10*$AO10 -> 0 | AW10: =AR10*$AO10 -> 0 | AX10: =AS10*$AO10 -> 0 | BB10: =AN10*0.8 -> 120
A11: 45646 | B11: 1600 | C11: 446 | D11: =(SUM(粮草!A11:X11)+AG11*10*IF(AK11="是",$AZ$4,$AZ$3)) -> 3060 | E11: =SUM($B$4:B11)+SUM($C$4:C11)-SUM($D$4:D11) -> 126 | F11: =SUM(经验!A11:X11) -> 805 | G11: =SUM($F$4:F11)+SUM($H$4:H11) -> 6530 | H11: 0 | I11: 1级 | J11: 1级 | K11: 商人 | L11: 1级 | M11: 1级 | N11: 1级 | O11: 1级 | P11: 1级 | Q11: 3级 | R11: 商人 | S11: 3级 | T11: 3级 | U11: 3级 | V11: 3级卦 | W11: 空 | X11: 空 | Y11: 4级 | Z11: 3级 | AA11: 3级 | AB11: 3级 | AC11: 3级 | AD11: 3级卦 | AE11: 空 | AF11: 空 | AG11: =AH11+AI11+AJ11 -> 3 | AH11: 3 | AK11: 否 | AM11: 塔2 | AN11: 150 | AO11: 40 | AP11: 29.110982 | AQ11: =COUNTIF($I$4:$P$93,AM11) -> 3 | AR11: =COUNTIF($Q$4:$X$93,AM11) -> 1 | AS11: =COUNTIF($Y$4:$AF$93,AM11) -> 0 | AT11: =AQ11+AR11+AS11 -> 4 | AU11: 2 | AV11: =AQ11*$AO11 -> 120 | AW11: =AR11*$AO11 -> 40 | AX11: =AS11*$AO11 -> 0 | BB11: =AN11*0.8 -> 120
A12: 45647 | B12: 1600 | D12: =(SUM(粮草!A12:X12)+AG12*10*IF(AK12="是",$AZ$4,$AZ$3)) -> 1612 | E12: =SUM($B$4:B12)+SUM($C$4:C12)-SUM($D$4:D12) -> 114 | F12: =SUM(经验!A12:X12) -> 620 | G12: =SUM($F$4:F12)+SUM($H$4:H12) -> 7150 | H12: 0 | I12: 1级 | J12: 1级 | K12: 商人 | L12: 2级 | M12: 2级 | N12: 2级 | O12: 营地 | P12: 2级 | Q12: 3级 | R12: 3级 | S12: 3级 | T12: 塔3 | U12: 3级 | V12: 3级 | W12: 空 | X12: 空 | Y12: 3级 | Z12: 3级 | AA12: 空 | AB12: 空 | AC12: 空 | AD12: 空 | AE12: 空 | AF12: 空 | AG12: =AH12+AI12+AJ12 -> 1 | AH12: 1 | AK12: 是 | AM12: 塔3 | AN12: 150 | AO12: 45 | AP12: 13.999855 | AQ12: =COUNTIF($I$4:$P$93,AM12) -> 0 | AR12: =COUNTIF($Q$4:$X$93,AM12) -> 1 | AS12: =COUNTIF($Y$4:$AF$93,AM12) -> 5 | AT12: =AQ12+AR12+AS12 -> 6 | AU12: 5 | AV12: =AQ12*$AO12 -> 0 | AW12: =AR12*$AO12 -> 45 | AX12: =AS12*$AO12 -> 225 | BB12: =AN12*0.8 -> 120
A13: 45648 | B13: 1600 | C13: 40 | D13: =(SUM(粮草!A13:X13)+AG13*10*IF(AK13="是",$AZ$4,$AZ$3)) -> 1564 | E13: =SUM($B$4:B13)+SUM($C$4:C13)-SUM($D$4:D13) -> 190 | F13: =SUM(经验!A13:X13) -> 1335 | G13: =SUM($F$4:F13)+SUM($H$4:H13) -> 8485 | H13: 0 | I13: 历练 | J13: 1级 | K13: 2级 | L13: 2级 | M13: 2级 | N13: 商人 | O13: 空 | P13: 空 | Q13: 3级 | R13: 3级 | S13: 营地 | T13: 3级 | U13: 3级 | V13: 商人 | W13: 3级 | X13: 3级 | Y13: 塔4 | Z13: 4级 | AA13: 营地 | AB13: 4级 | AC13: 6级 | AD13: 6级 | AE13: 营地 | AF13: 6级 | AG13: =AH13+AI13+AJ13 -> 2 | AH13: 1 | AI13: 1 | AK13: 是 | AM13: 塔4 | AN13: 150 | AO13: 50 | AQ13: =COUNTIF($I$4:$P$93,AM13) -> 0 | AR13: =COUNTIF($Q$4:$X$93,AM13) -> 0 | AS13: =COUNTIF($Y$4:$AF$93,AM13) -> 3 | AT13: =AQ13+AR13+AS13 -> 3 | AU13: 1 | AV13: =AQ13*$AO13 -> 0 | AW13: =AR13*$AO13 -> 0 | AX13: =AS13*$AO13 -> 150 | BB13: =AN13*0.8 -> 120
A14: 45649 | B14: 1600 | D14: =(SUM(粮草!A14:X14)+AG14*10*IF(AK14="是",$AZ$4,$AZ$3)) -> 1528 | E14: =SUM($B$4:B14)+SUM($C$4:C14)-SUM($D$4:D14) -> 262 | F14: =SUM(经验!A14:X14) -> 520 | G14: =SUM($F$4:F14)+SUM($H$4:H14) -> 9305 | H14: 300 | I14: 2级 | J14: 2级 | K14: 塔2 | L14: 2级 | M14: 空 | N14: 空 | O14: 空 | P14: 空 | Q14: 3级 | R14: 4级 | S14: 4级 | T14: 4级 | U14: 4级 | V14: 5级 | W14: 空 | X14: 空 | Y14: 6级 | Z14: 空 | AA14: 空 | AB14: 空 | AC14: 空 | AD14: 空 | AE14: 空 | AF14: 空 | AG14: =AH14+AI14+AJ14 -> 0 | AK14: 是 | AM14: 塔5 | AN14: 150 | AO14: 55 | AQ14: =COUNTIF($I$4:$P$93,AM14) -> 0 | AR14: =COUNTIF($Q$4:$X$93,AM14) -> 0 | AS14: =COUNTIF($Y$4:$AF$93,AM14) -> 3 | AT14: =AQ14+AR14+AS14 -> 3 | AU14: 0 | AV14: =AQ14*$AO14 -> 0 | AW14: =AR14*$AO14 -> 0 | AX14: =AS14*$AO14 -> 165 | BB14: =AN14*0.8 -> 120
A15: 45650 | B15: 1600 | D15: =(SUM(粮草!A15:X15)+AG15*10*IF(AK15="是",$AZ$4,$AZ$3)) -> 1488 | E15: =SUM($B$4:B15)+SUM($C$4:C15)-SUM($D$4:D15) -> 374 | F15: =SUM(经验!A15:X15) -> 730 | G15: =SUM($F$4:F15)+SUM($H$4:H15) -> 10035 | H15: 0 | I15: 2级 | J15: 营地 | K15: 2级 | L15: 2级 | M15: 2级 | N15: 商人 | O15: 空 | P15: 空 | Q15: 5级 | R15: 商人 | S15: 5级 | T15: 5级 | U15: 5级 | V15: 5级 | W15: 营地 | X15: 5级 | Y15: 6级 | Z15: 6级 | AA15: 6级 | AB15: 空 | AC15: 空 | AD15: 空 | AE15: 空 | AF15: 空 | AG15: =AH15+AI15+AJ15 -> 3 | AH15: 3 | AK15: 是 | AM15: 塔6 | AN15: 150 | AO15: 60 | AQ15: =COUNTIF($I$4:$P$93,AM15) -> 0 | AR15: =COUNTIF($Q$4:$X$93,AM15) -> 0 | AS15: =COUNTIF($Y$4:$AF$93,AM15) -> 1 | AT15: =AQ15+AR15+AS15 -> 1 | AU15: 0 | AV15: =AQ15*$AO15 -> 0 | AW15: =AR15*$AO15 -> 0 | AX15: =AS15*$AO15 -> 60 | BB15: =AN15*0.8 -> 120
A16: 45651 | B16: 1600 | C16: 40 | D16: =(SUM(粮草!A16:X16)+AG16*10*IF(AK16="是",$AZ$4,$AZ$3)) -> 1828 | E16: =SUM($B$4:B16)+SUM($C$4:C16)-SUM($D$4:D16) -> 186 | F16: =SUM(经验!A16:X16) -> 1660 | G16: =SUM($F$4:F16)+SUM($H$4:H16) -> 11895 | H16: 200 | I16: 3级 | J16: 3级 | K16: 4级 | L16: 营地 | M16: 4级 | N16: 4级 | O16: 4级 | P16: 空 | Q16: 5级 | R16: 5级 | S16: 4级 | T16: 4级 | U16: 4级 | V16: 4级 | W16: 空 | X16: 空 | Y16: 6级 | Z16: 大boss | AA16: 空 | AB16: 空 | AC16: 空 | AD16: 空 | AE16: 空 | AF16: 空 | AG16: =AH16+AI16+AJ16 -> 0 | AK16: 是 | AM16: 遗迹 | AN16: 150 | AO16: 35 | AP16: 44.222109 | AQ16: =COUNTIF($I$4:$P$93,AM16) -> 0 | AR16: =COUNTIF($Q$4:$X$93,AM16) -> 0 | AS16: =COUNTIF($Y$4:$AF$93,AM16) -> 0 | AT16: =AQ16+AR16+AS16 -> 0 | AU16: 0 | AV16: =AQ16*$AO16 -> 0 | AW16: =AR16*$AO16 -> 0 | AX16: =AS16*$AO16 -> 0 | BB16: =AN16*0.8 -> 120
A17: 45652 | B17: 1600 | D17: =(SUM(粮草!A17:X17)+AG17*10*IF(AK17="是",$AZ$4,$AZ$3)) -> 1560 | E17: =SUM($B$4:B17)+SUM($C$4:C17)-SUM($D$4:D17) -> 226 | F17: =SUM(经验!A17:X17) -> 740 | G17: =SUM($F$4:F17)+SUM($H$4:H17) -> 12635 | H17: 0 | I17: 4级 | J17: 4级 | K17: 4级 | L17: 4级 | M17: 4级 | N17: 6级 | O17: 6级 | P17: 营地 | Q17: 4级 | R17: 4级 | S17: 4级 | T17: 4级 | U17: 营地 | V17: 空 | W17: 空 | X17: 空 | Y17: 6级 | Z17: 6级 | AA17: 4级 | AB17: 空 | AC17: 空 | AD17: 空 | AE17: 空 | AF17: 空 | AG17: =AH17+AI17+AJ17 -> 0 | AK17: 是 | AM17: 商人 | AN17: 50 | AO17: 30 | AP17: 10 | AQ17: =COUNTIF($I$4:$P$93,AM17) -> 10 | AR17: =COUNTIF($Q$4:$X$93,AM17) -> 25 | AS17: =COUNTIF($Y$4:$AF$93,AM17) -> 4 | AT17: =AQ17+AR17+AS17 -> 39 | AU17: 34 | AV17: =AQ17*$AO17 -> 300 | AW17: =AR17*$AO17 -> 750 | AX17: =AS17*$AO17 -> 120 | BB17: =AN17*0.8 -> 40
A18: 45653 | B18: 1600 | D18: =(SUM(粮草!A18:X18)+AG18*10*IF(AK18="是",$AZ$4,$AZ$3)) -> 1464 | E18: =SUM($B$4:B18)+SUM($C$4:C18)-SUM($D$4:D18) -> 362 | F18: =SUM(经验!A18:X18) -> 530 | G18: =SUM($F$4:F18)+SUM($H$4:H18) -> 13165 | H18: 0 | I18: 6级 | J18: 6级 | K18: 6级 | L18: 6级 | M18: 6级 | N18: 6级 | O18: 6级 | P18: 6级 | Q18: 空 | R18: 空 | S18: 空 | T18: 空 | U18: 空 | V18: 空 | W18: 空 | X18: 空 | Y18: 4级 | Z18: 空 | AA18: 空 | AB18: 空 | AC18: 空 | AD18: 空 | AE18: 空 | AF18: 空 | AG18: =AH18+AI18+AJ18 -> 5 | AH18: 5 | AK18: 是 | AM18: 营地 | AN18: -150 | AO18: 0 | AP18: 10 | AQ18: =COUNTIF($I$4:$P$93,AM18) -> 6 | AR18: =COUNTIF($Q$4:$X$93,AM18) -> 5 | AS18: =COUNTIF($Y$4:$AF$93,AM18) -> 4 | AT18: =AQ18+AR18+AS18 -> 15 | AU18: 15 | AV18: =AQ18*$AO18 -> 0 | AW18: =AR18*$AO18 -> 0 | AX18: =AS18*$AO18 -> 0 | BB18: =AN18*0.8 -> -120
A19: 45654 | B19: 1600 | C19: 40 | D19: =(SUM(粮草!A19:X19)+AG19*10*IF(AK19="是",$AZ$4,$AZ$3)) -> 1862 | E19: =SUM($B$4:B19)+SUM($C$4:C19)-SUM($D$4:D19) -> 140 | F19: =SUM(经验!A19:X19) -> 2185 | G19: =SUM($F$4:F19)+SUM($H$4:H19) -> 15350 | H19: 0 | I19: 6级 | J19: 大boss | K19: 6级 | L19: 6级 | M19: 6级 | N19: 6级 | O19: 营地 | P19: 空 | Q19: 3级 | R19: 3级 | S19: 5级 | T19: 5级 | U19: 5级 | V19: 历练 | W19: 5级 | X19: 5级 | Y19: 空 | Z19: 空 | AA19: 空 | AB19: 空 | AC19: 空 | AD19: 空 | AE19: 空 | AF19: 空 | AG19: =AH19+AI19+AJ19 -> 0 | AK19: 是 | AM19: 大卦 | AN19: 250 | AO19: 300 | AQ19: =COUNTIF($I$4:$P$93,AM19) -> 0 | AR19: =COUNTIF($Q$4:$X$93,AM19) -> 2 | AS19: =COUNTIF($Y$4:$AF$93,AM19) -> 1 | AT19: =AQ19+AR19+AS19 -> 3 | AU19: 3 | AV19: =AQ19*$AO19 -> 0 | AW19: =AR19*$AO19 -> 600 | AX19: =AS19*$AO19 -> 300 | BB19: =AN19*0.8 -> 200
A20: 45655 | B20: 1600 | D20: =(SUM(粮草!A20:X20)+AG20*10*IF(AK20="是",$AZ$4,$AZ$3)) -> 1526 | E20: =SUM($B$4:B20)+SUM($C$4:C20)-SUM($D$4:D20) -> 214 | F20: =SUM(经验!A20:X20) -> 640 | G20: =SUM($F$4:F20)+SUM($H$4:H20) -> 15990 | H20: 0 | I20: 6级 | J20: 6级 | K20: 6级 | L20: 6级 | M20: 6级 | N20: 6级 | O20: 6级 | P20: 空 | Q20: 5级 | R20: 5级 | S20: 5级 | T20: 5级 | U20: 营地 | V20: 空 | W20: 空 | X20: 空 | Y20: 空 | Z20: 空 | AA20: 空 | AB20: 空 | AC20: 空 | AD20: 空 | AE20: 空 | AF20: 空 | AG20: =AH20+AI20+AJ20 -> 1 | AH20: 1 | AK20: 是 | AM20: 3级卦 | AN20: 170 | AO20: 45 | AQ20: =COUNTIF($I$4:$P$93,AM20) -> 0 | AR20: =COUNTIF($Q$4:$X$93,AM20) -> 2 | AS20: =COUNTIF($Y$4:$AF$93,AM20) -> 3 | AT20: =AQ20+AR20+AS20 -> 5 | AU20: 5 | AV20: =AQ20*$AO20 -> 0 | AW20: =AR20*$AO20 -> 90 | AX20: =AS20*$AO20 -> 135 | BB20: =AN20*0.8 -> 136
A21: 45656 | B21: 1600 | D21: =(SUM(粮草!A21:X21)+AG21*10*IF(AK21="是",$AZ$4,$AZ$3)) -> 1568 | E21: =SUM($B$4:B21)+SUM($C$4:C21)-SUM($D$4:D21) -> 246 | F21: =SUM(经验!A21:X21) -> 580 | G21: =SUM($F$4:F21)+SUM($H$4:H21) -> 16770 | H21: 200 | I21: 6级 | J21: 6级 | K21: 6级 | L21: 6级 | M21: 6级 | N21: 6级 | O21: 6级 | P21: 空 | Q21: 空 | R21: 空 | S21: 空 | T21: 空 | U21: 空 | V21: 空 | W21: 空 | X21: 空 | Y21: 4级 | Z21: 6级 | AA21: 4级 | AB21: 空 | AC21: 空 | AD21: 空 | AE21: 空 | AF21: 空 | AG21: =AH21+AI21+AJ21 -> 0 | AK21: 是 | AM21: 巨卦 | AN21: 250 | AO21: 400 | AQ21: =COUNTIF($I$4:$P$93,AM21) -> 0 | AR21: =COUNTIF($Q$4:$X$93,AM21) -> 0 | AS21: =COUNTIF($Y$4:$AF$93,AM21) -> 0 | AT21: =AQ21+AR21+AS21 -> 0 | AU21: 0 | AV21: =AQ21*$AO21 -> 0 | AW21: =AR21*$AO21 -> 0 | AX21: =AS21*$AO21 -> 0 | BB21: =AN21*0.8 -> 200
A22: 45657 | B22: 1600 | D22: =(SUM(粮草!A22:X22)+AG22*10*IF(AK22="是",$AZ$4,$AZ$3)) -> 1600 | E22: =SUM($B$4:B22)+SUM($C$4:C22)-SUM($D$4:D22) -> 246 | F22: =SUM(经验!A22:X22) -> 555 | G22: =SUM($F$4:F22)+SUM($H$4:H22) -> 17425 | H22: 100 | I22: 3级 | J22: 3级 | K22: 3级 | L22: 3级 | M22: 3级 | N22: 3级 | O22: 空 | P22: 空 | Q22: 空 | R22: 空 | S22: 空 | T22: 空 | U22: 空 | V22: 空 | W22: 空 | X22: 空 | Y22: 6级 | Z22: 6级 | AA22: 5级 | AB22: 5级 | AC22: 5级 | AD22: 空 | AE22: 空 | AF22: 空 | AG22: =AH22+AI22+AJ22 -> 1 | AH22: 1 | AK22: 是 | AM22: 大boss | AN22: 250 | AO22: 1000 | AQ22: =COUNTIF($I$4:$P$93,AM22) -> 1 | AR22: =COUNTIF($Q$4:$X$93,AM22) -> 0 | AS22: =COUNTIF($Y$4:$AF$93,AM22) -> 1 | AT22: =AQ22+AR22+AS22 -> 2 | AU22: 1 | AV22: =AQ22*$AO22 -> 1000 | AW22: =AR22*$AO22 -> 0 | AX22: =AS22*$AO22 -> 1000 | BB22: =AN22*0.8 -> 200
A23: 45658 | B23: 1600 | D23: =(SUM(粮草!A23:X23)+AG23*10*IF(AK23="是",$AZ$4,$AZ$3)) -> 1600 | E23: =SUM($B$4:B23)+SUM($C$4:C23)-SUM($D$4:D23) -> 246 | F23: =SUM(经验!A23:X23) -> 560 | G23: =SUM($F$4:F23)+SUM($H$4:H23) -> 18185 | H23: 200 | I23: 3级 | J23: 3级 | K23: 3级 | L23: 3级 | M23: 4级 | N23: 空 | O23: 空 | P23: 空 | Q23: 空 | R23: 空 | S23: 空 | T23: 空 | U23: 空 | V23: 空 | W23: 空 | X23: 空 | Y23: 5级 | Z23: 5级 | AA23: 5级 | AB23: 5级 | AC23: 5级 | AD23: 5级 | AE23: 空 | AF23: 空 | AG23: =AH23+AI23+AJ23 -> 0 | AK23: 是 | AM23: 中boss | AN23: 250 | AO23: 500 | AQ23: =COUNTIF($I$4:$P$93,AM23) -> 0 | AR23: =COUNTIF($Q$4:$X$93,AM23) -> 0 | AS23: =COUNTIF($Y$4:$AF$93,AM23) -> 2 | AT23: =AQ23+AR23+AS23 -> 2 | AU23: 0 | AV23: =AQ23*$AO23 -> 0 | AW23: =AR23*$AO23 -> 0 | AX23: =AS23*$AO23 -> 1000 | BB23: =AN23*0.8 -> 200
A24: 45659 | B24: 1600 | D24: =(SUM(粮草!A24:X24)+AG24*10*IF(AK24="是",$AZ$4,$AZ$3)) -> 940 | E24: =SUM($B$4:B24)+SUM($C$4:C24)-SUM($D$4:D24) -> 906 | F24: =SUM(经验!A24:X24) -> 495 | G24: =SUM($F$4:F24)+SUM($H$4:H24) -> 18680 | H24: 0 | I24: 4级 | J24: 商人 | K24: 4级 | L24: 4级 | M24: 4级 | N24: 4级 | O24: 4级 | P24: 营地 | Q24: 空 | R24: 空 | S24: 空 | T24: 空 | U24: 空 | V24: 空 | W24: 空 | X24: 空 | Y24: 5级 | Z24: 5级 | AA24: 5级 | AB24: 营地 | AC24: 空 | AD24: 空 | AE24: 空 | AF24: 空 | AG24: =AH24+AI24+AJ24 -> 0 | AK24: 是 | AM24: 4级卦 | AN24: 180 | AO24: 50 | AP24: 39.110982 | AQ24: =COUNTIF($I$4:$P$93,AM24) -> 0 | AR24: =COUNTIF($Q$4:$X$93,AM24) -> 0 | AS24: =COUNTIF($Y$4:$AF$93,AM24) -> 0 | AT24: =AQ24+AR24+AS24 -> 0 | AU24: 0 | AV24: =AQ24*$AO24 -> 0 | AW24: =AR24*$AO24 -> 0 | AX24: =AS24*$AO24 -> 0 | BB24: =AN24*0.8 -> 144
A25: 45660 | B25: 1600 | D25: =(SUM(粮草!A25:X25)+AG25*10*IF(AK25="是",$AZ$4,$AZ$3)) -> 0 | E25: =SUM($B$4:B25)+SUM($C$4:C25)-SUM($D$4:D25) -> 2506 | F25: =SUM(经验!A25:X25) -> 0 | G25: =SUM($F$4:F25)+SUM($H$4:H25) -> 18680 | H25: 0 | I25: 空 | J25: 空 | K25: 空 | L25: 空 | M25: 空 | N25: 空 | O25: 空 | P25: 空 | Q25: 空 | R25: 空 | S25: 空 | T25: 空 | U25: 空 | V25: 空 | W25: 空 | X25: 空 | Y25: 空 | Z25: 空 | AA25: 空 | AB25: 空 | AC25: 空 | AD25: 空 | AE25: 空 | AF25: 空 | AG25: =AH25+AI25+AJ25 -> 0 | AK25: 是 | AM25: 山中 | AN25: 160 | AO25: 40 | AP25: 39.110982 | AQ25: =COUNTIF($I$4:$P$93,AM25) -> 0 | AR25: =COUNTIF($Q$4:$X$93,AM25) -> 0 | AS25: =COUNTIF($Y$4:$AF$93,AM25) -> 0 | AT25: =AQ25+AR25+AS25 -> 0 | AU25: 0 | AV25: =AQ25*$AO25 -> 0 | AW25: =AR25*$AO25 -> 0 | AX25: =AS25*$AO25 -> 0 | BB25: =AN25*0.8 -> 128
A26: 45661 | B26: 1600 | D26: =(SUM(粮草!A26:X26)+AG26*10*IF(AK26="是",$AZ$4,$AZ$3)) -> 0 | E26: =SUM($B$4:B26)+SUM($C$4:C26)-SUM($D$4:D26) -> 4106 | F26: =SUM(经验!A26:X26) -> 0 | G26: =SUM($F$4:F26)+SUM($H$4:H26) -> 18680 | H26: 0 | I26: 空 | J26: 空 | K26: 空 | L26: 空 | M26: 空 | N26: 空 | O26: 空 | P26: 空 | Q26: 空 | R26: 空 | S26: 空 | T26: 空 | U26: 空 | V26: 空 | W26: 空 | X26: 空 | Y26: 空 | Z26: 空 | AA26: 空 | AB26: 空 | AC26: 空 | AD26: 空 | AE26: 空 | AF26: 空 | AG26: =AH26+AI26+AJ26 -> 0 | AK26: 是 | AM26: 秋道 | AN26: 150 | AO26: 35 | AP26: 44.222109 | AQ26: =COUNTIF($I$4:$P$93,AM26) -> 0 | AR26: =COUNTIF($Q$4:$X$93,AM26) -> 0 | AS26: =COUNTIF($Y$4:$AF$93,AM26) -> 0 | AT26: =AQ26+AR26+AS26 -> 0 | AU26: 0 | AV26: =AQ26*$AO26 -> 0 | AW26: =AR26*$AO26 -> 0 | AX26: =AS26*$AO26 -> 0 | BB26: =AN26*0.8 -> 120
A27: 45662 | B27: 1600 | D27: =(SUM(粮草!A27:X27)+AG27*10*IF(AK27="是",$AZ$4,$AZ$3)) -> 120 | E27: =SUM($B$4:B27)+SUM($C$4:C27)-SUM($D$4:D27) -> 5586 | F27: =SUM(经验!A27:X27) -> 40 | G27: =SUM($F$4:F27)+SUM($H$4:H27) -> 18720 | H27: 0 | I27: 塔2 | J27: 空 | K27: 空 | L27: 空 | M27: 空 | N27: 空 | O27: 空 | P27: 空 | Q27: 空 | R27: 空 | S27: 空 | T27: 空 | U27: 空 | V27: 空 | W27: 空 | X27: 空 | Y27: 空 | Z27: 空 | AA27: 空 | AB27: 空 | AC27: 空 | AD27: 空 | AE27: 空 | AF27: 空 | AG27: =AH27+AI27+AJ27 -> 0 | AK27: 是 | AM27: 空 | AN27: 0 | AO27: 0 | AP27: 0 | AV27: =AQ27*$AO27 -> 0 | AW27: =AR27*$AO27 -> 0 | AX27: =AS27*$AO27 -> 0 | BB27: =AN27*0.8 -> 0
A28: 45663 | B28: 1600 | D28: =(SUM(粮草!A28:X28)+AG28*10*IF(AK28="是",$AZ$4,$AZ$3)) -> 136 | E28: =SUM($B$4:B28)+SUM($C$4:C28)-SUM($D$4:D28) -> 7050 | F28: =SUM(经验!A28:X28) -> 70 | G28: =SUM($F$4:F28)+SUM($H$4:H28) -> 18990 | H28: 200 | I28: 2级 | J28: 商人 | K28: 空 | L28: 空 | M28: 空 | N28: 空 | O28: 空 | P28: 空 | Q28: 营地 | R28: 空 | S28: 空 | T28: 空 | U28: 空 | V28: 空 | W28: 空 | X28: 空 | Y28: 空 | Z28: 空 | AA28: 空 | AB28: 空 | AC28: 空 | AD28: 空 | AE28: 空 | AF28: 空 | AG28: =AH28+AI28+AJ28 -> 16 | AH28: 4 | AI28: 5 | AJ28: 7 | AK28: 是 | AM28: 作废 | AN28: 0 | AO28: 0 | AQ28: =COUNTIF($I$4:$P$93,AM28) -> 0 | AR28: =COUNTIF($Q$4:$X$93,AM28) -> 0 | AS28: =COUNTIF($Y$4:$AF$93,AM28) -> 0 | AT28: =AQ28+AR28+AS28 -> 0 | AU28: 0 | AV28: =AQ28*$AO28 -> 0 | AW28: =AR28*$AO28 -> 0 | AX28: =AS28*$AO28 -> 0 | BB28: =AN28*0.8 -> 0
A29: 45664 | B29: 1600 | D29: =(SUM(粮草!A29:X29)+AG29*10*IF(AK29="是",$AZ$4,$AZ$3)) -> 464 | E29: =SUM($B$4:B29)+SUM($C$4:C29)-SUM($D$4:D29) -> 8186 | F29: =SUM(经验!A29:X29) -> 180 | G29: =SUM($F$4:F29)+SUM($H$4:H29) -> 19270 | H29: 100 | I29: 商人 | J29: 2级 | K29: 2级 | L29: 2级 | M29: 商人 | N29: 空 | O29: 空 | P29: 空 | Q29: 空 | R29: 空 | S29: 空 | T29: 空 | U29: 空 | V29: 空 | W29: 空 | X29: 空 | Y29: 空 | Z29: 空 | AA29: 空 | AB29: 空 | AC29: 空 | AD29: 空 | AE29: 空 | AF29: 空 | AG29: =AH29+AI29+AJ29 -> 0 | AK29: 是 | AM29: 历练 | AN29: 50 | AO29: 520 | AQ29: =COUNTIF($I$4:$P$93,AM29) -> 1 | AR29: =COUNTIF($Q$4:$X$93,AM29) -> 1 | AS29: =COUNTIF($Y$4:$AF$93,AM29) -> 1 | AT29: =AQ29+AR29+AS29 -> 3 | AU29: 1 | AV29: =AQ29*$AO29 -> 520 | AW29: =AR29*$AO29 -> 520 | AX29: =AS29*$AO29 -> 520 | BB29: =AN29*0.8 -> 40
A30: 45665 | B30: 1600 | D30: =(SUM(粮草!A30:X30)+AG30*10*IF(AK30="是",$AZ$4,$AZ$3)) -> 416 | E30: =SUM($B$4:B30)+SUM($C$4:C30)-SUM($D$4:D30) -> 9370 | F30: =SUM(经验!A30:X30) -> 150 | G30: =SUM($F$4:F30)+SUM($H$4:H30) -> 19620 | H30: 200 | I30: 塔2 | J30: 2级 | K30: 2级 | L30: 商人 | M30: 空 | N30: 空 | O30: 空 | P30: 空 | Q30: 空 | R30: 空 | S30: 空 | T30: 空 | U30: 空 | V30: 空 | W30: 空 | X30: 空 | Y30: 空 | Z30: 空 | AA30: 空 | AB30: 空 | AC30: 空 | AD30: 空 | AE30: 空 | AF30: 空 | AG30: =AH30+AI30+AJ30 -> 0 | AK30: 是
A31: 45666 | B31: 1600 | D31: =(SUM(粮草!A31:X31)+AG31*10*IF(AK31="是",$AZ$4,$AZ$3)) -> 0 | E31: =SUM($B$4:B31)+SUM($C$4:C31)-SUM($D$4:D31) -> 10970 | F31: =SUM(经验!A31:X31) -> 0 | G31: =SUM($F$4:F31)+SUM($H$4:H31) -> 19620 | H31: 0 | I31: 空 | J31: 空 | K31: 空 | L31: 空 | M31: 空 | N31: 空 | O31: 空 | P31: 空 | Q31: 空 | R31: 空 | S31: 空 | T31: 空 | U31: 空 | V31: 空 | W31: 空 | X31: 空 | Y31: 空 | Z31: 空 | AA31: 空 | AB31: 空 | AC31: 空 | AD31: 空 | AE31: 空 | AF31: 空 | AG31: =AH31+AI31+AJ31 -> 0 | AK31: 是
A32: 45667 | B32: 1600 | D32: =(SUM(粮草!A32:X32)+AG32*10*IF(AK32="是",$AZ$4,$AZ$3)) -> 2648 | E32: =SUM($B$4:B32)+SUM($C$4:C32)-SUM($D$4:D32) -> 9922 | F32: =SUM(经验!A32:X32) -> 935 | G32: =SUM($F$4:F32)+SUM($H$4:H32) -> 20555 | H32: 0 | I32: 3级 | J32: 3级 | K32: 3级 | L32: 3级 | M32: 3级 | N32: 3级 | O32: 3级 | P32: 空 | Q32: 5级 | R32: 5级 | S32: 5级 | T32: 5级 | U32: 5级 | V32: 5级 | W32: 5级 | X32: 5级 | Y32: 塔3 | Z32: 塔3 | AA32: 塔3 | AB32: 塔3 | AC32: 空 | AD32: 空 | AE32: 空 | AF32: 空 | AG32: =AH32+AI32+AJ32 -> 0 | AK32: 是 | AM32: 地块统计 | AN32: 应占领 | AO32: 缺少 | AP32: 粮草 | AQ32: 分数
A33: 45668 | B33: 1600 | D33: =(SUM(粮草!A33:X33)+AG33*10*IF(AK33="是",$AZ$4,$AZ$3)) -> 2408 | E33: =SUM($B$4:B33)+SUM($C$4:C33)-SUM($D$4:D33) -> 9114 | F33: =SUM(经验!A33:X33) -> 855 | G33: =SUM($F$4:F33)+SUM($H$4:H33) -> 21410 | H33: 0 | I33: 3级 | J33: 3级 | K33: 3级 | L33: 3级 | M33: 3级 | N33: 3级 | O33: 3级 | P33: 空 | Q33: 5级 | R33: 5级 | S33: 5级 | T33: 5级 | U33: 5级 | V33: 5级 | W33: 5级 | X33: 5级 | Y33: 塔4 | Z33: 塔4 | AA33: 空 | AB33: 空 | AC33: 空 | AD33: 空 | AE33: 空 | AF33: 空 | AG33: =AH33+AI33+AJ33 -> 0 | AK33: 是 | AM33: 3级 | AN33: 205 | AO33: =AN33-AT6 -> 0 | AP33: =AO33*AN6*0.8 -> 0 | AQ33: =AO33*AO6 -> 0
A34: 45669 | B34: 1600 | D34: =(SUM(粮草!A34:X34)+AG34*10*IF(AK34="是",$AZ$4,$AZ$3)) -> 2528 | E34: =SUM($B$4:B34)+SUM($C$4:C34)-SUM($D$4:D34) -> 8186 | F34: =SUM(经验!A34:X34) -> 920 | G34: =SUM($F$4:F34)+SUM($H$4:H34) -> 22330 | H34: 0 | I34: 3级 | J34: 3级 | K34: 3级 | L34: 3级 | M34: 3级 | N34: 3级 | O34: 3级 | P34: 空 | Q34: 5级 | R34: 5级 | S34: 5级 | T34: 5级 | U34: 5级 | V34: 5级 | W34: 5级 | X34: 5级 | Y34: 塔5 | Z34: 塔5 | AA34: 塔5 | AB34: 空 | AC34: 空 | AD34: 空 | AE34: 空 | AF34: 空 | AG34: =AH34+AI34+AJ34 -> 0 | AK34: 是 | AM34: 4级 | AN34: 276 | AO34: =AN34-AT7 -> 0 | AP34: =AO34*AN7*0.8 -> 0 | AQ34: =AO34*AO7 -> 0
A35: 45670 | B35: 1600 | D35: =(SUM(粮草!A35:X35)+AG35*10*IF(AK35="是",$AZ$4,$AZ$3)) -> 2288 | E35: =SUM($B$4:B35)+SUM($C$4:C35)-SUM($D$4:D35) -> 7498 | F35: =SUM(经验!A35:X35) -> 815 | G35: =SUM($F$4:F35)+SUM($H$4:H35) -> 23345 | H35: 200 | I35: 3级 | J35: 3级 | K35: 3级 | L35: 3级 | M35: 3级 | N35: 3级 | O35: 3级 | P35: 空 | Q35: 5级 | R35: 5级 | S35: 5级 | T35: 5级 | U35: 5级 | V35: 5级 | W35: 5级 | X35: 5级 | Y35: 塔6 | Z35: 空 | AA35: 空 | AB35: 空 | AC35: 空 | AD35: 空 | AE35: 空 | AF35: 空 | AG35: =AH35+AI35+AJ35 -> 0 | AK35: 是 | AM35: 5级 | AN35: 234 | AO35: =AN35-AT8 -> 0 | AP35: =AO35*AN8*0.8 -> 0 | AQ35: =AO35*AO8 -> 0
A36: 45671 | B36: 1600 | D36: =(SUM(粮草!A36:X36)+AG36*10*IF(AK36="是",$AZ$4,$AZ$3)) -> 2568 | E36: =SUM($B$4:B36)+SUM($C$4:C36)-SUM($D$4:D36) -> 6530 | F36: =SUM(经验!A36:X36) -> 1755 | G36: =SUM($F$4:F36)+SUM($H$4:H36) -> 25200 | H36: 100 | I36: 3级 | J36: 3级 | K36: 3级 | L36: 3级 | M36: 3级 | N36: 3级 | O36: 3级 | P36: 空 | Q36: 5级 | R36: 5级 | S36: 5级 | T36: 5级 | U36: 5级 | V36: 5级 | W36: 5级 | X36: 5级 | Y36: 中boss | Z36: 中boss | AA36: 空 | AB36: 空 | AC36: 空 | AD36: 空 | AE36: 空 | AF36: 空 | AG36: =AH36+AI36+AJ36 -> 0 | AK36: 是 | AM36: 6级 | AN36: 191 | AO36: =AN36-AT9 -> 0 | AP36: =AO36*AN9*0.8 -> 0 | AQ36: =AO36*AO9 -> 0
A37: 45672 | B37: 1600 | D37: =(SUM(粮草!A37:X37)+AG37*10*IF(AK37="是",$AZ$4,$AZ$3)) -> 2208 | E37: =SUM($B$4:B37)+SUM($C$4:C37)-SUM($D$4:D37) -> 5922 | F37: =SUM(经验!A37:X37) -> 1275 | G37: =SUM($F$4:F37)+SUM($H$4:H37) -> 26675 | H37: 200 | I37: 3级 | J37: 3级 | K37: 3级 | L37: 3级 | M37: 3级 | N37: 3级 | O37: 3级 | P37: 空 | Q37: 5级 | R37: 5级 | S37: 5级 | T37: 5级 | U37: 5级 | V37: 5级 | W37: 5级 | X37: 5级 | Y37: 历练 | Z37: 空 | AA37: 空 | AB37: 空 | AC37: 空 | AD37: 空 | AE37: 空 | AF37: 空 | AG37: =AH37+AI37+AJ37 -> 0 | AK37: 是 | AM37: 商人 | AN37: 39 | AO37: =AN37-AT17 -> 0 | AP37: =AO37*AN17*0.8 -> 0 | AQ37: =AO37*AO17 -> 0
A38: 45673 | B38: 1600 | D38: =(SUM(粮草!A38:X38)+AG38*10*IF(AK38="是",$AZ$4,$AZ$3)) -> 2168 | E38: =SUM($B$4:B38)+SUM($C$4:C38)-SUM($D$4:D38) -> 5354 | F38: =SUM(经验!A38:X38) -> 755 | G38: =SUM($F$4:F38)+SUM($H$4:H38) -> 27430 | H38: 0 | I38: 3级 | J38: 3级 | K38: 3级 | L38: 3级 | M38: 3级 | N38: 3级 | O38: 3级 | P38: 空 | Q38: 5级 | R38: 5级 | S38: 5级 | T38: 5级 | U38: 5级 | V38: 5级 | W38: 5级 | X38: 5级 | Y38: 空 | Z38: 空 | AA38: 空 | AB38: 空 | AC38: 空 | AD38: 空 | AE38: 空 | AF38: 空 | AG38: =AH38+AI38+AJ38 -> 0 | AK38: 是 | AM38: 塔2 | AN38: 4 | AO38: =AN38-AT11 -> 0 | AP38: =AO38*AN11*0.8 -> 0 | AQ38: =AO38*AO11 -> 0
A39: 45674 | B39: 1600 | D39: =(SUM(粮草!A39:X39)+AG39*10*IF(AK39="是",$AZ$4,$AZ$3)) -> 2168 | E39: =SUM($B$4:B39)+SUM($C$4:C39)-SUM($D$4:D39) -> 4786 | F39: =SUM(经验!A39:X39) -> 755 | G39: =SUM($F$4:F39)+SUM($H$4:H39) -> 28185 | H39: 0 | I39: 3级 | J39: 3级 | K39: 3级 | L39: 3级 | M39: 3级 | N39: 3级 | O39: 3级 | P39: 空 | Q39: 5级 | R39: 5级 | S39: 5级 | T39: 5级 | U39: 5级 | V39: 5级 | W39: 5级 | X39: 5级 | Y39: 空 | Z39: 空 | AA39: 空 | AB39: 空 | AC39: 空 | AD39: 空 | AE39: 空 | AF39: 空 | AG39: =AH39+AI39+AJ39 -> 0 | AK39: 是 | AM39: 塔3 | AN39: 6 | AO39: =AN39-AT12 -> 0 | AP39: =AO39*AN12*0.8 -> 0 | AQ39: =AO39*AO12 -> 0
A40: 45675 | B40: 1600 | D40: =(SUM(粮草!A40:X40)+AG40*10*IF(AK40="是",$AZ$4,$AZ$3)) -> 2168 | E40: =SUM($B$4:B40)+SUM($C$4:C40)-SUM($D$4:D40) -> 4218 | F40: =SUM(经验!A40:X40) -> 755 | G40: =SUM($F$4:F40)+SUM($H$4:H40) -> 28940 | H40: 0 | I40: 3级 | J40: 3级 | K40: 3级 | L40: 3级 | M40: 3级 | N40: 3级 | O40: 3级 | P40: 空 | Q40: 5级 | R40: 5级 | S40: 5级 | T40: 5级 | U40: 5级 | V40: 5级 | W40: 5级 | X40: 5级 | Y40: 空 | Z40: 空 | AA40: 空 | AB40: 空 | AC40: 空 | AD40: 空 | AE40: 空 | AF40: 空 | AG40: =AH40+AI40+AJ40 -> 0 | AK40: 是 | AM40: 塔4 | AN40: 3 | AO40: =AN40-AT13 -> 0 | AP40: =AO40*AN13*0.8 -> 0 | AQ40: =AO40*AO13 -> 0
...

Sheet 粮草
A2: 队伍一 风 | C2: 步数 | D2: =COUNTIF(A4:H94,"<>空") -> 728 | E2: (不算跳步和传送) | I2: 队伍二 雷 | K2: 步数 | L2: =COUNTIF(I4:P94,"<>空") -> 728 | M2: (不算跳步和传送) | Q2: 队伍三 | S2: 总步数 | T2: =COUNTIF(Q4:X94,"<>空") -> 728 | U2: (不算跳步和传送) | Y2: 粮草调整
A3: 1 | B3: 2 | C3: 3 | D3: 4 | E3: 5 | F3: 6 | G3: 7 | H3: 8 | I3: 1 | J3: 2 | K3: 3 | L3: 4 | M3: 5 | N3: 6 | O3: 7 | P3: 8 | Q3: 1 | R3: 2 | S3: 3 | T3: 4 | U3: 5 | V3: 6 | W3: 7 | X3: 8
A4: =IF(ISNUMBER(SEARCH("营",'18.04'!I4)),(-$Y4+50*IF('18.04'!$AK4="是",'18.04'!$AZ$4,'18.04'!$AZ$3)),(VLOOKUP('18.04'!I4,'18.04'!$AM$4:$AO$55,2,FALSE))*IF('18.04'!$AK4="是",'18.04'!$AZ$4,'18.04'!$AZ$3)) -> 150 | B4: =IF(ISNUMBER(SEARCH("营",'18.04'!J4)),(-$Y4+50*IF('18.04'!$AK4="是",'18.04'!$AZ$4,'18.04'!$AZ$3)),(VLOOKUP('18.04'!J4,'18.04'!$AM$4:$AO$55,2,FALSE))*IF('18.04'!$AK4="是",'18.04'!$AZ$4,'18.04'!$AZ$3)) -> 150 | C4: =IF(ISNUMBER(SEARCH("营",'18.04'!K4)),(-$Y4+50*IF('18.04'!$AK4="是",'18.04'!$AZ$4,'18.04'!$AZ$3)),(VLOOKUP('18.04'!K4,'18.04'!$AM$4:$AO$55,2,FALSE))*IF('18.04'!$AK4="是",'18.04'!$AZ$4,'18.04'!$AZ$3)) -> 150 | D4: =IF(ISNUMBER(SEARCH("营",'18.04'!L4)),(-$Y4+50*IF('18.04'!$AK4="是",'18.04'!$AZ$4,'18.04'!$AZ$3)),(VLOOKUP('18.04'!L4,'18.04'!$AM$4:$AO$55,2,FALSE))*IF('18.04'!$AK4="是",'18.04'!$AZ$4,'18.04'!$AZ$3)) -> 150 | E4: =IF(ISNUMBER(SEARCH("营",'18.04'!M4)),(-$Y4+50*IF('18.04'!$AK4="是",'18.04'!$AZ$4,'18.04'!$AZ$3)),(VLOOKUP('18.04'!M4,'18.04'!$AM$4:$AO$55,2,FALSE))*IF('18.04'!$AK4="是",'18.04'!$AZ$4,'18.04'!$AZ$3)) -> 150 | F4: =IF(ISNUMBER(SEARCH("营",'18.04'!N4)),(-$Y4+50*IF('18.04'!$AK4="是",'18.04'!$AZ$4,'18.04'!$AZ$3)),(VLOOKUP('18.04'!N4,'18.04'!$AM$4:$AO$55,2,FALSE))*IF('18.04'!$AK4="是",'18.04'!$AZ$4,'18.04'!$AZ$3)) -> 0 | G4: =IF(ISNUMBER(SEARCH("营",'18.04'!O4)),(-$Y4+50*IF('18.04'!$AK4="是",'18.04'!$AZ$4,'18.04'!$AZ$3)),(VLOOKUP('18.04'!O4,'18.04'!$AM$4:$AO$55,2,FALSE))*IF('18.04'!$AK4="是",'18.04'!$AZ$4,'18.04'!$AZ$3)) -> 0 | H4: =IF(ISNUMBER(SEARCH("营",'18.04'!P4)),(-$Y4+50*IF('18.04'!$AK4="是",'18.04'!$AZ$4,'18.04'!$AZ$3)),(VLOOKUP('18.04'!P4,'18.04'!$AM$4:$AO$55,2,FALSE))*IF('18.04'!$AK4="是",'18.04'!$AZ$4,'18.04'!$AZ$3)) -> 0 | ... X4: =IF(ISNUMBER(SEARCH("营",'18.04'!AF4)),(-$Y4+50*IF('18.04'!$AK4="是",'18.04'!$AZ$4,'18.04'!$AZ$3)),(VLOOKUP('18.04'!AF4,'18.04'!$AM$4:$AO$55,2,FALSE))*IF('18.04'!$AK4="是",'18.04'!$AZ$4,'18.04'!$AZ$3)) -> 0 | Y4: 300 | Z4: 45639
A5: =IF(ISNUMBER(SEARCH("营",'18.04'!I5)),(-$Y5+50*IF('18.04'!$AK5="是",'18.04'!$AZ$4,'18.04'!$AZ$3)),(VLOOKUP('18.04'!I5,'18.04'!$AM$4:$AO$55,2,FALSE))*IF('18.04'!$AK5="是",'18.04'!$AZ$4,'18.04'!$AZ$3)) -> 0 | B5: =IF(ISNUMBER(SEARCH("营",'18.04'!J5)),(-$Y5+50*IF('18.04'!$AK5="是",'18.04'!$AZ$4,'18.04'!$AZ$3)),(VLOOKUP('18.04'!J5,'18.04'!$AM$4:$AO$55,2,FALSE))*IF('18.04'!$AK5="是",'18.04'!$AZ$4,'18.04'!$AZ$3)) -> 0 | C5: =IF(ISNUMBER(SEARCH("营",'18.04'!K5)),(-$Y5+50*IF('18.04'!$AK5="是",'18.04'!$AZ$4,'18.04'!$AZ$3)),(VLOOKUP('18.04'!K5,'18.04'!$AM$4:$AO$55,2,FALSE))*IF('18.04'!$AK5="是",'18.04'!$AZ$4,'18.04'!$AZ$3)) -> 0 | D5: =IF(ISNUMBER(SEARCH("营",'18.04'!L5)),(-$Y5+50*IF('18.04'!$AK5="是",'18.04'!$AZ$4,'18.04'!$AZ$3)),(VLOOKUP('18.04'!L5,'18.04'!$AM$4:$AO$55,2,FALSE))*IF('18.04'!$AK5="是",'18.04'!$AZ$4,'18.04'!$AZ$3)) -> 0 | E5: =IF(ISNUMBER(SEARCH("营",'18.04'!M5)),(-$Y5+50*IF('18.04'!$AK5="是",'18.04'!$AZ$4,'18.04'!$AZ$3)),(VLOOKUP('18.04'!M5,'18.04'!$AM$4:$AO$55,2,FALSE))*IF('18.04'!$AK5="是",'18.04'!$AZ$4,'18.04'!$AZ$3)) -> 0 | F5: =IF(ISNUMBER(SEARCH("营",'18.04'!N5)),(-$Y5+50*IF('18.04'!$AK5="是",'18.04'!$AZ$4,'18.04'!$AZ$3)),(VLOOKUP('18.04'!N5,'18.04'!$AM$4:$AO$55,2,FALSE))*IF('18.04'!$AK5="是",'18.04'!$AZ$4,'18.04'!$AZ$3)) -> 0 | G5: =IF(ISNUMBER(SEARCH("营",'18.04'!O5)),(-$Y5+50*IF('18.04'!$AK5="是",'18.04'!$AZ$4,'18.04'!$AZ$3)),(VLOOKUP('18.04'!O5,'18.04'!$AM$4:$AO$55,2,FALSE))*IF('18.04'!$AK5="是",'18.04'!$AZ$4,'18.04'!$AZ$3)) -> 0 | H5: =IF(ISNUMBER(SEARCH("营",'18.04'!P5)),(-$Y5+50*IF('18.04'!$AK5="是",'18.04'!$AZ$4,'18.04'!$AZ$3)),(VLOOKUP('18.04'!P5,'18.04'!$AM$4:$AO$55,2,FALSE))*IF('18.04'!$AK5="是",'18.04'!$AZ$4,'18.04'!$AZ$3)) -> 0 | ... X5: =IF(ISNUMBER(SEARCH("营",'18.04'!AF5)),(-$Y5+50*IF('18.04'!$AK5="是",'18.04'!$AZ$4,'18.04'!$AZ$3)),(VLOOKUP('18.04'!AF5,'18.04'!$AM$4:$AO$55,2,FALSE))*IF('18.04'!$AK5="是",'18.04'!$AZ$4,'18.04'!$AZ$3)) -> 160 | Y5: 300 | Z5: 45640
A6: =IF(ISNUMBER(SEARCH("营",'18.04'!I6)),(-$Y6+50*IF('18.04'!$AK6="是",'18.04'!$AZ$4,'18.04'!$AZ$3)),(VLOOKUP('18.04'!I6,'18.04'!$AM$4:$AO$55,2,FALSE))*IF('18.04'!$AK6="是",'18.04'!$AZ$4,'18.04'!$AZ$3)) -> 0 | B6: =IF(ISNUMBER(SEARCH("营",'18.04'!J6)),(-$Y6+50*IF('18.04'!$AK6="是",'18.04'!$AZ$4,'18.04'!$AZ$3)),(VLOOKUP('18.04'!J6,'18.04'!$AM$4:$AO$55,2,FALSE))*IF('18.04'!$AK6="是",'18.04'!$AZ$4,'18.04'!$AZ$3)) -> 0 | C6: =IF(ISNUMBER(SEARCH("营",'18.04'!K6)),(-$Y6+50*IF('18.04'!$AK6="是",'18.04'!$AZ$4,'18.04'!$AZ$3)),(VLOOKUP('18.04'!K6,'18.04'!$AM$4:$AO$55,2,FALSE))*IF('18.04'!$AK6="是",'18.04'!$AZ$4,'18.04'!$AZ$3)) -> 0 | D6: =IF(ISNUMBER(SEARCH("营",'18.04'!L6)),(-$Y6+50*IF('18.04'!$AK6="是",'18.04'!$AZ$4,'18.04'!$AZ$3)),(VLOOKUP('18.04'!L6,'18.04'!$AM$4:$AO$55,2,FALSE))*IF('18.04'!$AK6="是",'18.04'!$AZ$4,'18.04'!$AZ$3)) -> 0 | E6: =IF(ISNUMBER(SEARCH("营",'18.04'!M6)),(-$Y6+50*IF('18.04'!$AK6="是",'18.04'!$AZ$4,'18.04'!$AZ$3)),(VLOOKUP('18.04'!M6,'18.04'!$AM$4:$AO$55,2,FALSE))*IF('18.04'!$AK6="是",'18.04'!$AZ$4,'18.04'!$AZ$3)) -> 0 | F6: =IF(ISNUMBER(SEARCH("营",'18.04'!N6)),(-$Y6+50*IF('18.04'!$AK6="是",'18.04'!$AZ$4,'18.04'!$AZ$3)),(VLOOKUP('18.04'!N6,'18.04'!$AM$4:$AO$55,2,FALSE))*IF('18.04'!$AK6="是",'18.04'!$AZ$4,'18.04'!$AZ$3)) -> 0 | G6: =IF(ISNUMBER(SEARCH("营",'18.04'!O6)),(-$Y6+50*IF('18.04'!$AK6="是",'18.04'!$AZ$4,'18.04'!$AZ$3)),(VLOOKUP('18.04'!O6,'18.04'!$AM$4:$AO$55,2,FALSE))*IF('18.04'!$AK6="是",'18.04'!$AZ$4,'18.04'!$AZ$3)) -> 0 | H6: =IF(ISNUMBER(SEARCH("营",'18.04'!P6)),(-$Y6+50*IF('18.04'!$AK6="是",'18.04'!$AZ$4,'18.04'!$AZ$3)),(VLOOKUP('18.04'!P6,'18.04'!$AM$4:$AO$55,2,FALSE))*IF('18.04'!$AK6="是",'18.04'!$AZ$4,'18.04'!$AZ$3)) -> 0 | ... X6: =IF(ISNUMBER(SEARCH("营",'18.04'!AF6)),(-$Y6+50*IF('18.04'!$AK6="是",'18.04'!$AZ$4,'18.04'!$AZ$3)),(VLOOKUP('18.04'!AF6,'18.04'!$AM$4:$AO$55,2,FALSE))*IF('18.04'!$AK6="是",'18.04'!$AZ$4,'18.04'!$AZ$3)) -> 160 | Y6: 300 | Z6: 45641
A7: =IF(ISNUMBER(SEARCH("营",'18.04'!I7)),(-$Y7+50*IF('18.04'!$AK7="是",'18.04'!$AZ$4,'18.04'!$AZ$3)),(VLOOKUP('18.04'!I7,'18.04'!$AM$4:$AO$55,2,FALSE))*IF('18.04'!$AK7="是",'18.04'!$AZ$4,'18.04'!$AZ$3)) -> 0 | B7: =IF(ISNUMBER(SEARCH("营",'18.04'!J7)),(-$Y7+50*IF('18.04'!$AK7="是",'18.04'!$AZ$4,'18.04'!$AZ$3)),(VLOOKUP('18.04'!J7,'18.04'!$AM$4:$AO$55,2,FALSE))*IF('18.04'!$AK7="是",'18.04'!$AZ$4,'18.04'!$AZ$3)) -> 0 | C7: =IF(ISNUMBER(SEARCH("营",'18.04'!K7)),(-$Y7+50*IF('18.04'!$AK7="是",'18.04'!$AZ$4,'18.04'!$AZ$3)),(VLOOKUP('18.04'!K7,'18.04'!$AM$4:$AO$55,2,FALSE))*IF('18.04'!$AK7="是",'18.04'!$AZ$4,'18.04'!$AZ$3)) -> 0 | D7: =IF(ISNUMBER(SEARCH("营",'18.04'!L7)),(-$Y7+50*IF('18.04'!$AK7="是",'18.04'!$AZ$4,'18.04'!$AZ$3)),(VLOOKUP('18.04'!L7,'18.04'!$AM$4:$AO$55,2,FALSE))*IF('18.04'!$AK7="是",'18.04'!$AZ$4,'18.04'!$AZ$3)) -> 0 | E7: =IF(ISNUMBER(SEARCH("营",'18.04'!M7)),(-$Y7+50*IF('18.04'!$AK7="是",'18.04'!$AZ$4,'18.04'!$AZ$3)),(VLOOKUP('18.04'!M7,'18.04'!$AM$4:$AO$55,2,FALSE))*IF('18.04'!$AK7="是",'18.04'!$AZ$4,'18.04'!$AZ$3)) -> 0 | F7: =IF(ISNUMBER(SEARCH("营",'18.04'!N7)),(-$Y7+50*IF('18.04'!$AK7="是",'18.04'!$AZ$4,'18.04'!$AZ$3)),(VLOOKUP('18.04'!N7,'18.04'!$AM$4:$AO$55,2,FALSE))*IF('18.04'!$AK7="是",'18.04'!$AZ$4,'18.04'!$AZ$3)) -> 0 | G7: =IF(ISNUMBER(SEARCH("营",'18.04'!O7)),(-$Y7+50*IF('18.04'!$AK7="是",'18.04'!$AZ$4,'18.04'!$AZ$3)),(VLOOKUP('18.04'!O7,'18.04'!$AM$4:$AO$55,2,FALSE))*IF('18.04'!$AK7="是",'18.04'!$AZ$4,'18.04'!$AZ$3)) -> 0 | H7: =IF(ISNUMBER(SEARCH("营",'18.04'!P7)),(-$Y7+50*IF('18.04'!$AK7="是",'18.04'!$AZ$4,'18.04'!$AZ$3)),(VLOOKUP('18.04'!P7,'18.04'!$AM$4:$AO$55,2,FALSE))*IF('18.04'!$AK7="是",'18.04'!$AZ$4,'18.04'!$AZ$3)) -> 0 | ... X7: =IF(ISNUMBER(SEARCH("营",'18.04'!AF7)),(-$Y7+50*IF('18.04'!$AK7="是",'18.04'!$AZ$4,'18.04'!$AZ$3)),(VLOOKUP('18.04'!AF7,'18.04'!$AM$4:$AO$55,2,FALSE))*IF('18.04'!$AK7="是",'18.04'!$AZ$4,'18.04'!$AZ$3)) -> 170 | Y7: 300 | Z7: 45642
A8: =IF(ISNUMBER(SEARCH("营",'18.04'!I8)),(-$Y8+50*IF('18.04'!$AK8="是",'18.04'!$AZ$4,'18.04'!$AZ$3)),(VLOOKUP('18.04'!I8,'18.04'!$AM$4:$AO$55,2,FALSE))*IF('18.04'!$AK8="是",'18.04'!$AZ$4,'18.04'!$AZ$3)) -> 0 | B8: =IF(ISNUMBER(SEARCH("营",'18.04'!J8)),(-$Y8+50*IF('18.04'!$AK8="是",'18.04'!$AZ$4,'18.04'!$AZ$3)),(VLOOKUP('18.04'!J8,'18.04'!$AM$4:$AO$55,2,FALSE))*IF('18.04'!$AK8="是",'18.04'!$AZ$4,'18.04'!$AZ$3)) -> 0 | C8: =IF(ISNUMBER(SEARCH("营",'18.04'!K8)),(-$Y8+50*IF('18.04'!$AK8="是",'18.04'!$AZ$4,'18.04'!$AZ$3)),(VLOOKUP('18.04'!K8,'18.04'!$AM$4:$AO$55,2,FALSE))*IF('18.04'!$AK8="是",'18.04'!$AZ$4,'18.04'!$AZ$3)) -> 0 | D8: =IF(ISNUMBER(SEARCH("营",'18.04'!L8)),(-$Y8+50*IF('18.04'!$AK8="是",'18.04'!$AZ$4,'18.04'!$AZ$3)),(VLOOKUP('18.04'!L8,'18.04'!$AM$4:$AO$55,2,FALSE))*IF('18.04'!$AK8="是",'18.04'!$AZ$4,'18.04'!$AZ$3)) -> 0 | E8: =IF(ISNUMBER(SEARCH("营",'18.04'!M8)),(-$Y8+50*IF('18.04'!$AK8="是",'18.04'!$AZ$4,'18.04'!$AZ$3)),(VLOOKUP('18.04'!M8,'18.04'!$AM$4:$AO$55,2,FALSE))*IF('18.04'!$AK8="是",'18.04'!$AZ$4,'18.04'!$AZ$3)) -> 0 | F8: =IF(ISNUMBER(SEARCH("营",'18.04'!N8)),(-$Y8+50*IF('18.04'!$AK8="是",'18.04'!$AZ$4,'18.04'!$AZ$3)),(VLOOKUP('18.04'!N8,'18.04'!$AM$4:$AO$55,2,FALSE))*IF('18.04'!$AK8="是",'18.04'!$AZ$4,'18.04'!$AZ$3)) -> 0 | G8: =IF(ISNUMBER(SEARCH("营",'18.04'!O8)),(-$Y8+50*IF('18.04'!$AK8="是",'18.04'!$AZ$4,'18.04'!$AZ$3)),(VLOOKUP('18.04'!O8,'18.04'!$AM$4:$AO$55,2,FALSE))*IF('18.04'!$AK8="是",'18.04'!$AZ$4,'18.04'!$AZ$3)) -> 0 | H8: =IF(ISNUMBER(SEARCH("营",'18.04'!P8)),(-$Y8+50*IF('18.04'!$AK8="是",'18.04'!$AZ$4,'18.04'!$AZ$3)),(VLOOKUP('18.04'!P8,'18.04'!$AM$4:$AO$55,2,FALSE))*IF('18.04'!$AK8="是",'18.04'!$AZ$4,'18.04'!$AZ$3)) -> 0 | ... X8: =IF(ISNUMBER(SEARCH("营",'18.04'!AF8)),(-$Y8+50*IF('18.04'!$AK8="是",'18.04'!$AZ$4,'18.04'!$AZ$3)),(VLOOKUP('18.04'!AF8,'18.04'!$AM$4:$AO$55,2,FALSE))*IF('18.04'!$AK8="是",'18.04'!$AZ$4,'18.04'!$AZ$3)) -> 170 | Y8: 300 | Z8: 45643
A9: =IF(ISNUMBER(SEARCH("营",'18.04'!I9)),(-$Y9+50*IF('18.04'!$AK9="是",'18.04'!$AZ$4,'18.04'!$AZ$3)),(VLOOKUP('18.04'!I9,'18.04'!$AM$4:$AO$55,2,FALSE))*IF('18.04'!$AK9="是",'18.04'!$AZ$4,'18.04'!$AZ$3)) -> 0 | B9: =IF(ISNUMBER(SEARCH("营",'18.04'!J9)),(-$Y9+50*IF('18.04'!$AK9="是",'18.04'!$AZ$4,'18.04'!$AZ$3)),(VLOOKUP('18.04'!J9,'18.04'!$AM$4:$AO$55,2,FALSE))*IF('18.04'!$AK9="是",'18.04'!$AZ$4,'18.04'!$AZ$3)) -> 0 | C9: =IF(ISNUMBER(SEARCH("营",'18.04'!K9)),(-$Y9+50*IF('18.04'!$AK9="是",'18.04'!$AZ$4,'18.04'!$AZ$3)),(VLOOKUP('18.04'!K9,'18.04'!$AM$4:$AO$55,2,FALSE))*IF('18.04'!$AK9="是",'18.04'!$AZ$4,'18.04'!$AZ$3)) -> 0 | D9: =IF(ISNUMBER(SEARCH("营",'18.04'!L9)),(-$Y9+50*IF('18.04'!$AK9="是",'18.04'!$AZ$4,'18.04'!$AZ$3)),(VLOOKUP('18.04'!L9,'18.04'!$AM$4:$AO$55,2,FALSE))*IF('18.04'!$AK9="是",'18.04'!$AZ$4,'18.04'!$AZ$3)) -> 0 | E9: =IF(ISNUMBER(SEARCH("营",'18.04'!M9)),(-$Y9+50*IF('18.04'!$AK9="是",'18.04'!$AZ$4,'18.04'!$AZ$3)),(VLOOKUP('18.04'!M9,'18.04'!$AM$4:$AO$55,2,FALSE))*IF('18.04'!$AK9="是",'18.04'!$AZ$4,'18.04'!$AZ$3)) -> 0 | F9: =IF(ISNUMBER(SEARCH("营",'18.04'!N9)),(-$Y9+50*IF('18.04'!$AK9="是",'18.04'!$AZ$4,'18.04'!$AZ$3)),(VLOOKUP('18.04'!N9,'18.04'!$AM$4:$AO$55,2,FALSE))*IF('18.04'!$AK9="是",'18.04'!$AZ$4,'18.04'!$AZ$3)) -> 0 | G9: =IF(ISNUMBER(SEARCH("营",'18.04'!O9)),(-$Y9+50*IF('18.04'!$AK9="是",'18.04'!$AZ$4,'18.04'!$AZ$3)),(VLOOKUP('18.04'!O9,'18.04'!$AM$4:$AO$55,2,FALSE))*IF('18.04'!$AK9="是",'18.04'!$AZ$4,'18.04'!$AZ$3)) -> 0 | H9: =IF(ISNUMBER(SEARCH("营",'18.04'!P9)),(-$Y9+50*IF('18.04'!$AK9="是",'18.04'!$AZ$4,'18.04'!$AZ$3)),(VLOOKUP('18.04'!P9,'18.04'!$AM$4:$AO$55,2,FALSE))*IF('18.04'!$AK9="是",'18.04'!$AZ$4,'18.04'!$AZ$3)) -> 0 | ... X9: =IF(ISNUMBER(SEARCH("营",'18.04'!AF9)),(-$Y9+50*IF('18.04'!$AK9="是",'18.04'!$AZ$4,'18.04'!$AZ$3)),(VLOOKUP('18.04'!AF9,'18.04'!$AM$4:$AO$55,2,FALSE))*IF('18.04'!$AK9="是",'18.04'!$AZ$4,'18.04'!$AZ$3)) -> 0 | Y9: 300 | Z9: 45644
A10: =IF(ISNUMBER(SEARCH("营",'18.04'!I10)),(-$Y10+50*IF('18.04'!$AK10="是",'18.04'!$AZ$4,'18.04'!$AZ$3)),(VLOOKUP('18.04'!I10,'18.04'!$AM$4:$AO$55,2,FALSE))*IF('18.04'!$AK10="是",'18.04'!$AZ$4,'18.04'!$AZ$3)) -> 150 | B10: =IF(ISNUMBER(SEARCH("营",'18.04'!J10)),(-$Y10+50*IF('18.04'!$AK10="是",'18.04'!$AZ$4,'18.04'!$AZ$3)),(VLOOKUP('18.04'!J10,'18.04'!$AM$4:$AO$55,2,FALSE))*IF('18.04'!$AK10="是",'18.04'!$AZ$4,'18.04'!$AZ$3)) -> 150 | C10: =IF(ISNUMBER(SEARCH("营",'18.04'!K10)),(-$Y10+50*IF('18.04'!$AK10="是",'18.04'!$AZ$4,'18.04'!$AZ$3)),(VLOOKUP('18.04'!K10,'18.04'!$AM$4:$AO$55,2,FALSE))*IF('18.04'!$AK10="是",'18.04'!$AZ$4,'18.04'!$AZ$3)) -> 150 | D10: =IF(ISNUMBER(SEARCH("营",'18.04'!L10)),(-$Y10+50*IF('18.04'!$AK10="是",'18.04'!$AZ$4,'18.04'!$AZ$3)),(VLOOKUP('18.04'!L10,'18.04'!$AM$4:$AO$55,2,FALSE))*IF('18.04'!$AK10="是",'18.04'!$AZ$4,'18.04'!$AZ$3)) -> 150 | E10: =IF(ISNUMBER(SEARCH("营",'18.04'!M10)),(-$Y10+50*IF('18.04'!$AK10="是",'18.04'!$AZ$4,'18.04'!$AZ$3)),(VLOOKUP('18.04'!M10,'18.04'!$AM$4:$AO$55,2,FALSE))*IF('18.04'!$AK10="是",'18.04'!$AZ$4,'18.04'!$AZ$3)) -> 50 | F10: =IF(ISNUMBER(SEARCH("营",'18.04'!N10)),(-$Y10+50*IF('18.04'!$AK10="是",'18.04'!$AZ$4,'18.04'!$AZ$3)),(VLOOKUP('18.04'!N10,'18.04'!$AM$4:$AO$55,2,FALSE))*IF('18.04'!$AK10="是",'18.04'!$AZ$4,'18.04'!$AZ$3)) -> 150 | G10: =IF(ISNUMBER(SEARCH("营",'18.04'!O10)),(-$Y10+50*IF('18.04'!$AK10="是",'18.04'!$AZ$4,'18.04'!$AZ$3)),(VLOOKUP('18.04'!O10,'18.04'!$AM$4:$AO$55,2,FALSE))*IF('18.04'!$AK10="是",'18.04'!$AZ$4,'18.04'!$AZ$3)) -> 150 | H10: =IF(ISNUMBER(SEARCH("营",'18.04'!P10)),(-$Y10+50*IF('18.04'!$AK10="是",'18.04'!$AZ$4,'18.04'!$AZ$3)),(VLOOKUP('18.04'!P10,'18.04'!$AM$4:$AO$55,2,FALSE))*IF('18.04'!$AK10="是",'18.04'!$AZ$4,'18.04'!$AZ$3)) -> 150 | ... X10: =IF(ISNUMBER(SEARCH("营",'18.04'!AF10)),(-$Y10+50*IF('18.04'!$AK10="是",'18.04'!$AZ$4,'18.04'!$AZ$3)),(VLOOKUP('18.04'!AF10,'18.04'!$AM$4:$AO$55,2,FALSE))*IF('18.04'!$AK10="是",'18.04'!$AZ$4,'18.04'!$AZ$3)) -> 0 | Y10: 300 | Z10: 45645
A11: =IF(ISNUMBER(SEARCH("营",'18.04'!I11)),(-$Y11+50*IF('18.04'!$AK11="是",'18.04'!$AZ$4,'18.04'!$AZ$3)),(VLOOKUP('18.04'!I11,'18.04'!$AM$4:$AO$55,2,FALSE))*IF('18.04'!$AK11="是",'18.04'!$AZ$4,'18.04'!$AZ$3)) -> 150 | B11: =IF(ISNUMBER(SEARCH("营",'18.04'!J11)),(-$Y11+50*IF('18.04'!$AK11="是",'18.04'!$AZ$4,'18.04'!$AZ$3)),(VLOOKUP('18.04'!J11,'18.04'!$AM$4:$AO$55,2,FALSE))*IF('18.04'!$AK11="是",'18.04'!$AZ$4,'18.04'!$AZ$3)) -> 150 | C11: =IF(ISNUMBER(SEARCH("营",'18.04'!K11)),(-$Y11+50*IF('18.04'!$AK11="是",'18.04'!$AZ$4,'18.04'!$AZ$3)),(VLOOKUP('18.04'!K11,'18.04'!$AM$4:$AO$55,2,FALSE))*IF('18.04'!$AK11="是",'18.04'!$AZ$4,'18.04'!$AZ$3)) -> 50 | D11: =IF(ISNUMBER(SEARCH("营",'18.04'!L11)),(-$Y11+50*IF('18.04'!$AK11="是",'18.04'!$AZ$4,'18.04'!$AZ$3)),(VLOOKUP('18.04'!L11,'18.04'!$AM$4:$AO$55,2,FALSE))*IF('18.04'!$AK11="是",'18.04'!$AZ$4,'18.04'!$AZ$3)) -> 150 | E11: =IF(ISNUMBER(SEARCH("营",'18.04'!M11)),(-$Y11+50*IF('18.04'!$AK11="是",'18.04'!$AZ$4,'18.04'!$AZ$3)),(VLOOKUP('18.04'!M11,'18.04'!$AM$4:$AO$55,2,FALSE))*IF('18.04'!$AK11="是",'18.04'!$AZ$4,'18.04'!$AZ$3)) -> 150 | F11: =IF(ISNUMBER(SEARCH("营",'18.04'!N11)),(-$Y11+50*IF('18.04'!$AK11="是",'18.04'!$AZ$4,'18.04'!$AZ$3)),(VLOOKUP('18.04'!N11,'18.04'!$AM$4:$AO$55,2,FALSE))*IF('18.04'!$AK11="是",'18.04'!$AZ$4,'18.04'!$AZ$3)) -> 150 | G11: =IF(ISNUMBER(SEARCH("营",'18.04'!O11)),(-$Y11+50*IF('18.04'!$AK11="是",'18.04'!$AZ$4,'18.04'!$AZ$3)),(VLOOKUP('18.04'!O11,'18.04'!$AM$4:$AO$55,2,FALSE))*IF('18.04'!$AK11="是",'18.04'!$AZ$4,'18.04'!$AZ$3)) -> 150 | H11: =IF(ISNUMBER(SEARCH("营",'18.04'!P11)),(-$Y11+50*IF('18.04'!$AK11="是",'18.04'!$AZ$4,'18.04'!$AZ$3)),(VLOOKUP('18.04'!P11,'18.04'!$AM$4:$AO$55,2,FALSE))*IF('18.04'!$AK11="是",'18.04'!$AZ$4,'18.04'!$AZ$3)) -> 150 | ... X11: =IF(ISNUMBER(SEARCH("营",'18.04'!AF11)),(-$Y11+50*IF('18.04'!$AK11="是",'18.04'!$AZ$4,'18.04'!$AZ$3)),(VLOOKUP('18.04'!AF11,'18.04'!$AM$4:$AO$55,2,FALSE))*IF('18.04'!$AK11="是",'18.04'!$AZ$4,'18.04'!$AZ$3)) -> 0 | Y11: 300 | Z11: 45646
A12: =IF(ISNUMBER(SEARCH("营",'18.04'!I12)),(-$Y12+50*IF('18.04'!$AK12="是",'18.04'!$AZ$4,'18.04'!$AZ$3)),(VLOOKUP('18.04'!I12,'18.04'!$AM$4:$AO$55,2,FALSE))*IF('18.04'!$AK12="是",'18.04'!$AZ$4,'18.04'!$AZ$3)) -> 120 | B12: =IF(ISNUMBER(SEARCH("营",'18.04'!J12)),(-$Y12+50*IF('18.04'!$AK12="是",'18.04'!$AZ$4,'18.04'!$AZ$3)),(VLOOKUP('18.04'!J12,'18.04'!$AM$4:$AO$55,2,FALSE))*IF('18.04'!$AK12="是",'18.04'!$AZ$4,'18.04'!$AZ$3)) -> 120 | C12: =IF(ISNUMBER(SEARCH("营",'18.04'!K12)),(-$Y12+50*IF('18.04'!$AK12="是",'18.04'!$AZ$4,'18.04'!$AZ$3)),(VLOOKUP('18.04'!K12,'18.04'!$AM$4:$AO$55,2,FALSE))*IF('18.04'!$AK12="是",'18.04'!$AZ$4,'18.04'!$AZ$3)) -> 40 | D12: =IF(ISNUMBER(SEARCH("营",'18.04'!L12)),(-$Y12+50*IF('18.04'!$AK12="是",'18.04'!$AZ$4,'18.04'!$AZ$3)),(VLOOKUP('18.04'!L12,'18.04'!$AM$4:$AO$55,2,FALSE))*IF('18.04'!$AK12="是",'18.04'!$AZ$4,'18.04'!$AZ$3)) -> 128 | E12: =IF(ISNUMBER(SEARCH("营",'18.04'!M12)),(-$Y12+50*IF('18.04'!$AK12="是",'18.04'!$AZ$4,'18.04'!$AZ$3)),(VLOOKUP('18.04'!M12,'18.04'!$AM$4:$AO$55,2,FALSE))*IF('18.04'!$AK12="是",'18.04'!$AZ$4,'18.04'!$AZ$3)) -> 128 | F12: =IF(ISNUMBER(SEARCH("营",'18.04'!N12)),(-$Y12+50*IF('18.04'!$AK12="是",'18.04'!$AZ$4,'18.04'!$AZ$3)),(VLOOKUP('18.04'!N12,'18.04'!$AM$4:$AO$55,2,FALSE))*IF('18.04'!$AK12="是",'18.04'!$AZ$4,'18.04'!$AZ$3)) -> 128 | G12: =IF(ISNUMBER(SEARCH("营",'18.04'!O12)),(-$Y12+50*IF('18.04'!$AK12="是",'18.04'!$AZ$4,'18.04'!$AZ$3)),(VLOOKUP('18.04'!O12,'18.04'!$AM$4:$AO$55,2,FALSE))*IF('18.04'!$AK12="是",'18.04'!$AZ$4,'18.04'!$AZ$3)) -> -260 | H12: =IF(ISNUMBER(SEARCH("营",'18.04'!P12)),(-$Y12+50*IF('18.04'!$AK12="是",'18.04'!$AZ$4,'18.04'!$AZ$3)),(VLOOKUP('18.04'!P12,'18.04'!$AM$4:$AO$55,2,FALSE))*IF('18.04'!$AK12="是",'18.04'!$AZ$4,'18.04'!$AZ$3)) -> 128 | ... X12: =IF(ISNUMBER(SEARCH("营",'18.04'!AF12)),(-$Y12+50*IF('18.04'!$AK12="是",'18.04'!$AZ$4,'18.04'!$AZ$3)),(VLOOKUP('18.04'!AF12,'18.04'!$AM$4:$AO$55,2,FALSE))*IF('18.04'!$AK12="是",'18.04'!$AZ$4,'18.04'!$AZ$3)) -> 0 | Y12: 300 | Z12: 45647
A13: =IF(ISNUMBER(SEARCH("营",'18.04'!I13)),(-$Y13+50*IF('18.04'!$AK13="是",'18.04'!$AZ$4,'18.04'!$AZ$3)),(VLOOKUP('18.04'!I13,'18.04'!$AM$4:$AO$55,2,FALSE))*IF('18.04'!$AK13="是",'18.04'!$AZ$4,'18.04'!$AZ$3)) -> 40 | B13: =IF(ISNUMBER(SEARCH("营",'18.04'!J13)),(-$Y13+50*IF('18.04'!$AK13="是",'18.04'!$AZ$4,'18.04'!$AZ$3)),(VLOOKUP('18.04'!J13,'18.04'!$AM$4:$AO$55,2,FALSE))*IF('18.04'!$AK13="是",'18.04'!$AZ$4,'18.04'!$AZ$3)) -> 120 | C13: =IF(ISNUMBER(SEARCH("营",'18.04'!K13)),(-$Y13+50*IF('18.04'!$AK13="是",'18.04'!$AZ$4,'18.04'!$AZ$3)),(VLOOKUP('18.04'!K13,'18.04'!$AM$4:$AO$55,2,FALSE))*IF('18.04'!$AK13="是",'18.04'!$AZ$4,'18.04'!$AZ$3)) -> 128 | D13: =IF(ISNUMBER(SEARCH("营",'18.04'!L13)),(-$Y13+50*IF('18.04'!$AK13="是",'18.04'!$AZ$4,'18.04'!$AZ$3)),(VLOOKUP('18.04'!L13,'18.04'!$AM$4:$AO$55,2,FALSE))*IF('18.04'!$AK13="是",'18.04'!$AZ$4,'18.04'!$AZ$3)) -> 128 | E13: =IF(ISNUMBER(SEARCH("营",'18.04'!M13)),(-$Y13+50*IF('18.04'!$AK13="是",'18.04'!$AZ$4,'18.04'!$AZ$3)),(VLOOKUP('18.04'!M13,'18.04'!$AM$4:$AO$55,2,FALSE))*IF('18.04'!$AK13="是",'18.04'!$AZ$4,'18.04'!$AZ$3)) -> 128 | F13: =IF(ISNUMBER(SEARCH("营",'18.04'!N13)),(-$Y13+50*IF('18.04'!$AK13="是",'18.04'!$AZ$4,'18.04'!$AZ$3)),(VLOOKUP('18.04'!N13,'18.04'!$AM$4:$AO$55,2,FALSE))*IF('18.04'!$AK13="是",'18.04'!$AZ$4,'18.04'!$AZ$3)) -> 40 | G13: =IF(ISNUMBER(SEARCH("营",'18.04'!O13)),(-$Y13+50*IF('18.04'!$AK13="是",'18.04'!$AZ$4,'18.04'!$AZ$3)),(VLOOKUP('18.04'!O13,'18.04'!$AM$4:$AO$55,2,FALSE))*IF('18.04'!$AK13="是",'18.04'!$AZ$4,'18.04'!$AZ$3)) -> 0 | H13: =IF(ISNUMBER(SEARCH("营",'18.04'!P13)),(-$Y13+50*IF('18.04'!$AK13="是",'18.04'!$AZ$4,'18.04'!$AZ$3)),(VLOOKUP('18.04'!P13,'18.04'!$AM$4:$AO$55,2,FALSE))*IF('18.04'!$AK13="是",'18.04'!$AZ$4,'18.04'!$AZ$3)) -> 0 | ... X13: =IF(ISNUMBER(SEARCH("营",'18.04'!AF13)),(-$Y13+50*IF('18.04'!$AK13="是",'18.04'!$AZ$4,'18.04'!$AZ$3)),(VLOOKUP('18.04'!AF13,'18.04'!$AM$4:$AO$55,2,FALSE))*IF('18.04'!$AK13="是",'18.04'!$AZ$4,'18.04'!$AZ$3)) -> 160 | Y13: 300 | Z13: 45648
A14: =IF(ISNUMBER(SEARCH("营",'18.04'!I14)),(-$Y14+50*IF('18.04'!$AK14="是",'18.04'!$AZ$4,'18.04'!$AZ$3)),(VLOOKUP('18.04'!I14,'18.04'!$AM$4:$AO$55,2,FALSE))*IF('18.04'!$AK14="是",'18.04'!$AZ$4,'18.04'!$AZ$3)) -> 128 | B14: =IF(ISNUMBER(SEARCH("营",'18.04'!J14)),(-$Y14+50*IF('18.04'!$AK14="是",'18.04'!$AZ$4,'18.04'!$AZ$3)),(VLOOKUP('18.04'!J14,'18.04'!$AM$4:$AO$55,2,FALSE))*IF('18.04'!$AK14="是",'18.04'!$AZ$4,'18.04'!$AZ$3)) -> 128 | C14: =IF(ISNUMBER(SEARCH("营",'18.04'!K14)),(-$Y14+50*IF('18.04'!$AK14="是",'18.04'!$AZ$4,'18.04'!$AZ$3)),(VLOOKUP('18.04'!K14,'18.04'!$AM$4:$AO$55,2,FALSE))*IF('18.04'!$AK14="是",'18.04'!$AZ$4,'18.04'!$AZ$3)) -> 120 | D14: =IF(ISNUMBER(SEARCH("营",'18.04'!L14)),(-$Y14+50*IF('18.04'!$AK14="是",'18.04'!$AZ$4,'18.04'!$AZ$3)),(VLOOKUP('18.04'!L14,'18.04'!$AM$4:$AO$55,2,FALSE))*IF('18.04'!$AK14="是",'18.04'!$AZ$4,'18.04'!$AZ$3)) -> 128 | E14: =IF(ISNUMBER(SEARCH("营",'18.04'!M14)),(-$Y14+50*IF('18.04'!$AK14="是",'18.04'!$AZ$4,'18.04'!$AZ$3)),(VLOOKUP('18.04'!M14,'18.04'!$AM$4:$AO$55,2,FALSE))*IF('18.04'!$AK14="是",'18.04'!$AZ$4,'18.04'!$AZ$3)) -> 0 | F14: =IF(ISNUMBER(SEARCH("营",'18.04'!N14)),(-$Y14+50*IF('18.04'!$AK14="是",'18.04'!$AZ$4,'18.04'!$AZ$3)),(VLOOKUP('18.04'!N14,'18.04'!$AM$4:$AO$55,2,FALSE))*IF('18.04'!$AK14="是",'18.04'!$AZ$4,'18.04'!$AZ$3)) -> 0 | G14: =IF(ISNUMBER(SEARCH("营",'18.04'!O14)),(-$Y14+50*IF('18.04'!$AK14="是",'18.04'!$AZ$4,'18.04'!$AZ$3)),(VLOOKUP('18.04'!O14,'18.04'!$AM$4:$AO$55,2,FALSE))*IF('18.04'!$AK14="是",'18.04'!$AZ$4,'18.04'!$AZ$3)) -> 0 | H14: =IF(ISNUMBER(SEARCH("营",'18.04'!P14)),(-$Y14+50*IF('18.04'!$AK14="是",'18.04'!$AZ$4,'18.04'!$AZ$3)),(VLOOKUP('18.04'!P14,'18.04'!$AM$4:$AO$55,2,FALSE))*IF('18.04'!$AK14="是",'18.04'!$AZ$4,'18.04'!$AZ$3)) -> 0 | ... X14: =IF(ISNUMBER(SEARCH("营",'18.04'!AF14)),(-$Y14+50*IF('18.04'!$AK14="是",'18.04'!$AZ$4,'18.04'!$AZ$3)),(VLOOKUP('18.04'!AF14,'18.04'!$AM$4:$AO$55,2,FALSE))*IF('18.04'!$AK14="是",'18.04'!$AZ$4,'18.04'!$AZ$3)) -> 0 | Y14: 300 | Z14: 45649
A15: =IF(ISNUMBER(SEARCH("营",'18.04'!I15)),(-$Y15+50*IF('18.04'!$AK15="是",'18.04'!$AZ$4,'18.04'!$AZ$3)),(VLOOKUP('18.04'!I15,'18.04'!$AM$4:$AO$55,2,FALSE))*IF('18.04'!$AK15="是",'18.04'!$AZ$4,'18.04'!$AZ$3)) -> 128 | B15: =IF(ISNUMBER(SEARCH("营",'18.04'!J15)),(-$Y15+50*IF('18.04'!$AK15="是",'18.04'!$AZ$4,'18.04'!$AZ$3)),(VLOOKUP('18.04'!J15,'18.04'!$AM$4:$AO$55,2,FALSE))*IF('18.04'!$AK15="是",'18.04'!$AZ$4,'18.04'!$AZ$3)) -> -260 | C15: =IF(ISNUMBER(SEARCH("营",'18.04'!K15)),(-$Y15+50*IF('18.04'!$AK15="是",'18.04'!$AZ$4,'18.04'!$AZ$3)),(VLOOKUP('18.04'!K15,'18.04'!$AM$4:$AO$55,2,FALSE))*IF('18.04'!$AK15="是",'18.04'!$AZ$4,'18.04'!$AZ$3)) -> 128 | D15: =IF(ISNUMBER(SEARCH("营",'18.04'!L15)),(-$Y15+50*IF('18.04'!$AK15="是",'18.04'!$AZ$4,'18.04'!$AZ$3)),(VLOOKUP('18.04'!L15,'18.04'!$AM$4:$AO$55,2,FALSE))*IF('18.04'!$AK15="是",'18.04'!$AZ$4,'18.04'!$AZ$3)) -> 128 | E15: =IF(ISNUMBER(SEARCH("营",'18.04'!M15)),(-$Y15+50*IF('18.04'!$AK15="是",'18.04'!$AZ$4,'18.04'!$AZ$3)),(VLOOKUP('18.04'!M15,'18.04'!$AM$4:$AO$55,2,FALSE))*IF('18.04'!$AK15="是",'18.04'!$AZ$4,'18.04'!$AZ$3)) -> 128 | F15: =IF(ISNUMBER(SEARCH("营",'18.04'!N15)),(-$Y15+50*IF('18.04'!$AK15="是",'18.04'!$AZ$4,'18.04'!$AZ$3)),(VLOOKUP('18.04'!N15,'18.04'!$AM$4:$AO$55,2,FALSE))*IF('18.04'!$AK15="是",'18.04'!$AZ$4,'18.04'!$AZ$3)) -> 40 | G15: =IF(ISNUMBER(SEARCH("营",'18.04'!O15)),(-$Y15+50*IF('18.04'!$AK15="是",'18.04'!$AZ$4,'18.04'!$AZ$3)),(VLOOKUP('18.04'!O15,'18.04'!$AM$4:$AO$55,2,FALSE))*IF('18.04'!$AK15="是",'18.04'!$AZ$4,'18.04'!$AZ$3)) -> 0 | H15: =IF(ISNUMBER(SEARCH("营",'18.04'!P15)),(-$Y15+50*IF('18.04'!$AK15="是",'18.04'!$AZ$4,'18.04'!$AZ$3)),(VLOOKUP('18.04'!P15,'18.04'!$AM$4:$AO$55,2,FALSE))*IF('18.04'!$AK15="是",'18.04'!$AZ$4,'18.04'!$AZ$3)) -> 0 | ... X15: =IF(ISNUMBER(SEARCH("营",'18.04'!AF15)),(-$Y15+50*IF('18.04'!$AK15="是",'18.04'!$AZ$4,'18.04'!$AZ$3)),(VLOOKUP('18.04'!AF15,'18.04'!$AM$4:$AO$55,2,FALSE))*IF('18.04'!$AK15="是",'18.04'!$AZ$4,'18.04'!$AZ$3)) -> 0 | Y15: 300 | Z15: 45650
... A93: =IF(ISNUMBER(SEARCH("营",'18.04'!I93)),(-$Y93+50*IF('18.04'!$AK93="是",'18.04'!$AZ$4,'18.04'!$AZ$3)),(VLOOKUP('18.04'!I93,'18.04'!$AM$4:$AO$55,2,FALSE))*IF('18.04'!$AK93="是",'18.04'!$AZ$4,'18.04'!$AZ$3)) -> 0 | B93: =IF(ISNUMBER(SEARCH("营",'18.04'!J93)),(-$Y93+50*IF('18.04'!$AK93="是",'18.04'!$AZ$4,'18.04'!$AZ$3)),(VLOOKUP('18.04'!J93,'18.04'!$AM$4:$AO$55,2,FALSE))*IF('18.04'!$AK93="是",'18.04'!$AZ$4,'18.04'!$AZ$3)) -> 0 | C93: =IF(ISNUMBER(SEARCH("营",'18.04'!K93)),(-$Y93+50*IF('18.04'!$AK93="是",'18.04'!$AZ$4,'18.04'!$AZ$3)),(VLOOKUP('18.04'!K93,'18.04'!$AM$4:$AO$55,2,FALSE))*IF('18.04'!$AK93="是",'18.04'!$AZ$4,'18.04'!$AZ$3)) -> 0 | D93: =IF(ISNUMBER(SEARCH("营",'18.04'!L93)),(-$Y93+50*IF('18.04'!$AK93="是",'18.04'!$AZ$4,'18.04'!$AZ$3)),(VLOOKUP('18.04'!L93,'18.04'!$AM$4:$AO$55,2,FALSE))*IF('18.04'!$AK93="是",'18.04'!$AZ$4,'18.04'!$AZ$3)) -> 0 | E93: =IF(ISNUMBER(SEARCH("营",'18.04'!M93)),(-$Y93+50*IF('18.04'!$AK93="是",'18.04'!$AZ$4,'18.04'!$AZ$3)),(VLOOKUP('18.04'!M93,'18.04'!$AM$4:$AO$55,2,FALSE))*IF('18.04'!$AK93="是",'18.04'!$AZ$4,'18.04'!$AZ$3)) -> 0 | F93: =IF(ISNUMBER(SEARCH("营",'18.04'!N93)),(-$Y93+50*IF('18.04'!$AK93="是",'18.04'!$AZ$4,'18.04'!$AZ$3)),(VLOOKUP('18.04'!N93,'18.04'!$AM$4:$AO$55,2,FALSE))*IF('18.04'!$AK93="是",'18.04'!$AZ$4,'18.04'!$AZ$3)) -> 0 | G93: =IF(ISNUMBER(SEARCH("营",'18.04'!O93)),(-$Y93+50*IF('18.04'!$AK93="是",'18.04'!$AZ$4,'18.04'!$AZ$3)),(VLOOKUP('18.04'!O93,'18.04'!$AM$4:$AO$55,2,FALSE))*IF('18.04'!$AK93="是",'18.04'!$AZ$4,'18.04'!$AZ$3)) -> 0 | H93: =IF(ISNUMBER(SEARCH("营",'18.04'!P93)),(-$Y93+50*IF('18.04'!$AK93="是",'18.04'!$AZ$4,'18.04'!$AZ$3)),(VLOOKUP('18.04'!P93,'18.04'!$AM$4:$AO$55,2,FALSE))*IF('18.04'!$AK93="是",'18.04'!$AZ$4,'18.04'!$AZ$3)) -> 0 | ... X93: =IF(ISNUMBER(SEARCH("营",'18.04'!AF93)),(-$Y93+50*IF('18.04'!$AK93="是",'18.04'!$AZ$4,'18.04'!$AZ$3)),(VLOOKUP('18.04'!AF93,'18.04'!$AM$4:$AO$55,2,FALSE))*IF('18.04'!$AK93="是",'18.04'!$AZ$4,'18.04'!$AZ$3)) -> 0 | Y93: 100 | Z93: 45728

Sheet 经验
A2: 队伍一 风 | C2: 步数 | D2: =COUNTIF(A4:H94,"<>空") -> 728 | E2: (不算跳步和传送) | I2: 队伍二 雷 | K2: 步数 | L2: =COUNTIF(I4:P94,"<>空") -> 728 | M2: (不算跳步和传送) | Q2: 队伍三 | S2: 总步数 | T2: =COUNTIF(Q4:X94,"<>空") -> 728 | U2: (不算跳步和传送)
A3: 1 | B3: 2 | C3: 3 | D3: 4 | E3: 5 | F3: 6 | G3: 7 | H3: 8 | I3: 1 | J3: 2 | K3: 3 | L3: 4 | M3: 5 | N3: 6 | O3: 7 | P3: 8 | Q3: 1 | R3: 2 | S3: 3 | T3: 4 | U3: 5 | V3: 6 | W3: 7 | X3: 8
A4: =(VLOOKUP('18.04'!I4,'18.04'!$AM$4:$AO$55,3,FALSE)) -> 35 | B4: =(VLOOKUP('18.04'!J4,'18.04'!$AM$4:$AO$55,3,FALSE)) -> 35 | C4: =(VLOOKUP('18.04'!K4,'18.04'!$AM$4:$AO$55,3,FALSE)) -> 35 | D4: =(VLOOKUP('18.04'!L4,'18.04'!$AM$4:$AO$55,3,FALSE)) -> 35 | E4: =(VLOOKUP('18.04'!M4,'18.04'!$AM$4:$AO$55,3,FALSE)) -> 35 | F4: =(VLOOKUP('18.04'!N4,'18.04'!$AM$4:$AO$55,3,FALSE)) -> 0 | G4: =(VLOOKUP('18.04'!O4,'18.04'!$AM$4:$AO$55,3,FALSE)) -> 0 | H4: =(VLOOKUP('18.04'!P4,'18.04'!$AM$4:$AO$55,3,FALSE)) -> 0 | ... X4: =(VLOOKUP('18.04'!AF4,'18.04'!$AM$4:$AO$55,3,FALSE)) -> 0
A5: =(VLOOKUP('18.04'!I5,'18.04'!$AM$4:$AO$55,3,FALSE)) -> 0 | B5: =(VLOOKUP('18.04'!J5,'18.04'!$AM$4:$AO$55,3,FALSE)) -> 0 | C5: =(VLOOKUP('18.04'!K5,'18.04'!$AM$4:$AO$55,3,FALSE)) -> 0 | D5: =(VLOOKUP('18.04'!L5,'18.04'!$AM$4:$AO$55,3,FALSE)) -> 0 | E5: =(VLOOKUP('18.04'!M5,'18.04'!$AM$4:$AO$55,3,FALSE)) -> 0 | F5: =(VLOOKUP('18.04'!N5,'18.04'!$AM$4:$AO$55,3,FALSE)) -> 0 | G5: =(VLOOKUP('18.04'!O5,'18.04'!$AM$4:$AO$55,3,FALSE)) -> 0 | H5: =(VLOOKUP('18.04'!P5,'18.04'!$AM$4:$AO$55,3,FALSE)) -> 0 | ... X5: =(VLOOKUP('18.04'!AF5,'18.04'!$AM$4:$AO$55,3,FALSE)) -> 40
A6: =(VLOOKUP('18.04'!I6,'18.04'!$AM$4:$AO$55,3,FALSE)) -> 0 | B6: =(VLOOKUP('18.04'!J6,'18.04'!$AM$4:$AO$55,3,FALSE)) -> 0 | C6: =(VLOOKUP('18.04'!K6,'18.04'!$AM$4:$AO$55,3,FALSE)) -> 0 | D6: =(VLOOKUP('18.04'!L6,'18.04'!$AM$4:$AO$55,3,FALSE)) -> 0 | E6: =(VLOOKUP('18.04'!M6,'18.04'!$AM$4:$AO$55,3,FALSE)) -> 0 | F6: =(VLOOKUP('18.04'!N6,'18.04'!$AM$4:$AO$55,3,FALSE)) -> 0 | G6: =(VLOOKUP('18.04'!O6,'18.04'!$AM$4:$AO$55,3,FALSE)) -> 0 | H6: =(VLOOKUP('18.04'!P6,'18.04'!$AM$4:$AO$55,3,FALSE)) -> 0 | ... X6: =(VLOOKUP('18.04'!AF6,'18.04'!$AM$4:$AO$55,3,FALSE)) -> 40
A7: =(VLOOKUP('18.04'!I7,'18.04'!$AM$4:$AO$55,3,FALSE)) -> 0 | B7: =(VLOOKUP('18.04'!J7,'18.04'!$AM$4:$AO$55,3,FALSE)) -> 0 | C7: =(VLOOKUP('18.04'!K7,'18.04'!$AM$4:$AO$55,3,FALSE)) -> 0 | D7: =(VLOOKUP('18.04'!L7,'18.04'!$AM$4:$AO$55,3,FALSE)) -> 0 | E7: =(VLOOKUP('18.04'!M7,'18.04'!$AM$4:$AO$55,3,FALSE)) -> 0 | F7: =(VLOOKUP('18.04'!N7,'18.04'!$AM$4:$AO$55,3,FALSE)) -> 0 | G7: =(VLOOKUP('18.04'!O7,'18.04'!$AM$4:$AO$55,3,FALSE)) -> 0 | H7: =(VLOOKUP('18.04'!P7,'18.04'!$AM$4:$AO$55,3,FALSE)) -> 0 | ... X7: =(VLOOKUP('18.04'!AF7,'18.04'!$AM$4:$AO$55,3,FALSE)) -> 45
A8: =(VLOOKUP('18.04'!I8,'18.04'!$AM$4:$AO$55,3,FALSE)) -> 0 | B8: =(VLOOKUP('18.04'!J8,'18.04'!$AM$4:$AO$55,3,FALSE)) -> 0 | C8: =(VLOOKUP('18.04'!K8,'18.04'!$AM$4:$AO$55,3,FALSE)) -> 0 | D8: =(VLOOKUP('18.04'!L8,'18.04'!$AM$4:$AO$55,3,FALSE)) -> 0 | E8: =(VLOOKUP('18.04'!M8,'18.04'!$AM$4:$AO$55,3,FALSE)) -> 0 | F8: =(VLOOKUP('18.04'!N8,'18.04'!$AM$4:$AO$55,3,FALSE)) -> 0 | G8: =(VLOOKUP('18.04'!O8,'18.04'!$AM$4:$AO$55,3,FALSE)) -> 0 | H8: =(VLOOKUP('18.04'!P8,'18.04'!$AM$4:$AO$55,3,FALSE)) -> 0 | ... X8: =(VLOOKUP('18.04'!AF8,'18.04'!$AM$4:$AO$55,3,FALSE)) -> 45
A9: =(VLOOKUP('18.04'!I9,'18.04'!$AM$4:$AO$55,3,FALSE)) -> 0 | B9: =(VLOOKUP('18.04'!J9,'18.04'!$AM$4:$AO$55,3,FALSE)) -> 0 | C9: =(VLOOKUP('18.04'!K9,'18.04'!$AM$4:$AO$55,3,FALSE)) -> 0 | D9: =(VLOOKUP('18.04'!L9,'18.04'!$AM$4:$AO$55,3,FALSE)) -> 0 | E9: =(VLOOKUP('18.04'!M9,'18.04'!$AM$4:$AO$55,3,FALSE)) -> 0 | F9: =(VLOOKUP('18.04'!N9,'18.04'!$AM$4:$AO$55,3,FALSE)) -> 0 | G9: =(VLOOKUP('18.04'!O9,'18.04'!$AM$4:$AO$55,3,FALSE)) -> 0 | H9: =(VLOOKUP('18.04'!P9,'18.04'!$AM$4:$AO$55,3,FALSE)) -> 0 | ... X9: =(VLOOKUP('18.04'!AF9,'18.04'!$AM$4:$AO$55,3,FALSE)) -> 0
A10: =(VLOOKUP('18.04'!I10,'18.04'!$AM$4:$AO$55,3,FALSE)) -> 35 | B10: =(VLOOKUP('18.04'!J10,'18.04'!$AM$4:$AO$55,3,FALSE)) -> 35 | C10: =(VLOOKUP('18.04'!K10,'18.04'!$AM$4:$AO$55,3,FALSE)) -> 35 | D10: =(VLOOKUP('18.04'!L10,'18.04'!$AM$4:$AO$55,3,FALSE)) -> 35 | E10: =(VLOOKUP('18.04'!M10,'18.04'!$AM$4:$AO$55,3,FALSE)) -> 30 | F10: =(VLOOKUP('18.04'!N10,'18.04'!$AM$4:$AO$55,3,FALSE)) -> 35 | G10: =(VLOOKUP('18.04'!O10,'18.04'!$AM$4:$AO$55,3,FALSE)) -> 35 | H10: =(VLOOKUP('18.04'!P10,'18.04'!$AM$4:$AO$55,3,FALSE)) -> 35 | ... X10: =(VLOOKUP('18.04'!AF10,'18.04'!$AM$4:$AO$55,3,FALSE)) -> 0
A11: =(VLOOKUP('18.04'!I11,'18.04'!$AM$4:$AO$55,3,FALSE)) -> 35 | B11: =(VLOOKUP('18.04'!J11,'18.04'!$AM$4:$AO$55,3,FALSE)) -> 35 | C11: =(VLOOKUP('18.04'!K11,'18.04'!$AM$4:$AO$55,3,FALSE)) -> 30 | D11: =(VLOOKUP('18.04'!L11,'18.04'!$AM$4:$AO$55,3,FALSE)) -> 35 | E11: =(VLOOKUP('18.04'!M11,'18.04'!$AM$4:$AO$55,3,FALSE)) -> 35 | F11: =(VLOOKUP('18.04'!N11,'18.04'!$AM$4:$AO$55,3,FALSE)) -> 35 | G11: =(VLOOKUP('18.04'!O11,'18.04'!$AM$4:$AO$55,3,FALSE)) -> 35 | H11: =(VLOOKUP('18.04'!P11,'18.04'!$AM$4:$AO$55,3,FALSE)) -> 35 | ... X11: =(VLOOKUP('18.04'!AF11,'18.04'!$AM$4:$AO$55,3,FALSE)) -> 0
A12: =(VLOOKUP('18.04'!I12,'18.04'!$AM$4:$AO$55,3,FALSE)) -> 35 | B12: =(VLOOKUP('18.04'!J12,'18.04'!$AM$4:$AO$55,3,FALSE)) -> 35 | C12: =(VLOOKUP('18.04'!K12,'18.04'!$AM$4:$AO$55,3,FALSE)) -> 30 | D12: =(VLOOKUP('18.04'!L12,'18.04'!$AM$4:$AO$55,3,FALSE)) -> 40 | E12: =(VLOOKUP('18.04'!M12,'18.04'!$AM$4:$AO$55,3,FALSE)) -> 40 | F12: =(VLOOKUP('18.04'!N12,'18.04'!$AM$4:$AO$55,3,FALSE)) -> 40 | G12: =(VLOOKUP('18.04'!O12,'18.04'!$AM$4:$AO$55,3,FALSE)) -> 0 | H12: =(VLOOKUP('18.04'!P12,'18.04'!$AM$4:$AO$55,3,FALSE)) -> 40 | ... X12: =(VLOOKUP('18.04'!AF12,'18.04'!$AM$4:$AO$55,3,FALSE)) -> 0
