Workbook

Sheet 8.0.0
A1: =(_xlfn.DAYS(TODAY(),A4)+2)/((_xlfn.DAYS(A94,A4))+1) -> 0.054945055 | I1: 工作区 | AM1: 使用方法：按自己规划的路线，将下表中的地块名复制粘贴至工作区。初次使用传送门，当天跳步次数+5。重复使用传送门，当天跳步次数+1
A2: version 8.0.0 | B2: 八卦前亏 | C2: =SUM(亏损!A4:X94)+SUM(AG4:AG14)*10 -> 29663.768 | D2: 合计经验 | F2: =SUM(F4:F94)+SUM(H4:H94) -> 65160 | I2: 队伍一 火 | K2: 步数 | L2: =COUNTIF(I4:P94,"<>空") -> 538 | M2: (不算跳步和传送) | Q2: 队伍二 雷 | S2: 步数 | T2: =COUNTIF(Q4:X94,"<>空") -> 71 | U2: (不算跳步和传送) | Y2: 队伍三 | AA2: 总步数 | AB2: =COUNTIF(Y4:AF94,"<>空") -> 468 | AC2: (不算跳步和传送) | AG2: =SUM(AG4:AG94) -> 21 | AH2: =SUM(AH4:AH94) -> 11 | AI2: =SUM(AI4:AI94) -> 2 | AJ2: =SUM(AJ4:AJ94) -> 8 | AK2: 八卦全开 | AS2: 总地块 | AT2: =SUM(AT4:AT29) -> 1077 | AV2: 总经验 | AW2: =SUM(AU4:AW29)+7000 -> 65160 | AY2: 粮草系数
A3: 日期 | B3: 获得粮草 | C3: 种植粮草 | D3: 消耗粮草 | E3: 剩余粮草 | F3: 获得经验 | G3: 累计经验 | H3: 任务经验 | I3: 1 | J3: 2 | K3: 3 | L3: 4 | M3: 5 | N3: 6 | O3: 7 | P3: 8 | Q3: 1 | R3: 2 | S3: 3 | T3: 4 | U3: 5 | V3: 6 | W3: 7 | X3: 8 | Y3: 1 | Z3: 2 | AA3: 3 | AB3: 4 | AC3: 5 | AD3: 6 | AE3: 7 | AF3: 8 | AG3: 跳步次数 | AH3: 1队跳步 | AI3: 2队跳步 | AJ3: 3队跳步 | AM3: 地块 | AN3: 粮草 | AO3: 经验 | AP3: 八卦前亏损 | AQ3: 一队地块 | AR3: 二队地块 | AS3: 三队地块 | AT3: 总地块 | AU3: 一队经验 | AV3: 二队经验 | AW3: 三队经验 | AX3: 八卦前 | AY3: 1
A4: 44729 | B4: 800 | C4: 6000 | D4: =(SUM(粮草!A4:X4)+AG4*10)*IF(AK4="是",$AY$4,$AY$3) -> 2770 | E4: =SUM($B$4:B4)+SUM($C$4:C4)-SUM($D$4:D4) -> 4030 | F4: =SUM(经验!A4:X4) -> 1240 | G4: =SUM($F$4:F4)+SUM($H$4:H4) -> 1740 | H4: 500 | I4: 1级 | J4: 1级 | K4: 1级 | L4: 1级 | M4: 1级 | N4: 1级 | O4: 空 | P4: 空 | Q4: 商人 | R4: 2级 | S4: 2级 | T4: 2级 | U4: 2级 | V4: 2级 | W4: 空 | X4: 2级 | Y4: 2级 | Z4: 营地 | AA4: 2级 | AB4: 历练 | AC4: 2级 | AD4: 2级 | AE4: 2级 | AF4: 2级 | AG4: =AH4+AI4+AJ4 -> 0 | AK4: 否 | AM4: 1级 | AN4: 150 | AO4: 35 | AP4: 44.222109 | AQ4: =COUNTIF($I$4:$P$94,AM4) -> 6 | AR4: =COUNTIF($Q$4:$X$94,AM4) -> 5 | AS4: =COUNTIF($Y$4:$AF$94,AM4) -> 0 | AT4: =AQ4+AR4+AS4 -> 11 | AU4: =AQ4*$AO4 -> 210 | AV4: =AR4*$AO4 -> 175 | AW4: =AS4*$AO4 -> 0 | AX4: 八卦后 | AY4: 0.8 | BA4: =AN4*0.8 -> 120
A5: 44730 | B5: 1600 | D5: =(SUM(粮草!A5:X5)+AG5*10)*IF(AK5="是",$AY$4,$AY$3)-50 -> 2000 | E5: =SUM($B$4:B5)+SUM($C$4:C5)-SUM($D$4:D5) -> 3630 | F5: =SUM(经验!A5:X5) -> 675 | G5: =SUM($F$4:F5)+SUM($H$4:H5) -> 2415 | H5: 0 | I5: 3级 | J5: 3级 | K5: 商人 | L5: 3级 | M5: 3级 | N5: 3级 | O5: 空 | P5: 空 | Q5: 空 | R5: 空 | S5: 空 | T5: 空 | U5: 空 | V5: 空 | W5: 空 | X5: 空 | Y5: 2级 | Z5: 3级 | AA5: 3级 | AB5: 3级 | AC5: 大卦 | AD5: 3级 | AE5: 空 | AF5: 空 | AG5: =AH5+AI5+AJ5 -> 6 | AH5: 1 | AJ5: 5 | AK5: 否 | AM5: 2级 | AN5: 160 | AO5: 40 | AP5: 39.110982 | AQ5: =COUNTIF($I$4:$P$94,AM5) -> 0 | AR5: =COUNTIF($Q$4:$X$94,AM5) -> 48 | AS5: =COUNTIF($Y$4:$AF$94,AM5) -> 7 | AT5: =AQ5+AR5+AS5 -> 55 | AU5: =AQ5*$AO5 -> 0 | AV5: =AR5*$AO5 -> 1920 | AW5: =AS5*$AO5 -> 280 | AX5: Note：开完八卦当天可能需要手动计算粮草 | BA5: =AN5*0.8 -> 128
A6: 44731 | B6: 1600 | D6: =(SUM(粮草!A6:X6)+AG6*10)*IF(AK6="是",$AY$4,$AY$3) -> 2060 | E6: =SUM($B$4:B6)+SUM($C$4:C6)-SUM($D$4:D6) -> 3170 | F6: =SUM(经验!A6:X6) -> 585 | G6: =SUM($F$4:F6)+SUM($H$4:H6) -> 3000 | H6: 0 | I6: 小卦 | J6: 3级 | K6: 3级 | L6: 3级 | M6: 3级 | N6: 3级 | O6: 空 | P6: 空 | Q6: 空 | R6: 空 | S6: 空 | T6: 空 | U6: 空 | V6: 空 | W6: 空 | X6: 空 | Y6: 3级 | Z6: 3级 | AA6: 营地 | AB6: 3级 | AC6: 3级 | AD6: 3级 | AE6: 小卦 | AF6: 3级 | AG6: =AH6+AI6+AJ6 -> 0 | AK6: 否 | AM6: 3级 | AN6: 170 | AO6: 45 | AP6: 34 | AQ6: =COUNTIF($I$4:$P$94,AM6) -> 28 | AR6: =COUNTIF($Q$4:$X$94,AM6) -> 0 | AS6: =COUNTIF($Y$4:$AF$94,AM6) -> 205 | AT6: =AQ6+AR6+AS6 -> 233 | AU6: =AQ6*$AO6 -> 1260 | AV6: =AR6*$AO6 -> 0 | AW6: =AS6*$AO6 -> 9225 | BA6: =AN6*0.8 -> 136
A7: 44732 | B7: 1600 | D7: =(SUM(粮草!A7:X7)+AG7*10)*IF(AK7="是",$AY$4,$AY$3) -> 2040 | E7: =SUM($B$4:B7)+SUM($C$4:C7)-SUM($D$4:D7) -> 2730 | F7: =SUM(经验!A7:X7) -> 540 | G7: =SUM($F$4:F7)+SUM($H$4:H7) -> 3740 | H7: 200 | I7: 3级 | J7: 3级 | K7: 小卦 | L7: 3级 | M7: 3级 | N7: 3级 | O7: 空 | P7: 空 | Q7: 空 | R7: 空 | S7: 空 | T7: 空 | U7: 空 | V7: 空 | W7: 空 | X7: 空 | Y7: 3级 | Z7: 3级 | AA7: 3级 | AB7: 3级 | AC7: 3级 | AD7: 3级 | AE7: 空 | AF7: 空 | AG7: =AH7+AI7+AJ7 -> 0 | AK7: 否 | AM7: 4级 | AN7: 180 | AO7: 50 | AP7: 36 | AQ7: =COUNTIF($I$4:$P$94,AM7) -> 104 | AR7: =COUNTIF($Q$4:$X$94,AM7) -> 0 | AS7: =COUNTIF($Y$4:$AF$94,AM7) -> 161 | AT7: =AQ7+AR7+AS7 -> 265 | AU7: =AQ7*$AO7 -> 5200 | AV7: =AR7*$AO7 -> 0 | AW7: =AS7*$AO7 -> 8050 | BA7: =AN7*0.8 -> 144
A8: 44733 | B8: 1600 | D8: =(SUM(粮草!A8:X8)+AG8*10)*IF(AK8="是",$AY$4,$AY$3) -> 2200 | E8: =SUM($B$4:B8)+SUM($C$4:C8)-SUM($D$4:D8) -> 2130 | F8: =SUM(经验!A8:X8) -> 895 | G8: =SUM($F$4:F8)+SUM($H$4:H8) -> 4735 | H8: 100 | I8: 3级 | J8: 塔3 | K8: 3级 | L8: 大卦 | M8: 3级 | N8: 3级 | O8: 营地 | P8: 3级 | Q8: 空 | R8: 空 | S8: 空 | T8: 空 | U8: 空 | V8: 空 | W8: 空 | X8: 空 | Y8: 大卦 | Z8: 3级 | AA8: 3级 | AB8: 3级 | AC8: 3级 | AD8: 3级 | AE8: 空 | AF8: 空 | AG8: =AH8+AI8+AJ8 -> 0 | AK8: 否 | AM8: 5级 | AN8: 190 | AO8: 55 | AP8: 38 | AQ8: =COUNTIF($I$4:$P$94,AM8) -> 177 | AR8: =COUNTIF($Q$4:$X$94,AM8) -> 0 | AS8: =COUNTIF($Y$4:$AF$94,AM8) -> 57 | AT8: =AQ8+AR8+AS8 -> 234 | AU8: =AQ8*$AO8 -> 9735 | AV8: =AR8*$AO8 -> 0 | AW8: =AS8*$AO8 -> 3135 | BA8: =AN8*0.8 -> 152
A9: 44734 | B9: 1600 | D9: =(SUM(粮草!A9:X9)+AG9*10)*IF(AK9="是",$AY$4,$AY$3) -> 1580 | E9: =SUM($B$4:B9)+SUM($C$4:C9)-SUM($D$4:D9) -> 2150 | F9: =SUM(经验!A9:X9) -> 435 | G9: =SUM($F$4:F9)+SUM($H$4:H9) -> 5370 | H9: 200 | I9: 3级 | J9: 3级 | K9: 商人 | L9: 3级 | M9: 3级 | N9: 小卦 | O9: 空 | P9: 空 | Q9: 空 | R9: 空 | S9: 空 | T9: 空 | U9: 空 | V9: 空 | W9: 空 | X9: 空 | Y9: 3级 | Z9: 3级 | AA9: 3级 | AB9: 小卦 | AC9: 空 | AD9: 空 | AE9: 空 | AF9: 空 | AG9: =AH9+AI9+AJ9 -> 0 | AK9: 否 | AM9: 6级 | AN9: 200 | AO9: 60 | AQ9: =COUNTIF($I$4:$P$94,AM9) -> 194 | AR9: =COUNTIF($Q$4:$X$94,AM9) -> 0 | AS9: =COUNTIF($Y$4:$AF$94,AM9) -> 0 | AT9: =AQ9+AR9+AS9 -> 194 | AU9: =AQ9*$AO9 -> 11640 | AV9: =AR9*$AO9 -> 0 | AW9: =AS9*$AO9 -> 0 | BA9: =AN9*0.8 -> 160
A10: 44735 | B10: 1600 | D10: =(SUM(粮草!A10:X10)+AG10*10)*IF(AK10="是",$AY$4,$AY$3) -> 1448 | E10: =SUM($B$4:B10)+SUM($C$4:C10)-SUM($D$4:D10) -> 2302 | F10: =SUM(经验!A10:X10) -> 515 | G10: =SUM($F$4:F10)+SUM($H$4:H10) -> 5885 | H10: 0 | I10: 3级 | J10: 3级 | K10: 商人 | L10: 3级 | M10: 3级 | N10: 4级 | O10: 空 | P10: 空 | Q10: 空 | R10: 空 | S10: 空 | T10: 空 | U10: 空 | V10: 空 | W10: 空 | X10: 空 | Y10: 3级 | Z10: 3级 | AA10: 商人 | AB10: 3级 | AC10: 3级 | AD10: 3级 | AE10: 空 | AF10: 空 | AG10: =AH10+AI10+AJ10 -> 0 | AK10: 是 | AM10: 塔1 | AN10: 150 | AO10: 35 | AP10: 44.222109 | AQ10: =COUNTIF($I$4:$P$94,AM10) -> 0 | AR10: =COUNTIF($Q$4:$X$94,AM10) -> 0 | AS10: =COUNTIF($Y$4:$AF$94,AM10) -> 0 | AT10: =AQ10+AR10+AS10 -> 0 | AU10: =AQ10*$AO10 -> 0 | AV10: =AR10*$AO10 -> 0 | AW10: =AS10*$AO10 -> 0 | BA10: =AN10*0.8 -> 120
A11: 44736 | B11: 1600 | D11: =(SUM(粮草!A11:X11)+AG11*10)*IF(AK11="是",$AY$4,$AY$3) -> 1600 | E11: =SUM($B$4:B11)+SUM($C$4:C11)-SUM($D$4:D11) -> 2302 | F11: =SUM(经验!A11:X11) -> 600 | G11: =SUM($F$4:F11)+SUM($H$4:H11) -> 6485 | H11: 0 | I11: 4级 | J11: 4级 | K11: 商人 | L11: 4级 | M11: 4级 | N11: 营地+ | O11: 4级 | P11: 4级 | Q11: 空 | R11: 空 | S11: 空 | T11: 空 | U11: 空 | V11: 空 | W11: 空 | X11: 空 | Y11: 3级 | Z11: 3级 | AA11: 3级 | AB11: 3级 | AC11: 3级 | AD11: 3级 | AE11: 空 | AF11: 空 | AG11: =AH11+AI11+AJ11 -> 5 | AH11: 5 | AK11: 是 | AM11: 塔2 | AN11: 150 | AO11: 40 | AP11: 29.110982 | AQ11: =COUNTIF($I$4:$P$94,AM11) -> 0 | AR11: =COUNTIF($Q$4:$X$94,AM11) -> 2 | AS11: =COUNTIF($Y$4:$AF$94,AM11) -> 0 | AT11: =AQ11+AR11+AS11 -> 2 | AU11: =AQ11*$AO11 -> 0 | AV11: =AR11*$AO11 -> 80 | AW11: =AS11*$AO11 -> 0 | BA11: =AN11*0.8 -> 120
A12: 44737 | B12: 1600 | D12: =(SUM(粮草!A12:X12)+AG12*10)*IF(AK12="是",$AY$4,$AY$3) -> 1680 | E12: =SUM($B$4:B12)+SUM($C$4:C12)-SUM($D$4:D12) -> 2222 | F12: =SUM(经验!A12:X12) -> 570 | G12: =SUM($F$4:F12)+SUM($H$4:H12) -> 7055 | H12: 0 | I12: 4级 | J12: 4级 | K12: 4级 | L12: 4级 | M12: 4级 | N12: 4级 | O12: 空 | P12: 空 | Q12: 空 | R12: 空 | S12: 空 | T12: 空 | U12: 空 | V12: 空 | W12: 空 | X12: 空 | Y12: 3级 | Z12: 3级 | AA12: 3级 | AB12: 3级 | AC12: 3级 | AD12: 3级 | AE12: 空 | AF12: 空 | AG12: =AH12+AI12+AJ12 -> 0 | AK12: 是 | AM12: 塔3 | AN12: 150 | AO12: 45 | AP12: 13.999855 | AQ12: =COUNTIF($I$4:$P$94,AM12) -> 1 | AR12: =COUNTIF($Q$4:$X$94,AM12) -> 0 | AS12: =COUNTIF($Y$4:$AF$94,AM12) -> 5 | AT12: =AQ12+AR12+AS12 -> 6 | AU12: =AQ12*$AO12 -> 45 | AV12: =AR12*$AO12 -> 0 | AW12: =AS12*$AO12 -> 225 | BA12: =AN12*0.8 -> 120
A13: 44738 | B13: 1600 | D13: =(SUM(粮草!A13:X13)+AG13*10)*IF(AK13="是",$AY$4,$AY$3) -> 1584 | E13: =SUM($B$4:B13)+SUM($C$4:C13)-SUM($D$4:D13) -> 2238 | F13: =SUM(经验!A13:X13) -> 555 | G13: =SUM($F$4:F13)+SUM($H$4:H13) -> 7610 | H13: 0 | I13: 4级 | J13: 4级 | K13: 4级 | L13: 4级 | M13: 4级 | N13: 4级 | O13: 空 | P13: 空 | Q13: 空 | R13: 空 | S13: 空 | T13: 空 | U13: 空 | V13: 空 | W13: 空 | X13: 空 | Y13: 商人 | Z13: 3级 | AA13: 3级 | AB13: 3级 | AC13: 3级 | AD13: 3级 | AE13: 空 | AF13: 空 | AG13: =AH13+AI13+AJ13 -> 0 | AK13: 是 | AM13: 塔4 | AN13: 150 | AO13: 50 | AQ13: =COUNTIF($I$4:$P$94,AM13) -> 2 | AR13: =COUNTIF($Q$4:$X$94,AM13) -> 0 | AS13: =COUNTIF($Y$4:$AF$94,AM13) -> 2 | AT13: =AQ13+AR13+AS13 -> 4 | AU13: =AQ13*$AO13 -> 100 | AV13: =AR13*$AO13 -> 0 | AW13: =AS13*$AO13 -> 100 | BA13: =AN13*0.8 -> 120
A14: 44739 | B14: 1600 | D14: =(SUM(粮草!A14:X14)+AG14*10)*IF(AK14="是",$AY$4,$AY$3) -> 1680 | E14: =SUM($B$4:B14)+SUM($C$4:C14)-SUM($D$4:D14) -> 2158 | F14: =SUM(经验!A14:X14) -> 570 | G14: =SUM($F$4:F14)+SUM($H$4:H14) -> 8480 | H14: 300 | I14: 4级 | J14: 4级 | K14: 4级 | L14: 4级 | M14: 4级 | N14: 4级 | O14: 空 | P14: 空 | Q14: 空 | R14: 空 | S14: 空 | T14: 空 | U14: 空 | V14: 空 | W14: 空 | X14: 空 | Y14: 3级 | Z14: 3级 | AA14: 3级 | AB14: 3级 | AC14: 3级 | AD14: 3级 | AE14: 空 | AF14: 空 | AG14: =AH14+AI14+AJ14 -> 0 | AK14: 是 | AM14: 塔5 | AN14: 150 | AO14: 55 | AQ14: =COUNTIF($I$4:$P$94,AM14) -> 2 | AR14: =COUNTIF($Q$4:$X$94,AM14) -> 0 | AS14: =COUNTIF($Y$4:$AF$94,AM14) -> 1 | AT14: =AQ14+AR14+AS14 -> 3 | AU14: =AQ14*$AO14 -> 110 | AV14: =AR14*$AO14 -> 0 | AW14: =AS14*$AO14 -> 55 | BA14: =AN14*0.8 -> 120
A15: 44740 | B15: 1600 | D15: =(SUM(粮草!A15:X15)+AG15*10)*IF(AK15="是",$AY$4,$AY$3) -> 1680 | E15: =SUM($B$4:B15)+SUM($C$4:C15)-SUM($D$4:D15) -> 2078 | F15: =SUM(经验!A15:X15) -> 570 | G15: =SUM($F$4:F15)+SUM($H$4:H15) -> 9050 | H15: 0 | I15: 4级 | J15: 4级 | K15: 4级 | L15: 4级 | M15: 4级 | N15: 4级 | O15: 空 | P15: 空 | Q15: 空 | R15: 空 | S15: 空 | T15: 空 | U15: 空 | V15: 空 | W15: 空 | X15: 空 | Y15: 3级 | Z15: 3级 | AA15: 3级 | AB15: 3级 | AC15: 3级 | AD15: 3级 | AE15: 空 | AF15: 空 | AG15: =AH15+AI15+AJ15 -> 0 | AK15: 是 | AM15: 塔6 | AN15: 150 | AO15: 60 | AQ15: =COUNTIF($I$4:$P$94,AM15) -> 1 | AR15: =COUNTIF($Q$4:$X$94,AM15) -> 0 | AS15: =COUNTIF($Y$4:$AF$94,AM15) -> 0 | AT15: =AQ15+AR15+AS15 -> 1 | AU15: =AQ15*$AO15 -> 60 | AV15: =AR15*$AO15 -> 0 | AW15: =AS15*$AO15 -> 0 | BA15: =AN15*0.8 -> 120
A16: 44741 | B16: 1600 | D16: =(SUM(粮草!A16:X16)+AG16*10)*IF(AK16="是",$AY$4,$AY$3) -> 1680 | E16: =SUM($B$4:B16)+SUM($C$4:C16)-SUM($D$4:D16) -> 1998 | F16: =SUM(经验!A16:X16) -> 570 | G16: =SUM($F$4:F16)+SUM($H$4:H16) -> 9820 | H16: 200 | I16: 4级 | J16: 4级 | K16: 4级 | L16: 4级 | M16: 4级 | N16: 4级 | O16: 空 | P16: 空 | Q16: 空 | R16: 空 | S16: 空 | T16: 空 | U16: 空 | V16: 空 | W16: 空 | X16: 空 | Y16: 3级 | Z16: 3级 | AA16: 3级 | AB16: 3级 | AC16: 3级 | AD16: 3级 | AE16: 空 | AF16: 空 | AG16: =AH16+AI16+AJ16 -> 0 | AK16: 是 | AM16: 遗迹 | AN16: 150 | AO16: 35 | AP16: 44.222109 | AQ16: =COUNTIF($I$4:$P$94,AM16) -> 0 | AR16: =COUNTIF($Q$4:$X$94,AM16) -> 0 | AS16: =COUNTIF($Y$4:$AF$94,AM16) -> 0 | AT16: =AQ16+AR16+AS16 -> 0 | AU16: =AQ16*$AO16 -> 0 | AV16: =AR16*$AO16 -> 0 | AW16: =AS16*$AO16 -> 0 | BA16: =AN16*0.8 -> 120
A17: 44742 | B17: 1600 | D17: =(SUM(粮草!A17:X17)+AG17*10)*IF(AK17="是",$AY$4,$AY$3) -> 1592 | E17: =SUM($B$4:B17)+SUM($C$4:C17)-SUM($D$4:D17) -> 2006 | F17: =SUM(经验!A17:X17) -> 555 | G17: =SUM($F$4:F17)+SUM($H$4:H17) -> 10375 | H17: 0 | I17: 4级 | J17: 4级 | K17: 4级 | L17: 4级 | M17: 4级 | N17: 4级 | O17: 空 | P17: 空 | Q17: 空 | R17: 空 | S17: 空 | T17: 空 | U17: 空 | V17: 空 | W17: 空 | X17: 空 | Y17: 3级 | Z17: 商人 | AA17: 3级 | AB17: 3级 | AC17: 3级 | AD17: 3级 | AE17: 空 | AF17: 空 | AG17: =AH17+AI17+AJ17 -> 1 | AJ17: 1 | AK17: 是 | AM17: 商人 | AN17: 50 | AO17: 30 | AP17: 10 | AQ17: =COUNTIF($I$4:$P$94,AM17) -> 8 | AR17: =COUNTIF($Q$4:$X$94,AM17) -> 14 | AS17: =COUNTIF($Y$4:$AF$94,AM17) -> 17 | AT17: =AQ17+AR17+AS17 -> 39 | AU17: =AQ17*$AO17 -> 240 | AV17: =AR17*$AO17 -> 420 | AW17: =AS17*$AO17 -> 510 | BA17: =AN17*0.8 -> 40
A18: 44743 | B18: 1600 | D18: =(SUM(粮草!A18:X18)+AG18*10)*IF(AK18="是",$AY$4,$AY$3) -> 1664 | E18: =SUM($B$4:B18)+SUM($C$4:C18)-SUM($D$4:D18) -> 1942 | F18: =SUM(经验!A18:X18) -> 570 | G18: =SUM($F$4:F18)+SUM($H$4:H18) -> 10945 | H18: 0 | I18: 4级 | J18: 4级 | K18: 4级 | L18: 4级 | M18: 4级 | N18: 4级 | O18: 空 | P18: 空 | Q18: 空 | R18: 空 | S18: 空 | T18: 空 | U18: 空 | V18: 空 | W18: 空 | X18: 空 | Y18: 3级 | Z18: 3级 | AA18: 3级 | AB18: 3级 | AC18: 塔3 | AD18: 3级 | AE18: 空 | AF18: 空 | AG18: =AH18+AI18+AJ18 -> 0 | AK18: 是 | AL18: 八卦前 | AM18: 营地 | AN18: -150 | AO18: 0 | AP18: 10 | AQ18: =COUNTIF($I$4:$P$94,AM18) -> 1 | AR18: =COUNTIF($Q$4:$X$94,AM18) -> 0 | AS18: =COUNTIF($Y$4:$AF$94,AM18) -> 2 | AT18: =AQ18+AR18+AS18 -> 3 | AU18: =AQ18*$AO18 -> 0 | AV18: =AR18*$AO18 -> 0 | AW18: =AS18*$AO18 -> 0 | BA18: =AN18*0.8 -> -120
A19: 44744 | B19: 1600 | D19: =(SUM(粮草!A19:X19)+AG19*10)*IF(AK19="是",$AY$4,$AY$3) -> 1680 | E19: =SUM($B$4:B19)+SUM($C$4:C19)-SUM($D$4:D19) -> 1862 | F19: =SUM(经验!A19:X19) -> 570 | G19: =SUM($F$4:F19)+SUM($H$4:H19) -> 11515 | H19: 0 | I19: 4级 | J19: 4级 | K19: 4级 | L19: 4级 | M19: 4级 | N19: 4级 | O19: 空 | P19: 空 | Q19: 空 | R19: 空 | S19: 空 | T19: 空 | U19: 空 | V19: 空 | W19: 空 | X19: 空 | Y19: 3级 | Z19: 3级 | AA19: 3级 | AB19: 3级 | AC19: 3级 | AD19: 3级 | AE19: 空 | AF19: 空 | AG19: =AH19+AI19+AJ19 -> 0 | AK19: 是 | AM19: 大卦 | AN19: 250 | AO19: 200 | AQ19: =COUNTIF($I$4:$P$94,AM19) -> 1 | AR19: =COUNTIF($Q$4:$X$94,AM19) -> 0 | AS19: =COUNTIF($Y$4:$AF$94,AM19) -> 2 | AT19: =AQ19+AR19+AS19 -> 3 | AU19: =AQ19*$AO19 -> 200 | AV19: =AR19*$AO19 -> 0 | AW19: =AS19*$AO19 -> 400 | BA19: =AN19*0.8 -> 200
A20: 44745 | B20: 1600 | D20: =(SUM(粮草!A20:X20)+AG20*10)*IF(AK20="是",$AY$4,$AY$3) -> 1680 | E20: =SUM($B$4:B20)+SUM($C$4:C20)-SUM($D$4:D20) -> 1782 | F20: =SUM(经验!A20:X20) -> 570 | G20: =SUM($F$4:F20)+SUM($H$4:H20) -> 12085 | H20: 0 | I20: 4级 | J20: 4级 | K20: 4级 | L20: 4级 | M20: 4级 | N20: 4级 | O20: 空 | P20: 空 | Q20: 空 | R20: 空 | S20: 空 | T20: 空 | U20: 空 | V20: 空 | W20: 空 | X20: 空 | Y20: 3级 | Z20: 3级 | AA20: 3级 | AB20: 3级 | AC20: 3级 | AD20: 3级 | AE20: 空 | AF20: 空 | AG20: =AH20+AI20+AJ20 -> 0 | AK20: 是 | AM20: 小卦 | AN20: 170 | AO20: 45 | AQ20: =COUNTIF($I$4:$P$94,AM20) -> 3 | AR20: =COUNTIF($Q$4:$X$94,AM20) -> 0 | AS20: =COUNTIF($Y$4:$AF$94,AM20) -> 2 | AT20: =AQ20+AR20+AS20 -> 5 | AU20: =AQ20*$AO20 -> 135 | AV20: =AR20*$AO20 -> 0 | AW20: =AS20*$AO20 -> 90 | BA20: =AN20*0.8 -> 136
A21: 44746 | B21: 1600 | D21: =(SUM(粮草!A21:X21)+AG21*10)*IF(AK21="是",$AY$4,$AY$3) -> 1680 | E21: =SUM($B$4:B21)+SUM($C$4:C21)-SUM($D$4:D21) -> 1702 | F21: =SUM(经验!A21:X21) -> 570 | G21: =SUM($F$4:F21)+SUM($H$4:H21) -> 12855 | H21: 200 | I21: 4级 | J21: 4级 | K21: 4级 | L21: 4级 | M21: 4级 | N21: 4级 | O21: 空 | P21: 空 | Q21: 空 | R21: 空 | S21: 空 | T21: 空 | U21: 空 | V21: 空 | W21: 空 | X21: 空 | Y21: 3级 | Z21: 3级 | AA21: 3级 | AB21: 3级 | AC21: 3级 | AD21: 3级 | AE21: 空 | AF21: 空 | AG21: =AH21+AI21+AJ21 -> 0 | AK21: 是 | AM21: 小boss | AN21: 250 | AO21: 200 | AQ21: =COUNTIF($I$4:$P$94,AM21) -> 0 | AR21: =COUNTIF($Q$4:$X$94,AM21) -> 0 | AS21: =COUNTIF($Y$4:$AF$94,AM21) -> 0 | AT21: =AQ21+AR21+AS21 -> 0 | AU21: =AQ21*$AO21 -> 0 | AV21: =AR21*$AO21 -> 0 | AW21: =AS21*$AO21 -> 0 | BA21: =AN21*0.8 -> 200
A22: 44747 | B22: 1600 | D22: =(SUM(粮草!A22:X22)+AG22*10)*IF(AK22="是",$AY$4,$AY$3) -> 1576 | E22: =SUM($B$4:B22)+SUM($C$4:C22)-SUM($D$4:D22) -> 1726 | F22: =SUM(经验!A22:X22) -> 550 | G22: =SUM($F$4:F22)+SUM($H$4:H22) -> 13505 | H22: 100 | I22: 4级 | J22: 商人 | K22: 4级 | L22: 4级 | M22: 4级 | N22: 4级 | O22: 空 | P22: 空 | Q22: 空 | R22: 空 | S22: 空 | T22: 空 | U22: 空 | V22: 空 | W22: 空 | X22: 空 | Y22: 3级 | Z22: 3级 | AA22: 3级 | AB22: 3级 | AC22: 3级 | AD22: 3级 | AE22: 空 | AF22: 空 | AG22: =AH22+AI22+AJ22 -> 0 | AK22: 是 | AM22: 大boss | AN22: 250 | AO22: 1000 | AQ22: =COUNTIF($I$4:$P$94,AM22) -> 2 | AR22: =COUNTIF($Q$4:$X$94,AM22) -> 0 | AS22: =COUNTIF($Y$4:$AF$94,AM22) -> 0 | AT22: =AQ22+AR22+AS22 -> 2 | AU22: =AQ22*$AO22 -> 2000 | AV22: =AR22*$AO22 -> 0 | AW22: =AS22*$AO22 -> 0 | BA22: =AN22*0.8 -> 200
A23: 44748 | B23: 1600 | D23: =(SUM(粮草!A23:X23)+AG23*10)*IF(AK23="是",$AY$4,$AY$3) -> 1584 | E23: =SUM($B$4:B23)+SUM($C$4:C23)-SUM($D$4:D23) -> 1742 | F23: =SUM(经验!A23:X23) -> 555 | G23: =SUM($F$4:F23)+SUM($H$4:H23) -> 14260 | H23: 200 | I23: 4级 | J23: 4级 | K23: 4级 | L23: 4级 | M23: 4级 | N23: 4级 | O23: 空 | P23: 空 | Q23: 空 | R23: 空 | S23: 空 | T23: 空 | U23: 空 | V23: 空 | W23: 空 | X23: 空 | Y23: 3级 | Z23: 商人 | AA23: 3级 | AB23: 3级 | AC23: 3级 | AD23: 3级 | AE23: 空 | AF23: 空 | AG23: =AH23+AI23+AJ23 -> 0 | AK23: 是 | AM23: 中boss | AN23: 250 | AO23: 500 | AQ23: =COUNTIF($I$4:$P$94,AM23) -> 1 | AR23: =COUNTIF($Q$4:$X$94,AM23) -> 0 | AS23: =COUNTIF($Y$4:$AF$94,AM23) -> 1 | AT23: =AQ23+AR23+AS23 -> 2 | AU23: =AQ23*$AO23 -> 500 | AV23: =AR23*$AO23 -> 0 | AW23: =AS23*$AO23 -> 500 | BA23: =AN23*0.8 -> 200
A24: 44749 | B24: 1600 | D24: =(SUM(粮草!A24:X24)+AG24*10)*IF(AK24="是",$AY$4,$AY$3) -> 1680 | E24: =SUM($B$4:B24)+SUM($C$4:C24)-SUM($D$4:D24) -> 1662 | F24: =SUM(经验!A24:X24) -> 570 | G24: =SUM($F$4:F24)+SUM($H$4:H24) -> 14830 | H24: 0 | I24: 4级 | J24: 4级 | K24: 4级 | L24: 4级 | M24: 4级 | N24: 4级 | O24: 空 | P24: 空 | Q24: 空 | R24: 空 | S24: 空 | T24: 空 | U24: 空 | V24: 空 | W24: 空 | X24: 空 | Y24: 3级 | Z24: 3级 | AA24: 3级 | AB24: 3级 | AC24: 3级 | AD24: 3级 | AE24: 空 | AF24: 空 | AG24: =AH24+AI24+AJ24 -> 0 | AK24: 是 | AM24: 奈良 | AN24: 160 | AO24: 40 | AP24: 39.110982 | AQ24: =COUNTIF($I$4:$P$94,AM24) -> 0 | AR24: =COUNTIF($Q$4:$X$94,AM24) -> 0 | AS24: =COUNTIF($Y$4:$AF$94,AM24) -> 0 | AT24: =AQ24+AR24+AS24 -> 0 | AU24: =AQ24*$AO24 -> 0 | AV24: =AR24*$AO24 -> 0 | AW24: =AS24*$AO24 -> 0 | BA24: =AN24*0.8 -> 128
A25: 44750 | B25: 1600 | D25: =(SUM(粮草!A25:X25)+AG25*10)*IF(AK25="是",$AY$4,$AY$3) -> 1664 | E25: =SUM($B$4:B25)+SUM($C$4:C25)-SUM($D$4:D25) -> 1598 | F25: =SUM(经验!A25:X25) -> 570 | G25: =SUM($F$4:F25)+SUM($H$4:H25) -> 15400 | H25: 0 | I25: 4级 | J25: 4级 | K25: 4级 | L25: 4级 | M25: 4级 | N25: 4级 | O25: 空 | P25: 空 | Q25: 空 | R25: 空 | S25: 空 | T25: 空 | U25: 空 | V25: 空 | W25: 空 | X25: 空 | Y25: 3级 | Z25: 3级 | AA25: 塔3 | AB25: 3级 | AC25: 3级 | AD25: 3级 | AE25: 空 | AF25: 空 | AG25: =AH25+AI25+AJ25 -> 0 | AK25: 是 | AM25: 山中 | AN25: 160 | AO25: 40 | AP25: 39.110982 | AQ25: =COUNTIF($I$4:$P$94,AM25) -> 0 | AR25: =COUNTIF($Q$4:$X$94,AM25) -> 0 | AS25: =COUNTIF($Y$4:$AF$94,AM25) -> 0 | AT25: =AQ25+AR25+AS25 -> 0 | AU25: =AQ25*$AO25 -> 0 | AV25: =AR25*$AO25 -> 0 | AW25: =AS25*$AO25 -> 0 | BA25: =AN25*0.8 -> 128
A26: 44751 | B26: 1600 | D26: =(SUM(粮草!A26:X26)+AG26*10)*IF(AK26="是",$AY$4,$AY$3) -> 1576 | E26: =SUM($B$4:B26)+SUM($C$4:C26)-SUM($D$4:D26) -> 1622 | F26: =SUM(经验!A26:X26) -> 550 | G26: =SUM($F$4:F26)+SUM($H$4:H26) -> 15950 | H26: 0 | I26: 4级 | J26: 4级 | K26: 4级 | L26: 商人 | M26: 4级 | N26: 4级 | O26: 空 | P26: 空 | Q26: 空 | R26: 空 | S26: 空 | T26: 空 | U26: 空 | V26: 空 | W26: 空 | X26: 空 | Y26: 3级 | Z26: 3级 | AA26: 3级 | AB26: 3级 | AC26: 3级 | AD26: 3级 | AE26: 空 | AF26: 空 | AG26: =AH26+AI26+AJ26 -> 0 | AK26: 是 | AM26: 秋道 | AN26: 150 | AO26: 35 | AP26: 44.222109 | AQ26: =COUNTIF($I$4:$P$94,AM26) -> 0 | AR26: =COUNTIF($Q$4:$X$94,AM26) -> 0 | AS26: =COUNTIF($Y$4:$AF$94,AM26) -> 0 | AT26: =AQ26+AR26+AS26 -> 0 | AU26: =AQ26*$AO26 -> 0 | AV26: =AR26*$AO26 -> 0 | AW26: =AS26*$AO26 -> 0 | BA26: =AN26*0.8 -> 120
A27: 44752 | B27: 1600 | D27: =(SUM(粮草!A27:X27)+AG27*10)*IF(AK27="是",$AY$4,$AY$3) -> 1632 | E27: =SUM($B$4:B27)+SUM($C$4:C27)-SUM($D$4:D27) -> 1590 | F27: =SUM(经验!A27:X27) -> 615 | G27: =SUM($F$4:F27)+SUM($H$4:H27) -> 16565 | H27: 0 | I27: 4级 | J27: 塔4 | K27: 4级 | L27: 4级 | M27: 4级 | N27: 4级 | O27: 空 | P27: 空 | Q27: 空 | R27: 空 | S27: 空 | T27: 空 | U27: 空 | V27: 空 | W27: 空 | X27: 空 | Y27: 3级 | Z27: 3级 | AA27: 3级 | AB27: 营地+ | AC27: 3级 | AD27: 3级 | AE27: 3级 | AF27: 3级 | AG27: =AH27+AI27+AJ27 -> 0 | AK27: 是 | AM27: 空 | AN27: 0 | AO27: 0 | AP27: 0 | AU27: =AQ27*$AO27 -> 0 | AV27: =AR27*$AO27 -> 0 | AW27: =AS27*$AO27 -> 0 | BA27: =AN27*0.8 -> 0
A28: 44753 | B28: 1600 | D28: =(SUM(粮草!A28:X28)+AG28*10)*IF(AK28="是",$AY$4,$AY$3) -> 1680 | E28: =SUM($B$4:B28)+SUM($C$4:C28)-SUM($D$4:D28) -> 1510 | F28: =SUM(经验!A28:X28) -> 585 | G28: =SUM($F$4:F28)+SUM($H$4:H28) -> 17350 | H28: 200 | I28: 4级 | J28: 4级 | K28: 塔4 | L28: 5级 | M28: 5级 | N28: 5级 | O28: 空 | P28: 空 | Q28: 空 | R28: 空 | S28: 空 | T28: 空 | U28: 空 | V28: 空 | W28: 空 | X28: 空 | Y28: 3级 | Z28: 3级 | AA28: 3级 | AB28: 3级 | AC28: 3级 | AD28: 3级 | AE28: 空 | AF28: 空 | AG28: =AH28+AI28+AJ28 -> 0 | AK28: 是 | AL28: 八卦后 | AM28: 营地+ | AN28: -200 | AO28: 0 | AQ28: =COUNTIF($I$4:$P$94,AM28) -> 6 | AR28: =COUNTIF($Q$4:$X$94,AM28) -> 2 | AS28: =COUNTIF($Y$4:$AF$94,AM28) -> 4 | AT28: =AQ28+AR28+AS28 -> 12 | AU28: =AQ28*$AO28 -> 0 | AV28: =AR28*$AO28 -> 0 | AW28: =AS28*$AO28 -> 0 | BA28: =AN28*0.8 -> -160
A29: 44754 | B29: 1600 | D29: =(SUM(粮草!A29:X29)+AG29*10)*IF(AK29="是",$AY$4,$AY$3) -> 1704 | E29: =SUM($B$4:B29)+SUM($C$4:C29)-SUM($D$4:D29) -> 1406 | F29: =SUM(经验!A29:X29) -> 595 | G29: =SUM($F$4:F29)+SUM($H$4:H29) -> 18045 | H29: 100 | I29: 5级 | J29: 4级 | K29: 5级 | L29: 5级 | M29: 5级 | N29: 5级 | O29: 空 | P29: 空 | Q29: 空 | R29: 空 | S29: 空 | T29: 空 | U29: 空 | V29: 空 | W29: 空 | X29: 空 | Y29: 3级 | Z29: 3级 | AA29: 3级 | AB29: 3级 | AC29: 3级 | AD29: 塔3 | AE29: 空 | AF29: 空 | AG29: =AH29+AI29+AJ29 -> 0 | AK29: 是 | AM29: 历练 | AN29: 50 | AO29: 520 | AQ29: =COUNTIF($I$4:$P$94,AM29) -> 1 | AR29: =COUNTIF($Q$4:$X$94,AM29) -> 0 | AS29: =COUNTIF($Y$4:$AF$94,AM29) -> 2 | AT29: =AQ29+AR29+AS29 -> 3 | AU29: =AQ29*$AO29 -> 520 | AV29: =AR29*$AO29 -> 0 | AW29: =AS29*$AO29 -> 1040 | BA29: =AN29*0.8 -> 40
A30: 44755 | B30: 1600 | D30: =(SUM(粮草!A30:X30)+AG30*10)*IF(AK30="是",$AY$4,$AY$3) -> 1632 | E30: =SUM($B$4:B30)+SUM($C$4:C30)-SUM($D$4:D30) -> 1374 | F30: =SUM(经验!A30:X30) -> 585 | G30: =SUM($F$4:F30)+SUM($H$4:H30) -> 18830 | H30: 200 | I30: 5级 | J30: 5级 | K30: 5级 | L30: 5级 | M30: 5级 | N30: 5级 | O30: 空 | P30: 空 | Q30: 空 | R30: 空 | S30: 空 | T30: 空 | U30: 空 | V30: 空 | W30: 空 | X30: 空 | Y30: 3级 | Z30: 3级 | AA30: 3级 | AB30: 3级 | AC30: 商人 | AD30: 3级 | AE30: 空 | AF30: 空 | AG30: =AH30+AI30+AJ30 -> 0 | AK30: 是
A31: 44756 | B31: 1600 | D31: =(SUM(粮草!A31:X31)+AG31*10)*IF(AK31="是",$AY$4,$AY$3) -> 1728 | E31: =SUM($B$4:B31)+SUM($C$4:C31)-SUM($D$4:D31) -> 1246 | F31: =SUM(经验!A31:X31) -> 600 | G31: =SUM($F$4:F31)+SUM($H$4:H31) -> 19430 | H31: 0 | I31: 5级 | J31: 5级 | K31: 5级 | L31: 5级 | M31: 5级 | N31: 5级 | O31: 空 | P31: 空 | Q31: 空 | R31: 空 | S31: 空 | T31: 空 | U31: 空 | V31: 空 | W31: 空 | X31: 空 | Y31: 3级 | Z31: 3级 | AA31: 3级 | AB31: 3级 | AC31: 3级 | AD31: 3级 | AE31: 空 | AF31: 空 | AG31: =AH31+AI31+AJ31 -> 0 | AK31: 是
A32: 44757 | B32: 1600 | D32: =(SUM(粮草!A32:X32)+AG32*10)*IF(AK32="是",$AY$4,$AY$3) -> 1632 | E32: =SUM($B$4:B32)+SUM($C$4:C32)-SUM($D$4:D32) -> 1214 | F32: =SUM(经验!A32:X32) -> 585 | G32: =SUM($F$4:F32)+SUM($H$4:H32) -> 20015 | H32: 0 | I32: 5级 | J32: 5级 | K32: 5级 | L32: 5级 | M32: 5级 | N32: 5级 | O32: 空 | P32: 空 | Q32: 空 | R32: 空 | S32: 空 | T32: 空 | U32: 空 | V32: 空 | W32: 空 | X32: 空 | Y32: 商人 | Z32: 3级 | AA32: 3级 | AB32: 3级 | AC32: 3级 | AD32: 3级 | AE32: 空 | AF32: 空 | AG32: =AH32+AI32+AJ32 -> 0 | AK32: 是
A33: 44758 | B33: 1600 | D33: =(SUM(粮草!A33:X33)+AG33*10)*IF(AK33="是",$AY$4,$AY$3) -> 1728 | E33: =SUM($B$4:B33)+SUM($C$4:C33)-SUM($D$4:D33) -> 1086 | F33: =SUM(经验!A33:X33) -> 600 | G33: =SUM($F$4:F33)+SUM($H$4:H33) -> 20615 | H33: 0 | I33: 5级 | J33: 5级 | K33: 5级 | L33: 5级 | M33: 5级 | N33: 5级 | O33: 空 | P33: 空 | Q33: 空 | R33: 空 | S33: 空 | T33: 空 | U33: 空 | V33: 空 | W33: 空 | X33: 空 | Y33: 3级 | Z33: 3级 | AA33: 3级 | AB33: 3级 | AC33: 3级 | AD33: 3级 | AE33: 空 | AF33: 空 | AG33: =AH33+AI33+AJ33 -> 0 | AK33: 是
A34: 44759 | B34: 1600 | D34: =(SUM(粮草!A34:X34)+AG34*10)*IF(AK34="是",$AY$4,$AY$3) -> 1728 | E34: =SUM($B$4:B34)+SUM($C$4:C34)-SUM($D$4:D34) -> 958 | F34: =SUM(经验!A34:X34) -> 600 | G34: =SUM($F$4:F34)+SUM($H$4:H34) -> 21215 | H34: 0 | I34: 5级 | J34: 5级 | K34: 5级 | L34: 5级 | M34: 5级 | N34: 5级 | O34: 空 | P34: 空 | Q34: 空 | R34: 空 | S34: 空 | T34: 空 | U34: 空 | V34: 空 | W34: 空 | X34: 空 | Y34: 3级 | Z34: 3级 | AA34: 3级 | AB34: 3级 | AC34: 3级 | AD34: 3级 | AE34: 空 | AF34: 空 | AG34: =AH34+AI34+AJ34 -> 0 | AK34: 是
A35: 44760 | B35: 1600 | D35: =(SUM(粮草!A35:X35)+AG35*10)*IF(AK35="是",$AY$4,$AY$3) -> 1664 | E35: =SUM($B$4:B35)+SUM($C$4:C35)-SUM($D$4:D35) -> 894 | F35: =SUM(经验!A35:X35) -> 1030 | G35: =SUM($F$4:F35)+SUM($H$4:H35) -> 22445 | H35: 200 | I35: 5级 | J35: 5级 | K35: 5级 | L35: 中boss | M35: 5级 | N35: 5级 | O35: 空 | P35: 空 | Q35: 空 | R35: 空 | S35: 空 | T35: 空 | U35: 空 | V35: 空 | W35: 空 | X35: 空 | Y35: 商人 | Z35: 3级 | AA35: 3级 | AB35: 塔3 | AC35: 3级 | AD35: 3级 | AE35: 空 | AF35: 空 | AG35: =AH35+AI35+AJ35 -> 0 | AK35: 是
A36: 44761 | B36: 1600 | D36: =(SUM(粮草!A36:X36)+AG36*10)*IF(AK36="是",$AY$4,$AY$3) -> 1736 | E36: =SUM($B$4:B36)+SUM($C$4:C36)-SUM($D$4:D36) -> 758 | F36: =SUM(经验!A36:X36) -> 600 | G36: =SUM($F$4:F36)+SUM($H$4:H36) -> 23145 | H36: 100 | I36: 5级 | J36: 5级 | K36: 5级 | L36: 5级 | M36: 5级 | N36: 5级 | O36: 空 | P36: 空 | Q36: 空 | R36: 空 | S36: 空 | T36: 空 | U36: 空 | V36: 空 | W36: 空 | X36: 空 | Y36: 3级 | Z36: 3级 | AA36: 3级 | AB36: 3级 | AC36: 3级 | AD36: 3级 | AE36: 空 | AF36: 空 | AG36: =AH36+AI36+AJ36 -> 1 | AJ36: 1 | AK36: 是
A37: 44762 | B37: 1600 | D37: =(SUM(粮草!A37:X37)+AG37*10)*IF(AK37="是",$AY$4,$AY$3) -> 1632 | E37: =SUM($B$4:B37)+SUM($C$4:C37)-SUM($D$4:D37) -> 726 | F37: =SUM(经验!A37:X37) -> 585 | G37: =SUM($F$4:F37)+SUM($H$4:H37) -> 23930 | H37: 200 | I37: 5级 | J37: 5级 | K37: 5级 | L37: 5级 | M37: 5级 | N37: 5级 | O37: 空 | P37: 空 | Q37: 空 | R37: 空 | S37: 空 | T37: 空 | U37: 空 | V37: 空 | W37: 空 | X37: 空 | Y37: 商人 | Z37: 3级 | AA37: 3级 | AB37: 3级 | AC37: 3级 | AD37: 3级 | AE37: 空 | AF37: 空 | AG37: =AH37+AI37+AJ37 -> 0 | AK37: 是
A38: 44763 | B38: 1600 | D38: =(SUM(粮草!A38:X38)+AG38*10)*IF(AK38="是",$AY$4,$AY$3) -> 1616 | E38: =SUM($B$4:B38)+SUM($C$4:C38)-SUM($D$4:D38) -> 710 | F38: =SUM(经验!A38:X38) -> 575 | G38: =SUM($F$4:F38)+SUM($H$4:H38) -> 24505 | H38: 0 | I38: 5级 | J38: 5级 | K38: 商人 | L38: 5级 | M38: 5级 | N38: 5级 | O38: 空 | P38: 空 | Q38: 空 | R38: 空 | S38: 空 | T38: 空 | U38: 空 | V38: 空 | W38: 空 | X38: 空 | Y38: 3级 | Z38: 3级 | AA38: 3级 | AB38: 3级 | AC38: 3级 | AD38: 3级 | AE38: 空 | AF38: 空 | AG38: =AH38+AI38+AJ38 -> 0 | AK38: 是
A39: 44764 | B39: 1600 | D39: =(SUM(粮草!A39:X39)+AG39*10)*IF(AK39="是",$AY$4,$AY$3) -> 1632 | E39: =SUM($B$4:B39)+SUM($C$4:C39)-SUM($D$4:D39) -> 678 | F39: =SUM(经验!A39:X39) -> 585 | G39: =SUM($F$4:F39)+SUM($H$4:H39) -> 25090 | H39: 0 | I39: 5级 | J39: 5级 | K39: 5级 | L39: 5级 | M39: 5级 | N39: 5级 | O39: 空 | P39: 空 | Q39: 空 | R39: 空 | S39: 空 | T39: 空 | U39: 空 | V39: 空 | W39: 空 | X39: 空 | Y39: 3级 | Z39: 3级 | AA39: 3级 | AB39: 3级 | AC39: 3级 | AD39: 商人 | AE39: 空 | AF39: 空 | AG39: =AH39+AI39+AJ39 -> 0 | AK39: 是 | AM39: 2级194
A40: 44765 | B40: 1600 | D40: =(SUM(粮草!A40:X40)+AG40*10)*IF(AK40="是",$AY$4,$AY$3) -> 1768 | E40: =SUM($B$4:B40)+SUM($C$4:C40)-SUM($D$4:D40) -> 510 | F40: =SUM(经验!A40:X40) -> 1120 | G40: =SUM($F$4:F40)+SUM($H$4:H40) -> 26210 | H40: 0 | I40: 5级 | J40: 5级 | K40: 5级 | L40: 历练 | M40: 5级 | N40: 5级 | O40: 5级 | P40: 空 | Q40: 空 | R40: 空 | S40: 空 | T40: 空 | U40: 空 | V40: 空 | W40: 空 | X40: 空 | Y40: 3级 | Z40: 3级 | AA40: 3级 | AB40: 3级 | AC40: 3级 | AD40: 3级 | AE40: 空 | AF40: 空 | AG40: =AH40+AI40+AJ40 -> 0 | AK40: 是 | AM40: 3级349
...

Sheet 粮草
A2: 队伍一 风 | C2: 步数 | D2: =COUNTIF(A4:H94,"<>空") -> 728 | E2: (不算跳步和传送) | I2: 队伍二 雷 | K2: 步数 | L2: =COUNTIF(I4:P94,"<>空") -> 728 | M2: (不算跳步和传送) | Q2: 队伍三 | S2: 总步数 | T2: =COUNTIF(Q4:X94,"<>空") -> 728 | U2: (不算跳步和传送)
A3: 1 | B3: 2 | C3: 3 | D3: 4 | E3: 5 | F3: 6 | G3: 7 | H3: 8 | I3: 1 | J3: 2 | K3: 3 | L3: 4 | M3: 5 | N3: 6 | O3: 7 | P3: 8 | Q3: 1 | R3: 2 | S3: 3 | T3: 4 | U3: 5 | V3: 6 | W3: 7 | X3: 8
A4: =(VLOOKUP('8.0.0'!I4,'8.0.0'!$AM$4:$AO$45,2,FALSE))*IF('8.0.0'!AK$4="是",'8.0.0'!$AY$4,'8.0.0'!$AY$3) -> 150 | B4: =(VLOOKUP('8.0.0'!J4,'8.0.0'!$AM$4:$AO$45,2,FALSE))*IF('8.0.0'!AL$4="是",'8.0.0'!$AY$4,'8.0.0'!$AY$3) -> 150 | C4: =(VLOOKUP('8.0.0'!K4,'8.0.0'!$AM$4:$AO$45,2,FALSE))*IF('8.0.0'!AM$4="是",'8.0.0'!$AY$4,'8.0.0'!$AY$3) -> 150 | D4: =(VLOOKUP('8.0.0'!L4,'8.0.0'!$AM$4:$AO$45,2,FALSE))*IF('8.0.0'!AN$4="是",'8.0.0'!$AY$4,'8.0.0'!$AY$3) -> 150 | E4: =(VLOOKUP('8.0.0'!M4,'8.0.0'!$AM$4:$AO$45,2,FALSE))*IF('8.0.0'!AO$4="是",'8.0.0'!$AY$4,'8.0.0'!$AY$3) -> 150 | F4: =(VLOOKUP('8.0.0'!N4,'8.0.0'!$AM$4:$AO$45,2,FALSE))*IF('8.0.0'!AQ$4="是",'8.0.0'!$AY$4,'8.0.0'!$AY$3) -> 150 | G4: =(VLOOKUP('8.0.0'!O4,'8.0.0'!$AM$4:$AO$45,2,FALSE))*IF('8.0.0'!AR$4="是",'8.0.0'!$AY$4,'8.0.0'!$AY$3) -> 0 | H4: =(VLOOKUP('8.0.0'!P4,'8.0.0'!$AM$4:$AO$45,2,FALSE))*IF('8.0.0'!AS$4="是",'8.0.0'!$AY$4,'8.0.0'!$AY$3) -> 0 | I4: =(VLOOKUP('8.0.0'!Q4,'8.0.0'!$AM$4:$AO$45,2,FALSE))*IF('8.0.0'!AT$4="是",'8.0.0'!$AY$4,'8.0.0'!$AY$3) -> 50 | J4: =(VLOOKUP('8.0.0'!R4,'8.0.0'!$AM$4:$AO$45,2,FALSE))*IF('8.0.0'!AU$4="是",'8.0.0'!$AY$4,'8.0.0'!$AY$3) -> 160 | K4: =(VLOOKUP('8.0.0'!S4,'8.0.0'!$AM$4:$AO$45,2,FALSE))*IF('8.0.0'!AV$4="是",'8.0.0'!$AY$4,'8.0.0'!$AY$3) -> 160 | L4: =(VLOOKUP('8.0.0'!T4,'8.0.0'!$AM$4:$AO$45,2,FALSE))*IF('8.0.0'!AW$4="是",'8.0.0'!$AY$4,'8.0.0'!$AY$3) -> 160 | M4: =(VLOOKUP('8.0.0'!U4,'8.0.0'!$AM$4:$AO$45,2,FALSE))*IF('8.0.0'!AX$4="是",'8.0.0'!$AY$4,'8.0.0'!$AY$3) -> 160 | ... X4: =(VLOOKUP('8.0.0'!AF4,'8.0.0'!$AM$4:$AO$45,2,FALSE))*IF('8.0.0'!BI$4="是",'8.0.0'!$AY$4,'8.0.0'!$AY$3) -> 160
A5: =(VLOOKUP('8.0.0'!I5,'8.0.0'!$AM$4:$AO$45,2,FALSE))*IF('8.0.0'!AK$4="是",'8.0.0'!$AY$4,'8.0.0'!$AY$3) -> 170 | B5: =(VLOOKUP('8.0.0'!J5,'8.0.0'!$AM$4:$AO$45,2,FALSE))*IF('8.0.0'!AL$4="是",'8.0.0'!$AY$4,'8.0.0'!$AY$3) -> 170 | C5: =(VLOOKUP('8.0.0'!K5,'8.0.0'!$AM$4:$AO$45,2,FALSE))*IF('8.0.0'!AM$4="是",'8.0.0'!$AY$4,'8.0.0'!$AY$3) -> 50 | D5: =(VLOOKUP('8.0.0'!L5,'8.0.0'!$AM$4:$AO$45,2,FALSE))*IF('8.0.0'!AN$4="是",'8.0.0'!$AY$4,'8.0.0'!$AY$3) -> 170 | E5: =(VLOOKUP('8.0.0'!M5,'8.0.0'!$AM$4:$AO$45,2,FALSE))*IF('8.0.0'!AO$4="是",'8.0.0'!$AY$4,'8.0.0'!$AY$3) -> 170 | F5: =(VLOOKUP('8.0.0'!N5,'8.0.0'!$AM$4:$AO$45,2,FALSE))*IF('8.0.0'!AQ$4="是",'8.0.0'!$AY$4,'8.0.0'!$AY$3) -> 170 | G5: =(VLOOKUP('8.0.0'!O5,'8.0.0'!$AM$4:$AO$45,2,FALSE))*IF('8.0.0'!AR$4="是",'8.0.0'!$AY$4,'8.0.0'!$AY$3) -> 0 | H5: =(VLOOKUP('8.0.0'!P5,'8.0.0'!$AM$4:$AO$45,2,FALSE))*IF('8.0.0'!AS$4="是",'8.0.0'!$AY$4,'8.0.0'!$AY$3) -> 0 | I5: =(VLOOKUP('8.0.0'!Q5,'8.0.0'!$AM$4:$AO$45,2,FALSE))*IF('8.0.0'!AT$4="是",'8.0.0'!$AY$4,'8.0.0'!$AY$3) -> 0 | J5: =(VLOOKUP('8.0.0'!R5,'8.0.0'!$AM$4:$AO$45,2,FALSE))*IF('8.0.0'!AU$4="是",'8.0.0'!$AY$4,'8.0.0'!$AY$3) -> 0 | K5: =(VLOOKUP('8.0.0'!S5,'8.0.0'!$AM$4:$AO$45,2,FALSE))*IF('8.0.0'!AV$4="是",'8.0.0'!$AY$4,'8.0.0'!$AY$3) -> 0 | L5: =(VLOOKUP('8.0.0'!T5,'8.0.0'!$AM$4:$AO$45,2,FALSE))*IF('8.0.0'!AW$4="是",'8.0.0'!$AY$4,'8.0.0'!$AY$3) -> 0 | M5: =(VLOOKUP('8.0.0'!U5,'8.0.0'!$AM$4:$AO$45,2,FALSE))*IF('8.0.0'!AX$4="是",'8.0.0'!$AY$4,'8.0.0'!$AY$3) -> 0 | ... X5: =(VLOOKUP('8.0.0'!AF5,'8.0.0'!$AM$4:$AO$45,2,FALSE))*IF('8.0.0'!BI$4="是",'8.0.0'!$AY$4,'8.0.0'!$AY$3) -> 0
A6: =(VLOOKUP('8.0.0'!I6,'8.0.0'!$AM$4:$AO$45,2,FALSE))*IF('8.0.0'!AK$4="是",'8.0.0'!$AY$4,'8.0.0'!$AY$3) -> 170 | B6: =(VLOOKUP('8.0.0'!J6,'8.0.0'!$AM$4:$AO$45,2,FALSE))*IF('8.0.0'!AL$4="是",'8.0.0'!$AY$4,'8.0.0'!$AY$3) -> 170 | C6: =(VLOOKUP('8.0.0'!K6,'8.0.0'!$AM$4:$AO$45,2,FALSE))*IF('8.0.0'!AM$4="是",'8.0.0'!$AY$4,'8.0.0'!$AY$3) -> 170 | D6: =(VLOOKUP('8.0.0'!L6,'8.0.0'!$AM$4:$AO$45,2,FALSE))*IF('8.0.0'!AN$4="是",'8.0.0'!$AY$4,'8.0.0'!$AY$3) -> 170 | E6: =(VLOOKUP('8.0.0'!M6,'8.0.0'!$AM$4:$AO$45,2,FALSE))*IF('8.0.0'!AO$4="是",'8.0.0'!$AY$4,'8.0.0'!$AY$3) -> 170 | F6: =(VLOOKUP('8.0.0'!N6,'8.0.0'!$AM$4:$AO$45,2,FALSE))*IF('8.0.0'!AQ$4="是",'8.0.0'!$AY$4,'8.0.0'!$AY$3) -> 170 | G6: =(VLOOKUP('8.0.0'!O6,'8.0.0'!$AM$4:$AO$45,2,FALSE))*IF('8.0.0'!AR$4="是",'8.0.0'!$AY$4,'8.0.0'!$AY$3) -> 0 | H6: =(VLOOKUP('8.0.0'!P6,'8.0.0'!$AM$4:$AO$45,2,FALSE))*IF('8.0.0'!AS$4="是",'8.0.0'!$AY$4,'8.0.0'!$AY$3) -> 0 | I6: =(VLOOKUP('8.0.0'!Q6,'8.0.0'!$AM$4:$AO$45,2,FALSE))*IF('8.0.0'!AT$4="是",'8.0.0'!$AY$4,'8.0.0'!$AY$3) -> 0 | J6: =(VLOOKUP('8.0.0'!R6,'8.0.0'!$AM$4:$AO$45,2,FALSE))*IF('8.0.0'!AU$4="是",'8.0.0'!$AY$4,'8.0.0'!$AY$3) -> 0 | K6: =(VLOOKUP('8.0.0'!S6,'8.0.0'!$AM$4:$AO$45,2,FALSE))*IF('8.0.0'!AV$4="是",'8.0.0'!$AY$4,'8.0.0'!$AY$3) -> 0 | L6: =(VLOOKUP('8.0.0'!T6,'8.0.0'!$AM$4:$AO$45,2,FALSE))*IF('8.0.0'!AW$4="是",'8.0.0'!$AY$4,'8.0.0'!$AY$3) -> 0 | M6: =(VLOOKUP('8.0.0'!U6,'8.0.0'!$AM$4:$AO$45,2,FALSE))*IF('8.0.0'!AX$4="是",'8.0.0'!$AY$4,'8.0.0'!$AY$3) -> 0 | ... X6: =(VLOOKUP('8.0.0'!AF6,'8.0.0'!$AM$4:$AO$45,2,FALSE))*IF('8.0.0'!BI$4="是",'8.0.0'!$AY$4,'8.0.0'!$AY$3) -> 170
A7: =(VLOOKUP('8.0.0'!I7,'8.0.0'!$AM$4:$AO$45,2,FALSE))*IF('8.0.0'!AK$4="是",'8.0.0'!$AY$4,'8.0.0'!$AY$3) -> 170 | B7: =(VLOOKUP('8.0.0'!J7,'8.0.0'!$AM$4:$AO$45,2,FALSE))*IF('8.0.0'!AL$4="是",'8.0.0'!$AY$4,'8.0.0'!$AY$3) -> 170 | C7: =(VLOOKUP('8.0.0'!K7,'8.0.0'!$AM$4:$AO$45,2,FALSE))*IF('8.0.0'!AM$4="是",'8.0.0'!$AY$4,'8.0.0'!$AY$3) -> 170 | D7: =(VLOOKUP('8.0.0'!L7,'8.0.0'!$AM$4:$AO$45,2,FALSE))*IF('8.0.0'!AN$4="是",'8.0.0'!$AY$4,'8.0.0'!$AY$3) -> 170 | E7: =(VLOOKUP('8.0.0'!M7,'8.0.0'!$AM$4:$AO$45,2,FALSE))*IF('8.0.0'!AO$4="是",'8.0.0'!$AY$4,'8.0.0'!$AY$3) -> 170 | F7: =(VLOOKUP('8.0.0'!N7,'8.0.0'!$AM$4:$AO$45,2,FALSE))*IF('8.0.0'!AQ$4="是",'8.0.0'!$AY$4,'8.0.0'!$AY$3) -> 170 | G7: =(VLOOKUP('8.0.0'!O7,'8.0.0'!$AM$4:$AO$45,2,FALSE))*IF('8.0.0'!AR$4="是",'8.0.0'!$AY$4,'8.0.0'!$AY$3) -> 0 | H7: =(VLOOKUP('8.0.0'!P7,'8.0.0'!$AM$4:$AO$45,2,FALSE))*IF('8.0.0'!AS$4="是",'8.0.0'!$AY$4,'8.0.0'!$AY$3) -> 0 | I7: =(VLOOKUP('8.0.0'!Q7,'8.0.0'!$AM$4:$AO$45,2,FALSE))*IF('8.0.0'!AT$4="是",'8.0.0'!$AY$4,'8.0.0'!$AY$3) -> 0 | J7: =(VLOOKUP('8.0.0'!R7,'8.0.0'!$AM$4:$AO$45,2,FALSE))*IF('8.0.0'!AU$4="是",'8.0.0'!$AY$4,'8.0.0'!$AY$3) -> 0 | K7: =(VLOOKUP('8.0.0'!S7,'8.0.0'!$AM$4:$AO$45,2,FALSE))*IF('8.0.0'!AV$4="是",'8.0.0'!$AY$4,'8.0.0'!$AY$3) -> 0 | L7: =(VLOOKUP('8.0.0'!T7,'8.0.0'!$AM$4:$AO$45,2,FALSE))*IF('8.0.0'!AW$4="是",'8.0.0'!$AY$4,'8.0.0'!$AY$3) -> 0 | M7: =(VLOOKUP('8.0.0'!U7,'8.0.0'!$AM$4:$AO$45,2,FALSE))*IF('8.0.0'!AX$4="是",'8.0.0'!$AY$4,'8.0.0'!$AY$3) -> 0 | ... X7: =(VLOOKUP('8.0.0'!AF7,'8.0.0'!$AM$4:$AO$45,2,FALSE))*IF('8.0.0'!BI$4="是",'8.0.0'!$AY$4,'8.0.0'!$AY$3) -> 0
A8: =(VLOOKUP('8.0.0'!I8,'8.0.0'!$AM$4:$AO$45,2,FALSE))*IF('8.0.0'!AK$4="是",'8.0.0'!$AY$4,'8.0.0'!$AY$3) -> 170 | B8: =(VLOOKUP('8.0.0'!J8,'8.0.0'!$AM$4:$AO$45,2,FALSE))*IF('8.0.0'!AL$4="是",'8.0.0'!$AY$4,'8.0.0'!$AY$3) -> 150 | C8: =(VLOOKUP('8.0.0'!K8,'8.0.0'!$AM$4:$AO$45,2,FALSE))*IF('8.0.0'!AM$4="是",'8.0.0'!$AY$4,'8.0.0'!$AY$3) -> 170 | D8: =(VLOOKUP('8.0.0'!L8,'8.0.0'!$AM$4:$AO$45,2,FALSE))*IF('8.0.0'!AN$4="是",'8.0.0'!$AY$4,'8.0.0'!$AY$3) -> 250 | E8: =(VLOOKUP('8.0.0'!M8,'8.0.0'!$AM$4:$AO$45,2,FALSE))*IF('8.0.0'!AO$4="是",'8.0.0'!$AY$4,'8.0.0'!$AY$3) -> 170 | F8: =(VLOOKUP('8.0.0'!N8,'8.0.0'!$AM$4:$AO$45,2,FALSE))*IF('8.0.0'!AQ$4="是",'8.0.0'!$AY$4,'8.0.0'!$AY$3) -> 170 | G8: =(VLOOKUP('8.0.0'!O8,'8.0.0'!$AM$4:$AO$45,2,FALSE))*IF('8.0.0'!AR$4="是",'8.0.0'!$AY$4,'8.0.0'!$AY$3) -> -150 | H8: =(VLOOKUP('8.0.0'!P8,'8.0.0'!$AM$4:$AO$45,2,FALSE))*IF('8.0.0'!AS$4="是",'8.0.0'!$AY$4,'8.0.0'!$AY$3) -> 170 | I8: =(VLOOKUP('8.0.0'!Q8,'8.0.0'!$AM$4:$AO$45,2,FALSE))*IF('8.0.0'!AT$4="是",'8.0.0'!$AY$4,'8.0.0'!$AY$3) -> 0 | J8: =(VLOOKUP('8.0.0'!R8,'8.0.0'!$AM$4:$AO$45,2,FALSE))*IF('8.0.0'!AU$4="是",'8.0.0'!$AY$4,'8.0.0'!$AY$3) -> 0 | K8: =(VLOOKUP('8.0.0'!S8,'8.0.0'!$AM$4:$AO$45,2,FALSE))*IF('8.0.0'!AV$4="是",'8.0.0'!$AY$4,'8.0.0'!$AY$3) -> 0 | L8: =(VLOOKUP('8.0.0'!T8,'8.0.0'!$AM$4:$AO$45,2,FALSE))*IF('8.0.0'!AW$4="是",'8.0.0'!$AY$4,'8.0.0'!$AY$3) -> 0 | M8: =(VLOOKUP('8.0.0'!U8,'8.0.0'!$AM$4:$AO$45,2,FALSE))*IF('8.0.0'!AX$4="是",'8.0.0'!$AY$4,'8.0.0'!$AY$3) -> 0 | ... X8: =(VLOOKUP('8.0.0'!AF8,'8.0.0'!$AM$4:$AO$45,2,FALSE))*IF('8.0.0'!BI$4="是",'8.0.0'!$AY$4,'8.0.0'!$AY$3) -> 0
A9: =(VLOOKUP('8.0.0'!I9,'8.0.0'!$AM$4:$AO$45,2,FALSE))*IF('8.0.0'!AK$4="是",'8.0.0'!$AY$4,'8.0.0'!$AY$3) -> 170 | B9: =(VLOOKUP('8.0.0'!J9,'8.0.0'!$AM$4:$AO$45,2,FALSE))*IF('8.0.0'!AL$4="是",'8.0.0'!$AY$4,'8.0.0'!$AY$3) -> 170 | C9: =(VLOOKUP('8.0.0'!K9,'8.0.0'!$AM$4:$AO$45,2,FALSE))*IF('8.0.0'!AM$4="是",'8.0.0'!$AY$4,'8.0.0'!$AY$3) -> 50 | D9: =(VLOOKUP('8.0.0'!L9,'8.0.0'!$AM$4:$AO$45,2,FALSE))*IF('8.0.0'!AN$4="是",'8.0.0'!$AY$4,'8.0.0'!$AY$3) -> 170 | E9: =(VLOOKUP('8.0.0'!M9,'8.0.0'!$AM$4:$AO$45,2,FALSE))*IF('8.0.0'!AO$4="是",'8.0.0'!$AY$4,'8.0.0'!$AY$3) -> 170 | F9: =(VLOOKUP('8.0.0'!N9,'8.0.0'!$AM$4:$AO$45,2,FALSE))*IF('8.0.0'!AQ$4="是",'8.0.0'!$AY$4,'8.0.0'!$AY$3) -> 170 | G9: =(VLOOKUP('8.0.0'!O9,'8.0.0'!$AM$4:$AO$45,2,FALSE))*IF('8.0.0'!AR$4="是",'8.0.0'!$AY$4,'8.0.0'!$AY$3) -> 0 | H9: =(VLOOKUP('8.0.0'!P9,'8.0.0'!$AM$4:$AO$45,2,FALSE))*IF('8.0.0'!AS$4="是",'8.0.0'!$AY$4,'8.0.0'!$AY$3) -> 0 | I9: =(VLOOKUP('8.0.0'!Q9,'8.0.0'!$AM$4:$AO$45,2,FALSE))*IF('8.0.0'!AT$4="是",'8.0.0'!$AY$4,'8.0.0'!$AY$3) -> 0 | J9: =(VLOOKUP('8.0.0'!R9,'8.0.0'!$AM$4:$AO$45,2,FALSE))*IF('8.0.0'!AU$4="是",'8.0.0'!$AY$4,'8.0.0'!$AY$3) -> 0 | K9: =(VLOOKUP('8.0.0'!S9,'8.0.0'!$AM$4:$AO$45,2,FALSE))*IF('8.0.0'!AV$4="是",'8.0.0'!$AY$4,'8.0.0'!$AY$3) -> 0 | L9: =(VLOOKUP('8.0.0'!T9,'8.0.0'!$AM$4:$AO$45,2,FALSE))*IF('8.0.0'!AW$4="是",'8.0.0'!$AY$4,'8.0.0'!$AY$3) -> 0 | M9: =(VLOOKUP('8.0.0'!U9,'8.0.0'!$AM$4:$AO$45,2,FALSE))*IF('8.0.0'!AX$4="是",'8.0.0'!$AY$4,'8.0.0'!$AY$3) -> 0 | ... X9: =(VLOOKUP('8.0.0'!AF9,'8.0.0'!$AM$4:$AO$45,2,FALSE))*IF('8.0.0'!BI$4="是",'8.0.0'!$AY$4,'8.0.0'!$AY$3) -> 0
A10: =(VLOOKUP('8.0.0'!I10,'8.0.0'!$AM$4:$AO$45,2,FALSE))*IF('8.0.0'!AK$4="是",'8.0.0'!$AY$4,'8.0.0'!$AY$3) -> 170 | B10: =(VLOOKUP('8.0.0'!J10,'8.0.0'!$AM$4:$AO$45,2,FALSE))*IF('8.0.0'!AL$4="是",'8.0.0'!$AY$4,'8.0.0'!$AY$3) -> 170 | C10: =(VLOOKUP('8.0.0'!K10,'8.0.0'!$AM$4:$AO$45,2,FALSE))*IF('8.0.0'!AM$4="是",'8.0.0'!$AY$4,'8.0.0'!$AY$3) -> 50 | D10: =(VLOOKUP('8.0.0'!L10,'8.0.0'!$AM$4:$AO$45,2,FALSE))*IF('8.0.0'!AN$4="是",'8.0.0'!$AY$4,'8.0.0'!$AY$3) -> 170 | E10: =(VLOOKUP('8.0.0'!M10,'8.0.0'!$AM$4:$AO$45,2,FALSE))*IF('8.0.0'!AO$4="是",'8.0.0'!$AY$4,'8.0.0'!$AY$3) -> 170 | F10: =(VLOOKUP('8.0.0'!N10,'8.0.0'!$AM$4:$AO$45,2,FALSE))*IF('8.0.0'!AQ$4="是",'8.0.0'!$AY$4,'8.0.0'!$AY$3) -> 180 | G10: =(VLOOKUP('8.0.0'!O10,'8.0.0'!$AM$4:$AO$45,2,FALSE))*IF('8.0.0'!AR$4="是",'8.0.0'!$AY$4,'8.0.0'!$AY$3) -> 0 | H10: =(VLOOKUP('8.0.0'!P10,'8.0.0'!$AM$4:$AO$45,2,FALSE))*IF('8.0.0'!AS$4="是",'8.0.0'!$AY$4,'8.0.0'!$AY$3) -> 0 | I10: =(VLOOKUP('8.0.0'!Q10,'8.0.0'!$AM$4:$AO$45,2,FALSE))*IF('8.0.0'!AT$4="是",'8.0.0'!$AY$4,'8.0.0'!$AY$3) -> 0 | J10: =(VLOOKUP('8.0.0'!R10,'8.0.0'!$AM$4:$AO$45,2,FALSE))*IF('8.0.0'!AU$4="是",'8.0.0'!$AY$4,'8.0.0'!$AY$3) -> 0 | K10: =(VLOOKUP('8.0.0'!S10,'8.0.0'!$AM$4:$AO$45,2,FALSE))*IF('8.0.0'!AV$4="是",'8.0.0'!$AY$4,'8.0.0'!$AY$3) -> 0 | L10: =(VLOOKUP('8.0.0'!T10,'8.0.0'!$AM$4:$AO$45,2,FALSE))*IF('8.0.0'!AW$4="是",'8.0.0'!$AY$4,'8.0.0'!$AY$3) -> 0 | M10: =(VLOOKUP('8.0.0'!U10,'8.0.0'!$AM$4:$AO$45,2,FALSE))*IF('8.0.0'!AX$4="是",'8.0.0'!$AY$4,'8.0.0'!$AY$3) -> 0 | ... X10: =(VLOOKUP('8.0.0'!AF10,'8.0.0'!$AM$4:$AO$45,2,FALSE))*IF('8.0.0'!BI$4="是",'8.0.0'!$AY$4,'8.0.0'!$AY$3) -> 0
A11: =(VLOOKUP('8.0.0'!I11,'8.0.0'!$AM$4:$AO$45,2,FALSE))*IF('8.0.0'!AK$4="是",'8.0.0'!$AY$4,'8.0.0'!$AY$3) -> 180 | B11: =(VLOOKUP('8.0.0'!J11,'8.0.0'!$AM$4:$AO$45,2,FALSE))*IF('8.0.0'!AL$4="是",'8.0.0'!$AY$4,'8.0.0'!$AY$3) -> 180 | C11: =(VLOOKUP('8.0.0'!K11,'8.0.0'!$AM$4:$AO$45,2,FALSE))*IF('8.0.0'!AM$4="是",'8.0.0'!$AY$4,'8.0.0'!$AY$3) -> 50 | D11: =(VLOOKUP('8.0.0'!L11,'8.0.0'!$AM$4:$AO$45,2,FALSE))*IF('8.0.0'!AN$4="是",'8.0.0'!$AY$4,'8.0.0'!$AY$3) -> 180 | E11: =(VLOOKUP('8.0.0'!M11,'8.0.0'!$AM$4:$AO$45,2,FALSE))*IF('8.0.0'!AO$4="是",'8.0.0'!$AY$4,'8.0.0'!$AY$3) -> 180 | F11: =(VLOOKUP('8.0.0'!N11,'8.0.0'!$AM$4:$AO$45,2,FALSE))*IF('8.0.0'!AQ$4="是",'8.0.0'!$AY$4,'8.0.0'!$AY$3) -> -200 | G11: =(VLOOKUP('8.0.0'!O11,'8.0.0'!$AM$4:$AO$45,2,FALSE))*IF('8.0.0'!AR$4="是",'8.0.0'!$AY$4,'8.0.0'!$AY$3) -> 180 | H11: =(VLOOKUP('8.0.0'!P11,'8.0.0'!$AM$4:$AO$45,2,FALSE))*IF('8.0.0'!AS$4="是",'8.0.0'!$AY$4,'8.0.0'!$AY$3) -> 180 | I11: =(VLOOKUP('8.0.0'!Q11,'8.0.0'!$AM$4:$AO$45,2,FALSE))*IF('8.0.0'!AT$4="是",'8.0.0'!$AY$4,'8.0.0'!$AY$3) -> 0 | J11: =(VLOOKUP('8.0.0'!R11,'8.0.0'!$AM$4:$AO$45,2,FALSE))*IF('8.0.0'!AU$4="是",'8.0.0'!$AY$4,'8.0.0'!$AY$3) -> 0 | K11: =(VLOOKUP('8.0.0'!S11,'8.0.0'!$AM$4:$AO$45,2,FALSE))*IF('8.0.0'!AV$4="是",'8.0.0'!$AY$4,'8.0.0'!$AY$3) -> 0 | L11: =(VLOOKUP('8.0.0'!T11,'8.0.0'!$AM$4:$AO$45,2,FALSE))*IF('8.0.0'!AW$4="是",'8.0.0'!$AY$4,'8.0.0'!$AY$3) -> 0 | M11: =(VLOOKUP('8.0.0'!U11,'8.0.0'!$AM$4:$AO$45,2,FALSE))*IF('8.0.0'!AX$4="是",'8.0.0'!$AY$4,'8.0.0'!$AY$3) -> 0 | ... X11: =(VLOOKUP('8.0.0'!AF11,'8.0.0'!$AM$4:$AO$45,2,FALSE))*IF('8.0.0'!BI$4="是",'8.0.0'!$AY$4,'8.0.0'!$AY$3) -> 0
A12: =(VLOOKUP('8.0.0'!I12,'8.0.0'!$AM$4:$AO$45,2,FALSE))*IF('8.0.0'!AK$4="是",'8.0.0'!$AY$4,'8.0.0'!$AY$3) -> 180 | B12: =(VLOOKUP('8.0.0'!J12,'8.0.0'!$AM$4:$AO$45,2,FALSE))*IF('8.0.0'!AL$4="是",'8.0.0'!$AY$4,'8.0.0'!$AY$3) -> 180 | C12: =(VLOOKUP('8.0.0'!K12,'8.0.0'!$AM$4:$AO$45,2,FALSE))*IF('8.0.0'!AM$4="是",'8.0.0'!$AY$4,'8.0.0'!$AY$3) -> 180 | D12: =(VLOOKUP('8.0.0'!L12,'8.0.0'!$AM$4:$AO$45,2,FALSE))*IF('8.0.0'!AN$4="是",'8.0.0'!$AY$4,'8.0.0'!$AY$3) -> 180 | E12: =(VLOOKUP('8.0.0'!M12,'8.0.0'!$AM$4:$AO$45,2,FALSE))*IF('8.0.0'!AO$4="是",'8.0.0'!$AY$4,'8.0.0'!$AY$3) -> 180 | F12: =(VLOOKUP('8.0.0'!N12,'8.0.0'!$AM$4:$AO$45,2,FALSE))*IF('8.0.0'!AQ$4="是",'8.0.0'!$AY$4,'8.0.0'!$AY$3) -> 180 | G12: =(VLOOKUP('8.0.0'!O12,'8.0.0'!$AM$4:$AO$45,2,FALSE))*IF('8.0.0'!AR$4="是",'8.0.0'!$AY$4,'8.0.0'!$AY$3) -> 0 | H12: =(VLOOKUP('8.0.0'!P12,'8.0.0'!$AM$4:$AO$45,2,FALSE))*IF('8.0.0'!AS$4="是",'8.0.0'!$AY$4,'8.0.0'!$AY$3) -> 0 | I12: =(VLOOKUP('8.0.0'!Q12,'8.0.0'!$AM$4:$AO$45,2,FALSE))*IF('8.0.0'!AT$4="是",'8.0.0'!$AY$4,'8.0.0'!$AY$3) -> 0 | J12: =(VLOOKUP('8.0.0'!R12,'8.0.0'!$AM$4:$AO$45,2,FALSE))*IF('8.0.0'!AU$4="是",'8.0.0'!$AY$4,'8.0.0'!$AY$3) -> 0 | K12: =(VLOOKUP('8.0.0'!S12,'8.0.0'!$AM$4:$AO$45,2,FALSE))*IF('8.0.0'!AV$4="是",'8.0.0'!$AY$4,'8.0.0'!$AY$3) -> 0 | L12: =(VLOOKUP('8.0.0'!T12,'8.0.0'!$AM$4:$AO$45,2,FALSE))*IF('8.0.0'!AW$4="是",'8.0.0'!$AY$4,'8.0.0'!$AY$3) -> 0 | M12: =(VLOOKUP('8.0.0'!U12,'8.0.0'!$AM$4:$AO$45,2,FALSE))*IF('8.0.0'!AX$4="是",'8.0.0'!$AY$4,'8.0.0'!$AY$3) -> 0 | ... X12: =(VLOOKUP('8.0.0'!AF12,'8.0.0'!$AM$4:$AO$45,2,FALSE))*IF('8.0.0'!BI$4="是",'8.0.0'!$AY$4,'8.0.0'!$AY$3) -> 0
A13: =(VLOOKUP('8.0.0'!I13,'8.0.0'!$AM$4:$AO$45,2,FALSE))*IF('8.0.0'!AK$4="是",'8.0.0'!$AY$4,'8.0.0'!$AY$3) -> 180 | B13: =(VLOOKUP('8.0.0'!J13,'8.0.0'!$AM$4:$AO$45,2,FALSE))*IF('8.0.0'!AL$4="是",'8.0.0'!$AY$4,'8.0.0'!$AY$3) -> 180 | C13: =(VLOOKUP('8.0.0'!K13,'8.0.0'!$AM$4:$AO$45,2,FALSE))*IF('8.0.0'!AM$4="是",'8.0.0'!$AY$4,'8.0.0'!$AY$3) -> 180 | D13: =(VLOOKUP('8.0.0'!L13,'8.0.0'!$AM$4:$AO$45,2,FALSE))*IF('8.0.0'!AN$4="是",'8.0.0'!$AY$4,'8.0.0'!$AY$3) -> 180 | E13: =(VLOOKUP('8.0.0'!M13,'8.0.0'!$AM$4:$AO$45,2,FALSE))*IF('8.0.0'!AO$4="是",'8.0.0'!$AY$4,'8.0.0'!$AY$3) -> 180 | F13: =(VLOOKUP('8.0.0'!N13,'8.0.0'!$AM$4:$AO$45,2,FALSE))*IF('8.0.0'!AQ$4="是",'8.0.0'!$AY$4,'8.0.0'!$AY$3) -> 180 | G13: =(VLOOKUP('8.0.0'!O13,'8.0.0'!$AM$4:$AO$45,2,FALSE))*IF('8.0.0'!AR$4="是",'8.0.0'!$AY$4,'8.0.0'!$AY$3) -> 0 | H13: =(VLOOKUP('8.0.0'!P13,'8.0.0'!$AM$4:$AO$45,2,FALSE))*IF('8.0.0'!AS$4="是",'8.0.0'!$AY$4,'8.0.0'!$AY$3) -> 0 | I13: =(VLOOKUP('8.0.0'!Q13,'8.0.0'!$AM$4:$AO$45,2,FALSE))*IF('8.0.0'!AT$4="是",'8.0.0'!$AY$4,'8.0.0'!$AY$3) -> 0 | J13: =(VLOOKUP('8.0.0'!R13,'8.0.0'!$AM$4:$AO$45,2,FALSE))*IF('8.0.0'!AU$4="是",'8.0.0'!$AY$4,'8.0.0'!$AY$3) -> 0 | K13: =(VLOOKUP('8.0.0'!S13,'8.0.0'!$AM$4:$AO$45,2,FALSE))*IF('8.0.0'!AV$4="是",'8.0.0'!$AY$4,'8.0.0'!$AY$3) -> 0 | L13: =(VLOOKUP('8.0.0'!T13,'8.0.0'!$AM$4:$AO$45,2,FALSE))*IF('8.0.0'!AW$4="是",'8.0.0'!$AY$4,'8.0.0'!$AY$3) -> 0 | M13: =(VLOOKUP('8.0.0'!U13,'8.0.0'!$AM$4:$AO$45,2,FALSE))*IF('8.0.0'!AX$4="是",'8.0.0'!$AY$4,'8.0.0'!$AY$3) -> 0 | ... X13: =(VLOOKUP('8.0.0'!AF13,'8.0.0'!$AM$4:$AO$45,2,FALSE))*IF('8.0.0'!BI$4="是",'8.0.0'!$AY$4,'8.0.0'!$AY$3) -> 0
A14: =(VLOOKUP('8.0.0'!I14,'8.0.0'!$AM$4:$AO$45,2,FALSE))*IF('8.0.0'!AK$4="是",'8.0.0'!$AY$4,'8.0.0'!$AY$3) -> 180 | B14: =(VLOOKUP('8.0.0'!J14,'8.0.0'!$AM$4:$AO$45,2,FALSE))*IF('8.0.0'!AL$4="是",'8.0.0'!$AY$4,'8.0.0'!$AY$3) -> 180 | C14: =(VLOOKUP('8.0.0'!K14,'8.0.0'!$AM$4:$AO$45,2,FALSE))*IF('8.0.0'!AM$4="是",'8.0.0'!$AY$4,'8.0.0'!$AY$3) -> 180 | D14: =(VLOOKUP('8.0.0'!L14,'8.0.0'!$AM$4:$AO$45,2,FALSE))*IF('8.0.0'!AN$4="是",'8.0.0'!$AY$4,'8.0.0'!$AY$3) -> 180 | E14: =(VLOOKUP('8.0.0'!M14,'8.0.0'!$AM$4:$AO$45,2,FALSE))*IF('8.0.0'!AO$4="是",'8.0.0'!$AY$4,'8.0.0'!$AY$3) -> 180 | F14: =(VLOOKUP('8.0.0'!N14,'8.0.0'!$AM$4:$AO$45,2,FALSE))*IF('8.0.0'!AQ$4="是",'8.0.0'!$AY$4,'8.0.0'!$AY$3) -> 180 | G14: =(VLOOKUP('8.0.0'!O14,'8.0.0'!$AM$4:$AO$45,2,FALSE))*IF('8.0.0'!AR$4="是",'8.0.0'!$AY$4,'8.0.0'!$AY$3) -> 0 | H14: =(VLOOKUP('8.0.0'!P14,'8.0.0'!$AM$4:$AO$45,2,FALSE))*IF('8.0.0'!AS$4="是",'8.0.0'!$AY$4,'8.0.0'!$AY$3) -> 0 | I14: =(VLOOKUP('8.0.0'!Q14,'8.0.0'!$AM$4:$AO$45,2,FALSE))*IF('8.0.0'!AT$4="是",'8.0.0'!$AY$4,'8.0.0'!$AY$3) -> 0 | J14: =(VLOOKUP('8.0.0'!R14,'8.0.0'!$AM$4:$AO$45,2,FALSE))*IF('8.0.0'!AU$4="是",'8.0.0'!$AY$4,'8.0.0'!$AY$3) -> 0 | K14: =(VLOOKUP('8.0.0'!S14,'8.0.0'!$AM$4:$AO$45,2,FALSE))*IF('8.0.0'!AV$4="是",'8.0.0'!$AY$4,'8.0.0'!$AY$3) -> 0 | L14: =(VLOOKUP('8.0.0'!T14,'8.0.0'!$AM$4:$AO$45,2,FALSE))*IF('8.0.0'!AW$4="是",'8.0.0'!$AY$4,'8.0.0'!$AY$3) -> 0 | M14: =(VLOOKUP('8.0.0'!U14,'8.0.0'!$AM$4:$AO$45,2,FALSE))*IF('8.0.0'!AX$4="是",'8.0.0'!$AY$4,'8.0.0'!$AY$3) -> 0 | ... X14: =(VLOOKUP('8.0.0'!AF14,'8.0.0'!$AM$4:$AO$45,2,FALSE))*IF('8.0.0'!BI$4="是",'8.0.0'!$AY$4,'8.0.0'!$AY$3) -> 0
A15: =(VLOOKUP('8.0.0'!I15,'8.0.0'!$AM$4:$AO$45,2,FALSE))*IF('8.0.0'!AK$4="是",'8.0.0'!$AY$4,'8.0.0'!$AY$3) -> 180 | B15: =(VLOOKUP('8.0.0'!J15,'8.0.0'!$AM$4:$AO$45,2,FALSE))*IF('8.0.0'!AL$4="是",'8.0.0'!$AY$4,'8.0.0'!$AY$3) -> 180 | C15: =(VLOOKUP('8.0.0'!K15,'8.0.0'!$AM$4:$AO$45,2,FALSE))*IF('8.0.0'!AM$4="是",'8.0.0'!$AY$4,'8.0.0'!$AY$3) -> 180 | D15: =(VLOOKUP('8.0.0'!L15,'8.0.0'!$AM$4:$AO$45,2,FALSE))*IF('8.0.0'!AN$4="是",'8.0.0'!$AY$4,'8.0.0'!$AY$3) -> 180 | E15: =(VLOOKUP('8.0.0'!M15,'8.0.0'!$AM$4:$AO$45,2,FALSE))*IF('8.0.0'!AO$4="是",'8.0.0'!$AY$4,'8.0.0'!$AY$3) -> 180 | F15: =(VLOOKUP('8.0.0'!N15,'8.0.0'!$AM$4:$AO$45,2,FALSE))*IF('8.0.0'!AQ$4="是",'8.0.0'!$AY$4,'8.0.0'!$AY$3) -> 180 | G15: =(VLOOKUP('8.0.0'!O15,'8.0.0'!$AM$4:$AO$45,2,FALSE))*IF('8.0.0'!AR$4="是",'8.0.0'!$AY$4,'8.0.0'!$AY$3) -> 0 | H15: =(VLOOKUP('8.0.0'!P15,'8.0.0'!$AM$4:$AO$45,2,FALSE))*IF('8.0.0'!AS$4="是",'8.0.0'!$AY$4,'8.0.0'!$AY$3) -> 0 | I15: =(VLOOKUP('8.0.0'!Q15,'8.0.0'!$AM$4:$AO$45,2,FALSE))*IF('8.0.0'!AT$4="是",'8.0.0'!$AY$4,'8.0.0'!$AY$3) -> 0 | J15: =(VLOOKUP('8.0.0'!R15,'8.0.0'!$AM$4:$AO$45,2,FALSE))*IF('8.0.0'!AU$4="是",'8.0.0'!$AY$4,'8.0.0'!$AY$3) -> 0 | K15: =(VLOOKUP('8.0.0'!S15,'8.0.0'!$AM$4:$AO$45,2,FALSE))*IF('8.0.0'!AV$4="是",'8.0.0'!$AY$4,'8.0.0'!$AY$3) -> 0 | L15: =(VLOOKUP('8.0.0'!T15,'8.0.0'!$AM$4:$AO$45,2,FALSE))*IF('8.0.0'!AW$4="是",'8.0.0'!$AY$4,'8.0.0'!$AY$3) -> 0 | M15: =(VLOOKUP('8.0.0'!U15,'8.0.0'!$AM$4:$AO$45,2,FALSE))*IF('8.0.0'!AX$4="是",'8.0.0'!$AY$4,'8.0.0'!$AY$3) -> 0 | ... X15: =(VLOOKUP('8.0.0'!AF15,'8.0.0'!$AM$4:$AO$45,2,FALSE))*IF('8.0.0'!BI$4="是",'8.0.0'!$AY$4,'8.0.0'!$AY$3) -> 0
... A94: =(VLOOKUP('8.0.0'!I94,'8.0.0'!$AM$4:$AO$45,2,FALSE))*IF('8.0.0'!AK$4="是",'8.0.0'!$AY$4,'8.0.0'!$AY$3) -> 190 | B94: =(VLOOKUP('8.0.0'!J94,'8.0.0'!$AM$4:$AO$45,2,FALSE))*IF('8.0.0'!AL$4="是",'8.0.0'!$AY$4,'8.0.0'!$AY$3) -> 190 | C94: =(VLOOKUP('8.0.0'!K94,'8.0.0'!$AM$4:$AO$45,2,FALSE))*IF('8.0.0'!AM$4="是",'8.0.0'!$AY$4,'8.0.0'!$AY$3) -> 190 | D94: =(VLOOKUP('8.0.0'!L94,'8.0.0'!$AM$4:$AO$45,2,FALSE))*IF('8.0.0'!AN$4="是",'8.0.0'!$AY$4,'8.0.0'!$AY$3) -> 190 | E94: =(VLOOKUP('8.0.0'!M94,'8.0.0'!$AM$4:$AO$45,2,FALSE))*IF('8.0.0'!AO$4="是",'8.0.0'!$AY$4,'8.0.0'!$AY$3) -> 190 | F94: =(VLOOKUP('8.0.0'!N94,'8.0.0'!$AM$4:$AO$45,2,FALSE))*IF('8.0.0'!AQ$4="是",'8.0.0'!$AY$4,'8.0.0'!$AY$3) -> 0 | G94: =(VLOOKUP('8.0.0'!O94,'8.0.0'!$AM$4:$AO$45,2,FALSE))*IF('8.0.0'!AR$4="是",'8.0.0'!$AY$4,'8.0.0'!$AY$3) -> 0 | H94: =(VLOOKUP('8.0.0'!P94,'8.0.0'!$AM$4:$AO$45,2,FALSE))*IF('8.0.0'!AS$4="是",'8.0.0'!$AY$4,'8.0.0'!$AY$3) -> 0 | I94: =(VLOOKUP('8.0.0'!Q94,'8.0.0'!$AM$4:$AO$45,2,FALSE))*IF('8.0.0'!AT$4="是",'8.0.0'!$AY$4,'8.0.0'!$AY$3) -> 0 | J94: =(VLOOKUP('8.0.0'!R94,'8.0.0'!$AM$4:$AO$45,2,FALSE))*IF('8.0.0'!AU$4="是",'8.0.0'!$AY$4,'8.0.0'!$AY$3) -> 0 | K94: =(VLOOKUP('8.0.0'!S94,'8.0.0'!$AM$4:$AO$45,2,FALSE))*IF('8.0.0'!AV$4="是",'8.0.0'!$AY$4,'8.0.0'!$AY$3) -> 0 | L94: =(VLOOKUP('8.0.0'!T94,'8.0.0'!$AM$4:$AO$45,2,FALSE))*IF('8.0.0'!AW$4="是",'8.0.0'!$AY$4,'8.0.0'!$AY$3) -> 0 | M94: =(VLOOKUP('8.0.0'!U94,'8.0.0'!$AM$4:$AO$45,2,FALSE))*IF('8.0.0'!AX$4="是",'8.0.0'!$AY$4,'8.0.0'!$AY$3) -> 0 | ... X94: =(VLOOKUP('8.0.0'!AF94,'8.0.0'!$AM$4:$AO$45,2,FALSE))*IF('8.0.0'!BI$4="是",'8.0.0'!$AY$4,'8.0.0'!$AY$3) -> 0

Sheet 经验
A2: 队伍一 风 | C2: 步数 | D2: =COUNTIF(A4:H94,"<>空") -> 728 | E2: (不算跳步和传送) | I2: 队伍二 雷 | K2: 步数 | L2: =COUNTIF(I4:P94,"<>空") -> 728 | M2: (不算跳步和传送) | Q2: 队伍三 | S2: 总步数 | T2: =COUNTIF(Q4:X94,"<>空") -> 728 | U2: (不算跳步和传送)
A3: 1 | B3: 2 | C3: 3 | D3: 4 | E3: 5 | F3: 6 | G3: 7 | H3: 8 | I3: 1 | J3: 2 | K3: 3 | L3: 4 | M3: 5 | N3: 6 | O3: 7 | P3: 8 | Q3: 1 | R3: 2 | S3: 3 | T3: 4 | U3: 5 | V3: 6 | W3: 7 | X3: 8
A4: =(VLOOKUP('8.0.0'!I4,'8.0.0'!$AM$4:$AO$45,3,FALSE)) -> 35 | B4: =(VLOOKUP('8.0.0'!J4,'8.0.0'!$AM$4:$AO$45,3,FALSE)) -> 35 | C4: =(VLOOKUP('8.0.0'!K4,'8.0.0'!$AM$4:$AO$45,3,FALSE)) -> 35 | D4: =(VLOOKUP('8.0.0'!L4,'8.0.0'!$AM$4:$AO$45,3,FALSE)) -> 35 | E4: =(VLOOKUP('8.0.0'!M4,'8.0.0'!$AM$4:$AO$45,3,FALSE)) -> 35 | F4: =(VLOOKUP('8.0.0'!N4,'8.0.0'!$AM$4:$AO$45,3,FALSE)) -> 35 | G4: =(VLOOKUP('8.0.0'!O4,'8.0.0'!$AM$4:$AO$45,3,FALSE)) -> 0 | H4: =(VLOOKUP('8.0.0'!P4,'8.0.0'!$AM$4:$AO$45,3,FALSE)) -> 0 | ... X4: =(VLOOKUP('8.0.0'!AF4,'8.0.0'!$AM$4:$AO$45,3,FALSE)) -> 40
A5: =(VLOOKUP('8.0.0'!I5,'8.0.0'!$AM$4:$AO$45,3,FALSE)) -> 45 | B5: =(VLOOKUP('8.0.0'!J5,'8.0.0'!$AM$4:$AO$45,3,FALSE)) -> 45 | C5: =(VLOOKUP('8.0.0'!K5,'8.0.0'!$AM$4:$AO$45,3,FALSE)) -> 30 | D5: =(VLOOKUP('8.0.0'!L5,'8.0.0'!$AM$4:$AO$45,3,FALSE)) -> 45 | E5: =(VLOOKUP('8.0.0'!M5,'8.0.0'!$AM$4:$AO$45,3,FALSE)) -> 45 | F5: =(VLOOKUP('8.0.0'!N5,'8.0.0'!$AM$4:$AO$45,3,FALSE)) -> 45 | G5: =(VLOOKUP('8.0.0'!O5,'8.0.0'!$AM$4:$AO$45,3,FALSE)) -> 0 | H5: =(VLOOKUP('8.0.0'!P5,'8.0.0'!$AM$4:$AO$45,3,FALSE)) -> 0 | ... X5: =(VLOOKUP('8.0.0'!AF5,'8.0.0'!$AM$4:$AO$45,3,FALSE)) -> 0
A6: =(VLOOKUP('8.0.0'!I6,'8.0.0'!$AM$4:$AO$45,3,FALSE)) -> 45 | B6: =(VLOOKUP('8.0.0'!J6,'8.0.0'!$AM$4:$AO$45,3,FALSE)) -> 45 | C6: =(VLOOKUP('8.0.0'!K6,'8.0.0'!$AM$4:$AO$45,3,FALSE)) -> 45 | D6: =(VLOOKUP('8.0.0'!L6,'8.0.0'!$AM$4:$AO$45,3,FALSE)) -> 45 | E6: =(VLOOKUP('8.0.0'!M6,'8.0.0'!$AM$4:$AO$45,3,FALSE)) -> 45 | F6: =(VLOOKUP('8.0.0'!N6,'8.0.0'!$AM$4:$AO$45,3,FALSE)) -> 45 | G6: =(VLOOKUP('8.0.0'!O6,'8.0.0'!$AM$4:$AO$45,3,FALSE)) -> 0 | H6: =(VLOOKUP('8.0.0'!P6,'8.0.0'!$AM$4:$AO$45,3,FALSE)) -> 0 | ... X6: =(VLOOKUP('8.0.0'!AF6,'8.0.0'!$AM$4:$AO$45,3,FALSE)) -> 45
A7: =(VLOOKUP('8.0.0'!I7,'8.0.0'!$AM$4:$AO$45,3,FALSE)) -> 45 | B7: =(VLOOKUP('8.0.0'!J7,'8.0.0'!$AM$4:$AO$45,3,FALSE)) -> 45 | C7: =(VLOOKUP('8.0.0'!K7,'8.0.0'!$AM$4:$AO$45,3,FALSE)) -> 45 | D7: =(VLOOKUP('8.0.0'!L7,'8.0.0'!$AM$4:$AO$45,3,FALSE)) -> 45 | E7: =(VLOOKUP('8.0.0'!M7,'8.0.0'!$AM$4:$AO$45,3,FALSE)) -> 45 | F7: =(VLOOKUP('8.0.0'!N7,'8.0.0'!$AM$4:$AO$45,3,FALSE)) -> 45 | G7: =(VLOOKUP('8.0.0'!O7,'8.0.0'!$AM$4:$AO$45,3,FALSE)) -> 0 | H7: =(VLOOKUP('8.0.0'!P7,'8.0.0'!$AM$4:$AO$45,3,FALSE)) -> 0 | ... X7: =(VLOOKUP('8.0.0'!AF7,'8.0.0'!$AM$4:$AO$45,3,FALSE)) -> 0
A8: =(VLOOKUP('8.0.0'!I8,'8.0.0'!$AM$4:$AO$45,3,FALSE)) -> 45 | B8: =(VLOOKUP('8.0.0'!J8,'8.0.0'!$AM$4:$AO$45,3,FALSE)) -> 45 | C8: =(VLOOKUP('8.0.0'!K8,'8.0.0'!$AM$4:$AO$45,3,FALSE)) -> 45 | D8: =(VLOOKUP('8.0.0'!L8,'8.0.0'!$AM$4:$AO$45,3,FALSE)) -> 200 | E8: =(VLOOKUP('8.0.0'!M8,'8.0.0'!$AM$4:$AO$45,3,FALSE)) -> 45 | F8: =(VLOOKUP('8.0.0'!N8,'8.0.0'!$AM$4:$AO$45,3,FALSE)) -> 45 | G8: =(VLOOKUP('8.0.0'!O8,'8.0.0'!$AM$4:$AO$45,3,FALSE)) -> 0 | H8: =(VLOOKUP('8.0.0'!P8,'8.0.0'!$AM$4:$AO$45,3,FALSE)) -> 45 | ... X8: =(VLOOKUP('8.0.0'!AF8,'8.0.0'!$AM$4:$AO$45,3,FALSE)) -> 0
A9: =(VLOOKUP('8.0.0'!I9,'8.0.0'!$AM$4:$AO$45,3,FALSE)) -> 45 | B9: =(VLOOKUP('8.0.0'!J9,'8.0.0'!$AM$4:$AO$45,3,FALSE)) -> 45 | C9: =(VLOOKUP('8.0.0'!K9,'8.0.0'!$AM$4:$AO$45,3,FALSE)) -> 30 | D9: =(VLOOKUP('8.0.0'!L9,'8.0.0'!$AM$4:$AO$45,3,FALSE)) -> 45 | E9: =(VLOOKUP('8.0.0'!M9,'8.0.0'!$AM$4:$AO$45,3,FALSE)) -> 45 | F9: =(VLOOKUP('8.0.0'!N9,'8.0.0'!$AM$4:$AO$45,3,FALSE)) -> 45 | G9: =(VLOOKUP('8.0.0'!O9,'8.0.0'!$AM$4:$AO$45,3,FALSE)) -> 0 | H9: =(VLOOKUP('8.0.0'!P9,'8.0.0'!$AM$4:$AO$45,3,FALSE)) -> 0 | ... X9: =(VLOOKUP('8.0.0'!AF9,'8.0.0'!$AM$4:$AO$45,3,FALSE)) -> 0
A10: =(VLOOKUP('8.0.0'!I10,'8.0.0'!$AM$4:$AO$45,3,FALSE)) -> 45 | B10: =(VLOOKUP('8.0.0'!J10,'8.0.0'!$AM$4:$AO$45,3,FALSE)) -> 45 | C10: =(VLOOKUP('8.0.0'!K10,'8.0.0'!$AM$4:$AO$45,3,FALSE)) -> 30 | D10: =(VLOOKUP('8.0.0'!L10,'8.0.0'!$AM$4:$AO$45,3,FALSE)) -> 45 | E10: =(VLOOKUP('8.0.0'!M10,'8.0.0'!$AM$4:$AO$45,3,FALSE)) -> 45 | F10: =(VLOOKUP('8.0.0'!N10,'8.0.0'!$AM$4:$AO$45,3,FALSE)) -> 50 | G10: =(VLOOKUP('8.0.0'!O10,'8.0.0'!$AM$4:$AO$45,3,FALSE)) -> 0 | H10: =(VLOOKUP('8.0.0'!P10,'8.0.0'!$AM$4:$AO$45,3,FALSE)) -> 0 | ... X10: =(VLOOKUP('8.0.0'!AF10,'8.0.0'!$AM$4:$AO$45,3,FALSE)) -> 0
A11: =(VLOOKUP('8.0.0'!I11,'8.0.0'!$AM$4:$AO$45,3,FALSE)) -> 50 | B11: =(VLOOKUP('8.0.0'!J11,'8.0.0'!$AM$4:$AO$45,3,FALSE)) -> 50 | C11: =(VLOOKUP('8.0.0'!K11,'8.0.0'!$AM$4:$AO$45,3,FALSE)) -> 30 | D11: =(VLOOKUP('8.0.0'!L11,'8.0.0'!$AM$4:$AO$45,3,FALSE)) -> 50 | E11: =(VLOOKUP('8.0.0'!M11,'8.0.0'!$AM$4:$AO$45,3,FALSE)) -> 50 | F11: =(VLOOKUP('8.0.0'!N11,'8.0.0'!$AM$4:$AO$45,3,FALSE)) -> 0 | G11: =(VLOOKUP('8.0.0'!O11,'8.0.0'!$AM$4:$AO$45,3,FALSE)) -> 50 | H11: =(VLOOKUP('8.0.0'!P11,'8.0.0'!$AM$4:$AO$45,3,FALSE)) -> 50 | ... X11: =(VLOOKUP('8.0.0'!AF11,'8.0.0'!$AM$4:$AO$45,3,FALSE)) -> 0
A12: =(VLOOKUP('8.0.0'!I12,'8.0.0'!$AM$4:$AO$45,3,FALSE)) -> 50 | B12: =(VLOOKUP('8.0.0'!J12,'8.0.0'!$AM$4:$AO$45,3,FALSE)) -> 50 | C12: =(VLOOKUP('8.0.0'!K12,'8.0.0'!$AM$4:$AO$45,3,FALSE)) -> 50 | D12: =(VLOOKUP('8.0.0'!L12,'8.0.0'!$AM$4:$AO$45,3,FALSE)) -> 50 | E12: =(VLOOKUP('8.0.0'!M12,'8.0.0'!$AM$4:$AO$45,3,FALSE)) -> 50 | F12: =(VLOOKUP('8.0.0'!N12,'8.0.0'!$AM$4:$AO$45,3,FALSE)) -> 50 | G12: =(VLOOKUP('8.0.0'!O12,'8.0.0'!$AM$4:$AO$45,3,FALSE)) -> 0 | H12: =(VLOOKUP('8.0.0'!P12,'8.0.0'!$AM$4:$AO$45,3,FALSE)) -> 0 | ... X12: =(VLOOKUP('8.0.0'!AF12,'8.0.0'!$AM$4:$AO$45,3,FALSE)) -> 0
A13: =(VLOOKUP('8.0.0'!I13,'8.0.0'!$AM$4:$AO$45,3,FALSE)) -> 50 | B13: =(VLOOKUP('8.0.0'!J13,'8.0.0'!$AM$4:$AO$45,3,FALSE)) -> 50 | C13: =(VLOOKUP('8.0.0'!K13,'8.0.0'!$AM$4:$AO$45,3,FALSE)) -> 50 | D13: =(VLOOKUP('8.0.0'!L13,'8.0.0'!$AM$4:$AO$45,3,FALSE)) -> 50 | E13: =(VLOOKUP('8.0.0'!M13,'8.0.0'!$AM$4:$AO$45,3,FALSE)) -> 50 | F13: =(VLOOKUP('8.0.0'!N13,'8.0.0'!$AM$4:$AO$45,3,FALSE)) -> 50 | G13: =(VLOOKUP('8.0.0'!O13,'8.0.0'!$AM$4:$AO$45,3,FALSE)) -> 0 | H13: =(VLOOKUP('8.0.0'!P13,'8.0.0'!$AM$4:$AO$45,3,FALSE)) -> 0 | ... X13: =(VLOOKUP('8.0.0'!AF13,'8.0.0'!$AM$4:$AO$45,3,FALSE)) -> 0
A14: =(VLOOKUP('8.0.0'!I14,'8.0.0'!$AM$4:$AO$45,3,FALSE)) -> 50 | B14: =(VLOOKUP('8.0.0'!J14,'8.0.0'!$AM$4:$AO$45,3,FALSE)) -> 50 | C14: =(VLOOKUP('8.0.0'!K14,'8.0.0'!$AM$4:$AO$45,3,FALSE)) -> 50 | D14: =(VLOOKUP('8.0.0'!L14,'8.0.0'!$AM$4:$AO$45,3,FALSE)) -> 50 | E14: =(VLOOKUP('8.0.0'!M14,'8.0.0'!$AM$4:$AO$45,3,FALSE)) -> 50 | F14: =(VLOOKUP('8.0.0'!N14,'8.0.0'!$AM$4:$AO$45,3,FALSE)) -> 50 | G14: =(VLOOKUP('8.0.0'!O14,'8.0.0'!$AM$4:$AO$45,3,FALSE)) -> 0 | H14: =(VLOOKUP('8.0.0'!P14,'8.0.0'!$AM$4:$AO$45,3,FALSE)) -> 0 | ... X14: =(VLOOKUP('8.0.0'!AF14,'8.0.0'!$AM$4:$AO$45,3,FALSE)) -> 0
A15: =(VLOOKUP('8.0.0'!I15,'8.0.0'!$AM$4:$AO$45,3,FALSE)) -> 50 | B15: =(VLOOKUP('8.0.0'!J15,'8.0.0'!$AM$4:$AO$45,3,FALSE)) -> 50 | C15: =(VLOOKUP('8.0.0'!K15,'8.0.0'!$AM$4:$AO$45,3,FALSE)) -> 50 | D15: =(VLOOKUP('8.0.0'!L15,'8.0.0'!$AM$4:$AO$45,3,FALSE)) -> 50 | E15: =(VLOOKUP('8.0.0'!M15,'8.0.0'!$AM$4:$AO$45,3,FALSE)) -> 50 | F15: =(VLOOKUP('8.0.0'!N15,'8.0.0'!$AM$4:$AO$45,3,FALSE)) -> 50 | G15: =(VLOOKUP('8.0.0'!O15,'8.0.0'!$AM$4:$AO$45,3,FALSE)) -> 0 | H15: =(VLOOKUP('8.0.0'!P15,'8.0.0'!$AM$4:$AO$45,3,FALSE)) -> 0 | ... X15: =(VLOOKUP('8.0.0'!AF15,'8.0.0'!$AM$4:$AO$45,3,FALSE)) -> 0
... A94: =(VLOOKUP('8.0.0'!I94,'8.0.0'!$AM$4:$AO$45,3,FALSE)) -> 55 | B94: =(VLOOKUP('8.0.0'!J94,'8.0.0'!$AM$4:$AO$45,3,FALSE)) -> 55 | C94: =(VLOOKUP('8.0.0'!K94,'8.0.0'!$AM$4:$AO$45,3,FALSE)) -> 55 | D94: =(VLOOKUP('8.0.0'!L94,'8.0.0'!$AM$4:$AO$45,3,FALSE)) -> 55 | E94: =(VLOOKUP('8.0.0'!M94,'8.0.0'!$AM$4:$AO$45,3,FALSE)) -> 55 | F94: =(VLOOKUP('8.0.0'!N94,'8.0.0'!$AM$4:$AO$45,3,FALSE)) -> 0 | G94: =(VLOOKUP('8.0.0'!O94,'8.0.0'!$AM$4:$AO$45,3,FALSE)) -> 0 | H94: =(VLOOKUP('8.0.0'!P94,'8.0.0'!$AM$4:$AO$45,3,FALSE)) -> 0 | ... X94: =(VLOOKUP('8.0.0'!AF94,'8.0.0'!$AM$4:$AO$45,3,FALSE)) -> 0

Sheet 亏损
A2: 队伍一 风 | C2: 步数 | D2: =COUNTIF(A4:H94,"<>空") -> 728 | E2: (不算跳步和传送) | I2: 队伍二 雷 | K2: 步数 | L2: =COUNTIF(I4:P94,"<>空") -> 728 | M2: (不算跳步和传送) | Q2: 队伍三 | S2: 总步数 | T2: =COUNTIF(Q4:X94,"<>空") -> 728 | U2: (不算跳步和传送)
A3: 1 | B3: 2 | C3: 3 | D3: 4 | E3: 5 | F3: 6 | G3: 7 | H3: 8 | I3: 1 | J3: 2 | K3: 3 | L3: 4 | M3: 5 | N3: 6 | O3: 7 | P3: 8 | Q3: 1 | R3: 2 | S3: 3 | T3: 4 | U3: 5 | V3: 6 | W3: 7 | X3: 8
A4: =(VLOOKUP('8.0.0'!I4,'8.0.0'!$AM$4:$AP$48,4,FALSE)) -> 44.222109 | B4: =(VLOOKUP('8.0.0'!J4,'8.0.0'!$AM$4:$AP$48,4,FALSE)) -> 44.222109 | C4: =(VLOOKUP('8.0.0'!K4,'8.0.0'!$AM$4:$AP$48,4,FALSE)) -> 44.222109 | D4: =(VLOOKUP('8.0.0'!L4,'8.0.0'!$AM$4:$AP$48,4,FALSE)) -> 44.222109 | E4: =(VLOOKUP('8.0.0'!M4,'8.0.0'!$AM$4:$AP$48,4,FALSE)) -> 44.222109 | F4: =(VLOOKUP('8.0.0'!N4,'8.0.0'!$AM$4:$AP$48,4,FALSE)) -> 44.222109 | G4: =(VLOOKUP('8.0.0'!O4,'8.0.0'!$AM$4:$AP$48,4,FALSE)) -> 0 | H4: =(VLOOKUP('8.0.0'!P4,'8.0.0'!$AM$4:$AP$48,4,FALSE)) -> 0 | ... X4: =(VLOOKUP('8.0.0'!AF4,'8.0.0'!$AM$4:$AP$48,4,FALSE)) -> 39.110982
A5: =(VLOOKUP('8.0.0'!I5,'8.0.0'!$AM$4:$AP$48,4,FALSE)) -> 34 | B5: =(VLOOKUP('8.0.0'!J5,'8.0.0'!$AM$4:$AP$48,4,FALSE)) -> 34 | C5: =(VLOOKUP('8.0.0'!K5,'8.0.0'!$AM$4:$AP$48,4,FALSE)) -> 10 | D5: =(VLOOKUP('8.0.0'!L5,'8.0.0'!$AM$4:$AP$48,4,FALSE)) -> 34 | E5: =(VLOOKUP('8.0.0'!M5,'8.0.0'!$AM$4:$AP$48,4,FALSE)) -> 34 | F5: =(VLOOKUP('8.0.0'!N5,'8.0.0'!$AM$4:$AP$48,4,FALSE)) -> 34 | G5: =(VLOOKUP('8.0.0'!O5,'8.0.0'!$AM$4:$AP$48,4,FALSE)) -> 0 | H5: =(VLOOKUP('8.0.0'!P5,'8.0.0'!$AM$4:$AP$48,4,FALSE)) -> 0 | ... X5: =(VLOOKUP('8.0.0'!AF5,'8.0.0'!$AM$4:$AP$48,4,FALSE)) -> 0
A6: =(VLOOKUP('8.0.0'!I6,'8.0.0'!$AM$4:$AP$48,4,FALSE)) -> 0 | B6: =(VLOOKUP('8.0.0'!J6,'8.0.0'!$AM$4:$AP$48,4,FALSE)) -> 34 | C6: =(VLOOKUP('8.0.0'!K6,'8.0.0'!$AM$4:$AP$48,4,FALSE)) -> 34 | D6: =(VLOOKUP('8.0.0'!L6,'8.0.0'!$AM$4:$AP$48,4,FALSE)) -> 34 | E6: =(VLOOKUP('8.0.0'!M6,'8.0.0'!$AM$4:$AP$48,4,FALSE)) -> 34 | F6: =(VLOOKUP('8.0.0'!N6,'8.0.0'!$AM$4:$AP$48,4,FALSE)) -> 34 | G6: =(VLOOKUP('8.0.0'!O6,'8.0.0'!$AM$4:$AP$48,4,FALSE)) -> 0 | H6: =(VLOOKUP('8.0.0'!P6,'8.0.0'!$AM$4:$AP$48,4,FALSE)) -> 0 | ... X6: =(VLOOKUP('8.0.0'!AF6,'8.0.0'!$AM$4:$AP$48,4,FALSE)) -> 34
A7: =(VLOOKUP('8.0.0'!I7,'8.0.0'!$AM$4:$AP$48,4,FALSE)) -> 34 | B7: =(VLOOKUP('8.0.0'!J7,'8.0.0'!$AM$4:$AP$48,4,FALSE)) -> 34 | C7: =(VLOOKUP('8.0.0'!K7,'8.0.0'!$AM$4:$AP$48,4,FALSE)) -> 0 | D7: =(VLOOKUP('8.0.0'!L7,'8.0.0'!$AM$4:$AP$48,4,FALSE)) -> 34 | E7: =(VLOOKUP('8.0.0'!M7,'8.0.0'!$AM$4:$AP$48,4,FALSE)) -> 34 | F7: =(VLOOKUP('8.0.0'!N7,'8.0.0'!$AM$4:$AP$48,4,FALSE)) -> 34 | G7: =(VLOOKUP('8.0.0'!O7,'8.0.0'!$AM$4:$AP$48,4,FALSE)) -> 0 | H7: =(VLOOKUP('8.0.0'!P7,'8.0.0'!$AM$4:$AP$48,4,FALSE)) -> 0 | ... X7: =(VLOOKUP('8.0.0'!AF7,'8.0.0'!$AM$4:$AP$48,4,FALSE)) -> 0
A8: =(VLOOKUP('8.0.0'!I8,'8.0.0'!$AM$4:$AP$48,4,FALSE)) -> 34 | B8: =(VLOOKUP('8.0.0'!J8,'8.0.0'!$AM$4:$AP$48,4,FALSE)) -> 13.999855 | C8: =(VLOOKUP('8.0.0'!K8,'8.0.0'!$AM$4:$AP$48,4,FALSE)) -> 34 | D8: =(VLOOKUP('8.0.0'!L8,'8.0.0'!$AM$4:$AP$48,4,FALSE)) -> 0 | E8: =(VLOOKUP('8.0.0'!M8,'8.0.0'!$AM$4:$AP$48,4,FALSE)) -> 34 | F8: =(VLOOKUP('8.0.0'!N8,'8.0.0'!$AM$4:$AP$48,4,FALSE)) -> 34 | G8: =(VLOOKUP('8.0.0'!O8,'8.0.0'!$AM$4:$AP$48,4,FALSE)) -> 10 | H8: =(VLOOKUP('8.0.0'!P8,'8.0.0'!$AM$4:$AP$48,4,FALSE)) -> 34 | ... X8: =(VLOOKUP('8.0.0'!AF8,'8.0.0'!$AM$4:$AP$48,4,FALSE)) -> 0
