Workbook

Sheet  6.0.00
A1: =(_xlfn.DAYS(TODAY(),A4)+2)/((_xlfn.DAYS(A94,A4))+1) -> 0.010989011 | I1: 工作区 | AM1: 使用方法：按自己规划的路线，将下表中的地块名复制粘贴至工作区。初次使用传送门，当天跳步次数+5。重复使用传送门，当天跳步次数+1
A2: version 7.0.00b | D2: 合计经验 | F2: =SUM(F4:F94)+SUM(H4:H94) -> 7000 | I2: 队伍一 火 | K2: 步数 | L2: =COUNTIF(I4:P94,"<>空") -> 0 | M2: (不算跳步和传送) | Q2: 队伍二 雷 | S2: 步数 | T2: =COUNTIF(Q4:X94,"<>空") -> 0 | U2: (不算跳步和传送) | Y2: 队伍三 | AA2: 总步数 | AB2: =COUNTIF(Y4:AF94,"<>空") -> 0 | AC2: (不算跳步和传送) | AG2: =SUM(AG4:AG94) -> 0 | AH2: =SUM(AH4:AH94) -> 0 | AI2: =SUM(AI4:AI94) -> 0 | AJ2: =SUM(AJ4:AJ94) -> 0 | AK2: 八卦全开 | AR2: 总地块 | AS2: =SUM(AS4:AS28) -> 0 | AU2: 总经验 | AV2: =SUM(AT4:AV28)+7000 -> 7000 | AX2: 粮草系数
A3: 日期 | B3: 获得粮草 | C3: 种植粮草 | D3: 消耗粮草 | E3: 剩余粮草 | F3: 获得经验 | G3: 累计经验 | H3: 任务经验 | I3: 1 | J3: 2 | K3: 3 | L3: 4 | M3: 5 | N3: 6 | O3: 7 | P3: 8 | Q3: 1 | R3: 2 | S3: 3 | T3: 4 | U3: 5 | V3: 6 | W3: 7 | X3: 8 | Y3: 1 | Z3: 2 | AA3: 3 | AB3: 4 | AC3: 5 | AD3: 6 | AE3: 7 | AF3: 8 | AG3: 跳步次数 | AH3: 1队跳步 | AI3: 2队跳步 | AJ3: 3队跳步 | AM3: 地块 | AN3: 粮草 | AO3: 经验 | AP3: 一队地块 | AQ3: 二队地块 | AR3: 三队地块 | AS3: 总地块 | AT3: 一队经验 | AU3: 二队经验 | AV3: 三队经验 | AW3: 八卦前 | AX3: 1
A4: 44729 | B4: 800 | D4: =(SUM(粮草!A4:X4)+AG4*10)*IF(AK4="是",$AX$4,$AX$3) -> 0 | E4: =SUM($B$4:B4)+SUM($C$4:C4)-SUM($D$4:D4) -> 800 | F4: =SUM(经验!A4:X4) -> 0 | G4: =SUM($F$4:F4)+SUM($H$4:H4) -> 0 | H4: 0 | I4: 空 | J4: 空 | K4: 空 | L4: 空 | M4: 空 | N4: 空 | O4: 空 | P4: 空 | Q4: 空 | R4: 空 | S4: 空 | T4: 空 | U4: 空 | V4: 空 | W4: 空 | X4: 空 | Y4: 空 | Z4: 空 | AA4: 空 | AB4: 空 | AC4: 空 | AD4: 空 | AE4: 空 | AF4: 空 | AG4: 0 | AK4: 否 | AM4: 1级 | AN4: 150 | AO4: 35 | AP4: =COUNTIF($I$4:$P$94,AM4) -> 0 | AQ4: =COUNTIF($Q$4:$X$94,AM4) -> 0 | AR4: =COUNTIF($Y$4:$AF$94,AM4) -> 0 | AS4: =AP4+AQ4+AR4 -> 0 | AT4: =AP4*$AO4 -> 0 | AU4: =AQ4*$AO4 -> 0 | AV4: =AR4*$AO4 -> 0 | AW4: 八卦后 | AX4: 0.8 | AZ4: =AN4*0.8 -> 120
A5: 44730 | B5: 1600 | D5: =(SUM(粮草!A5:X5)+AG5*10)*IF(AK5="是",$AX$4,$AX$3) -> 0 | E5: =SUM($B$4:B5)+SUM($C$4:C5)-SUM($D$4:D5) -> 2400 | F5: =SUM(经验!A5:X5) -> 0 | G5: =SUM($F$4:F5)+SUM($H$4:H5) -> 500 | H5: 500 | I5: 空 | J5: 空 | K5: 空 | L5: 空 | M5: 空 | N5: 空 | O5: 空 | P5: 空 | Q5: 空 | R5: 空 | S5: 空 | T5: 空 | U5: 空 | V5: 空 | W5: 空 | X5: 空 | Y5: 空 | Z5: 空 | AA5: 空 | AB5: 空 | AC5: 空 | AD5: 空 | AE5: 空 | AF5: 空 | AG5: 0 | AK5: 否 | AM5: 2级 | AN5: 160 | AO5: 40 | AP5: =COUNTIF($I$4:$P$94,AM5) -> 0 | AQ5: =COUNTIF($Q$4:$X$94,AM5) -> 0 | AR5: =COUNTIF($Y$4:$AF$94,AM5) -> 0 | AS5: =AP5+AQ5+AR5 -> 0 | AT5: =AP5*$AO5 -> 0 | AU5: =AQ5*$AO5 -> 0 | AV5: =AR5*$AO5 -> 0 | AW5: Note：开完八卦当天可能需要手动计算粮草 | AZ5: =AN5*0.8 -> 128
A6: 44731 | B6: 1600 | D6: =(SUM(粮草!A6:X6)+AG6*10)*IF(AK6="是",$AX$4,$AX$3) -> 0 | E6: =SUM($B$4:B6)+SUM($C$4:C6)-SUM($D$4:D6) -> 4000 | F6: =SUM(经验!A6:X6) -> 0 | G6: =SUM($F$4:F6)+SUM($H$4:H6) -> 500 | H6: 0 | I6: 空 | J6: 空 | K6: 空 | L6: 空 | M6: 空 | N6: 空 | O6: 空 | P6: 空 | Q6: 空 | R6: 空 | S6: 空 | T6: 空 | U6: 空 | V6: 空 | W6: 空 | X6: 空 | Y6: 空 | Z6: 空 | AA6: 空 | AB6: 空 | AC6: 空 | AD6: 空 | AE6: 空 | AF6: 空 | AG6: 0 | AK6: 否 | AM6: 3级 | AN6: 170 | AO6: 45 | AP6: =COUNTIF($I$4:$P$94,AM6) -> 0 | AQ6: =COUNTIF($Q$4:$X$94,AM6) -> 0 | AR6: =COUNTIF($Y$4:$AF$94,AM6) -> 0 | AS6: =AP6+AQ6+AR6 -> 0 | AT6: =AP6*$AO6 -> 0 | AU6: =AQ6*$AO6 -> 0 | AV6: =AR6*$AO6 -> 0 | AZ6: =AN6*0.8 -> 136
A7: 44732 | B7: 1600 | D7: =(SUM(粮草!A7:X7)+AG7*10)*IF(AK7="是",$AX$4,$AX$3) -> 0 | E7: =SUM($B$4:B7)+SUM($C$4:C7)-SUM($D$4:D7) -> 5600 | F7: =SUM(经验!A7:X7) -> 0 | G7: =SUM($F$4:F7)+SUM($H$4:H7) -> 700 | H7: 200 | I7: 空 | J7: 空 | K7: 空 | L7: 空 | M7: 空 | N7: 空 | O7: 空 | P7: 空 | Q7: 空 | R7: 空 | S7: 空 | T7: 空 | U7: 空 | V7: 空 | W7: 空 | X7: 空 | Y7: 空 | Z7: 空 | AA7: 空 | AB7: 空 | AC7: 空 | AD7: 空 | AE7: 空 | AF7: 空 | AG7: 0 | AK7: 否 | AM7: 4级 | AN7: 180 | AO7: 50 | AP7: =COUNTIF($I$4:$P$94,AM7) -> 0 | AQ7: =COUNTIF($Q$4:$X$94,AM7) -> 0 | AR7: =COUNTIF($Y$4:$AF$94,AM7) -> 0 | AS7: =AP7+AQ7+AR7 -> 0 | AT7: =AP7*$AO7 -> 0 | AU7: =AQ7*$AO7 -> 0 | AV7: =AR7*$AO7 -> 0 | AZ7: =AN7*0.8 -> 144
A8: 44733 | B8: 1600 | D8: =(SUM(粮草!A8:X8)+AG8*10)*IF(AK8="是",$AX$4,$AX$3) -> 0 | E8: =SUM($B$4:B8)+SUM($C$4:C8)-SUM($D$4:D8) -> 7200 | F8: =SUM(经验!A8:X8) -> 0 | G8: =SUM($F$4:F8)+SUM($H$4:H8) -> 800 | H8: 100 | I8: 空 | J8: 空 | K8: 空 | L8: 空 | M8: 空 | N8: 空 | O8: 空 | P8: 空 | Q8: 空 | R8: 空 | S8: 空 | T8: 空 | U8: 空 | V8: 空 | W8: 空 | X8: 空 | Y8: 空 | Z8: 空 | AA8: 空 | AB8: 空 | AC8: 空 | AD8: 空 | AE8: 空 | AF8: 空 | AG8: 0 | AK8: 否 | AM8: 5级 | AN8: 190 | AO8: 55 | AP8: =COUNTIF($I$4:$P$94,AM8) -> 0 | AQ8: =COUNTIF($Q$4:$X$94,AM8) -> 0 | AR8: =COUNTIF($Y$4:$AF$94,AM8) -> 0 | AS8: =AP8+AQ8+AR8 -> 0 | AT8: =AP8*$AO8 -> 0 | AU8: =AQ8*$AO8 -> 0 | AV8: =AR8*$AO8 -> 0 | AZ8: =AN8*0.8 -> 152
A9: 44734 | B9: 1600 | D9: =(SUM(粮草!A9:X9)+AG9*10)*IF(AK9="是",$AX$4,$AX$3) -> 0 | E9: =SUM($B$4:B9)+SUM($C$4:C9)-SUM($D$4:D9) -> 8800 | F9: =SUM(经验!A9:X9) -> 0 | G9: =SUM($F$4:F9)+SUM($H$4:H9) -> 1000 | H9: 200 | I9: 空 | J9: 空 | K9: 空 | L9: 空 | M9: 空 | N9: 空 | O9: 空 | P9: 空 | Q9: 空 | R9: 空 | S9: 空 | T9: 空 | U9: 空 | V9: 空 | W9: 空 | X9: 空 | Y9: 空 | Z9: 空 | AA9: 空 | AB9: 空 | AC9: 空 | AD9: 空 | AE9: 空 | AF9: 空 | AG9: 0 | AK9: 否 | AM9: 6级 | AN9: 200 | AO9: 60 | AP9: =COUNTIF($I$4:$P$94,AM9) -> 0 | AQ9: =COUNTIF($Q$4:$X$94,AM9) -> 0 | AR9: =COUNTIF($Y$4:$AF$94,AM9) -> 0 | AS9: =AP9+AQ9+AR9 -> 0 | AT9: =AP9*$AO9 -> 0 | AU9: =AQ9*$AO9 -> 0 | AV9: =AR9*$AO9 -> 0 | AZ9: =AN9*0.8 -> 160
A10: 44735 | B10: 1600 | D10: =(SUM(粮草!A10:X10)+AG10*10)*IF(AK10="是",$AX$4,$AX$3) -> 0 | E10: =SUM($B$4:B10)+SUM($C$4:C10)-SUM($D$4:D10) -> 10400 | F10: =SUM(经验!A10:X10) -> 0 | G10: =SUM($F$4:F10)+SUM($H$4:H10) -> 1000 | H10: 0 | I10: 空 | J10: 空 | K10: 空 | L10: 空 | M10: 空 | N10: 空 | O10: 空 | P10: 空 | Q10: 空 | R10: 空 | S10: 空 | T10: 空 | U10: 空 | V10: 空 | W10: 空 | X10: 空 | Y10: 空 | Z10: 空 | AA10: 空 | AB10: 空 | AC10: 空 | AD10: 空 | AE10: 空 | AF10: 空 | AG10: 0 | AK10: 否 | AM10: 塔1 | AN10: 150 | AO10: 35 | AP10: =COUNTIF($I$4:$P$94,AM10) -> 0 | AQ10: =COUNTIF($Q$4:$X$94,AM10) -> 0 | AR10: =COUNTIF($Y$4:$AF$94,AM10) -> 0 | AS10: =AP10+AQ10+AR10 -> 0 | AT10: =AP10*$AO10 -> 0 | AU10: =AQ10*$AO10 -> 0 | AV10: =AR10*$AO10 -> 0 | AZ10: =AN10*0.8 -> 120
A11: 44736 | B11: 1600 | D11: =(SUM(粮草!A11:X11)+AG11*10)*IF(AK11="是",$AX$4,$AX$3) -> 0 | E11: =SUM($B$4:B11)+SUM($C$4:C11)-SUM($D$4:D11) -> 12000 | F11: =SUM(经验!A11:X11) -> 0 | G11: =SUM($F$4:F11)+SUM($H$4:H11) -> 1000 | H11: 0 | I11: 空 | J11: 空 | K11: 空 | L11: 空 | M11: 空 | N11: 空 | O11: 空 | P11: 空 | Q11: 空 | R11: 空 | S11: 空 | T11: 空 | U11: 空 | V11: 空 | W11: 空 | X11: 空 | Y11: 空 | Z11: 空 | AA11: 空 | AB11: 空 | AC11: 空 | AD11: 空 | AE11: 空 | AF11: 空 | AG11: 0 | AK11: 否 | AM11: 塔2 | AN11: 150 | AO11: 40 | AP11: =COUNTIF($I$4:$P$94,AM11) -> 0 | AQ11: =COUNTIF($Q$4:$X$94,AM11) -> 0 | AR11: =COUNTIF($Y$4:$AF$94,AM11) -> 0 | AS11: =AP11+AQ11+AR11 -> 0 | AT11: =AP11*$AO11 -> 0 | AU11: =AQ11*$AO11 -> 0 | AV11: =AR11*$AO11 -> 0 | AZ11: =AN11*0.8 -> 120
A12: 44737 | B12: 1600 | D12: =(SUM(粮草!A12:X12)+AG12*10)*IF(AK12="是",$AX$4,$AX$3) -> 0 | E12: =SUM($B$4:B12)+SUM($C$4:C12)-SUM($D$4:D12) -> 13600 | F12: =SUM(经验!A12:X12) -> 0 | G12: =SUM($F$4:F12)+SUM($H$4:H12) -> 1000 | H12: 0 | I12: 空 | J12: 空 | K12: 空 | L12: 空 | M12: 空 | N12: 空 | O12: 空 | P12: 空 | Q12: 空 | R12: 空 | S12: 空 | T12: 空 | U12: 空 | V12: 空 | W12: 空 | X12: 空 | Y12: 空 | Z12: 空 | AA12: 空 | AB12: 空 | AC12: 空 | AD12: 空 | AE12: 空 | AF12: 空 | AG12: 0 | AK12: 否 | AM12: 塔3 | AN12: 150 | AO12: 45 | AP12: =COUNTIF($I$4:$P$94,AM12) -> 0 | AQ12: =COUNTIF($Q$4:$X$94,AM12) -> 0 | AR12: =COUNTIF($Y$4:$AF$94,AM12) -> 0 | AS12: =AP12+AQ12+AR12 -> 0 | AT12: =AP12*$AO12 -> 0 | AU12: =AQ12*$AO12 -> 0 | AV12: =AR12*$AO12 -> 0 | AZ12: =AN12*0.8 -> 120
A13: 44738 | B13: 1600 | D13: =(SUM(粮草!A13:X13)+AG13*10)*IF(AK13="是",$AX$4,$AX$3) -> 0 | E13: =SUM($B$4:B13)+SUM($C$4:C13)-SUM($D$4:D13) -> 15200 | F13: =SUM(经验!A13:X13) -> 0 | G13: =SUM($F$4:F13)+SUM($H$4:H13) -> 1000 | H13: 0 | I13: 空 | J13: 空 | K13: 空 | L13: 空 | M13: 空 | N13: 空 | O13: 空 | P13: 空 | Q13: 空 | R13: 空 | S13: 空 | T13: 空 | U13: 空 | V13: 空 | W13: 空 | X13: 空 | Y13: 空 | Z13: 空 | AA13: 空 | AB13: 空 | AC13: 空 | AD13: 空 | AE13: 空 | AF13: 空 | AG13: 0 | AK13: 否 | AM13: 塔4 | AN13: 150 | AO13: 50 | AP13: =COUNTIF($I$4:$P$94,AM13) -> 0 | AQ13: =COUNTIF($Q$4:$X$94,AM13) -> 0 | AR13: =COUNTIF($Y$4:$AF$94,AM13) -> 0 | AS13: =AP13+AQ13+AR13 -> 0 | AT13: =AP13*$AO13 -> 0 | AU13: =AQ13*$AO13 -> 0 | AV13: =AR13*$AO13 -> 0 | AZ13: =AN13*0.8 -> 120
A14: 44739 | B14: 1600 | D14: =(SUM(粮草!A14:X14)+AG14*10)*IF(AK14="是",$AX$4,$AX$3) -> 0 | E14: =SUM($B$4:B14)+SUM($C$4:C14)-SUM($D$4:D14) -> 16800 | F14: =SUM(经验!A14:X14) -> 0 | G14: =SUM($F$4:F14)+SUM($H$4:H14) -> 1300 | H14: 300 | I14: 空 | J14: 空 | K14: 空 | L14: 空 | M14: 空 | N14: 空 | O14: 空 | P14: 空 | Q14: 空 | R14: 空 | S14: 空 | T14: 空 | U14: 空 | V14: 空 | W14: 空 | X14: 空 | Y14: 空 | Z14: 空 | AA14: 空 | AB14: 空 | AC14: 空 | AD14: 空 | AE14: 空 | AF14: 空 | AG14: 0 | AK14: 否 | AM14: 塔5 | AN14: 150 | AO14: 55 | AP14: =COUNTIF($I$4:$P$94,AM14) -> 0 | AQ14: =COUNTIF($Q$4:$X$94,AM14) -> 0 | AR14: =COUNTIF($Y$4:$AF$94,AM14) -> 0 | AS14: =AP14+AQ14+AR14 -> 0 | AT14: =AP14*$AO14 -> 0 | AU14: =AQ14*$AO14 -> 0 | AV14: =AR14*$AO14 -> 0 | AZ14: =AN14*0.8 -> 120
A15: 44740 | B15: 1600 | D15: =(SUM(粮草!A15:X15)+AG15*10)*IF(AK15="是",$AX$4,$AX$3) -> 0 | E15: =SUM($B$4:B15)+SUM($C$4:C15)-SUM($D$4:D15) -> 18400 | F15: =SUM(经验!A15:X15) -> 0 | G15: =SUM($F$4:F15)+SUM($H$4:H15) -> 1300 | H15: 0 | I15: 空 | J15: 空 | K15: 空 | L15: 空 | M15: 空 | N15: 空 | O15: 空 | P15: 空 | Q15: 空 | R15: 空 | S15: 空 | T15: 空 | U15: 空 | V15: 空 | W15: 空 | X15: 空 | Y15: 空 | Z15: 空 | AA15: 空 | AB15: 空 | AC15: 空 | AD15: 空 | AE15: 空 | AF15: 空 | AG15: 0 | AK15: 否 | AM15: 塔6 | AN15: 150 | AO15: 60 | AP15: =COUNTIF($I$4:$P$94,AM15) -> 0 | AQ15: =COUNTIF($Q$4:$X$94,AM15) -> 0 | AR15: =COUNTIF($Y$4:$AF$94,AM15) -> 0 | AS15: =AP15+AQ15+AR15 -> 0 | AT15: =AP15*$AO15 -> 0 | AU15: =AQ15*$AO15 -> 0 | AV15: =AR15*$AO15 -> 0 | AZ15: =AN15*0.8 -> 120
A16: 44741 | B16: 1600 | D16: =(SUM(粮草!A16:X16)+AG16*10)*IF(AK16="是",$AX$4,$AX$3) -> 0 | E16: =SUM($B$4:B16)+SUM($C$4:C16)-SUM($D$4:D16) -> 20000 | F16: =SUM(经验!A16:X16) -> 0 | G16: =SUM($F$4:F16)+SUM($H$4:H16) -> 1500 | H16: 200 | I16: 空 | J16: 空 | K16: 空 | L16: 空 | M16: 空 | N16: 空 | O16: 空 | P16: 空 | Q16: 空 | R16: 空 | S16: 空 | T16: 空 | U16: 空 | V16: 空 | W16: 空 | X16: 空 | Y16: 空 | Z16: 空 | AA16: 空 | AB16: 空 | AC16: 空 | AD16: 空 | AE16: 空 | AF16: 空 | AG16: 0 | AK16: 否 | AM16: 遗迹 | AN16: 150 | AO16: 35 | AP16: =COUNTIF($I$4:$P$94,AM16) -> 0 | AQ16: =COUNTIF($Q$4:$X$94,AM16) -> 0 | AR16: =COUNTIF($Y$4:$AF$94,AM16) -> 0 | AS16: =AP16+AQ16+AR16 -> 0 | AT16: =AP16*$AO16 -> 0 | AU16: =AQ16*$AO16 -> 0 | AV16: =AR16*$AO16 -> 0 | AZ16: =AN16*0.8 -> 120
A17: 44742 | B17: 1600 | D17: =(SUM(粮草!A17:X17)+AG17*10)*IF(AK17="是",$AX$4,$AX$3) -> 0 | E17: =SUM($B$4:B17)+SUM($C$4:C17)-SUM($D$4:D17) -> 21600 | F17: =SUM(经验!A17:X17) -> 0 | G17: =SUM($F$4:F17)+SUM($H$4:H17) -> 1500 | H17: 0 | I17: 空 | J17: 空 | K17: 空 | L17: 空 | M17: 空 | N17: 空 | O17: 空 | P17: 空 | Q17: 空 | R17: 空 | S17: 空 | T17: 空 | U17: 空 | V17: 空 | W17: 空 | X17: 空 | Y17: 空 | Z17: 空 | AA17: 空 | AB17: 空 | AC17: 空 | AD17: 空 | AE17: 空 | AF17: 空 | AG17: 0 | AK17: 否 | AM17: 商人 | AN17: 50 | AO17: 30 | AP17: =COUNTIF($I$4:$P$94,AM17) -> 0 | AQ17: =COUNTIF($Q$4:$X$94,AM17) -> 0 | AR17: =COUNTIF($Y$4:$AF$94,AM17) -> 0 | AS17: =AP17+AQ17+AR17 -> 0 | AT17: =AP17*$AO17 -> 0 | AU17: =AQ17*$AO17 -> 0 | AV17: =AR17*$AO17 -> 0 | AZ17: =AN17*0.8 -> 40
A18: 44743 | B18: 1600 | D18: =(SUM(粮草!A18:X18)+AG18*10)*IF(AK18="是",$AX$4,$AX$3) -> 0 | E18: =SUM($B$4:B18)+SUM($C$4:C18)-SUM($D$4:D18) -> 23200 | F18: =SUM(经验!A18:X18) -> 0 | G18: =SUM($F$4:F18)+SUM($H$4:H18) -> 1500 | H18: 0 | I18: 空 | J18: 空 | K18: 空 | L18: 空 | M18: 空 | N18: 空 | O18: 空 | P18: 空 | Q18: 空 | R18: 空 | S18: 空 | T18: 空 | U18: 空 | V18: 空 | W18: 空 | X18: 空 | Y18: 空 | Z18: 空 | AA18: 空 | AB18: 空 | AC18: 空 | AD18: 空 | AE18: 空 | AF18: 空 | AG18: 0 | AK18: 否 | AL18: 八卦前 | AM18: 营地 | AN18: -150 | AO18: 0 | AP18: =COUNTIF($I$4:$P$94,AM18) -> 0 | AQ18: =COUNTIF($Q$4:$X$94,AM18) -> 0 | AR18: =COUNTIF($Y$4:$AF$94,AM18) -> 0 | AS18: =AP18+AQ18+AR18 -> 0 | AT18: =AP18*$AO18 -> 0 | AU18: =AQ18*$AO18 -> 0 | AV18: =AR18*$AO18 -> 0 | AZ18: =AN18*0.8 -> -120
A19: 44744 | B19: 1600 | D19: =(SUM(粮草!A19:X19)+AG19*10)*IF(AK19="是",$AX$4,$AX$3) -> 0 | E19: =SUM($B$4:B19)+SUM($C$4:C19)-SUM($D$4:D19) -> 24800 | F19: =SUM(经验!A19:X19) -> 0 | G19: =SUM($F$4:F19)+SUM($H$4:H19) -> 1500 | H19: 0 | I19: 空 | J19: 空 | K19: 空 | L19: 空 | M19: 空 | N19: 空 | O19: 空 | P19: 空 | Q19: 空 | R19: 空 | S19: 空 | T19: 空 | U19: 空 | V19: 空 | W19: 空 | X19: 空 | Y19: 空 | Z19: 空 | AA19: 空 | AB19: 空 | AC19: 空 | AD19: 空 | AE19: 空 | AF19: 空 | AG19: 0 | AK19: 是 | AM19: 大卦 | AN19: 250 | AO19: 200 | AP19: =COUNTIF($I$4:$P$94,AM19) -> 0 | AQ19: =COUNTIF($Q$4:$X$94,AM19) -> 0 | AR19: =COUNTIF($Y$4:$AF$94,AM19) -> 0 | AS19: =AP19+AQ19+AR19 -> 0 | AT19: =AP19*$AO19 -> 0 | AU19: =AQ19*$AO19 -> 0 | AV19: =AR19*$AO19 -> 0 | AZ19: =AN19*0.8 -> 200
A20: 44745 | B20: 1600 | D20: =(SUM(粮草!A20:X20)+AG20*10)*IF(AK20="是",$AX$4,$AX$3) -> 0 | E20: =SUM($B$4:B20)+SUM($C$4:C20)-SUM($D$4:D20) -> 26400 | F20: =SUM(经验!A20:X20) -> 0 | G20: =SUM($F$4:F20)+SUM($H$4:H20) -> 1500 | H20: 0 | I20: 空 | J20: 空 | K20: 空 | L20: 空 | M20: 空 | N20: 空 | O20: 空 | P20: 空 | Q20: 空 | R20: 空 | S20: 空 | T20: 空 | U20: 空 | V20: 空 | W20: 空 | X20: 空 | Y20: 空 | Z20: 空 | AA20: 空 | AB20: 空 | AC20: 空 | AD20: 空 | AE20: 空 | AF20: 空 | AG20: 0 | AK20: 是 | AM20: 小卦 | AN20: 170 | AO20: 45 | AP20: =COUNTIF($I$4:$P$94,AM20) -> 0 | AQ20: =COUNTIF($Q$4:$X$94,AM20) -> 0 | AR20: =COUNTIF($Y$4:$AF$94,AM20) -> 0 | AS20: =AP20+AQ20+AR20 -> 0 | AT20: =AP20*$AO20 -> 0 | AU20: =AQ20*$AO20 -> 0 | AV20: =AR20*$AO20 -> 0 | AZ20: =AN20*0.8 -> 136
A21: 44746 | B21: 1600 | D21: =(SUM(粮草!A21:X21)+AG21*10)*IF(AK21="是",$AX$4,$AX$3) -> 0 | E21: =SUM($B$4:B21)+SUM($C$4:C21)-SUM($D$4:D21) -> 28000 | F21: =SUM(经验!A21:X21) -> 0 | G21: =SUM($F$4:F21)+SUM($H$4:H21) -> 1700 | H21: 200 | I21: 空 | J21: 空 | K21: 空 | L21: 空 | M21: 空 | N21: 空 | O21: 空 | P21: 空 | Q21: 空 | R21: 空 | S21: 空 | T21: 空 | U21: 空 | V21: 空 | W21: 空 | X21: 空 | Y21: 空 | Z21: 空 | AA21: 空 | AB21: 空 | AC21: 空 | AD21: 空 | AE21: 空 | AF21: 空 | AG21: 0 | AK21: 是 | AM21: 小boss | AN21: 250 | AO21: 200 | AP21: =COUNTIF($I$4:$P$94,AM21) -> 0 | AQ21: =COUNTIF($Q$4:$X$94,AM21) -> 0 | AR21: =COUNTIF($Y$4:$AF$94,AM21) -> 0 | AS21: =AP21+AQ21+AR21 -> 0 | AT21: =AP21*$AO21 -> 0 | AU21: =AQ21*$AO21 -> 0 | AV21: =AR21*$AO21 -> 0 | AZ21: =AN21*0.8 -> 200
A22: 44747 | B22: 1600 | D22: =(SUM(粮草!A22:X22)+AG22*10)*IF(AK22="是",$AX$4,$AX$3) -> 0 | E22: =SUM($B$4:B22)+SUM($C$4:C22)-SUM($D$4:D22) -> 29600 | F22: =SUM(经验!A22:X22) -> 0 | G22: =SUM($F$4:F22)+SUM($H$4:H22) -> 1800 | H22: 100 | I22: 空 | J22: 空 | K22: 空 | L22: 空 | M22: 空 | N22: 空 | O22: 空 | P22: 空 | Q22: 空 | R22: 空 | S22: 空 | T22: 空 | U22: 空 | V22: 空 | W22: 空 | X22: 空 | Y22: 空 | Z22: 空 | AA22: 空 | AB22: 空 | AC22: 空 | AD22: 空 | AE22: 空 | AF22: 空 | AG22: 0 | AK22: 是 | AM22: 大boss | AN22: 250 | AO22: 1000 | AP22: =COUNTIF($I$4:$P$94,AM22) -> 0 | AQ22: =COUNTIF($Q$4:$X$94,AM22) -> 0 | AR22: =COUNTIF($Y$4:$AF$94,AM22) -> 0 | AS22: =AP22+AQ22+AR22 -> 0 | AT22: =AP22*$AO22 -> 0 | AU22: =AQ22*$AO22 -> 0 | AV22: =AR22*$AO22 -> 0 | AZ22: =AN22*0.8 -> 200
A23: 44748 | B23: 1600 | D23: =(SUM(粮草!A23:X23)+AG23*10)*IF(AK23="是",$AX$4,$AX$3) -> 0 | E23: =SUM($B$4:B23)+SUM($C$4:C23)-SUM($D$4:D23) -> 31200 | F23: =SUM(经验!A23:X23) -> 0 | G23: =SUM($F$4:F23)+SUM($H$4:H23) -> 2000 | H23: 200 | I23: 空 | J23: 空 | K23: 空 | L23: 空 | M23: 空 | N23: 空 | O23: 空 | P23: 空 | Q23: 空 | R23: 空 | S23: 空 | T23: 空 | U23: 空 | V23: 空 | W23: 空 | X23: 空 | Y23: 空 | Z23: 空 | AA23: 空 | AB23: 空 | AC23: 空 | AD23: 空 | AE23: 空 | AF23: 空 | AG23: 0 | AK23: 是 | AM23: 中boss | AN23: 250 | AO23: 500 | AP23: =COUNTIF($I$4:$P$94,AM23) -> 0 | AQ23: =COUNTIF($Q$4:$X$94,AM23) -> 0 | AR23: =COUNTIF($Y$4:$AF$94,AM23) -> 0 | AS23: =AP23+AQ23+AR23 -> 0 | AT23: =AP23*$AO23 -> 0 | AU23: =AQ23*$AO23 -> 0 | AV23: =AR23*$AO23 -> 0 | AZ23: =AN23*0.8 -> 200
A24: 44749 | B24: 1600 | D24: =(SUM(粮草!A24:X24)+AG24*10)*IF(AK24="是",$AX$4,$AX$3) -> 0 | E24: =SUM($B$4:B24)+SUM($C$4:C24)-SUM($D$4:D24) -> 32800 | F24: =SUM(经验!A24:X24) -> 0 | G24: =SUM($F$4:F24)+SUM($H$4:H24) -> 2000 | H24: 0 | I24: 空 | J24: 空 | K24: 空 | L24: 空 | M24: 空 | N24: 空 | O24: 空 | P24: 空 | Q24: 空 | R24: 空 | S24: 空 | T24: 空 | U24: 空 | V24: 空 | W24: 空 | X24: 空 | Y24: 空 | Z24: 空 | AA24: 空 | AB24: 空 | AC24: 空 | AD24: 空 | AE24: 空 | AF24: 空 | AG24: 0 | AK24: 是 | AM24: 奈良 | AN24: 160 | AO24: 40 | AP24: =COUNTIF($I$4:$P$94,AM24) -> 0 | AQ24: =COUNTIF($Q$4:$X$94,AM24) -> 0 | AR24: =COUNTIF($Y$4:$AF$94,AM24) -> 0 | AS24: =AP24+AQ24+AR24 -> 0 | AT24: =AP24*$AO24 -> 0 | AU24: =AQ24*$AO24 -> 0 | AV24: =AR24*$AO24 -> 0 | AZ24: =AN24*0.8 -> 128
A25: 44750 | B25: 1600 | D25: =(SUM(粮草!A25:X25)+AG25*10)*IF(AK25="是",$AX$4,$AX$3) -> 0 | E25: =SUM($B$4:B25)+SUM($C$4:C25)-SUM($D$4:D25) -> 34400 | F25: =SUM(经验!A25:X25) -> 0 | G25: =SUM($F$4:F25)+SUM($H$4:H25) -> 2000 | H25: 0 | I25: 空 | J25: 空 | K25: 空 | L25: 空 | M25: 空 | N25: 空 | O25: 空 | P25: 空 | Q25: 空 | R25: 空 | S25: 空 | T25: 空 | U25: 空 | V25: 空 | W25: 空 | X25: 空 | Y25: 空 | Z25: 空 | AA25: 空 | AB25: 空 | AC25: 空 | AD25: 空 | AE25: 空 | AF25: 空 | AG25: 0 | AK25: 是 | AM25: 山中 | AN25: 160 | AO25: 40 | AP25: =COUNTIF($I$4:$P$94,AM25) -> 0 | AQ25: =COUNTIF($Q$4:$X$94,AM25) -> 0 | AR25: =COUNTIF($Y$4:$AF$94,AM25) -> 0 | AS25: =AP25+AQ25+AR25 -> 0 | AT25: =AP25*$AO25 -> 0 | AU25: =AQ25*$AO25 -> 0 | AV25: =AR25*$AO25 -> 0 | AZ25: =AN25*0.8 -> 128
A26: 44751 | B26: 1600 | D26: =(SUM(粮草!A26:X26)+AG26*10)*IF(AK26="是",$AX$4,$AX$3) -> 0 | E26: =SUM($B$4:B26)+SUM($C$4:C26)-SUM($D$4:D26) -> 36000 | F26: =SUM(经验!A26:X26) -> 0 | G26: =SUM($F$4:F26)+SUM($H$4:H26) -> 2000 | H26: 0 | I26: 空 | J26: 空 | K26: 空 | L26: 空 | M26: 空 | N26: 空 | O26: 空 | P26: 空 | Q26: 空 | R26: 空 | S26: 空 | T26: 空 | U26: 空 | V26: 空 | W26: 空 | X26: 空 | Y26: 空 | Z26: 空 | AA26: 空 | AB26: 空 | AC26: 空 | AD26: 空 | AE26: 空 | AF26: 空 | AG26: 0 | AK26: 是 | AM26: 秋道 | AN26: 150 | AO26: 35 | AP26: =COUNTIF($I$4:$P$94,AM26) -> 0 | AQ26: =COUNTIF($Q$4:$X$94,AM26) -> 0 | AR26: =COUNTIF($Y$4:$AF$94,AM26) -> 0 | AS26: =AP26+AQ26+AR26 -> 0 | AT26: =AP26*$AO26 -> 0 | AU26: =AQ26*$AO26 -> 0 | AV26: =AR26*$AO26 -> 0 | AZ26: =AN26*0.8 -> 120
A27: 44752 | B27: 1600 | D27: =(SUM(粮草!A27:X27)+AG27*10)*IF(AK27="是",$AX$4,$AX$3) -> 0 | E27: =SUM($B$4:B27)+SUM($C$4:C27)-SUM($D$4:D27) -> 37600 | F27: =SUM(经验!A27:X27) -> 0 | G27: =SUM($F$4:F27)+SUM($H$4:H27) -> 2000 | H27: 0 | I27: 空 | J27: 空 | K27: 空 | L27: 空 | M27: 空 | N27: 空 | O27: 空 | P27: 空 | Q27: 空 | R27: 空 | S27: 空 | T27: 空 | U27: 空 | V27: 空 | W27: 空 | X27: 空 | Y27: 空 | Z27: 空 | AA27: 空 | AB27: 空 | AC27: 空 | AD27: 空 | AE27: 空 | AF27: 空 | AG27: 0 | AK27: 是 | AM27: 空 | AN27: 0 | AO27: 0 | AT27: =AP27*$AO27 -> 0 | AU27: =AQ27*$AO27 -> 0 | AV27: =AR27*$AO27 -> 0 | AZ27: =AN27*0.8 -> 0
A28: 44753 | B28: 1600 | D28: =(SUM(粮草!A28:X28)+AG28*10)*IF(AK28="是",$AX$4,$AX$3) -> 0 | E28: =SUM($B$4:B28)+SUM($C$4:C28)-SUM($D$4:D28) -> 39200 | F28: =SUM(经验!A28:X28) -> 0 | G28: =SUM($F$4:F28)+SUM($H$4:H28) -> 2200 | H28: 200 | I28: 空 | J28: 空 | K28: 空 | L28: 空 | M28: 空 | N28: 空 | O28: 空 | P28: 空 | Q28: 空 | R28: 空 | S28: 空 | T28: 空 | U28: 空 | V28: 空 | W28: 空 | X28: 空 | Y28: 空 | Z28: 空 | AA28: 空 | AB28: 空 | AC28: 空 | AD28: 空 | AE28: 空 | AF28: 空 | AG28: 0 | AK28: 是 | AL28: 八卦后 | AM28: 营地+ | AN28: -200 | AO28: 0 | AP28: =COUNTIF($I$4:$P$94,AM28) -> 0 | AQ28: =COUNTIF($Q$4:$X$94,AM28) -> 0 | AR28: =COUNTIF($Y$4:$AF$94,AM28) -> 0 | AS28: =AP28+AQ28+AR28 -> 0 | AT28: =AP28*$AO28 -> 0 | AU28: =AQ28*$AO28 -> 0 | AV28: =AR28*$AO28 -> 0 | AZ28: =AN28*0.8 -> -160
A29: 44754 | B29: 1600 | D29: =(SUM(粮草!A29:X29)+AG29*10)*IF(AK29="是",$AX$4,$AX$3) -> 0 | E29: =SUM($B$4:B29)+SUM($C$4:C29)-SUM($D$4:D29) -> 40800 | F29: =SUM(经验!A29:X29) -> 0 | G29: =SUM($F$4:F29)+SUM($H$4:H29) -> 2300 | H29: 100 | I29: 空 | J29: 空 | K29: 空 | L29: 空 | M29: 空 | N29: 空 | O29: 空 | P29: 空 | Q29: 空 | R29: 空 | S29: 空 | T29: 空 | U29: 空 | V29: 空 | W29: 空 | X29: 空 | Y29: 空 | Z29: 空 | AA29: 空 | AB29: 空 | AC29: 空 | AD29: 空 | AE29: 空 | AF29: 空 | AG29: 0 | AK29: 是 | AM29: 历练 | AN29: 50 | AO29: 520 | AP29: =COUNTIF($I$4:$P$94,AM29) -> 0 | AQ29: =COUNTIF($Q$4:$X$94,AM29) -> 0 | AR29: =COUNTIF($Y$4:$AF$94,AM29) -> 0 | AS29: =AP29+AQ29+AR29 -> 0 | AT29: =AP29*$AO29 -> 0 | AU29: =AQ29*$AO29 -> 0 | AV29: =AR29*$AO29 -> 0 | AZ29: =AN29*0.8 -> 40
A30: 44755 | B30: 1600 | D30: =(SUM(粮草!A30:X30)+AG30*10)*IF(AK30="是",$AX$4,$AX$3) -> 0 | E30: =SUM($B$4:B30)+SUM($C$4:C30)-SUM($D$4:D30) -> 42400 | F30: =SUM(经验!A30:X30) -> 0 | G30: =SUM($F$4:F30)+SUM($H$4:H30) -> 2500 | H30: 200 | I30: 空 | J30: 空 | K30: 空 | L30: 空 | M30: 空 | N30: 空 | O30: 空 | P30: 空 | Q30: 空 | R30: 空 | S30: 空 | T30: 空 | U30: 空 | V30: 空 | W30: 空 | X30: 空 | Y30: 空 | Z30: 空 | AA30: 空 | AB30: 空 | AC30: 空 | AD30: 空 | AE30: 空 | AF30: 空 | AG30: 0 | AK30: 是
A31: 44756 | B31: 1600 | D31: =(SUM(粮草!A31:X31)+AG31*10)*IF(AK31="是",$AX$4,$AX$3) -> 0 | E31: =SUM($B$4:B31)+SUM($C$4:C31)-SUM($D$4:D31) -> 44000 | F31: =SUM(经验!A31:X31) -> 0 | G31: =SUM($F$4:F31)+SUM($H$4:H31) -> 2500 | H31: 0 | I31: 空 | J31: 空 | K31: 空 | L31: 空 | M31: 空 | N31: 空 | O31: 空 | P31: 空 | Q31: 空 | R31: 空 | S31: 空 | T31: 空 | U31: 空 | V31: 空 | W31: 空 | X31: 空 | Y31: 空 | Z31: 空 | AA31: 空 | AB31: 空 | AC31: 空 | AD31: 空 | AE31: 空 | AF31: 空 | AG31: 0 | AK31: 是
A32: 44757 | B32: 1600 | D32: =(SUM(粮草!A32:X32)+AG32*10)*IF(AK32="是",$AX$4,$AX$3) -> 0 | E32: =SUM($B$4:B32)+SUM($C$4:C32)-SUM($D$4:D32) -> 45600 | F32: =SUM(经验!A32:X32) -> 0 | G32: =SUM($F$4:F32)+SUM($H$4:H32) -> 2500 | H32: 0 | I32: 空 | J32: 空 | K32: 空 | L32: 空 | M32: 空 | N32: 空 | O32: 空 | P32: 空 | Q32: 空 | R32: 空 | S32: 空 | T32: 空 | U32: 空 | V32: 空 | W32: 空 | X32: 空 | Y32: 空 | Z32: 空 | AA32: 空 | AB32: 空 | AC32: 空 | AD32: 空 | AE32: 空 | AF32: 空 | AG32: 0 | AK32: 是
A33: 44758 | B33: 1600 | D33: =(SUM(粮草!A33:X33)+AG33*10)*IF(AK33="是",$AX$4,$AX$3) -> 0 | E33: =SUM($B$4:B33)+SUM($C$4:C33)-SUM($D$4:D33) -> 47200 | F33: =SUM(经验!A33:X33) -> 0 | G33: =SUM($F$4:F33)+SUM($H$4:H33) -> 2500 | H33: 0 | I33: 空 | J33: 空 | K33: 空 | L33: 空 | M33: 空 | N33: 空 | O33: 空 | P33: 空 | Q33: 空 | R33: 空 | S33: 空 | T33: 空 | U33: 空 | V33: 空 | W33: 空 | X33: 空 | Y33: 空 | Z33: 空 | AA33: 空 | AB33: 空 | AC33: 空 | AD33: 空 | AE33: 空 | AF33: 空 | AG33: 0 | AK33: 是
A34: 44759 | B34: 1600 | D34: =(SUM(粮草!A34:X34)+AG34*10)*IF(AK34="是",$AX$4,$AX$3) -> 0 | E34: =SUM($B$4:B34)+SUM($C$4:C34)-SUM($D$4:D34) -> 48800 | F34: =SUM(经验!A34:X34) -> 0 | G34: =SUM($F$4:F34)+SUM($H$4:H34) -> 2500 | H34: 0 | I34: 空 | J34: 空 | K34: 空 | L34: 空 | M34: 空 | N34: 空 | O34: 空 | P34: 空 | Q34: 空 | R34: 空 | S34: 空 | T34: 空 | U34: 空 | V34: 空 | W34: 空 | X34: 空 | Y34: 空 | Z34: 空 | AA34: 空 | AB34: 空 | AC34: 空 | AD34: 空 | AE34: 空 | AF34: 空 | AG34: 0 | AK34: 是
A35: 44760 | B35: 1600 | D35: =(SUM(粮草!A35:X35)+AG35*10)*IF(AK35="是",$AX$4,$AX$3) -> 0 | E35: =SUM($B$4:B35)+SUM($C$4:C35)-SUM($D$4:D35) -> 50400 | F35: =SUM(经验!A35:X35) -> 0 | G35: =SUM($F$4:F35)+SUM($H$4:H35) -> 2700 | H35: 200 | I35: 空 | J35: 空 | K35: 空 | L35: 空 | M35: 空 | N35: 空 | O35: 空 | P35: 空 | Q35: 空 | R35: 空 | S35: 空 | T35: 空 | U35: 空 | V35: 空 | W35: 空 | X35: 空 | Y35: 空 | Z35: 空 | AA35: 空 | AB35: 空 | AC35: 空 | AD35: 空 | AE35: 空 | AF35: 空 | AG35: 0 | AK35: 是
A36: 44761 | B36: 1600 | D36: =(SUM(粮草!A36:X36)+AG36*10)*IF(AK36="是",$AX$4,$AX$3) -> 0 | E36: =SUM($B$4:B36)+SUM($C$4:C36)-SUM($D$4:D36) -> 52000 | F36: =SUM(经验!A36:X36) -> 0 | G36: =SUM($F$4:F36)+SUM($H$4:H36) -> 2800 | H36: 100 | I36: 空 | J36: 空 | K36: 空 | L36: 空 | M36: 空 | N36: 空 | O36: 空 | P36: 空 | Q36: 空 | R36: 空 | S36: 空 | T36: 空 | U36: 空 | V36: 空 | W36: 空 | X36: 空 | Y36: 空 | Z36: 空 | AA36: 空 | AB36: 空 | AC36: 空 | AD36: 空 | AE36: 空 | AF36: 空 | AG36: 0 | AK36: 是
A37: 44762 | B37: 1600 | D37: =(SUM(粮草!A37:X37)+AG37*10)*IF(AK37="是",$AX$4,$AX$3) -> 0 | E37: =SUM($B$4:B37)+SUM($C$4:C37)-SUM($D$4:D37) -> 53600 | F37: =SUM(经验!A37:X37) -> 0 | G37: =SUM($F$4:F37)+SUM($H$4:H37) -> 3000 | H37: 200 | I37: 空 | J37: 空 | K37: 空 | L37: 空 | M37: 空 | N37: 空 | O37: 空 | P37: 空 | Q37: 空 | R37: 空 | S37: 空 | T37: 空 | U37: 空 | V37: 空 | W37: 空 | X37: 空 | Y37: 空 | Z37: 空 | AA37: 空 | AB37: 空 | AC37: 空 | AD37: 空 | AE37: 空 | AF37: 空 | AG37: 0 | AK37: 是
A38: 44763 | B38: 1600 | D38: =(SUM(粮草!A38:X38)+AG38*10)*IF(AK38="是",$AX$4,$AX$3) -> 0 | E38: =SUM($B$4:B38)+SUM($C$4:C38)-SUM($D$4:D38) -> 55200 | F38: =SUM(经验!A38:X38) -> 0 | G38: =SUM($F$4:F38)+SUM($H$4:H38) -> 3000 | H38: 0 | I38: 空 | J38: 空 | K38: 空 | L38: 空 | M38: 空 | N38: 空 | O38: 空 | P38: 空 | Q38: 空 | R38: 空 | S38: 空 | T38: 空 | U38: 空 | V38: 空 | W38: 空 | X38: 空 | Y38: 空 | Z38: 空 | AA38: 空 | AB38: 空 | AC38: 空 | AD38: 空 | AE38: 空 | AF38: 空 | AG38: 0 | AK38: 是
A39: 44764 | B39: 1600 | D39: =(SUM(粮草!A39:X39)+AG39*10)*IF(AK39="是",$AX$4,$AX$3) -> 0 | E39: =SUM($B$4:B39)+SUM($C$4:C39)-SUM($D$4:D39) -> 56800 | F39: =SUM(经验!A39:X39) -> 0 | G39: =SUM($F$4:F39)+SUM($H$4:H39) -> 3000 | H39: 0 | I39: 空 | J39: 空 | K39: 空 | L39: 空 | M39: 空 | N39: 空 | O39: 空 | P39: 空 | Q39: 空 | R39: 空 | S39: 空 | T39: 空 | U39: 空 | V39: 空 | W39: 空 | X39: 空 | Y39: 空 | Z39: 空 | AA39: 空 | AB39: 空 | AC39: 空 | AD39: 空 | AE39: 空 | AF39: 空 | AG39: 0 | AK39: 是
A40: 44765 | B40: 1600 | D40: =(SUM(粮草!A40:X40)+AG40*10)*IF(AK40="是",$AX$4,$AX$3) -> 0 | E40: =SUM($B$4:B40)+SUM($C$4:C40)-SUM($D$4:D40) -> 58400 | F40: =SUM(经验!A40:X40) -> 0 | G40: =SUM($F$4:F40)+SUM($H$4:H40) -> 3000 | H40: 0 | I40: 空 | J40: 空 | K40: 空 | L40: 空 | M40: 空 | N40: 空 | O40: 空 | P40: 空 | Q40: 空 | R40: 空 | S40: 空 | T40: 空 | U40: 空 | V40: 空 | W40: 空 | X40: 空 | Y40: 空 | Z40: 空 | AA40: 空 | AB40: 空 | AC40: 空 | AD40: 空 | AE40: 空 | AF40: 空 | AG40: 0 | AK40: 是
...

Sheet 粮草
A2: 队伍一 风 | C2: 步数 | D2: =COUNTIF(A4:H94,"<>空") -> 728 | E2: (不算跳步和传送) | I2: 队伍二 雷 | K2: 步数 | L2: =COUNTIF(I4:P94,"<>空") -> 728 | M2: (不算跳步和传送) | Q2: 队伍三 | S2: 总步数 | T2: =COUNTIF(Q4:X94,"<>空") -> 728 | U2: (不算跳步和传送)
A3: 1 | B3: 2 | C3: 3 | D3: 4 | E3: 5 | F3: 6 | G3: 7 | H3: 8 | I3: 1 | J3: 2 | K3: 3 | L3: 4 | M3: 5 | N3: 6 | O3: 7 | P3: 8 | Q3: 1 | R3: 2 | S3: 3 | T3: 4 | U3: 5 | V3: 6 | W3: 7 | X3: 8
A4: =(VLOOKUP(' 6.0.00'!I4,' 6.0.00'!$AM$4:$AO$55,2,FALSE))*IF(' 6.0.00'!AK$4="是",' 6.0.00'!$AX$4,' 6.0.00'!$AX$3) -> 0 | B4: =(VLOOKUP(' 6.0.00'!J4,' 6.0.00'!$AM$4:$AO$55,2,FALSE))*IF(' 6.0.00'!AL$4="是",' 6.0.00'!$AX$4,' 6.0.00'!$AX$3) -> 0 | C4: =(VLOOKUP(' 6.0.00'!K4,' 6.0.00'!$AM$4:$AO$55,2,FALSE))*IF(' 6.0.00'!AM$4="是",' 6.0.00'!$AX$4,' 6.0.00'!$AX$3) -> 0 | D4: =(VLOOKUP(' 6.0.00'!L4,' 6.0.00'!$AM$4:$AO$55,2,FALSE))*IF(' 6.0.00'!AN$4="是",' 6.0.00'!$AX$4,' 6.0.00'!$AX$3) -> 0 | E4: =(VLOOKUP(' 6.0.00'!M4,' 6.0.00'!$AM$4:$AO$55,2,FALSE))*IF(' 6.0.00'!AO$4="是",' 6.0.00'!$AX$4,' 6.0.00'!$AX$3) -> 0 | F4: =(VLOOKUP(' 6.0.00'!N4,' 6.0.00'!$AM$4:$AO$55,2,FALSE))*IF(' 6.0.00'!AP$4="是",' 6.0.00'!$AX$4,' 6.0.00'!$AX$3) -> 0 | G4: =(VLOOKUP(' 6.0.00'!O4,' 6.0.00'!$AM$4:$AO$55,2,FALSE))*IF(' 6.0.00'!AQ$4="是",' 6.0.00'!$AX$4,' 6.0.00'!$AX$3) -> 0 | H4: =(VLOOKUP(' 6.0.00'!P4,' 6.0.00'!$AM$4:$AO$55,2,FALSE))*IF(' 6.0.00'!AR$4="是",' 6.0.00'!$AX$4,' 6.0.00'!$AX$3) -> 0 | ... X4: =(VLOOKUP(' 6.0.00'!AF4,' 6.0.00'!$AM$4:$AO$55,2,FALSE))*IF(' 6.0.00'!BH$4="是",' 6.0.00'!$AX$4,' 6.0.00'!$AX$3) -> 0
A5: =(VLOOKUP(' 6.0.00'!I5,' 6.0.00'!$AM$4:$AO$55,2,FALSE))*IF(' 6.0.00'!AK$4="是",' 6.0.00'!$AX$4,' 6.0.00'!$AX$3) -> 0 | B5: =(VLOOKUP(' 6.0.00'!J5,' 6.0.00'!$AM$4:$AO$55,2,FALSE))*IF(' 6.0.00'!AL$4="是",' 6.0.00'!$AX$4,' 6.0.00'!$AX$3) -> 0 | C5: =(VLOOKUP(' 6.0.00'!K5,' 6.0.00'!$AM$4:$AO$55,2,FALSE))*IF(' 6.0.00'!AM$4="是",' 6.0.00'!$AX$4,' 6.0.00'!$AX$3) -> 0 | D5: =(VLOOKUP(' 6.0.00'!L5,' 6.0.00'!$AM$4:$AO$55,2,FALSE))*IF(' 6.0.00'!AN$4="是",' 6.0.00'!$AX$4,' 6.0.00'!$AX$3) -> 0 | E5: =(VLOOKUP(' 6.0.00'!M5,' 6.0.00'!$AM$4:$AO$55,2,FALSE))*IF(' 6.0.00'!AO$4="是",' 6.0.00'!$AX$4,' 6.0.00'!$AX$3) -> 0 | F5: =(VLOOKUP(' 6.0.00'!N5,' 6.0.00'!$AM$4:$AO$55,2,FALSE))*IF(' 6.0.00'!AP$4="是",' 6.0.00'!$AX$4,' 6.0.00'!$AX$3) -> 0 | G5: =(VLOOKUP(' 6.0.00'!O5,' 6.0.00'!$AM$4:$AO$55,2,FALSE))*IF(' 6.0.00'!AQ$4="是",' 6.0.00'!$AX$4,' 6.0.00'!$AX$3) -> 0 | H5: =(VLOOKUP(' 6.0.00'!P5,' 6.0.00'!$AM$4:$AO$55,2,FALSE))*IF(' 6.0.00'!AR$4="是",' 6.0.00'!$AX$4,' 6.0.00'!$AX$3) -> 0 | ... X5: =(VLOOKUP(' 6.0.00'!AF5,' 6.0.00'!$AM$4:$AO$55,2,FALSE))*IF(' 6.0.00'!BH$4="是",' 6.0.00'!$AX$4,' 6.0.00'!$AX$3) -> 0
A6: =(VLOOKUP(' 6.0.00'!I6,' 6.0.00'!$AM$4:$AO$55,2,FALSE))*IF(' 6.0.00'!AK$4="是",' 6.0.00'!$AX$4,' 6.0.00'!$AX$3) -> 0 | B6: =(VLOOKUP(' 6.0.00'!J6,' 6.0.00'!$AM$4:$AO$55,2,FALSE))*IF(' 6.0.00'!AL$4="是",' 6.0.00'!$AX$4,' 6.0.00'!$AX$3) -> 0 | C6: =(VLOOKUP(' 6.0.00'!K6,' 6.0.00'!$AM$4:$AO$55,2,FALSE))*IF(' 6.0.00'!AM$4="是",' 6.0.00'!$AX$4,' 6.0.00'!$AX$3) -> 0 | D6: =(VLOOKUP(' 6.0.00'!L6,' 6.0.00'!$AM$4:$AO$55,2,FALSE))*IF(' 6.0.00'!AN$4="是",' 6.0.00'!$AX$4,' 6.0.00'!$AX$3) -> 0 | E6: =(VLOOKUP(' 6.0.00'!M6,' 6.0.00'!$AM$4:$AO$55,2,FALSE))*IF(' 6.0.00'!AO$4="是",' 6.0.00'!$AX$4,' 6.0.00'!$AX$3) -> 0 | F6: =(VLOOKUP(' 6.0.00'!N6,' 6.0.00'!$AM$4:$AO$55,2,FALSE))*IF(' 6.0.00'!AP$4="是",' 6.0.00'!$AX$4,' 6.0.00'!$AX$3) -> 0 | G6: =(VLOOKUP(' 6.0.00'!O6,' 6.0.00'!$AM$4:$AO$55,2,FALSE))*IF(' 6.0.00'!AQ$4="是",' 6.0.00'!$AX$4,' 6.0.00'!$AX$3) -> 0 | H6: =(VLOOKUP(' 6.0.00'!P6,' 6.0.00'!$AM$4:$AO$55,2,FALSE))*IF(' 6.0.00'!AR$4="是",' 6.0.00'!$AX$4,' 6.0.00'!$AX$3) -> 0 | ... X6: =(VLOOKUP(' 6.0.00'!AF6,' 6.0.00'!$AM$4:$AO$55,2,FALSE))*IF(' 6.0.00'!BH$4="是",' 6.0.00'!$AX$4,' 6.0.00'!$AX$3) -> 0
A7: =(VLOOKUP(' 6.0.00'!I7,' 6.0.00'!$AM$4:$AO$55,2,FALSE))*IF(' 6.0.00'!AK$4="是",' 6.0.00'!$AX$4,' 6.0.00'!$AX$3) -> 0 | B7: =(VLOOKUP(' 6.0.00'!J7,' 6.0.00'!$AM$4:$AO$55,2,FALSE))*IF(' 6.0.00'!AL$4="是",' 6.0.00'!$AX$4,' 6.0.00'!$AX$3) -> 0 | C7: =(VLOOKUP(' 6.0.00'!K7,' 6.0.00'!$AM$4:$AO$55,2,FALSE))*IF(' 6.0.00'!AM$4="是",' 6.0.00'!$AX$4,' 6.0.00'!$AX$3) -> 0 | D7: =(VLOOKUP(' 6.0.00'!L7,' 6.0.00'!$AM$4:$AO$55,2,FALSE))*IF(' 6.0.00'!AN$4="是",' 6.0.00'!$AX$4,' 6.0.00'!$AX$3) -> 0 | E7: =(VLOOKUP(' 6.0.00'!M7,' 6.0.00'!$AM$4:$AO$55,2,FALSE))*IF(' 6.0.00'!AO$4="是",' 6.0.00'!$AX$4,' 6.0.00'!$AX$3) -> 0 | F7: =(VLOOKUP(' 6.0.00'!N7,' 6.0.00'!$AM$4:$AO$55,2,FALSE))*IF(' 6.0.00'!AP$4="是",' 6.0.00'!$AX$4,' 6.0.00'!$AX$3) -> 0 | G7: =(VLOOKUP(' 6.0.00'!O7,' 6.0.00'!$AM$4:$AO$55,2,FALSE))*IF(' 6.0.00'!AQ$4="是",' 6.0.00'!$AX$4,' 6.0.00'!$AX$3) -> 0 | H7: =(VLOOKUP(' 6.0.00'!P7,' 6.0.00'!$AM$4:$AO$55,2,FALSE))*IF(' 6.0.00'!AR$4="是",' 6.0.00'!$AX$4,' 6.0.00'!$AX$3) -> 0 | ... X7: =(VLOOKUP(' 6.0.00'!AF7,' 6.0.00'!$AM$4:$AO$55,2,FALSE))*IF(' 6.0.00'!BH$4="是",' 6.0.00'!$AX$4,' 6.0.00'!$AX$3) -> 0
A8: =(VLOOKUP(' 6.0.00'!I8,' 6.0.00'!$AM$4:$AO$55,2,FALSE))*IF(' 6.0.00'!AK$4="是",' 6.0.00'!$AX$4,' 6.0.00'!$AX$3) -> 0 | B8: =(VLOOKUP(' 6.0.00'!J8,' 6.0.00'!$AM$4:$AO$55,2,FALSE))*IF(' 6.0.00'!AL$4="是",' 6.0.00'!$AX$4,' 6.0.00'!$AX$3) -> 0 | C8: =(VLOOKUP(' 6.0.00'!K8,' 6.0.00'!$AM$4:$AO$55,2,FALSE))*IF(' 6.0.00'!AM$4="是",' 6.0.00'!$AX$4,' 6.0.00'!$AX$3) -> 0 | D8: =(VLOOKUP(' 6.0.00'!L8,' 6.0.00'!$AM$4:$AO$55,2,FALSE))*IF(' 6.0.00'!AN$4="是",' 6.0.00'!$AX$4,' 6.0.00'!$AX$3) -> 0 | E8: =(VLOOKUP(' 6.0.00'!M8,' 6.0.00'!$AM$4:$AO$55,2,FALSE))*IF(' 6.0.00'!AO$4="是",' 6.0.00'!$AX$4,' 6.0.00'!$AX$3) -> 0 | F8: =(VLOOKUP(' 6.0.00'!N8,' 6.0.00'!$AM$4:$AO$55,2,FALSE))*IF(' 6.0.00'!AP$4="是",' 6.0.00'!$AX$4,' 6.0.00'!$AX$3) -> 0 | G8: =(VLOOKUP(' 6.0.00'!O8,' 6.0.00'!$AM$4:$AO$55,2,FALSE))*IF(' 6.0.00'!AQ$4="是",' 6.0.00'!$AX$4,' 6.0.00'!$AX$3) -> 0 | H8: =(VLOOKUP(' 6.0.00'!P8,' 6.0.00'!$AM$4:$AO$55,2,FALSE))*IF(' 6.0.00'!AR$4="是",' 6.0.00'!$AX$4,' 6.0.00'!$AX$3) -> 0 | ... X8: =(VLOOKUP(' 6.0.00'!AF8,' 6.0.00'!$AM$4:$AO$55,2,FALSE))*IF(' 6.0.00'!BH$4="是",' 6.0.00'!$AX$4,' 6.0.00'!$AX$3) -> 0
A9: =(VLOOKUP(' 6.0.00'!I9,' 6.0.00'!$AM$4:$AO$55,2,FALSE))*IF(' 6.0.00'!AK$4="是",' 6.0.00'!$AX$4,' 6.0.00'!$AX$3) -> 0 | B9: =(VLOOKUP(' 6.0.00'!J9,' 6.0.00'!$AM$4:$AO$55,2,FALSE))*IF(' 6.0.00'!AL$4="是",' 6.0.00'!$AX$4,' 6.0.00'!$AX$3) -> 0 | C9: =(VLOOKUP(' 6.0.00'!K9,' 6.0.00'!$AM$4:$AO$55,2,FALSE))*IF(' 6.0.00'!AM$4="是",' 6.0.00'!$AX$4,' 6.0.00'!$AX$3) -> 0 | D9: =(VLOOKUP(' 6.0.00'!L9,' 6.0.00'!$AM$4:$AO$55,2,FALSE))*IF(' 6.0.00'!AN$4="是",' 6.0.00'!$AX$4,' 6.0.00'!$AX$3) -> 0 | E9: =(VLOOKUP(' 6.0.00'!M9,' 6.0.00'!$AM$4:$AO$55,2,FALSE))*IF(' 6.0.00'!AO$4="是",' 6.0.00'!$AX$4,' 6.0.00'!$AX$3) -> 0 | F9: =(VLOOKUP(' 6.0.00'!N9,' 6.0.00'!$AM$4:$AO$55,2,FALSE))*IF(' 6.0.00'!AP$4="是",' 6.0.00'!$AX$4,' 6.0.00'!$AX$3) -> 0 | G9: =(VLOOKUP(' 6.0.00'!O9,' 6.0.00'!$AM$4:$AO$55,2,FALSE))*IF(' 6.0.00'!AQ$4="是",' 6.0.00'!$AX$4,' 6.0.00'!$AX$3) -> 0 | H9: =(VLOOKUP(' 6.0.00'!P9,' 6.0.00'!$AM$4:$AO$55,2,FALSE))*IF(' 6.0.00'!AR$4="是",' 6.0.00'!$AX$4,' 6.0.00'!$AX$3) -> 0 | ... X9: =(VLOOKUP(' 6.0.00'!AF9,' 6.0.00'!$AM$4:$AO$55,2,FALSE))*IF(' 6.0.00'!BH$4="是",' 6.0.00'!$AX$4,' 6.0.00'!$AX$3) -> 0
A10: =(VLOOKUP(' 6.0.00'!I10,' 6.0.00'!$AM$4:$AO$55,2,FALSE))*IF(' 6.0.00'!AK$4="是",' 6.0.00'!$AX$4,' 6.0.00'!$AX$3) -> 0 | B10: =(VLOOKUP(' 6.0.00'!J10,' 6.0.00'!$AM$4:$AO$55,2,FALSE))*IF(' 6.0.00'!AL$4="是",' 6.0.00'!$AX$4,' 6.0.00'!$AX$3) -> 0 | C10: =(VLOOKUP(' 6.0.00'!K10,' 6.0.00'!$AM$4:$AO$55,2,FALSE))*IF(' 6.0.00'!AM$4="是",' 6.0.00'!$AX$4,' 6.0.00'!$AX$3) -> 0 | D10: =(VLOOKUP(' 6.0.00'!L10,' 6.0.00'!$AM$4:$AO$55,2,FALSE))*IF(' 6.0.00'!AN$4="是",' 6.0.00'!$AX$4,' 6.0.00'!$AX$3) -> 0 | E10: =(VLOOKUP(' 6.0.00'!M10,' 6.0.00'!$AM$4:$AO$55,2,FALSE))*IF(' 6.0.00'!AO$4="是",' 6.0.00'!$AX$4,' 6.0.00'!$AX$3) -> 0 | F10: =(VLOOKUP(' 6.0.00'!N10,' 6.0.00'!$AM$4:$AO$55,2,FALSE))*IF(' 6.0.00'!AP$4="是",' 6.0.00'!$AX$4,' 6.0.00'!$AX$3) -> 0 | G10: =(VLOOKUP(' 6.0.00'!O10,' 6.0.00'!$AM$4:$AO$55,2,FALSE))*IF(' 6.0.00'!AQ$4="是",' 6.0.00'!$AX$4,' 6.0.00'!$AX$3) -> 0 | H10: =(VLOOKUP(' 6.0.00'!P10,' 6.0.00'!$AM$4:$AO$55,2,FALSE))*IF(' 6.0.00'!AR$4="是",' 6.0.00'!$AX$4,' 6.0.00'!$AX$3) -> 0 | ... X10: =(VLOOKUP(' 6.0.00'!AF10,' 6.0.00'!$AM$4:$AO$55,2,FALSE))*IF(' 6.0.00'!BH$4="是",' 6.0.00'!$AX$4,' 6.0.00'!$AX$3) -> 0
A11: =(VLOOKUP(' 6.0.00'!I11,' 6.0.00'!$AM$4:$AO$55,2,FALSE))*IF(' 6.0.00'!AK$4="是",' 6.0.00'!$AX$4,' 6.0.00'!$AX$3) -> 0 | B11: =(VLOOKUP(' 6.0.00'!J11,' 6.0.00'!$AM$4:$AO$55,2,FALSE))*IF(' 6.0.00'!AL$4="是",' 6.0.00'!$AX$4,' 6.0.00'!$AX$3) -> 0 | C11: =(VLOOKUP(' 6.0.00'!K11,' 6.0.00'!$AM$4:$AO$55,2,FALSE))*IF(' 6.0.00'!AM$4="是",' 6.0.00'!$AX$4,' 6.0.00'!$AX$3) -> 0 | D11: =(VLOOKUP(' 6.0.00'!L11,' 6.0.00'!$AM$4:$AO$55,2,FALSE))*IF(' 6.0.00'!AN$4="是",' 6.0.00'!$AX$4,' 6.0.00'!$AX$3) -> 0 | E11: =(VLOOKUP(' 6.0.00'!M11,' 6.0.00'!$AM$4:$AO$55,2,FALSE))*IF(' 6.0.00'!AO$4="是",' 6.0.00'!$AX$4,' 6.0.00'!$AX$3) -> 0 | F11: =(VLOOKUP(' 6.0.00'!N11,' 6.0.00'!$AM$4:$AO$55,2,FALSE))*IF(' 6.0.00'!AP$4="是",' 6.0.00'!$AX$4,' 6.0.00'!$AX$3) -> 0 | G11: =(VLOOKUP(' 6.0.00'!O11,' 6.0.00'!$AM$4:$AO$55,2,FALSE))*IF(' 6.0.00'!AQ$4="是",' 6.0.00'!$AX$4,' 6.0.00'!$AX$3) -> 0 | H11: =(VLOOKUP(' 6.0.00'!P11,' 6.0.00'!$AM$4:$AO$55,2,FALSE))*IF(' 6.0.00'!AR$4="是",' 6.0.00'!$AX$4,' 6.0.00'!$AX$3) -> 0 | ... X11: =(VLOOKUP(' 6.0.00'!AF11,' 6.0.00'!$AM$4:$AO$55,2,FALSE))*IF(' 6.0.00'!BH$4="是",' 6.0.00'!$AX$4,' 6.0.00'!$AX$3) -> 0
A12: =(VLOOKUP(' 6.0.00'!I12,' 6.0.00'!$AM$4:$AO$55,2,FALSE))*IF(' 6.0.00'!AK$4="是",' 6.0.00'!$AX$4,' 6.0.00'!$AX$3) -> 0 | B12: =(VLOOKUP(' 6.0.00'!J12,' 6.0.00'!$AM$4:$AO$55,2,FALSE))*IF(' 6.0.00'!AL$4="是",' 6.0.00'!$AX$4,' 6.0.00'!$AX$3) -> 0 | C12: =(VLOOKUP(' 6.0.00'!K12,' 6.0.00'!$AM$4:$AO$55,2,FALSE))*IF(' 6.0.00'!AM$4="是",' 6.0.00'!$AX$4,' 6.0.00'!$AX$3) -> 0 | D12: =(VLOOKUP(' 6.0.00'!L12,' 6.0.00'!$AM$4:$AO$55,2,FALSE))*IF(' 6.0.00'!AN$4="是",' 6.0.00'!$AX$4,' 6.0.00'!$AX$3) -> 0 | E12: =(VLOOKUP(' 6.0.00'!M12,' 6.0.00'!$AM$4:$AO$55,2,FALSE))*IF(' 6.0.00'!AO$4="是",' 6.0.00'!$AX$4,' 6.0.00'!$AX$3) -> 0 | F12: =(VLOOKUP(' 6.0.00'!N12,' 6.0.00'!$AM$4:$AO$55,2,FALSE))*IF(' 6.0.00'!AP$4="是",' 6.0.00'!$AX$4,' 6.0.00'!$AX$3) -> 0 | G12: =(VLOOKUP(' 6.0.00'!O12,' 6.0.00'!$AM$4:$AO$55,2,FALSE))*IF(' 6.0.00'!AQ$4="是",' 6.0.00'!$AX$4,' 6.0.00'!$AX$3) -> 0 | H12: =(VLOOKUP(' 6.0.00'!P12,' 6.0.00'!$AM$4:$AO$55,2,FALSE))*IF(' 6.0.00'!AR$4="是",' 6.0.00'!$AX$4,' 6.0.00'!$AX$3) -> 0 | ... X12: =(VLOOKUP(' 6.0.00'!AF12,' 6.0.00'!$AM$4:$AO$55,2,FALSE))*IF(' 6.0.00'!BH$4="是",' 6.0.00'!$AX$4,' 6.0.00'!$AX$3) -> 0
A13: =(VLOOKUP(' 6.0.00'!I13,' 6.0.00'!$AM$4:$AO$55,2,FALSE))*IF(' 6.0.00'!AK$4="是",' 6.0.00'!$AX$4,' 6.0.00'!$AX$3) -> 0 | B13: =(VLOOKUP(' 6.0.00'!J13,' 6.0.00'!$AM$4:$AO$55,2,FALSE))*IF(' 6.0.00'!AL$4="是",' 6.0.00'!$AX$4,' 6.0.00'!$AX$3) -> 0 | C13: =(VLOOKUP(' 6.0.00'!K13,' 6.0.00'!$AM$4:$AO$55,2,FALSE))*IF(' 6.0.00'!AM$4="是",' 6.0.00'!$AX$4,' 6.0.00'!$AX$3) -> 0 | D13: =(VLOOKUP(' 6.0.00'!L13,' 6.0.00'!$AM$4:$AO$55,2,FALSE))*IF(' 6.0.00'!AN$4="是",' 6.0.00'!$AX$4,' 6.0.00'!$AX$3) -> 0 | E13: =(VLOOKUP(' 6.0.00'!M13,' 6.0.00'!$AM$4:$AO$55,2,FALSE))*IF(' 6.0.00'!AO$4="是",' 6.0.00'!$AX$4,' 6.0.00'!$AX$3) -> 0 | F13: =(VLOOKUP(' 6.0.00'!N13,' 6.0.00'!$AM$4:$AO$55,2,FALSE))*IF(' 6.0.00'!AP$4="是",' 6.0.00'!$AX$4,' 6.0.00'!$AX$3) -> 0 | G13: =(VLOOKUP(' 6.0.00'!O13,' 6.0.00'!$AM$4:$AO$55,2,FALSE))*IF(' 6.0.00'!AQ$4="是",' 6.0.00'!$AX$4,' 6.0.00'!$AX$3) -> 0 | H13: =(VLOOKUP(' 6.0.00'!P13,' 6.0.00'!$AM$4:$AO$55,2,FALSE))*IF(' 6.0.00'!AR$4="是",' 6.0.00'!$AX$4,' 6.0.00'!$AX$3) -> 0 | ... X13: =(VLOOKUP(' 6.0.00'!AF13,' 6.0.00'!$AM$4:$AO$55,2,FALSE))*IF(' 6.0.00'!BH$4="是",' 6.0.00'!$AX$4,' 6.0.00'!$AX$3) -> 0
A14: =(VLOOKUP(' 6.0.00'!I14,' 6.0.00'!$AM$4:$AO$55,2,FALSE))*IF(' 6.0.00'!AK$4="是",' 6.0.00'!$AX$4,' 6.0.00'!$AX$3) -> 0 | B14: =(VLOOKUP(' 6.0.00'!J14,' 6.0.00'!$AM$4:$AO$55,2,FALSE))*IF(' 6.0.00'!AL$4="是",' 6.0.00'!$AX$4,' 6.0.00'!$AX$3) -> 0 | C14: =(VLOOKUP(' 6.0.00'!K14,' 6.0.00'!$AM$4:$AO$55,2,FALSE))*IF(' 6.0.00'!AM$4="是",' 6.0.00'!$AX$4,' 6.0.00'!$AX$3) -> 0 | D14: =(VLOOKUP(' 6.0.00'!L14,' 6.0.00'!$AM$4:$AO$55,2,FALSE))*IF(' 6.0.00'!AN$4="是",' 6.0.00'!$AX$4,' 6.0.00'!$AX$3) -> 0 | E14: =(VLOOKUP(' 6.0.00'!M14,' 6.0.00'!$AM$4:$AO$55,2,FALSE))*IF(' 6.0.00'!AO$4="是",' 6.0.00'!$AX$4,' 6.0.00'!$AX$3) -> 0 | F14: =(VLOOKUP(' 6.0.00'!N14,' 6.0.00'!$AM$4:$AO$55,2,FALSE))*IF(' 6.0.00'!AP$4="是",' 6.0.00'!$AX$4,' 6.0.00'!$AX$3) -> 0 | G14: =(VLOOKUP(' 6.0.00'!O14,' 6.0.00'!$AM$4:$AO$55,2,FALSE))*IF(' 6.0.00'!AQ$4="是",' 6.0.00'!$AX$4,' 6.0.00'!$AX$3) -> 0 | H14: =(VLOOKUP(' 6.0.00'!P14,' 6.0.00'!$AM$4:$AO$55,2,FALSE))*IF(' 6.0.00'!AR$4="是",' 6.0.00'!$AX$4,' 6.0.00'!$AX$3) -> 0 | ... X14: =(VLOOKUP(' 6.0.00'!AF14,' 6.0.00'!$AM$4:$AO$55,2,FALSE))*IF(' 6.0.00'!BH$4="是",' 6.0.00'!$AX$4,' 6.0.00'!$AX$3) -> 0
A15: =(VLOOKUP(' 6.0.00'!I15,' 6.0.00'!$AM$4:$AO$55,2,FALSE))*IF(' 6.0.00'!AK$4="是",' 6.0.00'!$AX$4,' 6.0.00'!$AX$3) -> 0 | B15: =(VLOOKUP(' 6.0.00'!J15,' 6.0.00'!$AM$4:$AO$55,2,FALSE))*IF(' 6.0.00'!AL$4="是",' 6.0.00'!$AX$4,' 6.0.00'!$AX$3) -> 0 | C15: =(VLOOKUP(' 6.0.00'!K15,' 6.0.00'!$AM$4:$AO$55,2,FALSE))*IF(' 6.0.00'!AM$4="是",' 6.0.00'!$AX$4,' 6.0.00'!$AX$3) -> 0 | D15: =(VLOOKUP(' 6.0.00'!L15,' 6.0.00'!$AM$4:$AO$55,2,FALSE))*IF(' 6.0.00'!AN$4="是",' 6.0.00'!$AX$4,' 6.0.00'!$AX$3) -> 0 | E15: =(VLOOKUP(' 6.0.00'!M15,' 6.0.00'!$AM$4:$AO$55,2,FALSE))*IF(' 6.0.00'!AO$4="是",' 6.0.00'!$AX$4,' 6.0.00'!$AX$3) -> 0 | F15: =(VLOOKUP(' 6.0.00'!N15,' 6.0.00'!$AM$4:$AO$55,2,FALSE))*IF(' 6.0.00'!AP$4="是",' 6.0.00'!$AX$4,' 6.0.00'!$AX$3) -> 0 | G15: =(VLOOKUP(' 6.0.00'!O15,' 6.0.00'!$AM$4:$AO$55,2,FALSE))*IF(' 6.0.00'!AQ$4="是",' 6.0.00'!$AX$4,' 6.0.00'!$AX$3) -> 0 | H15: =(VLOOKUP(' 6.0.00'!P15,' 6.0.00'!$AM$4:$AO$55,2,FALSE))*IF(' 6.0.00'!AR$4="是",' 6.0.00'!$AX$4,' 6.0.00'!$AX$3) -> 0 | ... X15: =(VLOOKUP(' 6.0.00'!AF15,' 6.0.00'!$AM$4:$AO$55,2,FALSE))*IF(' 6.0.00'!BH$4="是",' 6.0.00'!$AX$4,' 6.0.00'!$AX$3) -> 0
... A94: =(VLOOKUP(' 6.0.00'!I94,' 6.0.00'!$AM$4:$AO$55,2,FALSE))*IF(' 6.0.00'!AK$4="是",' 6.0.00'!$AX$4,' 6.0.00'!$AX$3) -> 0 | B94: =(VLOOKUP(' 6.0.00'!J94,' 6.0.00'!$AM$4:$AO$55,2,FALSE))*IF(' 6.0.00'!AL$4="是",' 6.0.00'!$AX$4,' 6.0.00'!$AX$3) -> 0 | C94: =(VLOOKUP(' 6.0.00'!K94,' 6.0.00'!$AM$4:$AO$55,2,FALSE))*IF(' 6.0.00'!AM$4="是",' 6.0.00'!$AX$4,' 6.0.00'!$AX$3) -> 0 | D94: =(VLOOKUP(' 6.0.00'!L94,' 6.0.00'!$AM$4:$AO$55,2,FALSE))*IF(' 6.0.00'!AN$4="是",' 6.0.00'!$AX$4,' 6.0.00'!$AX$3) -> 0 | E94: =(VLOOKUP(' 6.0.00'!M94,' 6.0.00'!$AM$4:$AO$55,2,FALSE))*IF(' 6.0.00'!AO$4="是",' 6.0.00'!$AX$4,' 6.0.00'!$AX$3) -> 0 | F94: =(VLOOKUP(' 6.0.00'!N94,' 6.0.00'!$AM$4:$AO$55,2,FALSE))*IF(' 6.0.00'!AP$4="是",' 6.0.00'!$AX$4,' 6.0.00'!$AX$3) -> 0 | G94: =(VLOOKUP(' 6.0.00'!O94,' 6.0.00'!$AM$4:$AO$55,2,FALSE))*IF(' 6.0.00'!AQ$4="是",' 6.0.00'!$AX$4,' 6.0.00'!$AX$3) -> 0 | H94: =(VLOOKUP(' 6.0.00'!P94,' 6.0.00'!$AM$4:$AO$55,2,FALSE))*IF(' 6.0.00'!AR$4="是",' 6.0.00'!$AX$4,' 6.0.00'!$AX$3) -> 0 | ... X94: =(VLOOKUP(' 6.0.00'!AF94,' 6.0.00'!$AM$4:$AO$55,2,FALSE))*IF(' 6.0.00'!BH$4="是",' 6.0.00'!$AX$4,' 6.0.00'!$AX$3) -> 0

Sheet 经验
A2: 队伍一 风 | C2: 步数 | D2: =COUNTIF(A4:H94,"<>空") -> 728 | E2: (不算跳步和传送) | I2: 队伍二 雷 | K2: 步数 | L2: =COUNTIF(I4:P94,"<>空") -> 728 | M2: (不算跳步和传送) | Q2: 队伍三 | S2: 总步数 | T2: =COUNTIF(Q4:X94,"<>空") -> 728 | U2: (不算跳步和传送)
A3: 1 | B3: 2 | C3: 3 | D3: 4 | E3: 5 | F3: 6 | G3: 7 | H3: 8 | I3: 1 | J3: 2 | K3: 3 | L3: 4 | M3: 5 | N3: 6 | O3: 7 | P3: 8 | Q3: 1 | R3: 2 | S3: 3 | T3: 4 | U3: 5 | V3: 6 | W3: 7 | X3: 8
A4: =(VLOOKUP(' 6.0.00'!I4,' 6.0.00'!$AM$4:$AO$55,3,FALSE)) -> 0 | B4: =(VLOOKUP(' 6.0.00'!J4,' 6.0.00'!$AM$4:$AO$55,3,FALSE)) -> 0 | C4: =(VLOOKUP(' 6.0.00'!K4,' 6.0.00'!$AM$4:$AO$55,3,FALSE)) -> 0 | D4: =(VLOOKUP(' 6.0.00'!L4,' 6.0.00'!$AM$4:$AO$55,3,FALSE)) -> 0 | E4: =(VLOOKUP(' 6.0.00'!M4,' 6.0.00'!$AM$4:$AO$55,3,FALSE)) -> 0 | F4: =(VLOOKUP(' 6.0.00'!N4,' 6.0.00'!$AM$4:$AO$55,3,FALSE)) -> 0 | G4: =(VLOOKUP(' 6.0.00'!O4,' 6.0.00'!$AM$4:$AO$55,3,FALSE)) -> 0 | H4: =(VLOOKUP(' 6.0.00'!P4,' 6.0.00'!$AM$4:$AO$55,3,FALSE)) -> 0 | ... X4: =(VLOOKUP(' 6.0.00'!AF4,' 6.0.00'!$AM$4:$AO$55,3,FALSE)) -> 0
A5: =(VLOOKUP(' 6.0.00'!I5,' 6.0.00'!$AM$4:$AO$55,3,FALSE)) -> 0 | B5: =(VLOOKUP(' 6.0.00'!J5,' 6.0.00'!$AM$4:$AO$55,3,FALSE)) -> 0 | C5: =(VLOOKUP(' 6.0.00'!K5,' 6.0.00'!$AM$4:$AO$55,3,FALSE)) -> 0 | D5: =(VLOOKUP(' 6.0.00'!L5,' 6.0.00'!$AM$4:$AO$55,3,FALSE)) -> 0 | E5: =(VLOOKUP(' 6.0.00'!M5,' 6.0.00'!$AM$4:$AO$55,3,FALSE)) -> 0 | F5: =(VLOOKUP(' 6.0.00'!N5,' 6.0.00'!$AM$4:$AO$55,3,FALSE)) -> 0 | G5: =(VLOOKUP(' 6.0.00'!O5,' 6.0.00'!$AM$4:$AO$55,3,FALSE)) -> 0 | H5: =(VLOOKUP(' 6.0.00'!P5,' 6.0.00'!$AM$4:$AO$55,3,FALSE)) -> 0 | ... X5: =(VLOOKUP(' 6.0.00'!AF5,' 6.0.00'!$AM$4:$AO$55,3,FALSE)) -> 0
A6: =(VLOOKUP(' 6.0.00'!I6,' 6.0.00'!$AM$4:$AO$55,3,FALSE)) -> 0 | B6: =(VLOOKUP(' 6.0.00'!J6,' 6.0.00'!$AM$4:$AO$55,3,FALSE)) -> 0 | C6: =(VLOOKUP(' 6.0.00'!K6,' 6.0.00'!$AM$4:$AO$55,3,FALSE)) -> 0 | D6: =(VLOOKUP(' 6.0.00'!L6,' 6.0.00'!$AM$4:$AO$55,3,FALSE)) -> 0 | E6: =(VLOOKUP(' 6.0.00'!M6,' 6.0.00'!$AM$4:$AO$55,3,FALSE)) -> 0 | F6: =(VLOOKUP(' 6.0.00'!N6,' 6.0.00'!$AM$4:$AO$55,3,FALSE)) -> 0 | G6: =(VLOOKUP(' 6.0.00'!O6,' 6.0.00'!$AM$4:$AO$55,3,FALSE)) -> 0 | H6: =(VLOOKUP(' 6.0.00'!P6,' 6.0.00'!$AM$4:$AO$55,3,FALSE)) -> 0 | ... X6: =(VLOOKUP(' 6.0.00'!AF6,' 6.0.00'!$AM$4:$AO$55,3,FALSE)) -> 0
A7: =(VLOOKUP(' 6.0.00'!I7,' 6.0.00'!$AM$4:$AO$55,3,FALSE)) -> 0 | B7: =(VLOOKUP(' 6.0.00'!J7,' 6.0.00'!$AM$4:$AO$55,3,FALSE)) -> 0 | C7: =(VLOOKUP(' 6.0.00'!K7,' 6.0.00'!$AM$4:$AO$55,3,FALSE)) -> 0 | D7: =(VLOOKUP(' 6.0.00'!L7,' 6.0.00'!$AM$4:$AO$55,3,FALSE)) -> 0 | E7: =(VLOOKUP(' 6.0.00'!M7,' 6.0.00'!$AM$4:$AO$55,3,FALSE)) -> 0 | F7: =(VLOOKUP(' 6.0.00'!N7,' 6.0.00'!$AM$4:$AO$55,3,FALSE)) -> 0 | G7: =(VLOOKUP(' 6.0.00'!O7,' 6.0.00'!$AM$4:$AO$55,3,FALSE)) -> 0 | H7: =(VLOOKUP(' 6.0.00'!P7,' 6.0.00'!$AM$4:$AO$55,3,FALSE)) -> 0 | ... X7: =(VLOOKUP(' 6.0.00'!AF7,' 6.0.00'!$AM$4:$AO$55,3,FALSE)) -> 0
A8: =(VLOOKUP(' 6.0.00'!I8,' 6.0.00'!$AM$4:$AO$55,3,FALSE)) -> 0 | B8: =(VLOOKUP(' 6.0.00'!J8,' 6.0.00'!$AM$4:$AO$55,3,FALSE)) -> 0 | C8: =(VLOOKUP(' 6.0.00'!K8,' 6.0.00'!$AM$4:$AO$55,3,FALSE)) -> 0 | D8: =(VLOOKUP(' 6.0.00'!L8,' 6.0.00'!$AM$4:$AO$55,3,FALSE)) -> 0 | E8: =(VLOOKUP(' 6.0.00'!M8,' 6.0.00'!$AM$4:$AO$55,3,FALSE)) -> 0 | F8: =(VLOOKUP(' 6.0.00'!N8,' 6.0.00'!$AM$4:$AO$55,3,FALSE)) -> 0 | G8: =(VLOOKUP(' 6.0.00'!O8,' 6.0.00'!$AM$4:$AO$55,3,FALSE)) -> 0 | H8: =(VLOOKUP(' 6.0.00'!P8,' 6.0.00'!$AM$4:$AO$55,3,FALSE)) -> 0 | ... X8: =(VLOOKUP(' 6.0.00'!AF8,' 6.0.00'!$AM$4:$AO$55,3,FALSE)) -> 0
A9: =(VLOOKUP(' 6.0.00'!I9,' 6.0.00'!$AM$4:$AO$55,3,FALSE)) -> 0 | B9: =(VLOOKUP(' 6.0.00'!J9,' 6.0.00'!$AM$4:$AO$55,3,FALSE)) -> 0 | C9: =(VLOOKUP(' 6.0.00'!K9,' 6.0.00'!$AM$4:$AO$55,3,FALSE)) -> 0 | D9: =(VLOOKUP(' 6.0.00'!L9,' 6.0.00'!$AM$4:$AO$55,3,FALSE)) -> 0 | E9: =(VLOOKUP(' 6.0.00'!M9,' 6.0.00'!$AM$4:$AO$55,3,FALSE)) -> 0 | F9: =(VLOOKUP(' 6.0.00'!N9,' 6.0.00'!$AM$4:$AO$55,3,FALSE)) -> 0 | G9: =(VLOOKUP(' 6.0.00'!O9,' 6.0.00'!$AM$4:$AO$55,3,FALSE)) -> 0 | H9: =(VLOOKUP(' 6.0.00'!P9,' 6.0.00'!$AM$4:$AO$55,3,FALSE)) -> 0 | ... X9: =(VLOOKUP(' 6.0.00'!AF9,' 6.0.00'!$AM$4:$AO$55,3,FALSE)) -> 0
A10: =(VLOOKUP(' 6.0.00'!I10,' 6.0.00'!$AM$4:$AO$55,3,FALSE)) -> 0 | B10: =(VLOOKUP(' 6.0.00'!J10,' 6.0.00'!$AM$4:$AO$55,3,FALSE)) -> 0 | C10: =(VLOOKUP(' 6.0.00'!K10,' 6.0.00'!$AM$4:$AO$55,3,FALSE)) -> 0 | D10: =(VLOOKUP(' 6.0.00'!L10,' 6.0.00'!$AM$4:$AO$55,3,FALSE)) -> 0 | E10: =(VLOOKUP(' 6.0.00'!M10,' 6.0.00'!$AM$4:$AO$55,3,FALSE)) -> 0 | F10: =(VLOOKUP(' 6.0.00'!N10,' 6.0.00'!$AM$4:$AO$55,3,FALSE)) -> 0 | G10: =(VLOOKUP(' 6.0.00'!O10,' 6.0.00'!$AM$4:$AO$55,3,FALSE)) -> 0 | H10: =(VLOOKUP(' 6.0.00'!P10,' 6.0.00'!$AM$4:$AO$55,3,FALSE)) -> 0 | ... X10: =(VLOOKUP(' 6.0.00'!AF10,' 6.0.00'!$AM$4:$AO$55,3,FALSE)) -> 0
A11: =(VLOOKUP(' 6.0.00'!I11,' 6.0.00'!$AM$4:$AO$55,3,FALSE)) -> 0 | B11: =(VLOOKUP(' 6.0.00'!J11,' 6.0.00'!$AM$4:$AO$55,3,FALSE)) -> 0 | C11: =(VLOOKUP(' 6.0.00'!K11,' 6.0.00'!$AM$4:$AO$55,3,FALSE)) -> 0 | D11: =(VLOOKUP(' 6.0.00'!L11,' 6.0.00'!$AM$4:$AO$55,3,FALSE)) -> 0 | E11: =(VLOOKUP(' 6.0.00'!M11,' 6.0.00'!$AM$4:$AO$55,3,FALSE)) -> 0 | F11: =(VLOOKUP(' 6.0.00'!N11,' 6.0.00'!$AM$4:$AO$55,3,FALSE)) -> 0 | G11: =(VLOOKUP(' 6.0.00'!O11,' 6.0.00'!$AM$4:$AO$55,3,FALSE)) -> 0 | H11: =(VLOOKUP(' 6.0.00'!P11,' 6.0.00'!$AM$4:$AO$55,3,FALSE)) -> 0 | ... X11: =(VLOOKUP(' 6.0.00'!AF11,' 6.0.00'!$AM$4:$AO$55,3,FALSE)) -> 0
A12: =(VLOOKUP(' 6.0.00'!I12,' 6.0.00'!$AM$4:$AO$55,3,FALSE)) -> 0 | B12: =(VLOOKUP(' 6.0.00'!J12,' 6.0.00'!$AM$4:$AO$55,3,FALSE)) -> 0 | C12: =(VLOOKUP(' 6.0.00'!K12,' 6.0.00'!$AM$4:$AO$55,3,FALSE)) -> 0 | D12: =(VLOOKUP(' 6.0.00'!L12,' 6.0.00'!$AM$4:$AO$55,3,FALSE)) -> 0 | E12: =(VLOOKUP(' 6.0.00'!M12,' 6.0.00'!$AM$4:$AO$55,3,FALSE)) -> 0 | F12: =(VLOOKUP(' 6.0.00'!N12,' 6.0.00'!$AM$4:$AO$55,3,FALSE)) -> 0 | G12: =(VLOOKUP(' 6.0.00'!O12,' 6.0.00'!$AM$4:$AO$55,3,FALSE)) -> 0 | H12: =(VLOOKUP(' 6.0.00'!P12,' 6.0.00'!$AM$4:$AO$55,3,FALSE)) -> 0 | ... X12: =(VLOOKUP(' 6.0.00'!AF12,' 6.0.00'!$AM$4:$AO$55,3,FALSE)) -> 0
A13: =(VLOOKUP(' 6.0.00'!I13,' 6.0.00'!$AM$4:$AO$55,3,FALSE)) -> 0 | B13: =(VLOOKUP(' 6.0.00'!J13,' 6.0.00'!$AM$4:$AO$55,3,FALSE)) -> 0 | C13: =(VLOOKUP(' 6.0.00'!K13,' 6.0.00'!$AM$4:$AO$55,3,FALSE)) -> 0 | D13: =(VLOOKUP(' 6.0.00'!L13,' 6.0.00'!$AM$4:$AO$55,3,FALSE)) -> 0 | E13: =(VLOOKUP(' 6.0.00'!M13,' 6.0.00'!$AM$4:$AO$55,3,FALSE)) -> 0 | F13: =(VLOOKUP(' 6.0.00'!N13,' 6.0.00'!$AM$4:$AO$55,3,FALSE)) -> 0 | G13: =(VLOOKUP(' 6.0.00'!O13,' 6.0.00'!$AM$4:$AO$55,3,FALSE)) -> 0 | H13: =(VLOOKUP(' 6.0.00'!P13,' 6.0.00'!$AM$4:$AO$55,3,FALSE)) -> 0 | ... X13: =(VLOOKUP(' 6.0.00'!AF13,' 6.0.00'!$AM$4:$AO$55,3,FALSE)) -> 0
A14: =(VLOOKUP(' 6.0.00'!I14,' 6.0.00'!$AM$4:$AO$55,3,FALSE)) -> 0 | B14: =(VLOOKUP(' 6.0.00'!J14,' 6.0.00'!$AM$4:$AO$55,3,FALSE)) -> 0 | C14: =(VLOOKUP(' 6.0.00'!K14,' 6.0.00'!$AM$4:$AO$55,3,FALSE)) -> 0 | D14: =(VLOOKUP(' 6.0.00'!L14,' 6.0.00'!$AM$4:$AO$55,3,FALSE)) -> 0 | E14: =(VLOOKUP(' 6.0.00'!M14,' 6.0.00'!$AM$4:$AO$55,3,FALSE)) -> 0 | F14: =(VLOOKUP(' 6.0.00'!N14,' 6.0.00'!$AM$4:$AO$55,3,FALSE)) -> 0 | G14: =(VLOOKUP(' 6.0.00'!O14,' 6.0.00'!$AM$4:$AO$55,3,FALSE)) -> 0 | H14: =(VLOOKUP(' 6.0.00'!P14,' 6.0.00'!$AM$4:$AO$55,3,FALSE)) -> 0 | ... X14: =(VLOOKUP(' 6.0.00'!AF14,' 6.0.00'!$AM$4:$AO$55,3,FALSE)) -> 0
A15: =(VLOOKUP(' 6.0.00'!I15,' 6.0.00'!$AM$4:$AO$55,3,FALSE)) -> 0 | B15: =(VLOOKUP(' 6.0.00'!J15,' 6.0.00'!$AM$4:$AO$55,3,FALSE)) -> 0 | C15: =(VLOOKUP(' 6.0.00'!K15,' 6.0.00'!$AM$4:$AO$55,3,FALSE)) -> 0 | D15: =(VLOOKUP(' 6.0.00'!L15,' 6.0.00'!$AM$4:$AO$55,3,FALSE)) -> 0 | E15: =(VLOOKUP(' 6.0.00'!M15,' 6.0.00'!$AM$4:$AO$55,3,FALSE)) -> 0 | F15: =(VLOOKUP(' 6.0.00'!N15,' 6.0.00'!$AM$4:$AO$55,3,FALSE)) -> 0 | G15: =(VLOOKUP(' 6.0.00'!O15,' 6.0.00'!$AM$4:$AO$55,3,FALSE)) -> 0 | H15: =(VLOOKUP(' 6.0.00'!P15,' 6.0.00'!$AM$4:$AO$55,3,FALSE)) -> 0 | ... X15: =(VLOOKUP(' 6.0.00'!AF15,' 6.0.00'!$AM$4:$AO$55,3,FALSE)) -> 0
... A94: =(VLOOKUP(' 6.0.00'!I94,' 6.0.00'!$AM$4:$AO$55,3,FALSE)) -> 0 | B94: =(VLOOKUP(' 6.0.00'!J94,' 6.0.00'!$AM$4:$AO$55,3,FALSE)) -> 0 | C94: =(VLOOKUP(' 6.0.00'!K94,' 6.0.00'!$AM$4:$AO$55,3,FALSE)) -> 0 | D94: =(VLOOKUP(' 6.0.00'!L94,' 6.0.00'!$AM$4:$AO$55,3,FALSE)) -> 0 | E94: =(VLOOKUP(' 6.0.00'!M94,' 6.0.00'!$AM$4:$AO$55,3,FALSE)) -> 0 | F94: =(VLOOKUP(' 6.0.00'!N94,' 6.0.00'!$AM$4:$AO$55,3,FALSE)) -> 0 | G94: =(VLOOKUP(' 6.0.00'!O94,' 6.0.00'!$AM$4:$AO$55,3,FALSE)) -> 0 | H94: =(VLOOKUP(' 6.0.00'!P94,' 6.0.00'!$AM$4:$AO$55,3,FALSE)) -> 0 | ... X94: =(VLOOKUP(' 6.0.00'!AF94,' 6.0.00'!$AM$4:$AO$55,3,FALSE)) -> 0
