Workbook

Sheet 19.02
A1: =(_xlfn.DAYS(TODAY(),A4)+2)/((_xlfn.DAYS(A93,A4))+1) -> 0.022222222 | I1: 工作区
B2: 八卦前亏 | C2: =SUM(D4:D19) -> 30028 | D2: 合计经验 | F2: =SUM(F4:F93)+SUM(H4:H93) -> 25790 | I2: 队伍一 火 | K2: 步数 | L2: =COUNTIF(I4:P93,"<>空") -> 6 | M2: (不算跳步和传送) | Q2: 队伍二 雷 | S2: 步数 | T2: =COUNTIF(Q4:X93,"<>空") -> 184 | U2: (不算跳步和传送) | Y2: 队伍三 | AA2: 总步数 | AB2: =COUNTIF(Y4:AF93,"<>空") -> 138 | AC2: (不算跳步和传送) | AG2: =SUM(AG4:AG93) -> 36 | AH2: =SUM(AH4:AH93) -> 1 | AI2: =SUM(AI4:AI93) -> 26 | AJ2: =SUM(AJ4:AJ93) -> 9 | AK2: 八卦全开 | AU2: 总地块 | AV2: =SUM(AV4:AV29) -> 328 | AW2: 剩余粮草 | AX2: =AR47 -> -158 | AY2: 总经验 | AZ2: =SUM(AX4:AZ29)+7000 -> 25790 | BB2: 粮草系数
A3: 日期 | B3: 获得粮草 | C3: 粮草调整 | D3: 消耗粮草 | E3: 剩余粮草 | F3: 获得经验 | G3: 累计经验 | H3: 任务经验 | I3: 1 | J3: 2 | K3: 3 | L3: 4 | M3: 5 | N3: 6 | O3: 7 | P3: 8 | Q3: 1 | R3: 2 | S3: 3 | T3: 4 | U3: 5 | V3: 6 | W3: 7 | X3: 8 | Y3: 1 | Z3: 2 | AA3: 3 | AB3: 4 | AC3: 5 | AD3: 6 | AE3: 7 | AF3: 8 | AG3: 跳步次数 | AH3: 1队跳步 | AI3: 2队跳步 | AJ3: 3队跳步 | AL3: 1队剩步 | AM3: 2队剩步 | AN3: 3队剩步 | AO3: 地块 | AP3: 粮草 | AQ3: 经验 | AR3: 八卦前亏损 | AS3: 一队地块 | AT3: 二队地块 | AU3: 三队地块 | AV3: 总地块 | AX3: 一队经验 | AY3: 二队经验 | AZ3: 三队经验 | BA3: 八卦前 | BB3: 1
A4: 45730 | B4: 800 | C4: 4800 | D4: =(SUM(粮草!A4:X4)+AG4*10*IF(AK4="是",$BB$4,$BB$3)) -> 2600 | E4: =SUM($B$4:B4)+SUM($C$4:C4)-SUM($D$4:D4) -> 3000 | F4: =SUM(经验!A4:X4) -> 625 | G4: =SUM($F$4:F4)+SUM($H$4:H4) -> 1125 | H4: 500 | I4: 1级 | J4: 1级 | K4: 1级 | L4: 1级 | M4: 1级 | N4: 1级 | O4: 空 | P4: 空 | Q4: 1级 | R4: 1级 | S4: 1级 | T4: 1级 | U4: 1级 | V4: 1级 | W4: 空 | X4: 空 | Y4: 商人 | Z4: 1级 | AA4: 1级 | AB4: 1级 | AC4: 1级 | AD4: 1级 | AE4: 空 | AF4: 空 | AG4: =AH4+AI4+AJ4 -> 0 | AK4: 否 | AL4: =6-COUNTIF(I4:P4,"<>空") -> 0 | AM4: =6-COUNTIF(Q4:X4,"<>空") -> 0 | AN4: =6-COUNTIF(Y4:AF4,"<>空") -> 0 | AO4: 1级 | AP4: 150 | AQ4: 35 | AR4: 44.222109 | AS4: =COUNTIF($I$4:$P$93,AO4) -> 6 | AT4: =COUNTIF($Q$4:$X$93,AO4) -> 6 | AU4: =COUNTIF($Y$4:$AF$93,AO4) -> 13 | AV4: =AS4+AT4+AU4 -> 25 | AW4: 30 | AX4: =AS4*$AQ4 -> 210 | AY4: =AT4*$AQ4 -> 210 | AZ4: =AU4*$AQ4 -> 455 | BA4: 八卦后 | BB4: 0.8 | BD4: =AP4*0.8 -> 120
A5: 45731 | B5: 1600 | C5: 1250 | D5: =(SUM(粮草!A5:X5)+AG5*10*IF(AK5="是",$BB$4,$BB$3)) -> 1780 | E5: =SUM($B$4:B5)+SUM($C$4:C5)-SUM($D$4:D5) -> 4070 | F5: =SUM(经验!A5:X5) -> 450 | G5: =SUM($F$4:F5)+SUM($H$4:H5) -> 1575 | H5: 0 | I5: 空 | J5: 空 | K5: 空 | L5: 空 | M5: 空 | N5: 空 | O5: 空 | P5: 空 | Q5: 2级 | R5: 2级 | S5: 2级 | T5: 商人 | U5: 2级 | V5: 2级 | W5: 空 | X5: 空 | Y5: 1级 | Z5: 1级 | AA5: 1级 | AB5: 1级 | AC5: 2级 | AD5: 2级 | AE5: 空 | AF5: 空 | AG5: =AH5+AI5+AJ5 -> 1 | AI5: 1 | AK5: 否 | AL5: =MIN(AL4+6,18)-COUNTIF(I5:P5,"<>空")+COUNTIF(I5:P5,"历练")+COUNTIF(I5:P5,"营地")*2 -> 6 | AM5: =MIN(AM4+6,18)-COUNTIF(Q5:X5,"<>空")+COUNTIF(Q5:X5,"历练")+COUNTIF(Q5:X5,"营地")*2 -> 0 | AN5: =MIN(AN4+6,18)-COUNTIF(Y5:AF5,"<>空")+COUNTIF(Y5:AF5,"历练")+COUNTIF(Y5:AF5,"营地")*2 -> 0 | AO5: 2级 | AP5: 160 | AQ5: 40 | AR5: 39.110982 | AS5: =COUNTIF($I$4:$P$93,AO5) -> 0 | AT5: =COUNTIF($Q$4:$X$93,AO5) -> 15 | AU5: =COUNTIF($Y$4:$AF$93,AO5) -> 11 | AV5: =AS5+AT5+AU5 -> 26 | AW5: 54 | AX5: =AS5*$AQ5 -> 0 | AY5: =AT5*$AQ5 -> 600 | AZ5: =AU5*$AQ5 -> 440 | BA5: Note：开完八卦当天可能需要手动计算粮草 | BD5: =AP5*0.8 -> 128
A6: 45732 | B6: 1600 | D6: =(SUM(粮草!A6:X6)+AG6*10*IF(AK6="是",$BB$4,$BB$3)) -> 1920 | E6: =SUM($B$4:B6)+SUM($C$4:C6)-SUM($D$4:D6) -> 3750 | F6: =SUM(经验!A6:X6) -> 480 | G6: =SUM($F$4:F6)+SUM($H$4:H6) -> 2055 | H6: 0 | I6: 空 | J6: 空 | K6: 空 | L6: 空 | M6: 空 | N6: 空 | O6: 空 | P6: 空 | Q6: 2级 | R6: 2级 | S6: 2级 | T6: 2级 | U6: 2级 | V6: 2级 | W6: 空 | X6: 空 | Y6: 2级 | Z6: 2级 | AA6: 2级 | AB6: 2级 | AC6: 2级 | AD6: 2级 | AE6: 空 | AF6: 空 | AG6: =AH6+AI6+AJ6 -> 0 | AK6: 否 | AL6: =MIN(AL5+6,18)-COUNTIF(I6:P6,"<>空")+COUNTIF(I6:P6,"历练")+COUNTIF(I6:P6,"营地")*2 -> 12 | AM6: =MIN(AM5+6,18)-COUNTIF(Q6:X6,"<>空")+COUNTIF(Q6:X6,"历练")+COUNTIF(Q6:X6,"营地")*2 -> 0 | AN6: =MIN(AN5+6,18)-COUNTIF(Y6:AF6,"<>空")+COUNTIF(Y6:AF6,"历练")+COUNTIF(Y6:AF6,"营地")*2 -> 0 | AO6: 3级 | AP6: 170 | AQ6: 45 | AR6: 34 | AS6: =COUNTIF($I$4:$P$93,AO6) -> 0 | AT6: =COUNTIF($Q$4:$X$93,AO6) -> 54 | AU6: =COUNTIF($Y$4:$AF$93,AO6) -> 35 | AV6: =AS6+AT6+AU6 -> 89 | AW6: 180 | AX6: =AS6*$AQ6 -> 0 | AY6: =AT6*$AQ6 -> 2430 | AZ6: =AU6*$AQ6 -> 1575 | BD6: =AP6*0.8 -> 136
A7: 45733 | B7: 1600 | D7: =(SUM(粮草!A7:X7)+AG7*10*IF(AK7="是",$BB$4,$BB$3)) -> 1690 | E7: =SUM($B$4:B7)+SUM($C$4:C7)-SUM($D$4:D7) -> 3660 | F7: =SUM(经验!A7:X7) -> 1000 | G7: =SUM($F$4:F7)+SUM($H$4:H7) -> 3255 | H7: 200 | I7: 空 | J7: 空 | K7: 空 | L7: 空 | M7: 空 | N7: 空 | O7: 空 | P7: 空 | Q7: 2级 | R7: 历练 | S7: 2级 | T7: 2级 | U7: 营地 | V7: 2级 | W7: 4级 | X7: 4级 | Y7: 1级 | Z7: 2级 | AA7: 2级 | AB7: 商人 | AC7: 2级 | AD7: 1级 | AE7: 空 | AF7: 空 | AG7: =AH7+AI7+AJ7 -> 6 | AI7: 6 | AK7: 否 | AL7: =MIN(AL6+6,18)-COUNTIF(I7:P7,"<>空")+COUNTIF(I7:P7,"历练")+COUNTIF(I7:P7,"营地")*2 -> 18 | AM7: =MIN(AM6+6,18)-COUNTIF(Q7:X7,"<>空")+COUNTIF(Q7:X7,"历练")+COUNTIF(Q7:X7,"营地")*2 -> 1 | AN7: =MIN(AN6+6,18)-COUNTIF(Y7:AF7,"<>空")+COUNTIF(Y7:AF7,"历练")+COUNTIF(Y7:AF7,"营地")*2 -> 0 | AO7: 4级 | AP7: 180 | AQ7: 50 | AR7: 36 | AS7: =COUNTIF($I$4:$P$93,AO7) -> 0 | AT7: =COUNTIF($Q$4:$X$93,AO7) -> 4 | AU7: =COUNTIF($Y$4:$AF$93,AO7) -> 39 | AV7: =AS7+AT7+AU7 -> 43 | AW7: 104 | AX7: =AS7*$AQ7 -> 0 | AY7: =AT7*$AQ7 -> 200 | AZ7: =AU7*$AQ7 -> 1950 | BD7: =AP7*0.8 -> 144
A8: 45734 | B8: 1600 | D8: =(SUM(粮草!A8:X8)+AG8*10*IF(AK8="是",$BB$4,$BB$3)) -> 2130 | E8: =SUM($B$4:B8)+SUM($C$4:C8)-SUM($D$4:D8) -> 3130 | F8: =SUM(经验!A8:X8) -> 850 | G8: =SUM($F$4:F8)+SUM($H$4:H8) -> 4205 | H8: 100 | I8: 空 | J8: 空 | K8: 空 | L8: 空 | M8: 空 | N8: 空 | O8: 空 | P8: 空 | Q8: 4级 | R8: 营地 | S8: 4级 | T8: 3级 | U8: 3级 | V8: 大卦 | W8: 3级 | X8: 3级 | Y8: 3级 | Z8: 3级 | AA8: 3级 | AB8: 3级卦 | AC8: 3级 | AD8: 3级 | AE8: 空 | AF8: 空 | AG8: =AH8+AI8+AJ8 -> 7 | AI8: 5 | AJ8: 2 | AK8: 否 | AL8: =MIN(AL7+6,18)-COUNTIF(I8:P8,"<>空")+COUNTIF(I8:P8,"历练")+COUNTIF(I8:P8,"营地")*2 -> 18 | AM8: =MIN(AM7+6,18)-COUNTIF(Q8:X8,"<>空")+COUNTIF(Q8:X8,"历练")+COUNTIF(Q8:X8,"营地")*2 -> 1 | AN8: =MIN(AN7+6,18)-COUNTIF(Y8:AF8,"<>空")+COUNTIF(Y8:AF8,"历练")+COUNTIF(Y8:AF8,"营地")*2 -> 0 | AO8: 5级 | AP8: 190 | AQ8: 55 | AR8: 38 | AS8: =COUNTIF($I$4:$P$93,AO8) -> 0 | AT8: =COUNTIF($Q$4:$X$93,AO8) -> 26 | AU8: =COUNTIF($Y$4:$AF$93,AO8) -> 21 | AV8: =AS8+AT8+AU8 -> 47 | AW8: 31 | AX8: =AS8*$AQ8 -> 0 | AY8: =AT8*$AQ8 -> 1430 | AZ8: =AU8*$AQ8 -> 1155 | BD8: =AP8*0.8 -> 152
A9: 45735 | B9: 1600 | D9: =(SUM(粮草!A9:X9)+AG9*10*IF(AK9="是",$BB$4,$BB$3)) -> 1680 | E9: =SUM($B$4:B9)+SUM($C$4:C9)-SUM($D$4:D9) -> 3050 | F9: =SUM(经验!A9:X9) -> 545 | G9: =SUM($F$4:F9)+SUM($H$4:H9) -> 4950 | H9: 200 | I9: 空 | J9: 空 | K9: 空 | L9: 空 | M9: 空 | N9: 空 | O9: 空 | P9: 空 | Q9: 3级 | R9: 3级 | S9: 营地 | T9: 3级 | U9: 3级 | V9: 3级 | W9: 3级 | X9: 商人 | Y9: 1级 | Z9: 3级 | AA9: 商人 | AB9: 3级 | AC9: 塔3 | AD9: 3级 | AE9: 空 | AF9: 空 | AG9: =AH9+AI9+AJ9 -> 0 | AK9: 否 | AL9: =MIN(AL8+6,18)-COUNTIF(I9:P9,"<>空")+COUNTIF(I9:P9,"历练")+COUNTIF(I9:P9,"营地")*2 -> 18 | AM9: =MIN(AM8+6,18)-COUNTIF(Q9:X9,"<>空")+COUNTIF(Q9:X9,"历练")+COUNTIF(Q9:X9,"营地")*2 -> 1 | AN9: =MIN(AN8+6,18)-COUNTIF(Y9:AF9,"<>空")+COUNTIF(Y9:AF9,"历练")+COUNTIF(Y9:AF9,"营地")*2 -> 0 | AO9: 6级 | AP9: 200 | AQ9: 60 | AS9: =COUNTIF($I$4:$P$93,AO9) -> 0 | AT9: =COUNTIF($Q$4:$X$93,AO9) -> 58 | AU9: =COUNTIF($Y$4:$AF$93,AO9) -> 0 | AV9: =AS9+AT9+AU9 -> 58 | AW9: 98 | AX9: =AS9*$AQ9 -> 0 | AY9: =AT9*$AQ9 -> 3480 | AZ9: =AU9*$AQ9 -> 0 | BD9: =AP9*0.8 -> 160
A10: 45736 | B10: 1600 | D10: =(SUM(粮草!A10:X10)+AG10*10*IF(AK10="是",$BB$4,$BB$3)) -> 2080 | E10: =SUM($B$4:B10)+SUM($C$4:C10)-SUM($D$4:D10) -> 2570 | F10: =SUM(经验!A10:X10) -> 570 | G10: =SUM($F$4:F10)+SUM($H$4:H10) -> 5520 | H10: 0 | I10: 空 | J10: 空 | K10: 空 | L10: 空 | M10: 空 | N10: 空 | O10: 空 | P10: 空 | Q10: 3级 | R10: 3级 | S10: 塔3 | T10: 3级 | U10: 3级 | V10: 3级 | W10: 商人 | X10: 空 | Y10: 3级 | Z10: 3级卦 | AA10: 3级 | AB10: 3级 | AC10: 3级 | AD10: 3级 | AE10: 空 | AF10: 空 | AG10: =AH10+AI10+AJ10 -> 1 | AJ10: 1 | AK10: 否 | AL10: =MIN(AL9+6,18)-COUNTIF(I10:P10,"<>空")+COUNTIF(I10:P10,"历练")+COUNTIF(I10:P10,"营地")*2 -> 18 | AM10: =MIN(AM9+6,18)-COUNTIF(Q10:X10,"<>空")+COUNTIF(Q10:X10,"历练")+COUNTIF(Q10:X10,"营地")*2 -> 0 | AN10: =MIN(AN9+6,18)-COUNTIF(Y10:AF10,"<>空")+COUNTIF(Y10:AF10,"历练")+COUNTIF(Y10:AF10,"营地")*2 -> 0 | AO10: 塔1 | AP10: 150 | AQ10: 35 | AR10: 44.222109 | AS10: =COUNTIF($I$4:$P$93,AO10) -> 0 | AT10: =COUNTIF($Q$4:$X$93,AO10) -> 0 | AU10: =COUNTIF($Y$4:$AF$93,AO10) -> 0 | AV10: =AS10+AT10+AU10 -> 0 | AW10: 0 | AX10: =AS10*$AQ10 -> 0 | AY10: =AT10*$AQ10 -> 0 | AZ10: =AU10*$AQ10 -> 0 | BD10: =AP10*0.8 -> 120
A11: 45737 | B11: 1600 | D11: =(SUM(粮草!A11:X11)+AG11*10*IF(AK11="是",$BB$4,$BB$3)) -> 1960 | E11: =SUM($B$4:B11)+SUM($C$4:C11)-SUM($D$4:D11) -> 2210 | F11: =SUM(经验!A11:X11) -> 590 | G11: =SUM($F$4:F11)+SUM($H$4:H11) -> 6110 | H11: 0 | I11: 空 | J11: 空 | K11: 空 | L11: 空 | M11: 空 | N11: 空 | O11: 空 | P11: 空 | Q11: 3级 | R11: 3级 | S11: 3级 | T11: 营地 | U11: 3级 | V11: 3级 | W11: 3级 | X11: 3级 | Y11: 3级 | Z11: 3级 | AA11: 3级 | AB11: 塔3 | AC11: 3级 | AD11: 4级 | AE11: 空 | AF11: 空 | AG11: =AH11+AI11+AJ11 -> 1 | AI11: 1 | AK11: 否 | AL11: =MIN(AL10+6,18)-COUNTIF(I11:P11,"<>空")+COUNTIF(I11:P11,"历练")+COUNTIF(I11:P11,"营地")*2 -> 18 | AM11: =MIN(AM10+6,18)-COUNTIF(Q11:X11,"<>空")+COUNTIF(Q11:X11,"历练")+COUNTIF(Q11:X11,"营地")*2 -> 0 | AN11: =MIN(AN10+6,18)-COUNTIF(Y11:AF11,"<>空")+COUNTIF(Y11:AF11,"历练")+COUNTIF(Y11:AF11,"营地")*2 -> 0 | AO11: 塔2 | AP11: 150 | AQ11: 40 | AR11: 29.110982 | AS11: =COUNTIF($I$4:$P$93,AO11) -> 0 | AT11: =COUNTIF($Q$4:$X$93,AO11) -> 0 | AU11: =COUNTIF($Y$4:$AF$93,AO11) -> 0 | AV11: =AS11+AT11+AU11 -> 0 | AW11: 2 | AX11: =AS11*$AQ11 -> 0 | AY11: =AT11*$AQ11 -> 0 | AZ11: =AU11*$AQ11 -> 0 | BD11: =AP11*0.8 -> 120
A12: 45738 | B12: 1600 | D12: =(SUM(粮草!A12:X12)+AG12*10*IF(AK12="是",$BB$4,$BB$3)) -> 1980 | E12: =SUM($B$4:B12)+SUM($C$4:C12)-SUM($D$4:D12) -> 1830 | F12: =SUM(经验!A12:X12) -> 540 | G12: =SUM($F$4:F12)+SUM($H$4:H12) -> 6650 | H12: 0 | I12: 空 | J12: 空 | K12: 空 | L12: 空 | M12: 空 | N12: 空 | O12: 空 | P12: 空 | Q12: 3级卦 | R12: 3级 | S12: 商人 | T12: 3级 | U12: 3级 | V12: 3级 | W12: 空 | X12: 空 | Y12: 4级 | Z12: 4级 | AA12: 4级 | AB12: 3级 | AC12: 3级 | AD12: 3级卦 | AE12: 空 | AF12: 空 | AG12: =AH12+AI12+AJ12 -> 3 | AI12: 1 | AJ12: 2 | AK12: 否 | AL12: =MIN(AL11+6,18)-COUNTIF(I12:P12,"<>空")+COUNTIF(I12:P12,"历练")+COUNTIF(I12:P12,"营地")*2 -> 18 | AM12: =MIN(AM11+6,18)-COUNTIF(Q12:X12,"<>空")+COUNTIF(Q12:X12,"历练")+COUNTIF(Q12:X12,"营地")*2 -> 0 | AN12: =MIN(AN11+6,18)-COUNTIF(Y12:AF12,"<>空")+COUNTIF(Y12:AF12,"历练")+COUNTIF(Y12:AF12,"营地")*2 -> 0 | AO12: 塔3 | AP12: 150 | AQ12: 45 | AR12: 13.999855 | AS12: =COUNTIF($I$4:$P$93,AO12) -> 0 | AT12: =COUNTIF($Q$4:$X$93,AO12) -> 1 | AU12: =COUNTIF($Y$4:$AF$93,AO12) -> 3 | AV12: =AS12+AT12+AU12 -> 4 | AW12: 5 | AX12: =AS12*$AQ12 -> 0 | AY12: =AT12*$AQ12 -> 45 | AZ12: =AU12*$AQ12 -> 135 | BD12: =AP12*0.8 -> 120
A13: 45739 | B13: 1600 | D13: =(SUM(粮草!A13:X13)+AG13*10*IF(AK13="是",$BB$4,$BB$3)) -> 2090 | E13: =SUM($B$4:B13)+SUM($C$4:C13)-SUM($D$4:D13) -> 1340 | F13: =SUM(经验!A13:X13) -> 565 | G13: =SUM($F$4:F13)+SUM($H$4:H13) -> 7215 | H13: 0 | I13: 空 | J13: 空 | K13: 空 | L13: 空 | M13: 空 | N13: 空 | O13: 空 | P13: 空 | Q13: 3级 | R13: 3级 | S13: 3级 | T13: 3级 | U13: 3级 | V13: 3级 | W13: 空 | X13: 空 | Y13: 3级 | Z13: 4级 | AA13: 4级 | AB13: 4级 | AC13: 4级 | AD13: 4级 | AE13: 空 | AF13: 空 | AG13: =AH13+AI13+AJ13 -> 0 | AK13: 否 | AL13: =MIN(AL12+6,18)-COUNTIF(I13:P13,"<>空")+COUNTIF(I13:P13,"历练")+COUNTIF(I13:P13,"营地")*2 -> 18 | AM13: =MIN(AM12+6,18)-COUNTIF(Q13:X13,"<>空")+COUNTIF(Q13:X13,"历练")+COUNTIF(Q13:X13,"营地")*2 -> 0 | AN13: =MIN(AN12+6,18)-COUNTIF(Y13:AF13,"<>空")+COUNTIF(Y13:AF13,"历练")+COUNTIF(Y13:AF13,"营地")*2 -> 0 | AO13: 塔4 | AP13: 150 | AQ13: 50 | AS13: =COUNTIF($I$4:$P$93,AO13) -> 0 | AT13: =COUNTIF($Q$4:$X$93,AO13) -> 0 | AU13: =COUNTIF($Y$4:$AF$93,AO13) -> 0 | AV13: =AS13+AT13+AU13 -> 0 | AW13: 1 | AX13: =AS13*$AQ13 -> 0 | AY13: =AT13*$AQ13 -> 0 | AZ13: =AU13*$AQ13 -> 0 | BD13: =AP13*0.8 -> 120
A14: 45740 | B14: 1600 | D14: =(SUM(粮草!A14:X14)+AG14*10*IF(AK14="是",$BB$4,$BB$3)) -> 2050 | E14: =SUM($B$4:B14)+SUM($C$4:C14)-SUM($D$4:D14) -> 890 | F14: =SUM(经验!A14:X14) -> 555 | G14: =SUM($F$4:F14)+SUM($H$4:H14) -> 8070 | H14: 300 | I14: 空 | J14: 空 | K14: 空 | L14: 空 | M14: 空 | N14: 空 | O14: 空 | P14: 空 | Q14: 3级 | R14: 3级卦 | S14: 3级 | T14: 3级 | U14: 3级 | V14: 3级 | W14: 空 | X14: 空 | Y14: 4级 | Z14: 4级 | AA14: 4级 | AB14: 3级 | AC14: 塔3 | AD14: 3级 | AE14: 空 | AF14: 空 | AG14: =AH14+AI14+AJ14 -> 0 | AK14: 否 | AL14: =MIN(AL13+6,18)-COUNTIF(I14:P14,"<>空")+COUNTIF(I14:P14,"历练")+COUNTIF(I14:P14,"营地")*2 -> 18 | AM14: =MIN(AM13+6,18)-COUNTIF(Q14:X14,"<>空")+COUNTIF(Q14:X14,"历练")+COUNTIF(Q14:X14,"营地")*2 -> 0 | AN14: =MIN(AN13+6,18)-COUNTIF(Y14:AF14,"<>空")+COUNTIF(Y14:AF14,"历练")+COUNTIF(Y14:AF14,"营地")*2 -> 0 | AO14: 塔5 | AP14: 150 | AQ14: 55 | AS14: =COUNTIF($I$4:$P$93,AO14) -> 0 | AT14: =COUNTIF($Q$4:$X$93,AO14) -> 0 | AU14: =COUNTIF($Y$4:$AF$93,AO14) -> 0 | AV14: =AS14+AT14+AU14 -> 0 | AW14: 0 | AX14: =AS14*$AQ14 -> 0 | AY14: =AT14*$AQ14 -> 0 | AZ14: =AU14*$AQ14 -> 0 | BD14: =AP14*0.8 -> 120
A15: 45741 | B15: 1600 | D15: =(SUM(粮草!A15:X15)+AG15*10*IF(AK15="是",$BB$4,$BB$3)) -> 1890 | E15: =SUM($B$4:B15)+SUM($C$4:C15)-SUM($D$4:D15) -> 600 | F15: =SUM(经验!A15:X15) -> 765 | G15: =SUM($F$4:F15)+SUM($H$4:H15) -> 8835 | H15: 0 | I15: 空 | J15: 空 | K15: 空 | L15: 空 | M15: 空 | N15: 空 | O15: 空 | P15: 空 | Q15: 3级 | R15: 3级 | S15: 3级 | T15: 5级 | U15: 5级 | V15: 5级 | W15: 空 | X15: 空 | Y15: 商人 | Z15: 3级 | AA15: 3级 | AB15: 3级 | AC15: 大卦 | AD15: 空 | AE15: 空 | AF15: 空 | AG15: =AH15+AI15+AJ15 -> 0 | AK15: 否 | AL15: =MIN(AL14+6,18)-COUNTIF(I15:P15,"<>空")+COUNTIF(I15:P15,"历练")+COUNTIF(I15:P15,"营地")*2 -> 18 | AM15: =MIN(AM14+6,18)-COUNTIF(Q15:X15,"<>空")+COUNTIF(Q15:X15,"历练")+COUNTIF(Q15:X15,"营地")*2 -> 0 | AN15: =MIN(AN14+6,18)-COUNTIF(Y15:AF15,"<>空")+COUNTIF(Y15:AF15,"历练")+COUNTIF(Y15:AF15,"营地")*2 -> 1 | AO15: 塔6 | AP15: 150 | AQ15: 60 | AS15: =COUNTIF($I$4:$P$93,AO15) -> 0 | AT15: =COUNTIF($Q$4:$X$93,AO15) -> 0 | AU15: =COUNTIF($Y$4:$AF$93,AO15) -> 0 | AV15: =AS15+AT15+AU15 -> 0 | AW15: 0 | AX15: =AS15*$AQ15 -> 0 | AY15: =AT15*$AQ15 -> 0 | AZ15: =AU15*$AQ15 -> 0 | BD15: =AP15*0.8 -> 120
A16: 45742 | B16: 1600 | D16: =(SUM(粮草!A16:X16)+AG16*10*IF(AK16="是",$BB$4,$BB$3)) -> 1040 | E16: =SUM($B$4:B16)+SUM($C$4:C16)-SUM($D$4:D16) -> 1160 | F16: =SUM(经验!A16:X16) -> 280 | G16: =SUM($F$4:F16)+SUM($H$4:H16) -> 9315 | H16: 200 | I16: 空 | J16: 空 | K16: 空 | L16: 空 | M16: 空 | N16: 空 | O16: 空 | P16: 空 | Q16: 5级 | R16: 3级 | S16: 3级 | T16: 3级 | U16: 3级 | V16: 3级 | W16: 空 | X16: 空 | Y16: 空 | Z16: 空 | AA16: 空 | AB16: 空 | AC16: 空 | AD16: 空 | AE16: 空 | AF16: 空 | AG16: =AH16+AI16+AJ16 -> 0 | AK16: 否 | AL16: =MIN(AL15+6,18)-COUNTIF(I16:P16,"<>空")+COUNTIF(I16:P16,"历练")+COUNTIF(I16:P16,"营地")*2 -> 18 | AM16: =MIN(AM15+6,18)-COUNTIF(Q16:X16,"<>空")+COUNTIF(Q16:X16,"历练")+COUNTIF(Q16:X16,"营地")*2 -> 0 | AN16: =MIN(AN15+6,18)-COUNTIF(Y16:AF16,"<>空")+COUNTIF(Y16:AF16,"历练")+COUNTIF(Y16:AF16,"营地")*2 -> 7 | AO16: 遗迹 | AP16: 150 | AQ16: 35 | AR16: 44.222109 | AS16: =COUNTIF($I$4:$P$93,AO16) -> 0 | AT16: =COUNTIF($Q$4:$X$93,AO16) -> 0 | AU16: =COUNTIF($Y$4:$AF$93,AO16) -> 0 | AV16: =AS16+AT16+AU16 -> 0 | AW16: 0 | AX16: =AS16*$AQ16 -> 0 | AY16: =AT16*$AQ16 -> 0 | AZ16: =AU16*$AQ16 -> 0 | BD16: =AP16*0.8 -> 120
A17: 45743 | B17: 1600 | C17: -50 | D17: =(SUM(粮草!A17:X17)+AG17*10*IF(AK17="是",$BB$4,$BB$3)) -> 1654 | E17: =SUM($B$4:B17)+SUM($C$4:C17)-SUM($D$4:D17) -> 1056 | F17: =SUM(经验!A17:X17) -> 860 | G17: =SUM($F$4:F17)+SUM($H$4:H17) -> 10175 | H17: 0 | I17: 空 | J17: 空 | K17: 空 | L17: 空 | M17: 空 | N17: 空 | O17: 空 | P17: 空 | Q17: 大卦 | R17: 3级 | S17: 3级 | T17: 3级 | U17: 3级 | V17: 5级 | W17: 空 | X17: 空 | Y17: 3级 | Z17: 3级 | AA17: 3级 | AB17: 5级 | AC17: 3级 | AD17: 3级 | AE17: 营地 | AF17: 3级 | AG17: =AH17+AI17+AJ17 -> 0 | AK17: 是 | AL17: =MIN(AL16+6,18)-COUNTIF(I17:P17,"<>空")+COUNTIF(I17:P17,"历练")+COUNTIF(I17:P17,"营地")*2 -> 18 | AM17: =MIN(AM16+6,18)-COUNTIF(Q17:X17,"<>空")+COUNTIF(Q17:X17,"历练")+COUNTIF(Q17:X17,"营地")*2 -> 0 | AN17: =MIN(AN16+6,18)-COUNTIF(Y17:AF17,"<>空")+COUNTIF(Y17:AF17,"历练")+COUNTIF(Y17:AF17,"营地")*2 -> 7 | AO17: 商人 | AP17: 50 | AQ17: 30 | AR17: 10 | AS17: =COUNTIF($I$4:$P$93,AO17) -> 0 | AT17: =COUNTIF($Q$4:$X$93,AO17) -> 4 | AU17: =COUNTIF($Y$4:$AF$93,AO17) -> 7 | AV17: =AS17+AT17+AU17 -> 11 | AW17: 34 | AX17: =AS17*$AQ17 -> 0 | AY17: =AT17*$AQ17 -> 120 | AZ17: =AU17*$AQ17 -> 210 | BD17: =AP17*0.8 -> 40
A18: 45744 | B18: 1600 | D18: =(SUM(粮草!A18:X18)+AG18*10*IF(AK18="是",$BB$4,$BB$3)) -> 1936 | E18: =SUM($B$4:B18)+SUM($C$4:C18)-SUM($D$4:D18) -> 720 | F18: =SUM(经验!A18:X18) -> 670 | G18: =SUM($F$4:F18)+SUM($H$4:H18) -> 10845 | H18: 0 | I18: 空 | J18: 空 | K18: 空 | L18: 空 | M18: 空 | N18: 空 | O18: 空 | P18: 空 | Q18: 5级 | R18: 5级 | S18: 5级 | T18: 5级 | U18: 3级 | V18: 3级 | W18: 空 | X18: 空 | Y18: 3级 | Z18: 商人 | AA18: 3级 | AB18: 3级 | AC18: 3级 | AD18: 4级 | AE18: 4级 | AF18: 4级 | AG18: =AH18+AI18+AJ18 -> 5 | AI18: 5 | AK18: 是 | AL18: =MIN(AL17+6,18)-COUNTIF(I18:P18,"<>空")+COUNTIF(I18:P18,"历练")+COUNTIF(I18:P18,"营地")*2 -> 18 | AM18: =MIN(AM17+6,18)-COUNTIF(Q18:X18,"<>空")+COUNTIF(Q18:X18,"历练")+COUNTIF(Q18:X18,"营地")*2 -> 0 | AN18: =MIN(AN17+6,18)-COUNTIF(Y18:AF18,"<>空")+COUNTIF(Y18:AF18,"历练")+COUNTIF(Y18:AF18,"营地")*2 -> 5 | AO18: 营地 | AP18: -150 | AQ18: 0 | AR18: 10 | AS18: =COUNTIF($I$4:$P$93,AO18) -> 0 | AT18: =COUNTIF($Q$4:$X$93,AO18) -> 9 | AU18: =COUNTIF($Y$4:$AF$93,AO18) -> 4 | AV18: =AS18+AT18+AU18 -> 13 | AW18: 15 | AX18: =AS18*$AQ18 -> 0 | AY18: =AT18*$AQ18 -> 0 | AZ18: =AU18*$AQ18 -> 0 | BD18: =AP18*0.8 -> -120
A19: 45745 | B19: 1600 | D19: =(SUM(粮草!A19:X19)+AG19*10*IF(AK19="是",$BB$4,$BB$3)) -> 1548 | E19: =SUM($B$4:B19)+SUM($C$4:C19)-SUM($D$4:D19) -> 772 | F19: =SUM(经验!A19:X19) -> 710 | G19: =SUM($F$4:F19)+SUM($H$4:H19) -> 11555 | H19: 0 | I19: 空 | J19: 空 | K19: 空 | L19: 空 | M19: 空 | N19: 空 | O19: 空 | P19: 空 | Q19: 5级 | R19: 5级 | S19: 5级 | T19: 5级 | U19: 5级 | V19: 5级 | W19: 营地 | X19: 5级 | Y19: 营地 | Z19: 4级 | AA19: 1级 | AB19: 4级 | AC19: 4级 | AD19: 商人 | AE19: 5级 | AF19: 5级 | AG19: =AH19+AI19+AJ19 -> 1 | AI19: 1 | AK19: 是 | AL19: =MIN(AL18+6,18)-COUNTIF(I19:P19,"<>空")+COUNTIF(I19:P19,"历练")+COUNTIF(I19:P19,"营地")*2 -> 18 | AM19: =MIN(AM18+6,18)-COUNTIF(Q19:X19,"<>空")+COUNTIF(Q19:X19,"历练")+COUNTIF(Q19:X19,"营地")*2 -> 0 | AN19: =MIN(AN18+6,18)-COUNTIF(Y19:AF19,"<>空")+COUNTIF(Y19:AF19,"历练")+COUNTIF(Y19:AF19,"营地")*2 -> 5 | AO19: 大卦 | AP19: 250 | AQ19: 300 | AS19: =COUNTIF($I$4:$P$93,AO19) -> 0 | AT19: =COUNTIF($Q$4:$X$93,AO19) -> 2 | AU19: =COUNTIF($Y$4:$AF$93,AO19) -> 1 | AV19: =AS19+AT19+AU19 -> 3 | AW19: 3 | AX19: =AS19*$AQ19 -> 0 | AY19: =AT19*$AQ19 -> 600 | AZ19: =AU19*$AQ19 -> 300 | BD19: =AP19*0.8 -> 200
A20: 45746 | B20: 1600 | D20: =(SUM(粮草!A20:X20)+AG20*10*IF(AK20="是",$BB$4,$BB$3)) -> 2168 | E20: =SUM($B$4:B20)+SUM($C$4:C20)-SUM($D$4:D20) -> 204 | F20: =SUM(经验!A20:X20) -> 770 | G20: =SUM($F$4:F20)+SUM($H$4:H20) -> 12325 | H20: 0 | I20: 空 | J20: 空 | K20: 空 | L20: 空 | M20: 空 | N20: 空 | O20: 空 | P20: 空 | Q20: 5级 | R20: 5级 | S20: 5级 | T20: 5级 | U20: 5级 | V20: 5级 | W20: 空 | X20: 空 | Y20: 5级 | Z20: 5级 | AA20: 5级 | AB20: 5级 | AC20: 5级 | AD20: 5级 | AE20: 5级 | AF20: 5级 | AG20: =AH20+AI20+AJ20 -> 5 | AI20: 5 | AK20: 是 | AL20: =MIN(AL19+6,18)-COUNTIF(I20:P20,"<>空")+COUNTIF(I20:P20,"历练")+COUNTIF(I20:P20,"营地")*2 -> 18 | AM20: =MIN(AM19+6,18)-COUNTIF(Q20:X20,"<>空")+COUNTIF(Q20:X20,"历练")+COUNTIF(Q20:X20,"营地")*2 -> 0 | AN20: =MIN(AN19+6,18)-COUNTIF(Y20:AF20,"<>空")+COUNTIF(Y20:AF20,"历练")+COUNTIF(Y20:AF20,"营地")*2 -> 3 | AO20: 3级卦 | AP20: 170 | AQ20: 45 | AS20: =COUNTIF($I$4:$P$93,AO20) -> 0 | AT20: =COUNTIF($Q$4:$X$93,AO20) -> 2 | AU20: =COUNTIF($Y$4:$AF$93,AO20) -> 3 | AV20: =AS20+AT20+AU20 -> 5 | AW20: 5 | AX20: =AS20*$AQ20 -> 0 | AY20: =AT20*$AQ20 -> 90 | AZ20: =AU20*$AQ20 -> 135 | BD20: =AP20*0.8 -> 136
A21: 45747 | B21: 1600 | D21: =(SUM(粮草!A21:X21)+AG21*10*IF(AK21="是",$BB$4,$BB$3)) -> 1670 | E21: =SUM($B$4:B21)+SUM($C$4:C21)-SUM($D$4:D21) -> 134 | F21: =SUM(经验!A21:X21) -> 695 | G21: =SUM($F$4:F21)+SUM($H$4:H21) -> 13220 | H21: 200 | I21: 空 | J21: 空 | K21: 空 | L21: 空 | M21: 空 | N21: 空 | O21: 空 | P21: 空 | Q21: 6级 | R21: 6级 | S21: 6级 | T21: 6级 | U21: 6级 | V21: 营地 | W21: 6级 | X21: 6级 | Y21: 5级 | Z21: 5级 | AA21: 5级 | AB21: 5级 | AC21: 5级 | AD21: 空 | AE21: 空 | AF21: 空 | AG21: =AH21+AI21+AJ21 -> 0 | AK21: 是 | AL21: =MIN(AL20+6,18)-COUNTIF(I21:P21,"<>空")+COUNTIF(I21:P21,"历练")+COUNTIF(I21:P21,"营地")*2 -> 18 | AM21: =MIN(AM20+6,18)-COUNTIF(Q21:X21,"<>空")+COUNTIF(Q21:X21,"历练")+COUNTIF(Q21:X21,"营地")*2 -> 0 | AN21: =MIN(AN20+6,18)-COUNTIF(Y21:AF21,"<>空")+COUNTIF(Y21:AF21,"历练")+COUNTIF(Y21:AF21,"营地")*2 -> 4 | AO21: 巨卦 | AP21: 250 | AQ21: 400 | AS21: =COUNTIF($I$4:$P$93,AO21) -> 0 | AT21: =COUNTIF($Q$4:$X$93,AO21) -> 0 | AU21: =COUNTIF($Y$4:$AF$93,AO21) -> 0 | AV21: =AS21+AT21+AU21 -> 0 | AW21: 0 | AX21: =AS21*$AQ21 -> 0 | AY21: =AT21*$AQ21 -> 0 | AZ21: =AU21*$AQ21 -> 0 | BD21: =AP21*0.8 -> 200
A22: 45748 | B22: 1600 | D22: =(SUM(粮草!A22:X22)+AG22*10*IF(AK22="是",$BB$4,$BB$3)) -> 1704 | E22: =SUM($B$4:B22)+SUM($C$4:C22)-SUM($D$4:D22) -> 30 | F22: =SUM(经验!A22:X22) -> 625 | G22: =SUM($F$4:F22)+SUM($H$4:H22) -> 13945 | H22: 100 | I22: 空 | J22: 空 | K22: 空 | L22: 空 | M22: 空 | N22: 空 | O22: 空 | P22: 空 | Q22: 6级 | R22: 6级 | S22: 6级 | T22: 6级 | U22: 6级 | V22: 6级 | W22: 空 | X22: 空 | Y22: 5级 | Z22: 5级 | AA22: 5级 | AB22: 4级 | AC22: 4级 | AD22: 空 | AE22: 空 | AF22: 空 | AG22: =AH22+AI22+AJ22 -> 0 | AK22: 是 | AL22: =MIN(AL21+6,18)-COUNTIF(I22:P22,"<>空")+COUNTIF(I22:P22,"历练")+COUNTIF(I22:P22,"营地")*2 -> 18 | AM22: =MIN(AM21+6,18)-COUNTIF(Q22:X22,"<>空")+COUNTIF(Q22:X22,"历练")+COUNTIF(Q22:X22,"营地")*2 -> 0 | AN22: =MIN(AN21+6,18)-COUNTIF(Y22:AF22,"<>空")+COUNTIF(Y22:AF22,"历练")+COUNTIF(Y22:AF22,"营地")*2 -> 5 | AO22: 大boss | AP22: 250 | AQ22: 1000 | AS22: =COUNTIF($I$4:$P$93,AO22) -> 0 | AT22: =COUNTIF($Q$4:$X$93,AO22) -> 2 | AU22: =COUNTIF($Y$4:$AF$93,AO22) -> 0 | AV22: =AS22+AT22+AU22 -> 2 | AW22: 1 | AX22: =AS22*$AQ22 -> 0 | AY22: =AT22*$AQ22 -> 2000 | AZ22: =AU22*$AQ22 -> 0 | BD22: =AP22*0.8 -> 200
A23: 45749 | B23: 1600 | D23: =(SUM(粮草!A23:X23)+AG23*10*IF(AK23="是",$BB$4,$BB$3)) -> 916 | E23: =SUM($B$4:B23)+SUM($C$4:C23)-SUM($D$4:D23) -> 714 | F23: =SUM(经验!A23:X23) -> 930 | G23: =SUM($F$4:F23)+SUM($H$4:H23) -> 15075 | H23: 200 | I23: 空 | J23: 空 | K23: 空 | L23: 空 | M23: 空 | N23: 空 | O23: 空 | P23: 空 | Q23: 6级 | R23: 6级 | S23: 6级 | T23: 6级 | U23: 营地 | V23: 空 | W23: 空 | X23: 空 | Y23: 中boss | Z23: 商人 | AA23: 4级 | AB23: 5级 | AC23: 5级 | AD23: 营地 | AE23: 空 | AF23: 空 | AG23: =AH23+AI23+AJ23 -> 1 | AH23: 1 | AK23: 是 | AL23: =MIN(AL22+6,18)-COUNTIF(I23:P23,"<>空")+COUNTIF(I23:P23,"历练")+COUNTIF(I23:P23,"营地")*2 -> 18 | AM23: =MIN(AM22+6,18)-COUNTIF(Q23:X23,"<>空")+COUNTIF(Q23:X23,"历练")+COUNTIF(Q23:X23,"营地")*2 -> 3 | AN23: =MIN(AN22+6,18)-COUNTIF(Y23:AF23,"<>空")+COUNTIF(Y23:AF23,"历练")+COUNTIF(Y23:AF23,"营地")*2 -> 7 | AO23: 中boss | AP23: 250 | AQ23: 500 | AS23: =COUNTIF($I$4:$P$93,AO23) -> 0 | AT23: =COUNTIF($Q$4:$X$93,AO23) -> 0 | AU23: =COUNTIF($Y$4:$AF$93,AO23) -> 1 | AV23: =AS23+AT23+AU23 -> 1 | AW23: 0 | AX23: =AS23*$AQ23 -> 0 | AY23: =AT23*$AQ23 -> 0 | AZ23: =AU23*$AQ23 -> 500 | BD23: =AP23*0.8 -> 200
A24: 45750 | B24: 1600 | D24: =(SUM(粮草!A24:X24)+AG24*10*IF(AK24="是",$BB$4,$BB$3)) -> 40 | E24: =SUM($B$4:B24)+SUM($C$4:C24)-SUM($D$4:D24) -> 2274 | F24: =SUM(经验!A24:X24) -> 0 | G24: =SUM($F$4:F24)+SUM($H$4:H24) -> 15075 | H24: 0 | I24: 空 | J24: 空 | K24: 空 | L24: 空 | M24: 空 | N24: 空 | O24: 空 | P24: 空 | Q24: 空 | R24: 空 | S24: 空 | T24: 空 | U24: 空 | V24: 空 | W24: 空 | X24: 空 | Y24: 空 | Z24: 空 | AA24: 空 | AB24: 空 | AC24: 空 | AD24: 空 | AE24: 空 | AF24: 空 | AG24: =AH24+AI24+AJ24 -> 5 | AI24: 1 | AJ24: 4 | AK24: 是 | AL24: =MIN(AL23+6,18)-COUNTIF(I24:P24,"<>空")+COUNTIF(I24:P24,"历练")+COUNTIF(I24:P24,"营地")*2 -> 18 | AM24: =MIN(AM23+6,18)-COUNTIF(Q24:X24,"<>空")+COUNTIF(Q24:X24,"历练")+COUNTIF(Q24:X24,"营地")*2 -> 9 | AN24: =MIN(AN23+6,18)-COUNTIF(Y24:AF24,"<>空")+COUNTIF(Y24:AF24,"历练")+COUNTIF(Y24:AF24,"营地")*2 -> 13 | AO24: 4级卦 | AP24: 180 | AQ24: 50 | AR24: 39.110982 | AS24: =COUNTIF($I$4:$P$93,AO24) -> 0 | AT24: =COUNTIF($Q$4:$X$93,AO24) -> 0 | AU24: =COUNTIF($Y$4:$AF$93,AO24) -> 0 | AV24: =AS24+AT24+AU24 -> 0 | AW24: 0 | AX24: =AS24*$AQ24 -> 0 | AY24: =AT24*$AQ24 -> 0 | AZ24: =AU24*$AQ24 -> 0 | BD24: =AP24*0.8 -> 144
A25: 45751 | B25: 1600 | D25: =(SUM(粮草!A25:X25)+AG25*10*IF(AK25="是",$BB$4,$BB$3)) -> 840 | E25: =SUM($B$4:B25)+SUM($C$4:C25)-SUM($D$4:D25) -> 3034 | F25: =SUM(经验!A25:X25) -> 1240 | G25: =SUM($F$4:F25)+SUM($H$4:H25) -> 16315 | H25: 0 | I25: 空 | J25: 空 | K25: 空 | L25: 空 | M25: 空 | N25: 空 | O25: 空 | P25: 空 | Q25: 6级 | R25: 6级 | S25: 大boss | T25: 6级 | U25: 6级 | V25: 空 | W25: 空 | X25: 空 | Y25: 空 | Z25: 空 | AA25: 空 | AB25: 空 | AC25: 空 | AD25: 空 | AE25: 空 | AF25: 空 | AG25: =AH25+AI25+AJ25 -> 0 | AK25: 是 | AL25: =MIN(AL24+6,18)-COUNTIF(I25:P25,"<>空")+COUNTIF(I25:P25,"历练")+COUNTIF(I25:P25,"营地")*2 -> 18 | AM25: =MIN(AM24+6,18)-COUNTIF(Q25:X25,"<>空")+COUNTIF(Q25:X25,"历练")+COUNTIF(Q25:X25,"营地")*2 -> 10 | AN25: =MIN(AN24+6,18)-COUNTIF(Y25:AF25,"<>空")+COUNTIF(Y25:AF25,"历练")+COUNTIF(Y25:AF25,"营地")*2 -> 18 | AO25: 山中 | AP25: 160 | AQ25: 40 | AR25: 39.110982 | AS25: =COUNTIF($I$4:$P$93,AO25) -> 0 | AT25: =COUNTIF($Q$4:$X$93,AO25) -> 0 | AU25: =COUNTIF($Y$4:$AF$93,AO25) -> 0 | AV25: =AS25+AT25+AU25 -> 0 | AW25: 0 | AX25: =AS25*$AQ25 -> 0 | AY25: =AT25*$AQ25 -> 0 | AZ25: =AU25*$AQ25 -> 0 | BD25: =AP25*0.8 -> 128
A26: 45752 | B26: 1600 | D26: =(SUM(粮草!A26:X26)+AG26*10*IF(AK26="是",$BB$4,$BB$3)) -> 800 | E26: =SUM($B$4:B26)+SUM($C$4:C26)-SUM($D$4:D26) -> 3834 | F26: =SUM(经验!A26:X26) -> 300 | G26: =SUM($F$4:F26)+SUM($H$4:H26) -> 16615 | H26: 0 | I26: 空 | J26: 空 | K26: 空 | L26: 空 | M26: 空 | N26: 空 | O26: 空 | P26: 空 | Q26: 6级 | R26: 6级 | S26: 6级 | T26: 6级 | U26: 6级 | V26: 空 | W26: 空 | X26: 空 | Y26: 空 | Z26: 空 | AA26: 空 | AB26: 空 | AC26: 空 | AD26: 空 | AE26: 空 | AF26: 空 | AG26: =AH26+AI26+AJ26 -> 0 | AK26: 是 | AL26: =MIN(AL25+6,18)-COUNTIF(I26:P26,"<>空")+COUNTIF(I26:P26,"历练")+COUNTIF(I26:P26,"营地")*2 -> 18 | AM26: =MIN(AM25+6,18)-COUNTIF(Q26:X26,"<>空")+COUNTIF(Q26:X26,"历练")+COUNTIF(Q26:X26,"营地")*2 -> 11 | AN26: =MIN(AN25+6,18)-COUNTIF(Y26:AF26,"<>空")+COUNTIF(Y26:AF26,"历练")+COUNTIF(Y26:AF26,"营地")*2 -> 18 | AO26: 秋道 | AP26: 150 | AQ26: 35 | AR26: 44.222109 | AS26: =COUNTIF($I$4:$P$93,AO26) -> 0 | AT26: =COUNTIF($Q$4:$X$93,AO26) -> 0 | AU26: =COUNTIF($Y$4:$AF$93,AO26) -> 0 | AV26: =AS26+AT26+AU26 -> 0 | AW26: 0 | AX26: =AS26*$AQ26 -> 0 | AY26: =AT26*$AQ26 -> 0 | AZ26: =AU26*$AQ26 -> 0 | BD26: =AP26*0.8 -> 120
A27: 45753 | B27: 1600 | D27: =(SUM(粮草!A27:X27)+AG27*10*IF(AK27="是",$BB$4,$BB$3)) -> 1272 | E27: =SUM($B$4:B27)+SUM($C$4:C27)-SUM($D$4:D27) -> 4162 | F27: =SUM(经验!A27:X27) -> 475 | G27: =SUM($F$4:F27)+SUM($H$4:H27) -> 17090 | H27: 0 | I27: 空 | J27: 空 | K27: 空 | L27: 空 | M27: 空 | N27: 空 | O27: 空 | P27: 空 | Q27: 6级 | R27: 6级 | S27: 6级 | T27: 6级 | U27: 6级 | V27: 6级 | W27: 6级 | X27: 5级 | Y27: 空 | Z27: 空 | AA27: 空 | AB27: 空 | AC27: 空 | AD27: 空 | AE27: 空 | AF27: 空 | AG27: =AH27+AI27+AJ27 -> 0 | AK27: 是 | AL27: =MIN(AL26+6,18)-COUNTIF(I27:P27,"<>空")+COUNTIF(I27:P27,"历练")+COUNTIF(I27:P27,"营地")*2 -> 18 | AM27: =MIN(AM26+6,18)-COUNTIF(Q27:X27,"<>空")+COUNTIF(Q27:X27,"历练")+COUNTIF(Q27:X27,"营地")*2 -> 9 | AN27: =MIN(AN26+6,18)-COUNTIF(Y27:AF27,"<>空")+COUNTIF(Y27:AF27,"历练")+COUNTIF(Y27:AF27,"营地")*2 -> 18 | AO27: 空 | AP27: 0 | AQ27: 0 | AR27: 0 | AX27: =AS27*$AQ27 -> 0 | AY27: =AT27*$AQ27 -> 0 | AZ27: =AU27*$AQ27 -> 0 | BD27: =AP27*0.8 -> 0
A28: 45754 | B28: 1600 | C28: 40 | D28: =(SUM(粮草!A28:X28)+AG28*10*IF(AK28="是",$BB$4,$BB$3)) -> 864 | E28: =SUM($B$4:B28)+SUM($C$4:C28)-SUM($D$4:D28) -> 4938 | F28: =SUM(经验!A28:X28) -> 360 | G28: =SUM($F$4:F28)+SUM($H$4:H28) -> 17650 | H28: 200 | I28: 空 | J28: 空 | K28: 空 | L28: 空 | M28: 空 | N28: 空 | O28: 空 | P28: 空 | Q28: 5级 | R28: 5级 | S28: 营地 | T28: 5级 | U28: 3级 | V28: 3级 | W28: 3级 | X28: 6级 | Y28: 空 | Z28: 空 | AA28: 空 | AB28: 空 | AC28: 空 | AD28: 空 | AE28: 空 | AF28: 空 | AG28: =AH28+AI28+AJ28 -> 0 | AK28: 是 | AL28: =MIN(AL27+6,18)-COUNTIF(I28:P28,"<>空")+COUNTIF(I28:P28,"历练")+COUNTIF(I28:P28,"营地")*2 -> 18 | AM28: =MIN(AM27+6,18)-COUNTIF(Q28:X28,"<>空")+COUNTIF(Q28:X28,"历练")+COUNTIF(Q28:X28,"营地")*2 -> 9 | AN28: =MIN(AN27+6,18)-COUNTIF(Y28:AF28,"<>空")+COUNTIF(Y28:AF28,"历练")+COUNTIF(Y28:AF28,"营地")*2 -> 18 | AO28: 作废 | AP28: 0 | AQ28: 0 | AS28: =COUNTIF($I$4:$P$93,AO28) -> 0 | AT28: =COUNTIF($Q$4:$X$93,AO28) -> 0 | AU28: =COUNTIF($Y$4:$AF$93,AO28) -> 0 | AV28: =AS28+AT28+AU28 -> 0 | AW28: 0 | AX28: =AS28*$AQ28 -> 0 | AY28: =AT28*$AQ28 -> 0 | AZ28: =AU28*$AQ28 -> 0 | BD28: =AP28*0.8 -> 0
A29: 45755 | B29: 1600 | D29: =(SUM(粮草!A29:X29)+AG29*10*IF(AK29="是",$BB$4,$BB$3)) -> 1120 | E29: =SUM($B$4:B29)+SUM($C$4:C29)-SUM($D$4:D29) -> 5418 | F29: =SUM(经验!A29:X29) -> 420 | G29: =SUM($F$4:F29)+SUM($H$4:H29) -> 18170 | H29: 100 | I29: 空 | J29: 空 | K29: 空 | L29: 空 | M29: 空 | N29: 空 | O29: 空 | P29: 空 | Q29: 6级 | R29: 6级 | S29: 6级 | T29: 6级 | U29: 6级 | V29: 6级 | W29: 6级 | X29: 空 | Y29: 空 | Z29: 空 | AA29: 空 | AB29: 空 | AC29: 空 | AD29: 空 | AE29: 空 | AF29: 空 | AG29: =AH29+AI29+AJ29 -> 0 | AK29: 是 | AL29: =MIN(AL28+6,18)-COUNTIF(I29:P29,"<>空")+COUNTIF(I29:P29,"历练")+COUNTIF(I29:P29,"营地")*2 -> 18 | AM29: =MIN(AM28+6,18)-COUNTIF(Q29:X29,"<>空")+COUNTIF(Q29:X29,"历练")+COUNTIF(Q29:X29,"营地")*2 -> 8 | AN29: =MIN(AN28+6,18)-COUNTIF(Y29:AF29,"<>空")+COUNTIF(Y29:AF29,"历练")+COUNTIF(Y29:AF29,"营地")*2 -> 18 | AO29: 历练 | AP29: 50 | AQ29: 520 | AS29: =COUNTIF($I$4:$P$93,AO29) -> 0 | AT29: =COUNTIF($Q$4:$X$93,AO29) -> 1 | AU29: =COUNTIF($Y$4:$AF$93,AO29) -> 0 | AV29: =AS29+AT29+AU29 -> 1 | AW29: 1 | AX29: =AS29*$AQ29 -> 0 | AY29: =AT29*$AQ29 -> 520 | AZ29: =AU29*$AQ29 -> 0 | BD29: =AP29*0.8 -> 40
A30: 45756 | B30: 1600 | D30: =(SUM(粮草!A30:X30)+AG30*10*IF(AK30="是",$BB$4,$BB$3)) -> 960 | E30: =SUM($B$4:B30)+SUM($C$4:C30)-SUM($D$4:D30) -> 6058 | F30: =SUM(经验!A30:X30) -> 360 | G30: =SUM($F$4:F30)+SUM($H$4:H30) -> 18730 | H30: 200 | I30: 空 | J30: 空 | K30: 空 | L30: 空 | M30: 空 | N30: 空 | O30: 空 | P30: 空 | Q30: 6级 | R30: 6级 | S30: 6级 | T30: 6级 | U30: 6级 | V30: 6级 | W30: 空 | X30: 空 | Y30: 空 | Z30: 空 | AA30: 空 | AB30: 空 | AC30: 空 | AD30: 空 | AE30: 空 | AF30: 空 | AG30: =AH30+AI30+AJ30 -> 0 | AK30: 是 | AL30: =MIN(AL29+6,18)-COUNTIF(I30:P30,"<>空")+COUNTIF(I30:P30,"历练")+COUNTIF(I30:P30,"营地")*2 -> 18 | AM30: =MIN(AM29+6,18)-COUNTIF(Q30:X30,"<>空")+COUNTIF(Q30:X30,"历练")+COUNTIF(Q30:X30,"营地")*2 -> 8 | AN30: =MIN(AN29+6,18)-COUNTIF(Y30:AF30,"<>空")+COUNTIF(Y30:AF30,"历练")+COUNTIF(Y30:AF30,"营地")*2 -> 18
A31: 45757 | B31: 1600 | D31: =(SUM(粮草!A31:X31)+AG31*10*IF(AK31="是",$BB$4,$BB$3)) -> 960 | E31: =SUM($B$4:B31)+SUM($C$4:C31)-SUM($D$4:D31) -> 6698 | F31: =SUM(经验!A31:X31) -> 420 | G31: =SUM($F$4:F31)+SUM($H$4:H31) -> 19150 | H31: 0 | I31: 空 | J31: 空 | K31: 空 | L31: 空 | M31: 空 | N31: 空 | O31: 空 | P31: 空 | Q31: 6级 | R31: 6级 | S31: 6级 | T31: 6级 | U31: 6级 | V31: 营地 | W31: 6级 | X31: 6级 | Y31: 空 | Z31: 空 | AA31: 空 | AB31: 空 | AC31: 空 | AD31: 空 | AE31: 空 | AF31: 空 | AG31: =AH31+AI31+AJ31 -> 0 | AK31: 是 | AL31: =MIN(AL30+6,18)-COUNTIF(I31:P31,"<>空")+COUNTIF(I31:P31,"历练")+COUNTIF(I31:P31,"营地")*2 -> 18 | AM31: =MIN(AM30+6,18)-COUNTIF(Q31:X31,"<>空")+COUNTIF(Q31:X31,"历练")+COUNTIF(Q31:X31,"营地")*2 -> 8 | AN31: =MIN(AN30+6,18)-COUNTIF(Y31:AF31,"<>空")+COUNTIF(Y31:AF31,"历练")+COUNTIF(Y31:AF31,"营地")*2 -> 18
A32: 45758 | B32: 1600 | D32: =(SUM(粮草!A32:X32)+AG32*10*IF(AK32="是",$BB$4,$BB$3)) -> 840 | E32: =SUM($B$4:B32)+SUM($C$4:C32)-SUM($D$4:D32) -> 7458 | F32: =SUM(经验!A32:X32) -> 1240 | G32: =SUM($F$4:F32)+SUM($H$4:H32) -> 20390 | H32: 0 | I32: 空 | J32: 空 | K32: 空 | L32: 空 | M32: 空 | N32: 空 | O32: 空 | P32: 空 | Q32: 6级 | R32: 6级 | S32: 6级 | T32: 6级 | U32: 大boss | V32: 空 | W32: 空 | X32: 空 | Y32: 空 | Z32: 空 | AA32: 空 | AB32: 空 | AC32: 空 | AD32: 空 | AE32: 空 | AF32: 空 | AG32: =AH32+AI32+AJ32 -> 0 | AK32: 是 | AL32: =MIN(AL31+6,18)-COUNTIF(I32:P32,"<>空")+COUNTIF(I32:P32,"历练")+COUNTIF(I32:P32,"营地")*2 -> 18 | AM32: =MIN(AM31+6,18)-COUNTIF(Q32:X32,"<>空")+COUNTIF(Q32:X32,"历练")+COUNTIF(Q32:X32,"营地")*2 -> 9 | AN32: =MIN(AN31+6,18)-COUNTIF(Y32:AF32,"<>空")+COUNTIF(Y32:AF32,"历练")+COUNTIF(Y32:AF32,"营地")*2 -> 18 | AO32: 地块统计 | AP32: 应占领 | AQ32: 缺少 | AR32: 粮草 | AS32: 分数
A33: 45759 | B33: 1600 | D33: =(SUM(粮草!A33:X33)+AG33*10*IF(AK33="是",$BB$4,$BB$3)) -> 864 | E33: =SUM($B$4:B33)+SUM($C$4:C33)-SUM($D$4:D33) -> 8194 | F33: =SUM(经验!A33:X33) -> 300 | G33: =SUM($F$4:F33)+SUM($H$4:H33) -> 20690 | H33: 0 | I33: 空 | J33: 空 | K33: 空 | L33: 空 | M33: 空 | N33: 空 | O33: 空 | P33: 空 | Q33: 空 | R33: 空 | S33: 空 | T33: 空 | U33: 空 | V33: 空 | W33: 空 | X33: 空 | Y33: 4级 | Z33: 4级 | AA33: 4级 | AB33: 4级 | AC33: 4级 | AD33: 4级 | AE33: 空 | AF33: 空 | AG33: =AH33+AI33+AJ33 -> 0 | AK33: 是 | AL33: =MIN(AL32+6,18)-COUNTIF(I33:P33,"<>空")+COUNTIF(I33:P33,"历练")+COUNTIF(I33:P33,"营地")*2 -> 18 | AM33: =MIN(AM32+6,18)-COUNTIF(Q33:X33,"<>空")+COUNTIF(Q33:X33,"历练")+COUNTIF(Q33:X33,"营地")*2 -> 15 | AN33: =MIN(AN32+6,18)-COUNTIF(Y33:AF33,"<>空")+COUNTIF(Y33:AF33,"历练")+COUNTIF(Y33:AF33,"营地")*2 -> 12 | AO33: 3级 | AP33: 209 | AQ33: =AP33-AV6 -> 120 | AR33: =AQ33*AP6*0.8 -> 16320 | AS33: =AQ33*AQ6 -> 5400
A34: 45760 | B34: 1600 | D34: =(SUM(粮草!A34:X34)+AG34*10*IF(AK34="是",$BB$4,$BB$3)) -> 864 | E34: =SUM($B$4:B34)+SUM($C$4:C34)-SUM($D$4:D34) -> 8930 | F34: =SUM(经验!A34:X34) -> 300 | G34: =SUM($F$4:F34)+SUM($H$4:H34) -> 20990 | H34: 0 | I34: 空 | J34: 空 | K34: 空 | L34: 空 | M34: 空 | N34: 空 | O34: 空 | P34: 空 | Q34: 空 | R34: 空 | S34: 空 | T34: 空 | U34: 空 | V34: 空 | W34: 空 | X34: 空 | Y34: 4级 | Z34: 4级 | AA34: 4级 | AB34: 4级 | AC34: 4级 | AD34: 4级 | AE34: 空 | AF34: 空 | AG34: =AH34+AI34+AJ34 -> 0 | AK34: 是 | AL34: =MIN(AL33+6,18)-COUNTIF(I34:P34,"<>空")+COUNTIF(I34:P34,"历练")+COUNTIF(I34:P34,"营地")*2 -> 18 | AM34: =MIN(AM33+6,18)-COUNTIF(Q34:X34,"<>空")+COUNTIF(Q34:X34,"历练")+COUNTIF(Q34:X34,"营地")*2 -> 18 | AN34: =MIN(AN33+6,18)-COUNTIF(Y34:AF34,"<>空")+COUNTIF(Y34:AF34,"历练")+COUNTIF(Y34:AF34,"营地")*2 -> 12 | AO34: 4级 | AP34: 276 | AQ34: =AP34-AV7 -> 233 | AR34: =AQ34*AP7*0.8 -> 33552 | AS34: =AQ34*AQ7 -> 11650
A35: 45761 | B35: 1600 | D35: =(SUM(粮草!A35:X35)+AG35*10*IF(AK35="是",$BB$4,$BB$3)) -> 704 | E35: =SUM($B$4:B35)+SUM($C$4:C35)-SUM($D$4:D35) -> 9826 | F35: =SUM(经验!A35:X35) -> 300 | G35: =SUM($F$4:F35)+SUM($H$4:H35) -> 21490 | H35: 200 | I35: 空 | J35: 空 | K35: 空 | L35: 空 | M35: 空 | N35: 空 | O35: 空 | P35: 空 | Q35: 空 | R35: 空 | S35: 空 | T35: 空 | U35: 空 | V35: 空 | W35: 空 | X35: 空 | Y35: 4级 | Z35: 4级 | AA35: 4级 | AB35: 4级 | AC35: 4级 | AD35: 4级 | AE35: 营地 | AF35: 空 | AG35: =AH35+AI35+AJ35 -> 0 | AK35: 是 | AL35: =MIN(AL34+6,18)-COUNTIF(I35:P35,"<>空")+COUNTIF(I35:P35,"历练")+COUNTIF(I35:P35,"营地")*2 -> 18 | AM35: =MIN(AM34+6,18)-COUNTIF(Q35:X35,"<>空")+COUNTIF(Q35:X35,"历练")+COUNTIF(Q35:X35,"营地")*2 -> 18 | AN35: =MIN(AN34+6,18)-COUNTIF(Y35:AF35,"<>空")+COUNTIF(Y35:AF35,"历练")+COUNTIF(Y35:AF35,"营地")*2 -> 13 | AO35: 5级 | AP35: 233 | AQ35: =AP35-AV8 -> 186 | AR35: =AQ35*AP8*0.8 -> 28272 | AS35: =AQ35*AQ8 -> 10230
A36: 45762 | B36: 1600 | D36: =(SUM(粮草!A36:X36)+AG36*10*IF(AK36="是",$BB$4,$BB$3)) -> 0 | E36: =SUM($B$4:B36)+SUM($C$4:C36)-SUM($D$4:D36) -> 11426 | F36: =SUM(经验!A36:X36) -> 0 | G36: =SUM($F$4:F36)+SUM($H$4:H36) -> 21590 | H36: 100 | I36: 空 | J36: 空 | K36: 空 | L36: 空 | M36: 空 | N36: 空 | O36: 空 | P36: 空 | Q36: 空 | R36: 空 | S36: 空 | T36: 空 | U36: 空 | V36: 空 | W36: 空 | X36: 空 | Y36: 空 | Z36: 空 | AA36: 空 | AB36: 空 | AC36: 空 | AD36: 空 | AE36: 空 | AF36: 空 | AG36: =AH36+AI36+AJ36 -> 0 | AK36: 是 | AL36: =MIN(AL35+6,18)-COUNTIF(I36:P36,"<>空")+COUNTIF(I36:P36,"历练")+COUNTIF(I36:P36,"营地")*2 -> 18 | AM36: =MIN(AM35+6,18)-COUNTIF(Q36:X36,"<>空")+COUNTIF(Q36:X36,"历练")+COUNTIF(Q36:X36,"营地")*2 -> 18 | AN36: =MIN(AN35+6,18)-COUNTIF(Y36:AF36,"<>空")+COUNTIF(Y36:AF36,"历练")+COUNTIF(Y36:AF36,"营地")*2 -> 18 | AO36: 6级 | AP36: 193 | AQ36: =AP36-AV9 -> 135 | AR36: =AQ36*AP9*0.8 -> 21600 | AS36: =AQ36*AQ9 -> 8100
A37: 45763 | B37: 1600 | D37: =(SUM(粮草!A37:X37)+AG37*10*IF(AK37="是",$BB$4,$BB$3)) -> 0 | E37: =SUM($B$4:B37)+SUM($C$4:C37)-SUM($D$4:D37) -> 13026 | F37: =SUM(经验!A37:X37) -> 0 | G37: =SUM($F$4:F37)+SUM($H$4:H37) -> 21790 | H37: 200 | I37: 空 | J37: 空 | K37: 空 | L37: 空 | M37: 空 | N37: 空 | O37: 空 | P37: 空 | Q37: 空 | R37: 空 | S37: 空 | T37: 空 | U37: 空 | V37: 空 | W37: 空 | X37: 空 | Y37: 空 | Z37: 空 | AA37: 空 | AB37: 空 | AC37: 空 | AD37: 空 | AE37: 空 | AF37: 空 | AG37: =AH37+AI37+AJ37 -> 0 | AK37: 是 | AL37: =MIN(AL36+6,18)-COUNTIF(I37:P37,"<>空")+COUNTIF(I37:P37,"历练")+COUNTIF(I37:P37,"营地")*2 -> 18 | AM37: =MIN(AM36+6,18)-COUNTIF(Q37:X37,"<>空")+COUNTIF(Q37:X37,"历练")+COUNTIF(Q37:X37,"营地")*2 -> 18 | AN37: =MIN(AN36+6,18)-COUNTIF(Y37:AF37,"<>空")+COUNTIF(Y37:AF37,"历练")+COUNTIF(Y37:AF37,"营地")*2 -> 18 | AO37: 商人 | AP37: 38 | AQ37: =AP37-AV17 -> 27 | AR37: =AQ37*AP17*0.8 -> 1080 | AS37: =AQ37*AQ17 -> 810
A38: 45764 | B38: 1600 | D38: =(SUM(粮草!A38:X38)+AG38*10*IF(AK38="是",$BB$4,$BB$3)) -> 0 | E38: =SUM($B$4:B38)+SUM($C$4:C38)-SUM($D$4:D38) -> 14626 | F38: =SUM(经验!A38:X38) -> 0 | G38: =SUM($F$4:F38)+SUM($H$4:H38) -> 21790 | H38: 0 | I38: 空 | J38: 空 | K38: 空 | L38: 空 | M38: 空 | N38: 空 | O38: 空 | P38: 空 | Q38: 空 | R38: 空 | S38: 空 | T38: 空 | U38: 空 | V38: 空 | W38: 空 | X38: 空 | Y38: 空 | Z38: 空 | AA38: 空 | AB38: 空 | AC38: 空 | AD38: 空 | AE38: 空 | AF38: 空 | AG38: =AH38+AI38+AJ38 -> 0 | AK38: 是 | AL38: =MIN(AL37+6,18)-COUNTIF(I38:P38,"<>空")+COUNTIF(I38:P38,"历练")+COUNTIF(I38:P38,"营地")*2 -> 18 | AM38: =MIN(AM37+6,18)-COUNTIF(Q38:X38,"<>空")+COUNTIF(Q38:X38,"历练")+COUNTIF(Q38:X38,"营地")*2 -> 18 | AN38: =MIN(AN37+6,18)-COUNTIF(Y38:AF38,"<>空")+COUNTIF(Y38:AF38,"历练")+COUNTIF(Y38:AF38,"营地")*2 -> 18 | AO38: 塔2 | AP38: 5 | AQ38: =AP38-AV11 -> 5 | AR38: =AQ38*AP11*0.8 -> 600 | AS38: =AQ38*AQ11 -> 200
A39: 45765 | B39: 1600 | D39: =(SUM(粮草!A39:X39)+AG39*10*IF(AK39="是",$BB$4,$BB$3)) -> 0 | E39: =SUM($B$4:B39)+SUM($C$4:C39)-SUM($D$4:D39) -> 16226 | F39: =SUM(经验!A39:X39) -> 0 | G39: =SUM($F$4:F39)+SUM($H$4:H39) -> 21790 | H39: 0 | I39: 空 | J39: 空 | K39: 空 | L39: 空 | M39: 空 | N39: 空 | O39: 空 | P39: 空 | Q39: 空 | R39: 空 | S39: 空 | T39: 空 | U39: 空 | V39: 空 | W39: 空 | X39: 空 | Y39: 空 | Z39: 空 | AA39: 空 | AB39: 空 | AC39: 空 | AD39: 空 | AE39: 空 | AF39: 空 | AG39: =AH39+AI39+AJ39 -> 0 | AK39: 是 | AL39: =MIN(AL38+6,18)-COUNTIF(I39:P39,"<>空")+COUNTIF(I39:P39,"历练")+COUNTIF(I39:P39,"营地")*2 -> 18 | AM39: =MIN(AM38+6,18)-COUNTIF(Q39:X39,"<>空")+COUNTIF(Q39:X39,"历练")+COUNTIF(Q39:X39,"营地")*2 -> 18 | AN39: =MIN(AN38+6,18)-COUNTIF(Y39:AF39,"<>空")+COUNTIF(Y39:AF39,"历练")+COUNTIF(Y39:AF39,"营地")*2 -> 18 | AO39: 塔3 | AP39: 6 | AQ39: =AP39-AV12 -> 2 | AR39: =AQ39*AP12*0.8 -> 240 | AS39: =AQ39*AQ12 -> 90
A40: 45766 | B40: 1600 | D40: =(SUM(粮草!A40:X40)+AG40*10*IF(AK40="是",$BB$4,$BB$3)) -> 0 | E40: =SUM($B$4:B40)+SUM($C$4:C40)-SUM($D$4:D40) -> 17826 | F40: =SUM(经验!A40:X40) -> 0 | G40: =SUM($F$4:F40)+SUM($H$4:H40) -> 21790 | H40: 0 | I40: 空 | J40: 空 | K40: 空 | L40: 空 | M40: 空 | N40: 空 | O40: 空 | P40: 空 | Q40: 空 | R40: 空 | S40: 空 | T40: 空 | U40: 空 | V40: 空 | W40: 空 | X40: 空 | Y40: 空 | Z40: 空 | AA40: 空 | AB40: 空 | AC40: 空 | AD40: 空 | AE40: 空 | AF40: 空 | AG40: =AH40+AI40+AJ40 -> 0 | AK40: 是 | AL40: =MIN(AL39+6,18)-COUNTIF(I40:P40,"<>空")+COUNTIF(I40:P40,"历练")+COUNTIF(I40:P40,"营地")*2 -> 18 | AM40: =MIN(AM39+6,18)-COUNTIF(Q40:X40,"<>空")+COUNTIF(Q40:X40,"历练")+COUNTIF(Q40:X40,"营地")*2 -> 18 | AN40: =MIN(AN39+6,18)-COUNTIF(Y40:AF40,"<>空")+COUNTIF(Y40:AF40,"历练")+COUNTIF(Y40:AF40,"营地")*2 -> 18 | AO40: 塔4 | AP40: 3 | AQ40: =AP40-AV13 -> 3 | AR40: =AQ40*AP13*0.8 -> 360 | AS40: =AQ40*AQ13 -> 150
...

Sheet 粮草
A2: 队伍一 风 | C2: 步数 | D2: =COUNTIF(A4:H94,"<>空") -> 728 | E2: (不算跳步和传送) | I2: 队伍二 雷 | K2: 步数 | L2: =COUNTIF(I4:P94,"<>空") -> 728 | M2: (不算跳步和传送) | Q2: 队伍三 | S2: 总步数 | T2: =COUNTIF(Q4:X94,"<>空") -> 728 | U2: (不算跳步和传送) | Y2: 粮草调整
A3: 1 | B3: 2 | C3: 3 | D3: 4 | E3: 5 | F3: 6 | G3: 7 | H3: 8 | I3: 1 | J3: 2 | K3: 3 | L3: 4 | M3: 5 | N3: 6 | O3: 7 | P3: 8 | Q3: 1 | R3: 2 | S3: 3 | T3: 4 | U3: 5 | V3: 6 | W3: 7 | X3: 8
A4: =IF(ISNUMBER(SEARCH("营",'19.02'!I4)),(-$Y4+50*IF('19.02'!$AK4="是",'19.02'!$BB$4,'19.02'!$BB$3)),(VLOOKUP('19.02'!I4,'19.02'!$AO$4:$AQ$55,2,FALSE))*IF('19.02'!$AK4="是",'19.02'!$BB$4,'19.02'!$BB$3)) -> 150 | B4: =IF(ISNUMBER(SEARCH("营",'19.02'!J4)),(-$Y4+50*IF('19.02'!$AK4="是",'19.02'!$BB$4,'19.02'!$BB$3)),(VLOOKUP('19.02'!J4,'19.02'!$AO$4:$AQ$55,2,FALSE))*IF('19.02'!$AK4="是",'19.02'!$BB$4,'19.02'!$BB$3)) -> 150 | C4: =IF(ISNUMBER(SEARCH("营",'19.02'!K4)),(-$Y4+50*IF('19.02'!$AK4="是",'19.02'!$BB$4,'19.02'!$BB$3)),(VLOOKUP('19.02'!K4,'19.02'!$AO$4:$AQ$55,2,FALSE))*IF('19.02'!$AK4="是",'19.02'!$BB$4,'19.02'!$BB$3)) -> 150 | D4: =IF(ISNUMBER(SEARCH("营",'19.02'!L4)),(-$Y4+50*IF('19.02'!$AK4="是",'19.02'!$BB$4,'19.02'!$BB$3)),(VLOOKUP('19.02'!L4,'19.02'!$AO$4:$AQ$55,2,FALSE))*IF('19.02'!$AK4="是",'19.02'!$BB$4,'19.02'!$BB$3)) -> 150 | E4: =IF(ISNUMBER(SEARCH("营",'19.02'!M4)),(-$Y4+50*IF('19.02'!$AK4="是",'19.02'!$BB$4,'19.02'!$BB$3)),(VLOOKUP('19.02'!M4,'19.02'!$AO$4:$AQ$55,2,FALSE))*IF('19.02'!$AK4="是",'19.02'!$BB$4,'19.02'!$BB$3)) -> 150 | F4: =IF(ISNUMBER(SEARCH("营",'19.02'!N4)),(-$Y4+50*IF('19.02'!$AK4="是",'19.02'!$BB$4,'19.02'!$BB$3)),(VLOOKUP('19.02'!N4,'19.02'!$AO$4:$AQ$55,2,FALSE))*IF('19.02'!$AK4="是",'19.02'!$BB$4,'19.02'!$BB$3)) -> 150 | G4: =IF(ISNUMBER(SEARCH("营",'19.02'!O4)),(-$Y4+50*IF('19.02'!$AK4="是",'19.02'!$BB$4,'19.02'!$BB$3)),(VLOOKUP('19.02'!O4,'19.02'!$AO$4:$AQ$55,2,FALSE))*IF('19.02'!$AK4="是",'19.02'!$BB$4,'19.02'!$BB$3)) -> 0 | H4: =IF(ISNUMBER(SEARCH("营",'19.02'!P4)),(-$Y4+50*IF('19.02'!$AK4="是",'19.02'!$BB$4,'19.02'!$BB$3)),(VLOOKUP('19.02'!P4,'19.02'!$AO$4:$AQ$55,2,FALSE))*IF('19.02'!$AK4="是",'19.02'!$BB$4,'19.02'!$BB$3)) -> 0 | ... X4: =IF(ISNUMBER(SEARCH("营",'19.02'!AF4)),(-$Y4+50*IF('19.02'!$AK4="是",'19.02'!$BB$4,'19.02'!$BB$3)),(VLOOKUP('19.02'!AF4,'19.02'!$AO$4:$AQ$55,2,FALSE))*IF('19.02'!$AK4="是",'19.02'!$BB$4,'19.02'!$BB$3)) -> 0 | Y4: 300 | Z4: 45730
A5: =IF(ISNUMBER(SEARCH("营",'19.02'!I5)),(-$Y5+50*IF('19.02'!$AK5="是",'19.02'!$BB$4,'19.02'!$BB$3)),(VLOOKUP('19.02'!I5,'19.02'!$AO$4:$AQ$55,2,FALSE))*IF('19.02'!$AK5="是",'19.02'!$BB$4,'19.02'!$BB$3)) -> 0 | B5: =IF(ISNUMBER(SEARCH("营",'19.02'!J5)),(-$Y5+50*IF('19.02'!$AK5="是",'19.02'!$BB$4,'19.02'!$BB$3)),(VLOOKUP('19.02'!J5,'19.02'!$AO$4:$AQ$55,2,FALSE))*IF('19.02'!$AK5="是",'19.02'!$BB$4,'19.02'!$BB$3)) -> 0 | C5: =IF(ISNUMBER(SEARCH("营",'19.02'!K5)),(-$Y5+50*IF('19.02'!$AK5="是",'19.02'!$BB$4,'19.02'!$BB$3)),(VLOOKUP('19.02'!K5,'19.02'!$AO$4:$AQ$55,2,FALSE))*IF('19.02'!$AK5="是",'19.02'!$BB$4,'19.02'!$BB$3)) -> 0 | D5: =IF(ISNUMBER(SEARCH("营",'19.02'!L5)),(-$Y5+50*IF('19.02'!$AK5="是",'19.02'!$BB$4,'19.02'!$BB$3)),(VLOOKUP('19.02'!L5,'19.02'!$AO$4:$AQ$55,2,FALSE))*IF('19.02'!$AK5="是",'19.02'!$BB$4,'19.02'!$BB$3)) -> 0 | E5: =IF(ISNUMBER(SEARCH("营",'19.02'!M5)),(-$Y5+50*IF('19.02'!$AK5="是",'19.02'!$BB$4,'19.02'!$BB$3)),(VLOOKUP('19.02'!M5,'19.02'!$AO$4:$AQ$55,2,FALSE))*IF('19.02'!$AK5="是",'19.02'!$BB$4,'19.02'!$BB$3)) -> 0 | F5: =IF(ISNUMBER(SEARCH("营",'19.02'!N5)),(-$Y5+50*IF('19.02'!$AK5="是",'19.02'!$BB$4,'19.02'!$BB$3)),(VLOOKUP('19.02'!N5,'19.02'!$AO$4:$AQ$55,2,FALSE))*IF('19.02'!$AK5="是",'19.02'!$BB$4,'19.02'!$BB$3)) -> 0 | G5: =IF(ISNUMBER(SEARCH("营",'19.02'!O5)),(-$Y5+50*IF('19.02'!$AK5="是",'19.02'!$BB$4,'19.02'!$BB$3)),(VLOOKUP('19.02'!O5,'19.02'!$AO$4:$AQ$55,2,FALSE))*IF('19.02'!$AK5="是",'19.02'!$BB$4,'19.02'!$BB$3)) -> 0 | H5: =IF(ISNUMBER(SEARCH("营",'19.02'!P5)),(-$Y5+50*IF('19.02'!$AK5="是",'19.02'!$BB$4,'19.02'!$BB$3)),(VLOOKUP('19.02'!P5,'19.02'!$AO$4:$AQ$55,2,FALSE))*IF('19.02'!$AK5="是",'19.02'!$BB$4,'19.02'!$BB$3)) -> 0 | ... X5: =IF(ISNUMBER(SEARCH("营",'19.02'!AF5)),(-$Y5+50*IF('19.02'!$AK5="是",'19.02'!$BB$4,'19.02'!$BB$3)),(VLOOKUP('19.02'!AF5,'19.02'!$AO$4:$AQ$55,2,FALSE))*IF('19.02'!$AK5="是",'19.02'!$BB$4,'19.02'!$BB$3)) -> 0 | Y5: 300 | Z5: 45731
A6: =IF(ISNUMBER(SEARCH("营",'19.02'!I6)),(-$Y6+50*IF('19.02'!$AK6="是",'19.02'!$BB$4,'19.02'!$BB$3)),(VLOOKUP('19.02'!I6,'19.02'!$AO$4:$AQ$55,2,FALSE))*IF('19.02'!$AK6="是",'19.02'!$BB$4,'19.02'!$BB$3)) -> 0 | B6: =IF(ISNUMBER(SEARCH("营",'19.02'!J6)),(-$Y6+50*IF('19.02'!$AK6="是",'19.02'!$BB$4,'19.02'!$BB$3)),(VLOOKUP('19.02'!J6,'19.02'!$AO$4:$AQ$55,2,FALSE))*IF('19.02'!$AK6="是",'19.02'!$BB$4,'19.02'!$BB$3)) -> 0 | C6: =IF(ISNUMBER(SEARCH("营",'19.02'!K6)),(-$Y6+50*IF('19.02'!$AK6="是",'19.02'!$BB$4,'19.02'!$BB$3)),(VLOOKUP('19.02'!K6,'19.02'!$AO$4:$AQ$55,2,FALSE))*IF('19.02'!$AK6="是",'19.02'!$BB$4,'19.02'!$BB$3)) -> 0 | D6: =IF(ISNUMBER(SEARCH("营",'19.02'!L6)),(-$Y6+50*IF('19.02'!$AK6="是",'19.02'!$BB$4,'19.02'!$BB$3)),(VLOOKUP('19.02'!L6,'19.02'!$AO$4:$AQ$55,2,FALSE))*IF('19.02'!$AK6="是",'19.02'!$BB$4,'19.02'!$BB$3)) -> 0 | E6: =IF(ISNUMBER(SEARCH("营",'19.02'!M6)),(-$Y6+50*IF('19.02'!$AK6="是",'19.02'!$BB$4,'19.02'!$BB$3)),(VLOOKUP('19.02'!M6,'19.02'!$AO$4:$AQ$55,2,FALSE))*IF('19.02'!$AK6="是",'19.02'!$BB$4,'19.02'!$BB$3)) -> 0 | F6: =IF(ISNUMBER(SEARCH("营",'19.02'!N6)),(-$Y6+50*IF('19.02'!$AK6="是",'19.02'!$BB$4,'19.02'!$BB$3)),(VLOOKUP('19.02'!N6,'19.02'!$AO$4:$AQ$55,2,FALSE))*IF('19.02'!$AK6="是",'19.02'!$BB$4,'19.02'!$BB$3)) -> 0 | G6: =IF(ISNUMBER(SEARCH("营",'19.02'!O6)),(-$Y6+50*IF('19.02'!$AK6="是",'19.02'!$BB$4,'19.02'!$BB$3)),(VLOOKUP('19.02'!O6,'19.02'!$AO$4:$AQ$55,2,FALSE))*IF('19.02'!$AK6="是",'19.02'!$BB$4,'19.02'!$BB$3)) -> 0 | H6: =IF(ISNUMBER(SEARCH("营",'19.02'!P6)),(-$Y6+50*IF('19.02'!$AK6="是",'19.02'!$BB$4,'19.02'!$BB$3)),(VLOOKUP('19.02'!P6,'19.02'!$AO$4:$AQ$55,2,FALSE))*IF('19.02'!$AK6="是",'19.02'!$BB$4,'19.02'!$BB$3)) -> 0 | ... X6: =IF(ISNUMBER(SEARCH("营",'19.02'!AF6)),(-$Y6+50*IF('19.02'!$AK6="是",'19.02'!$BB$4,'19.02'!$BB$3)),(VLOOKUP('19.02'!AF6,'19.02'!$AO$4:$AQ$55,2,FALSE))*IF('19.02'!$AK6="是",'19.02'!$BB$4,'19.02'!$BB$3)) -> 0 | Y6: 300 | Z6: 45732
A7: =IF(ISNUMBER(SEARCH("营",'19.02'!I7)),(-$Y7+50*IF('19.02'!$AK7="是",'19.02'!$BB$4,'19.02'!$BB$3)),(VLOOKUP('19.02'!I7,'19.02'!$AO$4:$AQ$55,2,FALSE))*IF('19.02'!$AK7="是",'19.02'!$BB$4,'19.02'!$BB$3)) -> 0 | B7: =IF(ISNUMBER(SEARCH("营",'19.02'!J7)),(-$Y7+50*IF('19.02'!$AK7="是",'19.02'!$BB$4,'19.02'!$BB$3)),(VLOOKUP('19.02'!J7,'19.02'!$AO$4:$AQ$55,2,FALSE))*IF('19.02'!$AK7="是",'19.02'!$BB$4,'19.02'!$BB$3)) -> 0 | C7: =IF(ISNUMBER(SEARCH("营",'19.02'!K7)),(-$Y7+50*IF('19.02'!$AK7="是",'19.02'!$BB$4,'19.02'!$BB$3)),(VLOOKUP('19.02'!K7,'19.02'!$AO$4:$AQ$55,2,FALSE))*IF('19.02'!$AK7="是",'19.02'!$BB$4,'19.02'!$BB$3)) -> 0 | D7: =IF(ISNUMBER(SEARCH("营",'19.02'!L7)),(-$Y7+50*IF('19.02'!$AK7="是",'19.02'!$BB$4,'19.02'!$BB$3)),(VLOOKUP('19.02'!L7,'19.02'!$AO$4:$AQ$55,2,FALSE))*IF('19.02'!$AK7="是",'19.02'!$BB$4,'19.02'!$BB$3)) -> 0 | E7: =IF(ISNUMBER(SEARCH("营",'19.02'!M7)),(-$Y7+50*IF('19.02'!$AK7="是",'19.02'!$BB$4,'19.02'!$BB$3)),(VLOOKUP('19.02'!M7,'19.02'!$AO$4:$AQ$55,2,FALSE))*IF('19.02'!$AK7="是",'19.02'!$BB$4,'19.02'!$BB$3)) -> 0 | F7: =IF(ISNUMBER(SEARCH("营",'19.02'!N7)),(-$Y7+50*IF('19.02'!$AK7="是",'19.02'!$BB$4,'19.02'!$BB$3)),(VLOOKUP('19.02'!N7,'19.02'!$AO$4:$AQ$55,2,FALSE))*IF('19.02'!$AK7="是",'19.02'!$BB$4,'19.02'!$BB$3)) -> 0 | G7: =IF(ISNUMBER(SEARCH("营",'19.02'!O7)),(-$Y7+50*IF('19.02'!$AK7="是",'19.02'!$BB$4,'19.02'!$BB$3)),(VLOOKUP('19.02'!O7,'19.02'!$AO$4:$AQ$55,2,FALSE))*IF('19.02'!$AK7="是",'19.02'!$BB$4,'19.02'!$BB$3)) -> 0 | H7: =IF(ISNUMBER(SEARCH("营",'19.02'!P7)),(-$Y7+50*IF('19.02'!$AK7="是",'19.02'!$BB$4,'19.02'!$BB$3)),(VLOOKUP('19.02'!P7,'19.02'!$AO$4:$AQ$55,2,FALSE))*IF('19.02'!$AK7="是",'19.02'!$BB$4,'19.02'!$BB$3)) -> 0 | ... X7: =IF(ISNUMBER(SEARCH("营",'19.02'!AF7)),(-$Y7+50*IF('19.02'!$AK7="是",'19.02'!$BB$4,'19.02'!$BB$3)),(VLOOKUP('19.02'!AF7,'19.02'!$AO$4:$AQ$55,2,FALSE))*IF('19.02'!$AK7="是",'19.02'!$BB$4,'19.02'!$BB$3)) -> 0 | Y7: 300 | Z7: 45733
A8: =IF(ISNUMBER(SEARCH("营",'19.02'!I8)),(-$Y8+50*IF('19.02'!$AK8="是",'19.02'!$BB$4,'19.02'!$BB$3)),(VLOOKUP('19.02'!I8,'19.02'!$AO$4:$AQ$55,2,FALSE))*IF('19.02'!$AK8="是",'19.02'!$BB$4,'19.02'!$BB$3)) -> 0 | B8: =IF(ISNUMBER(SEARCH("营",'19.02'!J8)),(-$Y8+50*IF('19.02'!$AK8="是",'19.02'!$BB$4,'19.02'!$BB$3)),(VLOOKUP('19.02'!J8,'19.02'!$AO$4:$AQ$55,2,FALSE))*IF('19.02'!$AK8="是",'19.02'!$BB$4,'19.02'!$BB$3)) -> 0 | C8: =IF(ISNUMBER(SEARCH("营",'19.02'!K8)),(-$Y8+50*IF('19.02'!$AK8="是",'19.02'!$BB$4,'19.02'!$BB$3)),(VLOOKUP('19.02'!K8,'19.02'!$AO$4:$AQ$55,2,FALSE))*IF('19.02'!$AK8="是",'19.02'!$BB$4,'19.02'!$BB$3)) -> 0 | D8: =IF(ISNUMBER(SEARCH("营",'19.02'!L8)),(-$Y8+50*IF('19.02'!$AK8="是",'19.02'!$BB$4,'19.02'!$BB$3)),(VLOOKUP('19.02'!L8,'19.02'!$AO$4:$AQ$55,2,FALSE))*IF('19.02'!$AK8="是",'19.02'!$BB$4,'19.02'!$BB$3)) -> 0 | E8: =IF(ISNUMBER(SEARCH("营",'19.02'!M8)),(-$Y8+50*IF('19.02'!$AK8="是",'19.02'!$BB$4,'19.02'!$BB$3)),(VLOOKUP('19.02'!M8,'19.02'!$AO$4:$AQ$55,2,FALSE))*IF('19.02'!$AK8="是",'19.02'!$BB$4,'19.02'!$BB$3)) -> 0 | F8: =IF(ISNUMBER(SEARCH("营",'19.02'!N8)),(-$Y8+50*IF('19.02'!$AK8="是",'19.02'!$BB$4,'19.02'!$BB$3)),(VLOOKUP('19.02'!N8,'19.02'!$AO$4:$AQ$55,2,FALSE))*IF('19.02'!$AK8="是",'19.02'!$BB$4,'19.02'!$BB$3)) -> 0 | G8: =IF(ISNUMBER(SEARCH("营",'19.02'!O8)),(-$Y8+50*IF('19.02'!$AK8="是",'19.02'!$BB$4,'19.02'!$BB$3)),(VLOOKUP('19.02'!O8,'19.02'!$AO$4:$AQ$55,2,FALSE))*IF('19.02'!$AK8="是",'19.02'!$BB$4,'19.02'!$BB$3)) -> 0 | H8: =IF(ISNUMBER(SEARCH("营",'19.02'!P8)),(-$Y8+50*IF('19.02'!$AK8="是",'19.02'!$BB$4,'19.02'!$BB$3)),(VLOOKUP('19.02'!P8,'19.02'!$AO$4:$AQ$55,2,FALSE))*IF('19.02'!$AK8="是",'19.02'!$BB$4,'19.02'!$BB$3)) -> 0 | ... X8: =IF(ISNUMBER(SEARCH("营",'19.02'!AF8)),(-$Y8+50*IF('19.02'!$AK8="是",'19.02'!$BB$4,'19.02'!$BB$3)),(VLOOKUP('19.02'!AF8,'19.02'!$AO$4:$AQ$55,2,FALSE))*IF('19.02'!$AK8="是",'19.02'!$BB$4,'19.02'!$BB$3)) -> 0 | Y8: 300 | Z8: 45734
A9: =IF(ISNUMBER(SEARCH("营",'19.02'!I9)),(-$Y9+50*IF('19.02'!$AK9="是",'19.02'!$BB$4,'19.02'!$BB$3)),(VLOOKUP('19.02'!I9,'19.02'!$AO$4:$AQ$55,2,FALSE))*IF('19.02'!$AK9="是",'19.02'!$BB$4,'19.02'!$BB$3)) -> 0 | B9: =IF(ISNUMBER(SEARCH("营",'19.02'!J9)),(-$Y9+50*IF('19.02'!$AK9="是",'19.02'!$BB$4,'19.02'!$BB$3)),(VLOOKUP('19.02'!J9,'19.02'!$AO$4:$AQ$55,2,FALSE))*IF('19.02'!$AK9="是",'19.02'!$BB$4,'19.02'!$BB$3)) -> 0 | C9: =IF(ISNUMBER(SEARCH("营",'19.02'!K9)),(-$Y9+50*IF('19.02'!$AK9="是",'19.02'!$BB$4,'19.02'!$BB$3)),(VLOOKUP('19.02'!K9,'19.02'!$AO$4:$AQ$55,2,FALSE))*IF('19.02'!$AK9="是",'19.02'!$BB$4,'19.02'!$BB$3)) -> 0 | D9: =IF(ISNUMBER(SEARCH("营",'19.02'!L9)),(-$Y9+50*IF('19.02'!$AK9="是",'19.02'!$BB$4,'19.02'!$BB$3)),(VLOOKUP('19.02'!L9,'19.02'!$AO$4:$AQ$55,2,FALSE))*IF('19.02'!$AK9="是",'19.02'!$BB$4,'19.02'!$BB$3)) -> 0 | E9: =IF(ISNUMBER(SEARCH("营",'19.02'!M9)),(-$Y9+50*IF('19.02'!$AK9="是",'19.02'!$BB$4,'19.02'!$BB$3)),(VLOOKUP('19.02'!M9,'19.02'!$AO$4:$AQ$55,2,FALSE))*IF('19.02'!$AK9="是",'19.02'!$BB$4,'19.02'!$BB$3)) -> 0 | F9: =IF(ISNUMBER(SEARCH("营",'19.02'!N9)),(-$Y9+50*IF('19.02'!$AK9="是",'19.02'!$BB$4,'19.02'!$BB$3)),(VLOOKUP('19.02'!N9,'19.02'!$AO$4:$AQ$55,2,FALSE))*IF('19.02'!$AK9="是",'19.02'!$BB$4,'19.02'!$BB$3)) -> 0 | G9: =IF(ISNUMBER(SEARCH("营",'19.02'!O9)),(-$Y9+50*IF('19.02'!$AK9="是",'19.02'!$BB$4,'19.02'!$BB$3)),(VLOOKUP('19.02'!O9,'19.02'!$AO$4:$AQ$55,2,FALSE))*IF('19.02'!$AK9="是",'19.02'!$BB$4,'19.02'!$BB$3)) -> 0 | H9: =IF(ISNUMBER(SEARCH("营",'19.02'!P9)),(-$Y9+50*IF('19.02'!$AK9="是",'19.02'!$BB$4,'19.02'!$BB$3)),(VLOOKUP('19.02'!P9,'19.02'!$AO$4:$AQ$55,2,FALSE))*IF('19.02'!$AK9="是",'19.02'!$BB$4,'19.02'!$BB$3)) -> 0 | ... X9: =IF(ISNUMBER(SEARCH("营",'19.02'!AF9)),(-$Y9+50*IF('19.02'!$AK9="是",'19.02'!$BB$4,'19.02'!$BB$3)),(VLOOKUP('19.02'!AF9,'19.02'!$AO$4:$AQ$55,2,FALSE))*IF('19.02'!$AK9="是",'19.02'!$BB$4,'19.02'!$BB$3)) -> 0 | Y9: 300 | Z9: 45735
A10: =IF(ISNUMBER(SEARCH("营",'19.02'!I10)),(-$Y10+50*IF('19.02'!$AK10="是",'19.02'!$BB$4,'19.02'!$BB$3)),(VLOOKUP('19.02'!I10,'19.02'!$AO$4:$AQ$55,2,FALSE))*IF('19.02'!$AK10="是",'19.02'!$BB$4,'19.02'!$BB$3)) -> 0 | B10: =IF(ISNUMBER(SEARCH("营",'19.02'!J10)),(-$Y10+50*IF('19.02'!$AK10="是",'19.02'!$BB$4,'19.02'!$BB$3)),(VLOOKUP('19.02'!J10,'19.02'!$AO$4:$AQ$55,2,FALSE))*IF('19.02'!$AK10="是",'19.02'!$BB$4,'19.02'!$BB$3)) -> 0 | C10: =IF(ISNUMBER(SEARCH("营",'19.02'!K10)),(-$Y10+50*IF('19.02'!$AK10="是",'19.02'!$BB$4,'19.02'!$BB$3)),(VLOOKUP('19.02'!K10,'19.02'!$AO$4:$AQ$55,2,FALSE))*IF('19.02'!$AK10="是",'19.02'!$BB$4,'19.02'!$BB$3)) -> 0 | D10: =IF(ISNUMBER(SEARCH("营",'19.02'!L10)),(-$Y10+50*IF('19.02'!$AK10="是",'19.02'!$BB$4,'19.02'!$BB$3)),(VLOOKUP('19.02'!L10,'19.02'!$AO$4:$AQ$55,2,FALSE))*IF('19.02'!$AK10="是",'19.02'!$BB$4,'19.02'!$BB$3)) -> 0 | E10: =IF(ISNUMBER(SEARCH("营",'19.02'!M10)),(-$Y10+50*IF('19.02'!$AK10="是",'19.02'!$BB$4,'19.02'!$BB$3)),(VLOOKUP('19.02'!M10,'19.02'!$AO$4:$AQ$55,2,FALSE))*IF('19.02'!$AK10="是",'19.02'!$BB$4,'19.02'!$BB$3)) -> 0 | F10: =IF(ISNUMBER(SEARCH("营",'19.02'!N10)),(-$Y10+50*IF('19.02'!$AK10="是",'19.02'!$BB$4,'19.02'!$BB$3)),(VLOOKUP('19.02'!N10,'19.02'!$AO$4:$AQ$55,2,FALSE))*IF('19.02'!$AK10="是",'19.02'!$BB$4,'19.02'!$BB$3)) -> 0 | G10: =IF(ISNUMBER(SEARCH("营",'19.02'!O10)),(-$Y10+50*IF('19.02'!$AK10="是",'19.02'!$BB$4,'19.02'!$BB$3)),(VLOOKUP('19.02'!O10,'19.02'!$AO$4:$AQ$55,2,FALSE))*IF('19.02'!$AK10="是",'19.02'!$BB$4,'19.02'!$BB$3)) -> 0 | H10: =IF(ISNUMBER(SEARCH("营",'19.02'!P10)),(-$Y10+50*IF('19.02'!$AK10="是",'19.02'!$BB$4,'19.02'!$BB$3)),(VLOOKUP('19.02'!P10,'19.02'!$AO$4:$AQ$55,2,FALSE))*IF('19.02'!$AK10="是",'19.02'!$BB$4,'19.02'!$BB$3)) -> 0 | ... X10: =IF(ISNUMBER(SEARCH("营",'19.02'!AF10)),(-$Y10+50*IF('19.02'!$AK10="是",'19.02'!$BB$4,'19.02'!$BB$3)),(VLOOKUP('19.02'!AF10,'19.02'!$AO$4:$AQ$55,2,FALSE))*IF('19.02'!$AK10="是",'19.02'!$BB$4,'19.02'!$BB$3)) -> 0 | Y10: 300 | Z10: 45736
A11: =IF(ISNUMBER(SEARCH("营",'19.02'!I11)),(-$Y11+50*IF('19.02'!$AK11="是",'19.02'!$BB$4,'19.02'!$BB$3)),(VLOOKUP('19.02'!I11,'19.02'!$AO$4:$AQ$55,2,FALSE))*IF('19.02'!$AK11="是",'19.02'!$BB$4,'19.02'!$BB$3)) -> 0 | B11: =IF(ISNUMBER(SEARCH("营",'19.02'!J11)),(-$Y11+50*IF('19.02'!$AK11="是",'19.02'!$BB$4,'19.02'!$BB$3)),(VLOOKUP('19.02'!J11,'19.02'!$AO$4:$AQ$55,2,FALSE))*IF('19.02'!$AK11="是",'19.02'!$BB$4,'19.02'!$BB$3)) -> 0 | C11: =IF(ISNUMBER(SEARCH("营",'19.02'!K11)),(-$Y11+50*IF('19.02'!$AK11="是",'19.02'!$BB$4,'19.02'!$BB$3)),(VLOOKUP('19.02'!K11,'19.02'!$AO$4:$AQ$55,2,FALSE))*IF('19.02'!$AK11="是",'19.02'!$BB$4,'19.02'!$BB$3)) -> 0 | D11: =IF(ISNUMBER(SEARCH("营",'19.02'!L11)),(-$Y11+50*IF('19.02'!$AK11="是",'19.02'!$BB$4,'19.02'!$BB$3)),(VLOOKUP('19.02'!L11,'19.02'!$AO$4:$AQ$55,2,FALSE))*IF('19.02'!$AK11="是",'19.02'!$BB$4,'19.02'!$BB$3)) -> 0 | E11: =IF(ISNUMBER(SEARCH("营",'19.02'!M11)),(-$Y11+50*IF('19.02'!$AK11="是",'19.02'!$BB$4,'19.02'!$BB$3)),(VLOOKUP('19.02'!M11,'19.02'!$AO$4:$AQ$55,2,FALSE))*IF('19.02'!$AK11="是",'19.02'!$BB$4,'19.02'!$BB$3)) -> 0 | F11: =IF(ISNUMBER(SEARCH("营",'19.02'!N11)),(-$Y11+50*IF('19.02'!$AK11="是",'19.02'!$BB$4,'19.02'!$BB$3)),(VLOOKUP('19.02'!N11,'19.02'!$AO$4:$AQ$55,2,FALSE))*IF('19.02'!$AK11="是",'19.02'!$BB$4,'19.02'!$BB$3)) -> 0 | G11: =IF(ISNUMBER(SEARCH("营",'19.02'!O11)),(-$Y11+50*IF('19.02'!$AK11="是",'19.02'!$BB$4,'19.02'!$BB$3)),(VLOOKUP('19.02'!O11,'19.02'!$AO$4:$AQ$55,2,FALSE))*IF('19.02'!$AK11="是",'19.02'!$BB$4,'19.02'!$BB$3)) -> 0 | H11: =IF(ISNUMBER(SEARCH("营",'19.02'!P11)),(-$Y11+50*IF('19.02'!$AK11="是",'19.02'!$BB$4,'19.02'!$BB$3)),(VLOOKUP('19.02'!P11,'19.02'!$AO$4:$AQ$55,2,FALSE))*IF('19.02'!$AK11="是",'19.02'!$BB$4,'19.02'!$BB$3)) -> 0 | ... X11: =IF(ISNUMBER(SEARCH("营",'19.02'!AF11)),(-$Y11+50*IF('19.02'!$AK11="是",'19.02'!$BB$4,'19.02'!$BB$3)),(VLOOKUP('19.02'!AF11,'19.02'!$AO$4:$AQ$55,2,FALSE))*IF('19.02'!$AK11="是",'19.02'!$BB$4,'19.02'!$BB$3)) -> 0 | Y11: 300 | Z11: 45737
A12: =IF(ISNUMBER(SEARCH("营",'19.02'!I12)),(-$Y12+50*IF('19.02'!$AK12="是",'19.02'!$BB$4,'19.02'!$BB$3)),(VLOOKUP('19.02'!I12,'19.02'!$AO$4:$AQ$55,2,FALSE))*IF('19.02'!$AK12="是",'19.02'!$BB$4,'19.02'!$BB$3)) -> 0 | B12: =IF(ISNUMBER(SEARCH("营",'19.02'!J12)),(-$Y12+50*IF('19.02'!$AK12="是",'19.02'!$BB$4,'19.02'!$BB$3)),(VLOOKUP('19.02'!J12,'19.02'!$AO$4:$AQ$55,2,FALSE))*IF('19.02'!$AK12="是",'19.02'!$BB$4,'19.02'!$BB$3)) -> 0 | C12: =IF(ISNUMBER(SEARCH("营",'19.02'!K12)),(-$Y12+50*IF('19.02'!$AK12="是",'19.02'!$BB$4,'19.02'!$BB$3)),(VLOOKUP('19.02'!K12,'19.02'!$AO$4:$AQ$55,2,FALSE))*IF('19.02'!$AK12="是",'19.02'!$BB$4,'19.02'!$BB$3)) -> 0 | D12: =IF(ISNUMBER(SEARCH("营",'19.02'!L12)),(-$Y12+50*IF('19.02'!$AK12="是",'19.02'!$BB$4,'19.02'!$BB$3)),(VLOOKUP('19.02'!L12,'19.02'!$AO$4:$AQ$55,2,FALSE))*IF('19.02'!$AK12="是",'19.02'!$BB$4,'19.02'!$BB$3)) -> 0 | E12: =IF(ISNUMBER(SEARCH("营",'19.02'!M12)),(-$Y12+50*IF('19.02'!$AK12="是",'19.02'!$BB$4,'19.02'!$BB$3)),(VLOOKUP('19.02'!M12,'19.02'!$AO$4:$AQ$55,2,FALSE))*IF('19.02'!$AK12="是",'19.02'!$BB$4,'19.02'!$BB$3)) -> 0 | F12: =IF(ISNUMBER(SEARCH("营",'19.02'!N12)),(-$Y12+50*IF('19.02'!$AK12="是",'19.02'!$BB$4,'19.02'!$BB$3)),(VLOOKUP('19.02'!N12,'19.02'!$AO$4:$AQ$55,2,FALSE))*IF('19.02'!$AK12="是",'19.02'!$BB$4,'19.02'!$BB$3)) -> 0 | G12: =IF(ISNUMBER(SEARCH("营",'19.02'!O12)),(-$Y12+50*IF('19.02'!$AK12="是",'19.02'!$BB$4,'19.02'!$BB$3)),(VLOOKUP('19.02'!O12,'19.02'!$AO$4:$AQ$55,2,FALSE))*IF('19.02'!$AK12="是",'19.02'!$BB$4,'19.02'!$BB$3)) -> 0 | H12: =IF(ISNUMBER(SEARCH("营",'19.02'!P12)),(-$Y12+50*IF('19.02'!$AK12="是",'19.02'!$BB$4,'19.02'!$BB$3)),(VLOOKUP('19.02'!P12,'19.02'!$AO$4:$AQ$55,2,FALSE))*IF('19.02'!$AK12="是",'19.02'!$BB$4,'19.02'!$BB$3)) -> 0 | ... X12: =IF(ISNUMBER(SEARCH("营",'19.02'!AF12)),(-$Y12+50*IF('19.02'!$AK12="是",'19.02'!$BB$4,'19.02'!$BB$3)),(VLOOKUP('19.02'!AF12,'19.02'!$AO$4:$AQ$55,2,FALSE))*IF('19.02'!$AK12="是",'19.02'!$BB$4,'19.02'!$BB$3)) -> 0 | Y12: 300 | Z12: 45738
A13: =IF(ISNUMBER(SEARCH("营",'19.02'!I13)),(-$Y13+50*IF('19.02'!$AK13="是",'19.02'!$BB$4,'19.02'!$BB$3)),(VLOOKUP('19.02'!I13,'19.02'!$AO$4:$AQ$55,2,FALSE))*IF('19.02'!$AK13="是",'19.02'!$BB$4,'19.02'!$BB$3)) -> 0 | B13: =IF(ISNUMBER(SEARCH("营",'19.02'!J13)),(-$Y13+50*IF('19.02'!$AK13="是",'19.02'!$BB$4,'19.02'!$BB$3)),(VLOOKUP('19.02'!J13,'19.02'!$AO$4:$AQ$55,2,FALSE))*IF('19.02'!$AK13="是",'19.02'!$BB$4,'19.02'!$BB$3)) -> 0 | C13: =IF(ISNUMBER(SEARCH("营",'19.02'!K13)),(-$Y13+50*IF('19.02'!$AK13="是",'19.02'!$BB$4,'19.02'!$BB$3)),(VLOOKUP('19.02'!K13,'19.02'!$AO$4:$AQ$55,2,FALSE))*IF('19.02'!$AK13="是",'19.02'!$BB$4,'19.02'!$BB$3)) -> 0 | D13: =IF(ISNUMBER(SEARCH("营",'19.02'!L13)),(-$Y13+50*IF('19.02'!$AK13="是",'19.02'!$BB$4,'19.02'!$BB$3)),(VLOOKUP('19.02'!L13,'19.02'!$AO$4:$AQ$55,2,FALSE))*IF('19.02'!$AK13="是",'19.02'!$BB$4,'19.02'!$BB$3)) -> 0 | E13: =IF(ISNUMBER(SEARCH("营",'19.02'!M13)),(-$Y13+50*IF('19.02'!$AK13="是",'19.02'!$BB$4,'19.02'!$BB$3)),(VLOOKUP('19.02'!M13,'19.02'!$AO$4:$AQ$55,2,FALSE))*IF('19.02'!$AK13="是",'19.02'!$BB$4,'19.02'!$BB$3)) -> 0 | F13: =IF(ISNUMBER(SEARCH("营",'19.02'!N13)),(-$Y13+50*IF('19.02'!$AK13="是",'19.02'!$BB$4,'19.02'!$BB$3)),(VLOOKUP('19.02'!N13,'19.02'!$AO$4:$AQ$55,2,FALSE))*IF('19.02'!$AK13="是",'19.02'!$BB$4,'19.02'!$BB$3)) -> 0 | G13: =IF(ISNUMBER(SEARCH("营",'19.02'!O13)),(-$Y13+50*IF('19.02'!$AK13="是",'19.02'!$BB$4,'19.02'!$BB$3)),(VLOOKUP('19.02'!O13,'19.02'!$AO$4:$AQ$55,2,FALSE))*IF('19.02'!$AK13="是",'19.02'!$BB$4,'19.02'!$BB$3)) -> 0 | H13: =IF(ISNUMBER(SEARCH("营",'19.02'!P13)),(-$Y13+50*IF('19.02'!$AK13="是",'19.02'!$BB$4,'19.02'!$BB$3)),(VLOOKUP('19.02'!P13,'19.02'!$AO$4:$AQ$55,2,FALSE))*IF('19.02'!$AK13="是",'19.02'!$BB$4,'19.02'!$BB$3)) -> 0 | ... X13: =IF(ISNUMBER(SEARCH("营",'19.02'!AF13)),(-$Y13+50*IF('19.02'!$AK13="是",'19.02'!$BB$4,'19.02'!$BB$3)),(VLOOKUP('19.02'!AF13,'19.02'!$AO$4:$AQ$55,2,FALSE))*IF('19.02'!$AK13="是",'19.02'!$BB$4,'19.02'!$BB$3)) -> 0 | Y13: 300 | Z13: 45739
