Workbook

Sheet 15.01
A1: =(_xlfn.DAYS(TODAY(),A4)+2)/((_xlfn.DAYS(A93,A4))+1) -> 0.85555556 | I1: 工作区 | AM1: 使用方法：按自己规划的路线，将下表中的地块名复制粘贴至工作区。初次使用传送门，当天跳步次数+5。重复使用传送门，当天跳步次数+1
A2: 15.01 | B2: 八卦前亏 | C2: =SUM(亏损!A4:X94)+SUM(AG4:AG14)*10 -> #REF! | D2: 合计经验 | F2: =SUM(F4:F93)+SUM(H4:H93) -> 64590 | I2: 队伍一 火 | K2: 步数 | L2: =COUNTIF(I4:P93,"<>空") -> 43 | M2: (不算跳步和传送) | Q2: 队伍二 雷 | S2: 步数 | T2: =COUNTIF(Q4:X93,"<>空") -> 500 | U2: (不算跳步和传送) | Y2: 队伍三 | AA2: 总步数 | AB2: =COUNTIF(Y4:AF93,"<>空") -> 516 | AC2: (不算跳步和传送) | AG2: =SUM(AG4:AG93) -> 47 | AH2: =SUM(AH4:AH93) -> 3 | AI2: =SUM(AI4:AI93) -> 10 | AJ2: =SUM(AJ4:AJ93) -> 34 | AK2: 八卦全开 | AS2: 总地块 | AT2: =SUM(AT4:AT29) -> 1059 | AV2: 总经验 | AW2: =SUM(AU4:AW29)+7000 -> 64590 | AY2: 粮草系数
A3: 日期 | B3: 获得粮草 | C3: 粮草调整 | D3: 消耗粮草 | E3: 剩余粮草 | F3: 获得经验 | G3: 累计经验 | H3: 任务经验 | I3: 1 | J3: 2 | K3: 3 | L3: 4 | M3: 5 | N3: 6 | O3: 7 | P3: 8 | Q3: 1 | R3: 2 | S3: 3 | T3: 4 | U3: 5 | V3: 6 | W3: 7 | X3: 8 | Y3: 1 | Z3: 2 | AA3: 3 | AB3: 4 | AC3: 5 | AD3: 6 | AE3: 7 | AF3: 8 | AG3: 跳步次数 | AH3: 1队跳步 | AI3: 2队跳步 | AJ3: 3队跳步 | AM3: 地块 | AN3: 粮草 | AO3: 经验 | AP3: 八卦前亏损 | AQ3: 一队地块 | AR3: 二队地块 | AS3: 三队地块 | AT3: 总地块 | AU3: 一队经验 | AV3: 二队经验 | AW3: 三队经验 | AX3: 八卦前 | AY3: 1
A4: 45366 | B4: 800 | C4: 4800 | D4: =(SUM(粮草!A4:X4)+AG4*10)*IF(AK4="是",$AY$4,$AY$3) -> 1700 | E4: =SUM($B$4:B4)+SUM($C$4:C4)-SUM($D$4:D4) -> 3900 | F4: =SUM(经验!A4:X4) -> 415 | G4: =SUM($F$4:F4)+SUM($H$4:H4) -> 915 | H4: 500 | I4: 1级 | J4: 1级 | K4: 1级 | L4: 1级 | M4: 1级 | N4: 商人 | O4: 空 | P4: 空 | Q4: 1级 | R4: 1级 | S4: 1级 | T4: 1级 | U4: 1级 | V4: 1级 | W4: 空 | X4: 空 | Y4: 空 | Z4: 空 | AA4: 空 | AB4: 空 | AC4: 空 | AD4: 空 | AE4: 空 | AF4: 空 | AG4: =AH4+AI4+AJ4 -> 0 | AK4: 否 | AM4: 1级 | AN4: 150 | AO4: 35 | AP4: 44.222109 | AQ4: =COUNTIF($I$4:$P$93,AM4) -> 8 | AR4: =COUNTIF($Q$4:$X$93,AM4) -> 12 | AS4: =COUNTIF($Y$4:$AF$93,AM4) -> 7 | AT4: =AQ4+AR4+AS4 -> 27 | AU4: =AQ4*$AO4 -> 280 | AV4: =AR4*$AO4 -> 420 | AW4: =AS4*$AO4 -> 245 | AX4: 八卦后 | AY4: 0.8 | BA4: =AN4*0.8 -> 120
A5: 45367 | B5: 1600 | C5: 1200 | D5: =(SUM(粮草!A5:X5)+AG5*10)*IF(AK5="是",$AY$4,$AY$3) -> 1810 | E5: =SUM($B$4:B5)+SUM($C$4:C5)-SUM($D$4:D5) -> 4890 | F5: =SUM(经验!A5:X5) -> 480 | G5: =SUM($F$4:F5)+SUM($H$4:H5) -> 1395 | H5: 0 | I5: 空 | J5: 空 | K5: 空 | L5: 空 | M5: 空 | N5: 空 | O5: 空 | P5: 空 | Q5: 1级 | R5: 商人 | S5: 1级 | T5: 1级 | U5: 1级 | V5: 商人 | W5: 空 | X5: 空 | Y5: 1级 | Z5: 1级 | AA5: 1级 | AB5: 商人 | AC5: 1级 | AD5: 1级 | AE5: 1级 | AF5: 2级 | AG5: =AH5+AI5+AJ5 -> 0 | AK5: 否 | AM5: 2级 | AN5: 160 | AO5: 40 | AP5: 39.110982 | AQ5: =COUNTIF($I$4:$P$93,AM5) -> 24 | AR5: =COUNTIF($Q$4:$X$93,AM5) -> 15 | AS5: =COUNTIF($Y$4:$AF$93,AM5) -> 10 | AT5: =AQ5+AR5+AS5 -> 49 | AU5: =AQ5*$AO5 -> 960 | AV5: =AR5*$AO5 -> 600 | AW5: =AS5*$AO5 -> 400 | AX5: Note：开完八卦当天可能需要手动计算粮草 | BA5: =AN5*0.8 -> 128
A6: 45368 | B6: 1600 | D6: =(SUM(粮草!A6:X6)+AG6*10)*IF(AK6="是",$AY$4,$AY$3) -> 1700 | E6: =SUM($B$4:B6)+SUM($C$4:C6)-SUM($D$4:D6) -> 4790 | F6: =SUM(经验!A6:X6) -> 495 | G6: =SUM($F$4:F6)+SUM($H$4:H6) -> 1890 | H6: 0 | I6: 空 | J6: 空 | K6: 空 | L6: 空 | M6: 空 | N6: 空 | O6: 空 | P6: 空 | Q6: 1级 | R6: 1级 | S6: 2级 | T6: 2级 | U6: 营地 | V6: 2级 | W6: 空 | X6: 空 | Y6: 2级 | Z6: 2级 | AA6: 2级 | AB6: 商人 | AC6: 2级 | AD6: 2级 | AE6: 商人 | AF6: 3级 | AG6: =AH6+AI6+AJ6 -> 0 | AK6: 否 | AM6: 3级 | AN6: 170 | AO6: 45 | AP6: 34 | AQ6: =COUNTIF($I$4:$P$93,AM6) -> 0 | AR6: =COUNTIF($Q$4:$X$93,AM6) -> 47 | AS6: =COUNTIF($Y$4:$AF$93,AM6) -> 156 | AT6: =AQ6+AR6+AS6 -> 203 | AU6: =AQ6*$AO6 -> 0 | AV6: =AR6*$AO6 -> 2115 | AW6: =AS6*$AO6 -> 7020 | BA6: =AN6*0.8 -> 136
A7: 45369 | B7: 1600 | D7: =(SUM(粮草!A7:X7)+AG7*10)*IF(AK7="是",$AY$4,$AY$3) -> 2110 | E7: =SUM($B$4:B7)+SUM($C$4:C7)-SUM($D$4:D7) -> 4280 | F7: =SUM(经验!A7:X7) -> 575 | G7: =SUM($F$4:F7)+SUM($H$4:H7) -> 2665 | H7: 200 | I7: 空 | J7: 空 | K7: 空 | L7: 空 | M7: 空 | N7: 空 | O7: 空 | P7: 空 | Q7: 2级 | R7: 2级 | S7: 商人 | T7: 2级 | U7: 塔2 | V7: 2级 | W7: 空 | X7: 空 | Y7: 3级 | Z7: 3级 | AA7: 3级 | AB7: 3级 | AC7: 商人 | AD7: 3级 | AE7: 塔3 | AF7: 3级 | AG7: =AH7+AI7+AJ7 -> 5 | AI7: 5 | AK7: 否 | AM7: 4级 | AN7: 180 | AO7: 50 | AP7: 36 | AQ7: =COUNTIF($I$4:$P$93,AM7) -> 0 | AR7: =COUNTIF($Q$4:$X$93,AM7) -> 191 | AS7: =COUNTIF($Y$4:$AF$93,AM7) -> 78 | AT7: =AQ7+AR7+AS7 -> 269 | AU7: =AQ7*$AO7 -> 0 | AV7: =AR7*$AO7 -> 9550 | AW7: =AS7*$AO7 -> 3900 | BA7: =AN7*0.8 -> 144
A8: 45370 | B8: 1600 | D8: =(SUM(粮草!A8:X8)+AG8*10)*IF(AK8="是",$AY$4,$AY$3) -> 2040 | E8: =SUM($B$4:B8)+SUM($C$4:C8)-SUM($D$4:D8) -> 3840 | F8: =SUM(经验!A8:X8) -> 550 | G8: =SUM($F$4:F8)+SUM($H$4:H8) -> 3315 | H8: 100 | I8: 空 | J8: 空 | K8: 空 | L8: 空 | M8: 空 | N8: 空 | O8: 空 | P8: 空 | Q8: 2级 | R8: 2级 | S8: 4级 | T8: 4级 | U8: 4级 | V8: 4级 | W8: 空 | X8: 空 | Y8: 3级 | Z8: 3级 | AA8: 塔3 | AB8: 3级 | AC8: 3级 | AD8: 3级卦 | AE8: 空 | AF8: 空 | AG8: =AH8+AI8+AJ8 -> 0 | AK8: 否 | AM8: 5级 | AN8: 190 | AO8: 55 | AP8: 38 | AQ8: =COUNTIF($I$4:$P$93,AM8) -> 0 | AR8: =COUNTIF($Q$4:$X$93,AM8) -> 169 | AS8: =COUNTIF($Y$4:$AF$93,AM8) -> 66 | AT8: =AQ8+AR8+AS8 -> 235 | AU8: =AQ8*$AO8 -> 0 | AV8: =AR8*$AO8 -> 9295 | AW8: =AS8*$AO8 -> 3630 | BA8: =AN8*0.8 -> 152
A9: 45371 | B9: 1600 | D9: =(SUM(粮草!A9:X9)+AG9*10)*IF(AK9="是",$AY$4,$AY$3) -> 1280 | E9: =SUM($B$4:B9)+SUM($C$4:C9)-SUM($D$4:D9) -> 4160 | F9: =SUM(经验!A9:X9) -> 670 | G9: =SUM($F$4:F9)+SUM($H$4:H9) -> 4185 | H9: 200 | I9: 空 | J9: 空 | K9: 空 | L9: 空 | M9: 空 | N9: 空 | O9: 空 | P9: 空 | Q9: 巨卦 | R9: 空 | S9: 空 | T9: 空 | U9: 空 | V9: 空 | W9: 空 | X9: 空 | Y9: 3级 | Z9: 3级 | AA9: 3级 | AB9: 3级 | AC9: 3级 | AD9: 3级 | AE9: 空 | AF9: 空 | AG9: =AH9+AI9+AJ9 -> 1 | AJ9: 1 | AK9: 否 | AM9: 6级 | AN9: 200 | AO9: 60 | AQ9: =COUNTIF($I$4:$P$93,AM9) -> 0 | AR9: =COUNTIF($Q$4:$X$93,AM9) -> 34 | AS9: =COUNTIF($Y$4:$AF$93,AM9) -> 157 | AT9: =AQ9+AR9+AS9 -> 191 | AU9: =AQ9*$AO9 -> 0 | AV9: =AR9*$AO9 -> 2040 | AW9: =AS9*$AO9 -> 9420 | BA9: =AN9*0.8 -> 160
A10: 45372 | B10: 1600 | C10: 50 | D10: =(SUM(粮草!A10:X10)+AG10*10)*IF(AK10="是",$AY$4,$AY$3) -> 1020 | E10: =SUM($B$4:B10)+SUM($C$4:C10)-SUM($D$4:D10) -> 4790 | F10: =SUM(经验!A10:X10) -> 270 | G10: =SUM($F$4:F10)+SUM($H$4:H10) -> 4455 | H10: 0 | I10: 空 | J10: 空 | K10: 空 | L10: 空 | M10: 空 | N10: 空 | O10: 空 | P10: 空 | Q10: 空 | R10: 空 | S10: 空 | T10: 空 | U10: 空 | V10: 空 | W10: 空 | X10: 空 | Y10: 3级 | Z10: 3级卦 | AA10: 3级 | AB10: 3级 | AC10: 3级卦 | AD10: 3级 | AE10: 空 | AF10: 空 | AG10: =AH10+AI10+AJ10 -> 0 | AK10: 否 | AM10: 塔1 | AN10: 150 | AO10: 35 | AP10: 44.222109 | AQ10: =COUNTIF($I$4:$P$93,AM10) -> 0 | AR10: =COUNTIF($Q$4:$X$93,AM10) -> 0 | AS10: =COUNTIF($Y$4:$AF$93,AM10) -> 0 | AT10: =AQ10+AR10+AS10 -> 0 | AU10: =AQ10*$AO10 -> 0 | AV10: =AR10*$AO10 -> 0 | AW10: =AS10*$AO10 -> 0 | BA10: =AN10*0.8 -> 120
A11: 45373 | B11: 1600 | D11: =(SUM(粮草!A11:X11)+AG11*10)*IF(AK11="是",$AY$4,$AY$3) -> 900 | E11: =SUM($B$4:B11)+SUM($C$4:C11)-SUM($D$4:D11) -> 5490 | F11: =SUM(经验!A11:X11) -> 255 | G11: =SUM($F$4:F11)+SUM($H$4:H11) -> 4710 | H11: 0 | I11: 空 | J11: 空 | K11: 空 | L11: 空 | M11: 空 | N11: 空 | O11: 空 | P11: 空 | Q11: 空 | R11: 空 | S11: 空 | T11: 空 | U11: 空 | V11: 空 | W11: 空 | X11: 空 | Y11: 3级 | Z11: 3级 | AA11: 3级 | AB11: 商人 | AC11: 3级 | AD11: 3级 | AE11: 空 | AF11: 空 | AG11: =AH11+AI11+AJ11 -> 0 | AK11: 否 | AM11: 塔2 | AN11: 150 | AO11: 40 | AP11: 29.110982 | AQ11: =COUNTIF($I$4:$P$93,AM11) -> 0 | AR11: =COUNTIF($Q$4:$X$93,AM11) -> 1 | AS11: =COUNTIF($Y$4:$AF$93,AM11) -> 1 | AT11: =AQ11+AR11+AS11 -> 2 | AU11: =AQ11*$AO11 -> 0 | AV11: =AR11*$AO11 -> 40 | AW11: =AS11*$AO11 -> 40 | BA11: =AN11*0.8 -> 120
A12: 45374 | B12: 1600 | D12: =(SUM(粮草!A12:X12)+AG12*10)*IF(AK12="是",$AY$4,$AY$3) -> 980 | E12: =SUM($B$4:B12)+SUM($C$4:C12)-SUM($D$4:D12) -> 6110 | F12: =SUM(经验!A12:X12) -> 510 | G12: =SUM($F$4:F12)+SUM($H$4:H12) -> 5220 | H12: 0 | I12: 空 | J12: 空 | K12: 空 | L12: 空 | M12: 空 | N12: 空 | O12: 空 | P12: 空 | Q12: 空 | R12: 空 | S12: 空 | T12: 空 | U12: 空 | V12: 空 | W12: 空 | X12: 空 | Y12: 3级 | Z12: 3级 | AA12: 3级 | AB12: 商人 | AC12: 3级 | AD12: 大卦 | AE12: 空 | AF12: 空 | AG12: =AH12+AI12+AJ12 -> 0 | AK12: 否 | AM12: 塔3 | AN12: 150 | AO12: 45 | AP12: 13.999855 | AQ12: =COUNTIF($I$4:$P$93,AM12) -> 0 | AR12: =COUNTIF($Q$4:$X$93,AM12) -> 1 | AS12: =COUNTIF($Y$4:$AF$93,AM12) -> 5 | AT12: =AQ12+AR12+AS12 -> 6 | AU12: =AQ12*$AO12 -> 0 | AV12: =AR12*$AO12 -> 45 | AW12: =AS12*$AO12 -> 225 | BA12: =AN12*0.8 -> 120
A13: 45375 | B13: 1600 | D13: =(SUM(粮草!A13:X13)+AG13*10)*IF(AK13="是",$AY$4,$AY$3) -> 1070 | E13: =SUM($B$4:B13)+SUM($C$4:C13)-SUM($D$4:D13) -> 6640 | F13: =SUM(经验!A13:X13) -> 270 | G13: =SUM($F$4:F13)+SUM($H$4:H13) -> 5490 | H13: 0 | I13: 空 | J13: 空 | K13: 空 | L13: 空 | M13: 空 | N13: 空 | O13: 空 | P13: 空 | Q13: 空 | R13: 空 | S13: 空 | T13: 空 | U13: 空 | V13: 空 | W13: 空 | X13: 空 | Y13: 3级 | Z13: 3级 | AA13: 3级 | AB13: 3级 | AC13: 3级 | AD13: 3级 | AE13: 空 | AF13: 空 | AG13: =AH13+AI13+AJ13 -> 5 | AJ13: 5 | AK13: 否 | AM13: 塔4 | AN13: 150 | AO13: 50 | AQ13: =COUNTIF($I$4:$P$93,AM13) -> 0 | AR13: =COUNTIF($Q$4:$X$93,AM13) -> 2 | AS13: =COUNTIF($Y$4:$AF$93,AM13) -> 1 | AT13: =AQ13+AR13+AS13 -> 3 | AU13: =AQ13*$AO13 -> 0 | AV13: =AR13*$AO13 -> 100 | AW13: =AS13*$AO13 -> 50 | BA13: =AN13*0.8 -> 120
A14: 45376 | B14: 1600 | D14: =(SUM(粮草!A14:X14)+AG14*10)*IF(AK14="是",$AY$4,$AY$3) -> 1100 | E14: =SUM($B$4:B14)+SUM($C$4:C14)-SUM($D$4:D14) -> 7140 | F14: =SUM(经验!A14:X14) -> 280 | G14: =SUM($F$4:F14)+SUM($H$4:H14) -> 6070 | H14: 300 | I14: 空 | J14: 空 | K14: 空 | L14: 空 | M14: 空 | N14: 空 | O14: 空 | P14: 空 | Q14: 空 | R14: 空 | S14: 空 | T14: 空 | U14: 空 | V14: 空 | W14: 空 | X14: 空 | Y14: 4级 | Z14: 4级卦 | AA14: 3级 | AB14: 3级 | AC14: 3级 | AD14: 3级 | AE14: 空 | AF14: 空 | AG14: =AH14+AI14+AJ14 -> 6 | AJ14: 6 | AK14: 否 | AM14: 塔5 | AN14: 150 | AO14: 55 | AQ14: =COUNTIF($I$4:$P$93,AM14) -> 0 | AR14: =COUNTIF($Q$4:$X$93,AM14) -> 3 | AS14: =COUNTIF($Y$4:$AF$93,AM14) -> 0 | AT14: =AQ14+AR14+AS14 -> 3 | AU14: =AQ14*$AO14 -> 0 | AV14: =AR14*$AO14 -> 165 | AW14: =AS14*$AO14 -> 0 | BA14: =AN14*0.8 -> 120
A15: 45377 | B15: 1600 | D15: =(SUM(粮草!A15:X15)+AG15*10)*IF(AK15="是",$AY$4,$AY$3) -> 1120 | E15: =SUM($B$4:B15)+SUM($C$4:C15)-SUM($D$4:D15) -> 7620 | F15: =SUM(经验!A15:X15) -> 525 | G15: =SUM($F$4:F15)+SUM($H$4:H15) -> 6595 | H15: 0 | I15: 空 | J15: 空 | K15: 空 | L15: 空 | M15: 空 | N15: 空 | O15: 空 | P15: 空 | Q15: 空 | R15: 空 | S15: 空 | T15: 空 | U15: 空 | V15: 空 | W15: 空 | X15: 空 | Y15: 3级 | Z15: 大卦 | AA15: 3级 | AB15: 3级 | AC15: 3级 | AD15: 3级 | AE15: 空 | AF15: 空 | AG15: =AH15+AI15+AJ15 -> 2 | AJ15: 2 | AK15: 否 | AM15: 塔6 | AN15: 150 | AO15: 60 | AQ15: =COUNTIF($I$4:$P$93,AM15) -> 0 | AR15: =COUNTIF($Q$4:$X$93,AM15) -> 0 | AS15: =COUNTIF($Y$4:$AF$93,AM15) -> 1 | AT15: =AQ15+AR15+AS15 -> 1 | AU15: =AQ15*$AO15 -> 0 | AV15: =AR15*$AO15 -> 0 | AW15: =AS15*$AO15 -> 60 | BA15: =AN15*0.8 -> 120
A16: 45378 | B16: 1600 | C16: 216 | D16: =(SUM(粮草!A16:X16)+AG16*10)*IF(AK16="是",$AY$4,$AY$3) -> 2100 | E16: =SUM($B$4:B16)+SUM($C$4:C16)-SUM($D$4:D16) -> 7336 | F16: =SUM(经验!A16:X16) -> 570 | G16: =SUM($F$4:F16)+SUM($H$4:H16) -> 7365 | H16: 200 | I16: 空 | J16: 空 | K16: 空 | L16: 空 | M16: 空 | N16: 空 | O16: 空 | P16: 空 | Q16: 4级 | R16: 4级 | S16: 4级 | T16: 4级 | U16: 4级 | V16: 4级 | W16: 空 | X16: 空 | Y16: 3级 | Z16: 3级 | AA16: 3级 | AB16: 3级 | AC16: 3级 | AD16: 3级卦 | AE16: 空 | AF16: 空 | AG16: =AH16+AI16+AJ16 -> 0 | AK16: 否 | AM16: 遗迹 | AN16: 150 | AO16: 35 | AP16: 44.222109 | AQ16: =COUNTIF($I$4:$P$93,AM16) -> 0 | AR16: =COUNTIF($Q$4:$X$93,AM16) -> 0 | AS16: =COUNTIF($Y$4:$AF$93,AM16) -> 0 | AT16: =AQ16+AR16+AS16 -> 0 | AU16: =AQ16*$AO16 -> 0 | AV16: =AR16*$AO16 -> 0 | AW16: =AS16*$AO16 -> 0 | BA16: =AN16*0.8 -> 120
A17: 45379 | B17: 1600 | D17: =(SUM(粮草!A17:X17)+AG17*10)*IF(AK17="是",$AY$4,$AY$3) -> 1584 | E17: =SUM($B$4:B17)+SUM($C$4:C17)-SUM($D$4:D17) -> 7352 | F17: =SUM(经验!A17:X17) -> 555 | G17: =SUM($F$4:F17)+SUM($H$4:H17) -> 7920 | H17: 0 | I17: 空 | J17: 空 | K17: 空 | L17: 空 | M17: 空 | N17: 空 | O17: 空 | P17: 空 | Q17: 4级 | R17: 4级 | S17: 4级 | T17: 4级 | U17: 4级 | V17: 4级 | W17: 空 | X17: 空 | Y17: 3级 | Z17: 3级 | AA17: 商人 | AB17: 3级 | AC17: 3级 | AD17: 3级 | AE17: 空 | AF17: 空 | AG17: =AH17+AI17+AJ17 -> 0 | AK17: 是 | AM17: 商人 | AN17: 50 | AO17: 30 | AP17: 10 | AQ17: =COUNTIF($I$4:$P$93,AM17) -> 9 | AR17: =COUNTIF($Q$4:$X$93,AM17) -> 11 | AS17: =COUNTIF($Y$4:$AF$93,AM17) -> 20 | AT17: =AQ17+AR17+AS17 -> 40 | AU17: =AQ17*$AO17 -> 270 | AV17: =AR17*$AO17 -> 330 | AW17: =AS17*$AO17 -> 600 | BA17: =AN17*0.8 -> 40
A18: 45380 | B18: 1600 | D18: =(SUM(粮草!A18:X18)+AG18*10)*IF(AK18="是",$AY$4,$AY$3) -> 1688 | E18: =SUM($B$4:B18)+SUM($C$4:C18)-SUM($D$4:D18) -> 7264 | F18: =SUM(经验!A18:X18) -> 570 | G18: =SUM($F$4:F18)+SUM($H$4:H18) -> 8490 | H18: 0 | I18: 空 | J18: 空 | K18: 空 | L18: 空 | M18: 空 | N18: 空 | O18: 空 | P18: 空 | Q18: 4级 | R18: 4级 | S18: 4级 | T18: 4级 | U18: 4级 | V18: 4级 | W18: 空 | X18: 空 | Y18: 3级 | Z18: 3级 | AA18: 3级 | AB18: 3级 | AC18: 3级 | AD18: 3级 | AE18: 空 | AF18: 空 | AG18: =AH18+AI18+AJ18 -> 1 | AJ18: 1 | AK18: 是 | AL18: 八卦前 | AM18: 营地 | AN18: -150 | AO18: 0 | AP18: 10 | AQ18: =COUNTIF($I$4:$P$93,AM18) -> 0 | AR18: =COUNTIF($Q$4:$X$93,AM18) -> 1 | AS18: =COUNTIF($Y$4:$AF$93,AM18) -> 0 | AT18: =AQ18+AR18+AS18 -> 1 | AU18: =AQ18*$AO18 -> 0 | AV18: =AR18*$AO18 -> 0 | AW18: =AS18*$AO18 -> 0 | BA18: =AN18*0.8 -> -120
A19: 45381 | B19: 1600 | D19: =(SUM(粮草!A19:X19)+AG19*10)*IF(AK19="是",$AY$4,$AY$3) -> 1384 | E19: =SUM($B$4:B19)+SUM($C$4:C19)-SUM($D$4:D19) -> 7480 | F19: =SUM(经验!A19:X19) -> 525 | G19: =SUM($F$4:F19)+SUM($H$4:H19) -> 9015 | H19: 0 | I19: 空 | J19: 空 | K19: 空 | L19: 空 | M19: 空 | N19: 空 | O19: 空 | P19: 空 | Q19: 4级 | R19: 4级 | S19: 4级 | T19: 4级 | U19: 4级 | V19: 4级 | W19: 空 | X19: 空 | Y19: 3级 | Z19: 3级 | AA19: 营地+ | AB19: 3级 | AC19: 3级 | AD19: 3级 | AE19: 空 | AF19: 空 | AG19: =AH19+AI19+AJ19 -> 0 | AK19: 是 | AM19: 大卦 | AN19: 250 | AO19: 300 | AQ19: =COUNTIF($I$4:$P$93,AM19) -> 0 | AR19: =COUNTIF($Q$4:$X$93,AM19) -> 0 | AS19: =COUNTIF($Y$4:$AF$93,AM19) -> 2 | AT19: =AQ19+AR19+AS19 -> 2 | AU19: =AQ19*$AO19 -> 0 | AV19: =AR19*$AO19 -> 0 | AW19: =AS19*$AO19 -> 600 | BA19: =AN19*0.8 -> 200
A20: 45382 | B20: 1600 | D20: =(SUM(粮草!A20:X20)+AG20*10)*IF(AK20="是",$AY$4,$AY$3) -> 1248 | E20: =SUM($B$4:B20)+SUM($C$4:C20)-SUM($D$4:D20) -> 7832 | F20: =SUM(经验!A20:X20) -> 445 | G20: =SUM($F$4:F20)+SUM($H$4:H20) -> 9460 | H20: 0 | I20: 空 | J20: 空 | K20: 空 | L20: 空 | M20: 空 | N20: 空 | O20: 空 | P20: 空 | Q20: 2级 | R20: 2级 | S20: 营地+ | T20: 2级 | U20: 2级 | V20: 2级 | W20: 空 | X20: 空 | Y20: 3级 | Z20: 塔2 | AA20: 2级 | AB20: 2级 | AC20: 2级 | AD20: 2级 | AE20: 空 | AF20: 空 | AG20: =AH20+AI20+AJ20 -> 0 | AK20: 是 | AM20: 3级卦 | AN20: 170 | AO20: 45 | AQ20: =COUNTIF($I$4:$P$93,AM20) -> 0 | AR20: =COUNTIF($Q$4:$X$93,AM20) -> 0 | AS20: =COUNTIF($Y$4:$AF$93,AM20) -> 4 | AT20: =AQ20+AR20+AS20 -> 4 | AU20: =AQ20*$AO20 -> 0 | AV20: =AR20*$AO20 -> 0 | AW20: =AS20*$AO20 -> 180 | BA20: =AN20*0.8 -> 136
A21: 45383 | B21: 1600 | D21: =(SUM(粮草!A21:X21)+AG21*10)*IF(AK21="是",$AY$4,$AY$3) -> 1472 | E21: =SUM($B$4:B21)+SUM($C$4:C21)-SUM($D$4:D21) -> 7960 | F21: =SUM(经验!A21:X21) -> 530 | G21: =SUM($F$4:F21)+SUM($H$4:H21) -> 10190 | H21: 200 | I21: 空 | J21: 空 | K21: 空 | L21: 空 | M21: 空 | N21: 空 | O21: 空 | P21: 空 | Q21: 2级 | R21: 4级 | S21: 4级 | T21: 4级 | U21: 4级 | V21: 4级 | W21: 空 | X21: 空 | Y21: 商人 | Z21: 3级 | AA21: 3级 | AB21: 3级 | AC21: 3级 | AD21: 商人 | AE21: 空 | AF21: 空 | AG21: =AH21+AI21+AJ21 -> 0 | AK21: 是 | AM21: 巨卦 | AN21: 250 | AO21: 400 | AQ21: =COUNTIF($I$4:$P$93,AM21) -> 0 | AR21: =COUNTIF($Q$4:$X$93,AM21) -> 1 | AS21: =COUNTIF($Y$4:$AF$93,AM21) -> 0 | AT21: =AQ21+AR21+AS21 -> 1 | AU21: =AQ21*$AO21 -> 0 | AV21: =AR21*$AO21 -> 400 | AW21: =AS21*$AO21 -> 0 | BA21: =AN21*0.8 -> 200
A22: 45384 | B22: 1600 | D22: =(SUM(粮草!A22:X22)+AG22*10)*IF(AK22="是",$AY$4,$AY$3) -> 1680 | E22: =SUM($B$4:B22)+SUM($C$4:C22)-SUM($D$4:D22) -> 7880 | F22: =SUM(经验!A22:X22) -> 570 | G22: =SUM($F$4:F22)+SUM($H$4:H22) -> 10860 | H22: 100 | I22: 空 | J22: 空 | K22: 空 | L22: 空 | M22: 空 | N22: 空 | O22: 空 | P22: 空 | Q22: 4级 | R22: 4级 | S22: 4级 | T22: 4级 | U22: 4级 | V22: 4级 | W22: 空 | X22: 空 | Y22: 3级 | Z22: 3级 | AA22: 3级 | AB22: 3级 | AC22: 3级 | AD22: 3级 | AE22: 空 | AF22: 空 | AG22: =AH22+AI22+AJ22 -> 0 | AK22: 是 | AM22: 大boss | AN22: 250 | AO22: 1000 | AQ22: =COUNTIF($I$4:$P$93,AM22) -> 0 | AR22: =COUNTIF($Q$4:$X$93,AM22) -> 1 | AS22: =COUNTIF($Y$4:$AF$93,AM22) -> 1 | AT22: =AQ22+AR22+AS22 -> 2 | AU22: =AQ22*$AO22 -> 0 | AV22: =AR22*$AO22 -> 1000 | AW22: =AS22*$AO22 -> 1000 | BA22: =AN22*0.8 -> 200
A23: 45385 | B23: 1600 | D23: =(SUM(粮草!A23:X23)+AG23*10)*IF(AK23="是",$AY$4,$AY$3) -> 1680 | E23: =SUM($B$4:B23)+SUM($C$4:C23)-SUM($D$4:D23) -> 7800 | F23: =SUM(经验!A23:X23) -> 570 | G23: =SUM($F$4:F23)+SUM($H$4:H23) -> 11630 | H23: 200 | I23: 空 | J23: 空 | K23: 空 | L23: 空 | M23: 空 | N23: 空 | O23: 空 | P23: 空 | Q23: 4级 | R23: 4级 | S23: 4级 | T23: 4级 | U23: 4级 | V23: 4级 | W23: 空 | X23: 空 | Y23: 3级 | Z23: 3级 | AA23: 3级 | AB23: 3级 | AC23: 3级 | AD23: 3级 | AE23: 空 | AF23: 空 | AG23: =AH23+AI23+AJ23 -> 0 | AK23: 是 | AM23: 中boss | AN23: 250 | AO23: 500 | AQ23: =COUNTIF($I$4:$P$93,AM23) -> 0 | AR23: =COUNTIF($Q$4:$X$93,AM23) -> 2 | AS23: =COUNTIF($Y$4:$AF$93,AM23) -> 0 | AT23: =AQ23+AR23+AS23 -> 2 | AU23: =AQ23*$AO23 -> 0 | AV23: =AR23*$AO23 -> 1000 | AW23: =AS23*$AO23 -> 0 | BA23: =AN23*0.8 -> 200
A24: 45386 | B24: 1600 | D24: =(SUM(粮草!A24:X24)+AG24*10)*IF(AK24="是",$AY$4,$AY$3) -> 1584 | E24: =SUM($B$4:B24)+SUM($C$4:C24)-SUM($D$4:D24) -> 7816 | F24: =SUM(经验!A24:X24) -> 550 | G24: =SUM($F$4:F24)+SUM($H$4:H24) -> 12180 | H24: 0 | I24: 空 | J24: 空 | K24: 空 | L24: 空 | M24: 空 | N24: 空 | O24: 空 | P24: 空 | Q24: 4级 | R24: 4级 | S24: 4级 | T24: 4级 | U24: 商人 | V24: 4级 | W24: 空 | X24: 空 | Y24: 3级 | Z24: 3级 | AA24: 3级 | AB24: 3级 | AC24: 3级 | AD24: 3级 | AE24: 空 | AF24: 空 | AG24: =AH24+AI24+AJ24 -> 1 | AI24: 1 | AK24: 是 | AM24: 4级卦 | AN24: 180 | AO24: 50 | AP24: 39.110982 | AQ24: =COUNTIF($I$4:$P$93,AM24) -> 0 | AR24: =COUNTIF($Q$4:$X$93,AM24) -> 0 | AS24: =COUNTIF($Y$4:$AF$93,AM24) -> 1 | AT24: =AQ24+AR24+AS24 -> 1 | AU24: =AQ24*$AO24 -> 0 | AV24: =AR24*$AO24 -> 0 | AW24: =AS24*$AO24 -> 50 | BA24: =AN24*0.8 -> 144
A25: 45387 | B25: 1600 | D25: =(SUM(粮草!A25:X25)+AG25*10)*IF(AK25="是",$AY$4,$AY$3) -> 1600 | E25: =SUM($B$4:B25)+SUM($C$4:C25)-SUM($D$4:D25) -> 7816 | F25: =SUM(经验!A25:X25) -> 555 | G25: =SUM($F$4:F25)+SUM($H$4:H25) -> 12735 | H25: 0 | I25: 空 | J25: 空 | K25: 空 | L25: 空 | M25: 空 | N25: 空 | O25: 空 | P25: 空 | Q25: 4级 | R25: 4级 | S25: 4级 | T25: 4级 | U25: 塔4 | V25: 4级 | W25: 空 | X25: 空 | Y25: 商人 | Z25: 3级 | AA25: 3级 | AB25: 3级 | AC25: 3级 | AD25: 3级 | AE25: 空 | AF25: 空 | AG25: =AH25+AI25+AJ25 -> 5 | AI25: 3 | AJ25: 2 | AK25: 是 | AM25: 山中 | AN25: 160 | AO25: 40 | AP25: 39.110982 | AQ25: =COUNTIF($I$4:$P$93,AM25) -> 0 | AR25: =COUNTIF($Q$4:$X$93,AM25) -> 0 | AS25: =COUNTIF($Y$4:$AF$93,AM25) -> 0 | AT25: =AQ25+AR25+AS25 -> 0 | AU25: =AQ25*$AO25 -> 0 | AV25: =AR25*$AO25 -> 0 | AW25: =AS25*$AO25 -> 0 | BA25: =AN25*0.8 -> 128
A26: 45388 | B26: 1600 | D26: =(SUM(粮草!A26:X26)+AG26*10)*IF(AK26="是",$AY$4,$AY$3) -> 1688 | E26: =SUM($B$4:B26)+SUM($C$4:C26)-SUM($D$4:D26) -> 7728 | F26: =SUM(经验!A26:X26) -> 570 | G26: =SUM($F$4:F26)+SUM($H$4:H26) -> 13305 | H26: 0 | I26: 空 | J26: 空 | K26: 空 | L26: 空 | M26: 空 | N26: 空 | O26: 空 | P26: 空 | Q26: 4级 | R26: 4级 | S26: 4级 | T26: 4级 | U26: 4级 | V26: 4级 | W26: 空 | X26: 空 | Y26: 3级 | Z26: 3级 | AA26: 3级 | AB26: 3级 | AC26: 3级 | AD26: 3级 | AE26: 空 | AF26: 空 | AG26: =AH26+AI26+AJ26 -> 1 | AJ26: 1 | AK26: 是 | AM26: 秋道 | AN26: 150 | AO26: 35 | AP26: 44.222109 | AQ26: =COUNTIF($I$4:$P$93,AM26) -> 0 | AR26: =COUNTIF($Q$4:$X$93,AM26) -> 0 | AS26: =COUNTIF($Y$4:$AF$93,AM26) -> 0 | AT26: =AQ26+AR26+AS26 -> 0 | AU26: =AQ26*$AO26 -> 0 | AV26: =AR26*$AO26 -> 0 | AW26: =AS26*$AO26 -> 0 | BA26: =AN26*0.8 -> 120
A27: 45389 | B27: 1600 | D27: =(SUM(粮草!A27:X27)+AG27*10)*IF(AK27="是",$AY$4,$AY$3) -> 1680 | E27: =SUM($B$4:B27)+SUM($C$4:C27)-SUM($D$4:D27) -> 7648 | F27: =SUM(经验!A27:X27) -> 570 | G27: =SUM($F$4:F27)+SUM($H$4:H27) -> 13875 | H27: 0 | I27: 空 | J27: 空 | K27: 空 | L27: 空 | M27: 空 | N27: 空 | O27: 空 | P27: 空 | Q27: 4级 | R27: 4级 | S27: 4级 | T27: 4级 | U27: 4级 | V27: 4级 | W27: 空 | X27: 空 | Y27: 3级 | Z27: 3级 | AA27: 3级 | AB27: 3级 | AC27: 3级 | AD27: 3级 | AE27: 空 | AF27: 空 | AG27: =AH27+AI27+AJ27 -> 0 | AK27: 是 | AM27: 空 | AN27: 0 | AO27: 0 | AP27: 0 | AU27: =AQ27*$AO27 -> 0 | AV27: =AR27*$AO27 -> 0 | AW27: =AS27*$AO27 -> 0 | BA27: =AN27*0.8 -> 0
A28: 45390 | B28: 1600 | D28: =(SUM(粮草!A28:X28)+AG28*10)*IF(AK28="是",$AY$4,$AY$3) -> 1680 | E28: =SUM($B$4:B28)+SUM($C$4:C28)-SUM($D$4:D28) -> 7568 | F28: =SUM(经验!A28:X28) -> 570 | G28: =SUM($F$4:F28)+SUM($H$4:H28) -> 14645 | H28: 200 | I28: 空 | J28: 空 | K28: 空 | L28: 空 | M28: 空 | N28: 空 | O28: 空 | P28: 空 | Q28: 4级 | R28: 4级 | S28: 4级 | T28: 4级 | U28: 4级 | V28: 4级 | W28: 空 | X28: 空 | Y28: 3级 | Z28: 3级 | AA28: 3级 | AB28: 3级 | AC28: 3级 | AD28: 3级 | AE28: 空 | AF28: 空 | AG28: =AH28+AI28+AJ28 -> 0 | AK28: 是 | AL28: 八卦后 | AM28: 营地+ | AN28: -200 | AO28: 0 | AQ28: =COUNTIF($I$4:$P$93,AM28) -> 1 | AR28: =COUNTIF($Q$4:$X$93,AM28) -> 7 | AS28: =COUNTIF($Y$4:$AF$93,AM28) -> 6 | AT28: =AQ28+AR28+AS28 -> 14 | AU28: =AQ28*$AO28 -> 0 | AV28: =AR28*$AO28 -> 0 | AW28: =AS28*$AO28 -> 0 | BA28: =AN28*0.8 -> -160
A29: 45391 | B29: 1600 | D29: =(SUM(粮草!A29:X29)+AG29*10)*IF(AK29="是",$AY$4,$AY$3) -> 1584 | E29: =SUM($B$4:B29)+SUM($C$4:C29)-SUM($D$4:D29) -> 7584 | F29: =SUM(经验!A29:X29) -> 555 | G29: =SUM($F$4:F29)+SUM($H$4:H29) -> 15300 | H29: 100 | I29: 空 | J29: 空 | K29: 空 | L29: 空 | M29: 空 | N29: 空 | O29: 空 | P29: 空 | Q29: 4级 | R29: 4级 | S29: 4级 | T29: 4级 | U29: 4级 | V29: 4级 | W29: 空 | X29: 空 | Y29: 商人 | Z29: 3级 | AA29: 3级 | AB29: 3级 | AC29: 3级 | AD29: 3级 | AE29: 空 | AF29: 空 | AG29: =AH29+AI29+AJ29 -> 0 | AK29: 是 | AM29: 历练 | AN29: 50 | AO29: 520 | AQ29: =COUNTIF($I$4:$P$93,AM29) -> 1 | AR29: =COUNTIF($Q$4:$X$93,AM29) -> 2 | AS29: =COUNTIF($Y$4:$AF$93,AM29) -> 0 | AT29: =AQ29+AR29+AS29 -> 3 | AU29: =AQ29*$AO29 -> 520 | AV29: =AR29*$AO29 -> 1040 | AW29: =AS29*$AO29 -> 0 | BA29: =AN29*0.8 -> 40
A30: 45392 | B30: 1600 | D30: =(SUM(粮草!A30:X30)+AG30*10)*IF(AK30="是",$AY$4,$AY$3) -> 1480 | E30: =SUM($B$4:B30)+SUM($C$4:C30)-SUM($D$4:D30) -> 7704 | F30: =SUM(经验!A30:X30) -> 535 | G30: =SUM($F$4:F30)+SUM($H$4:H30) -> 16035 | H30: 200 | I30: 空 | J30: 空 | K30: 空 | L30: 空 | M30: 空 | N30: 空 | O30: 空 | P30: 空 | Q30: 4级 | R30: 商人 | S30: 4级 | T30: 4级 | U30: 4级 | V30: 4级 | W30: 空 | X30: 空 | Y30: 3级 | Z30: 3级 | AA30: 3级 | AB30: 3级 | AC30: 商人 | AD30: 3级 | AE30: 空 | AF30: 空 | AG30: =AH30+AI30+AJ30 -> 0 | AK30: 是
A31: 45393 | B31: 1600 | D31: =(SUM(粮草!A31:X31)+AG31*10)*IF(AK31="是",$AY$4,$AY$3) -> 968 | E31: =SUM($B$4:B31)+SUM($C$4:C31)-SUM($D$4:D31) -> 8336 | F31: =SUM(经验!A31:X31) -> 385 | G31: =SUM($F$4:F31)+SUM($H$4:H31) -> 16420 | H31: 0 | I31: 空 | J31: 空 | K31: 空 | L31: 空 | M31: 空 | N31: 空 | O31: 空 | P31: 空 | Q31: 4级 | R31: 营地+ | S31: 4级 | T31: 4级 | U31: 4级 | V31: 4级 | W31: 空 | X31: 空 | Y31: 3级 | Z31: 3级 | AA31: 3级 | AB31: 空 | AC31: 空 | AD31: 空 | AE31: 空 | AF31: 空 | AG31: =AH31+AI31+AJ31 -> 0 | AK31: 是
A32: 45394 | B32: 1600 | D32: =(SUM(粮草!A32:X32)+AG32*10)*IF(AK32="是",$AY$4,$AY$3) -> 1656 | E32: =SUM($B$4:B32)+SUM($C$4:C32)-SUM($D$4:D32) -> 8280 | F32: =SUM(经验!A32:X32) -> 555 | G32: =SUM($F$4:F32)+SUM($H$4:H32) -> 16975 | H32: 0 | I32: 空 | J32: 空 | K32: 空 | L32: 空 | M32: 空 | N32: 空 | O32: 空 | P32: 空 | Q32: 3级 | R32: 3级 | S32: 塔3 | T32: 3级 | U32: 3级 | V32: 3级 | W32: 空 | X32: 空 | Y32: 3级 | Z32: 3级 | AA32: 3级 | AB32: 4级 | AC32: 4级 | AD32: 4级 | AE32: 空 | AF32: 空 | AG32: =AH32+AI32+AJ32 -> 2 | AJ32: 2 | AK32: 是
A33: 45395 | B33: 1600 | D33: =(SUM(粮草!A33:X33)+AG33*10)*IF(AK33="是",$AY$4,$AY$3) -> 1656 | E33: =SUM($B$4:B33)+SUM($C$4:C33)-SUM($D$4:D33) -> 8224 | F33: =SUM(经验!A33:X33) -> 565 | G33: =SUM($F$4:F33)+SUM($H$4:H33) -> 17540 | H33: 0 | I33: 空 | J33: 空 | K33: 空 | L33: 空 | M33: 空 | N33: 空 | O33: 空 | P33: 空 | Q33: 3级 | R33: 3级 | S33: 3级 | T33: 3级 | U33: 3级 | V33: 3级 | W33: 空 | X33: 空 | Y33: 4级 | Z33: 4级 | AA33: 塔3 | AB33: 4级 | AC33: 4级 | AD33: 4级 | AE33: 空 | AF33: 空 | AG33: =AH33+AI33+AJ33 -> 0 | AK33: 是
A34: 45396 | B34: 1600 | D34: =(SUM(粮草!A34:X34)+AG34*10)*IF(AK34="是",$AY$4,$AY$3) -> 1488 | E34: =SUM($B$4:B34)+SUM($C$4:C34)-SUM($D$4:D34) -> 8336 | F34: =SUM(经验!A34:X34) -> 540 | G34: =SUM($F$4:F34)+SUM($H$4:H34) -> 18080 | H34: 0 | I34: 空 | J34: 空 | K34: 空 | L34: 空 | M34: 空 | N34: 空 | O34: 空 | P34: 空 | Q34: 商人 | R34: 3级 | S34: 3级 | T34: 3级 | U34: 3级 | V34: 4级 | W34: 空 | X34: 空 | Y34: 商人 | Z34: 4级 | AA34: 4级 | AB34: 4级 | AC34: 4级 | AD34: 4级 | AE34: 空 | AF34: 空 | AG34: =AH34+AI34+AJ34 -> 0 | AK34: 是
A35: 45397 | B35: 1600 | D35: =(SUM(粮草!A35:X35)+AG35*10)*IF(AK35="是",$AY$4,$AY$3) -> 1440 | E35: =SUM($B$4:B35)+SUM($C$4:C35)-SUM($D$4:D35) -> 8496 | F35: =SUM(经验!A35:X35) -> 560 | G35: =SUM($F$4:F35)+SUM($H$4:H35) -> 18840 | H35: 200 | I35: 空 | J35: 空 | K35: 空 | L35: 空 | M35: 空 | N35: 空 | O35: 空 | P35: 空 | Q35: 4级 | R35: 4级 | S35: 4级 | T35: 4级 | U35: 4级 | V35: 6级 | W35: 空 | X35: 空 | Y35: 4级 | Z35: 4级 | AA35: 4级 | AB35: 4级 | AC35: 营地+ | AD35: 4级 | AE35: 空 | AF35: 空 | AG35: =AH35+AI35+AJ35 -> 0 | AK35: 是
A36: 45398 | B36: 1600 | D36: =(SUM(粮草!A36:X36)+AG36*10)*IF(AK36="是",$AY$4,$AY$3) -> 1504 | E36: =SUM($B$4:B36)+SUM($C$4:C36)-SUM($D$4:D36) -> 8592 | F36: =SUM(经验!A36:X36) -> 600 | G36: =SUM($F$4:F36)+SUM($H$4:H36) -> 19540 | H36: 100 | I36: 空 | J36: 空 | K36: 空 | L36: 空 | M36: 空 | N36: 空 | O36: 空 | P36: 空 | Q36: 6级 | R36: 营地+ | S36: 6级 | T36: 6级 | U36: 6级 | V36: 6级 | W36: 空 | X36: 空 | Y36: 4级 | Z36: 4级 | AA36: 4级 | AB36: 4级 | AC36: 4级 | AD36: 4级 | AE36: 空 | AF36: 空 | AG36: =AH36+AI36+AJ36 -> 0 | AK36: 是
A37: 45399 | B37: 1600 | D37: =(SUM(粮草!A37:X37)+AG37*10)*IF(AK37="是",$AY$4,$AY$3) -> 1792 | E37: =SUM($B$4:B37)+SUM($C$4:C37)-SUM($D$4:D37) -> 8400 | F37: =SUM(经验!A37:X37) -> 640 | G37: =SUM($F$4:F37)+SUM($H$4:H37) -> 20380 | H37: 200 | I37: 空 | J37: 空 | K37: 空 | L37: 空 | M37: 空 | N37: 空 | O37: 空 | P37: 空 | Q37: 6级 | R37: 6级 | S37: 4级 | T37: 4级 | U37: 4级 | V37: 4级 | W37: 空 | X37: 空 | Y37: 4级 | Z37: 4级 | AA37: 4级 | AB37: 4级 | AC37: 6级 | AD37: 6级 | AE37: 空 | AF37: 空 | AG37: =AH37+AI37+AJ37 -> 0 | AK37: 是
A38: 45400 | B38: 1600 | D38: =(SUM(粮草!A38:X38)+AG38*10)*IF(AK38="是",$AY$4,$AY$3) -> 1824 | E38: =SUM($B$4:B38)+SUM($C$4:C38)-SUM($D$4:D38) -> 8176 | F38: =SUM(经验!A38:X38) -> 660 | G38: =SUM($F$4:F38)+SUM($H$4:H38) -> 21040 | H38: 0 | I38: 空 | J38: 空 | K38: 空 | L38: 空 | M38: 空 | N38: 空 | O38: 空 | P38: 空 | Q38: 4级 | R38: 6级 | S38: 6级 | T38: 6级 | U38: 3级 | V38: 3级 | W38: 空 | X38: 空 | Y38: 6级 | Z38: 6级 | AA38: 6级 | AB38: 6级 | AC38: 4级 | AD38: 4级 | AE38: 空 | AF38: 空 | AG38: =AH38+AI38+AJ38 -> 0 | AK38: 是
A39: 45401 | B39: 1600 | D39: =(SUM(粮草!A39:X39)+AG39*10)*IF(AK39="是",$AY$4,$AY$3) -> 1496 | E39: =SUM($B$4:B39)+SUM($C$4:C39)-SUM($D$4:D39) -> 8280 | F39: =SUM(经验!A39:X39) -> 545 | G39: =SUM($F$4:F39)+SUM($H$4:H39) -> 21585 | H39: 0 | I39: 空 | J39: 空 | K39: 空 | L39: 空 | M39: 空 | N39: 空 | O39: 空 | P39: 空 | Q39: 3级 | R39: 3级 | S39: 4级 | T39: 4级 | U39: 4级 | V39: 4级 | W39: 空 | X39: 空 | Y39: 4级 | Z39: 商人 | AA39: 4级 | AB39: 4级 | AC39: 商人 | AD39: 3级 | AE39: 空 | AF39: 空 | AG39: =AH39+AI39+AJ39 -> 0 | AK39: 是 | AM39: 2级194
A40: 45402 | B40: 1600 | D40: =(SUM(粮草!A40:X40)+AG40*10)*IF(AK40="是",$AY$4,$AY$3) -> 1392 | E40: =SUM($B$4:B40)+SUM($C$4:C40)-SUM($D$4:D40) -> 8488 | F40: =SUM(经验!A40:X40) -> 530 | G40: =SUM($F$4:F40)+SUM($H$4:H40) -> 22115 | H40: 0 | I40: 空 | J40: 空 | K40: 空 | L40: 空 | M40: 空 | N40: 空 | O40: 空 | P40: 空 | Q40: 4级 | R40: 4级 | S40: 4级 | T40: 4级 | U40: 4级 | V40: 4级 | W40: 空 | X40: 空 | Y40: 3级 | Z40: 3级 | AA40: 3级 | AB40: 营地+ | AC40: 3级 | AD40: 4级 | AE40: 空 | AF40: 空 | AG40: =AH40+AI40+AJ40 -> 0 | AK40: 是 | AM40: 3级349
...

Sheet 粮草
A2: 队伍一 风 | C2: 步数 | D2: =COUNTIF(A4:H94,"<>空") -> 728 | E2: (不算跳步和传送) | I2: 队伍二 雷 | K2: 步数 | L2: =COUNTIF(I4:P94,"<>空") -> 728 | M2: (不算跳步和传送) | Q2: 队伍三 | S2: 总步数 | T2: =COUNTIF(Q4:X94,"<>空") -> 728 | U2: (不算跳步和传送)
A3: 1 | B3: 2 | C3: 3 | D3: 4 | E3: 5 | F3: 6 | G3: 7 | H3: 8 | I3: 1 | J3: 2 | K3: 3 | L3: 4 | M3: 5 | N3: 6 | O3: 7 | P3: 8 | Q3: 1 | R3: 2 | S3: 3 | T3: 4 | U3: 5 | V3: 6 | W3: 7 | X3: 8
A4: =(VLOOKUP('15.01'!I4,'15.01'!$AM$4:$AO$55,2,FALSE))*IF('15.01'!AK$4="是",'15.01'!$AY$4,'15.01'!$AY$3) -> 150 | B4: =(VLOOKUP('15.01'!J4,'15.01'!$AM$4:$AO$55,2,FALSE))*IF('15.01'!AL$4="是",'15.01'!$AY$4,'15.01'!$AY$3) -> 150 | C4: =(VLOOKUP('15.01'!K4,'15.01'!$AM$4:$AO$55,2,FALSE))*IF('15.01'!AM$4="是",'15.01'!$AY$4,'15.01'!$AY$3) -> 150 | D4: =(VLOOKUP('15.01'!L4,'15.01'!$AM$4:$AO$55,2,FALSE))*IF('15.01'!AN$4="是",'15.01'!$AY$4,'15.01'!$AY$3) -> 150 | E4: =(VLOOKUP('15.01'!M4,'15.01'!$AM$4:$AO$55,2,FALSE))*IF('15.01'!AO$4="是",'15.01'!$AY$4,'15.01'!$AY$3) -> 150 | F4: =(VLOOKUP('15.01'!N4,'15.01'!$AM$4:$AO$55,2,FALSE))*IF('15.01'!AQ$4="是",'15.01'!$AY$4,'15.01'!$AY$3) -> 50 | G4: =(VLOOKUP('15.01'!O4,'15.01'!$AM$4:$AO$55,2,FALSE))*IF('15.01'!AR$4="是",'15.01'!$AY$4,'15.01'!$AY$3) -> 0 | H4: =(VLOOKUP('15.01'!P4,'15.01'!$AM$4:$AO$55,2,FALSE))*IF('15.01'!AS$4="是",'15.01'!$AY$4,'15.01'!$AY$3) -> 0 | I4: =(VLOOKUP('15.01'!Q4,'15.01'!$AM$4:$AO$55,2,FALSE))*IF('15.01'!AT$4="是",'15.01'!$AY$4,'15.01'!$AY$3) -> 150 | J4: =(VLOOKUP('15.01'!R4,'15.01'!$AM$4:$AO$55,2,FALSE))*IF('15.01'!AU$4="是",'15.01'!$AY$4,'15.01'!$AY$3) -> 150 | K4: =(VLOOKUP('15.01'!S4,'15.01'!$AM$4:$AO$55,2,FALSE))*IF('15.01'!AV$4="是",'15.01'!$AY$4,'15.01'!$AY$3) -> 150 | L4: =(VLOOKUP('15.01'!T4,'15.01'!$AM$4:$AO$55,2,FALSE))*IF('15.01'!AW$4="是",'15.01'!$AY$4,'15.01'!$AY$3) -> 150 | M4: =(VLOOKUP('15.01'!U4,'15.01'!$AM$4:$AO$55,2,FALSE))*IF('15.01'!AX$4="是",'15.01'!$AY$4,'15.01'!$AY$3) -> 150 | ... X4: =(VLOOKUP('15.01'!AF4,'15.01'!$AM$4:$AO$55,2,FALSE))*IF('15.01'!BI$4="是",'15.01'!$AY$4,'15.01'!$AY$3) -> 0
A5: =(VLOOKUP('15.01'!I5,'15.01'!$AM$4:$AO$55,2,FALSE))*IF('15.01'!AK$4="是",'15.01'!$AY$4,'15.01'!$AY$3) -> 0 | B5: =(VLOOKUP('15.01'!J5,'15.01'!$AM$4:$AO$55,2,FALSE))*IF('15.01'!AL$4="是",'15.01'!$AY$4,'15.01'!$AY$3) -> 0 | C5: =(VLOOKUP('15.01'!K5,'15.01'!$AM$4:$AO$55,2,FALSE))*IF('15.01'!AM$4="是",'15.01'!$AY$4,'15.01'!$AY$3) -> 0 | D5: =(VLOOKUP('15.01'!L5,'15.01'!$AM$4:$AO$55,2,FALSE))*IF('15.01'!AN$4="是",'15.01'!$AY$4,'15.01'!$AY$3) -> 0 | E5: =(VLOOKUP('15.01'!M5,'15.01'!$AM$4:$AO$55,2,FALSE))*IF('15.01'!AO$4="是",'15.01'!$AY$4,'15.01'!$AY$3) -> 0 | F5: =(VLOOKUP('15.01'!N5,'15.01'!$AM$4:$AO$55,2,FALSE))*IF('15.01'!AQ$4="是",'15.01'!$AY$4,'15.01'!$AY$3) -> 0 | G5: =(VLOOKUP('15.01'!O5,'15.01'!$AM$4:$AO$55,2,FALSE))*IF('15.01'!AR$4="是",'15.01'!$AY$4,'15.01'!$AY$3) -> 0 | H5: =(VLOOKUP('15.01'!P5,'15.01'!$AM$4:$AO$55,2,FALSE))*IF('15.01'!AS$4="是",'15.01'!$AY$4,'15.01'!$AY$3) -> 0 | I5: =(VLOOKUP('15.01'!Q5,'15.01'!$AM$4:$AO$55,2,FALSE))*IF('15.01'!AT$4="是",'15.01'!$AY$4,'15.01'!$AY$3) -> 150 | J5: =(VLOOKUP('15.01'!R5,'15.01'!$AM$4:$AO$55,2,FALSE))*IF('15.01'!AU$4="是",'15.01'!$AY$4,'15.01'!$AY$3) -> 50 | K5: =(VLOOKUP('15.01'!S5,'15.01'!$AM$4:$AO$55,2,FALSE))*IF('15.01'!AV$4="是",'15.01'!$AY$4,'15.01'!$AY$3) -> 150 | L5: =(VLOOKUP('15.01'!T5,'15.01'!$AM$4:$AO$55,2,FALSE))*IF('15.01'!AW$4="是",'15.01'!$AY$4,'15.01'!$AY$3) -> 150 | M5: =(VLOOKUP('15.01'!U5,'15.01'!$AM$4:$AO$55,2,FALSE))*IF('15.01'!AX$4="是",'15.01'!$AY$4,'15.01'!$AY$3) -> 150 | ... X5: =(VLOOKUP('15.01'!AF5,'15.01'!$AM$4:$AO$55,2,FALSE))*IF('15.01'!BI$4="是",'15.01'!$AY$4,'15.01'!$AY$3) -> 160
A6: =(VLOOKUP('15.01'!I6,'15.01'!$AM$4:$AO$55,2,FALSE))*IF('15.01'!AK$4="是",'15.01'!$AY$4,'15.01'!$AY$3) -> 0 | B6: =(VLOOKUP('15.01'!J6,'15.01'!$AM$4:$AO$55,2,FALSE))*IF('15.01'!AL$4="是",'15.01'!$AY$4,'15.01'!$AY$3) -> 0 | C6: =(VLOOKUP('15.01'!K6,'15.01'!$AM$4:$AO$55,2,FALSE))*IF('15.01'!AM$4="是",'15.01'!$AY$4,'15.01'!$AY$3) -> 0 | D6: =(VLOOKUP('15.01'!L6,'15.01'!$AM$4:$AO$55,2,FALSE))*IF('15.01'!AN$4="是",'15.01'!$AY$4,'15.01'!$AY$3) -> 0 | E6: =(VLOOKUP('15.01'!M6,'15.01'!$AM$4:$AO$55,2,FALSE))*IF('15.01'!AO$4="是",'15.01'!$AY$4,'15.01'!$AY$3) -> 0 | F6: =(VLOOKUP('15.01'!N6,'15.01'!$AM$4:$AO$55,2,FALSE))*IF('15.01'!AQ$4="是",'15.01'!$AY$4,'15.01'!$AY$3) -> 0 | G6: =(VLOOKUP('15.01'!O6,'15.01'!$AM$4:$AO$55,2,FALSE))*IF('15.01'!AR$4="是",'15.01'!$AY$4,'15.01'!$AY$3) -> 0 | H6: =(VLOOKUP('15.01'!P6,'15.01'!$AM$4:$AO$55,2,FALSE))*IF('15.01'!AS$4="是",'15.01'!$AY$4,'15.01'!$AY$3) -> 0 | I6: =(VLOOKUP('15.01'!Q6,'15.01'!$AM$4:$AO$55,2,FALSE))*IF('15.01'!AT$4="是",'15.01'!$AY$4,'15.01'!$AY$3) -> 150 | J6: =(VLOOKUP('15.01'!R6,'15.01'!$AM$4:$AO$55,2,FALSE))*IF('15.01'!AU$4="是",'15.01'!$AY$4,'15.01'!$AY$3) -> 150 | K6: =(VLOOKUP('15.01'!S6,'15.01'!$AM$4:$AO$55,2,FALSE))*IF('15.01'!AV$4="是",'15.01'!$AY$4,'15.01'!$AY$3) -> 160 | L6: =(VLOOKUP('15.01'!T6,'15.01'!$AM$4:$AO$55,2,FALSE))*IF('15.01'!AW$4="是",'15.01'!$AY$4,'15.01'!$AY$3) -> 160 | M6: =(VLOOKUP('15.01'!U6,'15.01'!$AM$4:$AO$55,2,FALSE))*IF('15.01'!AX$4="是",'15.01'!$AY$4,'15.01'!$AY$3) -> -150 | ... X6: =(VLOOKUP('15.01'!AF6,'15.01'!$AM$4:$AO$55,2,FALSE))*IF('15.01'!BI$4="是",'15.01'!$AY$4,'15.01'!$AY$3) -> 170
A7: =(VLOOKUP('15.01'!I7,'15.01'!$AM$4:$AO$55,2,FALSE))*IF('15.01'!AK$4="是",'15.01'!$AY$4,'15.01'!$AY$3) -> 0 | B7: =(VLOOKUP('15.01'!J7,'15.01'!$AM$4:$AO$55,2,FALSE))*IF('15.01'!AL$4="是",'15.01'!$AY$4,'15.01'!$AY$3) -> 0 | C7: =(VLOOKUP('15.01'!K7,'15.01'!$AM$4:$AO$55,2,FALSE))*IF('15.01'!AM$4="是",'15.01'!$AY$4,'15.01'!$AY$3) -> 0 | D7: =(VLOOKUP('15.01'!L7,'15.01'!$AM$4:$AO$55,2,FALSE))*IF('15.01'!AN$4="是",'15.01'!$AY$4,'15.01'!$AY$3) -> 0 | E7: =(VLOOKUP('15.01'!M7,'15.01'!$AM$4:$AO$55,2,FALSE))*IF('15.01'!AO$4="是",'15.01'!$AY$4,'15.01'!$AY$3) -> 0 | F7: =(VLOOKUP('15.01'!N7,'15.01'!$AM$4:$AO$55,2,FALSE))*IF('15.01'!AQ$4="是",'15.01'!$AY$4,'15.01'!$AY$3) -> 0 | G7: =(VLOOKUP('15.01'!O7,'15.01'!$AM$4:$AO$55,2,FALSE))*IF('15.01'!AR$4="是",'15.01'!$AY$4,'15.01'!$AY$3) -> 0 | H7: =(VLOOKUP('15.01'!P7,'15.01'!$AM$4:$AO$55,2,FALSE))*IF('15.01'!AS$4="是",'15.01'!$AY$4,'15.01'!$AY$3) -> 0 | I7: =(VLOOKUP('15.01'!Q7,'15.01'!$AM$4:$AO$55,2,FALSE))*IF('15.01'!AT$4="是",'15.01'!$AY$4,'15.01'!$AY$3) -> 160 | J7: =(VLOOKUP('15.01'!R7,'15.01'!$AM$4:$AO$55,2,FALSE))*IF('15.01'!AU$4="是",'15.01'!$AY$4,'15.01'!$AY$3) -> 160 | K7: =(VLOOKUP('15.01'!S7,'15.01'!$AM$4:$AO$55,2,FALSE))*IF('15.01'!AV$4="是",'15.01'!$AY$4,'15.01'!$AY$3) -> 50 | L7: =(VLOOKUP('15.01'!T7,'15.01'!$AM$4:$AO$55,2,FALSE))*IF('15.01'!AW$4="是",'15.01'!$AY$4,'15.01'!$AY$3) -> 160 | M7: =(VLOOKUP('15.01'!U7,'15.01'!$AM$4:$AO$55,2,FALSE))*IF('15.01'!AX$4="是",'15.01'!$AY$4,'15.01'!$AY$3) -> 150 | ... X7: =(VLOOKUP('15.01'!AF7,'15.01'!$AM$4:$AO$55,2,FALSE))*IF('15.01'!BI$4="是",'15.01'!$AY$4,'15.01'!$AY$3) -> 170
A8: =(VLOOKUP('15.01'!I8,'15.01'!$AM$4:$AO$55,2,FALSE))*IF('15.01'!AK$4="是",'15.01'!$AY$4,'15.01'!$AY$3) -> 0 | B8: =(VLOOKUP('15.01'!J8,'15.01'!$AM$4:$AO$55,2,FALSE))*IF('15.01'!AL$4="是",'15.01'!$AY$4,'15.01'!$AY$3) -> 0 | C8: =(VLOOKUP('15.01'!K8,'15.01'!$AM$4:$AO$55,2,FALSE))*IF('15.01'!AM$4="是",'15.01'!$AY$4,'15.01'!$AY$3) -> 0 | D8: =(VLOOKUP('15.01'!L8,'15.01'!$AM$4:$AO$55,2,FALSE))*IF('15.01'!AN$4="是",'15.01'!$AY$4,'15.01'!$AY$3) -> 0 | E8: =(VLOOKUP('15.01'!M8,'15.01'!$AM$4:$AO$55,2,FALSE))*IF('15.01'!AO$4="是",'15.01'!$AY$4,'15.01'!$AY$3) -> 0 | F8: =(VLOOKUP('15.01'!N8,'15.01'!$AM$4:$AO$55,2,FALSE))*IF('15.01'!AQ$4="是",'15.01'!$AY$4,'15.01'!$AY$3) -> 0 | G8: =(VLOOKUP('15.01'!O8,'15.01'!$AM$4:$AO$55,2,FALSE))*IF('15.01'!AR$4="是",'15.01'!$AY$4,'15.01'!$AY$3) -> 0 | H8: =(VLOOKUP('15.01'!P8,'15.01'!$AM$4:$AO$55,2,FALSE))*IF('15.01'!AS$4="是",'15.01'!$AY$4,'15.01'!$AY$3) -> 0 | I8: =(VLOOKUP('15.01'!Q8,'15.01'!$AM$4:$AO$55,2,FALSE))*IF('15.01'!AT$4="是",'15.01'!$AY$4,'15.01'!$AY$3) -> 160 | J8: =(VLOOKUP('15.01'!R8,'15.01'!$AM$4:$AO$55,2,FALSE))*IF('15.01'!AU$4="是",'15.01'!$AY$4,'15.01'!$AY$3) -> 160 | K8: =(VLOOKUP('15.01'!S8,'15.01'!$AM$4:$AO$55,2,FALSE))*IF('15.01'!AV$4="是",'15.01'!$AY$4,'15.01'!$AY$3) -> 180 | L8: =(VLOOKUP('15.01'!T8,'15.01'!$AM$4:$AO$55,2,FALSE))*IF('15.01'!AW$4="是",'15.01'!$AY$4,'15.01'!$AY$3) -> 180 | M8: =(VLOOKUP('15.01'!U8,'15.01'!$AM$4:$AO$55,2,FALSE))*IF('15.01'!AX$4="是",'15.01'!$AY$4,'15.01'!$AY$3) -> 180 | ... X8: =(VLOOKUP('15.01'!AF8,'15.01'!$AM$4:$AO$55,2,FALSE))*IF('15.01'!BI$4="是",'15.01'!$AY$4,'15.01'!$AY$3) -> 0
A9: =(VLOOKUP('15.01'!I9,'15.01'!$AM$4:$AO$55,2,FALSE))*IF('15.01'!AK$4="是",'15.01'!$AY$4,'15.01'!$AY$3) -> 0 | B9: =(VLOOKUP('15.01'!J9,'15.01'!$AM$4:$AO$55,2,FALSE))*IF('15.01'!AL$4="是",'15.01'!$AY$4,'15.01'!$AY$3) -> 0 | C9: =(VLOOKUP('15.01'!K9,'15.01'!$AM$4:$AO$55,2,FALSE))*IF('15.01'!AM$4="是",'15.01'!$AY$4,'15.01'!$AY$3) -> 0 | D9: =(VLOOKUP('15.01'!L9,'15.01'!$AM$4:$AO$55,2,FALSE))*IF('15.01'!AN$4="是",'15.01'!$AY$4,'15.01'!$AY$3) -> 0 | E9: =(VLOOKUP('15.01'!M9,'15.01'!$AM$4:$AO$55,2,FALSE))*IF('15.01'!AO$4="是",'15.01'!$AY$4,'15.01'!$AY$3) -> 0 | F9: =(VLOOKUP('15.01'!N9,'15.01'!$AM$4:$AO$55,2,FALSE))*IF('15.01'!AQ$4="是",'15.01'!$AY$4,'15.01'!$AY$3) -> 0 | G9: =(VLOOKUP('15.01'!O9,'15.01'!$AM$4:$AO$55,2,FALSE))*IF('15.01'!AR$4="是",'15.01'!$AY$4,'15.01'!$AY$3) -> 0 | H9: =(VLOOKUP('15.01'!P9,'15.01'!$AM$4:$AO$55,2,FALSE))*IF('15.01'!AS$4="是",'15.01'!$AY$4,'15.01'!$AY$3) -> 0 | I9: =(VLOOKUP('15.01'!Q9,'15.01'!$AM$4:$AO$55,2,FALSE))*IF('15.01'!AT$4="是",'15.01'!$AY$4,'15.01'!$AY$3) -> 250 | J9: =(VLOOKUP('15.01'!R9,'15.01'!$AM$4:$AO$55,2,FALSE))*IF('15.01'!AU$4="是",'15.01'!$AY$4,'15.01'!$AY$3) -> 0 | K9: =(VLOOKUP('15.01'!S9,'15.01'!$AM$4:$AO$55,2,FALSE))*IF('15.01'!AV$4="是",'15.01'!$AY$4,'15.01'!$AY$3) -> 0 | L9: =(VLOOKUP('15.01'!T9,'15.01'!$AM$4:$AO$55,2,FALSE))*IF('15.01'!AW$4="是",'15.01'!$AY$4,'15.01'!$AY$3) -> 0 | M9: =(VLOOKUP('15.01'!U9,'15.01'!$AM$4:$AO$55,2,FALSE))*IF('15.01'!AX$4="是",'15.01'!$AY$4,'15.01'!$AY$3) -> 0 | ... X9: =(VLOOKUP('15.01'!AF9,'15.01'!$AM$4:$AO$55,2,FALSE))*IF('15.01'!BI$4="是",'15.01'!$AY$4,'15.01'!$AY$3) -> 0
A10: =(VLOOKUP('15.01'!I10,'15.01'!$AM$4:$AO$55,2,FALSE))*IF('15.01'!AK$4="是",'15.01'!$AY$4,'15.01'!$AY$3) -> 0 | B10: =(VLOOKUP('15.01'!J10,'15.01'!$AM$4:$AO$55,2,FALSE))*IF('15.01'!AL$4="是",'15.01'!$AY$4,'15.01'!$AY$3) -> 0 | C10: =(VLOOKUP('15.01'!K10,'15.01'!$AM$4:$AO$55,2,FALSE))*IF('15.01'!AM$4="是",'15.01'!$AY$4,'15.01'!$AY$3) -> 0 | D10: =(VLOOKUP('15.01'!L10,'15.01'!$AM$4:$AO$55,2,FALSE))*IF('15.01'!AN$4="是",'15.01'!$AY$4,'15.01'!$AY$3) -> 0 | E10: =(VLOOKUP('15.01'!M10,'15.01'!$AM$4:$AO$55,2,FALSE))*IF('15.01'!AO$4="是",'15.01'!$AY$4,'15.01'!$AY$3) -> 0 | F10: =(VLOOKUP('15.01'!N10,'15.01'!$AM$4:$AO$55,2,FALSE))*IF('15.01'!AQ$4="是",'15.01'!$AY$4,'15.01'!$AY$3) -> 0 | G10: =(VLOOKUP('15.01'!O10,'15.01'!$AM$4:$AO$55,2,FALSE))*IF('15.01'!AR$4="是",'15.01'!$AY$4,'15.01'!$AY$3) -> 0 | H10: =(VLOOKUP('15.01'!P10,'15.01'!$AM$4:$AO$55,2,FALSE))*IF('15.01'!AS$4="是",'15.01'!$AY$4,'15.01'!$AY$3) -> 0 | I10: =(VLOOKUP('15.01'!Q10,'15.01'!$AM$4:$AO$55,2,FALSE))*IF('15.01'!AT$4="是",'15.01'!$AY$4,'15.01'!$AY$3) -> 0 | J10: =(VLOOKUP('15.01'!R10,'15.01'!$AM$4:$AO$55,2,FALSE))*IF('15.01'!AU$4="是",'15.01'!$AY$4,'15.01'!$AY$3) -> 0 | K10: =(VLOOKUP('15.01'!S10,'15.01'!$AM$4:$AO$55,2,FALSE))*IF('15.01'!AV$4="是",'15.01'!$AY$4,'15.01'!$AY$3) -> 0 | L10: =(VLOOKUP('15.01'!T10,'15.01'!$AM$4:$AO$55,2,FALSE))*IF('15.01'!AW$4="是",'15.01'!$AY$4,'15.01'!$AY$3) -> 0 | M10: =(VLOOKUP('15.01'!U10,'15.01'!$AM$4:$AO$55,2,FALSE))*IF('15.01'!AX$4="是",'15.01'!$AY$4,'15.01'!$AY$3) -> 0 | ... X10: =(VLOOKUP('15.01'!AF10,'15.01'!$AM$4:$AO$55,2,FALSE))*IF('15.01'!BI$4="是",'15.01'!$AY$4,'15.01'!$AY$3) -> 0
A11: =(VLOOKUP('15.01'!I11,'15.01'!$AM$4:$AO$55,2,FALSE))*IF('15.01'!AK$4="是",'15.01'!$AY$4,'15.01'!$AY$3) -> 0 | B11: =(VLOOKUP('15.01'!J11,'15.01'!$AM$4:$AO$55,2,FALSE))*IF('15.01'!AL$4="是",'15.01'!$AY$4,'15.01'!$AY$3) -> 0 | C11: =(VLOOKUP('15.01'!K11,'15.01'!$AM$4:$AO$55,2,FALSE))*IF('15.01'!AM$4="是",'15.01'!$AY$4,'15.01'!$AY$3) -> 0 | D11: =(VLOOKUP('15.01'!L11,'15.01'!$AM$4:$AO$55,2,FALSE))*IF('15.01'!AN$4="是",'15.01'!$AY$4,'15.01'!$AY$3) -> 0 | E11: =(VLOOKUP('15.01'!M11,'15.01'!$AM$4:$AO$55,2,FALSE))*IF('15.01'!AO$4="是",'15.01'!$AY$4,'15.01'!$AY$3) -> 0 | F11: =(VLOOKUP('15.01'!N11,'15.01'!$AM$4:$AO$55,2,FALSE))*IF('15.01'!AQ$4="是",'15.01'!$AY$4,'15.01'!$AY$3) -> 0 | G11: =(VLOOKUP('15.01'!O11,'15.01'!$AM$4:$AO$55,2,FALSE))*IF('15.01'!AR$4="是",'15.01'!$AY$4,'15.01'!$AY$3) -> 0 | H11: =(VLOOKUP('15.01'!P11,'15.01'!$AM$4:$AO$55,2,FALSE))*IF('15.01'!AS$4="是",'15.01'!$AY$4,'15.01'!$AY$3) -> 0 | I11: =(VLOOKUP('15.01'!Q11,'15.01'!$AM$4:$AO$55,2,FALSE))*IF('15.01'!AT$4="是",'15.01'!$AY$4,'15.01'!$AY$3) -> 0 | J11: =(VLOOKUP('15.01'!R11,'15.01'!$AM$4:$AO$55,2,FALSE))*IF('15.01'!AU$4="是",'15.01'!$AY$4,'15.01'!$AY$3) -> 0 | K11: =(VLOOKUP('15.01'!S11,'15.01'!$AM$4:$AO$55,2,FALSE))*IF('15.01'!AV$4="是",'15.01'!$AY$4,'15.01'!$AY$3) -> 0 | L11: =(VLOOKUP('15.01'!T11,'15.01'!$AM$4:$AO$55,2,FALSE))*IF('15.01'!AW$4="是",'15.01'!$AY$4,'15.01'!$AY$3) -> 0 | M11: =(VLOOKUP('15.01'!U11,'15.01'!$AM$4:$AO$55,2,FALSE))*IF('15.01'!AX$4="是",'15.01'!$AY$4,'15.01'!$AY$3) -> 0 | ... X11: =(VLOOKUP('15.01'!AF11,'15.01'!$AM$4:$AO$55,2,FALSE))*IF('15.01'!BI$4="是",'15.01'!$AY$4,'15.01'!$AY$3) -> 0
A12: =(VLOOKUP('15.01'!I12,'15.01'!$AM$4:$AO$55,2,FALSE))*IF('15.01'!AK$4="是",'15.01'!$AY$4,'15.01'!$AY$3) -> 0 | B12: =(VLOOKUP('15.01'!J12,'15.01'!$AM$4:$AO$55,2,FALSE))*IF('15.01'!AL$4="是",'15.01'!$AY$4,'15.01'!$AY$3) -> 0 | C12: =(VLOOKUP('15.01'!K12,'15.01'!$AM$4:$AO$55,2,FALSE))*IF('15.01'!AM$4="是",'15.01'!$AY$4,'15.01'!$AY$3) -> 0 | D12: =(VLOOKUP('15.01'!L12,'15.01'!$AM$4:$AO$55,2,FALSE))*IF('15.01'!AN$4="是",'15.01'!$AY$4,'15.01'!$AY$3) -> 0 | E12: =(VLOOKUP('15.01'!M12,'15.01'!$AM$4:$AO$55,2,FALSE))*IF('15.01'!AO$4="是",'15.01'!$AY$4,'15.01'!$AY$3) -> 0 | F12: =(VLOOKUP('15.01'!N12,'15.01'!$AM$4:$AO$55,2,FALSE))*IF('15.01'!AQ$4="是",'15.01'!$AY$4,'15.01'!$AY$3) -> 0 | G12: =(VLOOKUP('15.01'!O12,'15.01'!$AM$4:$AO$55,2,FALSE))*IF('15.01'!AR$4="是",'15.01'!$AY$4,'15.01'!$AY$3) -> 0 | H12: =(VLOOKUP('15.01'!P12,'15.01'!$AM$4:$AO$55,2,FALSE))*IF('15.01'!AS$4="是",'15.01'!$AY$4,'15.01'!$AY$3) -> 0 | I12: =(VLOOKUP('15.01'!Q12,'15.01'!$AM$4:$AO$55,2,FALSE))*IF('15.01'!AT$4="是",'15.01'!$AY$4,'15.01'!$AY$3) -> 0 | J12: =(VLOOKUP('15.01'!R12,'15.01'!$AM$4:$AO$55,2,FALSE))*IF('15.01'!AU$4="是",'15.01'!$AY$4,'15.01'!$AY$3) -> 0 | K12: =(VLOOKUP('15.01'!S12,'15.01'!$AM$4:$AO$55,2,FALSE))*IF('15.01'!AV$4="是",'15.01'!$AY$4,'15.01'!$AY$3) -> 0 | L12: =(VLOOKUP('15.01'!T12,'15.01'!$AM$4:$AO$55,2,FALSE))*IF('15.01'!AW$4="是",'15.01'!$AY$4,'15.01'!$AY$3) -> 0 | M12: =(VLOOKUP('15.01'!U12,'15.01'!$AM$4:$AO$55,2,FALSE))*IF('15.01'!AX$4="是",'15.01'!$AY$4,'15.01'!$AY$3) -> 0 | ... X12: =(VLOOKUP('15.01'!AF12,'15.01'!$AM$4:$AO$55,2,FALSE))*IF('15.01'!BI$4="是",'15.01'!$AY$4,'15.01'!$AY$3) -> 0
A13: =(VLOOKUP('15.01'!I13,'15.01'!$AM$4:$AO$55,2,FALSE))*IF('15.01'!AK$4="是",'15.01'!$AY$4,'15.01'!$AY$3) -> 0 | B13: =(VLOOKUP('15.01'!J13,'15.01'!$AM$4:$AO$55,2,FALSE))*IF('15.01'!AL$4="是",'15.01'!$AY$4,'15.01'!$AY$3) -> 0 | C13: =(VLOOKUP('15.01'!K13,'15.01'!$AM$4:$AO$55,2,FALSE))*IF('15.01'!AM$4="是",'15.01'!$AY$4,'15.01'!$AY$3) -> 0 | D13: =(VLOOKUP('15.01'!L13,'15.01'!$AM$4:$AO$55,2,FALSE))*IF('15.01'!AN$4="是",'15.01'!$AY$4,'15.01'!$AY$3) -> 0 | E13: =(VLOOKUP('15.01'!M13,'15.01'!$AM$4:$AO$55,2,FALSE))*IF('15.01'!AO$4="是",'15.01'!$AY$4,'15.01'!$AY$3) -> 0 | F13: =(VLOOKUP('15.01'!N13,'15.01'!$AM$4:$AO$55,2,FALSE))*IF('15.01'!AQ$4="是",'15.01'!$AY$4,'15.01'!$AY$3) -> 0 | G13: =(VLOOKUP('15.01'!O13,'15.01'!$AM$4:$AO$55,2,FALSE))*IF('15.01'!AR$4="是",'15.01'!$AY$4,'15.01'!$AY$3) -> 0 | H13: =(VLOOKUP('15.01'!P13,'15.01'!$AM$4:$AO$55,2,FALSE))*IF('15.01'!AS$4="是",'15.01'!$AY$4,'15.01'!$AY$3) -> 0 | I13: =(VLOOKUP('15.01'!Q13,'15.01'!$AM$4:$AO$55,2,FALSE))*IF('15.01'!AT$4="是",'15.01'!$AY$4,'15.01'!$AY$3) -> 0 | J13: =(VLOOKUP('15.01'!R13,'15.01'!$AM$4:$AO$55,2,FALSE))*IF('15.01'!AU$4="是",'15.01'!$AY$4,'15.01'!$AY$3) -> 0 | K13: =(VLOOKUP('15.01'!S13,'15.01'!$AM$4:$AO$55,2,FALSE))*IF('15.01'!AV$4="是",'15.01'!$AY$4,'15.01'!$AY$3) -> 0 | L13: =(VLOOKUP('15.01'!T13,'15.01'!$AM$4:$AO$55,2,FALSE))*IF('15.01'!AW$4="是",'15.01'!$AY$4,'15.01'!$AY$3) -> 0 | M13: =(VLOOKUP('15.01'!U13,'15.01'!$AM$4:$AO$55,2,FALSE))*IF('15.01'!AX$4="是",'15.01'!$AY$4,'15.01'!$AY$3) -> 0 | ... X13: =(VLOOKUP('15.01'!AF13,'15.01'!$AM$4:$AO$55,2,FALSE))*IF('15.01'!BI$4="是",'15.01'!$AY$4,'15.01'!$AY$3) -> 0
A14: =(VLOOKUP('15.01'!I14,'15.01'!$AM$4:$AO$55,2,FALSE))*IF('15.01'!AK$4="是",'15.01'!$AY$4,'15.01'!$AY$3) -> 0 | B14: =(VLOOKUP('15.01'!J14,'15.01'!$AM$4:$AO$55,2,FALSE))*IF('15.01'!AL$4="是",'15.01'!$AY$4,'15.01'!$AY$3) -> 0 | C14: =(VLOOKUP('15.01'!K14,'15.01'!$AM$4:$AO$55,2,FALSE))*IF('15.01'!AM$4="是",'15.01'!$AY$4,'15.01'!$AY$3) -> 0 | D14: =(VLOOKUP('15.01'!L14,'15.01'!$AM$4:$AO$55,2,FALSE))*IF('15.01'!AN$4="是",'15.01'!$AY$4,'15.01'!$AY$3) -> 0 | E14: =(VLOOKUP('15.01'!M14,'15.01'!$AM$4:$AO$55,2,FALSE))*IF('15.01'!AO$4="是",'15.01'!$AY$4,'15.01'!$AY$3) -> 0 | F14: =(VLOOKUP('15.01'!N14,'15.01'!$AM$4:$AO$55,2,FALSE))*IF('15.01'!AQ$4="是",'15.01'!$AY$4,'15.01'!$AY$3) -> 0 | G14: =(VLOOKUP('15.01'!O14,'15.01'!$AM$4:$AO$55,2,FALSE))*IF('15.01'!AR$4="是",'15.01'!$AY$4,'15.01'!$AY$3) -> 0 | H14: =(VLOOKUP('15.01'!P14,'15.01'!$AM$4:$AO$55,2,FALSE))*IF('15.01'!AS$4="是",'15.01'!$AY$4,'15.01'!$AY$3) -> 0 | I14: =(VLOOKUP('15.01'!Q14,'15.01'!$AM$4:$AO$55,2,FALSE))*IF('15.01'!AT$4="是",'15.01'!$AY$4,'15.01'!$AY$3) -> 0 | J14: =(VLOOKUP('15.01'!R14,'15.01'!$AM$4:$AO$55,2,FALSE))*IF('15.01'!AU$4="是",'15.01'!$AY$4,'15.01'!$AY$3) -> 0 | K14: =(VLOOKUP('15.01'!S14,'15.01'!$AM$4:$AO$55,2,FALSE))*IF('15.01'!AV$4="是",'15.01'!$AY$4,'15.01'!$AY$3) -> 0 | L14: =(VLOOKUP('15.01'!T14,'15.01'!$AM$4:$AO$55,2,FALSE))*IF('15.01'!AW$4="是",'15.01'!$AY$4,'15.01'!$AY$3) -> 0 | M14: =(VLOOKUP('15.01'!U14,'15.01'!$AM$4:$AO$55,2,FALSE))*IF('15.01'!AX$4="是",'15.01'!$AY$4,'15.01'!$AY$3) -> 0 | ... X14: =(VLOOKUP('15.01'!AF14,'15.01'!$AM$4:$AO$55,2,FALSE))*IF('15.01'!BI$4="是",'15.01'!$AY$4,'15.01'!$AY$3) -> 0
A15: =(VLOOKUP('15.01'!I15,'15.01'!$AM$4:$AO$55,2,FALSE))*IF('15.01'!AK$4="是",'15.01'!$AY$4,'15.01'!$AY$3) -> 0 | B15: =(VLOOKUP('15.01'!J15,'15.01'!$AM$4:$AO$55,2,FALSE))*IF('15.01'!AL$4="是",'15.01'!$AY$4,'15.01'!$AY$3) -> 0 | C15: =(VLOOKUP('15.01'!K15,'15.01'!$AM$4:$AO$55,2,FALSE))*IF('15.01'!AM$4="是",'15.01'!$AY$4,'15.01'!$AY$3) -> 0 | D15: =(VLOOKUP('15.01'!L15,'15.01'!$AM$4:$AO$55,2,FALSE))*IF('15.01'!AN$4="是",'15.01'!$AY$4,'15.01'!$AY$3) -> 0 | E15: =(VLOOKUP('15.01'!M15,'15.01'!$AM$4:$AO$55,2,FALSE))*IF('15.01'!AO$4="是",'15.01'!$AY$4,'15.01'!$AY$3) -> 0 | F15: =(VLOOKUP('15.01'!N15,'15.01'!$AM$4:$AO$55,2,FALSE))*IF('15.01'!AQ$4="是",'15.01'!$AY$4,'15.01'!$AY$3) -> 0 | G15: =(VLOOKUP('15.01'!O15,'15.01'!$AM$4:$AO$55,2,FALSE))*IF('15.01'!AR$4="是",'15.01'!$AY$4,'15.01'!$AY$3) -> 0 | H15: =(VLOOKUP('15.01'!P15,'15.01'!$AM$4:$AO$55,2,FALSE))*IF('15.01'!AS$4="是",'15.01'!$AY$4,'15.01'!$AY$3) -> 0 | I15: =(VLOOKUP('15.01'!Q15,'15.01'!$AM$4:$AO$55,2,FALSE))*IF('15.01'!AT$4="是",'15.01'!$AY$4,'15.01'!$AY$3) -> 0 | J15: =(VLOOKUP('15.01'!R15,'15.01'!$AM$4:$AO$55,2,FALSE))*IF('15.01'!AU$4="是",'15.01'!$AY$4,'15.01'!$AY$3) -> 0 | K15: =(VLOOKUP('15.01'!S15,'15.01'!$AM$4:$AO$55,2,FALSE))*IF('15.01'!AV$4="是",'15.01'!$AY$4,'15.01'!$AY$3) -> 0 | L15: =(VLOOKUP('15.01'!T15,'15.01'!$AM$4:$AO$55,2,FALSE))*IF('15.01'!AW$4="是",'15.01'!$AY$4,'15.01'!$AY$3) -> 0 | M15: =(VLOOKUP('15.01'!U15,'15.01'!$AM$4:$AO$55,2,FALSE))*IF('15.01'!AX$4="是",'15.01'!$AY$4,'15.01'!$AY$3) -> 0 | ... X15: =(VLOOKUP('15.01'!AF15,'15.01'!$AM$4:$AO$55,2,FALSE))*IF('15.01'!BI$4="是",'15.01'!$AY$4,'15.01'!$AY$3) -> 0
... A93: =(VLOOKUP('15.01'!I93,'15.01'!$AM$4:$AO$55,2,FALSE))*IF('15.01'!AK$4="是",'15.01'!$AY$4,'15.01'!$AY$3) -> 0 | B93: =(VLOOKUP('15.01'!J93,'15.01'!$AM$4:$AO$55,2,FALSE))*IF('15.01'!AL$4="是",'15.01'!$AY$4,'15.01'!$AY$3) -> 0 | C93: =(VLOOKUP('15.01'!K93,'15.01'!$AM$4:$AO$55,2,FALSE))*IF('15.01'!AM$4="是",'15.01'!$AY$4,'15.01'!$AY$3) -> 160 | D93: =(VLOOKUP('15.01'!L93,'15.01'!$AM$4:$AO$55,2,FALSE))*IF('15.01'!AN$4="是",'15.01'!$AY$4,'15.01'!$AY$3) -> 50 | E93: =(VLOOKUP('15.01'!M93,'15.01'!$AM$4:$AO$55,2,FALSE))*IF('15.01'!AO$4="是",'15.01'!$AY$4,'15.01'!$AY$3) -> 0 | F93: =(VLOOKUP('15.01'!N93,'15.01'!$AM$4:$AO$55,2,FALSE))*IF('15.01'!AQ$4="是",'15.01'!$AY$4,'15.01'!$AY$3) -> 0 | G93: =(VLOOKUP('15.01'!O93,'15.01'!$AM$4:$AO$55,2,FALSE))*IF('15.01'!AR$4="是",'15.01'!$AY$4,'15.01'!$AY$3) -> 0 | H93: =(VLOOKUP('15.01'!P93,'15.01'!$AM$4:$AO$55,2,FALSE))*IF('15.01'!AS$4="是",'15.01'!$AY$4,'15.01'!$AY$3) -> 0 | I93: =(VLOOKUP('15.01'!Q93,'15.01'!$AM$4:$AO$55,2,FALSE))*IF('15.01'!AT$4="是",'15.01'!$AY$4,'15.01'!$AY$3) -> 190 | J93: =(VLOOKUP('15.01'!R93,'15.01'!$AM$4:$AO$55,2,FALSE))*IF('15.01'!AU$4="是",'15.01'!$AY$4,'15.01'!$AY$3) -> 190 | K93: =(VLOOKUP('15.01'!S93,'15.01'!$AM$4:$AO$55,2,FALSE))*IF('15.01'!AV$4="是",'15.01'!$AY$4,'15.01'!$AY$3) -> 190 | L93: =(VLOOKUP('15.01'!T93,'15.01'!$AM$4:$AO$55,2,FALSE))*IF('15.01'!AW$4="是",'15.01'!$AY$4,'15.01'!$AY$3) -> 190 | M93: =(VLOOKUP('15.01'!U93,'15.01'!$AM$4:$AO$55,2,FALSE))*IF('15.01'!AX$4="是",'15.01'!$AY$4,'15.01'!$AY$3) -> 190 | ... X93: =(VLOOKUP('15.01'!AF93,'15.01'!$AM$4:$AO$55,2,FALSE))*IF('15.01'!BI$4="是",'15.01'!$AY$4,'15.01'!$AY$3) -> 0
A94: =(VLOOKUP('15.01'!#REF!,'15.01'!$AM$4:$AO$55,2,FALSE))*IF('15.01'!AK$4="是",'15.01'!$AY$4,'15.01'!$AY$3) -> #REF! | B94: =(VLOOKUP('15.01'!#REF!,'15.01'!$AM$4:$AO$55,2,FALSE))*IF('15.01'!AL$4="是",'15.01'!$AY$4,'15.01'!$AY$3) -> #REF! | C94: =(VLOOKUP('15.01'!#REF!,'15.01'!$AM$4:$AO$55,2,FALSE))*IF('15.01'!AM$4="是",'15.01'!$AY$4,'15.01'!$AY$3) -> #REF! | D94: =(VLOOKUP('15.01'!#REF!,'15.01'!$AM$4:$AO$55,2,FALSE))*IF('15.01'!AN$4="是",'15.01'!$AY$4,'15.01'!$AY$3) -> #REF! | E94: =(VLOOKUP('15.01'!#REF!,'15.01'!$AM$4:$AO$55,2,FALSE))*IF('15.01'!AO$4="是",'15.01'!$AY$4,'15.01'!$AY$3) -> #REF! | F94: =(VLOOKUP('15.01'!#REF!,'15.01'!$AM$4:$AO$55,2,FALSE))*IF('15.01'!AQ$4="是",'15.01'!$AY$4,'15.01'!$AY$3) -> #REF! | G94: =(VLOOKUP('15.01'!#REF!,'15.01'!$AM$4:$AO$55,2,FALSE))*IF('15.01'!AR$4="是",'15.01'!$AY$4,'15.01'!$AY$3) -> #REF! | H94: =(VLOOKUP('15.01'!#REF!,'15.01'!$AM$4:$AO$55,2,FALSE))*IF('15.01'!AS$4="是",'15.01'!$AY$4,'15.01'!$AY$3) -> #REF! | I94: =(VLOOKUP('15.01'!#REF!,'15.01'!$AM$4:$AO$55,2,FALSE))*IF('15.01'!AT$4="是",'15.01'!$AY$4,'15.01'!$AY$3) -> #REF! | J94: =(VLOOKUP('15.01'!#REF!,'15.01'!$AM$4:$AO$55,2,FALSE))*IF('15.01'!AU$4="是",'15.01'!$AY$4,'15.01'!$AY$3) -> #REF! | K94: =(VLOOKUP('15.01'!#REF!,'15.01'!$AM$4:$AO$55,2,FALSE))*IF('15.01'!AV$4="是",'15.01'!$AY$4,'15.01'!$AY$3) -> #REF! | L94: =(VLOOKUP('15.01'!#REF!,'15.01'!$AM$4:$AO$55,2,FALSE))*IF('15.01'!AW$4="是",'15.01'!$AY$4,'15.01'!$AY$3) -> #REF! | M94: =(VLOOKUP('15.01'!#REF!,'15.01'!$AM$4:$AO$55,2,FALSE))*IF('15.01'!AX$4="是",'15.01'!$AY$4,'15.01'!$AY$3) -> #REF! | ... X94: =(VLOOKUP('15.01'!#REF!,'15.01'!$AM$4:$AO$55,2,FALSE))*IF('15.01'!BI$4="是",'15.01'!$AY$4,'15.01'!$AY$3) -> #REF!

Sheet 经验
A2: 队伍一 风 | C2: 步数 | D2: =COUNTIF(A4:H94,"<>空") -> 728 | E2: (不算跳步和传送) | I2: 队伍二 雷 | K2: 步数 | L2: =COUNTIF(I4:P94,"<>空") -> 728 | M2: (不算跳步和传送) | Q2: 队伍三 | S2: 总步数 | T2: =COUNTIF(Q4:X94,"<>空") -> 728 | U2: (不算跳步和传送)
A3: 1 | B3: 2 | C3: 3 | D3: 4 | E3: 5 | F3: 6 | G3: 7 | H3: 8 | I3: 1 | J3: 2 | K3: 3 | L3: 4 | M3: 5 | N3: 6 | O3: 7 | P3: 8 | Q3: 1 | R3: 2 | S3: 3 | T3: 4 | U3: 5 | V3: 6 | W3: 7 | X3: 8
A4: =(VLOOKUP('15.01'!I4,'15.01'!$AM$4:$AO$55,3,FALSE)) -> 35 | B4: =(VLOOKUP('15.01'!J4,'15.01'!$AM$4:$AO$55,3,FALSE)) -> 35 | C4: =(VLOOKUP('15.01'!K4,'15.01'!$AM$4:$AO$55,3,FALSE)) -> 35 | D4: =(VLOOKUP('15.01'!L4,'15.01'!$AM$4:$AO$55,3,FALSE)) -> 35 | E4: =(VLOOKUP('15.01'!M4,'15.01'!$AM$4:$AO$55,3,FALSE)) -> 35 | F4: =(VLOOKUP('15.01'!N4,'15.01'!$AM$4:$AO$55,3,FALSE)) -> 30 | G4: =(VLOOKUP('15.01'!O4,'15.01'!$AM$4:$AO$55,3,FALSE)) -> 0 | H4: =(VLOOKUP('15.01'!P4,'15.01'!$AM$4:$AO$55,3,FALSE)) -> 0 | ... X4: =(VLOOKUP('15.01'!AF4,'15.01'!$AM$4:$AO$55,3,FALSE)) -> 0
A5: =(VLOOKUP('15.01'!I5,'15.01'!$AM$4:$AO$55,3,FALSE)) -> 0 | B5: =(VLOOKUP('15.01'!J5,'15.01'!$AM$4:$AO$55,3,FALSE)) -> 0 | C5: =(VLOOKUP('15.01'!K5,'15.01'!$AM$4:$AO$55,3,FALSE)) -> 0 | D5: =(VLOOKUP('15.01'!L5,'15.01'!$AM$4:$AO$55,3,FALSE)) -> 0 | E5: =(VLOOKUP('15.01'!M5,'15.01'!$AM$4:$AO$55,3,FALSE)) -> 0 | F5: =(VLOOKUP('15.01'!N5,'15.01'!$AM$4:$AO$55,3,FALSE)) -> 0 | G5: =(VLOOKUP('15.01'!O5,'15.01'!$AM$4:$AO$55,3,FALSE)) -> 0 | H5: =(VLOOKUP('15.01'!P5,'15.01'!$AM$4:$AO$55,3,FALSE)) -> 0 | ... X5: =(VLOOKUP('15.01'!AF5,'15.01'!$AM$4:$AO$55,3,FALSE)) -> 40
A6: =(VLOOKUP('15.01'!I6,'15.01'!$AM$4:$AO$55,3,FALSE)) -> 0 | B6: =(VLOOKUP('15.01'!J6,'15.01'!$AM$4:$AO$55,3,FALSE)) -> 0 | C6: =(VLOOKUP('15.01'!K6,'15.01'!$AM$4:$AO$55,3,FALSE)) -> 0 | D6: =(VLOOKUP('15.01'!L6,'15.01'!$AM$4:$AO$55,3,FALSE)) -> 0 | E6: =(VLOOKUP('15.01'!M6,'15.01'!$AM$4:$AO$55,3,FALSE)) -> 0 | F6: =(VLOOKUP('15.01'!N6,'15.01'!$AM$4:$AO$55,3,FALSE)) -> 0 | G6: =(VLOOKUP('15.01'!O6,'15.01'!$AM$4:$AO$55,3,FALSE)) -> 0 | H6: =(VLOOKUP('15.01'!P6,'15.01'!$AM$4:$AO$55,3,FALSE)) -> 0 | ... X6: =(VLOOKUP('15.01'!AF6,'15.01'!$AM$4:$AO$55,3,FALSE)) -> 45
A7: =(VLOOKUP('15.01'!I7,'15.01'!$AM$4:$AO$55,3,FALSE)) -> 0 | B7: =(VLOOKUP('15.01'!J7,'15.01'!$AM$4:$AO$55,3,FALSE)) -> 0 | C7: =(VLOOKUP('15.01'!K7,'15.01'!$AM$4:$AO$55,3,FALSE)) -> 0 | D7: =(VLOOKUP('15.01'!L7,'15.01'!$AM$4:$AO$55,3,FALSE)) -> 0 | E7: =(VLOOKUP('15.01'!M7,'15.01'!$AM$4:$AO$55,3,FALSE)) -> 0 | F7: =(VLOOKUP('15.01'!N7,'15.01'!$AM$4:$AO$55,3,FALSE)) -> 0 | G7: =(VLOOKUP('15.01'!O7,'15.01'!$AM$4:$AO$55,3,FALSE)) -> 0 | H7: =(VLOOKUP('15.01'!P7,'15.01'!$AM$4:$AO$55,3,FALSE)) -> 0 | ... X7: =(VLOOKUP('15.01'!AF7,'15.01'!$AM$4:$AO$55,3,FALSE)) -> 45
A8: =(VLOOKUP('15.01'!I8,'15.01'!$AM$4:$AO$55,3,FALSE)) -> 0 | B8: =(VLOOKUP('15.01'!J8,'15.01'!$AM$4:$AO$55,3,FALSE)) -> 0 | C8: =(VLOOKUP('15.01'!K8,'15.01'!$AM$4:$AO$55,3,FALSE)) -> 0 | D8: =(VLOOKUP('15.01'!L8,'15.01'!$AM$4:$AO$55,3,FALSE)) -> 0 | E8: =(VLOOKUP('15.01'!M8,'15.01'!$AM$4:$AO$55,3,FALSE)) -> 0 | F8: =(VLOOKUP('15.01'!N8,'15.01'!$AM$4:$AO$55,3,FALSE)) -> 0 | G8: =(VLOOKUP('15.01'!O8,'15.01'!$AM$4:$AO$55,3,FALSE)) -> 0 | H8: =(VLOOKUP('15.01'!P8,'15.01'!$AM$4:$AO$55,3,FALSE)) -> 0 | ... X8: =(VLOOKUP('15.01'!AF8,'15.01'!$AM$4:$AO$55,3,FALSE)) -> 0
A9: =(VLOOKUP('15.01'!I9,'15.01'!$AM$4:$AO$55,3,FALSE)) -> 0 | B9: =(VLOOKUP('15.01'!J9,'15.01'!$AM$4:$AO$55,3,FALSE)) -> 0 | C9: =(VLOOKUP('15.01'!K9,'15.01'!$AM$4:$AO$55,3,FALSE)) -> 0 | D9: =(VLOOKUP('15.01'!L9,'15.01'!$AM$4:$AO$55,3,FALSE)) -> 0 | E9: =(VLOOKUP('15.01'!M9,'15.01'!$AM$4:$AO$55,3,FALSE)) -> 0 | F9: =(VLOOKUP('15.01'!N9,'15.01'!$AM$4:$AO$55,3,FALSE)) -> 0 | G9: =(VLOOKUP('15.01'!O9,'15.01'!$AM$4:$AO$55,3,FALSE)) -> 0 | H9: =(VLOOKUP('15.01'!P9,'15.01'!$AM$4:$AO$55,3,FALSE)) -> 0 | ... X9: =(VLOOKUP('15.01'!AF9,'15.01'!$AM$4:$AO$55,3,FALSE)) -> 0
A10: =(VLOOKUP('15.01'!I10,'15.01'!$AM$4:$AO$55,3,FALSE)) -> 0 | B10: =(VLOOKUP('15.01'!J10,'15.01'!$AM$4:$AO$55,3,FALSE)) -> 0 | C10: =(VLOOKUP('15.01'!K10,'15.01'!$AM$4:$AO$55,3,FALSE)) -> 0 | D10: =(VLOOKUP('15.01'!L10,'15.01'!$AM$4:$AO$55,3,FALSE)) -> 0 | E10: =(VLOOKUP('15.01'!M10,'15.01'!$AM$4:$AO$55,3,FALSE)) -> 0 | F10: =(VLOOKUP('15.01'!N10,'15.01'!$AM$4:$AO$55,3,FALSE)) -> 0 | G10: =(VLOOKUP('15.01'!O10,'15.01'!$AM$4:$AO$55,3,FALSE)) -> 0 | H10: =(VLOOKUP('15.01'!P10,'15.01'!$AM$4:$AO$55,3,FALSE)) -> 0 | ... X10: =(VLOOKUP('15.01'!AF10,'15.01'!$AM$4:$AO$55,3,FALSE)) -> 0
A11: =(VLOOKUP('15.01'!I11,'15.01'!$AM$4:$AO$55,3,FALSE)) -> 0 | B11: =(VLOOKUP('15.01'!J11,'15.01'!$AM$4:$AO$55,3,FALSE)) -> 0 | C11: =(VLOOKUP('15.01'!K11,'15.01'!$AM$4:$AO$55,3,FALSE)) -> 0 | D11: =(VLOOKUP('15.01'!L11,'15.01'!$AM$4:$AO$55,3,FALSE)) -> 0 | E11: =(VLOOKUP('15.01'!M11,'15.01'!$AM$4:$AO$55,3,FALSE)) -> 0 | F11: =(VLOOKUP('15.01'!N11,'15.01'!$AM$4:$AO$55,3,FALSE)) -> 0 | G11: =(VLOOKUP('15.01'!O11,'15.01'!$AM$4:$AO$55,3,FALSE)) -> 0 | H11: =(VLOOKUP('15.01'!P11,'15.01'!$AM$4:$AO$55,3,FALSE)) -> 0 | ... X11: =(VLOOKUP('15.01'!AF11,'15.01'!$AM$4:$AO$55,3,FALSE)) -> 0
A12: =(VLOOKUP('15.01'!I12,'15.01'!$AM$4:$AO$55,3,FALSE)) -> 0 | B12: =(VLOOKUP('15.01'!J12,'15.01'!$AM$4:$AO$55,3,FALSE)) -> 0 | C12: =(VLOOKUP('15.01'!K12,'15.01'!$AM$4:$AO$55,3,FALSE)) -> 0 | D12: =(VLOOKUP('15.01'!L12,'15.01'!$AM$4:$AO$55,3,FALSE)) -> 0 | E12: =(VLOOKUP('15.01'!M12,'15.01'!$AM$4:$AO$55,3,FALSE)) -> 0 | F12: =(VLOOKUP('15.01'!N12,'15.01'!$AM$4:$AO$55,3,FALSE)) -> 0 | G12: =(VLOOKUP('15.01'!O12,'15.01'!$AM$4:$AO$55,3,FALSE)) -> 0 | H12: =(VLOOKUP('15.01'!P12,'15.01'!$AM$4:$AO$55,3,FALSE)) -> 0 | ... X12: =(VLOOKUP('15.01'!AF12,'15.01'!$AM$4:$AO$55,3,FALSE)) -> 0
A13: =(VLOOKUP('15.01'!I13,'15.01'!$AM$4:$AO$55,3,FALSE)) -> 0 | B13: =(VLOOKUP('15.01'!J13,'15.01'!$AM$4:$AO$55,3,FALSE)) -> 0 | C13: =(VLOOKUP('15.01'!K13,'15.01'!$AM$4:$AO$55,3,FALSE)) -> 0 | D13: =(VLOOKUP('15.01'!L13,'15.01'!$AM$4:$AO$55,3,FALSE)) -> 0 | E13: =(VLOOKUP('15.01'!M13,'15.01'!$AM$4:$AO$55,3,FALSE)) -> 0 | F13: =(VLOOKUP('15.01'!N13,'15.01'!$AM$4:$AO$55,3,FALSE)) -> 0 | G13: =(VLOOKUP('15.01'!O13,'15.01'!$AM$4:$AO$55,3,FALSE)) -> 0 | H13: =(VLOOKUP('15.01'!P13,'15.01'!$AM$4:$AO$55,3,FALSE)) -> 0 | ... X13: =(VLOOKUP('15.01'!AF13,'15.01'!$AM$4:$AO$55,3,FALSE)) -> 0
A14: =(VLOOKUP('15.01'!I14,'15.01'!$AM$4:$AO$55,3,FALSE)) -> 0 | B14: =(VLOOKUP('15.01'!J14,'15.01'!$AM$4:$AO$55,3,FALSE)) -> 0 | C14: =(VLOOKUP('15.01'!K14,'15.01'!$AM$4:$AO$55,3,FALSE)) -> 0 | D14: =(VLOOKUP('15.01'!L14,'15.01'!$AM$4:$AO$55,3,FALSE)) -> 0 | E14: =(VLOOKUP('15.01'!M14,'15.01'!$AM$4:$AO$55,3,FALSE)) -> 0 | F14: =(VLOOKUP('15.01'!N14,'15.01'!$AM$4:$AO$55,3,FALSE)) -> 0 | G14: =(VLOOKUP('15.01'!O14,'15.01'!$AM$4:$AO$55,3,FALSE)) -> 0 | H14: =(VLOOKUP('15.01'!P14,'15.01'!$AM$4:$AO$55,3,FALSE)) -> 0 | ... X14: =(VLOOKUP('15.01'!AF14,'15.01'!$AM$4:$AO$55,3,FALSE)) -> 0
A15: =(VLOOKUP('15.01'!I15,'15.01'!$AM$4:$AO$55,3,FALSE)) -> 0 | B15: =(VLOOKUP('15.01'!J15,'15.01'!$AM$4:$AO$55,3,FALSE)) -> 0 | C15: =(VLOOKUP('15.01'!K15,'15.01'!$AM$4:$AO$55,3,FALSE)) -> 0 | D15: =(VLOOKUP('15.01'!L15,'15.01'!$AM$4:$AO$55,3,FALSE)) -> 0 | E15: =(VLOOKUP('15.01'!M15,'15.01'!$AM$4:$AO$55,3,FALSE)) -> 0 | F15: =(VLOOKUP('15.01'!N15,'15.01'!$AM$4:$AO$55,3,FALSE)) -> 0 | G15: =(VLOOKUP('15.01'!O15,'15.01'!$AM$4:$AO$55,3,FALSE)) -> 0 | H15: =(VLOOKUP('15.01'!P15,'15.01'!$AM$4:$AO$55,3,FALSE)) -> 0 | ... X15: =(VLOOKUP('15.01'!AF15,'15.01'!$AM$4:$AO$55,3,FALSE)) -> 0
... A93: =(VLOOKUP('15.01'!I93,'15.01'!$AM$4:$AO$55,3,FALSE)) -> 0 | B93: =(VLOOKUP('15.01'!J93,'15.01'!$AM$4:$AO$55,3,FALSE)) -> 0 | C93: =(VLOOKUP('15.01'!K93,'15.01'!$AM$4:$AO$55,3,FALSE)) -> 40 | D93: =(VLOOKUP('15.01'!L93,'15.01'!$AM$4:$AO$55,3,FALSE)) -> 30 | E93: =(VLOOKUP('15.01'!M93,'15.01'!$AM$4:$AO$55,3,FALSE)) -> 0 | F93: =(VLOOKUP('15.01'!N93,'15.01'!$AM$4:$AO$55,3,FALSE)) -> 0 | G93: =(VLOOKUP('15.01'!O93,'15.01'!$AM$4:$AO$55,3,FALSE)) -> 0 | H93: =(VLOOKUP('15.01'!P93,'15.01'!$AM$4:$AO$55,3,FALSE)) -> 0 | ... X93: =(VLOOKUP('15.01'!AF93,'15.01'!$AM$4:$AO$55,3,FALSE)) -> 0
A94: =(VLOOKUP('15.01'!#REF!,'15.01'!$AM$4:$AO$55,3,FALSE)) -> #REF! | B94: =(VLOOKUP('15.01'!#REF!,'15.01'!$AM$4:$AO$55,3,FALSE)) -> #REF! | C94: =(VLOOKUP('15.01'!#REF!,'15.01'!$AM$4:$AO$55,3,FALSE)) -> #REF! | D94: =(VLOOKUP('15.01'!#REF!,'15.01'!$AM$4:$AO$55,3,FALSE)) -> #REF! | E94: =(VLOOKUP('15.01'!#REF!,'15.01'!$AM$4:$AO$55,3,FALSE)) -> #REF! | F94: =(VLOOKUP('15.01'!#REF!,'15.01'!$AM$4:$AO$55,3,FALSE)) -> #REF! | G94: =(VLOOKUP('15.01'!#REF!,'15.01'!$AM$4:$AO$55,3,FALSE)) -> #REF! | H94: =(VLOOKUP('15.01'!#REF!,'15.01'!$AM$4:$AO$55,3,FALSE)) -> #REF! | ... X94: =(VLOOKUP('15.01'!#REF!,'15.01'!$AM$4:$AO$55,3,FALSE)) -> #REF!

Sheet 亏损
A2: 队伍一 风 | C2: 步数 | D2: =COUNTIF(A4:H94,"<>空") -> 728 | E2: (不算跳步和传送) | I2: 队伍二 雷 | K2: 步数 | L2: =COUNTIF(I4:P94,"<>空") -> 728 | M2: (不算跳步和传送) | Q2: 队伍三 | S2: 总步数 | T2: =COUNTIF(Q4:X94,"<>空") -> 728 | U2: (不算跳步和传送)
A3: 1 | B3: 2 | C3: 3 | D3: 4 | E3: 5 | F3: 6 | G3: 7 | H3: 8 | I3: 1 | J3: 2 | K3: 3 | L3: 4 | M3: 5 | N3: 6 | O3: 7 | P3: 8 | Q3: 1 | R3: 2 | S3: 3 | T3: 4 | U3: 5 | V3: 6 | W3: 7 | X3: 8
A4: =(VLOOKUP('15.01'!I4,'15.01'!$AM$4:$AP$55,4,FALSE)) -> 44.222109 | B4: =(VLOOKUP('15.01'!J4,'15.01'!$AM$4:$AP$55,4,FALSE)) -> 44.222109 | C4: =(VLOOKUP('15.01'!K4,'15.01'!$AM$4:$AP$55,4,FALSE)) -> 44.222109 | D4: =(VLOOKUP('15.01'!L4,'15.01'!$AM$4:$AP$55,4,FALSE)) -> 44.222109 | E4: =(VLOOKUP('15.01'!M4,'15.01'!$AM$4:$AP$55,4,FALSE)) -> 44.222109 | F4: =(VLOOKUP('15.01'!N4,'15.01'!$AM$4:$AP$55,4,FALSE)) -> 10 | G4: =(VLOOKUP('15.01'!O4,'15.01'!$AM$4:$AP$55,4,FALSE)) -> 0 | H4: =(VLOOKUP('15.01'!P4,'15.01'!$AM$4:$AP$55,4,FALSE)) -> 0 | ... X4: =(VLOOKUP('15.01'!AF4,'15.01'!$AM$4:$AP$55,4,FALSE)) -> 0
