Workbook

Sheet 14.05
A1: =(_xlfn.DAYS(TODAY(),A4)+2)/((_xlfn.DAYS(A93,A4))+1) -> 1 | I1: 工作区 | AM1: 使用方法：按自己规划的路线，将下表中的地块名复制粘贴至工作区。初次使用传送门，当天跳步次数+5。重复使用传送门，当天跳步次数+1
A2: 14.05 | B2: 八卦前亏 | C2: =SUM(亏损!A4:X94)+SUM(AG4:AG14)*10 -> #REF! | D2: 合计经验 | F2: =SUM(F4:F93)+SUM(H4:H93) -> 64920 | I2: 队伍一 火 | K2: 步数 | L2: =COUNTIF(I4:P93,"<>空") -> 374 | M2: (不算跳步和传送) | Q2: 队伍二 雷 | S2: 步数 | T2: =COUNTIF(Q4:X93,"<>空") -> 315 | U2: (不算跳步和传送) | Y2: 队伍三 | AA2: 总步数 | AB2: =COUNTIF(Y4:AF93,"<>空") -> 375 | AC2: (不算跳步和传送) | AG2: =SUM(AG4:AG93) -> 32 | AH2: =SUM(AH4:AH93) -> 7 | AI2: =SUM(AI4:AI93) -> 4 | AJ2: =SUM(AJ4:AJ93) -> 21 | AK2: 八卦全开 | AS2: 总地块 | AT2: =SUM(AT4:AT29) -> 1064 | AV2: 总经验 | AW2: =SUM(AU4:AW29)+7000 -> 64920 | AY2: 粮草系数
A3: 日期 | B3: 获得粮草 | C3: 粮草调整 | D3: 消耗粮草 | E3: 剩余粮草 | F3: 获得经验 | G3: 累计经验 | H3: 任务经验 | I3: 1 | J3: 2 | K3: 3 | L3: 4 | M3: 5 | N3: 6 | O3: 7 | P3: 8 | Q3: 1 | R3: 2 | S3: 3 | T3: 4 | U3: 5 | V3: 6 | W3: 7 | X3: 8 | Y3: 1 | Z3: 2 | AA3: 3 | AB3: 4 | AC3: 5 | AD3: 6 | AE3: 7 | AF3: 8 | AG3: 跳步次数 | AH3: 1队跳步 | AI3: 2队跳步 | AJ3: 3队跳步 | AM3: 地块 | AN3: 粮草 | AO3: 经验 | AP3: 八卦前亏损 | AQ3: 一队地块 | AR3: 二队地块 | AS3: 三队地块 | AT3: 总地块 | AU3: 一队经验 | AV3: 二队经验 | AW3: 三队经验 | AX3: 八卦前 | AY3: 1
A4: 45275 | B4: 800 | C4: 4800 | D4: =(SUM(粮草!A4:X4)+AG4*10)*IF(AK4="是",$AY$4,$AY$3) -> 1760 | E4: =SUM($B$4:B4)+SUM($C$4:C4)-SUM($D$4:D4) -> 3840 | F4: =SUM(经验!A4:X4) -> 450 | G4: =SUM($F$4:F4)+SUM($H$4:H4) -> 950 | H4: 500 | I4: 1级 | J4: 1级 | K4: 1级 | L4: 空 | M4: 空 | N4: 空 | O4: 空 | P4: 空 | Q4: 1级 | R4: 商人 | S4: 1级 | T4: 2级 | U4: 空 | V4: 空 | W4: 空 | X4: 空 | Y4: 2级 | Z4: 2级 | AA4: 2级 | AB4: 塔2 | AC4: 3级 | AD4: 空 | AE4: 空 | AF4: 空 | AG4: =AH4+AI4+AJ4 -> 0 | AK4: 否 | AM4: 1级 | AN4: 150 | AO4: 35 | AP4: 44.222109 | AQ4: =COUNTIF($I$4:$P$93,AM4) -> 8 | AR4: =COUNTIF($Q$4:$X$93,AM4) -> 3 | AS4: =COUNTIF($Y$4:$AF$93,AM4) -> 3 | AT4: =AQ4+AR4+AS4 -> 14 | AU4: =AQ4*$AO4 -> 280 | AV4: =AR4*$AO4 -> 105 | AW4: =AS4*$AO4 -> 105 | AX4: 八卦后 | AY4: 0.8 | BA4: =AN4*0.8 -> 120
A5: 45276 | B5: 1600 | C5: 1200 | D5: =(SUM(粮草!A5:X5)+AG5*10)*IF(AK5="是",$AY$4,$AY$3) -> 1750 | E5: =SUM($B$4:B5)+SUM($C$4:C5)-SUM($D$4:D5) -> 4890 | F5: =SUM(经验!A5:X5) -> 510 | G5: =SUM($F$4:F5)+SUM($H$4:H5) -> 1460 | H5: 0 | I5: 1级 | J5: 1级 | K5: 商人 | L5: 1级 | M5: 1级 | N5: 2级 | O5: 空 | P5: 空 | Q5: 空 | R5: 空 | S5: 空 | T5: 空 | U5: 空 | V5: 空 | W5: 空 | X5: 空 | Y5: 3级 | Z5: 3级 | AA5: 小卦 | AB5: 商人 | AC5: 3级 | AD5: 营地 | AE5: 3级 | AF5: 3级 | AG5: =AH5+AI5+AJ5 -> 2 | AJ5: 2 | AK5: 否 | AM5: 2级 | AN5: 160 | AO5: 40 | AP5: 39.110982 | AQ5: =COUNTIF($I$4:$P$93,AM5) -> 12 | AR5: =COUNTIF($Q$4:$X$93,AM5) -> 7 | AS5: =COUNTIF($Y$4:$AF$93,AM5) -> 13 | AT5: =AQ5+AR5+AS5 -> 32 | AU5: =AQ5*$AO5 -> 480 | AV5: =AR5*$AO5 -> 280 | AW5: =AS5*$AO5 -> 520 | AX5: Note：开完八卦当天可能需要手动计算粮草 | BA5: =AN5*0.8 -> 128
A6: 45277 | B6: 1600 | D6: =(SUM(粮草!A6:X6)+AG6*10)*IF(AK6="是",$AY$4,$AY$3) -> 1960 | E6: =SUM($B$4:B6)+SUM($C$4:C6)-SUM($D$4:D6) -> 4530 | F6: =SUM(经验!A6:X6) -> 555 | G6: =SUM($F$4:F6)+SUM($H$4:H6) -> 2015 | H6: 0 | I6: 2级 | J6: 商人 | K6: 2级 | L6: 2级 | M6: 营地 | N6: 3级 | O6: 3级 | P6: 3级 | Q6: 空 | R6: 空 | S6: 空 | T6: 空 | U6: 空 | V6: 空 | W6: 空 | X6: 空 | Y6: 小卦 | Z6: 3级 | AA6: 3级 | AB6: 3级 | AC6: 3级 | AD6: 3级 | AE6: 空 | AF6: 空 | AG6: =AH6+AI6+AJ6 -> 5 | AJ6: 5 | AK6: 否 | AM6: 3级 | AN6: 170 | AO6: 45 | AP6: 34 | AQ6: =COUNTIF($I$4:$P$93,AM6) -> 82 | AR6: =COUNTIF($Q$4:$X$93,AM6) -> 57 | AS6: =COUNTIF($Y$4:$AF$93,AM6) -> 94 | AT6: =AQ6+AR6+AS6 -> 233 | AU6: =AQ6*$AO6 -> 3690 | AV6: =AR6*$AO6 -> 2565 | AW6: =AS6*$AO6 -> 4230 | BA6: =AN6*0.8 -> 136
A7: 45278 | B7: 1600 | D7: =(SUM(粮草!A7:X7)+AG7*10)*IF(AK7="是",$AY$4,$AY$3) -> 2060 | E7: =SUM($B$4:B7)+SUM($C$4:C7)-SUM($D$4:D7) -> 4070 | F7: =SUM(经验!A7:X7) -> 1035 | G7: =SUM($F$4:F7)+SUM($H$4:H7) -> 3250 | H7: 200 | I7: 3级 | J7: 大卦 | K7: 3级 | L7: 3级 | M7: 塔3 | N7: 3级 | O7: 空 | P7: 空 | Q7: 空 | R7: 空 | S7: 空 | T7: 空 | U7: 空 | V7: 空 | W7: 空 | X7: 空 | Y7: 商人 | Z7: 3级 | AA7: 3级 | AB7: 3级 | AC7: 大卦 | AD7: 3级 | AE7: 空 | AF7: 空 | AG7: =AH7+AI7+AJ7 -> 0 | AK7: 否 | AM7: 4级 | AN7: 180 | AO7: 50 | AP7: 36 | AQ7: =COUNTIF($I$4:$P$93,AM7) -> 97 | AR7: =COUNTIF($Q$4:$X$93,AM7) -> 90 | AS7: =COUNTIF($Y$4:$AF$93,AM7) -> 89 | AT7: =AQ7+AR7+AS7 -> 276 | AU7: =AQ7*$AO7 -> 4850 | AV7: =AR7*$AO7 -> 4500 | AW7: =AS7*$AO7 -> 4450 | BA7: =AN7*0.8 -> 144
A8: 45279 | B8: 1600 | D8: =(SUM(粮草!A8:X8)+AG8*10)*IF(AK8="是",$AY$4,$AY$3) -> 2120 | E8: =SUM($B$4:B8)+SUM($C$4:C8)-SUM($D$4:D8) -> 3550 | F8: =SUM(经验!A8:X8) -> 540 | G8: =SUM($F$4:F8)+SUM($H$4:H8) -> 3890 | H8: 100 | I8: 3级 | J8: 3级 | K8: 3级 | L8: 3级 | M8: 3级 | N8: 3级 | O8: 空 | P8: 空 | Q8: 空 | R8: 空 | S8: 空 | T8: 空 | U8: 空 | V8: 空 | W8: 空 | X8: 空 | Y8: 3级 | Z8: 塔3 | AA8: 3级 | AB8: 3级 | AC8: 3级 | AD8: 3级 | AE8: 空 | AF8: 空 | AG8: =AH8+AI8+AJ8 -> 10 | AH8: 5 | AJ8: 5 | AK8: 否 | AM8: 5级 | AN8: 190 | AO8: 55 | AP8: 38 | AQ8: =COUNTIF($I$4:$P$93,AM8) -> 87 | AR8: =COUNTIF($Q$4:$X$93,AM8) -> 77 | AS8: =COUNTIF($Y$4:$AF$93,AM8) -> 73 | AT8: =AQ8+AR8+AS8 -> 237 | AU8: =AQ8*$AO8 -> 4785 | AV8: =AR8*$AO8 -> 4235 | AW8: =AS8*$AO8 -> 4015 | BA8: =AN8*0.8 -> 152
A9: 45280 | B9: 1600 | D9: =(SUM(粮草!A9:X9)+AG9*10)*IF(AK9="是",$AY$4,$AY$3) -> 1150 | E9: =SUM($B$4:B9)+SUM($C$4:C9)-SUM($D$4:D9) -> 4000 | F9: =SUM(经验!A9:X9) -> 555 | G9: =SUM($F$4:F9)+SUM($H$4:H9) -> 4645 | H9: 200 | I9: 小卦 | J9: 空 | K9: 空 | L9: 空 | M9: 空 | N9: 空 | O9: 空 | P9: 空 | Q9: 空 | R9: 空 | S9: 空 | T9: 空 | U9: 空 | V9: 空 | W9: 空 | X9: 空 | Y9: 3级 | Z9: 商人 | AA9: 3级 | AB9: 3级 | AC9: 3级 | AD9: 大卦 | AE9: 空 | AF9: 空 | AG9: =AH9+AI9+AJ9 -> 0 | AK9: 否 | AM9: 6级 | AN9: 200 | AO9: 60 | AQ9: =COUNTIF($I$4:$P$93,AM9) -> 59 | AR9: =COUNTIF($Q$4:$X$93,AM9) -> 61 | AS9: =COUNTIF($Y$4:$AF$93,AM9) -> 67 | AT9: =AQ9+AR9+AS9 -> 187 | AU9: =AQ9*$AO9 -> 3540 | AV9: =AR9*$AO9 -> 3660 | AW9: =AS9*$AO9 -> 4020 | BA9: =AN9*0.8 -> 160
A10: 45281 | B10: 1600 | D10: =(SUM(粮草!A10:X10)+AG10*10)*IF(AK10="是",$AY$4,$AY$3) -> 1090 | E10: =SUM($B$4:B10)+SUM($C$4:C10)-SUM($D$4:D10) -> 4510 | F10: =SUM(经验!A10:X10) -> 315 | G10: =SUM($F$4:F10)+SUM($H$4:H10) -> 4960 | H10: 0 | I10: 空 | J10: 空 | K10: 空 | L10: 空 | M10: 空 | N10: 空 | O10: 空 | P10: 空 | Q10: 空 | R10: 空 | S10: 空 | T10: 空 | U10: 空 | V10: 空 | W10: 空 | X10: 空 | Y10: 3级 | Z10: 营地 | AA10: 3级 | AB10: 3级 | AC10: 3级 | AD10: 3级 | AE10: 3级 | AF10: 3级 | AG10: =AH10+AI10+AJ10 -> 5 | AJ10: 5 | AK10: 否 | AM10: 塔1 | AN10: 150 | AO10: 35 | AP10: 44.222109 | AQ10: =COUNTIF($I$4:$P$93,AM10) -> 0 | AR10: =COUNTIF($Q$4:$X$93,AM10) -> 0 | AS10: =COUNTIF($Y$4:$AF$93,AM10) -> 0 | AT10: =AQ10+AR10+AS10 -> 0 | AU10: =AQ10*$AO10 -> 0 | AV10: =AR10*$AO10 -> 0 | AW10: =AS10*$AO10 -> 0 | BA10: =AN10*0.8 -> 120
A11: 45282 | B11: 1600 | D11: =(SUM(粮草!A11:X11)+AG11*10)*IF(AK11="是",$AY$4,$AY$3) -> 900 | E11: =SUM($B$4:B11)+SUM($C$4:C11)-SUM($D$4:D11) -> 5210 | F11: =SUM(经验!A11:X11) -> 255 | G11: =SUM($F$4:F11)+SUM($H$4:H11) -> 5215 | H11: 0 | I11: 空 | J11: 空 | K11: 空 | L11: 空 | M11: 空 | N11: 空 | O11: 空 | P11: 空 | Q11: 空 | R11: 空 | S11: 空 | T11: 空 | U11: 空 | V11: 空 | W11: 空 | X11: 空 | Y11: 小卦 | Z11: 3级 | AA11: 商人 | AB11: 3级 | AC11: 3级 | AD11: 3级 | AE11: 空 | AF11: 空 | AG11: =AH11+AI11+AJ11 -> 0 | AK11: 否 | AM11: 塔2 | AN11: 150 | AO11: 40 | AP11: 29.110982 | AQ11: =COUNTIF($I$4:$P$93,AM11) -> 1 | AR11: =COUNTIF($Q$4:$X$93,AM11) -> 0 | AS11: =COUNTIF($Y$4:$AF$93,AM11) -> 1 | AT11: =AQ11+AR11+AS11 -> 2 | AU11: =AQ11*$AO11 -> 40 | AV11: =AR11*$AO11 -> 0 | AW11: =AS11*$AO11 -> 40 | BA11: =AN11*0.8 -> 120
A12: 45283 | B12: 1600 | D12: =(SUM(粮草!A12:X12)+AG12*10)*IF(AK12="是",$AY$4,$AY$3) -> 170 | E12: =SUM($B$4:B12)+SUM($C$4:C12)-SUM($D$4:D12) -> 6640 | F12: =SUM(经验!A12:X12) -> 45 | G12: =SUM($F$4:F12)+SUM($H$4:H12) -> 5260 | H12: 0 | I12: 空 | J12: 空 | K12: 空 | L12: 空 | M12: 空 | N12: 空 | O12: 空 | P12: 空 | Q12: 空 | R12: 空 | S12: 空 | T12: 空 | U12: 空 | V12: 空 | W12: 空 | X12: 空 | Y12: 小卦 | Z12: 空 | AA12: 空 | AB12: 空 | AC12: 空 | AD12: 空 | AE12: 空 | AF12: 空 | AG12: =AH12+AI12+AJ12 -> 0 | AK12: 否 | AM12: 塔3 | AN12: 150 | AO12: 45 | AP12: 13.999855 | AQ12: =COUNTIF($I$4:$P$93,AM12) -> 2 | AR12: =COUNTIF($Q$4:$X$93,AM12) -> 2 | AS12: =COUNTIF($Y$4:$AF$93,AM12) -> 2 | AT12: =AQ12+AR12+AS12 -> 6 | AU12: =AQ12*$AO12 -> 90 | AV12: =AR12*$AO12 -> 90 | AW12: =AS12*$AO12 -> 90 | BA12: =AN12*0.8 -> 120
A13: 45284 | B13: 1600 | C13: 40 | D13: =(SUM(粮草!A13:X13)+AG13*10)*IF(AK13="是",$AY$4,$AY$3) -> 1816 | E13: =SUM($B$4:B13)+SUM($C$4:C13)-SUM($D$4:D13) -> 6464 | F13: =SUM(经验!A13:X13) -> 645 | G13: =SUM($F$4:F13)+SUM($H$4:H13) -> 5905 | H13: 0 | I13: 3级 | J13: 塔3 | K13: 3级 | L13: 3级 | M13: 商人 | N13: 3级 | O13: 空 | P13: 空 | Q13: 商人 | R13: 3级 | S13: 3级 | T13: 3级 | U13: 3级 | V13: 3级 | W13: 空 | X13: 空 | Y13: 3级 | Z13: 3级 | AA13: 塔3 | AB13: 空 | AC13: 空 | AD13: 空 | AE13: 空 | AF13: 空 | AG13: =AH13+AI13+AJ13 -> 0 | AK13: 是 | AM13: 塔4 | AN13: 150 | AO13: 50 | AQ13: =COUNTIF($I$4:$P$93,AM13) -> 1 | AR13: =COUNTIF($Q$4:$X$93,AM13) -> 0 | AS13: =COUNTIF($Y$4:$AF$93,AM13) -> 2 | AT13: =AQ13+AR13+AS13 -> 3 | AU13: =AQ13*$AO13 -> 50 | AV13: =AR13*$AO13 -> 0 | AW13: =AS13*$AO13 -> 100 | BA13: =AN13*0.8 -> 120
A14: 45285 | B14: 1600 | D14: =(SUM(粮草!A14:X14)+AG14*10)*IF(AK14="是",$AY$4,$AY$3) -> 2352 | E14: =SUM($B$4:B14)+SUM($C$4:C14)-SUM($D$4:D14) -> 5712 | F14: =SUM(经验!A14:X14) -> 840 | G14: =SUM($F$4:F14)+SUM($H$4:H14) -> 7045 | H14: 300 | I14: 4级 | J14: 4级 | K14: 4级 | L14: 4级 | M14: 4级 | N14: 4级 | O14: 空 | P14: 空 | Q14: 商人 | R14: 3级 | S14: 3级 | T14: 3级 | U14: 商人 | V14: 3级 | W14: 空 | X14: 空 | Y14: 4级 | Z14: 4级 | AA14: 4级 | AB14: 4级 | AC14: 4级 | AD14: 4级 | AE14: 空 | AF14: 空 | AG14: =AH14+AI14+AJ14 -> 0 | AK14: 是 | AM14: 塔5 | AN14: 150 | AO14: 55 | AQ14: =COUNTIF($I$4:$P$93,AM14) -> 1 | AR14: =COUNTIF($Q$4:$X$93,AM14) -> 1 | AS14: =COUNTIF($Y$4:$AF$93,AM14) -> 1 | AT14: =AQ14+AR14+AS14 -> 3 | AU14: =AQ14*$AO14 -> 55 | AV14: =AR14*$AO14 -> 55 | AW14: =AS14*$AO14 -> 55 | BA14: =AN14*0.8 -> 120
A15: 45286 | B15: 1600 | D15: =(SUM(粮草!A15:X15)+AG15*10)*IF(AK15="是",$AY$4,$AY$3) -> 2552 | E15: =SUM($B$4:B15)+SUM($C$4:C15)-SUM($D$4:D15) -> 4760 | F15: =SUM(经验!A15:X15) -> 870 | G15: =SUM($F$4:F15)+SUM($H$4:H15) -> 7915 | H15: 0 | I15: 4级 | J15: 4级 | K15: 4级 | L15: 4级 | M15: 4级 | N15: 4级 | O15: 空 | P15: 空 | Q15: 3级 | R15: 3级 | S15: 3级 | T15: 3级 | U15: 3级 | V15: 3级 | W15: 空 | X15: 空 | Y15: 4级 | Z15: 4级 | AA15: 4级 | AB15: 4级 | AC15: 4级 | AD15: 4级 | AE15: 空 | AF15: 空 | AG15: =AH15+AI15+AJ15 -> 1 | AI15: 1 | AK15: 是 | AM15: 塔6 | AN15: 150 | AO15: 60 | AQ15: =COUNTIF($I$4:$P$93,AM15) -> 1 | AR15: =COUNTIF($Q$4:$X$93,AM15) -> 0 | AS15: =COUNTIF($Y$4:$AF$93,AM15) -> 0 | AT15: =AQ15+AR15+AS15 -> 1 | AU15: =AQ15*$AO15 -> 60 | AV15: =AR15*$AO15 -> 0 | AW15: =AS15*$AO15 -> 0 | BA15: =AN15*0.8 -> 120
A16: 45287 | B16: 1600 | D16: =(SUM(粮草!A16:X16)+AG16*10)*IF(AK16="是",$AY$4,$AY$3) -> 2520 | E16: =SUM($B$4:B16)+SUM($C$4:C16)-SUM($D$4:D16) -> 3840 | F16: =SUM(经验!A16:X16) -> 870 | G16: =SUM($F$4:F16)+SUM($H$4:H16) -> 8985 | H16: 200 | I16: 4级 | J16: 4级 | K16: 4级 | L16: 4级 | M16: 4级 | N16: 4级 | O16: 空 | P16: 空 | Q16: 3级 | R16: 3级 | S16: 3级 | T16: 3级 | U16: 3级 | V16: 3级 | W16: 空 | X16: 空 | Y16: 4级 | Z16: 塔4 | AA16: 4级 | AB16: 4级 | AC16: 4级 | AD16: 4级 | AE16: 空 | AF16: 空 | AG16: =AH16+AI16+AJ16 -> 0 | AK16: 是 | AM16: 遗迹 | AN16: 150 | AO16: 35 | AP16: 44.222109 | AQ16: =COUNTIF($I$4:$P$93,AM16) -> 0 | AR16: =COUNTIF($Q$4:$X$93,AM16) -> 0 | AS16: =COUNTIF($Y$4:$AF$93,AM16) -> 0 | AT16: =AQ16+AR16+AS16 -> 0 | AU16: =AQ16*$AO16 -> 0 | AV16: =AR16*$AO16 -> 0 | AW16: =AS16*$AO16 -> 0 | BA16: =AN16*0.8 -> 120
A17: 45288 | B17: 1600 | D17: =(SUM(粮草!A17:X17)+AG17*10)*IF(AK17="是",$AY$4,$AY$3) -> 2120 | E17: =SUM($B$4:B17)+SUM($C$4:C17)-SUM($D$4:D17) -> 3320 | F17: =SUM(经验!A17:X17) -> 735 | G17: =SUM($F$4:F17)+SUM($H$4:H17) -> 9720 | H17: 0 | I17: 4级 | J17: 4级 | K17: 4级 | L17: 4级 | M17: 4级 | N17: 4级 | O17: 空 | P17: 空 | Q17: 塔3 | R17: 3级 | S17: 3级 | T17: 空 | U17: 空 | V17: 空 | W17: 空 | X17: 空 | Y17: 4级 | Z17: 4级 | AA17: 4级 | AB17: 4级 | AC17: 4级 | AD17: 4级 | AE17: 空 | AF17: 空 | AG17: =AH17+AI17+AJ17 -> 0 | AK17: 是 | AM17: 商人 | AN17: 50 | AO17: 30 | AP17: 10 | AQ17: =COUNTIF($I$4:$P$93,AM17) -> 13 | AR17: =COUNTIF($Q$4:$X$93,AM17) -> 11 | AS17: =COUNTIF($Y$4:$AF$93,AM17) -> 16 | AT17: =AQ17+AR17+AS17 -> 40 | AU17: =AQ17*$AO17 -> 390 | AV17: =AR17*$AO17 -> 330 | AW17: =AS17*$AO17 -> 480 | BA17: =AN17*0.8 -> 40
A18: 45289 | B18: 1600 | D18: =(SUM(粮草!A18:X18)+AG18*10)*IF(AK18="是",$AY$4,$AY$3) -> 1760 | E18: =SUM($B$4:B18)+SUM($C$4:C18)-SUM($D$4:D18) -> 3160 | F18: =SUM(经验!A18:X18) -> 620 | G18: =SUM($F$4:F18)+SUM($H$4:H18) -> 10340 | H18: 0 | I18: 4级 | J18: 4级 | K18: 4级 | L18: 4级 | M18: 4级 | N18: 5级 | O18: 空 | P18: 空 | Q18: 空 | R18: 空 | S18: 空 | T18: 空 | U18: 空 | V18: 空 | W18: 空 | X18: 空 | Y18: 4级 | Z18: 4级 | AA18: 4级 | AB18: 5级 | AC18: 5级 | AD18: 5级 | AE18: 空 | AF18: 空 | AG18: =AH18+AI18+AJ18 -> 0 | AK18: 是 | AL18: 八卦前 | AM18: 营地 | AN18: -150 | AO18: 0 | AP18: 10 | AQ18: =COUNTIF($I$4:$P$93,AM18) -> 1 | AR18: =COUNTIF($Q$4:$X$93,AM18) -> 0 | AS18: =COUNTIF($Y$4:$AF$93,AM18) -> 2 | AT18: =AQ18+AR18+AS18 -> 3 | AU18: =AQ18*$AO18 -> 0 | AV18: =AR18*$AO18 -> 0 | AW18: =AS18*$AO18 -> 0 | BA18: =AN18*0.8 -> -120
A19: 45290 | B19: 1600 | D19: =(SUM(粮草!A19:X19)+AG19*10)*IF(AK19="是",$AY$4,$AY$3) -> 1824 | E19: =SUM($B$4:B19)+SUM($C$4:C19)-SUM($D$4:D19) -> 2936 | F19: =SUM(经验!A19:X19) -> 660 | G19: =SUM($F$4:F19)+SUM($H$4:H19) -> 11000 | H19: 0 | I19: 5级 | J19: 5级 | K19: 5级 | L19: 5级 | M19: 5级 | N19: 5级 | O19: 空 | P19: 空 | Q19: 空 | R19: 空 | S19: 空 | T19: 空 | U19: 空 | V19: 空 | W19: 空 | X19: 空 | Y19: 5级 | Z19: 5级 | AA19: 5级 | AB19: 5级 | AC19: 5级 | AD19: 5级 | AE19: 空 | AF19: 空 | AG19: =AH19+AI19+AJ19 -> 0 | AK19: 是 | AM19: 大卦 | AN19: 250 | AO19: 300 | AQ19: =COUNTIF($I$4:$P$93,AM19) -> 1 | AR19: =COUNTIF($Q$4:$X$93,AM19) -> 0 | AS19: =COUNTIF($Y$4:$AF$93,AM19) -> 2 | AT19: =AQ19+AR19+AS19 -> 3 | AU19: =AQ19*$AO19 -> 300 | AV19: =AR19*$AO19 -> 0 | AW19: =AS19*$AO19 -> 600 | BA19: =AN19*0.8 -> 200
A20: 45291 | B20: 1600 | D20: =(SUM(粮草!A20:X20)+AG20*10)*IF(AK20="是",$AY$4,$AY$3) -> 1584 | E20: =SUM($B$4:B20)+SUM($C$4:C20)-SUM($D$4:D20) -> 2952 | F20: =SUM(经验!A20:X20) -> 620 | G20: =SUM($F$4:F20)+SUM($H$4:H20) -> 11620 | H20: 0 | I20: 商人 | J20: 5级 | K20: 5级 | L20: 5级 | M20: 塔5 | N20: 5级 | O20: 空 | P20: 空 | Q20: 空 | R20: 空 | S20: 空 | T20: 空 | U20: 空 | V20: 空 | W20: 空 | X20: 空 | Y20: 5级 | Z20: 5级 | AA20: 商人 | AB20: 5级 | AC20: 6级 | AD20: 6级 | AE20: 空 | AF20: 空 | AG20: =AH20+AI20+AJ20 -> 0 | AK20: 是 | AM20: 小卦 | AN20: 170 | AO20: 45 | AQ20: =COUNTIF($I$4:$P$93,AM20) -> 1 | AR20: =COUNTIF($Q$4:$X$93,AM20) -> 0 | AS20: =COUNTIF($Y$4:$AF$93,AM20) -> 4 | AT20: =AQ20+AR20+AS20 -> 5 | AU20: =AQ20*$AO20 -> 45 | AV20: =AR20*$AO20 -> 0 | AW20: =AS20*$AO20 -> 180 | BA20: =AN20*0.8 -> 136
A21: 45292 | B21: 1600 | D21: =(SUM(粮草!A21:X21)+AG21*10)*IF(AK21="是",$AY$4,$AY$3) -> 2440 | E21: =SUM($B$4:B21)+SUM($C$4:C21)-SUM($D$4:D21) -> 2112 | F21: =SUM(经验!A21:X21) -> 945 | G21: =SUM($F$4:F21)+SUM($H$4:H21) -> 12765 | H21: 200 | I21: 5级 | J21: 5级 | K21: 6级 | L21: 6级 | M21: 6级 | N21: 6级 | O21: 空 | P21: 空 | Q21: 4级 | R21: 4级 | S21: 4级 | T21: 4级 | U21: 4级 | V21: 3级 | W21: 空 | X21: 空 | Y21: 6级 | Z21: 6级 | AA21: 6级 | AB21: 6级 | AC21: 6级 | AD21: 营地+ | AE21: 空 | AF21: 空 | AG21: =AH21+AI21+AJ21 -> 0 | AK21: 是 | AM21: 小boss | AN21: 250 | AO21: 200 | AQ21: =COUNTIF($I$4:$P$93,AM21) -> 0 | AR21: =COUNTIF($Q$4:$X$93,AM21) -> 0 | AS21: =COUNTIF($Y$4:$AF$93,AM21) -> 0 | AT21: =AQ21+AR21+AS21 -> 0 | AU21: =AQ21*$AO21 -> 0 | AV21: =AR21*$AO21 -> 0 | AW21: =AS21*$AO21 -> 0 | BA21: =AN21*0.8 -> 200
A22: 45293 | B22: 1600 | D22: =(SUM(粮草!A22:X22)+AG22*10)*IF(AK22="是",$AY$4,$AY$3) -> 1920 | E22: =SUM($B$4:B22)+SUM($C$4:C22)-SUM($D$4:D22) -> 1792 | F22: =SUM(经验!A22:X22) -> 720 | G22: =SUM($F$4:F22)+SUM($H$4:H22) -> 13585 | H22: 100 | I22: 6级 | J22: 6级 | K22: 6级 | L22: 6级 | M22: 6级 | N22: 6级 | O22: 空 | P22: 空 | Q22: 空 | R22: 空 | S22: 空 | T22: 空 | U22: 空 | V22: 空 | W22: 空 | X22: 空 | Y22: 6级 | Z22: 6级 | AA22: 6级 | AB22: 6级 | AC22: 6级 | AD22: 6级 | AE22: 空 | AF22: 空 | AG22: =AH22+AI22+AJ22 -> 0 | AK22: 是 | AM22: 大boss | AN22: 250 | AO22: 1000 | AQ22: =COUNTIF($I$4:$P$93,AM22) -> 0 | AR22: =COUNTIF($Q$4:$X$93,AM22) -> 1 | AS22: =COUNTIF($Y$4:$AF$93,AM22) -> 1 | AT22: =AQ22+AR22+AS22 -> 2 | AU22: =AQ22*$AO22 -> 0 | AV22: =AR22*$AO22 -> 1000 | AW22: =AS22*$AO22 -> 1000 | BA22: =AN22*0.8 -> 200
A23: 45294 | B23: 1600 | D23: =(SUM(粮草!A23:X23)+AG23*10)*IF(AK23="是",$AY$4,$AY$3) -> 1888 | E23: =SUM($B$4:B23)+SUM($C$4:C23)-SUM($D$4:D23) -> 1504 | F23: =SUM(经验!A23:X23) -> 1640 | G23: =SUM($F$4:F23)+SUM($H$4:H23) -> 15425 | H23: 200 | I23: 6级 | J23: 6级 | K23: 6级 | L23: 6级 | M23: 6级 | N23: 塔6 | O23: 空 | P23: 空 | Q23: 空 | R23: 空 | S23: 空 | T23: 空 | U23: 空 | V23: 空 | W23: 空 | X23: 空 | Y23: 5级 | Z23: 5级 | AA23: 5级 | AB23: 5级 | AC23: 6级 | AD23: 大boss | AE23: 空 | AF23: 空 | AG23: =AH23+AI23+AJ23 -> 0 | AK23: 是 | AM23: 中boss | AN23: 250 | AO23: 500 | AQ23: =COUNTIF($I$4:$P$93,AM23) -> 2 | AR23: =COUNTIF($Q$4:$X$93,AM23) -> 0 | AS23: =COUNTIF($Y$4:$AF$93,AM23) -> 0 | AT23: =AQ23+AR23+AS23 -> 2 | AU23: =AQ23*$AO23 -> 1000 | AV23: =AR23*$AO23 -> 0 | AW23: =AS23*$AO23 -> 0 | BA23: =AN23*0.8 -> 200
A24: 45295 | B24: 1600 | D24: =(SUM(粮草!A24:X24)+AG24*10)*IF(AK24="是",$AY$4,$AY$3) -> 1920 | E24: =SUM($B$4:B24)+SUM($C$4:C24)-SUM($D$4:D24) -> 1184 | F24: =SUM(经验!A24:X24) -> 720 | G24: =SUM($F$4:F24)+SUM($H$4:H24) -> 16145 | H24: 0 | I24: 6级 | J24: 6级 | K24: 6级 | L24: 6级 | M24: 6级 | N24: 6级 | O24: 空 | P24: 空 | Q24: 空 | R24: 空 | S24: 空 | T24: 空 | U24: 空 | V24: 空 | W24: 空 | X24: 空 | Y24: 6级 | Z24: 6级 | AA24: 6级 | AB24: 6级 | AC24: 6级 | AD24: 6级 | AE24: 空 | AF24: 空 | AG24: =AH24+AI24+AJ24 -> 0 | AK24: 是 | AM24: 奈良 | AN24: 160 | AO24: 40 | AP24: 39.110982 | AQ24: =COUNTIF($I$4:$P$93,AM24) -> 0 | AR24: =COUNTIF($Q$4:$X$93,AM24) -> 0 | AS24: =COUNTIF($Y$4:$AF$93,AM24) -> 0 | AT24: =AQ24+AR24+AS24 -> 0 | AU24: =AQ24*$AO24 -> 0 | AV24: =AR24*$AO24 -> 0 | AW24: =AS24*$AO24 -> 0 | BA24: =AN24*0.8 -> 128
A25: 45296 | B25: 1600 | D25: =(SUM(粮草!A25:X25)+AG25*10)*IF(AK25="是",$AY$4,$AY$3) -> 1880 | E25: =SUM($B$4:B25)+SUM($C$4:C25)-SUM($D$4:D25) -> 904 | F25: =SUM(经验!A25:X25) -> 695 | G25: =SUM($F$4:F25)+SUM($H$4:H25) -> 16840 | H25: 0 | I25: 6级 | J25: 6级 | K25: 6级 | L25: 6级 | M25: 6级 | N25: 5级 | O25: 空 | P25: 空 | Q25: 空 | R25: 空 | S25: 空 | T25: 空 | U25: 空 | V25: 空 | W25: 空 | X25: 空 | Y25: 5级 | Z25: 5级 | AA25: 5级 | AB25: 5级 | AC25: 6级 | AD25: 6级 | AE25: 空 | AF25: 空 | AG25: =AH25+AI25+AJ25 -> 0 | AK25: 是 | AM25: 山中 | AN25: 160 | AO25: 40 | AP25: 39.110982 | AQ25: =COUNTIF($I$4:$P$93,AM25) -> 0 | AR25: =COUNTIF($Q$4:$X$93,AM25) -> 0 | AS25: =COUNTIF($Y$4:$AF$93,AM25) -> 0 | AT25: =AQ25+AR25+AS25 -> 0 | AU25: =AQ25*$AO25 -> 0 | AV25: =AR25*$AO25 -> 0 | AW25: =AS25*$AO25 -> 0 | BA25: =AN25*0.8 -> 128
A26: 45297 | B26: 1600 | D26: =(SUM(粮草!A26:X26)+AG26*10)*IF(AK26="是",$AY$4,$AY$3) -> 1864 | E26: =SUM($B$4:B26)+SUM($C$4:C26)-SUM($D$4:D26) -> 640 | F26: =SUM(经验!A26:X26) -> 685 | G26: =SUM($F$4:F26)+SUM($H$4:H26) -> 17525 | H26: 0 | I26: 5级 | J26: 5级 | K26: 5级 | L26: 5级 | M26: 5级 | N26: 5级 | O26: 空 | P26: 空 | Q26: 空 | R26: 空 | S26: 空 | T26: 空 | U26: 空 | V26: 空 | W26: 空 | X26: 空 | Y26: 6级 | Z26: 6级 | AA26: 6级 | AB26: 6级 | AC26: 6级 | AD26: 5级 | AE26: 空 | AF26: 空 | AG26: =AH26+AI26+AJ26 -> 0 | AK26: 是 | AM26: 秋道 | AN26: 150 | AO26: 35 | AP26: 44.222109 | AQ26: =COUNTIF($I$4:$P$93,AM26) -> 0 | AR26: =COUNTIF($Q$4:$X$93,AM26) -> 0 | AS26: =COUNTIF($Y$4:$AF$93,AM26) -> 0 | AT26: =AQ26+AR26+AS26 -> 0 | AU26: =AQ26*$AO26 -> 0 | AV26: =AR26*$AO26 -> 0 | AW26: =AS26*$AO26 -> 0 | BA26: =AN26*0.8 -> 120
A27: 45298 | B27: 1600 | D27: =(SUM(粮草!A27:X27)+AG27*10)*IF(AK27="是",$AY$4,$AY$3) -> 1400 | E27: =SUM($B$4:B27)+SUM($C$4:C27)-SUM($D$4:D27) -> 840 | F27: =SUM(经验!A27:X27) -> 1070 | G27: =SUM($F$4:F27)+SUM($H$4:H27) -> 18595 | H27: 0 | I27: 5级 | J27: 5级 | K27: 营地+ | L27: 5级 | M27: 5级 | N27: 5级 | O27: 空 | P27: 空 | Q27: 空 | R27: 空 | S27: 空 | T27: 空 | U27: 空 | V27: 空 | W27: 空 | X27: 空 | Y27: 5级 | Z27: 历练 | AA27: 5级 | AB27: 5级 | AC27: 5级 | AD27: 5级 | AE27: 空 | AF27: 空 | AG27: =AH27+AI27+AJ27 -> 0 | AK27: 是 | AM27: 空 | AN27: 0 | AO27: 0 | AP27: 0 | AU27: =AQ27*$AO27 -> 0 | AV27: =AR27*$AO27 -> 0 | AW27: =AS27*$AO27 -> 0 | BA27: =AN27*0.8 -> 0
A28: 45299 | B28: 1600 | D28: =(SUM(粮草!A28:X28)+AG28*10)*IF(AK28="是",$AY$4,$AY$3) -> 1872 | E28: =SUM($B$4:B28)+SUM($C$4:C28)-SUM($D$4:D28) -> 568 | F28: =SUM(经验!A28:X28) -> 1105 | G28: =SUM($F$4:F28)+SUM($H$4:H28) -> 19900 | H28: 200 | I28: 5级 | J28: 5级 | K28: 5级 | L28: 中boss | M28: 5级 | N28: 5级 | O28: 空 | P28: 空 | Q28: 空 | R28: 空 | S28: 空 | T28: 空 | U28: 空 | V28: 空 | W28: 空 | X28: 空 | Y28: 5级 | Z28: 5级 | AA28: 5级 | AB28: 5级 | AC28: 5级 | AD28: 5级 | AE28: 空 | AF28: 空 | AG28: =AH28+AI28+AJ28 -> 0 | AK28: 是 | AL28: 八卦后 | AM28: 营地+ | AN28: -200 | AO28: 0 | AQ28: =COUNTIF($I$4:$P$93,AM28) -> 4 | AR28: =COUNTIF($Q$4:$X$93,AM28) -> 4 | AS28: =COUNTIF($Y$4:$AF$93,AM28) -> 4 | AT28: =AQ28+AR28+AS28 -> 12 | AU28: =AQ28*$AO28 -> 0 | AV28: =AR28*$AO28 -> 0 | AW28: =AS28*$AO28 -> 0 | BA28: =AN28*0.8 -> -160
A29: 45300 | B29: 1600 | D29: =(SUM(粮草!A29:X29)+AG29*10)*IF(AK29="是",$AY$4,$AY$3) -> 1480 | E29: =SUM($B$4:B29)+SUM($C$4:C29)-SUM($D$4:D29) -> 688 | F29: =SUM(经验!A29:X29) -> 585 | G29: =SUM($F$4:F29)+SUM($H$4:H29) -> 20585 | H29: 100 | I29: 5级 | J29: 5级 | K29: 5级 | L29: 5级 | M29: 5级 | N29: 5级 | O29: 空 | P29: 空 | Q29: 空 | R29: 空 | S29: 空 | T29: 空 | U29: 空 | V29: 空 | W29: 空 | X29: 空 | Y29: 5级 | Z29: 4级 | AA29: 营地+ | AB29: 4级 | AC29: 4级 | AD29: 4级 | AE29: 空 | AF29: 空 | AG29: =AH29+AI29+AJ29 -> 0 | AK29: 是 | AM29: 历练 | AN29: 50 | AO29: 520 | AQ29: =COUNTIF($I$4:$P$93,AM29) -> 1 | AR29: =COUNTIF($Q$4:$X$93,AM29) -> 1 | AS29: =COUNTIF($Y$4:$AF$93,AM29) -> 1 | AT29: =AQ29+AR29+AS29 -> 3 | AU29: =AQ29*$AO29 -> 520 | AV29: =AR29*$AO29 -> 520 | AW29: =AS29*$AO29 -> 520 | BA29: =AN29*0.8 -> 40
A30: 45301 | B30: 1600 | D30: =(SUM(粮草!A30:X30)+AG30*10)*IF(AK30="是",$AY$4,$AY$3) -> 1752 | E30: =SUM($B$4:B30)+SUM($C$4:C30)-SUM($D$4:D30) -> 536 | F30: =SUM(经验!A30:X30) -> 615 | G30: =SUM($F$4:F30)+SUM($H$4:H30) -> 21400 | H30: 200 | I30: 5级 | J30: 5级 | K30: 5级 | L30: 4级 | M30: 4级 | N30: 4级 | O30: 空 | P30: 空 | Q30: 空 | R30: 空 | S30: 空 | T30: 空 | U30: 空 | V30: 空 | W30: 空 | X30: 空 | Y30: 4级 | Z30: 4级 | AA30: 4级 | AB30: 4级 | AC30: 4级 | AD30: 4级 | AE30: 空 | AF30: 空 | AG30: =AH30+AI30+AJ30 -> 0 | AK30: 是
A31: 45302 | B31: 1600 | D31: =(SUM(粮草!A31:X31)+AG31*10)*IF(AK31="是",$AY$4,$AY$3) -> 1640 | E31: =SUM($B$4:B31)+SUM($C$4:C31)-SUM($D$4:D31) -> 496 | F31: =SUM(经验!A31:X31) -> 590 | G31: =SUM($F$4:F31)+SUM($H$4:H31) -> 21990 | H31: 0 | I31: 4级 | J31: 4级 | K31: 4级 | L31: 4级 | M31: 5级 | N31: 5级 | O31: 空 | P31: 空 | Q31: 空 | R31: 空 | S31: 空 | T31: 空 | U31: 空 | V31: 空 | W31: 空 | X31: 空 | Y31: 4级 | Z31: 商人 | AA31: 4级 | AB31: 4级 | AC31: 4级 | AD31: 4级 | AE31: 空 | AF31: 空 | AG31: =AH31+AI31+AJ31 -> 0 | AK31: 是
A32: 45303 | B32: 1600 | D32: =(SUM(粮草!A32:X32)+AG32*10)*IF(AK32="是",$AY$4,$AY$3) -> 1464 | E32: =SUM($B$4:B32)+SUM($C$4:C32)-SUM($D$4:D32) -> 632 | F32: =SUM(经验!A32:X32) -> 515 | G32: =SUM($F$4:F32)+SUM($H$4:H32) -> 22505 | H32: 0 | I32: 5级 | J32: 5级 | K32: 5级 | L32: 4级 | M32: 4级 | N32: 4级 | O32: 空 | P32: 空 | Q32: 空 | R32: 空 | S32: 空 | T32: 空 | U32: 空 | V32: 空 | W32: 空 | X32: 空 | Y32: 4级 | Z32: 4级 | AA32: 4级 | AB32: 4级 | AC32: 空 | AD32: 空 | AE32: 空 | AF32: 空 | AG32: =AH32+AI32+AJ32 -> 0 | AK32: 是
A33: 45304 | B33: 1600 | D33: =(SUM(粮草!A33:X33)+AG33*10)*IF(AK33="是",$AY$4,$AY$3) -> 1576 | E33: =SUM($B$4:B33)+SUM($C$4:C33)-SUM($D$4:D33) -> 656 | F33: =SUM(经验!A33:X33) -> 550 | G33: =SUM($F$4:F33)+SUM($H$4:H33) -> 23055 | H33: 0 | I33: 商人 | J33: 4级 | K33: 4级 | L33: 4级 | M33: 4级 | N33: 4级 | O33: 空 | P33: 空 | Q33: 空 | R33: 空 | S33: 空 | T33: 空 | U33: 空 | V33: 空 | W33: 空 | X33: 空 | Y33: 3级 | Z33: 3级 | AA33: 3级 | AB33: 3级 | AC33: 3级 | AD33: 3级 | AE33: 空 | AF33: 空 | AG33: =AH33+AI33+AJ33 -> 0 | AK33: 是
A34: 45305 | B34: 1600 | D34: =(SUM(粮草!A34:X34)+AG34*10)*IF(AK34="是",$AY$4,$AY$3) -> 1536 | E34: =SUM($B$4:B34)+SUM($C$4:C34)-SUM($D$4:D34) -> 720 | F34: =SUM(经验!A34:X34) -> 520 | G34: =SUM($F$4:F34)+SUM($H$4:H34) -> 23575 | H34: 0 | I34: 4级 | J34: 4级 | K34: 4级 | L34: 4级 | M34: 4级 | N34: 空 | O34: 空 | P34: 空 | Q34: 空 | R34: 空 | S34: 空 | T34: 空 | U34: 空 | V34: 空 | W34: 空 | X34: 空 | Y34: 3级 | Z34: 3级 | AA34: 3级 | AB34: 3级 | AC34: 3级 | AD34: 3级 | AE34: 空 | AF34: 空 | AG34: =AH34+AI34+AJ34 -> 0 | AK34: 是
A35: 45306 | B35: 1600 | D35: =(SUM(粮草!A35:X35)+AG35*10)*IF(AK35="是",$AY$4,$AY$3) -> 1536 | E35: =SUM($B$4:B35)+SUM($C$4:C35)-SUM($D$4:D35) -> 784 | F35: =SUM(经验!A35:X35) -> 525 | G35: =SUM($F$4:F35)+SUM($H$4:H35) -> 24300 | H35: 200 | I35: 3级 | J35: 3级 | K35: 3级 | L35: 3级 | M35: 3级 | N35: 3级 | O35: 空 | P35: 空 | Q35: 空 | R35: 空 | S35: 空 | T35: 空 | U35: 空 | V35: 空 | W35: 空 | X35: 空 | Y35: 商人 | Z35: 3级 | AA35: 3级 | AB35: 3级 | AC35: 3级 | AD35: 3级 | AE35: 空 | AF35: 空 | AG35: =AH35+AI35+AJ35 -> 0 | AK35: 是
A36: 45307 | B36: 1600 | D36: =(SUM(粮草!A36:X36)+AG36*10)*IF(AK36="是",$AY$4,$AY$3) -> 1632 | E36: =SUM($B$4:B36)+SUM($C$4:C36)-SUM($D$4:D36) -> 752 | F36: =SUM(经验!A36:X36) -> 540 | G36: =SUM($F$4:F36)+SUM($H$4:H36) -> 24940 | H36: 100 | I36: 3级 | J36: 3级 | K36: 3级 | L36: 3级 | M36: 3级 | N36: 3级 | O36: 空 | P36: 空 | Q36: 空 | R36: 空 | S36: 空 | T36: 空 | U36: 空 | V36: 空 | W36: 空 | X36: 空 | Y36: 3级 | Z36: 3级 | AA36: 3级 | AB36: 3级 | AC36: 3级 | AD36: 3级 | AE36: 空 | AF36: 空 | AG36: =AH36+AI36+AJ36 -> 0 | AK36: 是
A37: 45308 | B37: 1600 | D37: =(SUM(粮草!A37:X37)+AG37*10)*IF(AK37="是",$AY$4,$AY$3) -> 1384 | E37: =SUM($B$4:B37)+SUM($C$4:C37)-SUM($D$4:D37) -> 968 | F37: =SUM(经验!A37:X37) -> 525 | G37: =SUM($F$4:F37)+SUM($H$4:H37) -> 25665 | H37: 200 | I37: 3级 | J37: 3级 | K37: 3级 | L37: 3级 | M37: 3级 | N37: 3级 | O37: 空 | P37: 空 | Q37: 空 | R37: 空 | S37: 空 | T37: 空 | U37: 空 | V37: 空 | W37: 空 | X37: 空 | Y37: 3级 | Z37: 3级 | AA37: 3级 | AB37: 3级 | AC37: 商人 | AD37: 3级 | AE37: 营地+ | AF37: 空 | AG37: =AH37+AI37+AJ37 -> 1 | AJ37: 1 | AK37: 是
A38: 45309 | B38: 1600 | D38: =(SUM(粮草!A38:X38)+AG38*10)*IF(AK38="是",$AY$4,$AY$3) -> 2080 | E38: =SUM($B$4:B38)+SUM($C$4:C38)-SUM($D$4:D38) -> 488 | F38: =SUM(经验!A38:X38) -> 760 | G38: =SUM($F$4:F38)+SUM($H$4:H38) -> 26425 | H38: 0 | I38: 3级 | J38: 2级 | K38: 商人 | L38: 3级 | M38: 营地+ | N38: 3级 | O38: 空 | P38: 空 | Q38: 3级 | R38: 4级 | S38: 4级 | T38: 4级 | U38: 4级 | V38: 4级 | W38: 空 | X38: 空 | Y38: 2级 | Z38: 3级 | AA38: 3级 | AB38: 3级 | AC38: 3级 | AD38: 2级 | AE38: 空 | AF38: 空 | AG38: =AH38+AI38+AJ38 -> 1 | AH38: 1 | AK38: 是
A39: 45310 | B39: 1600 | D39: =(SUM(粮草!A39:X39)+AG39*10)*IF(AK39="是",$AY$4,$AY$3) -> 2024 | E39: =SUM($B$4:B39)+SUM($C$4:C39)-SUM($D$4:D39) -> 64 | F39: =SUM(经验!A39:X39) -> 720 | G39: =SUM($F$4:F39)+SUM($H$4:H39) -> 27145 | H39: 0 | I39: 3级 | J39: 3级 | K39: 商人 | L39: 3级 | M39: 3级 | N39: 3级 | O39: 空 | P39: 空 | Q39: 4级 | R39: 4级 | S39: 4级 | T39: 4级 | U39: 4级 | V39: 空 | W39: 空 | X39: 空 | Y39: 商人 | Z39: 2级 | AA39: 2级 | AB39: 2级 | AC39: 1级 | AD39: 商人 | AE39: 空 | AF39: 空 | AG39: =AH39+AI39+AJ39 -> 0 | AK39: 是 | AM39: 2级194
A40: 45311 | B40: 1600 | D40: =(SUM(粮草!A40:X40)+AG40*10)*IF(AK40="是",$AY$4,$AY$3) -> 1384 | E40: =SUM($B$4:B40)+SUM($C$4:C40)-SUM($D$4:D40) -> 280 | F40: =SUM(经验!A40:X40) -> 1070 | G40: =SUM($F$4:F40)+SUM($H$4:H40) -> 28215 | H40: 0 | I40: 3级 | J40: 2级 | K40: 2级 | L40: 商人 | M40: 2级 | N40: 历练 | O40: 空 | P40: 空 | Q40: 4级 | R40: 商人 | S40: 5级 | T40: 5级 | U40: 5级 | V40: 营地+ | W40: 5级 | X40: 5级 | Y40: 空 | Z40: 空 | AA40: 空 | AB40: 空 | AC40: 空 | AD40: 空 | AE40: 空 | AF40: 空 | AG40: =AH40+AI40+AJ40 -> 0 | AK40: 是 | AM40: 3级349
...

Sheet 粮草
A2: 队伍一 风 | C2: 步数 | D2: =COUNTIF(A4:H94,"<>空") -> 728 | E2: (不算跳步和传送) | I2: 队伍二 雷 | K2: 步数 | L2: =COUNTIF(I4:P94,"<>空") -> 728 | M2: (不算跳步和传送) | Q2: 队伍三 | S2: 总步数 | T2: =COUNTIF(Q4:X94,"<>空") -> 728 | U2: (不算跳步和传送)
A3: 1 | B3: 2 | C3: 3 | D3: 4 | E3: 5 | F3: 6 | G3: 7 | H3: 8 | I3: 1 | J3: 2 | K3: 3 | L3: 4 | M3: 5 | N3: 6 | O3: 7 | P3: 8 | Q3: 1 | R3: 2 | S3: 3 | T3: 4 | U3: 5 | V3: 6 | W3: 7 | X3: 8
A4: =(VLOOKUP('14.05'!I4,'14.05'!$AM$4:$AO$55,2,FALSE))*IF('14.05'!AK$4="是",'14.05'!$AY$4,'14.05'!$AY$3) -> 150 | B4: =(VLOOKUP('14.05'!J4,'14.05'!$AM$4:$AO$55,2,FALSE))*IF('14.05'!AL$4="是",'14.05'!$AY$4,'14.05'!$AY$3) -> 150 | C4: =(VLOOKUP('14.05'!K4,'14.05'!$AM$4:$AO$55,2,FALSE))*IF('14.05'!AM$4="是",'14.05'!$AY$4,'14.05'!$AY$3) -> 150 | D4: =(VLOOKUP('14.05'!L4,'14.05'!$AM$4:$AO$55,2,FALSE))*IF('14.05'!AN$4="是",'14.05'!$AY$4,'14.05'!$AY$3) -> 0 | E4: =(VLOOKUP('14.05'!M4,'14.05'!$AM$4:$AO$55,2,FALSE))*IF('14.05'!AO$4="是",'14.05'!$AY$4,'14.05'!$AY$3) -> 0 | F4: =(VLOOKUP('14.05'!N4,'14.05'!$AM$4:$AO$55,2,FALSE))*IF('14.05'!AQ$4="是",'14.05'!$AY$4,'14.05'!$AY$3) -> 0 | G4: =(VLOOKUP('14.05'!O4,'14.05'!$AM$4:$AO$55,2,FALSE))*IF('14.05'!AR$4="是",'14.05'!$AY$4,'14.05'!$AY$3) -> 0 | H4: =(VLOOKUP('14.05'!P4,'14.05'!$AM$4:$AO$55,2,FALSE))*IF('14.05'!AS$4="是",'14.05'!$AY$4,'14.05'!$AY$3) -> 0 | I4: =(VLOOKUP('14.05'!Q4,'14.05'!$AM$4:$AO$55,2,FALSE))*IF('14.05'!AT$4="是",'14.05'!$AY$4,'14.05'!$AY$3) -> 150 | J4: =(VLOOKUP('14.05'!R4,'14.05'!$AM$4:$AO$55,2,FALSE))*IF('14.05'!AU$4="是",'14.05'!$AY$4,'14.05'!$AY$3) -> 50 | K4: =(VLOOKUP('14.05'!S4,'14.05'!$AM$4:$AO$55,2,FALSE))*IF('14.05'!AV$4="是",'14.05'!$AY$4,'14.05'!$AY$3) -> 150 | L4: =(VLOOKUP('14.05'!T4,'14.05'!$AM$4:$AO$55,2,FALSE))*IF('14.05'!AW$4="是",'14.05'!$AY$4,'14.05'!$AY$3) -> 160 | M4: =(VLOOKUP('14.05'!U4,'14.05'!$AM$4:$AO$55,2,FALSE))*IF('14.05'!AX$4="是",'14.05'!$AY$4,'14.05'!$AY$3) -> 0 | ... X4: =(VLOOKUP('14.05'!AF4,'14.05'!$AM$4:$AO$55,2,FALSE))*IF('14.05'!BI$4="是",'14.05'!$AY$4,'14.05'!$AY$3) -> 0
A5: =(VLOOKUP('14.05'!I5,'14.05'!$AM$4:$AO$55,2,FALSE))*IF('14.05'!AK$4="是",'14.05'!$AY$4,'14.05'!$AY$3) -> 150 | B5: =(VLOOKUP('14.05'!J5,'14.05'!$AM$4:$AO$55,2,FALSE))*IF('14.05'!AL$4="是",'14.05'!$AY$4,'14.05'!$AY$3) -> 150 | C5: =(VLOOKUP('14.05'!K5,'14.05'!$AM$4:$AO$55,2,FALSE))*IF('14.05'!AM$4="是",'14.05'!$AY$4,'14.05'!$AY$3) -> 50 | D5: =(VLOOKUP('14.05'!L5,'14.05'!$AM$4:$AO$55,2,FALSE))*IF('14.05'!AN$4="是",'14.05'!$AY$4,'14.05'!$AY$3) -> 150 | E5: =(VLOOKUP('14.05'!M5,'14.05'!$AM$4:$AO$55,2,FALSE))*IF('14.05'!AO$4="是",'14.05'!$AY$4,'14.05'!$AY$3) -> 150 | F5: =(VLOOKUP('14.05'!N5,'14.05'!$AM$4:$AO$55,2,FALSE))*IF('14.05'!AQ$4="是",'14.05'!$AY$4,'14.05'!$AY$3) -> 160 | G5: =(VLOOKUP('14.05'!O5,'14.05'!$AM$4:$AO$55,2,FALSE))*IF('14.05'!AR$4="是",'14.05'!$AY$4,'14.05'!$AY$3) -> 0 | H5: =(VLOOKUP('14.05'!P5,'14.05'!$AM$4:$AO$55,2,FALSE))*IF('14.05'!AS$4="是",'14.05'!$AY$4,'14.05'!$AY$3) -> 0 | I5: =(VLOOKUP('14.05'!Q5,'14.05'!$AM$4:$AO$55,2,FALSE))*IF('14.05'!AT$4="是",'14.05'!$AY$4,'14.05'!$AY$3) -> 0 | J5: =(VLOOKUP('14.05'!R5,'14.05'!$AM$4:$AO$55,2,FALSE))*IF('14.05'!AU$4="是",'14.05'!$AY$4,'14.05'!$AY$3) -> 0 | K5: =(VLOOKUP('14.05'!S5,'14.05'!$AM$4:$AO$55,2,FALSE))*IF('14.05'!AV$4="是",'14.05'!$AY$4,'14.05'!$AY$3) -> 0 | L5: =(VLOOKUP('14.05'!T5,'14.05'!$AM$4:$AO$55,2,FALSE))*IF('14.05'!AW$4="是",'14.05'!$AY$4,'14.05'!$AY$3) -> 0 | M5: =(VLOOKUP('14.05'!U5,'14.05'!$AM$4:$AO$55,2,FALSE))*IF('14.05'!AX$4="是",'14.05'!$AY$4,'14.05'!$AY$3) -> 0 | ... X5: =(VLOOKUP('14.05'!AF5,'14.05'!$AM$4:$AO$55,2,FALSE))*IF('14.05'!BI$4="是",'14.05'!$AY$4,'14.05'!$AY$3) -> 170
A6: =(VLOOKUP('14.05'!I6,'14.05'!$AM$4:$AO$55,2,FALSE))*IF('14.05'!AK$4="是",'14.05'!$AY$4,'14.05'!$AY$3) -> 160 | B6: =(VLOOKUP('14.05'!J6,'14.05'!$AM$4:$AO$55,2,FALSE))*IF('14.05'!AL$4="是",'14.05'!$AY$4,'14.05'!$AY$3) -> 50 | C6: =(VLOOKUP('14.05'!K6,'14.05'!$AM$4:$AO$55,2,FALSE))*IF('14.05'!AM$4="是",'14.05'!$AY$4,'14.05'!$AY$3) -> 160 | D6: =(VLOOKUP('14.05'!L6,'14.05'!$AM$4:$AO$55,2,FALSE))*IF('14.05'!AN$4="是",'14.05'!$AY$4,'14.05'!$AY$3) -> 160 | E6: =(VLOOKUP('14.05'!M6,'14.05'!$AM$4:$AO$55,2,FALSE))*IF('14.05'!AO$4="是",'14.05'!$AY$4,'14.05'!$AY$3) -> -150 | F6: =(VLOOKUP('14.05'!N6,'14.05'!$AM$4:$AO$55,2,FALSE))*IF('14.05'!AQ$4="是",'14.05'!$AY$4,'14.05'!$AY$3) -> 170 | G6: =(VLOOKUP('14.05'!O6,'14.05'!$AM$4:$AO$55,2,FALSE))*IF('14.05'!AR$4="是",'14.05'!$AY$4,'14.05'!$AY$3) -> 170 | H6: =(VLOOKUP('14.05'!P6,'14.05'!$AM$4:$AO$55,2,FALSE))*IF('14.05'!AS$4="是",'14.05'!$AY$4,'14.05'!$AY$3) -> 170 | I6: =(VLOOKUP('14.05'!Q6,'14.05'!$AM$4:$AO$55,2,FALSE))*IF('14.05'!AT$4="是",'14.05'!$AY$4,'14.05'!$AY$3) -> 0 | J6: =(VLOOKUP('14.05'!R6,'14.05'!$AM$4:$AO$55,2,FALSE))*IF('14.05'!AU$4="是",'14.05'!$AY$4,'14.05'!$AY$3) -> 0 | K6: =(VLOOKUP('14.05'!S6,'14.05'!$AM$4:$AO$55,2,FALSE))*IF('14.05'!AV$4="是",'14.05'!$AY$4,'14.05'!$AY$3) -> 0 | L6: =(VLOOKUP('14.05'!T6,'14.05'!$AM$4:$AO$55,2,FALSE))*IF('14.05'!AW$4="是",'14.05'!$AY$4,'14.05'!$AY$3) -> 0 | M6: =(VLOOKUP('14.05'!U6,'14.05'!$AM$4:$AO$55,2,FALSE))*IF('14.05'!AX$4="是",'14.05'!$AY$4,'14.05'!$AY$3) -> 0 | ... X6: =(VLOOKUP('14.05'!AF6,'14.05'!$AM$4:$AO$55,2,FALSE))*IF('14.05'!BI$4="是",'14.05'!$AY$4,'14.05'!$AY$3) -> 0
A7: =(VLOOKUP('14.05'!I7,'14.05'!$AM$4:$AO$55,2,FALSE))*IF('14.05'!AK$4="是",'14.05'!$AY$4,'14.05'!$AY$3) -> 170 | B7: =(VLOOKUP('14.05'!J7,'14.05'!$AM$4:$AO$55,2,FALSE))*IF('14.05'!AL$4="是",'14.05'!$AY$4,'14.05'!$AY$3) -> 250 | C7: =(VLOOKUP('14.05'!K7,'14.05'!$AM$4:$AO$55,2,FALSE))*IF('14.05'!AM$4="是",'14.05'!$AY$4,'14.05'!$AY$3) -> 170 | D7: =(VLOOKUP('14.05'!L7,'14.05'!$AM$4:$AO$55,2,FALSE))*IF('14.05'!AN$4="是",'14.05'!$AY$4,'14.05'!$AY$3) -> 170 | E7: =(VLOOKUP('14.05'!M7,'14.05'!$AM$4:$AO$55,2,FALSE))*IF('14.05'!AO$4="是",'14.05'!$AY$4,'14.05'!$AY$3) -> 150 | F7: =(VLOOKUP('14.05'!N7,'14.05'!$AM$4:$AO$55,2,FALSE))*IF('14.05'!AQ$4="是",'14.05'!$AY$4,'14.05'!$AY$3) -> 170 | G7: =(VLOOKUP('14.05'!O7,'14.05'!$AM$4:$AO$55,2,FALSE))*IF('14.05'!AR$4="是",'14.05'!$AY$4,'14.05'!$AY$3) -> 0 | H7: =(VLOOKUP('14.05'!P7,'14.05'!$AM$4:$AO$55,2,FALSE))*IF('14.05'!AS$4="是",'14.05'!$AY$4,'14.05'!$AY$3) -> 0 | I7: =(VLOOKUP('14.05'!Q7,'14.05'!$AM$4:$AO$55,2,FALSE))*IF('14.05'!AT$4="是",'14.05'!$AY$4,'14.05'!$AY$3) -> 0 | J7: =(VLOOKUP('14.05'!R7,'14.05'!$AM$4:$AO$55,2,FALSE))*IF('14.05'!AU$4="是",'14.05'!$AY$4,'14.05'!$AY$3) -> 0 | K7: =(VLOOKUP('14.05'!S7,'14.05'!$AM$4:$AO$55,2,FALSE))*IF('14.05'!AV$4="是",'14.05'!$AY$4,'14.05'!$AY$3) -> 0 | L7: =(VLOOKUP('14.05'!T7,'14.05'!$AM$4:$AO$55,2,FALSE))*IF('14.05'!AW$4="是",'14.05'!$AY$4,'14.05'!$AY$3) -> 0 | M7: =(VLOOKUP('14.05'!U7,'14.05'!$AM$4:$AO$55,2,FALSE))*IF('14.05'!AX$4="是",'14.05'!$AY$4,'14.05'!$AY$3) -> 0 | ... X7: =(VLOOKUP('14.05'!AF7,'14.05'!$AM$4:$AO$55,2,FALSE))*IF('14.05'!BI$4="是",'14.05'!$AY$4,'14.05'!$AY$3) -> 0
A8: =(VLOOKUP('14.05'!I8,'14.05'!$AM$4:$AO$55,2,FALSE))*IF('14.05'!AK$4="是",'14.05'!$AY$4,'14.05'!$AY$3) -> 170 | B8: =(VLOOKUP('14.05'!J8,'14.05'!$AM$4:$AO$55,2,FALSE))*IF('14.05'!AL$4="是",'14.05'!$AY$4,'14.05'!$AY$3) -> 170 | C8: =(VLOOKUP('14.05'!K8,'14.05'!$AM$4:$AO$55,2,FALSE))*IF('14.05'!AM$4="是",'14.05'!$AY$4,'14.05'!$AY$3) -> 170 | D8: =(VLOOKUP('14.05'!L8,'14.05'!$AM$4:$AO$55,2,FALSE))*IF('14.05'!AN$4="是",'14.05'!$AY$4,'14.05'!$AY$3) -> 170 | E8: =(VLOOKUP('14.05'!M8,'14.05'!$AM$4:$AO$55,2,FALSE))*IF('14.05'!AO$4="是",'14.05'!$AY$4,'14.05'!$AY$3) -> 170 | F8: =(VLOOKUP('14.05'!N8,'14.05'!$AM$4:$AO$55,2,FALSE))*IF('14.05'!AQ$4="是",'14.05'!$AY$4,'14.05'!$AY$3) -> 170 | G8: =(VLOOKUP('14.05'!O8,'14.05'!$AM$4:$AO$55,2,FALSE))*IF('14.05'!AR$4="是",'14.05'!$AY$4,'14.05'!$AY$3) -> 0 | H8: =(VLOOKUP('14.05'!P8,'14.05'!$AM$4:$AO$55,2,FALSE))*IF('14.05'!AS$4="是",'14.05'!$AY$4,'14.05'!$AY$3) -> 0 | I8: =(VLOOKUP('14.05'!Q8,'14.05'!$AM$4:$AO$55,2,FALSE))*IF('14.05'!AT$4="是",'14.05'!$AY$4,'14.05'!$AY$3) -> 0 | J8: =(VLOOKUP('14.05'!R8,'14.05'!$AM$4:$AO$55,2,FALSE))*IF('14.05'!AU$4="是",'14.05'!$AY$4,'14.05'!$AY$3) -> 0 | K8: =(VLOOKUP('14.05'!S8,'14.05'!$AM$4:$AO$55,2,FALSE))*IF('14.05'!AV$4="是",'14.05'!$AY$4,'14.05'!$AY$3) -> 0 | L8: =(VLOOKUP('14.05'!T8,'14.05'!$AM$4:$AO$55,2,FALSE))*IF('14.05'!AW$4="是",'14.05'!$AY$4,'14.05'!$AY$3) -> 0 | M8: =(VLOOKUP('14.05'!U8,'14.05'!$AM$4:$AO$55,2,FALSE))*IF('14.05'!AX$4="是",'14.05'!$AY$4,'14.05'!$AY$3) -> 0 | ... X8: =(VLOOKUP('14.05'!AF8,'14.05'!$AM$4:$AO$55,2,FALSE))*IF('14.05'!BI$4="是",'14.05'!$AY$4,'14.05'!$AY$3) -> 0
A9: =(VLOOKUP('14.05'!I9,'14.05'!$AM$4:$AO$55,2,FALSE))*IF('14.05'!AK$4="是",'14.05'!$AY$4,'14.05'!$AY$3) -> 170 | B9: =(VLOOKUP('14.05'!J9,'14.05'!$AM$4:$AO$55,2,FALSE))*IF('14.05'!AL$4="是",'14.05'!$AY$4,'14.05'!$AY$3) -> 0 | C9: =(VLOOKUP('14.05'!K9,'14.05'!$AM$4:$AO$55,2,FALSE))*IF('14.05'!AM$4="是",'14.05'!$AY$4,'14.05'!$AY$3) -> 0 | D9: =(VLOOKUP('14.05'!L9,'14.05'!$AM$4:$AO$55,2,FALSE))*IF('14.05'!AN$4="是",'14.05'!$AY$4,'14.05'!$AY$3) -> 0 | E9: =(VLOOKUP('14.05'!M9,'14.05'!$AM$4:$AO$55,2,FALSE))*IF('14.05'!AO$4="是",'14.05'!$AY$4,'14.05'!$AY$3) -> 0 | F9: =(VLOOKUP('14.05'!N9,'14.05'!$AM$4:$AO$55,2,FALSE))*IF('14.05'!AQ$4="是",'14.05'!$AY$4,'14.05'!$AY$3) -> 0 | G9: =(VLOOKUP('14.05'!O9,'14.05'!$AM$4:$AO$55,2,FALSE))*IF('14.05'!AR$4="是",'14.05'!$AY$4,'14.05'!$AY$3) -> 0 | H9: =(VLOOKUP('14.05'!P9,'14.05'!$AM$4:$AO$55,2,FALSE))*IF('14.05'!AS$4="是",'14.05'!$AY$4,'14.05'!$AY$3) -> 0 | I9: =(VLOOKUP('14.05'!Q9,'14.05'!$AM$4:$AO$55,2,FALSE))*IF('14.05'!AT$4="是",'14.05'!$AY$4,'14.05'!$AY$3) -> 0 | J9: =(VLOOKUP('14.05'!R9,'14.05'!$AM$4:$AO$55,2,FALSE))*IF('14.05'!AU$4="是",'14.05'!$AY$4,'14.05'!$AY$3) -> 0 | K9: =(VLOOKUP('14.05'!S9,'14.05'!$AM$4:$AO$55,2,FALSE))*IF('14.05'!AV$4="是",'14.05'!$AY$4,'14.05'!$AY$3) -> 0 | L9: =(VLOOKUP('14.05'!T9,'14.05'!$AM$4:$AO$55,2,FALSE))*IF('14.05'!AW$4="是",'14.05'!$AY$4,'14.05'!$AY$3) -> 0 | M9: =(VLOOKUP('14.05'!U9,'14.05'!$AM$4:$AO$55,2,FALSE))*IF('14.05'!AX$4="是",'14.05'!$AY$4,'14.05'!$AY$3) -> 0 | ... X9: =(VLOOKUP('14.05'!AF9,'14.05'!$AM$4:$AO$55,2,FALSE))*IF('14.05'!BI$4="是",'14.05'!$AY$4,'14.05'!$AY$3) -> 0
A10: =(VLOOKUP('14.05'!I10,'14.05'!$AM$4:$AO$55,2,FALSE))*IF('14.05'!AK$4="是",'14.05'!$AY$4,'14.05'!$AY$3) -> 0 | B10: =(VLOOKUP('14.05'!J10,'14.05'!$AM$4:$AO$55,2,FALSE))*IF('14.05'!AL$4="是",'14.05'!$AY$4,'14.05'!$AY$3) -> 0 | C10: =(VLOOKUP('14.05'!K10,'14.05'!$AM$4:$AO$55,2,FALSE))*IF('14.05'!AM$4="是",'14.05'!$AY$4,'14.05'!$AY$3) -> 0 | D10: =(VLOOKUP('14.05'!L10,'14.05'!$AM$4:$AO$55,2,FALSE))*IF('14.05'!AN$4="是",'14.05'!$AY$4,'14.05'!$AY$3) -> 0 | E10: =(VLOOKUP('14.05'!M10,'14.05'!$AM$4:$AO$55,2,FALSE))*IF('14.05'!AO$4="是",'14.05'!$AY$4,'14.05'!$AY$3) -> 0 | F10: =(VLOOKUP('14.05'!N10,'14.05'!$AM$4:$AO$55,2,FALSE))*IF('14.05'!AQ$4="是",'14.05'!$AY$4,'14.05'!$AY$3) -> 0 | G10: =(VLOOKUP('14.05'!O10,'14.05'!$AM$4:$AO$55,2,FALSE))*IF('14.05'!AR$4="是",'14.05'!$AY$4,'14.05'!$AY$3) -> 0 | H10: =(VLOOKUP('14.05'!P10,'14.05'!$AM$4:$AO$55,2,FALSE))*IF('14.05'!AS$4="是",'14.05'!$AY$4,'14.05'!$AY$3) -> 0 | I10: =(VLOOKUP('14.05'!Q10,'14.05'!$AM$4:$AO$55,2,FALSE))*IF('14.05'!AT$4="是",'14.05'!$AY$4,'14.05'!$AY$3) -> 0 | J10: =(VLOOKUP('14.05'!R10,'14.05'!$AM$4:$AO$55,2,FALSE))*IF('14.05'!AU$4="是",'14.05'!$AY$4,'14.05'!$AY$3) -> 0 | K10: =(VLOOKUP('14.05'!S10,'14.05'!$AM$4:$AO$55,2,FALSE))*IF('14.05'!AV$4="是",'14.05'!$AY$4,'14.05'!$AY$3) -> 0 | L10: =(VLOOKUP('14.05'!T10,'14.05'!$AM$4:$AO$55,2,FALSE))*IF('14.05'!AW$4="是",'14.05'!$AY$4,'14.05'!$AY$3) -> 0 | M10: =(VLOOKUP('14.05'!U10,'14.05'!$AM$4:$AO$55,2,FALSE))*IF('14.05'!AX$4="是",'14.05'!$AY$4,'14.05'!$AY$3) -> 0 | ... X10: =(VLOOKUP('14.05'!AF10,'14.05'!$AM$4:$AO$55,2,FALSE))*IF('14.05'!BI$4="是",'14.05'!$AY$4,'14.05'!$AY$3) -> 170
A11: =(VLOOKUP('14.05'!I11,'14.05'!$AM$4:$AO$55,2,FALSE))*IF('14.05'!AK$4="是",'14.05'!$AY$4,'14.05'!$AY$3) -> 0 | B11: =(VLOOKUP('14.05'!J11,'14.05'!$AM$4:$AO$55,2,FALSE))*IF('14.05'!AL$4="是",'14.05'!$AY$4,'14.05'!$AY$3) -> 0 | C11: =(VLOOKUP('14.05'!K11,'14.05'!$AM$4:$AO$55,2,FALSE))*IF('14.05'!AM$4="是",'14.05'!$AY$4,'14.05'!$AY$3) -> 0 | D11: =(VLOOKUP('14.05'!L11,'14.05'!$AM$4:$AO$55,2,FALSE))*IF('14.05'!AN$4="是",'14.05'!$AY$4,'14.05'!$AY$3) -> 0 | E11: =(VLOOKUP('14.05'!M11,'14.05'!$AM$4:$AO$55,2,FALSE))*IF('14.05'!AO$4="是",'14.05'!$AY$4,'14.05'!$AY$3) -> 0 | F11: =(VLOOKUP('14.05'!N11,'14.05'!$AM$4:$AO$55,2,FALSE))*IF('14.05'!AQ$4="是",'14.05'!$AY$4,'14.05'!$AY$3) -> 0 | G11: =(VLOOKUP('14.05'!O11,'14.05'!$AM$4:$AO$55,2,FALSE))*IF('14.05'!AR$4="是",'14.05'!$AY$4,'14.05'!$AY$3) -> 0 | H11: =(VLOOKUP('14.05'!P11,'14.05'!$AM$4:$AO$55,2,FALSE))*IF('14.05'!AS$4="是",'14.05'!$AY$4,'14.05'!$AY$3) -> 0 | I11: =(VLOOKUP('14.05'!Q11,'14.05'!$AM$4:$AO$55,2,FALSE))*IF('14.05'!AT$4="是",'14.05'!$AY$4,'14.05'!$AY$3) -> 0 | J11: =(VLOOKUP('14.05'!R11,'14.05'!$AM$4:$AO$55,2,FALSE))*IF('14.05'!AU$4="是",'14.05'!$AY$4,'14.05'!$AY$3) -> 0 | K11: =(VLOOKUP('14.05'!S11,'14.05'!$AM$4:$AO$55,2,FALSE))*IF('14.05'!AV$4="是",'14.05'!$AY$4,'14.05'!$AY$3) -> 0 | L11: =(VLOOKUP('14.05'!T11,'14.05'!$AM$4:$AO$55,2,FALSE))*IF('14.05'!AW$4="是",'14.05'!$AY$4,'14.05'!$AY$3) -> 0 | M11: =(VLOOKUP('14.05'!U11,'14.05'!$AM$4:$AO$55,2,FALSE))*IF('14.05'!AX$4="是",'14.05'!$AY$4,'14.05'!$AY$3) -> 0 | ... X11: =(VLOOKUP('14.05'!AF11,'14.05'!$AM$4:$AO$55,2,FALSE))*IF('14.05'!BI$4="是",'14.05'!$AY$4,'14.05'!$AY$3) -> 0
A12: =(VLOOKUP('14.05'!I12,'14.05'!$AM$4:$AO$55,2,FALSE))*IF('14.05'!AK$4="是",'14.05'!$AY$4,'14.05'!$AY$3) -> 0 | B12: =(VLOOKUP('14.05'!J12,'14.05'!$AM$4:$AO$55,2,FALSE))*IF('14.05'!AL$4="是",'14.05'!$AY$4,'14.05'!$AY$3) -> 0 | C12: =(VLOOKUP('14.05'!K12,'14.05'!$AM$4:$AO$55,2,FALSE))*IF('14.05'!AM$4="是",'14.05'!$AY$4,'14.05'!$AY$3) -> 0 | D12: =(VLOOKUP('14.05'!L12,'14.05'!$AM$4:$AO$55,2,FALSE))*IF('14.05'!AN$4="是",'14.05'!$AY$4,'14.05'!$AY$3) -> 0 | E12: =(VLOOKUP('14.05'!M12,'14.05'!$AM$4:$AO$55,2,FALSE))*IF('14.05'!AO$4="是",'14.05'!$AY$4,'14.05'!$AY$3) -> 0 | F12: =(VLOOKUP('14.05'!N12,'14.05'!$AM$4:$AO$55,2,FALSE))*IF('14.05'!AQ$4="是",'14.05'!$AY$4,'14.05'!$AY$3) -> 0 | G12: =(VLOOKUP('14.05'!O12,'14.05'!$AM$4:$AO$55,2,FALSE))*IF('14.05'!AR$4="是",'14.05'!$AY$4,'14.05'!$AY$3) -> 0 | H12: =(VLOOKUP('14.05'!P12,'14.05'!$AM$4:$AO$55,2,FALSE))*IF('14.05'!AS$4="是",'14.05'!$AY$4,'14.05'!$AY$3) -> 0 | I12: =(VLOOKUP('14.05'!Q12,'14.05'!$AM$4:$AO$55,2,FALSE))*IF('14.05'!AT$4="是",'14.05'!$AY$4,'14.05'!$AY$3) -> 0 | J12: =(VLOOKUP('14.05'!R12,'14.05'!$AM$4:$AO$55,2,FALSE))*IF('14.05'!AU$4="是",'14.05'!$AY$4,'14.05'!$AY$3) -> 0 | K12: =(VLOOKUP('14.05'!S12,'14.05'!$AM$4:$AO$55,2,FALSE))*IF('14.05'!AV$4="是",'14.05'!$AY$4,'14.05'!$AY$3) -> 0 | L12: =(VLOOKUP('14.05'!T12,'14.05'!$AM$4:$AO$55,2,FALSE))*IF('14.05'!AW$4="是",'14.05'!$AY$4,'14.05'!$AY$3) -> 0 | M12: =(VLOOKUP('14.05'!U12,'14.05'!$AM$4:$AO$55,2,FALSE))*IF('14.05'!AX$4="是",'14.05'!$AY$4,'14.05'!$AY$3) -> 0 | ... X12: =(VLOOKUP('14.05'!AF12,'14.05'!$AM$4:$AO$55,2,FALSE))*IF('14.05'!BI$4="是",'14.05'!$AY$4,'14.05'!$AY$3) -> 0
A13: =(VLOOKUP('14.05'!I13,'14.05'!$AM$4:$AO$55,2,FALSE))*IF('14.05'!AK$4="是",'14.05'!$AY$4,'14.05'!$AY$3) -> 170 | B13: =(VLOOKUP('14.05'!J13,'14.05'!$AM$4:$AO$55,2,FALSE))*IF('14.05'!AL$4="是",'14.05'!$AY$4,'14.05'!$AY$3) -> 150 | C13: =(VLOOKUP('14.05'!K13,'14.05'!$AM$4:$AO$55,2,FALSE))*IF('14.05'!AM$4="是",'14.05'!$AY$4,'14.05'!$AY$3) -> 170 | D13: =(VLOOKUP('14.05'!L13,'14.05'!$AM$4:$AO$55,2,FALSE))*IF('14.05'!AN$4="是",'14.05'!$AY$4,'14.05'!$AY$3) -> 170 | E13: =(VLOOKUP('14.05'!M13,'14.05'!$AM$4:$AO$55,2,FALSE))*IF('14.05'!AO$4="是",'14.05'!$AY$4,'14.05'!$AY$3) -> 50 | F13: =(VLOOKUP('14.05'!N13,'14.05'!$AM$4:$AO$55,2,FALSE))*IF('14.05'!AQ$4="是",'14.05'!$AY$4,'14.05'!$AY$3) -> 170 | G13: =(VLOOKUP('14.05'!O13,'14.05'!$AM$4:$AO$55,2,FALSE))*IF('14.05'!AR$4="是",'14.05'!$AY$4,'14.05'!$AY$3) -> 0 | H13: =(VLOOKUP('14.05'!P13,'14.05'!$AM$4:$AO$55,2,FALSE))*IF('14.05'!AS$4="是",'14.05'!$AY$4,'14.05'!$AY$3) -> 0 | I13: =(VLOOKUP('14.05'!Q13,'14.05'!$AM$4:$AO$55,2,FALSE))*IF('14.05'!AT$4="是",'14.05'!$AY$4,'14.05'!$AY$3) -> 50 | J13: =(VLOOKUP('14.05'!R13,'14.05'!$AM$4:$AO$55,2,FALSE))*IF('14.05'!AU$4="是",'14.05'!$AY$4,'14.05'!$AY$3) -> 170 | K13: =(VLOOKUP('14.05'!S13,'14.05'!$AM$4:$AO$55,2,FALSE))*IF('14.05'!AV$4="是",'14.05'!$AY$4,'14.05'!$AY$3) -> 170 | L13: =(VLOOKUP('14.05'!T13,'14.05'!$AM$4:$AO$55,2,FALSE))*IF('14.05'!AW$4="是",'14.05'!$AY$4,'14.05'!$AY$3) -> 170 | M13: =(VLOOKUP('14.05'!U13,'14.05'!$AM$4:$AO$55,2,FALSE))*IF('14.05'!AX$4="是",'14.05'!$AY$4,'14.05'!$AY$3) -> 170 | ... X13: =(VLOOKUP('14.05'!AF13,'14.05'!$AM$4:$AO$55,2,FALSE))*IF('14.05'!BI$4="是",'14.05'!$AY$4,'14.05'!$AY$3) -> 0
A14: =(VLOOKUP('14.05'!I14,'14.05'!$AM$4:$AO$55,2,FALSE))*IF('14.05'!AK$4="是",'14.05'!$AY$4,'14.05'!$AY$3) -> 180 | B14: =(VLOOKUP('14.05'!J14,'14.05'!$AM$4:$AO$55,2,FALSE))*IF('14.05'!AL$4="是",'14.05'!$AY$4,'14.05'!$AY$3) -> 180 | C14: =(VLOOKUP('14.05'!K14,'14.05'!$AM$4:$AO$55,2,FALSE))*IF('14.05'!AM$4="是",'14.05'!$AY$4,'14.05'!$AY$3) -> 180 | D14: =(VLOOKUP('14.05'!L14,'14.05'!$AM$4:$AO$55,2,FALSE))*IF('14.05'!AN$4="是",'14.05'!$AY$4,'14.05'!$AY$3) -> 180 | E14: =(VLOOKUP('14.05'!M14,'14.05'!$AM$4:$AO$55,2,FALSE))*IF('14.05'!AO$4="是",'14.05'!$AY$4,'14.05'!$AY$3) -> 180 | F14: =(VLOOKUP('14.05'!N14,'14.05'!$AM$4:$AO$55,2,FALSE))*IF('14.05'!AQ$4="是",'14.05'!$AY$4,'14.05'!$AY$3) -> 180 | G14: =(VLOOKUP('14.05'!O14,'14.05'!$AM$4:$AO$55,2,FALSE))*IF('14.05'!AR$4="是",'14.05'!$AY$4,'14.05'!$AY$3) -> 0 | H14: =(VLOOKUP('14.05'!P14,'14.05'!$AM$4:$AO$55,2,FALSE))*IF('14.05'!AS$4="是",'14.05'!$AY$4,'14.05'!$AY$3) -> 0 | I14: =(VLOOKUP('14.05'!Q14,'14.05'!$AM$4:$AO$55,2,FALSE))*IF('14.05'!AT$4="是",'14.05'!$AY$4,'14.05'!$AY$3) -> 50 | J14: =(VLOOKUP('14.05'!R14,'14.05'!$AM$4:$AO$55,2,FALSE))*IF('14.05'!AU$4="是",'14.05'!$AY$4,'14.05'!$AY$3) -> 170 | K14: =(VLOOKUP('14.05'!S14,'14.05'!$AM$4:$AO$55,2,FALSE))*IF('14.05'!AV$4="是",'14.05'!$AY$4,'14.05'!$AY$3) -> 170 | L14: =(VLOOKUP('14.05'!T14,'14.05'!$AM$4:$AO$55,2,FALSE))*IF('14.05'!AW$4="是",'14.05'!$AY$4,'14.05'!$AY$3) -> 170 | M14: =(VLOOKUP('14.05'!U14,'14.05'!$AM$4:$AO$55,2,FALSE))*IF('14.05'!AX$4="是",'14.05'!$AY$4,'14.05'!$AY$3) -> 50 | ... X14: =(VLOOKUP('14.05'!AF14,'14.05'!$AM$4:$AO$55,2,FALSE))*IF('14.05'!BI$4="是",'14.05'!$AY$4,'14.05'!$AY$3) -> 0
A15: =(VLOOKUP('14.05'!I15,'14.05'!$AM$4:$AO$55,2,FALSE))*IF('14.05'!AK$4="是",'14.05'!$AY$4,'14.05'!$AY$3) -> 180 | B15: =(VLOOKUP('14.05'!J15,'14.05'!$AM$4:$AO$55,2,FALSE))*IF('14.05'!AL$4="是",'14.05'!$AY$4,'14.05'!$AY$3) -> 180 | C15: =(VLOOKUP('14.05'!K15,'14.05'!$AM$4:$AO$55,2,FALSE))*IF('14.05'!AM$4="是",'14.05'!$AY$4,'14.05'!$AY$3) -> 180 | D15: =(VLOOKUP('14.05'!L15,'14.05'!$AM$4:$AO$55,2,FALSE))*IF('14.05'!AN$4="是",'14.05'!$AY$4,'14.05'!$AY$3) -> 180 | E15: =(VLOOKUP('14.05'!M15,'14.05'!$AM$4:$AO$55,2,FALSE))*IF('14.05'!AO$4="是",'14.05'!$AY$4,'14.05'!$AY$3) -> 180 | F15: =(VLOOKUP('14.05'!N15,'14.05'!$AM$4:$AO$55,2,FALSE))*IF('14.05'!AQ$4="是",'14.05'!$AY$4,'14.05'!$AY$3) -> 180 | G15: =(VLOOKUP('14.05'!O15,'14.05'!$AM$4:$AO$55,2,FALSE))*IF('14.05'!AR$4="是",'14.05'!$AY$4,'14.05'!$AY$3) -> 0 | H15: =(VLOOKUP('14.05'!P15,'14.05'!$AM$4:$AO$55,2,FALSE))*IF('14.05'!AS$4="是",'14.05'!$AY$4,'14.05'!$AY$3) -> 0 | I15: =(VLOOKUP('14.05'!Q15,'14.05'!$AM$4:$AO$55,2,FALSE))*IF('14.05'!AT$4="是",'14.05'!$AY$4,'14.05'!$AY$3) -> 170 | J15: =(VLOOKUP('14.05'!R15,'14.05'!$AM$4:$AO$55,2,FALSE))*IF('14.05'!AU$4="是",'14.05'!$AY$4,'14.05'!$AY$3) -> 170 | K15: =(VLOOKUP('14.05'!S15,'14.05'!$AM$4:$AO$55,2,FALSE))*IF('14.05'!AV$4="是",'14.05'!$AY$4,'14.05'!$AY$3) -> 170 | L15: =(VLOOKUP('14.05'!T15,'14.05'!$AM$4:$AO$55,2,FALSE))*IF('14.05'!AW$4="是",'14.05'!$AY$4,'14.05'!$AY$3) -> 170 | M15: =(VLOOKUP('14.05'!U15,'14.05'!$AM$4:$AO$55,2,FALSE))*IF('14.05'!AX$4="是",'14.05'!$AY$4,'14.05'!$AY$3) -> 170 | ... X15: =(VLOOKUP('14.05'!AF15,'14.05'!$AM$4:$AO$55,2,FALSE))*IF('14.05'!BI$4="是",'14.05'!$AY$4,'14.05'!$AY$3) -> 0
... A93: =(VLOOKUP('14.05'!I93,'14.05'!$AM$4:$AO$55,2,FALSE))*IF('14.05'!AK$4="是",'14.05'!$AY$4,'14.05'!$AY$3) -> 0 | B93: =(VLOOKUP('14.05'!J93,'14.05'!$AM$4:$AO$55,2,FALSE))*IF('14.05'!AL$4="是",'14.05'!$AY$4,'14.05'!$AY$3) -> 0 | C93: =(VLOOKUP('14.05'!K93,'14.05'!$AM$4:$AO$55,2,FALSE))*IF('14.05'!AM$4="是",'14.05'!$AY$4,'14.05'!$AY$3) -> 0 | D93: =(VLOOKUP('14.05'!L93,'14.05'!$AM$4:$AO$55,2,FALSE))*IF('14.05'!AN$4="是",'14.05'!$AY$4,'14.05'!$AY$3) -> 0 | E93: =(VLOOKUP('14.05'!M93,'14.05'!$AM$4:$AO$55,2,FALSE))*IF('14.05'!AO$4="是",'14.05'!$AY$4,'14.05'!$AY$3) -> 0 | F93: =(VLOOKUP('14.05'!N93,'14.05'!$AM$4:$AO$55,2,FALSE))*IF('14.05'!AQ$4="是",'14.05'!$AY$4,'14.05'!$AY$3) -> 0 | G93: =(VLOOKUP('14.05'!O93,'14.05'!$AM$4:$AO$55,2,FALSE))*IF('14.05'!AR$4="是",'14.05'!$AY$4,'14.05'!$AY$3) -> 0 | H93: =(VLOOKUP('14.05'!P93,'14.05'!$AM$4:$AO$55,2,FALSE))*IF('14.05'!AS$4="是",'14.05'!$AY$4,'14.05'!$AY$3) -> 0 | I93: =(VLOOKUP('14.05'!Q93,'14.05'!$AM$4:$AO$55,2,FALSE))*IF('14.05'!AT$4="是",'14.05'!$AY$4,'14.05'!$AY$3) -> 160 | J93: =(VLOOKUP('14.05'!R93,'14.05'!$AM$4:$AO$55,2,FALSE))*IF('14.05'!AU$4="是",'14.05'!$AY$4,'14.05'!$AY$3) -> 160 | K93: =(VLOOKUP('14.05'!S93,'14.05'!$AM$4:$AO$55,2,FALSE))*IF('14.05'!AV$4="是",'14.05'!$AY$4,'14.05'!$AY$3) -> 160 | L93: =(VLOOKUP('14.05'!T93,'14.05'!$AM$4:$AO$55,2,FALSE))*IF('14.05'!AW$4="是",'14.05'!$AY$4,'14.05'!$AY$3) -> 160 | M93: =(VLOOKUP('14.05'!U93,'14.05'!$AM$4:$AO$55,2,FALSE))*IF('14.05'!AX$4="是",'14.05'!$AY$4,'14.05'!$AY$3) -> 50 | ... X93: =(VLOOKUP('14.05'!AF93,'14.05'!$AM$4:$AO$55,2,FALSE))*IF('14.05'!BI$4="是",'14.05'!$AY$4,'14.05'!$AY$3) -> 50
A94: =(VLOOKUP('14.05'!#REF!,'14.05'!$AM$4:$AO$55,2,FALSE))*IF('14.05'!AK$4="是",'14.05'!$AY$4,'14.05'!$AY$3) -> #REF! | B94: =(VLOOKUP('14.05'!#REF!,'14.05'!$AM$4:$AO$55,2,FALSE))*IF('14.05'!AL$4="是",'14.05'!$AY$4,'14.05'!$AY$3) -> #REF! | C94: =(VLOOKUP('14.05'!#REF!,'14.05'!$AM$4:$AO$55,2,FALSE))*IF('14.05'!AM$4="是",'14.05'!$AY$4,'14.05'!$AY$3) -> #REF! | D94: =(VLOOKUP('14.05'!#REF!,'14.05'!$AM$4:$AO$55,2,FALSE))*IF('14.05'!AN$4="是",'14.05'!$AY$4,'14.05'!$AY$3) -> #REF! | E94: =(VLOOKUP('14.05'!#REF!,'14.05'!$AM$4:$AO$55,2,FALSE))*IF('14.05'!AO$4="是",'14.05'!$AY$4,'14.05'!$AY$3) -> #REF! | F94: =(VLOOKUP('14.05'!#REF!,'14.05'!$AM$4:$AO$55,2,FALSE))*IF('14.05'!AQ$4="是",'14.05'!$AY$4,'14.05'!$AY$3) -> #REF! | G94: =(VLOOKUP('14.05'!#REF!,'14.05'!$AM$4:$AO$55,2,FALSE))*IF('14.05'!AR$4="是",'14.05'!$AY$4,'14.05'!$AY$3) -> #REF! | H94: =(VLOOKUP('14.05'!#REF!,'14.05'!$AM$4:$AO$55,2,FALSE))*IF('14.05'!AS$4="是",'14.05'!$AY$4,'14.05'!$AY$3) -> #REF! | I94: =(VLOOKUP('14.05'!#REF!,'14.05'!$AM$4:$AO$55,2,FALSE))*IF('14.05'!AT$4="是",'14.05'!$AY$4,'14.05'!$AY$3) -> #REF! | J94: =(VLOOKUP('14.05'!#REF!,'14.05'!$AM$4:$AO$55,2,FALSE))*IF('14.05'!AU$4="是",'14.05'!$AY$4,'14.05'!$AY$3) -> #REF! | K94: =(VLOOKUP('14.05'!#REF!,'14.05'!$AM$4:$AO$55,2,FALSE))*IF('14.05'!AV$4="是",'14.05'!$AY$4,'14.05'!$AY$3) -> #REF! | L94: =(VLOOKUP('14.05'!#REF!,'14.05'!$AM$4:$AO$55,2,FALSE))*IF('14.05'!AW$4="是",'14.05'!$AY$4,'14.05'!$AY$3) -> #REF! | M94: =(VLOOKUP('14.05'!#REF!,'14.05'!$AM$4:$AO$55,2,FALSE))*IF('14.05'!AX$4="是",'14.05'!$AY$4,'14.05'!$AY$3) -> #REF! | ... X94: =(VLOOKUP('14.05'!#REF!,'14.05'!$AM$4:$AO$55,2,FALSE))*IF('14.05'!BI$4="是",'14.05'!$AY$4,'14.05'!$AY$3) -> #REF!

Sheet 经验
A2: 队伍一 风 | C2: 步数 | D2: =COUNTIF(A4:H94,"<>空") -> 728 | E2: (不算跳步和传送) | I2: 队伍二 雷 | K2: 步数 | L2: =COUNTIF(I4:P94,"<>空") -> 728 | M2: (不算跳步和传送) | Q2: 队伍三 | S2: 总步数 | T2: =COUNTIF(Q4:X94,"<>空") -> 728 | U2: (不算跳步和传送)
A3: 1 | B3: 2 | C3: 3 | D3: 4 | E3: 5 | F3: 6 | G3: 7 | H3: 8 | I3: 1 | J3: 2 | K3: 3 | L3: 4 | M3: 5 | N3: 6 | O3: 7 | P3: 8 | Q3: 1 | R3: 2 | S3: 3 | T3: 4 | U3: 5 | V3: 6 | W3: 7 | X3: 8
A4: =(VLOOKUP('14.05'!I4,'14.05'!$AM$4:$AO$55,3,FALSE)) -> 35 | B4: =(VLOOKUP('14.05'!J4,'14.05'!$AM$4:$AO$55,3,FALSE)) -> 35 | C4: =(VLOOKUP('14.05'!K4,'14.05'!$AM$4:$AO$55,3,FALSE)) -> 35 | D4: =(VLOOKUP('14.05'!L4,'14.05'!$AM$4:$AO$55,3,FALSE)) -> 0 | E4: =(VLOOKUP('14.05'!M4,'14.05'!$AM$4:$AO$55,3,FALSE)) -> 0 | F4: =(VLOOKUP('14.05'!N4,'14.05'!$AM$4:$AO$55,3,FALSE)) -> 0 | G4: =(VLOOKUP('14.05'!O4,'14.05'!$AM$4:$AO$55,3,FALSE)) -> 0 | H4: =(VLOOKUP('14.05'!P4,'14.05'!$AM$4:$AO$55,3,FALSE)) -> 0 | ... X4: =(VLOOKUP('14.05'!AF4,'14.05'!$AM$4:$AO$55,3,FALSE)) -> 0
A5: =(VLOOKUP('14.05'!I5,'14.05'!$AM$4:$AO$55,3,FALSE)) -> 35 | B5: =(VLOOKUP('14.05'!J5,'14.05'!$AM$4:$AO$55,3,FALSE)) -> 35 | C5: =(VLOOKUP('14.05'!K5,'14.05'!$AM$4:$AO$55,3,FALSE)) -> 30 | D5: =(VLOOKUP('14.05'!L5,'14.05'!$AM$4:$AO$55,3,FALSE)) -> 35 | E5: =(VLOOKUP('14.05'!M5,'14.05'!$AM$4:$AO$55,3,FALSE)) -> 35 | F5: =(VLOOKUP('14.05'!N5,'14.05'!$AM$4:$AO$55,3,FALSE)) -> 40 | G5: =(VLOOKUP('14.05'!O5,'14.05'!$AM$4:$AO$55,3,FALSE)) -> 0 | H5: =(VLOOKUP('14.05'!P5,'14.05'!$AM$4:$AO$55,3,FALSE)) -> 0 | ... X5: =(VLOOKUP('14.05'!AF5,'14.05'!$AM$4:$AO$55,3,FALSE)) -> 45
A6: =(VLOOKUP('14.05'!I6,'14.05'!$AM$4:$AO$55,3,FALSE)) -> 40 | B6: =(VLOOKUP('14.05'!J6,'14.05'!$AM$4:$AO$55,3,FALSE)) -> 30 | C6: =(VLOOKUP('14.05'!K6,'14.05'!$AM$4:$AO$55,3,FALSE)) -> 40 | D6: =(VLOOKUP('14.05'!L6,'14.05'!$AM$4:$AO$55,3,FALSE)) -> 40 | E6: =(VLOOKUP('14.05'!M6,'14.05'!$AM$4:$AO$55,3,FALSE)) -> 0 | F6: =(VLOOKUP('14.05'!N6,'14.05'!$AM$4:$AO$55,3,FALSE)) -> 45 | G6: =(VLOOKUP('14.05'!O6,'14.05'!$AM$4:$AO$55,3,FALSE)) -> 45 | H6: =(VLOOKUP('14.05'!P6,'14.05'!$AM$4:$AO$55,3,FALSE)) -> 45 | ... X6: =(VLOOKUP('14.05'!AF6,'14.05'!$AM$4:$AO$55,3,FALSE)) -> 0
A7: =(VLOOKUP('14.05'!I7,'14.05'!$AM$4:$AO$55,3,FALSE)) -> 45 | B7: =(VLOOKUP('14.05'!J7,'14.05'!$AM$4:$AO$55,3,FALSE)) -> 300 | C7: =(VLOOKUP('14.05'!K7,'14.05'!$AM$4:$AO$55,3,FALSE)) -> 45 | D7: =(VLOOKUP('14.05'!L7,'14.05'!$AM$4:$AO$55,3,FALSE)) -> 45 | E7: =(VLOOKUP('14.05'!M7,'14.05'!$AM$4:$AO$55,3,FALSE)) -> 45 | F7: =(VLOOKUP('14.05'!N7,'14.05'!$AM$4:$AO$55,3,FALSE)) -> 45 | G7: =(VLOOKUP('14.05'!O7,'14.05'!$AM$4:$AO$55,3,FALSE)) -> 0 | H7: =(VLOOKUP('14.05'!P7,'14.05'!$AM$4:$AO$55,3,FALSE)) -> 0 | ... X7: =(VLOOKUP('14.05'!AF7,'14.05'!$AM$4:$AO$55,3,FALSE)) -> 0
A8: =(VLOOKUP('14.05'!I8,'14.05'!$AM$4:$AO$55,3,FALSE)) -> 45 | B8: =(VLOOKUP('14.05'!J8,'14.05'!$AM$4:$AO$55,3,FALSE)) -> 45 | C8: =(VLOOKUP('14.05'!K8,'14.05'!$AM$4:$AO$55,3,FALSE)) -> 45 | D8: =(VLOOKUP('14.05'!L8,'14.05'!$AM$4:$AO$55,3,FALSE)) -> 45 | E8: =(VLOOKUP('14.05'!M8,'14.05'!$AM$4:$AO$55,3,FALSE)) -> 45 | F8: =(VLOOKUP('14.05'!N8,'14.05'!$AM$4:$AO$55,3,FALSE)) -> 45 | G8: =(VLOOKUP('14.05'!O8,'14.05'!$AM$4:$AO$55,3,FALSE)) -> 0 | H8: =(VLOOKUP('14.05'!P8,'14.05'!$AM$4:$AO$55,3,FALSE)) -> 0 | ... X8: =(VLOOKUP('14.05'!AF8,'14.05'!$AM$4:$AO$55,3,FALSE)) -> 0
A9: =(VLOOKUP('14.05'!I9,'14.05'!$AM$4:$AO$55,3,FALSE)) -> 45 | B9: =(VLOOKUP('14.05'!J9,'14.05'!$AM$4:$AO$55,3,FALSE)) -> 0 | C9: =(VLOOKUP('14.05'!K9,'14.05'!$AM$4:$AO$55,3,FALSE)) -> 0 | D9: =(VLOOKUP('14.05'!L9,'14.05'!$AM$4:$AO$55,3,FALSE)) -> 0 | E9: =(VLOOKUP('14.05'!M9,'14.05'!$AM$4:$AO$55,3,FALSE)) -> 0 | F9: =(VLOOKUP('14.05'!N9,'14.05'!$AM$4:$AO$55,3,FALSE)) -> 0 | G9: =(VLOOKUP('14.05'!O9,'14.05'!$AM$4:$AO$55,3,FALSE)) -> 0 | H9: =(VLOOKUP('14.05'!P9,'14.05'!$AM$4:$AO$55,3,FALSE)) -> 0 | ... X9: =(VLOOKUP('14.05'!AF9,'14.05'!$AM$4:$AO$55,3,FALSE)) -> 0
A10: =(VLOOKUP('14.05'!I10,'14.05'!$AM$4:$AO$55,3,FALSE)) -> 0 | B10: =(VLOOKUP('14.05'!J10,'14.05'!$AM$4:$AO$55,3,FALSE)) -> 0 | C10: =(VLOOKUP('14.05'!K10,'14.05'!$AM$4:$AO$55,3,FALSE)) -> 0 | D10: =(VLOOKUP('14.05'!L10,'14.05'!$AM$4:$AO$55,3,FALSE)) -> 0 | E10: =(VLOOKUP('14.05'!M10,'14.05'!$AM$4:$AO$55,3,FALSE)) -> 0 | F10: =(VLOOKUP('14.05'!N10,'14.05'!$AM$4:$AO$55,3,FALSE)) -> 0 | G10: =(VLOOKUP('14.05'!O10,'14.05'!$AM$4:$AO$55,3,FALSE)) -> 0 | H10: =(VLOOKUP('14.05'!P10,'14.05'!$AM$4:$AO$55,3,FALSE)) -> 0 | ... X10: =(VLOOKUP('14.05'!AF10,'14.05'!$AM$4:$AO$55,3,FALSE)) -> 45
A11: =(VLOOKUP('14.05'!I11,'14.05'!$AM$4:$AO$55,3,FALSE)) -> 0 | B11: =(VLOOKUP('14.05'!J11,'14.05'!$AM$4:$AO$55,3,FALSE)) -> 0 | C11: =(VLOOKUP('14.05'!K11,'14.05'!$AM$4:$AO$55,3,FALSE)) -> 0 | D11: =(VLOOKUP('14.05'!L11,'14.05'!$AM$4:$AO$55,3,FALSE)) -> 0 | E11: =(VLOOKUP('14.05'!M11,'14.05'!$AM$4:$AO$55,3,FALSE)) -> 0 | F11: =(VLOOKUP('14.05'!N11,'14.05'!$AM$4:$AO$55,3,FALSE)) -> 0 | G11: =(VLOOKUP('14.05'!O11,'14.05'!$AM$4:$AO$55,3,FALSE)) -> 0 | H11: =(VLOOKUP('14.05'!P11,'14.05'!$AM$4:$AO$55,3,FALSE)) -> 0 | ... X11: =(VLOOKUP('14.05'!AF11,'14.05'!$AM$4:$AO$55,3,FALSE)) -> 0
A12: =(VLOOKUP('14.05'!I12,'14.05'!$AM$4:$AO$55,3,FALSE)) -> 0 | B12: =(VLOOKUP('14.05'!J12,'14.05'!$AM$4:$AO$55,3,FALSE)) -> 0 | C12: =(VLOOKUP('14.05'!K12,'14.05'!$AM$4:$AO$55,3,FALSE)) -> 0 | D12: =(VLOOKUP('14.05'!L12,'14.05'!$AM$4:$AO$55,3,FALSE)) -> 0 | E12: =(VLOOKUP('14.05'!M12,'14.05'!$AM$4:$AO$55,3,FALSE)) -> 0 | F12: =(VLOOKUP('14.05'!N12,'14.05'!$AM$4:$AO$55,3,FALSE)) -> 0 | G12: =(VLOOKUP('14.05'!O12,'14.05'!$AM$4:$AO$55,3,FALSE)) -> 0 | H12: =(VLOOKUP('14.05'!P12,'14.05'!$AM$4:$AO$55,3,FALSE)) -> 0 | ... X12: =(VLOOKUP('14.05'!AF12,'14.05'!$AM$4:$AO$55,3,FALSE)) -> 0
A13: =(VLOOKUP('14.05'!I13,'14.05'!$AM$4:$AO$55,3,FALSE)) -> 45 | B13: =(VLOOKUP('14.05'!J13,'14.05'!$AM$4:$AO$55,3,FALSE)) -> 45 | C13: =(VLOOKUP('14.05'!K13,'14.05'!$AM$4:$AO$55,3,FALSE)) -> 45 | D13: =(VLOOKUP('14.05'!L13,'14.05'!$AM$4:$AO$55,3,FALSE)) -> 45 | E13: =(VLOOKUP('14.05'!M13,'14.05'!$AM$4:$AO$55,3,FALSE)) -> 30 | F13: =(VLOOKUP('14.05'!N13,'14.05'!$AM$4:$AO$55,3,FALSE)) -> 45 | G13: =(VLOOKUP('14.05'!O13,'14.05'!$AM$4:$AO$55,3,FALSE)) -> 0 | H13: =(VLOOKUP('14.05'!P13,'14.05'!$AM$4:$AO$55,3,FALSE)) -> 0 | ... X13: =(VLOOKUP('14.05'!AF13,'14.05'!$AM$4:$AO$55,3,FALSE)) -> 0
A14: =(VLOOKUP('14.05'!I14,'14.05'!$AM$4:$AO$55,3,FALSE)) -> 50 | B14: =(VLOOKUP('14.05'!J14,'14.05'!$AM$4:$AO$55,3,FALSE)) -> 50 | C14: =(VLOOKUP('14.05'!K14,'14.05'!$AM$4:$AO$55,3,FALSE)) -> 50 | D14: =(VLOOKUP('14.05'!L14,'14.05'!$AM$4:$AO$55,3,FALSE)) -> 50 | E14: =(VLOOKUP('14.05'!M14,'14.05'!$AM$4:$AO$55,3,FALSE)) -> 50 | F14: =(VLOOKUP('14.05'!N14,'14.05'!$AM$4:$AO$55,3,FALSE)) -> 50 | G14: =(VLOOKUP('14.05'!O14,'14.05'!$AM$4:$AO$55,3,FALSE)) -> 0 | H14: =(VLOOKUP('14.05'!P14,'14.05'!$AM$4:$AO$55,3,FALSE)) -> 0 | ... X14: =(VLOOKUP('14.05'!AF14,'14.05'!$AM$4:$AO$55,3,FALSE)) -> 0
A15: =(VLOOKUP('14.05'!I15,'14.05'!$AM$4:$AO$55,3,FALSE)) -> 50 | B15: =(VLOOKUP('14.05'!J15,'14.05'!$AM$4:$AO$55,3,FALSE)) -> 50 | C15: =(VLOOKUP('14.05'!K15,'14.05'!$AM$4:$AO$55,3,FALSE)) -> 50 | D15: =(VLOOKUP('14.05'!L15,'14.05'!$AM$4:$AO$55,3,FALSE)) -> 50 | E15: =(VLOOKUP('14.05'!M15,'14.05'!$AM$4:$AO$55,3,FALSE)) -> 50 | F15: =(VLOOKUP('14.05'!N15,'14.05'!$AM$4:$AO$55,3,FALSE)) -> 50 | G15: =(VLOOKUP('14.05'!O15,'14.05'!$AM$4:$AO$55,3,FALSE)) -> 0 | H15: =(VLOOKUP('14.05'!P15,'14.05'!$AM$4:$AO$55,3,FALSE)) -> 0 | ... X15: =(VLOOKUP('14.05'!AF15,'14.05'!$AM$4:$AO$55,3,FALSE)) -> 0
... A93: =(VLOOKUP('14.05'!I93,'14.05'!$AM$4:$AO$55,3,FALSE)) -> 0 | B93: =(VLOOKUP('14.05'!J93,'14.05'!$AM$4:$AO$55,3,FALSE)) -> 0 | C93: =(VLOOKUP('14.05'!K93,'14.05'!$AM$4:$AO$55,3,FALSE)) -> 0 | D93: =(VLOOKUP('14.05'!L93,'14.05'!$AM$4:$AO$55,3,FALSE)) -> 0 | E93: =(VLOOKUP('14.05'!M93,'14.05'!$AM$4:$AO$55,3,FALSE)) -> 0 | F93: =(VLOOKUP('14.05'!N93,'14.05'!$AM$4:$AO$55,3,FALSE)) -> 0 | G93: =(VLOOKUP('14.05'!O93,'14.05'!$AM$4:$AO$55,3,FALSE)) -> 0 | H93: =(VLOOKUP('14.05'!P93,'14.05'!$AM$4:$AO$55,3,FALSE)) -> 0 | ... X93: =(VLOOKUP('14.05'!AF93,'14.05'!$AM$4:$AO$55,3,FALSE)) -> 30
A94: =(VLOOKUP('14.05'!#REF!,'14.05'!$AM$4:$AO$55,3,FALSE)) -> #REF! | B94: =(VLOOKUP('14.05'!#REF!,'14.05'!$AM$4:$AO$55,3,FALSE)) -> #REF! | C94: =(VLOOKUP('14.05'!#REF!,'14.05'!$AM$4:$AO$55,3,FALSE)) -> #REF! | D94: =(VLOOKUP('14.05'!#REF!,'14.05'!$AM$4:$AO$55,3,FALSE)) -> #REF! | E94: =(VLOOKUP('14.05'!#REF!,'14.05'!$AM$4:$AO$55,3,FALSE)) -> #REF! | F94: =(VLOOKUP('14.05'!#REF!,'14.05'!$AM$4:$AO$55,3,FALSE)) -> #REF! | G94: =(VLOOKUP('14.05'!#REF!,'14.05'!$AM$4:$AO$55,3,FALSE)) -> #REF! | H94: =(VLOOKUP('14.05'!#REF!,'14.05'!$AM$4:$AO$55,3,FALSE)) -> #REF! | ... X94: =(VLOOKUP('14.05'!#REF!,'14.05'!$AM$4:$AO$55,3,FALSE)) -> #REF!

Sheet 亏损
A2: 队伍一 风 | C2: 步数 | D2: =COUNTIF(A4:H94,"<>空") -> 728 | E2: (不算跳步和传送) | I2: 队伍二 雷 | K2: 步数 | L2: =COUNTIF(I4:P94,"<>空") -> 728 | M2: (不算跳步和传送) | Q2: 队伍三 | S2: 总步数 | T2: =COUNTIF(Q4:X94,"<>空") -> 728 | U2: (不算跳步和传送)
A3: 1 | B3: 2 | C3: 3 | D3: 4 | E3: 5 | F3: 6 | G3: 7 | H3: 8 | I3: 1 | J3: 2 | K3: 3 | L3: 4 | M3: 5 | N3: 6 | O3: 7 | P3: 8 | Q3: 1 | R3: 2 | S3: 3 | T3: 4 | U3: 5 | V3: 6 | W3: 7 | X3: 8
A4: =(VLOOKUP('14.05'!I4,'14.05'!$AM$4:$AP$55,4,FALSE)) -> 44.222109 | B4: =(VLOOKUP('14.05'!J4,'14.05'!$AM$4:$AP$55,4,FALSE)) -> 44.222109 | C4: =(VLOOKUP('14.05'!K4,'14.05'!$AM$4:$AP$55,4,FALSE)) -> 44.222109 | D4: =(VLOOKUP('14.05'!L4,'14.05'!$AM$4:$AP$55,4,FALSE)) -> 0 | E4: =(VLOOKUP('14.05'!M4,'14.05'!$AM$4:$AP$55,4,FALSE)) -> 0 | F4: =(VLOOKUP('14.05'!N4,'14.05'!$AM$4:$AP$55,4,FALSE)) -> 0 | G4: =(VLOOKUP('14.05'!O4,'14.05'!$AM$4:$AP$55,4,FALSE)) -> 0 | H4: =(VLOOKUP('14.05'!P4,'14.05'!$AM$4:$AP$55,4,FALSE)) -> 0 | ... X4: =(VLOOKUP('14.05'!AF4,'14.05'!$AM$4:$AP$55,4,FALSE)) -> 0
