Workbook

Sheet 102 5.1.00
A1: =(_xlfn.DAYS(TODAY(),A4)+1)/((_xlfn.DAYS(A94,A4))+1) -> 0.21978022 | H1: 工作区 | AL1: 使用方法：按自己规划的路线，将下表中的地块名复制粘贴至工作区。初次使用传送门，当天跳步次数+5。重复使用传送门，当天跳步次数+1
A2: version 5.1.00 | C2: 合计经验 | E2: =SUM(E4:E94)+SUM(G4:G94) -> 7000 | H2: 队伍一 火 | J2: 步数 | K2: =COUNTIF(H4:O94,"<>空") -> 0 | L2: (不算跳步和传送) | P2: 队伍二 雷 | R2: 步数 | S2: =COUNTIF(P4:W94,"<>空") -> 0 | T2: (不算跳步和传送) | X2: 队伍三 | Z2: 总步数 | AA2: =COUNTIF(X4:AE94,"<>空") -> 0 | AB2: (不算跳步和传送) | AF2: =SUM(AF4:AF94) -> 0 | AG2: =SUM(AG4:AG94) -> 0 | AH2: =SUM(AH4:AH94) -> 0 | AI2: =SUM(AI4:AI94) -> 0 | AJ2: 八卦全开 | AW2: 粮草系数
A3: 日期 | B3: 获得粮草 | C3: 消耗粮草 | D3: 剩余粮草 | E3: 获得经验 | F3: 累计经验 | G3: 任务经验 | H3: 1 | I3: 2 | J3: 3 | K3: 4 | L3: 5 | M3: 6 | N3: 7 | O3: 8 | P3: 1 | Q3: 2 | R3: 3 | S3: 4 | T3: 5 | U3: 6 | V3: 7 | W3: 8 | X3: 1 | Y3: 2 | Z3: 3 | AA3: 4 | AB3: 5 | AC3: 6 | AD3: 7 | AE3: 8 | AF3: 跳步次数 | AG3: 1队跳步 | AH3: 2队跳步 | AI3: 3队跳步 | AL3: 地块 | AM3: 粮草 | AN3: 经验 | AO3: 一队地块 | AP3: 二队地块 | AQ3: 三队地块 | AR3: 总地块 | AS3: 一队经验 | AT3: 二队经验 | AU3: 三队经验 | AV3: 八卦前 | AW3: 1
A4: 44456 | B4: 800 | C4: =(SUM(粮草!A4:X4)+AF4*10)*IF(AJ4="是",$AW$4,$AW$3) -> 0 | D4: =SUM($B$4:B4)-SUM($C$4:C4) -> 800 | E4: =SUM(经验!A4:X4) -> 0 | F4: =SUM($E$4:E4)+SUM($G$4:G4) -> 0 | G4: 0 | H4: 空 | I4: 空 | J4: 空 | K4: 空 | L4: 空 | M4: 空 | N4: 空 | O4: 空 | P4: 空 | Q4: 空 | R4: 空 | S4: 空 | T4: 空 | U4: 空 | V4: 空 | W4: 空 | X4: 空 | Y4: 空 | Z4: 空 | AA4: 空 | AB4: 空 | AC4: 空 | AD4: 空 | AE4: 空 | AF4: 0 | AJ4: 否 | AL4: 1级 | AM4: 150 | AN4: 35 | AO4: =COUNTIF($H$4:$O$94,AL4) -> 0 | AP4: =COUNTIF($P$4:$W$94,AL4) -> 0 | AQ4: =COUNTIF($X$4:$AE$94,AL4) -> 0 | AR4: =AO4+AP4+AQ4 -> 0 | AS4: =AO4*$AN4 -> 0 | AT4: =AP4*$AN4 -> 0 | AU4: =AQ4*$AN4 -> 0 | AV4: 八卦后 | AW4: 0.8 | AY4: =AM4*0.8 -> 120
A5: 44457 | B5: 1600 | C5: =(SUM(粮草!A5:X5)+AF5*10)*IF(AJ5="是",$AW$4,$AW$3) -> 0 | D5: =SUM($B$4:B5)-SUM($C$4:C5) -> 2400 | E5: =SUM(经验!A5:X5) -> 0 | F5: =SUM($E$4:E5)+SUM($G$4:G5) -> 500 | G5: 500 | H5: 空 | I5: 空 | J5: 空 | K5: 空 | L5: 空 | M5: 空 | N5: 空 | O5: 空 | P5: 空 | Q5: 空 | R5: 空 | S5: 空 | T5: 空 | U5: 空 | V5: 空 | W5: 空 | X5: 空 | Y5: 空 | Z5: 空 | AA5: 空 | AB5: 空 | AC5: 空 | AD5: 空 | AE5: 空 | AF5: 0 | AJ5: 否 | AL5: 2级 | AM5: 160 | AN5: 40 | AO5: =COUNTIF($H$4:$O$94,AL5) -> 0 | AP5: =COUNTIF($P$4:$W$94,AL5) -> 0 | AQ5: =COUNTIF($X$4:$AE$94,AL5) -> 0 | AR5: =AO5+AP5+AQ5 -> 0 | AS5: =AO5*$AN5 -> 0 | AT5: =AP5*$AN5 -> 0 | AU5: =AQ5*$AN5 -> 0 | AV5: Note：开完八卦当天可能需要手动计算粮草 | AY5: =AM5*0.8 -> 128
A6: 44458 | B6: 1600 | C6: =(SUM(粮草!A6:X6)+AF6*10)*IF(AJ6="是",$AW$4,$AW$3) -> 0 | D6: =SUM($B$4:B6)-SUM($C$4:C6) -> 4000 | E6: =SUM(经验!A6:X6) -> 0 | F6: =SUM($E$4:E6)+SUM($G$4:G6) -> 500 | G6: 0 | H6: 空 | I6: 空 | J6: 空 | K6: 空 | L6: 空 | M6: 空 | N6: 空 | O6: 空 | P6: 空 | Q6: 空 | R6: 空 | S6: 空 | T6: 空 | U6: 空 | V6: 空 | W6: 空 | X6: 空 | Y6: 空 | Z6: 空 | AA6: 空 | AB6: 空 | AC6: 空 | AD6: 空 | AE6: 空 | AF6: 0 | AJ6: 否 | AL6: 3级 | AM6: 170 | AN6: 45 | AO6: =COUNTIF($H$4:$O$94,AL6) -> 0 | AP6: =COUNTIF($P$4:$W$94,AL6) -> 0 | AQ6: =COUNTIF($X$4:$AE$94,AL6) -> 0 | AR6: =AO6+AP6+AQ6 -> 0 | AS6: =AO6*$AN6 -> 0 | AT6: =AP6*$AN6 -> 0 | AU6: =AQ6*$AN6 -> 0 | AY6: =AM6*0.8 -> 136
A7: 44459 | B7: 1600 | C7: =(SUM(粮草!A7:X7)+AF7*10)*IF(AJ7="是",$AW$4,$AW$3) -> 0 | D7: =SUM($B$4:B7)-SUM($C$4:C7) -> 5600 | E7: =SUM(经验!A7:X7) -> 0 | F7: =SUM($E$4:E7)+SUM($G$4:G7) -> 700 | G7: 200 | H7: 空 | I7: 空 | J7: 空 | K7: 空 | L7: 空 | M7: 空 | N7: 空 | O7: 空 | P7: 空 | Q7: 空 | R7: 空 | S7: 空 | T7: 空 | U7: 空 | V7: 空 | W7: 空 | X7: 空 | Y7: 空 | Z7: 空 | AA7: 空 | AB7: 空 | AC7: 空 | AD7: 空 | AE7: 空 | AF7: 0 | AJ7: 否 | AL7: 4级 | AM7: 180 | AN7: 50 | AO7: =COUNTIF($H$4:$O$94,AL7) -> 0 | AP7: =COUNTIF($P$4:$W$94,AL7) -> 0 | AQ7: =COUNTIF($X$4:$AE$94,AL7) -> 0 | AR7: =AO7+AP7+AQ7 -> 0 | AS7: =AO7*$AN7 -> 0 | AT7: =AP7*$AN7 -> 0 | AU7: =AQ7*$AN7 -> 0 | AY7: =AM7*0.8 -> 144
A8: 44460 | B8: 1600 | C8: =(SUM(粮草!A8:X8)+AF8*10)*IF(AJ8="是",$AW$4,$AW$3) -> 0 | D8: =SUM($B$4:B8)-SUM($C$4:C8) -> 7200 | E8: =SUM(经验!A8:X8) -> 0 | F8: =SUM($E$4:E8)+SUM($G$4:G8) -> 800 | G8: 100 | H8: 空 | I8: 空 | J8: 空 | K8: 空 | L8: 空 | M8: 空 | N8: 空 | O8: 空 | P8: 空 | Q8: 空 | R8: 空 | S8: 空 | T8: 空 | U8: 空 | V8: 空 | W8: 空 | X8: 空 | Y8: 空 | Z8: 空 | AA8: 空 | AB8: 空 | AC8: 空 | AD8: 空 | AE8: 空 | AF8: 0 | AJ8: 否 | AL8: 5级 | AM8: 190 | AN8: 55 | AO8: =COUNTIF($H$4:$O$94,AL8) -> 0 | AP8: =COUNTIF($P$4:$W$94,AL8) -> 0 | AQ8: =COUNTIF($X$4:$AE$94,AL8) -> 0 | AR8: =AO8+AP8+AQ8 -> 0 | AS8: =AO8*$AN8 -> 0 | AT8: =AP8*$AN8 -> 0 | AU8: =AQ8*$AN8 -> 0 | AY8: =AM8*0.8 -> 152
A9: 44461 | B9: 1600 | C9: =(SUM(粮草!A9:X9)+AF9*10)*IF(AJ9="是",$AW$4,$AW$3) -> 0 | D9: =SUM($B$4:B9)-SUM($C$4:C9) -> 8800 | E9: =SUM(经验!A9:X9) -> 0 | F9: =SUM($E$4:E9)+SUM($G$4:G9) -> 1000 | G9: 200 | H9: 空 | I9: 空 | J9: 空 | K9: 空 | L9: 空 | M9: 空 | N9: 空 | O9: 空 | P9: 空 | Q9: 空 | R9: 空 | S9: 空 | T9: 空 | U9: 空 | V9: 空 | W9: 空 | X9: 空 | Y9: 空 | Z9: 空 | AA9: 空 | AB9: 空 | AC9: 空 | AD9: 空 | AE9: 空 | AF9: 0 | AJ9: 否 | AL9: 6级 | AM9: 200 | AN9: 60 | AO9: =COUNTIF($H$4:$O$94,AL9) -> 0 | AP9: =COUNTIF($P$4:$W$94,AL9) -> 0 | AQ9: =COUNTIF($X$4:$AE$94,AL9) -> 0 | AR9: =AO9+AP9+AQ9 -> 0 | AS9: =AO9*$AN9 -> 0 | AT9: =AP9*$AN9 -> 0 | AU9: =AQ9*$AN9 -> 0 | AY9: =AM9*0.8 -> 160
A10: 44462 | B10: 1600 | C10: =(SUM(粮草!A10:X10)+AF10*10)*IF(AJ10="是",$AW$4,$AW$3) -> 0 | D10: =SUM($B$4:B10)-SUM($C$4:C10) -> 10400 | E10: =SUM(经验!A10:X10) -> 0 | F10: =SUM($E$4:E10)+SUM($G$4:G10) -> 1000 | G10: 0 | H10: 空 | I10: 空 | J10: 空 | K10: 空 | L10: 空 | M10: 空 | N10: 空 | O10: 空 | P10: 空 | Q10: 空 | R10: 空 | S10: 空 | T10: 空 | U10: 空 | V10: 空 | W10: 空 | X10: 空 | Y10: 空 | Z10: 空 | AA10: 空 | AB10: 空 | AC10: 空 | AD10: 空 | AE10: 空 | AF10: 0 | AJ10: 否 | AL10: 塔1 | AM10: 150 | AN10: 35 | AO10: =COUNTIF($H$4:$O$94,AL10) -> 0 | AP10: =COUNTIF($P$4:$W$94,AL10) -> 0 | AQ10: =COUNTIF($X$4:$AE$94,AL10) -> 0 | AR10: =AO10+AP10+AQ10 -> 0 | AS10: =AO10*$AN10 -> 0 | AT10: =AP10*$AN10 -> 0 | AU10: =AQ10*$AN10 -> 0 | AY10: =AM10*0.8 -> 120
A11: 44463 | B11: 1600 | C11: =(SUM(粮草!A11:X11)+AF11*10)*IF(AJ11="是",$AW$4,$AW$3) -> 0 | D11: =SUM($B$4:B11)-SUM($C$4:C11) -> 12000 | E11: =SUM(经验!A11:X11) -> 0 | F11: =SUM($E$4:E11)+SUM($G$4:G11) -> 1000 | G11: 0 | H11: 空 | I11: 空 | J11: 空 | K11: 空 | L11: 空 | M11: 空 | N11: 空 | O11: 空 | P11: 空 | Q11: 空 | R11: 空 | S11: 空 | T11: 空 | U11: 空 | V11: 空 | W11: 空 | X11: 空 | Y11: 空 | Z11: 空 | AA11: 空 | AB11: 空 | AC11: 空 | AD11: 空 | AE11: 空 | AF11: 0 | AJ11: 否 | AL11: 塔2 | AM11: 150 | AN11: 40 | AO11: =COUNTIF($H$4:$O$94,AL11) -> 0 | AP11: =COUNTIF($P$4:$W$94,AL11) -> 0 | AQ11: =COUNTIF($X$4:$AE$94,AL11) -> 0 | AR11: =AO11+AP11+AQ11 -> 0 | AS11: =AO11*$AN11 -> 0 | AT11: =AP11*$AN11 -> 0 | AU11: =AQ11*$AN11 -> 0 | AY11: =AM11*0.8 -> 120
A12: 44464 | B12: 1600 | C12: =(SUM(粮草!A12:X12)+AF12*10)*IF(AJ12="是",$AW$4,$AW$3) -> 0 | D12: =SUM($B$4:B12)-SUM($C$4:C12) -> 13600 | E12: =SUM(经验!A12:X12) -> 0 | F12: =SUM($E$4:E12)+SUM($G$4:G12) -> 1000 | G12: 0 | H12: 空 | I12: 空 | J12: 空 | K12: 空 | L12: 空 | M12: 空 | N12: 空 | O12: 空 | P12: 空 | Q12: 空 | R12: 空 | S12: 空 | T12: 空 | U12: 空 | V12: 空 | W12: 空 | X12: 空 | Y12: 空 | Z12: 空 | AA12: 空 | AB12: 空 | AC12: 空 | AD12: 空 | AE12: 空 | AF12: 0 | AJ12: 否 | AL12: 塔3 | AM12: 150 | AN12: 45 | AO12: =COUNTIF($H$4:$O$94,AL12) -> 0 | AP12: =COUNTIF($P$4:$W$94,AL12) -> 0 | AQ12: =COUNTIF($X$4:$AE$94,AL12) -> 0 | AR12: =AO12+AP12+AQ12 -> 0 | AS12: =AO12*$AN12 -> 0 | AT12: =AP12*$AN12 -> 0 | AU12: =AQ12*$AN12 -> 0 | AY12: =AM12*0.8 -> 120
A13: 44465 | B13: 1600 | C13: =(SUM(粮草!A13:X13)+AF13*10)*IF(AJ13="是",$AW$4,$AW$3) -> 0 | D13: =SUM($B$4:B13)-SUM($C$4:C13) -> 15200 | E13: =SUM(经验!A13:X13) -> 0 | F13: =SUM($E$4:E13)+SUM($G$4:G13) -> 1000 | G13: 0 | H13: 空 | I13: 空 | J13: 空 | K13: 空 | L13: 空 | M13: 空 | N13: 空 | O13: 空 | P13: 空 | Q13: 空 | R13: 空 | S13: 空 | T13: 空 | U13: 空 | V13: 空 | W13: 空 | X13: 空 | Y13: 空 | Z13: 空 | AA13: 空 | AB13: 空 | AC13: 空 | AD13: 空 | AE13: 空 | AF13: 0 | AJ13: 否 | AL13: 塔4 | AM13: 150 | AN13: 50 | AO13: =COUNTIF($H$4:$O$94,AL13) -> 0 | AP13: =COUNTIF($P$4:$W$94,AL13) -> 0 | AQ13: =COUNTIF($X$4:$AE$94,AL13) -> 0 | AR13: =AO13+AP13+AQ13 -> 0 | AS13: =AO13*$AN13 -> 0 | AT13: =AP13*$AN13 -> 0 | AU13: =AQ13*$AN13 -> 0 | AY13: =AM13*0.8 -> 120
A14: 44466 | B14: 1600 | C14: =(SUM(粮草!A14:X14)+AF14*10)*IF(AJ14="是",$AW$4,$AW$3) -> 0 | D14: =SUM($B$4:B14)-SUM($C$4:C14) -> 16800 | E14: =SUM(经验!A14:X14) -> 0 | F14: =SUM($E$4:E14)+SUM($G$4:G14) -> 1300 | G14: 300 | H14: 空 | I14: 空 | J14: 空 | K14: 空 | L14: 空 | M14: 空 | N14: 空 | O14: 空 | P14: 空 | Q14: 空 | R14: 空 | S14: 空 | T14: 空 | U14: 空 | V14: 空 | W14: 空 | X14: 空 | Y14: 空 | Z14: 空 | AA14: 空 | AB14: 空 | AC14: 空 | AD14: 空 | AE14: 空 | AF14: 0 | AJ14: 否 | AL14: 塔5 | AM14: 150 | AN14: 55 | AO14: =COUNTIF($H$4:$O$94,AL14) -> 0 | AP14: =COUNTIF($P$4:$W$94,AL14) -> 0 | AQ14: =COUNTIF($X$4:$AE$94,AL14) -> 0 | AR14: =AO14+AP14+AQ14 -> 0 | AS14: =AO14*$AN14 -> 0 | AT14: =AP14*$AN14 -> 0 | AU14: =AQ14*$AN14 -> 0 | AY14: =AM14*0.8 -> 120
A15: 44467 | B15: 1600 | C15: =(SUM(粮草!A15:X15)+AF15*10)*IF(AJ15="是",$AW$4,$AW$3) -> 0 | D15: =SUM($B$4:B15)-SUM($C$4:C15) -> 18400 | E15: =SUM(经验!A15:X15) -> 0 | F15: =SUM($E$4:E15)+SUM($G$4:G15) -> 1300 | G15: 0 | H15: 空 | I15: 空 | J15: 空 | K15: 空 | L15: 空 | M15: 空 | N15: 空 | O15: 空 | P15: 空 | Q15: 空 | R15: 空 | S15: 空 | T15: 空 | U15: 空 | V15: 空 | W15: 空 | X15: 空 | Y15: 空 | Z15: 空 | AA15: 空 | AB15: 空 | AC15: 空 | AD15: 空 | AE15: 空 | AF15: 0 | AJ15: 否 | AL15: 塔6 | AM15: 150 | AN15: 60 | AO15: =COUNTIF($H$4:$O$94,AL15) -> 0 | AP15: =COUNTIF($P$4:$W$94,AL15) -> 0 | AQ15: =COUNTIF($X$4:$AE$94,AL15) -> 0 | AR15: =AO15+AP15+AQ15 -> 0 | AS15: =AO15*$AN15 -> 0 | AT15: =AP15*$AN15 -> 0 | AU15: =AQ15*$AN15 -> 0 | AY15: =AM15*0.8 -> 120
A16: 44468 | B16: 1600 | C16: =(SUM(粮草!A16:X16)+AF16*10)*IF(AJ16="是",$AW$4,$AW$3) -> 0 | D16: =SUM($B$4:B16)-SUM($C$4:C16) -> 20000 | E16: =SUM(经验!A16:X16) -> 0 | F16: =SUM($E$4:E16)+SUM($G$4:G16) -> 1500 | G16: 200 | H16: 空 | I16: 空 | J16: 空 | K16: 空 | L16: 空 | M16: 空 | N16: 空 | O16: 空 | P16: 空 | Q16: 空 | R16: 空 | S16: 空 | T16: 空 | U16: 空 | V16: 空 | W16: 空 | X16: 空 | Y16: 空 | Z16: 空 | AA16: 空 | AB16: 空 | AC16: 空 | AD16: 空 | AE16: 空 | AF16: 0 | AJ16: 否 | AL16: 遗迹 | AM16: 150 | AN16: 35 | AO16: =COUNTIF($H$4:$O$94,AL16) -> 0 | AP16: =COUNTIF($P$4:$W$94,AL16) -> 0 | AQ16: =COUNTIF($X$4:$AE$94,AL16) -> 0 | AR16: =AO16+AP16+AQ16 -> 0 | AS16: =AO16*$AN16 -> 0 | AT16: =AP16*$AN16 -> 0 | AU16: =AQ16*$AN16 -> 0 | AY16: =AM16*0.8 -> 120
A17: 44469 | B17: 1600 | C17: =(SUM(粮草!A17:X17)+AF17*10)*IF(AJ17="是",$AW$4,$AW$3) -> 0 | D17: =SUM($B$4:B17)-SUM($C$4:C17) -> 21600 | E17: =SUM(经验!A17:X17) -> 0 | F17: =SUM($E$4:E17)+SUM($G$4:G17) -> 1500 | G17: 0 | H17: 空 | I17: 空 | J17: 空 | K17: 空 | L17: 空 | M17: 空 | N17: 空 | O17: 空 | P17: 空 | Q17: 空 | R17: 空 | S17: 空 | T17: 空 | U17: 空 | V17: 空 | W17: 空 | X17: 空 | Y17: 空 | Z17: 空 | AA17: 空 | AB17: 空 | AC17: 空 | AD17: 空 | AE17: 空 | AF17: 0 | AJ17: 否 | AL17: 商人 | AM17: 50 | AN17: 30 | AO17: =COUNTIF($H$4:$O$94,AL17) -> 0 | AP17: =COUNTIF($P$4:$W$94,AL17) -> 0 | AQ17: =COUNTIF($X$4:$AE$94,AL17) -> 0 | AR17: =AO17+AP17+AQ17 -> 0 | AS17: =AO17*$AN17 -> 0 | AT17: =AP17*$AN17 -> 0 | AU17: =AQ17*$AN17 -> 0 | AY17: =AM17*0.8 -> 40
A18: 44470 | B18: 1600 | C18: =(SUM(粮草!A18:X18)+AF18*10)*IF(AJ18="是",$AW$4,$AW$3) -> 0 | D18: =SUM($B$4:B18)-SUM($C$4:C18) -> 23200 | E18: =SUM(经验!A18:X18) -> 0 | F18: =SUM($E$4:E18)+SUM($G$4:G18) -> 1500 | G18: 0 | H18: 空 | I18: 空 | J18: 空 | K18: 空 | L18: 空 | M18: 空 | N18: 空 | O18: 空 | P18: 空 | Q18: 空 | R18: 空 | S18: 空 | T18: 空 | U18: 空 | V18: 空 | W18: 空 | X18: 空 | Y18: 空 | Z18: 空 | AA18: 空 | AB18: 空 | AC18: 空 | AD18: 空 | AE18: 空 | AF18: 0 | AJ18: 否 | AK18: 八卦前 | AL18: 营地 | AM18: -150 | AN18: 0 | AO18: =COUNTIF($H$4:$O$94,AL18) -> 0 | AP18: =COUNTIF($P$4:$W$94,AL18) -> 0 | AQ18: =COUNTIF($X$4:$AE$94,AL18) -> 0 | AR18: =AO18+AP18+AQ18 -> 0 | AS18: =AO18*$AN18 -> 0 | AT18: =AP18*$AN18 -> 0 | AU18: =AQ18*$AN18 -> 0 | AY18: =AM18*0.8 -> -120
A19: 44471 | B19: 1600 | C19: =(SUM(粮草!A19:X19)+AF19*10)*IF(AJ19="是",$AW$4,$AW$3) -> 0 | D19: =SUM($B$4:B19)-SUM($C$4:C19) -> 24800 | E19: =SUM(经验!A19:X19) -> 0 | F19: =SUM($E$4:E19)+SUM($G$4:G19) -> 1500 | G19: 0 | H19: 空 | I19: 空 | J19: 空 | K19: 空 | L19: 空 | M19: 空 | N19: 空 | O19: 空 | P19: 空 | Q19: 空 | R19: 空 | S19: 空 | T19: 空 | U19: 空 | V19: 空 | W19: 空 | X19: 空 | Y19: 空 | Z19: 空 | AA19: 空 | AB19: 空 | AC19: 空 | AD19: 空 | AE19: 空 | AF19: 0 | AJ19: 是 | AL19: 离兑坤 | AM19: 250 | AN19: 200 | AO19: =COUNTIF($H$4:$O$94,AL19) -> 0 | AP19: =COUNTIF($P$4:$W$94,AL19) -> 0 | AQ19: =COUNTIF($X$4:$AE$94,AL19) -> 0 | AR19: =AO19+AP19+AQ19 -> 0 | AS19: =AO19*$AN19 -> 0 | AT19: =AP19*$AN19 -> 0 | AU19: =AQ19*$AN19 -> 0 | AY19: =AM19*0.8 -> 200
A20: 44472 | B20: 1600 | C20: =(SUM(粮草!A20:X20)+AF20*10)*IF(AJ20="是",$AW$4,$AW$3) -> 0 | D20: =SUM($B$4:B20)-SUM($C$4:C20) -> 26400 | E20: =SUM(经验!A20:X20) -> 0 | F20: =SUM($E$4:E20)+SUM($G$4:G20) -> 1500 | G20: 0 | H20: 空 | I20: 空 | J20: 空 | K20: 空 | L20: 空 | M20: 空 | N20: 空 | O20: 空 | P20: 空 | Q20: 空 | R20: 空 | S20: 空 | T20: 空 | U20: 空 | V20: 空 | W20: 空 | X20: 空 | Y20: 空 | Z20: 空 | AA20: 空 | AB20: 空 | AC20: 空 | AD20: 空 | AE20: 空 | AF20: 0 | AJ20: 是 | AL20: 艮震巽坎乾 | AM20: 170 | AN20: 45 | AO20: =COUNTIF($H$4:$O$94,AL20) -> 0 | AP20: =COUNTIF($P$4:$W$94,AL20) -> 0 | AQ20: =COUNTIF($X$4:$AE$94,AL20) -> 0 | AR20: =AO20+AP20+AQ20 -> 0 | AS20: =AO20*$AN20 -> 0 | AT20: =AP20*$AN20 -> 0 | AU20: =AQ20*$AN20 -> 0 | AY20: =AM20*0.8 -> 136
A21: 44473 | B21: 1600 | C21: =(SUM(粮草!A21:X21)+AF21*10)*IF(AJ21="是",$AW$4,$AW$3) -> 0 | D21: =SUM($B$4:B21)-SUM($C$4:C21) -> 28000 | E21: =SUM(经验!A21:X21) -> 0 | F21: =SUM($E$4:E21)+SUM($G$4:G21) -> 1700 | G21: 200 | H21: 空 | I21: 空 | J21: 空 | K21: 空 | L21: 空 | M21: 空 | N21: 空 | O21: 空 | P21: 空 | Q21: 空 | R21: 空 | S21: 空 | T21: 空 | U21: 空 | V21: 空 | W21: 空 | X21: 空 | Y21: 空 | Z21: 空 | AA21: 空 | AB21: 空 | AC21: 空 | AD21: 空 | AE21: 空 | AF21: 0 | AJ21: 是 | AL21: 小boss | AM21: 250 | AN21: 200 | AO21: =COUNTIF($H$4:$O$94,AL21) -> 0 | AP21: =COUNTIF($P$4:$W$94,AL21) -> 0 | AQ21: =COUNTIF($X$4:$AE$94,AL21) -> 0 | AR21: =AO21+AP21+AQ21 -> 0 | AS21: =AO21*$AN21 -> 0 | AT21: =AP21*$AN21 -> 0 | AU21: =AQ21*$AN21 -> 0 | AY21: =AM21*0.8 -> 200
A22: 44474 | B22: 1600 | C22: =(SUM(粮草!A22:X22)+AF22*10)*IF(AJ22="是",$AW$4,$AW$3) -> 0 | D22: =SUM($B$4:B22)-SUM($C$4:C22) -> 29600 | E22: =SUM(经验!A22:X22) -> 0 | F22: =SUM($E$4:E22)+SUM($G$4:G22) -> 1800 | G22: 100 | H22: 空 | I22: 空 | J22: 空 | K22: 空 | L22: 空 | M22: 空 | N22: 空 | O22: 空 | P22: 空 | Q22: 空 | R22: 空 | S22: 空 | T22: 空 | U22: 空 | V22: 空 | W22: 空 | X22: 空 | Y22: 空 | Z22: 空 | AA22: 空 | AB22: 空 | AC22: 空 | AD22: 空 | AE22: 空 | AF22: 0 | AJ22: 是 | AL22: 大boss | AM22: 250 | AN22: 1000 | AO22: =COUNTIF($H$4:$O$94,AL22) -> 0 | AP22: =COUNTIF($P$4:$W$94,AL22) -> 0 | AQ22: =COUNTIF($X$4:$AE$94,AL22) -> 0 | AR22: =AO22+AP22+AQ22 -> 0 | AS22: =AO22*$AN22 -> 0 | AT22: =AP22*$AN22 -> 0 | AU22: =AQ22*$AN22 -> 0 | AY22: =AM22*0.8 -> 200
A23: 44475 | B23: 1600 | C23: =(SUM(粮草!A23:X23)+AF23*10)*IF(AJ23="是",$AW$4,$AW$3) -> 0 | D23: 4672 | E23: =SUM(经验!A23:X23) -> 0 | F23: 9070 | G23: 200 | H23: 空 | I23: 空 | J23: 空 | K23: 空 | L23: 空 | M23: 空 | N23: 空 | O23: 空 | P23: 空 | Q23: 空 | R23: 空 | S23: 空 | T23: 空 | U23: 空 | V23: 空 | W23: 空 | X23: 空 | Y23: 空 | Z23: 空 | AA23: 空 | AB23: 空 | AC23: 空 | AD23: 空 | AE23: 空 | AF23: 0 | AJ23: 是 | AL23: 中boss | AM23: 250 | AN23: 500 | AO23: =COUNTIF($H$4:$O$94,AL23) -> 0 | AP23: =COUNTIF($P$4:$W$94,AL23) -> 0 | AQ23: =COUNTIF($X$4:$AE$94,AL23) -> 0 | AR23: =AO23+AP23+AQ23 -> 0 | AS23: =AO23*$AN23 -> 0 | AT23: =AP23*$AN23 -> 0 | AU23: =AQ23*$AN23 -> 0 | AY23: =AM23*0.8 -> 200
A24: 44476 | B24: 1600 | C24: =(SUM(粮草!A24:X24)+AF24*10)*IF(AJ24="是",$AW$4,$AW$3) -> 0 | D24: =SUM($B$24:B24)-SUM($C$24:C24)+$D$23 -> 6272 | E24: =SUM(经验!A24:X24) -> 0 | F24: =SUM($E$24:E24)+SUM($G$24:G24)+$F$23 -> 9070 | G24: 0 | H24: 空 | I24: 空 | J24: 空 | K24: 空 | L24: 空 | M24: 空 | N24: 空 | O24: 空 | P24: 空 | Q24: 空 | R24: 空 | S24: 空 | T24: 空 | U24: 空 | V24: 空 | W24: 空 | X24: 空 | Y24: 空 | Z24: 空 | AA24: 空 | AB24: 空 | AC24: 空 | AD24: 空 | AE24: 空 | AF24: 0 | AJ24: 是 | AL24: 奈良 | AM24: 160 | AN24: 40 | AO24: =COUNTIF($H$4:$O$94,AL24) -> 0 | AP24: =COUNTIF($P$4:$W$94,AL24) -> 0 | AQ24: =COUNTIF($X$4:$AE$94,AL24) -> 0 | AR24: =AO24+AP24+AQ24 -> 0 | AS24: =AO24*$AN24 -> 0 | AT24: =AP24*$AN24 -> 0 | AU24: =AQ24*$AN24 -> 0 | AY24: =AM24*0.8 -> 128
A25: 44477 | B25: 1600 | C25: =(SUM(粮草!A25:X25)+AF25*10)*IF(AJ25="是",$AW$4,$AW$3) -> 0 | D25: =SUM($B$4:B25)-SUM($C$4:C25) -> 34400 | E25: =SUM(经验!A25:X25) -> 0 | F25: =SUM($E$4:E25)+SUM($G$4:G25) -> 2000 | G25: 0 | H25: 空 | I25: 空 | J25: 空 | K25: 空 | L25: 空 | M25: 空 | N25: 空 | O25: 空 | P25: 空 | Q25: 空 | R25: 空 | S25: 空 | T25: 空 | U25: 空 | V25: 空 | W25: 空 | X25: 空 | Y25: 空 | Z25: 空 | AA25: 空 | AB25: 空 | AC25: 空 | AD25: 空 | AE25: 空 | AF25: 0 | AJ25: 是 | AL25: 山中 | AM25: 160 | AN25: 40 | AO25: =COUNTIF($H$4:$O$94,AL25) -> 0 | AP25: =COUNTIF($P$4:$W$94,AL25) -> 0 | AQ25: =COUNTIF($X$4:$AE$94,AL25) -> 0 | AR25: =AO25+AP25+AQ25 -> 0 | AS25: =AO25*$AN25 -> 0 | AT25: =AP25*$AN25 -> 0 | AU25: =AQ25*$AN25 -> 0 | AY25: =AM25*0.8 -> 128
A26: 44478 | B26: 1600 | C26: =(SUM(粮草!A26:X26)+AF26*10)*IF(AJ26="是",$AW$4,$AW$3) -> 0 | D26: =SUM($B$4:B26)-SUM($C$4:C26) -> 36000 | E26: =SUM(经验!A26:X26) -> 0 | F26: =SUM($E$4:E26)+SUM($G$4:G26) -> 2000 | G26: 0 | H26: 空 | I26: 空 | J26: 空 | K26: 空 | L26: 空 | M26: 空 | N26: 空 | O26: 空 | P26: 空 | Q26: 空 | R26: 空 | S26: 空 | T26: 空 | U26: 空 | V26: 空 | W26: 空 | X26: 空 | Y26: 空 | Z26: 空 | AA26: 空 | AB26: 空 | AC26: 空 | AD26: 空 | AE26: 空 | AF26: 0 | AJ26: 是 | AL26: 秋道 | AM26: 150 | AN26: 35 | AO26: =COUNTIF($H$4:$O$94,AL26) -> 0 | AP26: =COUNTIF($P$4:$W$94,AL26) -> 0 | AQ26: =COUNTIF($X$4:$AE$94,AL26) -> 0 | AR26: =AO26+AP26+AQ26 -> 0 | AS26: =AO26*$AN26 -> 0 | AT26: =AP26*$AN26 -> 0 | AU26: =AQ26*$AN26 -> 0 | AY26: =AM26*0.8 -> 120
A27: 44479 | B27: 1600 | C27: =(SUM(粮草!A27:X27)+AF27*10)*IF(AJ27="是",$AW$4,$AW$3) -> 0 | D27: =SUM($B$4:B27)-SUM($C$4:C27) -> 37600 | E27: =SUM(经验!A27:X27) -> 0 | F27: =SUM($E$4:E27)+SUM($G$4:G27) -> 2000 | G27: 0 | H27: 空 | I27: 空 | J27: 空 | K27: 空 | L27: 空 | M27: 空 | N27: 空 | O27: 空 | P27: 空 | Q27: 空 | R27: 空 | S27: 空 | T27: 空 | U27: 空 | V27: 空 | W27: 空 | X27: 空 | Y27: 空 | Z27: 空 | AA27: 空 | AB27: 空 | AC27: 空 | AD27: 空 | AE27: 空 | AF27: 0 | AJ27: 是 | AL27: 空 | AM27: 0 | AN27: 0 | AS27: =AO27*$AN27 -> 0 | AT27: =AP27*$AN27 -> 0 | AU27: =AQ27*$AN27 -> 0 | AY27: =AM27*0.8 -> 0
A28: 44480 | B28: 1600 | C28: =(SUM(粮草!A28:X28)+AF28*10)*IF(AJ28="是",$AW$4,$AW$3) -> 0 | D28: =SUM($B$4:B28)-SUM($C$4:C28) -> 39200 | E28: =SUM(经验!A28:X28) -> 0 | F28: =SUM($E$4:E28)+SUM($G$4:G28) -> 2200 | G28: 200 | H28: 空 | I28: 空 | J28: 空 | K28: 空 | L28: 空 | M28: 空 | N28: 空 | O28: 空 | P28: 空 | Q28: 空 | R28: 空 | S28: 空 | T28: 空 | U28: 空 | V28: 空 | W28: 空 | X28: 空 | Y28: 空 | Z28: 空 | AA28: 空 | AB28: 空 | AC28: 空 | AD28: 空 | AE28: 空 | AF28: 0 | AJ28: 是 | AK28: 八卦后 | AL28: 营地+ | AM28: -200 | AN28: 0 | AO28: =COUNTIF($H$4:$O$94,AL28) -> 0 | AP28: =COUNTIF($P$4:$W$94,AL28) -> 0 | AQ28: =COUNTIF($X$4:$AE$94,AL28) -> 0 | AR28: =AO28+AP28+AQ28 -> 0 | AS28: =AO28*$AN28 -> 0 | AT28: =AP28*$AN28 -> 0 | AU28: =AQ28*$AN28 -> 0 | AY28: =AM28*0.8 -> -160
A29: 44481 | B29: 1600 | C29: =(SUM(粮草!A29:X29)+AF29*10)*IF(AJ29="是",$AW$4,$AW$3) -> 0 | D29: =SUM($B$4:B29)-SUM($C$4:C29) -> 40800 | E29: =SUM(经验!A29:X29) -> 0 | F29: =SUM($E$4:E29)+SUM($G$4:G29) -> 2300 | G29: 100 | H29: 空 | I29: 空 | J29: 空 | K29: 空 | L29: 空 | M29: 空 | N29: 空 | O29: 空 | P29: 空 | Q29: 空 | R29: 空 | S29: 空 | T29: 空 | U29: 空 | V29: 空 | W29: 空 | X29: 空 | Y29: 空 | Z29: 空 | AA29: 空 | AB29: 空 | AC29: 空 | AD29: 空 | AE29: 空 | AF29: 0 | AJ29: 是 | AQ29: 总地块 | AR29: =SUM(AR4:AR28) -> 0 | AT29: 总经验 | AU29: =SUM(AS4:AU28)+7000 -> 7000
A30: 44482 | B30: 1600 | C30: =(SUM(粮草!A30:X30)+AF30*10)*IF(AJ30="是",$AW$4,$AW$3) -> 0 | D30: =SUM($B$4:B30)-SUM($C$4:C30) -> 42400 | E30: =SUM(经验!A30:X30) -> 0 | F30: =SUM($E$4:E30)+SUM($G$4:G30) -> 2500 | G30: 200 | H30: 空 | I30: 空 | J30: 空 | K30: 空 | L30: 空 | M30: 空 | N30: 空 | O30: 空 | P30: 空 | Q30: 空 | R30: 空 | S30: 空 | T30: 空 | U30: 空 | V30: 空 | W30: 空 | X30: 空 | Y30: 空 | Z30: 空 | AA30: 空 | AB30: 空 | AC30: 空 | AD30: 空 | AE30: 空 | AF30: 0 | AJ30: 是
A31: 44483 | B31: 1600 | C31: =(SUM(粮草!A31:X31)+AF31*10)*IF(AJ31="是",$AW$4,$AW$3) -> 0 | D31: =SUM($B$4:B31)-SUM($C$4:C31) -> 44000 | E31: =SUM(经验!A31:X31) -> 0 | F31: =SUM($E$4:E31)+SUM($G$4:G31) -> 2500 | G31: 0 | H31: 空 | I31: 空 | J31: 空 | K31: 空 | L31: 空 | M31: 空 | N31: 空 | O31: 空 | P31: 空 | Q31: 空 | R31: 空 | S31: 空 | T31: 空 | U31: 空 | V31: 空 | W31: 空 | X31: 空 | Y31: 空 | Z31: 空 | AA31: 空 | AB31: 空 | AC31: 空 | AD31: 空 | AE31: 空 | AF31: 0 | AJ31: 是
A32: 44484 | B32: 1600 | C32: =(SUM(粮草!A32:X32)+AF32*10)*IF(AJ32="是",$AW$4,$AW$3) -> 0 | D32: =SUM($B$4:B32)-SUM($C$4:C32) -> 45600 | E32: =SUM(经验!A32:X32) -> 0 | F32: =SUM($E$4:E32)+SUM($G$4:G32) -> 2500 | G32: 0 | H32: 空 | I32: 空 | J32: 空 | K32: 空 | L32: 空 | M32: 空 | N32: 空 | O32: 空 | P32: 空 | Q32: 空 | R32: 空 | S32: 空 | T32: 空 | U32: 空 | V32: 空 | W32: 空 | X32: 空 | Y32: 空 | Z32: 空 | AA32: 空 | AB32: 空 | AC32: 空 | AD32: 空 | AE32: 空 | AF32: 0 | AJ32: 是
A33: 44485 | B33: 1600 | C33: =(SUM(粮草!A33:X33)+AF33*10)*IF(AJ33="是",$AW$4,$AW$3) -> 0 | D33: =SUM($B$4:B33)-SUM($C$4:C33) -> 47200 | E33: =SUM(经验!A33:X33) -> 0 | F33: =SUM($E$4:E33)+SUM($G$4:G33) -> 2500 | G33: 0 | H33: 空 | I33: 空 | J33: 空 | K33: 空 | L33: 空 | M33: 空 | N33: 空 | O33: 空 | P33: 空 | Q33: 空 | R33: 空 | S33: 空 | T33: 空 | U33: 空 | V33: 空 | W33: 空 | X33: 空 | Y33: 空 | Z33: 空 | AA33: 空 | AB33: 空 | AC33: 空 | AD33: 空 | AE33: 空 | AF33: 0 | AJ33: 是
A34: 44486 | B34: 1600 | C34: =(SUM(粮草!A34:X34)+AF34*10)*IF(AJ34="是",$AW$4,$AW$3) -> 0 | D34: =SUM($B$4:B34)-SUM($C$4:C34) -> 48800 | E34: =SUM(经验!A34:X34) -> 0 | F34: =SUM($E$4:E34)+SUM($G$4:G34) -> 2500 | G34: 0 | H34: 空 | I34: 空 | J34: 空 | K34: 空 | L34: 空 | M34: 空 | N34: 空 | O34: 空 | P34: 空 | Q34: 空 | R34: 空 | S34: 空 | T34: 空 | U34: 空 | V34: 空 | W34: 空 | X34: 空 | Y34: 空 | Z34: 空 | AA34: 空 | AB34: 空 | AC34: 空 | AD34: 空 | AE34: 空 | AF34: 0 | AJ34: 是
A35: 44487 | B35: 1600 | C35: =(SUM(粮草!A35:X35)+AF35*10)*IF(AJ35="是",$AW$4,$AW$3) -> 0 | D35: =SUM($B$4:B35)-SUM($C$4:C35) -> 50400 | E35: =SUM(经验!A35:X35) -> 0 | F35: =SUM($E$4:E35)+SUM($G$4:G35) -> 2700 | G35: 200 | H35: 空 | I35: 空 | J35: 空 | K35: 空 | L35: 空 | M35: 空 | N35: 空 | O35: 空 | P35: 空 | Q35: 空 | R35: 空 | S35: 空 | T35: 空 | U35: 空 | V35: 空 | W35: 空 | X35: 空 | Y35: 空 | Z35: 空 | AA35: 空 | AB35: 空 | AC35: 空 | AD35: 空 | AE35: 空 | AF35: 0 | AJ35: 是
A36: 44488 | B36: 1600 | C36: =(SUM(粮草!A36:X36)+AF36*10)*IF(AJ36="是",$AW$4,$AW$3) -> 0 | D36: =SUM($B$4:B36)-SUM($C$4:C36) -> 52000 | E36: =SUM(经验!A36:X36) -> 0 | F36: =SUM($E$4:E36)+SUM($G$4:G36) -> 2800 | G36: 100 | H36: 空 | I36: 空 | J36: 空 | K36: 空 | L36: 空 | M36: 空 | N36: 空 | O36: 空 | P36: 空 | Q36: 空 | R36: 空 | S36: 空 | T36: 空 | U36: 空 | V36: 空 | W36: 空 | X36: 空 | Y36: 空 | Z36: 空 | AA36: 空 | AB36: 空 | AC36: 空 | AD36: 空 | AE36: 空 | AF36: 0 | AJ36: 是
A37: 44489 | B37: 1600 | C37: =(SUM(粮草!A37:X37)+AF37*10)*IF(AJ37="是",$AW$4,$AW$3) -> 0 | D37: =SUM($B$4:B37)-SUM($C$4:C37) -> 53600 | E37: =SUM(经验!A37:X37) -> 0 | F37: =SUM($E$4:E37)+SUM($G$4:G37) -> 3000 | G37: 200 | H37: 空 | I37: 空 | J37: 空 | K37: 空 | L37: 空 | M37: 空 | N37: 空 | O37: 空 | P37: 空 | Q37: 空 | R37: 空 | S37: 空 | T37: 空 | U37: 空 | V37: 空 | W37: 空 | X37: 空 | Y37: 空 | Z37: 空 | AA37: 空 | AB37: 空 | AC37: 空 | AD37: 空 | AE37: 空 | AF37: 0 | AJ37: 是
A38: 44490 | B38: 1600 | C38: =(SUM(粮草!A38:X38)+AF38*10)*IF(AJ38="是",$AW$4,$AW$3) -> 0 | D38: =SUM($B$4:B38)-SUM($C$4:C38) -> 55200 | E38: =SUM(经验!A38:X38) -> 0 | F38: =SUM($E$4:E38)+SUM($G$4:G38) -> 3000 | G38: 0 | H38: 空 | I38: 空 | J38: 空 | K38: 空 | L38: 空 | M38: 空 | N38: 空 | O38: 空 | P38: 空 | Q38: 空 | R38: 空 | S38: 空 | T38: 空 | U38: 空 | V38: 空 | W38: 空 | X38: 空 | Y38: 空 | Z38: 空 | AA38: 空 | AB38: 空 | AC38: 空 | AD38: 空 | AE38: 空 | AF38: 0 | AJ38: 是
A39: 44491 | B39: 1600 | C39: =(SUM(粮草!A39:X39)+AF39*10)*IF(AJ39="是",$AW$4,$AW$3) -> 0 | D39: =SUM($B$4:B39)-SUM($C$4:C39) -> 56800 | E39: =SUM(经验!A39:X39) -> 0 | F39: =SUM($E$4:E39)+SUM($G$4:G39) -> 3000 | G39: 0 | H39: 空 | I39: 空 | J39: 空 | K39: 空 | L39: 空 | M39: 空 | N39: 空 | O39: 空 | P39: 空 | Q39: 空 | R39: 空 | S39: 空 | T39: 空 | U39: 空 | V39: 空 | W39: 空 | X39: 空 | Y39: 空 | Z39: 空 | AA39: 空 | AB39: 空 | AC39: 空 | AD39: 空 | AE39: 空 | AF39: 0 | AJ39: 是
A40: 44492 | B40: 1600 | C40: =(SUM(粮草!A40:X40)+AF40*10)*IF(AJ40="是",$AW$4,$AW$3) -> 0 | D40: =SUM($B$4:B40)-SUM($C$4:C40) -> 58400 | E40: =SUM(经验!A40:X40) -> 0 | F40: =SUM($E$4:E40)+SUM($G$4:G40) -> 3000 | G40: 0 | H40: 空 | I40: 空 | J40: 空 | K40: 空 | L40: 空 | M40: 空 | N40: 空 | O40: 空 | P40: 空 | Q40: 空 | R40: 空 | S40: 空 | T40: 空 | U40: 空 | V40: 空 | W40: 空 | X40: 空 | Y40: 空 | Z40: 空 | AA40: 空 | AB40: 空 | AC40: 空 | AD40: 空 | AE40: 空 | AF40: 0 | AJ40: 是
...

Sheet 粮草
A2: 队伍一 风 | C2: 步数 | D2: =COUNTIF(A4:H94,"<>空") -> 728 | E2: (不算跳步和传送) | I2: 队伍二 雷 | K2: 步数 | L2: =COUNTIF(I4:P94,"<>空") -> 728 | M2: (不算跳步和传送) | Q2: 队伍三 | S2: 总步数 | T2: =COUNTIF(Q4:X94,"<>空") -> 728 | U2: (不算跳步和传送)
A3: 1 | B3: 2 | C3: 3 | D3: 4 | E3: 5 | F3: 6 | G3: 7 | H3: 8 | I3: 1 | J3: 2 | K3: 3 | L3: 4 | M3: 5 | N3: 6 | O3: 7 | P3: 8 | Q3: 1 | R3: 2 | S3: 3 | T3: 4 | U3: 5 | V3: 6 | W3: 7 | X3: 8
A4: =(VLOOKUP('102 5.1.00'!H4,'102 5.1.00'!$AL$4:$AN$55,2,FALSE))*IF('102 5.1.00'!AJ$4="是",'102 5.1.00'!$AW$4,'102 5.1.00'!$AW$3) -> 0 | B4: =(VLOOKUP('102 5.1.00'!I4,'102 5.1.00'!$AL$4:$AN$55,2,FALSE))*IF('102 5.1.00'!AK$4="是",'102 5.1.00'!$AW$4,'102 5.1.00'!$AW$3) -> 0 | C4: =(VLOOKUP('102 5.1.00'!J4,'102 5.1.00'!$AL$4:$AN$55,2,FALSE))*IF('102 5.1.00'!AL$4="是",'102 5.1.00'!$AW$4,'102 5.1.00'!$AW$3) -> 0 | D4: =(VLOOKUP('102 5.1.00'!K4,'102 5.1.00'!$AL$4:$AN$55,2,FALSE))*IF('102 5.1.00'!AM$4="是",'102 5.1.00'!$AW$4,'102 5.1.00'!$AW$3) -> 0 | E4: =(VLOOKUP('102 5.1.00'!L4,'102 5.1.00'!$AL$4:$AN$55,2,FALSE))*IF('102 5.1.00'!AN$4="是",'102 5.1.00'!$AW$4,'102 5.1.00'!$AW$3) -> 0 | F4: =(VLOOKUP('102 5.1.00'!M4,'102 5.1.00'!$AL$4:$AN$55,2,FALSE))*IF('102 5.1.00'!AO$4="是",'102 5.1.00'!$AW$4,'102 5.1.00'!$AW$3) -> 0 | G4: =(VLOOKUP('102 5.1.00'!N4,'102 5.1.00'!$AL$4:$AN$55,2,FALSE))*IF('102 5.1.00'!AP$4="是",'102 5.1.00'!$AW$4,'102 5.1.00'!$AW$3) -> 0 | H4: =(VLOOKUP('102 5.1.00'!O4,'102 5.1.00'!$AL$4:$AN$55,2,FALSE))*IF('102 5.1.00'!AQ$4="是",'102 5.1.00'!$AW$4,'102 5.1.00'!$AW$3) -> 0 | ... X4: =(VLOOKUP('102 5.1.00'!AE4,'102 5.1.00'!$AL$4:$AN$55,2,FALSE))*IF('102 5.1.00'!BG$4="是",'102 5.1.00'!$AW$4,'102 5.1.00'!$AW$3) -> 0
A5: =(VLOOKUP('102 5.1.00'!H5,'102 5.1.00'!$AL$4:$AN$55,2,FALSE))*IF('102 5.1.00'!AJ$4="是",'102 5.1.00'!$AW$4,'102 5.1.00'!$AW$3) -> 0 | B5: =(VLOOKUP('102 5.1.00'!I5,'102 5.1.00'!$AL$4:$AN$55,2,FALSE))*IF('102 5.1.00'!AK$4="是",'102 5.1.00'!$AW$4,'102 5.1.00'!$AW$3) -> 0 | C5: =(VLOOKUP('102 5.1.00'!J5,'102 5.1.00'!$AL$4:$AN$55,2,FALSE))*IF('102 5.1.00'!AL$4="是",'102 5.1.00'!$AW$4,'102 5.1.00'!$AW$3) -> 0 | D5: =(VLOOKUP('102 5.1.00'!K5,'102 5.1.00'!$AL$4:$AN$55,2,FALSE))*IF('102 5.1.00'!AM$4="是",'102 5.1.00'!$AW$4,'102 5.1.00'!$AW$3) -> 0 | E5: =(VLOOKUP('102 5.1.00'!L5,'102 5.1.00'!$AL$4:$AN$55,2,FALSE))*IF('102 5.1.00'!AN$4="是",'102 5.1.00'!$AW$4,'102 5.1.00'!$AW$3) -> 0 | F5: =(VLOOKUP('102 5.1.00'!M5,'102 5.1.00'!$AL$4:$AN$55,2,FALSE))*IF('102 5.1.00'!AO$4="是",'102 5.1.00'!$AW$4,'102 5.1.00'!$AW$3) -> 0 | G5: =(VLOOKUP('102 5.1.00'!N5,'102 5.1.00'!$AL$4:$AN$55,2,FALSE))*IF('102 5.1.00'!AP$4="是",'102 5.1.00'!$AW$4,'102 5.1.00'!$AW$3) -> 0 | H5: =(VLOOKUP('102 5.1.00'!O5,'102 5.1.00'!$AL$4:$AN$55,2,FALSE))*IF('102 5.1.00'!AQ$4="是",'102 5.1.00'!$AW$4,'102 5.1.00'!$AW$3) -> 0 | ... X5: =(VLOOKUP('102 5.1.00'!AE5,'102 5.1.00'!$AL$4:$AN$55,2,FALSE))*IF('102 5.1.00'!BG$4="是",'102 5.1.00'!$AW$4,'102 5.1.00'!$AW$3) -> 0
A6: =(VLOOKUP('102 5.1.00'!H6,'102 5.1.00'!$AL$4:$AN$55,2,FALSE))*IF('102 5.1.00'!AJ$4="是",'102 5.1.00'!$AW$4,'102 5.1.00'!$AW$3) -> 0 | B6: =(VLOOKUP('102 5.1.00'!I6,'102 5.1.00'!$AL$4:$AN$55,2,FALSE))*IF('102 5.1.00'!AK$4="是",'102 5.1.00'!$AW$4,'102 5.1.00'!$AW$3) -> 0 | C6: =(VLOOKUP('102 5.1.00'!J6,'102 5.1.00'!$AL$4:$AN$55,2,FALSE))*IF('102 5.1.00'!AL$4="是",'102 5.1.00'!$AW$4,'102 5.1.00'!$AW$3) -> 0 | D6: =(VLOOKUP('102 5.1.00'!K6,'102 5.1.00'!$AL$4:$AN$55,2,FALSE))*IF('102 5.1.00'!AM$4="是",'102 5.1.00'!$AW$4,'102 5.1.00'!$AW$3) -> 0 | E6: =(VLOOKUP('102 5.1.00'!L6,'102 5.1.00'!$AL$4:$AN$55,2,FALSE))*IF('102 5.1.00'!AN$4="是",'102 5.1.00'!$AW$4,'102 5.1.00'!$AW$3) -> 0 | F6: =(VLOOKUP('102 5.1.00'!M6,'102 5.1.00'!$AL$4:$AN$55,2,FALSE))*IF('102 5.1.00'!AO$4="是",'102 5.1.00'!$AW$4,'102 5.1.00'!$AW$3) -> 0 | G6: =(VLOOKUP('102 5.1.00'!N6,'102 5.1.00'!$AL$4:$AN$55,2,FALSE))*IF('102 5.1.00'!AP$4="是",'102 5.1.00'!$AW$4,'102 5.1.00'!$AW$3) -> 0 | H6: =(VLOOKUP('102 5.1.00'!O6,'102 5.1.00'!$AL$4:$AN$55,2,FALSE))*IF('102 5.1.00'!AQ$4="是",'102 5.1.00'!$AW$4,'102 5.1.00'!$AW$3) -> 0 | ... X6: =(VLOOKUP('102 5.1.00'!AE6,'102 5.1.00'!$AL$4:$AN$55,2,FALSE))*IF('102 5.1.00'!BG$4="是",'102 5.1.00'!$AW$4,'102 5.1.00'!$AW$3) -> 0
A7: =(VLOOKUP('102 5.1.00'!H7,'102 5.1.00'!$AL$4:$AN$55,2,FALSE))*IF('102 5.1.00'!AJ$4="是",'102 5.1.00'!$AW$4,'102 5.1.00'!$AW$3) -> 0 | B7: =(VLOOKUP('102 5.1.00'!I7,'102 5.1.00'!$AL$4:$AN$55,2,FALSE))*IF('102 5.1.00'!AK$4="是",'102 5.1.00'!$AW$4,'102 5.1.00'!$AW$3) -> 0 | C7: =(VLOOKUP('102 5.1.00'!J7,'102 5.1.00'!$AL$4:$AN$55,2,FALSE))*IF('102 5.1.00'!AL$4="是",'102 5.1.00'!$AW$4,'102 5.1.00'!$AW$3) -> 0 | D7: =(VLOOKUP('102 5.1.00'!K7,'102 5.1.00'!$AL$4:$AN$55,2,FALSE))*IF('102 5.1.00'!AM$4="是",'102 5.1.00'!$AW$4,'102 5.1.00'!$AW$3) -> 0 | E7: =(VLOOKUP('102 5.1.00'!L7,'102 5.1.00'!$AL$4:$AN$55,2,FALSE))*IF('102 5.1.00'!AN$4="是",'102 5.1.00'!$AW$4,'102 5.1.00'!$AW$3) -> 0 | F7: =(VLOOKUP('102 5.1.00'!M7,'102 5.1.00'!$AL$4:$AN$55,2,FALSE))*IF('102 5.1.00'!AO$4="是",'102 5.1.00'!$AW$4,'102 5.1.00'!$AW$3) -> 0 | G7: =(VLOOKUP('102 5.1.00'!N7,'102 5.1.00'!$AL$4:$AN$55,2,FALSE))*IF('102 5.1.00'!AP$4="是",'102 5.1.00'!$AW$4,'102 5.1.00'!$AW$3) -> 0 | H7: =(VLOOKUP('102 5.1.00'!O7,'102 5.1.00'!$AL$4:$AN$55,2,FALSE))*IF('102 5.1.00'!AQ$4="是",'102 5.1.00'!$AW$4,'102 5.1.00'!$AW$3) -> 0 | ... X7: =(VLOOKUP('102 5.1.00'!AE7,'102 5.1.00'!$AL$4:$AN$55,2,FALSE))*IF('102 5.1.00'!BG$4="是",'102 5.1.00'!$AW$4,'102 5.1.00'!$AW$3) -> 0
A8: =(VLOOKUP('102 5.1.00'!H8,'102 5.1.00'!$AL$4:$AN$55,2,FALSE))*IF('102 5.1.00'!AJ$4="是",'102 5.1.00'!$AW$4,'102 5.1.00'!$AW$3) -> 0 | B8: =(VLOOKUP('102 5.1.00'!I8,'102 5.1.00'!$AL$4:$AN$55,2,FALSE))*IF('102 5.1.00'!AK$4="是",'102 5.1.00'!$AW$4,'102 5.1.00'!$AW$3) -> 0 | C8: =(VLOOKUP('102 5.1.00'!J8,'102 5.1.00'!$AL$4:$AN$55,2,FALSE))*IF('102 5.1.00'!AL$4="是",'102 5.1.00'!$AW$4,'102 5.1.00'!$AW$3) -> 0 | D8: =(VLOOKUP('102 5.1.00'!K8,'102 5.1.00'!$AL$4:$AN$55,2,FALSE))*IF('102 5.1.00'!AM$4="是",'102 5.1.00'!$AW$4,'102 5.1.00'!$AW$3) -> 0 | E8: =(VLOOKUP('102 5.1.00'!L8,'102 5.1.00'!$AL$4:$AN$55,2,FALSE))*IF('102 5.1.00'!AN$4="是",'102 5.1.00'!$AW$4,'102 5.1.00'!$AW$3) -> 0 | F8: =(VLOOKUP('102 5.1.00'!M8,'102 5.1.00'!$AL$4:$AN$55,2,FALSE))*IF('102 5.1.00'!AO$4="是",'102 5.1.00'!$AW$4,'102 5.1.00'!$AW$3) -> 0 | G8: =(VLOOKUP('102 5.1.00'!N8,'102 5.1.00'!$AL$4:$AN$55,2,FALSE))*IF('102 5.1.00'!AP$4="是",'102 5.1.00'!$AW$4,'102 5.1.00'!$AW$3) -> 0 | H8: =(VLOOKUP('102 5.1.00'!O8,'102 5.1.00'!$AL$4:$AN$55,2,FALSE))*IF('102 5.1.00'!AQ$4="是",'102 5.1.00'!$AW$4,'102 5.1.00'!$AW$3) -> 0 | ... X8: =(VLOOKUP('102 5.1.00'!AE8,'102 5.1.00'!$AL$4:$AN$55,2,FALSE))*IF('102 5.1.00'!BG$4="是",'102 5.1.00'!$AW$4,'102 5.1.00'!$AW$3) -> 0
A9: =(VLOOKUP('102 5.1.00'!H9,'102 5.1.00'!$AL$4:$AN$55,2,FALSE))*IF('102 5.1.00'!AJ$4="是",'102 5.1.00'!$AW$4,'102 5.1.00'!$AW$3) -> 0 | B9: =(VLOOKUP('102 5.1.00'!I9,'102 5.1.00'!$AL$4:$AN$55,2,FALSE))*IF('102 5.1.00'!AK$4="是",'102 5.1.00'!$AW$4,'102 5.1.00'!$AW$3) -> 0 | C9: =(VLOOKUP('102 5.1.00'!J9,'102 5.1.00'!$AL$4:$AN$55,2,FALSE))*IF('102 5.1.00'!AL$4="是",'102 5.1.00'!$AW$4,'102 5.1.00'!$AW$3) -> 0 | D9: =(VLOOKUP('102 5.1.00'!K9,'102 5.1.00'!$AL$4:$AN$55,2,FALSE))*IF('102 5.1.00'!AM$4="是",'102 5.1.00'!$AW$4,'102 5.1.00'!$AW$3) -> 0 | E9: =(VLOOKUP('102 5.1.00'!L9,'102 5.1.00'!$AL$4:$AN$55,2,FALSE))*IF('102 5.1.00'!AN$4="是",'102 5.1.00'!$AW$4,'102 5.1.00'!$AW$3) -> 0 | F9: =(VLOOKUP('102 5.1.00'!M9,'102 5.1.00'!$AL$4:$AN$55,2,FALSE))*IF('102 5.1.00'!AO$4="是",'102 5.1.00'!$AW$4,'102 5.1.00'!$AW$3) -> 0 | G9: =(VLOOKUP('102 5.1.00'!N9,'102 5.1.00'!$AL$4:$AN$55,2,FALSE))*IF('102 5.1.00'!AP$4="是",'102 5.1.00'!$AW$4,'102 5.1.00'!$AW$3) -> 0 | H9: =(VLOOKUP('102 5.1.00'!O9,'102 5.1.00'!$AL$4:$AN$55,2,FALSE))*IF('102 5.1.00'!AQ$4="是",'102 5.1.00'!$AW$4,'102 5.1.00'!$AW$3) -> 0 | ... X9: =(VLOOKUP('102 5.1.00'!AE9,'102 5.1.00'!$AL$4:$AN$55,2,FALSE))*IF('102 5.1.00'!BG$4="是",'102 5.1.00'!$AW$4,'102 5.1.00'!$AW$3) -> 0
A10: =(VLOOKUP('102 5.1.00'!H10,'102 5.1.00'!$AL$4:$AN$55,2,FALSE))*IF('102 5.1.00'!AJ$4="是",'102 5.1.00'!$AW$4,'102 5.1.00'!$AW$3) -> 0 | B10: =(VLOOKUP('102 5.1.00'!I10,'102 5.1.00'!$AL$4:$AN$55,2,FALSE))*IF('102 5.1.00'!AK$4="是",'102 5.1.00'!$AW$4,'102 5.1.00'!$AW$3) -> 0 | C10: =(VLOOKUP('102 5.1.00'!J10,'102 5.1.00'!$AL$4:$AN$55,2,FALSE))*IF('102 5.1.00'!AL$4="是",'102 5.1.00'!$AW$4,'102 5.1.00'!$AW$3) -> 0 | D10: =(VLOOKUP('102 5.1.00'!K10,'102 5.1.00'!$AL$4:$AN$55,2,FALSE))*IF('102 5.1.00'!AM$4="是",'102 5.1.00'!$AW$4,'102 5.1.00'!$AW$3) -> 0 | E10: =(VLOOKUP('102 5.1.00'!L10,'102 5.1.00'!$AL$4:$AN$55,2,FALSE))*IF('102 5.1.00'!AN$4="是",'102 5.1.00'!$AW$4,'102 5.1.00'!$AW$3) -> 0 | F10: =(VLOOKUP('102 5.1.00'!M10,'102 5.1.00'!$AL$4:$AN$55,2,FALSE))*IF('102 5.1.00'!AO$4="是",'102 5.1.00'!$AW$4,'102 5.1.00'!$AW$3) -> 0 | G10: =(VLOOKUP('102 5.1.00'!N10,'102 5.1.00'!$AL$4:$AN$55,2,FALSE))*IF('102 5.1.00'!AP$4="是",'102 5.1.00'!$AW$4,'102 5.1.00'!$AW$3) -> 0 | H10: =(VLOOKUP('102 5.1.00'!O10,'102 5.1.00'!$AL$4:$AN$55,2,FALSE))*IF('102 5.1.00'!AQ$4="是",'102 5.1.00'!$AW$4,'102 5.1.00'!$AW$3) -> 0 | ... X10: =(VLOOKUP('102 5.1.00'!AE10,'102 5.1.00'!$AL$4:$AN$55,2,FALSE))*IF('102 5.1.00'!BG$4="是",'102 5.1.00'!$AW$4,'102 5.1.00'!$AW$3) -> 0
A11: =(VLOOKUP('102 5.1.00'!H11,'102 5.1.00'!$AL$4:$AN$55,2,FALSE))*IF('102 5.1.00'!AJ$4="是",'102 5.1.00'!$AW$4,'102 5.1.00'!$AW$3) -> 0 | B11: =(VLOOKUP('102 5.1.00'!I11,'102 5.1.00'!$AL$4:$AN$55,2,FALSE))*IF('102 5.1.00'!AK$4="是",'102 5.1.00'!$AW$4,'102 5.1.00'!$AW$3) -> 0 | C11: =(VLOOKUP('102 5.1.00'!J11,'102 5.1.00'!$AL$4:$AN$55,2,FALSE))*IF('102 5.1.00'!AL$4="是",'102 5.1.00'!$AW$4,'102 5.1.00'!$AW$3) -> 0 | D11: =(VLOOKUP('102 5.1.00'!K11,'102 5.1.00'!$AL$4:$AN$55,2,FALSE))*IF('102 5.1.00'!AM$4="是",'102 5.1.00'!$AW$4,'102 5.1.00'!$AW$3) -> 0 | E11: =(VLOOKUP('102 5.1.00'!L11,'102 5.1.00'!$AL$4:$AN$55,2,FALSE))*IF('102 5.1.00'!AN$4="是",'102 5.1.00'!$AW$4,'102 5.1.00'!$AW$3) -> 0 | F11: =(VLOOKUP('102 5.1.00'!M11,'102 5.1.00'!$AL$4:$AN$55,2,FALSE))*IF('102 5.1.00'!AO$4="是",'102 5.1.00'!$AW$4,'102 5.1.00'!$AW$3) -> 0 | G11: =(VLOOKUP('102 5.1.00'!N11,'102 5.1.00'!$AL$4:$AN$55,2,FALSE))*IF('102 5.1.00'!AP$4="是",'102 5.1.00'!$AW$4,'102 5.1.00'!$AW$3) -> 0 | H11: =(VLOOKUP('102 5.1.00'!O11,'102 5.1.00'!$AL$4:$AN$55,2,FALSE))*IF('102 5.1.00'!AQ$4="是",'102 5.1.00'!$AW$4,'102 5.1.00'!$AW$3) -> 0 | ... X11: =(VLOOKUP('102 5.1.00'!AE11,'102 5.1.00'!$AL$4:$AN$55,2,FALSE))*IF('102 5.1.00'!BG$4="是",'102 5.1.00'!$AW$4,'102 5.1.00'!$AW$3) -> 0
A12: =(VLOOKUP('102 5.1.00'!H12,'102 5.1.00'!$AL$4:$AN$55,2,FALSE))*IF('102 5.1.00'!AJ$4="是",'102 5.1.00'!$AW$4,'102 5.1.00'!$AW$3) -> 0 | B12: =(VLOOKUP('102 5.1.00'!I12,'102 5.1.00'!$AL$4:$AN$55,2,FALSE))*IF('102 5.1.00'!AK$4="是",'102 5.1.00'!$AW$4,'102 5.1.00'!$AW$3) -> 0 | C12: =(VLOOKUP('102 5.1.00'!J12,'102 5.1.00'!$AL$4:$AN$55,2,FALSE))*IF('102 5.1.00'!AL$4="是",'102 5.1.00'!$AW$4,'102 5.1.00'!$AW$3) -> 0 | D12: =(VLOOKUP('102 5.1.00'!K12,'102 5.1.00'!$AL$4:$AN$55,2,FALSE))*IF('102 5.1.00'!AM$4="是",'102 5.1.00'!$AW$4,'102 5.1.00'!$AW$3) -> 0 | E12: =(VLOOKUP('102 5.1.00'!L12,'102 5.1.00'!$AL$4:$AN$55,2,FALSE))*IF('102 5.1.00'!AN$4="是",'102 5.1.00'!$AW$4,'102 5.1.00'!$AW$3) -> 0 | F12: =(VLOOKUP('102 5.1.00'!M12,'102 5.1.00'!$AL$4:$AN$55,2,FALSE))*IF('102 5.1.00'!AO$4="是",'102 5.1.00'!$AW$4,'102 5.1.00'!$AW$3) -> 0 | G12: =(VLOOKUP('102 5.1.00'!N12,'102 5.1.00'!$AL$4:$AN$55,2,FALSE))*IF('102 5.1.00'!AP$4="是",'102 5.1.00'!$AW$4,'102 5.1.00'!$AW$3) -> 0 | H12: =(VLOOKUP('102 5.1.00'!O12,'102 5.1.00'!$AL$4:$AN$55,2,FALSE))*IF('102 5.1.00'!AQ$4="是",'102 5.1.00'!$AW$4,'102 5.1.00'!$AW$3) -> 0 | ... X12: =(VLOOKUP('102 5.1.00'!AE12,'102 5.1.00'!$AL$4:$AN$55,2,FALSE))*IF('102 5.1.00'!BG$4="是",'102 5.1.00'!$AW$4,'102 5.1.00'!$AW$3) -> 0
A13: =(VLOOKUP('102 5.1.00'!H13,'102 5.1.00'!$AL$4:$AN$55,2,FALSE))*IF('102 5.1.00'!AJ$4="是",'102 5.1.00'!$AW$4,'102 5.1.00'!$AW$3) -> 0 | B13: =(VLOOKUP('102 5.1.00'!I13,'102 5.1.00'!$AL$4:$AN$55,2,FALSE))*IF('102 5.1.00'!AK$4="是",'102 5.1.00'!$AW$4,'102 5.1.00'!$AW$3) -> 0 | C13: =(VLOOKUP('102 5.1.00'!J13,'102 5.1.00'!$AL$4:$AN$55,2,FALSE))*IF('102 5.1.00'!AL$4="是",'102 5.1.00'!$AW$4,'102 5.1.00'!$AW$3) -> 0 | D13: =(VLOOKUP('102 5.1.00'!K13,'102 5.1.00'!$AL$4:$AN$55,2,FALSE))*IF('102 5.1.00'!AM$4="是",'102 5.1.00'!$AW$4,'102 5.1.00'!$AW$3) -> 0 | E13: =(VLOOKUP('102 5.1.00'!L13,'102 5.1.00'!$AL$4:$AN$55,2,FALSE))*IF('102 5.1.00'!AN$4="是",'102 5.1.00'!$AW$4,'102 5.1.00'!$AW$3) -> 0 | F13: =(VLOOKUP('102 5.1.00'!M13,'102 5.1.00'!$AL$4:$AN$55,2,FALSE))*IF('102 5.1.00'!AO$4="是",'102 5.1.00'!$AW$4,'102 5.1.00'!$AW$3) -> 0 | G13: =(VLOOKUP('102 5.1.00'!N13,'102 5.1.00'!$AL$4:$AN$55,2,FALSE))*IF('102 5.1.00'!AP$4="是",'102 5.1.00'!$AW$4,'102 5.1.00'!$AW$3) -> 0 | H13: =(VLOOKUP('102 5.1.00'!O13,'102 5.1.00'!$AL$4:$AN$55,2,FALSE))*IF('102 5.1.00'!AQ$4="是",'102 5.1.00'!$AW$4,'102 5.1.00'!$AW$3) -> 0 | ... X13: =(VLOOKUP('102 5.1.00'!AE13,'102 5.1.00'!$AL$4:$AN$55,2,FALSE))*IF('102 5.1.00'!BG$4="是",'102 5.1.00'!$AW$4,'102 5.1.00'!$AW$3) -> 0
A14: =(VLOOKUP('102 5.1.00'!H14,'102 5.1.00'!$AL$4:$AN$55,2,FALSE))*IF('102 5.1.00'!AJ$4="是",'102 5.1.00'!$AW$4,'102 5.1.00'!$AW$3) -> 0 | B14: =(VLOOKUP('102 5.1.00'!I14,'102 5.1.00'!$AL$4:$AN$55,2,FALSE))*IF('102 5.1.00'!AK$4="是",'102 5.1.00'!$AW$4,'102 5.1.00'!$AW$3) -> 0 | C14: =(VLOOKUP('102 5.1.00'!J14,'102 5.1.00'!$AL$4:$AN$55,2,FALSE))*IF('102 5.1.00'!AL$4="是",'102 5.1.00'!$AW$4,'102 5.1.00'!$AW$3) -> 0 | D14: =(VLOOKUP('102 5.1.00'!K14,'102 5.1.00'!$AL$4:$AN$55,2,FALSE))*IF('102 5.1.00'!AM$4="是",'102 5.1.00'!$AW$4,'102 5.1.00'!$AW$3) -> 0 | E14: =(VLOOKUP('102 5.1.00'!L14,'102 5.1.00'!$AL$4:$AN$55,2,FALSE))*IF('102 5.1.00'!AN$4="是",'102 5.1.00'!$AW$4,'102 5.1.00'!$AW$3) -> 0 | F14: =(VLOOKUP('102 5.1.00'!M14,'102 5.1.00'!$AL$4:$AN$55,2,FALSE))*IF('102 5.1.00'!AO$4="是",'102 5.1.00'!$AW$4,'102 5.1.00'!$AW$3) -> 0 | G14: =(VLOOKUP('102 5.1.00'!N14,'102 5.1.00'!$AL$4:$AN$55,2,FALSE))*IF('102 5.1.00'!AP$4="是",'102 5.1.00'!$AW$4,'102 5.1.00'!$AW$3) -> 0 | H14: =(VLOOKUP('102 5.1.00'!O14,'102 5.1.00'!$AL$4:$AN$55,2,FALSE))*IF('102 5.1.00'!AQ$4="是",'102 5.1.00'!$AW$4,'102 5.1.00'!$AW$3) -> 0 | ... X14: =(VLOOKUP('102 5.1.00'!AE14,'102 5.1.00'!$AL$4:$AN$55,2,FALSE))*IF('102 5.1.00'!BG$4="是",'102 5.1.00'!$AW$4,'102 5.1.00'!$AW$3) -> 0
A15: =(VLOOKUP('102 5.1.00'!H15,'102 5.1.00'!$AL$4:$AN$55,2,FALSE))*IF('102 5.1.00'!AJ$4="是",'102 5.1.00'!$AW$4,'102 5.1.00'!$AW$3) -> 0 | B15: =(VLOOKUP('102 5.1.00'!I15,'102 5.1.00'!$AL$4:$AN$55,2,FALSE))*IF('102 5.1.00'!AK$4="是",'102 5.1.00'!$AW$4,'102 5.1.00'!$AW$3) -> 0 | C15: =(VLOOKUP('102 5.1.00'!J15,'102 5.1.00'!$AL$4:$AN$55,2,FALSE))*IF('102 5.1.00'!AL$4="是",'102 5.1.00'!$AW$4,'102 5.1.00'!$AW$3) -> 0 | D15: =(VLOOKUP('102 5.1.00'!K15,'102 5.1.00'!$AL$4:$AN$55,2,FALSE))*IF('102 5.1.00'!AM$4="是",'102 5.1.00'!$AW$4,'102 5.1.00'!$AW$3) -> 0 | E15: =(VLOOKUP('102 5.1.00'!L15,'102 5.1.00'!$AL$4:$AN$55,2,FALSE))*IF('102 5.1.00'!AN$4="是",'102 5.1.00'!$AW$4,'102 5.1.00'!$AW$3) -> 0 | F15: =(VLOOKUP('102 5.1.00'!M15,'102 5.1.00'!$AL$4:$AN$55,2,FALSE))*IF('102 5.1.00'!AO$4="是",'102 5.1.00'!$AW$4,'102 5.1.00'!$AW$3) -> 0 | G15: =(VLOOKUP('102 5.1.00'!N15,'102 5.1.00'!$AL$4:$AN$55,2,FALSE))*IF('102 5.1.00'!AP$4="是",'102 5.1.00'!$AW$4,'102 5.1.00'!$AW$3) -> 0 | H15: =(VLOOKUP('102 5.1.00'!O15,'102 5.1.00'!$AL$4:$AN$55,2,FALSE))*IF('102 5.1.00'!AQ$4="是",'102 5.1.00'!$AW$4,'102 5.1.00'!$AW$3) -> 0 | ... X15: =(VLOOKUP('102 5.1.00'!AE15,'102 5.1.00'!$AL$4:$AN$55,2,FALSE))*IF('102 5.1.00'!BG$4="是",'102 5.1.00'!$AW$4,'102 5.1.00'!$AW$3) -> 0
... A94: =(VLOOKUP('102 5.1.00'!H94,'102 5.1.00'!$AL$4:$AN$55,2,FALSE))*IF('102 5.1.00'!AJ$4="是",'102 5.1.00'!$AW$4,'102 5.1.00'!$AW$3) -> 0 | B94: =(VLOOKUP('102 5.1.00'!I94,'102 5.1.00'!$AL$4:$AN$55,2,FALSE))*IF('102 5.1.00'!AK$4="是",'102 5.1.00'!$AW$4,'102 5.1.00'!$AW$3) -> 0 | C94: =(VLOOKUP('102 5.1.00'!J94,'102 5.1.00'!$AL$4:$AN$55,2,FALSE))*IF('102 5.1.00'!AL$4="是",'102 5.1.00'!$AW$4,'102 5.1.00'!$AW$3) -> 0 | D94: =(VLOOKUP('102 5.1.00'!K94,'102 5.1.00'!$AL$4:$AN$55,2,FALSE))*IF('102 5.1.00'!AM$4="是",'102 5.1.00'!$AW$4,'102 5.1.00'!$AW$3) -> 0 | E94: =(VLOOKUP('102 5.1.00'!L94,'102 5.1.00'!$AL$4:$AN$55,2,FALSE))*IF('102 5.1.00'!AN$4="是",'102 5.1.00'!$AW$4,'102 5.1.00'!$AW$3) -> 0 | F94: =(VLOOKUP('102 5.1.00'!M94,'102 5.1.00'!$AL$4:$AN$55,2,FALSE))*IF('102 5.1.00'!AO$4="是",'102 5.1.00'!$AW$4,'102 5.1.00'!$AW$3) -> 0 | G94: =(VLOOKUP('102 5.1.00'!N94,'102 5.1.00'!$AL$4:$AN$55,2,FALSE))*IF('102 5.1.00'!AP$4="是",'102 5.1.00'!$AW$4,'102 5.1.00'!$AW$3) -> 0 | H94: =(VLOOKUP('102 5.1.00'!O94,'102 5.1.00'!$AL$4:$AN$55,2,FALSE))*IF('102 5.1.00'!AQ$4="是",'102 5.1.00'!$AW$4,'102 5.1.00'!$AW$3) -> 0 | ... X94: =(VLOOKUP('102 5.1.00'!AE94,'102 5.1.00'!$AL$4:$AN$55,2,FALSE))*IF('102 5.1.00'!BG$4="是",'102 5.1.00'!$AW$4,'102 5.1.00'!$AW$3) -> 0

Sheet 经验
A2: 队伍一 风 | C2: 步数 | D2: =COUNTIF(A4:H94,"<>空") -> 728 | E2: (不算跳步和传送) | I2: 队伍二 雷 | K2: 步数 | L2: =COUNTIF(I4:P94,"<>空") -> 728 | M2: (不算跳步和传送) | Q2: 队伍三 | S2: 总步数 | T2: =COUNTIF(Q4:X94,"<>空") -> 728 | U2: (不算跳步和传送)
A3: 1 | B3: 2 | C3: 3 | D3: 4 | E3: 5 | F3: 6 | G3: 7 | H3: 8 | I3: 1 | J3: 2 | K3: 3 | L3: 4 | M3: 5 | N3: 6 | O3: 7 | P3: 8 | Q3: 1 | R3: 2 | S3: 3 | T3: 4 | U3: 5 | V3: 6 | W3: 7 | X3: 8
A4: =(VLOOKUP('102 5.1.00'!H4,'102 5.1.00'!$AL$4:$AN$55,3,FALSE)) -> 0 | B4: =(VLOOKUP('102 5.1.00'!I4,'102 5.1.00'!$AL$4:$AN$55,3,FALSE)) -> 0 | C4: =(VLOOKUP('102 5.1.00'!J4,'102 5.1.00'!$AL$4:$AN$55,3,FALSE)) -> 0 | D4: =(VLOOKUP('102 5.1.00'!K4,'102 5.1.00'!$AL$4:$AN$55,3,FALSE)) -> 0 | E4: =(VLOOKUP('102 5.1.00'!L4,'102 5.1.00'!$AL$4:$AN$55,3,FALSE)) -> 0 | F4: =(VLOOKUP('102 5.1.00'!M4,'102 5.1.00'!$AL$4:$AN$55,3,FALSE)) -> 0 | G4: =(VLOOKUP('102 5.1.00'!N4,'102 5.1.00'!$AL$4:$AN$55,3,FALSE)) -> 0 | H4: =(VLOOKUP('102 5.1.00'!O4,'102 5.1.00'!$AL$4:$AN$55,3,FALSE)) -> 0 | ... X4: =(VLOOKUP('102 5.1.00'!AE4,'102 5.1.00'!$AL$4:$AN$55,3,FALSE)) -> 0
A5: =(VLOOKUP('102 5.1.00'!H5,'102 5.1.00'!$AL$4:$AN$55,3,FALSE)) -> 0 | B5: =(VLOOKUP('102 5.1.00'!I5,'102 5.1.00'!$AL$4:$AN$55,3,FALSE)) -> 0 | C5: =(VLOOKUP('102 5.1.00'!J5,'102 5.1.00'!$AL$4:$AN$55,3,FALSE)) -> 0 | D5: =(VLOOKUP('102 5.1.00'!K5,'102 5.1.00'!$AL$4:$AN$55,3,FALSE)) -> 0 | E5: =(VLOOKUP('102 5.1.00'!L5,'102 5.1.00'!$AL$4:$AN$55,3,FALSE)) -> 0 | F5: =(VLOOKUP('102 5.1.00'!M5,'102 5.1.00'!$AL$4:$AN$55,3,FALSE)) -> 0 | G5: =(VLOOKUP('102 5.1.00'!N5,'102 5.1.00'!$AL$4:$AN$55,3,FALSE)) -> 0 | H5: =(VLOOKUP('102 5.1.00'!O5,'102 5.1.00'!$AL$4:$AN$55,3,FALSE)) -> 0 | ... X5: =(VLOOKUP('102 5.1.00'!AE5,'102 5.1.00'!$AL$4:$AN$55,3,FALSE)) -> 0
A6: =(VLOOKUP('102 5.1.00'!H6,'102 5.1.00'!$AL$4:$AN$55,3,FALSE)) -> 0 | B6: =(VLOOKUP('102 5.1.00'!I6,'102 5.1.00'!$AL$4:$AN$55,3,FALSE)) -> 0 | C6: =(VLOOKUP('102 5.1.00'!J6,'102 5.1.00'!$AL$4:$AN$55,3,FALSE)) -> 0 | D6: =(VLOOKUP('102 5.1.00'!K6,'102 5.1.00'!$AL$4:$AN$55,3,FALSE)) -> 0 | E6: =(VLOOKUP('102 5.1.00'!L6,'102 5.1.00'!$AL$4:$AN$55,3,FALSE)) -> 0 | F6: =(VLOOKUP('102 5.1.00'!M6,'102 5.1.00'!$AL$4:$AN$55,3,FALSE)) -> 0 | G6: =(VLOOKUP('102 5.1.00'!N6,'102 5.1.00'!$AL$4:$AN$55,3,FALSE)) -> 0 | H6: =(VLOOKUP('102 5.1.00'!O6,'102 5.1.00'!$AL$4:$AN$55,3,FALSE)) -> 0 | ... X6: =(VLOOKUP('102 5.1.00'!AE6,'102 5.1.00'!$AL$4:$AN$55,3,FALSE)) -> 0
A7: =(VLOOKUP('102 5.1.00'!H7,'102 5.1.00'!$AL$4:$AN$55,3,FALSE)) -> 0 | B7: =(VLOOKUP('102 5.1.00'!I7,'102 5.1.00'!$AL$4:$AN$55,3,FALSE)) -> 0 | C7: =(VLOOKUP('102 5.1.00'!J7,'102 5.1.00'!$AL$4:$AN$55,3,FALSE)) -> 0 | D7: =(VLOOKUP('102 5.1.00'!K7,'102 5.1.00'!$AL$4:$AN$55,3,FALSE)) -> 0 | E7: =(VLOOKUP('102 5.1.00'!L7,'102 5.1.00'!$AL$4:$AN$55,3,FALSE)) -> 0 | F7: =(VLOOKUP('102 5.1.00'!M7,'102 5.1.00'!$AL$4:$AN$55,3,FALSE)) -> 0 | G7: =(VLOOKUP('102 5.1.00'!N7,'102 5.1.00'!$AL$4:$AN$55,3,FALSE)) -> 0 | H7: =(VLOOKUP('102 5.1.00'!O7,'102 5.1.00'!$AL$4:$AN$55,3,FALSE)) -> 0 | ... X7: =(VLOOKUP('102 5.1.00'!AE7,'102 5.1.00'!$AL$4:$AN$55,3,FALSE)) -> 0
A8: =(VLOOKUP('102 5.1.00'!H8,'102 5.1.00'!$AL$4:$AN$55,3,FALSE)) -> 0 | B8: =(VLOOKUP('102 5.1.00'!I8,'102 5.1.00'!$AL$4:$AN$55,3,FALSE)) -> 0 | C8: =(VLOOKUP('102 5.1.00'!J8,'102 5.1.00'!$AL$4:$AN$55,3,FALSE)) -> 0 | D8: =(VLOOKUP('102 5.1.00'!K8,'102 5.1.00'!$AL$4:$AN$55,3,FALSE)) -> 0 | E8: =(VLOOKUP('102 5.1.00'!L8,'102 5.1.00'!$AL$4:$AN$55,3,FALSE)) -> 0 | F8: =(VLOOKUP('102 5.1.00'!M8,'102 5.1.00'!$AL$4:$AN$55,3,FALSE)) -> 0 | G8: =(VLOOKUP('102 5.1.00'!N8,'102 5.1.00'!$AL$4:$AN$55,3,FALSE)) -> 0 | H8: =(VLOOKUP('102 5.1.00'!O8,'102 5.1.00'!$AL$4:$AN$55,3,FALSE)) -> 0 | ... X8: =(VLOOKUP('102 5.1.00'!AE8,'102 5.1.00'!$AL$4:$AN$55,3,FALSE)) -> 0
A9: =(VLOOKUP('102 5.1.00'!H9,'102 5.1.00'!$AL$4:$AN$55,3,FALSE)) -> 0 | B9: =(VLOOKUP('102 5.1.00'!I9,'102 5.1.00'!$AL$4:$AN$55,3,FALSE)) -> 0 | C9: =(VLOOKUP('102 5.1.00'!J9,'102 5.1.00'!$AL$4:$AN$55,3,FALSE)) -> 0 | D9: =(VLOOKUP('102 5.1.00'!K9,'102 5.1.00'!$AL$4:$AN$55,3,FALSE)) -> 0 | E9: =(VLOOKUP('102 5.1.00'!L9,'102 5.1.00'!$AL$4:$AN$55,3,FALSE)) -> 0 | F9: =(VLOOKUP('102 5.1.00'!M9,'102 5.1.00'!$AL$4:$AN$55,3,FALSE)) -> 0 | G9: =(VLOOKUP('102 5.1.00'!N9,'102 5.1.00'!$AL$4:$AN$55,3,FALSE)) -> 0 | H9: =(VLOOKUP('102 5.1.00'!O9,'102 5.1.00'!$AL$4:$AN$55,3,FALSE)) -> 0 | ... X9: =(VLOOKUP('102 5.1.00'!AE9,'102 5.1.00'!$AL$4:$AN$55,3,FALSE)) -> 0
A10: =(VLOOKUP('102 5.1.00'!H10,'102 5.1.00'!$AL$4:$AN$55,3,FALSE)) -> 0 | B10: =(VLOOKUP('102 5.1.00'!I10,'102 5.1.00'!$AL$4:$AN$55,3,FALSE)) -> 0 | C10: =(VLOOKUP('102 5.1.00'!J10,'102 5.1.00'!$AL$4:$AN$55,3,FALSE)) -> 0 | D10: =(VLOOKUP('102 5.1.00'!K10,'102 5.1.00'!$AL$4:$AN$55,3,FALSE)) -> 0 | E10: =(VLOOKUP('102 5.1.00'!L10,'102 5.1.00'!$AL$4:$AN$55,3,FALSE)) -> 0 | F10: =(VLOOKUP('102 5.1.00'!M10,'102 5.1.00'!$AL$4:$AN$55,3,FALSE)) -> 0 | G10: =(VLOOKUP('102 5.1.00'!N10,'102 5.1.00'!$AL$4:$AN$55,3,FALSE)) -> 0 | H10: =(VLOOKUP('102 5.1.00'!O10,'102 5.1.00'!$AL$4:$AN$55,3,FALSE)) -> 0 | ... X10: =(VLOOKUP('102 5.1.00'!AE10,'102 5.1.00'!$AL$4:$AN$55,3,FALSE)) -> 0
A11: =(VLOOKUP('102 5.1.00'!H11,'102 5.1.00'!$AL$4:$AN$55,3,FALSE)) -> 0 | B11: =(VLOOKUP('102 5.1.00'!I11,'102 5.1.00'!$AL$4:$AN$55,3,FALSE)) -> 0 | C11: =(VLOOKUP('102 5.1.00'!J11,'102 5.1.00'!$AL$4:$AN$55,3,FALSE)) -> 0 | D11: =(VLOOKUP('102 5.1.00'!K11,'102 5.1.00'!$AL$4:$AN$55,3,FALSE)) -> 0 | E11: =(VLOOKUP('102 5.1.00'!L11,'102 5.1.00'!$AL$4:$AN$55,3,FALSE)) -> 0 | F11: =(VLOOKUP('102 5.1.00'!M11,'102 5.1.00'!$AL$4:$AN$55,3,FALSE)) -> 0 | G11: =(VLOOKUP('102 5.1.00'!N11,'102 5.1.00'!$AL$4:$AN$55,3,FALSE)) -> 0 | H11: =(VLOOKUP('102 5.1.00'!O11,'102 5.1.00'!$AL$4:$AN$55,3,FALSE)) -> 0 | ... X11: =(VLOOKUP('102 5.1.00'!AE11,'102 5.1.00'!$AL$4:$AN$55,3,FALSE)) -> 0
A12: =(VLOOKUP('102 5.1.00'!H12,'102 5.1.00'!$AL$4:$AN$55,3,FALSE)) -> 0 | B12: =(VLOOKUP('102 5.1.00'!I12,'102 5.1.00'!$AL$4:$AN$55,3,FALSE)) -> 0 | C12: =(VLOOKUP('102 5.1.00'!J12,'102 5.1.00'!$AL$4:$AN$55,3,FALSE)) -> 0 | D12: =(VLOOKUP('102 5.1.00'!K12,'102 5.1.00'!$AL$4:$AN$55,3,FALSE)) -> 0 | E12: =(VLOOKUP('102 5.1.00'!L12,'102 5.1.00'!$AL$4:$AN$55,3,FALSE)) -> 0 | F12: =(VLOOKUP('102 5.1.00'!M12,'102 5.1.00'!$AL$4:$AN$55,3,FALSE)) -> 0 | G12: =(VLOOKUP('102 5.1.00'!N12,'102 5.1.00'!$AL$4:$AN$55,3,FALSE)) -> 0 | H12: =(VLOOKUP('102 5.1.00'!O12,'102 5.1.00'!$AL$4:$AN$55,3,FALSE)) -> 0 | ... X12: =(VLOOKUP('102 5.1.00'!AE12,'102 5.1.00'!$AL$4:$AN$55,3,FALSE)) -> 0
A13: =(VLOOKUP('102 5.1.00'!H13,'102 5.1.00'!$AL$4:$AN$55,3,FALSE)) -> 0 | B13: =(VLOOKUP('102 5.1.00'!I13,'102 5.1.00'!$AL$4:$AN$55,3,FALSE)) -> 0 | C13: =(VLOOKUP('102 5.1.00'!J13,'102 5.1.00'!$AL$4:$AN$55,3,FALSE)) -> 0 | D13: =(VLOOKUP('102 5.1.00'!K13,'102 5.1.00'!$AL$4:$AN$55,3,FALSE)) -> 0 | E13: =(VLOOKUP('102 5.1.00'!L13,'102 5.1.00'!$AL$4:$AN$55,3,FALSE)) -> 0 | F13: =(VLOOKUP('102 5.1.00'!M13,'102 5.1.00'!$AL$4:$AN$55,3,FALSE)) -> 0 | G13: =(VLOOKUP('102 5.1.00'!N13,'102 5.1.00'!$AL$4:$AN$55,3,FALSE)) -> 0 | H13: =(VLOOKUP('102 5.1.00'!O13,'102 5.1.00'!$AL$4:$AN$55,3,FALSE)) -> 0 | ... X13: =(VLOOKUP('102 5.1.00'!AE13,'102 5.1.00'!$AL$4:$AN$55,3,FALSE)) -> 0
A14: =(VLOOKUP('102 5.1.00'!H14,'102 5.1.00'!$AL$4:$AN$55,3,FALSE)) -> 0 | B14: =(VLOOKUP('102 5.1.00'!I14,'102 5.1.00'!$AL$4:$AN$55,3,FALSE)) -> 0 | C14: =(VLOOKUP('102 5.1.00'!J14,'102 5.1.00'!$AL$4:$AN$55,3,FALSE)) -> 0 | D14: =(VLOOKUP('102 5.1.00'!K14,'102 5.1.00'!$AL$4:$AN$55,3,FALSE)) -> 0 | E14: =(VLOOKUP('102 5.1.00'!L14,'102 5.1.00'!$AL$4:$AN$55,3,FALSE)) -> 0 | F14: =(VLOOKUP('102 5.1.00'!M14,'102 5.1.00'!$AL$4:$AN$55,3,FALSE)) -> 0 | G14: =(VLOOKUP('102 5.1.00'!N14,'102 5.1.00'!$AL$4:$AN$55,3,FALSE)) -> 0 | H14: =(VLOOKUP('102 5.1.00'!O14,'102 5.1.00'!$AL$4:$AN$55,3,FALSE)) -> 0 | ... X14: =(VLOOKUP('102 5.1.00'!AE14,'102 5.1.00'!$AL$4:$AN$55,3,FALSE)) -> 0
A15: =(VLOOKUP('102 5.1.00'!H15,'102 5.1.00'!$AL$4:$AN$55,3,FALSE)) -> 0 | B15: =(VLOOKUP('102 5.1.00'!I15,'102 5.1.00'!$AL$4:$AN$55,3,FALSE)) -> 0 | C15: =(VLOOKUP('102 5.1.00'!J15,'102 5.1.00'!$AL$4:$AN$55,3,FALSE)) -> 0 | D15: =(VLOOKUP('102 5.1.00'!K15,'102 5.1.00'!$AL$4:$AN$55,3,FALSE)) -> 0 | E15: =(VLOOKUP('102 5.1.00'!L15,'102 5.1.00'!$AL$4:$AN$55,3,FALSE)) -> 0 | F15: =(VLOOKUP('102 5.1.00'!M15,'102 5.1.00'!$AL$4:$AN$55,3,FALSE)) -> 0 | G15: =(VLOOKUP('102 5.1.00'!N15,'102 5.1.00'!$AL$4:$AN$55,3,FALSE)) -> 0 | H15: =(VLOOKUP('102 5.1.00'!O15,'102 5.1.00'!$AL$4:$AN$55,3,FALSE)) -> 0 | ... X15: =(VLOOKUP('102 5.1.00'!AE15,'102 5.1.00'!$AL$4:$AN$55,3,FALSE)) -> 0
... A94: =(VLOOKUP('102 5.1.00'!H94,'102 5.1.00'!$AL$4:$AN$55,3,FALSE)) -> 0 | B94: =(VLOOKUP('102 5.1.00'!I94,'102 5.1.00'!$AL$4:$AN$55,3,FALSE)) -> 0 | C94: =(VLOOKUP('102 5.1.00'!J94,'102 5.1.00'!$AL$4:$AN$55,3,FALSE)) -> 0 | D94: =(VLOOKUP('102 5.1.00'!K94,'102 5.1.00'!$AL$4:$AN$55,3,FALSE)) -> 0 | E94: =(VLOOKUP('102 5.1.00'!L94,'102 5.1.00'!$AL$4:$AN$55,3,FALSE)) -> 0 | F94: =(VLOOKUP('102 5.1.00'!M94,'102 5.1.00'!$AL$4:$AN$55,3,FALSE)) -> 0 | G94: =(VLOOKUP('102 5.1.00'!N94,'102 5.1.00'!$AL$4:$AN$55,3,FALSE)) -> 0 | H94: =(VLOOKUP('102 5.1.00'!O94,'102 5.1.00'!$AL$4:$AN$55,3,FALSE)) -> 0 | ... X94: =(VLOOKUP('102 5.1.00'!AE94,'102 5.1.00'!$AL$4:$AN$55,3,FALSE)) -> 0
