Workbook

Sheet 9.0.10
A1: =(_xlfn.DAYS(TODAY(),A4)+2)/((_xlfn.DAYS(A94,A4))+1) -> 0.054945055 | I1: 工作区 | AM1: 使用方法：按自己规划的路线，将下表中的地块名复制粘贴至工作区。初次使用传送门，当天跳步次数+5。重复使用传送门，当天跳步次数+1
A2: version 9.0.10 | B2: 八卦前亏 | C2: =SUM(亏损!A4:X94)+SUM(AG4:AG14)*10 -> 29783.324 | D2: 合计经验 | F2: =SUM(F4:F94)+SUM(H4:H94) -> 65010 | I2: 队伍一 火 | K2: 步数 | L2: =COUNTIF(I4:P94,"<>空") -> 34 | M2: (不算跳步和传送) | Q2: 队伍二 雷 | S2: 步数 | T2: =COUNTIF(Q4:X94,"<>空") -> 557 | U2: (不算跳步和传送) | Y2: 队伍三 | AA2: 总步数 | AB2: =COUNTIF(Y4:AF94,"<>空") -> 484 | AC2: (不算跳步和传送) | AG2: =SUM(AG4:AG94) -> 32 | AH2: =SUM(AH4:AH94) -> 3 | AI2: =SUM(AI4:AI94) -> 15 | AJ2: =SUM(AJ4:AJ94) -> 14 | AK2: 八卦全开 | AS2: 总地块 | AT2: =SUM(AT4:AT29) -> 1075 | AV2: 总经验 | AW2: =SUM(AU4:AW29)+7000 -> 65010 | AY2: 粮草系数
A3: 日期 | B3: 获得粮草 | C3: 种植粮草 | D3: 消耗粮草 | E3: 剩余粮草 | F3: 获得经验 | G3: 累计经验 | H3: 任务经验 | I3: 1 | J3: 2 | K3: 3 | L3: 4 | M3: 5 | N3: 6 | O3: 7 | P3: 8 | Q3: 1 | R3: 2 | S3: 3 | T3: 4 | U3: 5 | V3: 6 | W3: 7 | X3: 8 | Y3: 1 | Z3: 2 | AA3: 3 | AB3: 4 | AC3: 5 | AD3: 6 | AE3: 7 | AF3: 8 | AG3: 跳步次数 | AH3: 1队跳步 | AI3: 2队跳步 | AJ3: 3队跳步 | AM3: 地块 | AN3: 粮草 | AO3: 经验 | AP3: 八卦前亏损 | AQ3: 一队地块 | AR3: 二队地块 | AS3: 三队地块 | AT3: 总地块 | AU3: 一队经验 | AV3: 二队经验 | AW3: 三队经验 | AX3: 八卦前 | AY3: 1
A4: 44820 | B4: 800 | C4: 6000 | D4: =(SUM(粮草!A4:X4)+AG4*10)*IF(AK4="是",$AY$4,$AY$3) -> 2930 | E4: =SUM($B$4:B4)+SUM($C$4:C4)-SUM($D$4:D4) -> 3870 | F4: =SUM(经验!A4:X4) -> 1355 | G4: =SUM($F$4:F4)+SUM($H$4:H4) -> 1855 | H4: 500 | I4: 1级 | J4: 1级 | K4: 1级 | L4: 1级 | M4: 1级 | N4: 1级 | O4: 空 | P4: 空 | Q4: 1级 | R4: 1级 | S4: 1级 | T4: 1级 | U4: 1级 | V4: 1级 | W4: 空 | X4: 空 | Y4: 2级 | Z4: 历练 | AA4: 2级 | AB4: 3级 | AC4: 3级 | AD4: 大卦 | AE4: 3级 | AF4: 空 | AG4: =AH4+AI4+AJ4 -> 0 | AK4: 否 | AM4: 1级 | AN4: 150 | AO4: 35 | AP4: 44.222109 | AQ4: =COUNTIF($I$4:$P$94,AM4) -> 14 | AR4: =COUNTIF($Q$4:$X$94,AM4) -> 7 | AS4: =COUNTIF($Y$4:$AF$94,AM4) -> 4 | AT4: =AQ4+AR4+AS4 -> 25 | AU4: =AQ4*$AO4 -> 490 | AV4: =AR4*$AO4 -> 245 | AW4: =AS4*$AO4 -> 140 | AX4: 八卦后 | AY4: 0.8 | BA4: =AN4*0.8 -> 120
A5: 44821 | B5: 1600 | D5: =(SUM(粮草!A5:X5)+AG5*10)*IF(AK5="是",$AY$4,$AY$3) -> 1770 | E5: =SUM($B$4:B5)+SUM($C$4:C5)-SUM($D$4:D5) -> 3700 | F5: =SUM(经验!A5:X5) -> 510 | G5: =SUM($F$4:F5)+SUM($H$4:H5) -> 2365 | H5: 0 | I5: 空 | J5: 空 | K5: 空 | L5: 空 | M5: 空 | N5: 空 | O5: 空 | P5: 空 | Q5: 3级 | R5: 3级 | S5: 3级 | T5: 3级 | U5: 商人 | V5: 3级 | W5: 空 | X5: 空 | Y5: 3级 | Z5: 商人 | AA5: 2级 | AB5: 营地 | AC5: 1级 | AD5: 1级 | AE5: 1级 | AF5: 1级 | AG5: =AH5+AI5+AJ5 -> 4 | AI5: 4 | AK5: 否 | AM5: 2级 | AN5: 160 | AO5: 40 | AP5: 39.110982 | AQ5: =COUNTIF($I$4:$P$94,AM5) -> 6 | AR5: =COUNTIF($Q$4:$X$94,AM5) -> 15 | AS5: =COUNTIF($Y$4:$AF$94,AM5) -> 19 | AT5: =AQ5+AR5+AS5 -> 40 | AU5: =AQ5*$AO5 -> 240 | AV5: =AR5*$AO5 -> 600 | AW5: =AS5*$AO5 -> 760 | AX5: Note：开完八卦当天可能需要手动计算粮草 | BA5: =AN5*0.8 -> 128
A6: 44822 | B6: 1600 | D6: =(SUM(粮草!A6:X6)+AG6*10)*IF(AK6="是",$AY$4,$AY$3) -> 1950 | E6: =SUM($B$4:B6)+SUM($C$4:C6)-SUM($D$4:D6) -> 3350 | F6: =SUM(经验!A6:X6) -> 525 | G6: =SUM($F$4:F6)+SUM($H$4:H6) -> 2890 | H6: 0 | I6: 空 | J6: 空 | K6: 空 | L6: 空 | M6: 空 | N6: 空 | O6: 空 | P6: 空 | Q6: 小卦 | R6: 3级 | S6: 2级 | T6: 2级 | U6: 2级 | V6: 2级 | W6: 空 | X6: 空 | Y6: 商人 | Z6: 2级 | AA6: 2级 | AB6: 2级 | AC6: 营地 | AD6: 2级 | AE6: 2级 | AF6: 3级 | AG6: =AH6+AI6+AJ6 -> 10 | AI6: 5 | AJ6: 5 | AK6: 否 | AM6: 3级 | AN6: 170 | AO6: 45 | AP6: 34 | AQ6: =COUNTIF($I$4:$P$94,AM6) -> 6 | AR6: =COUNTIF($Q$4:$X$94,AM6) -> 75 | AS6: =COUNTIF($Y$4:$AF$94,AM6) -> 146 | AT6: =AQ6+AR6+AS6 -> 227 | AU6: =AQ6*$AO6 -> 270 | AV6: =AR6*$AO6 -> 3375 | AW6: =AS6*$AO6 -> 6570 | BA6: =AN6*0.8 -> 136
A7: 44823 | B7: 1600 | D7: =(SUM(粮草!A7:X7)+AG7*10)*IF(AK7="是",$AY$4,$AY$3) -> 1940 | E7: =SUM($B$4:B7)+SUM($C$4:C7)-SUM($D$4:D7) -> 3010 | F7: =SUM(经验!A7:X7) -> 495 | G7: =SUM($F$4:F7)+SUM($H$4:H7) -> 3585 | H7: 200 | I7: 空 | J7: 空 | K7: 空 | L7: 空 | M7: 空 | N7: 空 | O7: 空 | P7: 空 | Q7: 2级 | R7: 2级 | S7: 商人 | T7: 2级 | U7: 2级 | V7: 2级 | W7: 空 | X7: 空 | Y7: 3级 | Z7: 3级 | AA7: 3级 | AB7: 3级 | AC7: 小卦 | AD7: 2级 | AE7: 空 | AF7: 空 | AG7: =AH7+AI7+AJ7 -> 8 | AJ7: 8 | AK7: 否 | AM7: 4级 | AN7: 180 | AO7: 50 | AP7: 36 | AQ7: =COUNTIF($I$4:$P$94,AM7) -> 0 | AR7: =COUNTIF($Q$4:$X$94,AM7) -> 173 | AS7: =COUNTIF($Y$4:$AF$94,AM7) -> 93 | AT7: =AQ7+AR7+AS7 -> 266 | AU7: =AQ7*$AO7 -> 0 | AV7: =AR7*$AO7 -> 8650 | AW7: =AS7*$AO7 -> 4650 | BA7: =AN7*0.8 -> 144
A8: 44824 | B8: 1600 | D8: =(SUM(粮草!A8:X8)+AG8*10)*IF(AK8="是",$AY$4,$AY$3) -> 1720 | E8: =SUM($B$4:B8)+SUM($C$4:C8)-SUM($D$4:D8) -> 2890 | F8: =SUM(经验!A8:X8) -> 470 | G8: =SUM($F$4:F8)+SUM($H$4:H8) -> 4155 | H8: 100 | I8: 空 | J8: 空 | K8: 空 | L8: 空 | M8: 空 | N8: 空 | O8: 空 | P8: 空 | Q8: 2级 | R8: 商人 | S8: 2级 | T8: 3级 | U8: 1级 | V8: 3级 | W8: 空 | X8: 空 | Y8: 2级 | Z8: 2级 | AA8: 商人 | AB8: 2级 | AC8: 2级 | AD8: 3级 | AE8: 空 | AF8: 空 | AG8: =AH8+AI8+AJ8 -> 0 | AK8: 否 | AM8: 5级 | AN8: 190 | AO8: 55 | AP8: 38 | AQ8: =COUNTIF($I$4:$P$94,AM8) -> 0 | AR8: =COUNTIF($Q$4:$X$94,AM8) -> 76 | AS8: =COUNTIF($Y$4:$AF$94,AM8) -> 160 | AT8: =AQ8+AR8+AS8 -> 236 | AU8: =AQ8*$AO8 -> 0 | AV8: =AR8*$AO8 -> 4180 | AW8: =AS8*$AO8 -> 8800 | BA8: =AN8*0.8 -> 152
A9: 44825 | B9: 1600 | D9: =(SUM(粮草!A9:X9)+AG9*10)*IF(AK9="是",$AY$4,$AY$3)-50 -> 2150 | E9: =SUM($B$4:B9)+SUM($C$4:C9)-SUM($D$4:D9) -> 2340 | F9: =SUM(经验!A9:X9) -> 845 | G9: =SUM($F$4:F9)+SUM($H$4:H9) -> 5200 | H9: 200 | I9: 空 | J9: 空 | K9: 空 | L9: 空 | M9: 空 | N9: 空 | O9: 空 | P9: 空 | Q9: 小卦 | R9: 3级 | S9: 3级 | T9: 3级 | U9: 大卦 | V9: 3级 | W9: 空 | X9: 空 | Y9: 3级 | Z9: 塔2 | AA9: 3级 | AB9: 大卦 | AC9: 3级 | AD9: 3级 | AE9: 空 | AF9: 空 | AG9: =AH9+AI9+AJ9 -> 2 | AI9: 2 | AK9: 否 | AM9: 6级 | AN9: 200 | AO9: 60 | AQ9: =COUNTIF($I$4:$P$94,AM9) -> 0 | AR9: =COUNTIF($Q$4:$X$94,AM9) -> 171 | AS9: =COUNTIF($Y$4:$AF$94,AM9) -> 23 | AT9: =AQ9+AR9+AS9 -> 194 | AU9: =AQ9*$AO9 -> 0 | AV9: =AR9*$AO9 -> 10260 | AW9: =AS9*$AO9 -> 1380 | BA9: =AN9*0.8 -> 160
A10: 44826 | B10: 1600 | D10: =(SUM(粮草!A10:X10)+AG10*10)*IF(AK10="是",$AY$4,$AY$3) -> 1680 | E10: =SUM($B$4:B10)+SUM($C$4:C10)-SUM($D$4:D10) -> 2260 | F10: =SUM(经验!A10:X10) -> 475 | G10: =SUM($F$4:F10)+SUM($H$4:H10) -> 5675 | H10: 0 | I10: 空 | J10: 空 | K10: 空 | L10: 空 | M10: 空 | N10: 空 | O10: 空 | P10: 空 | Q10: 2级 | R10: 2级 | S10: 2级 | T10: 2级 | U10: 3级 | V10: 3级 | W10: 空 | X10: 空 | Y10: 3级 | Z10: 3级 | AA10: 营地 | AB10: 3级 | AC10: 3级 | AD10: 小卦 | AE10: 空 | AF10: 空 | AG10: =AH10+AI10+AJ10 -> 0 | AK10: 否 | AM10: 塔1 | AN10: 150 | AO10: 35 | AP10: 44.222109 | AQ10: =COUNTIF($I$4:$P$94,AM10) -> 0 | AR10: =COUNTIF($Q$4:$X$94,AM10) -> 0 | AS10: =COUNTIF($Y$4:$AF$94,AM10) -> 0 | AT10: =AQ10+AR10+AS10 -> 0 | AU10: =AQ10*$AO10 -> 0 | AV10: =AR10*$AO10 -> 0 | AW10: =AS10*$AO10 -> 0 | BA10: =AN10*0.8 -> 120
A11: 44827 | B11: 1600 | D11: =(SUM(粮草!A11:X11)+AG11*10)*IF(AK11="是",$AY$4,$AY$3)-132 -> 868 | E11: =SUM($B$4:B11)+SUM($C$4:C11)-SUM($D$4:D11) -> 2992 | F11: =SUM(经验!A11:X11) -> 265 | G11: =SUM($F$4:F11)+SUM($H$4:H11) -> 5940 | H11: 0 | I11: 空 | J11: 空 | K11: 空 | L11: 空 | M11: 空 | N11: 空 | O11: 空 | P11: 空 | Q11: 3级 | R11: 小卦 | S11: 3级 | T11: 3级 | U11: 3级 | V11: 塔2 | W11: 空 | X11: 空 | Y11: 空 | Z11: 空 | AA11: 空 | AB11: 空 | AC11: 空 | AD11: 空 | AE11: 空 | AF11: 空 | AG11: =AH11+AI11+AJ11 -> 0 | AK11: 否 | AM11: 塔2 | AN11: 150 | AO11: 40 | AP11: 29.110982 | AQ11: =COUNTIF($I$4:$P$94,AM11) -> 1 | AR11: =COUNTIF($Q$4:$X$94,AM11) -> 1 | AS11: =COUNTIF($Y$4:$AF$94,AM11) -> 1 | AT11: =AQ11+AR11+AS11 -> 3 | AU11: =AQ11*$AO11 -> 40 | AV11: =AR11*$AO11 -> 40 | AW11: =AS11*$AO11 -> 40 | BA11: =AN11*0.8 -> 120
A12: 44828 | B12: 1600 | D12: =(SUM(粮草!A12:X12)+AG12*10)*IF(AK12="是",$AY$4,$AY$3) -> 1536 | E12: =SUM($B$4:B12)+SUM($C$4:C12)-SUM($D$4:D12) -> 3056 | F12: =SUM(经验!A12:X12) -> 525 | G12: =SUM($F$4:F12)+SUM($H$4:H12) -> 6465 | H12: 0 | I12: 空 | J12: 空 | K12: 空 | L12: 空 | M12: 空 | N12: 空 | O12: 空 | P12: 空 | Q12: 3级 | R12: 3级 | S12: 商人 | T12: 3级 | U12: 3级 | V12: 3级 | W12: 空 | X12: 空 | Y12: 3级 | Z12: 3级 | AA12: 3级 | AB12: 3级 | AC12: 3级 | AD12: 3级 | AE12: 空 | AF12: 空 | AG12: =AH12+AI12+AJ12 -> 0 | AK12: 是 | AM12: 塔3 | AN12: 150 | AO12: 45 | AP12: 13.999855 | AQ12: =COUNTIF($I$4:$P$94,AM12) -> 0 | AR12: =COUNTIF($Q$4:$X$94,AM12) -> 3 | AS12: =COUNTIF($Y$4:$AF$94,AM12) -> 3 | AT12: =AQ12+AR12+AS12 -> 6 | AU12: =AQ12*$AO12 -> 0 | AV12: =AR12*$AO12 -> 135 | AW12: =AS12*$AO12 -> 135 | BA12: =AN12*0.8 -> 120
A13: 44829 | B13: 1600 | D13: =(SUM(粮草!A13:X13)+AG13*10)*IF(AK13="是",$AY$4,$AY$3) -> 1496 | E13: =SUM($B$4:B13)+SUM($C$4:C13)-SUM($D$4:D13) -> 3160 | F13: =SUM(经验!A13:X13) -> 495 | G13: =SUM($F$4:F13)+SUM($H$4:H13) -> 6960 | H13: 0 | I13: 空 | J13: 空 | K13: 空 | L13: 空 | M13: 空 | N13: 空 | O13: 空 | P13: 空 | Q13: 3级 | R13: 3级 | S13: 3级 | T13: 3级 | U13: 3级 | V13: 空 | W13: 空 | X13: 空 | Y13: 3级 | Z13: 3级 | AA13: 3级 | AB13: 3级 | AC13: 3级 | AD13: 3级 | AE13: 空 | AF13: 空 | AG13: =AH13+AI13+AJ13 -> 0 | AK13: 是 | AM13: 塔4 | AN13: 150 | AO13: 50 | AQ13: =COUNTIF($I$4:$P$94,AM13) -> 0 | AR13: =COUNTIF($Q$4:$X$94,AM13) -> 3 | AS13: =COUNTIF($Y$4:$AF$94,AM13) -> 1 | AT13: =AQ13+AR13+AS13 -> 4 | AU13: =AQ13*$AO13 -> 0 | AV13: =AR13*$AO13 -> 150 | AW13: =AS13*$AO13 -> 50 | BA13: =AN13*0.8 -> 120
A14: 44830 | B14: 1600 | D14: =(SUM(粮草!A14:X14)+AG14*10)*IF(AK14="是",$AY$4,$AY$3) -> 1408 | E14: =SUM($B$4:B14)+SUM($C$4:C14)-SUM($D$4:D14) -> 3352 | F14: =SUM(经验!A14:X14) -> 480 | G14: =SUM($F$4:F14)+SUM($H$4:H14) -> 7740 | H14: 300 | I14: 空 | J14: 空 | K14: 空 | L14: 空 | M14: 空 | N14: 空 | O14: 空 | P14: 空 | Q14: 商人 | R14: 3级 | S14: 3级 | T14: 3级 | U14: 3级 | V14: 空 | W14: 空 | X14: 空 | Y14: 3级 | Z14: 3级 | AA14: 3级 | AB14: 3级 | AC14: 3级 | AD14: 3级 | AE14: 空 | AF14: 空 | AG14: =AH14+AI14+AJ14 -> 1 | AI14: 1 | AK14: 是 | AM14: 塔5 | AN14: 150 | AO14: 55 | AQ14: =COUNTIF($I$4:$P$94,AM14) -> 0 | AR14: =COUNTIF($Q$4:$X$94,AM14) -> 1 | AS14: =COUNTIF($Y$4:$AF$94,AM14) -> 2 | AT14: =AQ14+AR14+AS14 -> 3 | AU14: =AQ14*$AO14 -> 0 | AV14: =AR14*$AO14 -> 55 | AW14: =AS14*$AO14 -> 110 | BA14: =AN14*0.8 -> 120
A15: 44831 | B15: 1600 | D15: =(SUM(粮草!A15:X15)+AG15*10)*IF(AK15="是",$AY$4,$AY$3) -> 1552 | E15: =SUM($B$4:B15)+SUM($C$4:C15)-SUM($D$4:D15) -> 3400 | F15: =SUM(经验!A15:X15) -> 525 | G15: =SUM($F$4:F15)+SUM($H$4:H15) -> 8265 | H15: 0 | I15: 空 | J15: 空 | K15: 空 | L15: 空 | M15: 空 | N15: 空 | O15: 空 | P15: 空 | Q15: 3级 | R15: 3级 | S15: 3级 | T15: 3级 | U15: 3级 | V15: 3级 | W15: 空 | X15: 空 | Y15: 3级 | Z15: 3级 | AA15: 商人 | AB15: 3级 | AC15: 3级 | AD15: 3级 | AE15: 空 | AF15: 空 | AG15: =AH15+AI15+AJ15 -> 2 | AI15: 2 | AK15: 是 | AM15: 塔6 | AN15: 150 | AO15: 60 | AQ15: =COUNTIF($I$4:$P$94,AM15) -> 0 | AR15: =COUNTIF($Q$4:$X$94,AM15) -> 0 | AS15: =COUNTIF($Y$4:$AF$94,AM15) -> 1 | AT15: =AQ15+AR15+AS15 -> 1 | AU15: =AQ15*$AO15 -> 0 | AV15: =AR15*$AO15 -> 0 | AW15: =AS15*$AO15 -> 60 | BA15: =AN15*0.8 -> 120
A16: 44832 | B16: 1600 | D16: =(SUM(粮草!A16:X16)+AG16*10)*IF(AK16="是",$AY$4,$AY$3) -> 1512 | E16: =SUM($B$4:B16)+SUM($C$4:C16)-SUM($D$4:D16) -> 3488 | F16: =SUM(经验!A16:X16) -> 570 | G16: =SUM($F$4:F16)+SUM($H$4:H16) -> 9035 | H16: 200 | I16: 空 | J16: 空 | K16: 空 | L16: 空 | M16: 空 | N16: 空 | O16: 空 | P16: 空 | Q16: 3级 | R16: 3级 | S16: 营地+ | T16: 3级 | U16: 商人 | V16: 3级 | W16: 3级 | X16: 3级 | Y16: 3级 | Z16: 3级 | AA16: 3级 | AB16: 3级 | AC16: 3级 | AD16: 3级 | AE16: 空 | AF16: 空 | AG16: =AH16+AI16+AJ16 -> 0 | AK16: 是 | AM16: 遗迹 | AN16: 150 | AO16: 35 | AP16: 44.222109 | AQ16: =COUNTIF($I$4:$P$94,AM16) -> 0 | AR16: =COUNTIF($Q$4:$X$94,AM16) -> 0 | AS16: =COUNTIF($Y$4:$AF$94,AM16) -> 0 | AT16: =AQ16+AR16+AS16 -> 0 | AU16: =AQ16*$AO16 -> 0 | AV16: =AR16*$AO16 -> 0 | AW16: =AS16*$AO16 -> 0 | BA16: =AN16*0.8 -> 120
A17: 44833 | B17: 1600 | D17: =(SUM(粮草!A17:X17)+AG17*10)*IF(AK17="是",$AY$4,$AY$3) -> 1520 | E17: =SUM($B$4:B17)+SUM($C$4:C17)-SUM($D$4:D17) -> 3568 | F17: =SUM(经验!A17:X17) -> 525 | G17: =SUM($F$4:F17)+SUM($H$4:H17) -> 9560 | H17: 0 | I17: 空 | J17: 空 | K17: 空 | L17: 空 | M17: 空 | N17: 空 | O17: 空 | P17: 空 | Q17: 3级 | R17: 3级 | S17: 塔3 | T17: 3级 | U17: 3级 | V17: 商人 | W17: 空 | X17: 空 | Y17: 3级 | Z17: 3级 | AA17: 3级 | AB17: 3级 | AC17: 3级 | AD17: 3级 | AE17: 空 | AF17: 空 | AG17: =AH17+AI17+AJ17 -> 0 | AK17: 是 | AM17: 商人 | AN17: 50 | AO17: 30 | AP17: 10 | AQ17: =COUNTIF($I$4:$P$94,AM17) -> 6 | AR17: =COUNTIF($Q$4:$X$94,AM17) -> 18 | AS17: =COUNTIF($Y$4:$AF$94,AM17) -> 16 | AT17: =AQ17+AR17+AS17 -> 40 | AU17: =AQ17*$AO17 -> 180 | AV17: =AR17*$AO17 -> 540 | AW17: =AS17*$AO17 -> 480 | BA17: =AN17*0.8 -> 40
A18: 44834 | B18: 1600 | D18: =(SUM(粮草!A18:X18)+AG18*10)*IF(AK18="是",$AY$4,$AY$3) -> 1568 | E18: =SUM($B$4:B18)+SUM($C$4:C18)-SUM($D$4:D18) -> 3600 | F18: =SUM(经验!A18:X18) -> 545 | G18: =SUM($F$4:F18)+SUM($H$4:H18) -> 10105 | H18: 0 | I18: 空 | J18: 空 | K18: 空 | L18: 空 | M18: 空 | N18: 空 | O18: 空 | P18: 空 | Q18: 3级 | R18: 3级 | S18: 4级 | T18: 4级 | U18: 4级 | V18: 4级 | W18: 空 | X18: 空 | Y18: 3级 | Z18: 3级 | AA18: 3级 | AB18: 商人 | AC18: 3级 | AD18: 3级 | AE18: 空 | AF18: 空 | AG18: =AH18+AI18+AJ18 -> 0 | AK18: 是 | AL18: 八卦前 | AM18: 营地 | AN18: -150 | AO18: 0 | AP18: 10 | AQ18: =COUNTIF($I$4:$P$94,AM18) -> 0 | AR18: =COUNTIF($Q$4:$X$94,AM18) -> 0 | AS18: =COUNTIF($Y$4:$AF$94,AM18) -> 3 | AT18: =AQ18+AR18+AS18 -> 3 | AU18: =AQ18*$AO18 -> 0 | AV18: =AR18*$AO18 -> 0 | AW18: =AS18*$AO18 -> 0 | BA18: =AN18*0.8 -> -120
A19: 44835 | B19: 1600 | D19: =(SUM(粮草!A19:X19)+AG19*10)*IF(AK19="是",$AY$4,$AY$3) -> 1680 | E19: =SUM($B$4:B19)+SUM($C$4:C19)-SUM($D$4:D19) -> 3520 | F19: =SUM(经验!A19:X19) -> 570 | G19: =SUM($F$4:F19)+SUM($H$4:H19) -> 10675 | H19: 0 | I19: 空 | J19: 空 | K19: 空 | L19: 空 | M19: 空 | N19: 空 | O19: 空 | P19: 空 | Q19: 4级 | R19: 4级 | S19: 4级 | T19: 4级 | U19: 4级 | V19: 4级 | W19: 空 | X19: 空 | Y19: 3级 | Z19: 3级 | AA19: 3级 | AB19: 3级 | AC19: 3级 | AD19: 3级 | AE19: 空 | AF19: 空 | AG19: =AH19+AI19+AJ19 -> 0 | AK19: 是 | AM19: 大卦 | AN19: 250 | AO19: 200 | AQ19: =COUNTIF($I$4:$P$94,AM19) -> 0 | AR19: =COUNTIF($Q$4:$X$94,AM19) -> 1 | AS19: =COUNTIF($Y$4:$AF$94,AM19) -> 2 | AT19: =AQ19+AR19+AS19 -> 3 | AU19: =AQ19*$AO19 -> 0 | AV19: =AR19*$AO19 -> 200 | AW19: =AS19*$AO19 -> 400 | BA19: =AN19*0.8 -> 200
A20: 44836 | B20: 1600 | D20: =(SUM(粮草!A20:X20)+AG20*10)*IF(AK20="是",$AY$4,$AY$3) -> 1584 | E20: =SUM($B$4:B20)+SUM($C$4:C20)-SUM($D$4:D20) -> 3536 | F20: =SUM(经验!A20:X20) -> 555 | G20: =SUM($F$4:F20)+SUM($H$4:H20) -> 11230 | H20: 0 | I20: 空 | J20: 空 | K20: 空 | L20: 空 | M20: 空 | N20: 空 | O20: 空 | P20: 空 | Q20: 4级 | R20: 4级 | S20: 4级 | T20: 4级 | U20: 4级 | V20: 4级 | W20: 空 | X20: 空 | Y20: 3级 | Z20: 3级 | AA20: 3级 | AB20: 商人 | AC20: 3级 | AD20: 3级 | AE20: 空 | AF20: 空 | AG20: =AH20+AI20+AJ20 -> 0 | AK20: 是 | AM20: 小卦 | AN20: 170 | AO20: 45 | AQ20: =COUNTIF($I$4:$P$94,AM20) -> 0 | AR20: =COUNTIF($Q$4:$X$94,AM20) -> 3 | AS20: =COUNTIF($Y$4:$AF$94,AM20) -> 2 | AT20: =AQ20+AR20+AS20 -> 5 | AU20: =AQ20*$AO20 -> 0 | AV20: =AR20*$AO20 -> 135 | AW20: =AS20*$AO20 -> 90 | BA20: =AN20*0.8 -> 136
A21: 44837 | B21: 1600 | D21: =(SUM(粮草!A21:X21)+AG21*10)*IF(AK21="是",$AY$4,$AY$3) -> 1560 | E21: =SUM($B$4:B21)+SUM($C$4:C21)-SUM($D$4:D21) -> 3576 | F21: =SUM(经验!A21:X21) -> 600 | G21: =SUM($F$4:F21)+SUM($H$4:H21) -> 12030 | H21: 200 | I21: 空 | J21: 空 | K21: 空 | L21: 空 | M21: 空 | N21: 空 | O21: 空 | P21: 空 | Q21: 4级 | R21: 4级 | S21: 4级 | T21: 4级 | U21: 4级 | V21: 营地+ | W21: 4级 | X21: 商人 | Y21: 3级 | Z21: 3级 | AA21: 3级 | AB21: 3级 | AC21: 3级 | AD21: 3级 | AE21: 空 | AF21: 空 | AG21: =AH21+AI21+AJ21 -> 0 | AK21: 是 | AM21: 小boss | AN21: 250 | AO21: 200 | AQ21: =COUNTIF($I$4:$P$94,AM21) -> 0 | AR21: =COUNTIF($Q$4:$X$94,AM21) -> 0 | AS21: =COUNTIF($Y$4:$AF$94,AM21) -> 0 | AT21: =AQ21+AR21+AS21 -> 0 | AU21: =AQ21*$AO21 -> 0 | AV21: =AR21*$AO21 -> 0 | AW21: =AS21*$AO21 -> 0 | BA21: =AN21*0.8 -> 200
A22: 44838 | B22: 1600 | D22: =(SUM(粮草!A22:X22)+AG22*10)*IF(AK22="是",$AY$4,$AY$3) -> 1680 | E22: =SUM($B$4:B22)+SUM($C$4:C22)-SUM($D$4:D22) -> 3496 | F22: =SUM(经验!A22:X22) -> 570 | G22: =SUM($F$4:F22)+SUM($H$4:H22) -> 12700 | H22: 100 | I22: 空 | J22: 空 | K22: 空 | L22: 空 | M22: 空 | N22: 空 | O22: 空 | P22: 空 | Q22: 4级 | R22: 4级 | S22: 4级 | T22: 4级 | U22: 4级 | V22: 4级 | W22: 空 | X22: 空 | Y22: 3级 | Z22: 3级 | AA22: 3级 | AB22: 3级 | AC22: 3级 | AD22: 3级 | AE22: 空 | AF22: 空 | AG22: =AH22+AI22+AJ22 -> 0 | AK22: 是 | AM22: 大boss | AN22: 250 | AO22: 1000 | AQ22: =COUNTIF($I$4:$P$94,AM22) -> 0 | AR22: =COUNTIF($Q$4:$X$94,AM22) -> 2 | AS22: =COUNTIF($Y$4:$AF$94,AM22) -> 0 | AT22: =AQ22+AR22+AS22 -> 2 | AU22: =AQ22*$AO22 -> 0 | AV22: =AR22*$AO22 -> 2000 | AW22: =AS22*$AO22 -> 0 | BA22: =AN22*0.8 -> 200
A23: 44839 | B23: 1600 | D23: =(SUM(粮草!A23:X23)+AG23*10)*IF(AK23="是",$AY$4,$AY$3) -> 1656 | E23: =SUM($B$4:B23)+SUM($C$4:C23)-SUM($D$4:D23) -> 3440 | F23: =SUM(经验!A23:X23) -> 555 | G23: =SUM($F$4:F23)+SUM($H$4:H23) -> 13455 | H23: 200 | I23: 空 | J23: 空 | K23: 空 | L23: 空 | M23: 空 | N23: 空 | O23: 空 | P23: 空 | Q23: 4级 | R23: 4级 | S23: 4级 | T23: 3级 | U23: 3级 | V23: 3级 | W23: 空 | X23: 空 | Y23: 3级 | Z23: 3级 | AA23: 3级 | AB23: 3级 | AC23: 3级 | AD23: 3级 | AE23: 空 | AF23: 空 | AG23: =AH23+AI23+AJ23 -> 0 | AK23: 是 | AM23: 中boss | AN23: 250 | AO23: 500 | AQ23: =COUNTIF($I$4:$P$94,AM23) -> 0 | AR23: =COUNTIF($Q$4:$X$94,AM23) -> 1 | AS23: =COUNTIF($Y$4:$AF$94,AM23) -> 1 | AT23: =AQ23+AR23+AS23 -> 2 | AU23: =AQ23*$AO23 -> 0 | AV23: =AR23*$AO23 -> 500 | AW23: =AS23*$AO23 -> 500 | BA23: =AN23*0.8 -> 200
A24: 44840 | B24: 1600 | D24: =(SUM(粮草!A24:X24)+AG24*10)*IF(AK24="是",$AY$4,$AY$3) -> 1520 | E24: =SUM($B$4:B24)+SUM($C$4:C24)-SUM($D$4:D24) -> 3520 | F24: =SUM(经验!A24:X24) -> 525 | G24: =SUM($F$4:F24)+SUM($H$4:H24) -> 13980 | H24: 0 | I24: 空 | J24: 空 | K24: 空 | L24: 空 | M24: 空 | N24: 空 | O24: 空 | P24: 空 | Q24: 3级 | R24: 3级 | S24: 商人 | T24: 3级 | U24: 3级 | V24: 3级 | W24: 空 | X24: 空 | Y24: 塔3 | Z24: 3级 | AA24: 3级 | AB24: 3级 | AC24: 3级 | AD24: 3级 | AE24: 空 | AF24: 空 | AG24: =AH24+AI24+AJ24 -> 0 | AK24: 是 | AM24: 奈良 | AN24: 160 | AO24: 40 | AP24: 39.110982 | AQ24: =COUNTIF($I$4:$P$94,AM24) -> 0 | AR24: =COUNTIF($Q$4:$X$94,AM24) -> 0 | AS24: =COUNTIF($Y$4:$AF$94,AM24) -> 0 | AT24: =AQ24+AR24+AS24 -> 0 | AU24: =AQ24*$AO24 -> 0 | AV24: =AR24*$AO24 -> 0 | AW24: =AS24*$AO24 -> 0 | BA24: =AN24*0.8 -> 128
A25: 44841 | B25: 1600 | D25: =(SUM(粮草!A25:X25)+AG25*10)*IF(AK25="是",$AY$4,$AY$3) -> 1528 | E25: =SUM($B$4:B25)+SUM($C$4:C25)-SUM($D$4:D25) -> 3592 | F25: =SUM(经验!A25:X25) -> 580 | G25: =SUM($F$4:F25)+SUM($H$4:H25) -> 14560 | H25: 0 | I25: 空 | J25: 空 | K25: 空 | L25: 空 | M25: 空 | N25: 空 | O25: 空 | P25: 空 | Q25: 3级 | R25: 3级 | S25: 3级 | T25: 营地+ | U25: 4级 | V25: 4级 | W25: 4级 | X25: 4级 | Y25: 商人 | Z25: 3级 | AA25: 3级 | AB25: 3级 | AC25: 2级 | AD25: 2级 | AE25: 空 | AF25: 空 | AG25: =AH25+AI25+AJ25 -> 0 | AK25: 是 | AM25: 山中 | AN25: 160 | AO25: 40 | AP25: 39.110982 | AQ25: =COUNTIF($I$4:$P$94,AM25) -> 0 | AR25: =COUNTIF($Q$4:$X$94,AM25) -> 0 | AS25: =COUNTIF($Y$4:$AF$94,AM25) -> 0 | AT25: =AQ25+AR25+AS25 -> 0 | AU25: =AQ25*$AO25 -> 0 | AV25: =AR25*$AO25 -> 0 | AW25: =AS25*$AO25 -> 0 | BA25: =AN25*0.8 -> 128
A26: 44842 | B26: 1600 | D26: =(SUM(粮草!A26:X26)+AG26*10)*IF(AK26="是",$AY$4,$AY$3)-40 -> 992 | E26: =SUM($B$4:B26)+SUM($C$4:C26)-SUM($D$4:D26) -> 4200 | F26: =SUM(经验!A26:X26) -> 370 | G26: =SUM($F$4:F26)+SUM($H$4:H26) -> 14930 | H26: 0 | I26: 空 | J26: 空 | K26: 空 | L26: 空 | M26: 空 | N26: 空 | O26: 空 | P26: 空 | Q26: 4级 | R26: 4级 | S26: 4级 | T26: 4级 | U26: 4级 | V26: 4级 | W26: 空 | X26: 空 | Y26: 2级 | Z26: 商人 | AA26: 空 | AB26: 空 | AC26: 空 | AD26: 空 | AE26: 空 | AF26: 空 | AG26: =AH26+AI26+AJ26 -> 0 | AK26: 是 | AM26: 秋道 | AN26: 150 | AO26: 35 | AP26: 44.222109 | AQ26: =COUNTIF($I$4:$P$94,AM26) -> 0 | AR26: =COUNTIF($Q$4:$X$94,AM26) -> 0 | AS26: =COUNTIF($Y$4:$AF$94,AM26) -> 0 | AT26: =AQ26+AR26+AS26 -> 0 | AU26: =AQ26*$AO26 -> 0 | AV26: =AR26*$AO26 -> 0 | AW26: =AS26*$AO26 -> 0 | BA26: =AN26*0.8 -> 120
A27: 44843 | B27: 1600 | D27: =(SUM(粮草!A27:X27)+AG27*10)*IF(AK27="是",$AY$4,$AY$3) -> 864 | E27: =SUM($B$4:B27)+SUM($C$4:C27)-SUM($D$4:D27) -> 4936 | F27: =SUM(经验!A27:X27) -> 300 | G27: =SUM($F$4:F27)+SUM($H$4:H27) -> 15230 | H27: 0 | I27: 空 | J27: 空 | K27: 空 | L27: 空 | M27: 空 | N27: 空 | O27: 空 | P27: 空 | Q27: 4级 | R27: 4级 | S27: 4级 | T27: 4级 | U27: 4级 | V27: 4级 | W27: 空 | X27: 空 | Y27: 空 | Z27: 空 | AA27: 空 | AB27: 空 | AC27: 空 | AD27: 空 | AE27: 空 | AF27: 空 | AG27: =AH27+AI27+AJ27 -> 0 | AK27: 是 | AM27: 空 | AN27: 0 | AO27: 0 | AP27: 0 | AU27: =AQ27*$AO27 -> 0 | AV27: =AR27*$AO27 -> 0 | AW27: =AS27*$AO27 -> 0 | BA27: =AN27*0.8 -> 0
A28: 44844 | B28: 1600 | D28: =(SUM(粮草!A28:X28)+AG28*10)*IF(AK28="是",$AY$4,$AY$3) -> 840 | E28: =SUM($B$4:B28)+SUM($C$4:C28)-SUM($D$4:D28) -> 5696 | F28: =SUM(经验!A28:X28) -> 300 | G28: =SUM($F$4:F28)+SUM($H$4:H28) -> 15730 | H28: 200 | I28: 空 | J28: 空 | K28: 空 | L28: 空 | M28: 空 | N28: 空 | O28: 空 | P28: 空 | Q28: 4级 | R28: 4级 | S28: 塔4 | T28: 4级 | U28: 4级 | V28: 4级 | W28: 空 | X28: 空 | Y28: 空 | Z28: 空 | AA28: 空 | AB28: 空 | AC28: 空 | AD28: 空 | AE28: 空 | AF28: 空 | AG28: =AH28+AI28+AJ28 -> 0 | AK28: 是 | AL28: 八卦后 | AM28: 营地+ | AN28: -200 | AO28: 0 | AQ28: =COUNTIF($I$4:$P$94,AM28) -> 1 | AR28: =COUNTIF($Q$4:$X$94,AM28) -> 7 | AS28: =COUNTIF($Y$4:$AF$94,AM28) -> 4 | AT28: =AQ28+AR28+AS28 -> 12 | AU28: =AQ28*$AO28 -> 0 | AV28: =AR28*$AO28 -> 0 | AW28: =AS28*$AO28 -> 0 | BA28: =AN28*0.8 -> -160
A29: 44845 | B29: 1600 | D29: =(SUM(粮草!A29:X29)+AG29*10)*IF(AK29="是",$AY$4,$AY$3) -> 864 | E29: =SUM($B$4:B29)+SUM($C$4:C29)-SUM($D$4:D29) -> 6432 | F29: =SUM(经验!A29:X29) -> 300 | G29: =SUM($F$4:F29)+SUM($H$4:H29) -> 16130 | H29: 100 | I29: 空 | J29: 空 | K29: 空 | L29: 空 | M29: 空 | N29: 空 | O29: 空 | P29: 空 | Q29: 4级 | R29: 4级 | S29: 4级 | T29: 4级 | U29: 4级 | V29: 4级 | W29: 空 | X29: 空 | Y29: 空 | Z29: 空 | AA29: 空 | AB29: 空 | AC29: 空 | AD29: 空 | AE29: 空 | AF29: 空 | AG29: =AH29+AI29+AJ29 -> 0 | AK29: 是 | AM29: 历练 | AN29: 50 | AO29: 520 | AQ29: =COUNTIF($I$4:$P$94,AM29) -> 0 | AR29: =COUNTIF($Q$4:$X$94,AM29) -> 0 | AS29: =COUNTIF($Y$4:$AF$94,AM29) -> 3 | AT29: =AQ29+AR29+AS29 -> 3 | AU29: =AQ29*$AO29 -> 0 | AV29: =AR29*$AO29 -> 0 | AW29: =AS29*$AO29 -> 1560 | BA29: =AN29*0.8 -> 40
A30: 44846 | B30: 1600 | D30: =(SUM(粮草!A30:X30)+AG30*10)*IF(AK30="是",$AY$4,$AY$3) -> 760 | E30: =SUM($B$4:B30)+SUM($C$4:C30)-SUM($D$4:D30) -> 7272 | F30: =SUM(经验!A30:X30) -> 280 | G30: =SUM($F$4:F30)+SUM($H$4:H30) -> 16610 | H30: 200 | I30: 空 | J30: 空 | K30: 空 | L30: 空 | M30: 空 | N30: 空 | O30: 空 | P30: 空 | Q30: 4级 | R30: 4级 | S30: 4级 | T30: 4级 | U30: 4级 | V30: 商人 | W30: 空 | X30: 空 | Y30: 空 | Z30: 空 | AA30: 空 | AB30: 空 | AC30: 空 | AD30: 空 | AE30: 空 | AF30: 空 | AG30: =AH30+AI30+AJ30 -> 0 | AK30: 是
A31: 44847 | B31: 1600 | D31: =(SUM(粮草!A31:X31)+AG31*10)*IF(AK31="是",$AY$4,$AY$3) -> 864 | E31: =SUM($B$4:B31)+SUM($C$4:C31)-SUM($D$4:D31) -> 8008 | F31: =SUM(经验!A31:X31) -> 300 | G31: =SUM($F$4:F31)+SUM($H$4:H31) -> 16910 | H31: 0 | I31: 空 | J31: 空 | K31: 空 | L31: 空 | M31: 空 | N31: 空 | O31: 空 | P31: 空 | Q31: 4级 | R31: 4级 | S31: 4级 | T31: 4级 | U31: 4级 | V31: 4级 | W31: 空 | X31: 空 | Y31: 空 | Z31: 空 | AA31: 空 | AB31: 空 | AC31: 空 | AD31: 空 | AE31: 空 | AF31: 空 | AG31: =AH31+AI31+AJ31 -> 0 | AK31: 是
A32: 44848 | B32: 1600 | D32: =(SUM(粮草!A32:X32)+AG32*10)*IF(AK32="是",$AY$4,$AY$3) -> 864 | E32: =SUM($B$4:B32)+SUM($C$4:C32)-SUM($D$4:D32) -> 8744 | F32: =SUM(经验!A32:X32) -> 300 | G32: =SUM($F$4:F32)+SUM($H$4:H32) -> 17210 | H32: 0 | I32: 空 | J32: 空 | K32: 空 | L32: 空 | M32: 空 | N32: 空 | O32: 空 | P32: 空 | Q32: 4级 | R32: 4级 | S32: 4级 | T32: 4级 | U32: 4级 | V32: 4级 | W32: 空 | X32: 空 | Y32: 空 | Z32: 空 | AA32: 空 | AB32: 空 | AC32: 空 | AD32: 空 | AE32: 空 | AF32: 空 | AG32: =AH32+AI32+AJ32 -> 0 | AK32: 是
A33: 44849 | B33: 1600 | D33: =(SUM(粮草!A33:X33)+AG33*10)*IF(AK33="是",$AY$4,$AY$3) -> 864 | E33: =SUM($B$4:B33)+SUM($C$4:C33)-SUM($D$4:D33) -> 9480 | F33: =SUM(经验!A33:X33) -> 300 | G33: =SUM($F$4:F33)+SUM($H$4:H33) -> 17510 | H33: 0 | I33: 空 | J33: 空 | K33: 空 | L33: 空 | M33: 空 | N33: 空 | O33: 空 | P33: 空 | Q33: 4级 | R33: 4级 | S33: 4级 | T33: 4级 | U33: 4级 | V33: 4级 | W33: 空 | X33: 空 | Y33: 空 | Z33: 空 | AA33: 空 | AB33: 空 | AC33: 空 | AD33: 空 | AE33: 空 | AF33: 空 | AG33: =AH33+AI33+AJ33 -> 0 | AK33: 是
A34: 44850 | B34: 1600 | D34: =(SUM(粮草!A34:X34)+AG34*10)*IF(AK34="是",$AY$4,$AY$3) -> 760 | E34: =SUM($B$4:B34)+SUM($C$4:C34)-SUM($D$4:D34) -> 10320 | F34: =SUM(经验!A34:X34) -> 280 | G34: =SUM($F$4:F34)+SUM($H$4:H34) -> 17790 | H34: 0 | I34: 空 | J34: 空 | K34: 空 | L34: 空 | M34: 空 | N34: 空 | O34: 空 | P34: 空 | Q34: 商人 | R34: 4级 | S34: 4级 | T34: 4级 | U34: 4级 | V34: 4级 | W34: 空 | X34: 空 | Y34: 空 | Z34: 空 | AA34: 空 | AB34: 空 | AC34: 空 | AD34: 空 | AE34: 空 | AF34: 空 | AG34: =AH34+AI34+AJ34 -> 0 | AK34: 是
A35: 44851 | B35: 1600 | D35: =(SUM(粮草!A35:X35)+AG35*10)*IF(AK35="是",$AY$4,$AY$3) -> 848 | E35: =SUM($B$4:B35)+SUM($C$4:C35)-SUM($D$4:D35) -> 11072 | F35: =SUM(经验!A35:X35) -> 350 | G35: =SUM($F$4:F35)+SUM($H$4:H35) -> 18340 | H35: 200 | I35: 空 | J35: 空 | K35: 空 | L35: 空 | M35: 空 | N35: 空 | O35: 空 | P35: 空 | Q35: 4级 | R35: 4级 | S35: 4级 | T35: 4级 | U35: 4级 | V35: 营地+ | W35: 4级 | X35: 4级 | Y35: 空 | Z35: 空 | AA35: 空 | AB35: 空 | AC35: 空 | AD35: 空 | AE35: 空 | AF35: 空 | AG35: =AH35+AI35+AJ35 -> 0 | AK35: 是
A36: 44852 | B36: 1600 | D36: =(SUM(粮草!A36:X36)+AG36*10)*IF(AK36="是",$AY$4,$AY$3) -> 864 | E36: =SUM($B$4:B36)+SUM($C$4:C36)-SUM($D$4:D36) -> 11808 | F36: =SUM(经验!A36:X36) -> 300 | G36: =SUM($F$4:F36)+SUM($H$4:H36) -> 18740 | H36: 100 | I36: 空 | J36: 空 | K36: 空 | L36: 空 | M36: 空 | N36: 空 | O36: 空 | P36: 空 | Q36: 4级 | R36: 4级 | S36: 4级 | T36: 4级 | U36: 4级 | V36: 4级 | W36: 空 | X36: 空 | Y36: 空 | Z36: 空 | AA36: 空 | AB36: 空 | AC36: 空 | AD36: 空 | AE36: 空 | AF36: 空 | AG36: =AH36+AI36+AJ36 -> 0 | AK36: 是
A37: 44853 | B37: 1600 | D37: =(SUM(粮草!A37:X37)+AG37*10)*IF(AK37="是",$AY$4,$AY$3) -> 864 | E37: =SUM($B$4:B37)+SUM($C$4:C37)-SUM($D$4:D37) -> 12544 | F37: =SUM(经验!A37:X37) -> 300 | G37: =SUM($F$4:F37)+SUM($H$4:H37) -> 19240 | H37: 200 | I37: 空 | J37: 空 | K37: 空 | L37: 空 | M37: 空 | N37: 空 | O37: 空 | P37: 空 | Q37: 4级 | R37: 4级 | S37: 4级 | T37: 4级 | U37: 4级 | V37: 4级 | W37: 空 | X37: 空 | Y37: 空 | Z37: 空 | AA37: 空 | AB37: 空 | AC37: 空 | AD37: 空 | AE37: 空 | AF37: 空 | AG37: =AH37+AI37+AJ37 -> 0 | AK37: 是
A38: 44854 | B38: 1600 | D38: =(SUM(粮草!A38:X38)+AG38*10)*IF(AK38="是",$AY$4,$AY$3) -> 1680 | E38: =SUM($B$4:B38)+SUM($C$4:C38)-SUM($D$4:D38) -> 12464 | F38: =SUM(经验!A38:X38) -> 570 | G38: =SUM($F$4:F38)+SUM($H$4:H38) -> 19810 | H38: 0 | I38: 空 | J38: 空 | K38: 空 | L38: 空 | M38: 空 | N38: 空 | O38: 空 | P38: 空 | Q38: 4级 | R38: 4级 | S38: 4级 | T38: 4级 | U38: 4级 | V38: 4级 | W38: 空 | X38: 空 | Y38: 3级 | Z38: 3级 | AA38: 3级 | AB38: 3级 | AC38: 3级 | AD38: 3级 | AE38: 空 | AF38: 空 | AG38: =AH38+AI38+AJ38 -> 0 | AK38: 是
A39: 44855 | B39: 1600 | D39: =(SUM(粮草!A39:X39)+AG39*10)*IF(AK39="是",$AY$4,$AY$3) -> 2064 | E39: =SUM($B$4:B39)+SUM($C$4:C39)-SUM($D$4:D39) -> 12000 | F39: =SUM(经验!A39:X39) -> 1145 | G39: =SUM($F$4:F39)+SUM($H$4:H39) -> 20955 | H39: 0 | I39: 空 | J39: 空 | K39: 空 | L39: 空 | M39: 空 | N39: 空 | O39: 空 | P39: 空 | Q39: 4级 | R39: 4级 | S39: 中boss | T39: 5级 | U39: 5级 | V39: 5级 | W39: 5级 | X39: 5级 | Y39: 3级 | Z39: 3级 | AA39: 3级 | AB39: 3级 | AC39: 3级 | AD39: 3级 | AE39: 空 | AF39: 空 | AG39: =AH39+AI39+AJ39 -> 0 | AK39: 是 | AM39: 2级194
A40: 44856 | B40: 1600 | D40: =(SUM(粮草!A40:X40)+AG40*10)*IF(AK40="是",$AY$4,$AY$3) -> 1776 | E40: =SUM($B$4:B40)+SUM($C$4:C40)-SUM($D$4:D40) -> 11824 | F40: =SUM(经验!A40:X40) -> 1615 | G40: =SUM($F$4:F40)+SUM($H$4:H40) -> 22570 | H40: 0 | I40: 空 | J40: 空 | K40: 空 | L40: 空 | M40: 空 | N40: 空 | O40: 空 | P40: 空 | Q40: 6级 | R40: 营地+ | S40: 6级 | T40: 5级 | U40: 5级 | V40: 5级 | W40: 6级 | X40: 大boss | Y40: 3级 | Z40: 3级 | AA40: 3级 | AB40: 3级 | AC40: 3级 | AD40: 塔3 | AE40: 空 | AF40: 空 | AG40: =AH40+AI40+AJ40 -> 0 | AK40: 是 | AM40: 3级349
...

Sheet Sheet1
A1: 3级 | B1: 3级 | C1: 3级 | D1: 3级 | E1: 商人 | F1: 3级 | G1: 空 | H1: 空
A2: 小卦 | B2: 3级 | C2: 2级 | D2: 2级 | E2: 2级 | F2: 2级 | G2: 空 | H2: 空
A3: 2级 | B3: 2级 | C3: 商人 | D3: 2级 | E3: 2级 | F3: 2级 | G3: 空 | H3: 空
A4: 2级 | B4: 商人 | C4: 2级 | D4: 3级 | E4: 1级 | F4: 3级 | G4: 空 | H4: 空
A5: 小卦 | B5: 3级 | C5: 3级 | D5: 3级 | E5: 大卦 | F5: 3级 | G5: 空 | H5: 空
A6: 2级 | B6: 2级 | C6: 2级 | D6: 2级 | E6: 3级 | F6: 3级 | G6: 空 | H6: 空
A7: 3级 | B7: 小卦 | C7: 空 | D7: 空 | E7: 空 | F7: 空 | G7: 空 | H7: 空
A8: 3级 | B8: 3级 | C8: 3级 | D8: 塔2 | E8: 3级 | F8: 3级 | G8: 空 | H8: 空
A9: 3级 | B9: 3级 | C9: 3级 | D9: 3级 | E9: 3级 | F9: 3级 | G9: 空 | H9: 空
A10: 3级 | B10: 3级 | C10: 3级 | D10: 3级 | E10: 商人 | F10: 3级 | G10: 空 | H10: 空
A11: 3级 | B11: 3级 | C11: 3级 | D11: 3级 | E11: 3级 | F11: 3级 | G11: 空 | H11: 空
A12: 3级 | B12: 3级 | C12: 3级 | D12: 3级 | E12: 3级 | F12: 3级 | G12: 空 | H12: 空
... A90: 5级 | B90: 5级 | C90: 5级 | D90: 5级 | E90: 5级 | F90: 空 | G90: 空 | H90: 空

Sheet 粮草
A2: 队伍一 风 | C2: 步数 | D2: =COUNTIF(A4:H94,"<>空") -> 728 | E2: (不算跳步和传送) | I2: 队伍二 雷 | K2: 步数 | L2: =COUNTIF(I4:P94,"<>空") -> 728 | M2: (不算跳步和传送) | Q2: 队伍三 | S2: 总步数 | T2: =COUNTIF(Q4:X94,"<>空") -> 728 | U2: (不算跳步和传送)
A3: 1 | B3: 2 | C3: 3 | D3: 4 | E3: 5 | F3: 6 | G3: 7 | H3: 8 | I3: 1 | J3: 2 | K3: 3 | L3: 4 | M3: 5 | N3: 6 | O3: 7 | P3: 8 | Q3: 1 | R3: 2 | S3: 3 | T3: 4 | U3: 5 | V3: 6 | W3: 7 | X3: 8
A4: =(VLOOKUP('9.0.10'!I4,'9.0.10'!$AM$4:$AO$55,2,FALSE))*IF('9.0.10'!AK$4="是",'9.0.10'!$AY$4,'9.0.10'!$AY$3) -> 150 | B4: =(VLOOKUP('9.0.10'!J4,'9.0.10'!$AM$4:$AO$55,2,FALSE))*IF('9.0.10'!AL$4="是",'9.0.10'!$AY$4,'9.0.10'!$AY$3) -> 150 | C4: =(VLOOKUP('9.0.10'!K4,'9.0.10'!$AM$4:$AO$55,2,FALSE))*IF('9.0.10'!AM$4="是",'9.0.10'!$AY$4,'9.0.10'!$AY$3) -> 150 | D4: =(VLOOKUP('9.0.10'!L4,'9.0.10'!$AM$4:$AO$55,2,FALSE))*IF('9.0.10'!AN$4="是",'9.0.10'!$AY$4,'9.0.10'!$AY$3) -> 150 | E4: =(VLOOKUP('9.0.10'!M4,'9.0.10'!$AM$4:$AO$55,2,FALSE))*IF('9.0.10'!AO$4="是",'9.0.10'!$AY$4,'9.0.10'!$AY$3) -> 150 | F4: =(VLOOKUP('9.0.10'!N4,'9.0.10'!$AM$4:$AO$55,2,FALSE))*IF('9.0.10'!AQ$4="是",'9.0.10'!$AY$4,'9.0.10'!$AY$3) -> 150 | G4: =(VLOOKUP('9.0.10'!O4,'9.0.10'!$AM$4:$AO$55,2,FALSE))*IF('9.0.10'!AR$4="是",'9.0.10'!$AY$4,'9.0.10'!$AY$3) -> 0 | H4: =(VLOOKUP('9.0.10'!P4,'9.0.10'!$AM$4:$AO$55,2,FALSE))*IF('9.0.10'!AS$4="是",'9.0.10'!$AY$4,'9.0.10'!$AY$3) -> 0 | I4: =(VLOOKUP('9.0.10'!Q4,'9.0.10'!$AM$4:$AO$55,2,FALSE))*IF('9.0.10'!AT$4="是",'9.0.10'!$AY$4,'9.0.10'!$AY$3) -> 150 | J4: =(VLOOKUP('9.0.10'!R4,'9.0.10'!$AM$4:$AO$55,2,FALSE))*IF('9.0.10'!AU$4="是",'9.0.10'!$AY$4,'9.0.10'!$AY$3) -> 150 | K4: =(VLOOKUP('9.0.10'!S4,'9.0.10'!$AM$4:$AO$55,2,FALSE))*IF('9.0.10'!AV$4="是",'9.0.10'!$AY$4,'9.0.10'!$AY$3) -> 150 | L4: =(VLOOKUP('9.0.10'!T4,'9.0.10'!$AM$4:$AO$55,2,FALSE))*IF('9.0.10'!AW$4="是",'9.0.10'!$AY$4,'9.0.10'!$AY$3) -> 150 | M4: =(VLOOKUP('9.0.10'!U4,'9.0.10'!$AM$4:$AO$55,2,FALSE))*IF('9.0.10'!AX$4="是",'9.0.10'!$AY$4,'9.0.10'!$AY$3) -> 150 | ... X4: =(VLOOKUP('9.0.10'!AF4,'9.0.10'!$AM$4:$AO$55,2,FALSE))*IF('9.0.10'!BI$4="是",'9.0.10'!$AY$4,'9.0.10'!$AY$3) -> 0
A5: =(VLOOKUP('9.0.10'!I5,'9.0.10'!$AM$4:$AO$55,2,FALSE))*IF('9.0.10'!AK$4="是",'9.0.10'!$AY$4,'9.0.10'!$AY$3) -> 0 | B5: =(VLOOKUP('9.0.10'!J5,'9.0.10'!$AM$4:$AO$55,2,FALSE))*IF('9.0.10'!AL$4="是",'9.0.10'!$AY$4,'9.0.10'!$AY$3) -> 0 | C5: =(VLOOKUP('9.0.10'!K5,'9.0.10'!$AM$4:$AO$55,2,FALSE))*IF('9.0.10'!AM$4="是",'9.0.10'!$AY$4,'9.0.10'!$AY$3) -> 0 | D5: =(VLOOKUP('9.0.10'!L5,'9.0.10'!$AM$4:$AO$55,2,FALSE))*IF('9.0.10'!AN$4="是",'9.0.10'!$AY$4,'9.0.10'!$AY$3) -> 0 | E5: =(VLOOKUP('9.0.10'!M5,'9.0.10'!$AM$4:$AO$55,2,FALSE))*IF('9.0.10'!AO$4="是",'9.0.10'!$AY$4,'9.0.10'!$AY$3) -> 0 | F5: =(VLOOKUP('9.0.10'!N5,'9.0.10'!$AM$4:$AO$55,2,FALSE))*IF('9.0.10'!AQ$4="是",'9.0.10'!$AY$4,'9.0.10'!$AY$3) -> 0 | G5: =(VLOOKUP('9.0.10'!O5,'9.0.10'!$AM$4:$AO$55,2,FALSE))*IF('9.0.10'!AR$4="是",'9.0.10'!$AY$4,'9.0.10'!$AY$3) -> 0 | H5: =(VLOOKUP('9.0.10'!P5,'9.0.10'!$AM$4:$AO$55,2,FALSE))*IF('9.0.10'!AS$4="是",'9.0.10'!$AY$4,'9.0.10'!$AY$3) -> 0 | I5: =(VLOOKUP('9.0.10'!Q5,'9.0.10'!$AM$4:$AO$55,2,FALSE))*IF('9.0.10'!AT$4="是",'9.0.10'!$AY$4,'9.0.10'!$AY$3) -> 170 | J5: =(VLOOKUP('9.0.10'!R5,'9.0.10'!$AM$4:$AO$55,2,FALSE))*IF('9.0.10'!AU$4="是",'9.0.10'!$AY$4,'9.0.10'!$AY$3) -> 170 | K5: =(VLOOKUP('9.0.10'!S5,'9.0.10'!$AM$4:$AO$55,2,FALSE))*IF('9.0.10'!AV$4="是",'9.0.10'!$AY$4,'9.0.10'!$AY$3) -> 170 | L5: =(VLOOKUP('9.0.10'!T5,'9.0.10'!$AM$4:$AO$55,2,FALSE))*IF('9.0.10'!AW$4="是",'9.0.10'!$AY$4,'9.0.10'!$AY$3) -> 170 | M5: =(VLOOKUP('9.0.10'!U5,'9.0.10'!$AM$4:$AO$55,2,FALSE))*IF('9.0.10'!AX$4="是",'9.0.10'!$AY$4,'9.0.10'!$AY$3) -> 50 | ... X5: =(VLOOKUP('9.0.10'!AF5,'9.0.10'!$AM$4:$AO$55,2,FALSE))*IF('9.0.10'!BI$4="是",'9.0.10'!$AY$4,'9.0.10'!$AY$3) -> 150
A6: =(VLOOKUP('9.0.10'!I6,'9.0.10'!$AM$4:$AO$55,2,FALSE))*IF('9.0.10'!AK$4="是",'9.0.10'!$AY$4,'9.0.10'!$AY$3) -> 0 | B6: =(VLOOKUP('9.0.10'!J6,'9.0.10'!$AM$4:$AO$55,2,FALSE))*IF('9.0.10'!AL$4="是",'9.0.10'!$AY$4,'9.0.10'!$AY$3) -> 0 | C6: =(VLOOKUP('9.0.10'!K6,'9.0.10'!$AM$4:$AO$55,2,FALSE))*IF('9.0.10'!AM$4="是",'9.0.10'!$AY$4,'9.0.10'!$AY$3) -> 0 | D6: =(VLOOKUP('9.0.10'!L6,'9.0.10'!$AM$4:$AO$55,2,FALSE))*IF('9.0.10'!AN$4="是",'9.0.10'!$AY$4,'9.0.10'!$AY$3) -> 0 | E6: =(VLOOKUP('9.0.10'!M6,'9.0.10'!$AM$4:$AO$55,2,FALSE))*IF('9.0.10'!AO$4="是",'9.0.10'!$AY$4,'9.0.10'!$AY$3) -> 0 | F6: =(VLOOKUP('9.0.10'!N6,'9.0.10'!$AM$4:$AO$55,2,FALSE))*IF('9.0.10'!AQ$4="是",'9.0.10'!$AY$4,'9.0.10'!$AY$3) -> 0 | G6: =(VLOOKUP('9.0.10'!O6,'9.0.10'!$AM$4:$AO$55,2,FALSE))*IF('9.0.10'!AR$4="是",'9.0.10'!$AY$4,'9.0.10'!$AY$3) -> 0 | H6: =(VLOOKUP('9.0.10'!P6,'9.0.10'!$AM$4:$AO$55,2,FALSE))*IF('9.0.10'!AS$4="是",'9.0.10'!$AY$4,'9.0.10'!$AY$3) -> 0 | I6: =(VLOOKUP('9.0.10'!Q6,'9.0.10'!$AM$4:$AO$55,2,FALSE))*IF('9.0.10'!AT$4="是",'9.0.10'!$AY$4,'9.0.10'!$AY$3) -> 170 | J6: =(VLOOKUP('9.0.10'!R6,'9.0.10'!$AM$4:$AO$55,2,FALSE))*IF('9.0.10'!AU$4="是",'9.0.10'!$AY$4,'9.0.10'!$AY$3) -> 170 | K6: =(VLOOKUP('9.0.10'!S6,'9.0.10'!$AM$4:$AO$55,2,FALSE))*IF('9.0.10'!AV$4="是",'9.0.10'!$AY$4,'9.0.10'!$AY$3) -> 160 | L6: =(VLOOKUP('9.0.10'!T6,'9.0.10'!$AM$4:$AO$55,2,FALSE))*IF('9.0.10'!AW$4="是",'9.0.10'!$AY$4,'9.0.10'!$AY$3) -> 160 | M6: =(VLOOKUP('9.0.10'!U6,'9.0.10'!$AM$4:$AO$55,2,FALSE))*IF('9.0.10'!AX$4="是",'9.0.10'!$AY$4,'9.0.10'!$AY$3) -> 160 | ... X6: =(VLOOKUP('9.0.10'!AF6,'9.0.10'!$AM$4:$AO$55,2,FALSE))*IF('9.0.10'!BI$4="是",'9.0.10'!$AY$4,'9.0.10'!$AY$3) -> 170
A7: =(VLOOKUP('9.0.10'!I7,'9.0.10'!$AM$4:$AO$55,2,FALSE))*IF('9.0.10'!AK$4="是",'9.0.10'!$AY$4,'9.0.10'!$AY$3) -> 0 | B7: =(VLOOKUP('9.0.10'!J7,'9.0.10'!$AM$4:$AO$55,2,FALSE))*IF('9.0.10'!AL$4="是",'9.0.10'!$AY$4,'9.0.10'!$AY$3) -> 0 | C7: =(VLOOKUP('9.0.10'!K7,'9.0.10'!$AM$4:$AO$55,2,FALSE))*IF('9.0.10'!AM$4="是",'9.0.10'!$AY$4,'9.0.10'!$AY$3) -> 0 | D7: =(VLOOKUP('9.0.10'!L7,'9.0.10'!$AM$4:$AO$55,2,FALSE))*IF('9.0.10'!AN$4="是",'9.0.10'!$AY$4,'9.0.10'!$AY$3) -> 0 | E7: =(VLOOKUP('9.0.10'!M7,'9.0.10'!$AM$4:$AO$55,2,FALSE))*IF('9.0.10'!AO$4="是",'9.0.10'!$AY$4,'9.0.10'!$AY$3) -> 0 | F7: =(VLOOKUP('9.0.10'!N7,'9.0.10'!$AM$4:$AO$55,2,FALSE))*IF('9.0.10'!AQ$4="是",'9.0.10'!$AY$4,'9.0.10'!$AY$3) -> 0 | G7: =(VLOOKUP('9.0.10'!O7,'9.0.10'!$AM$4:$AO$55,2,FALSE))*IF('9.0.10'!AR$4="是",'9.0.10'!$AY$4,'9.0.10'!$AY$3) -> 0 | H7: =(VLOOKUP('9.0.10'!P7,'9.0.10'!$AM$4:$AO$55,2,FALSE))*IF('9.0.10'!AS$4="是",'9.0.10'!$AY$4,'9.0.10'!$AY$3) -> 0 | I7: =(VLOOKUP('9.0.10'!Q7,'9.0.10'!$AM$4:$AO$55,2,FALSE))*IF('9.0.10'!AT$4="是",'9.0.10'!$AY$4,'9.0.10'!$AY$3) -> 160 | J7: =(VLOOKUP('9.0.10'!R7,'9.0.10'!$AM$4:$AO$55,2,FALSE))*IF('9.0.10'!AU$4="是",'9.0.10'!$AY$4,'9.0.10'!$AY$3) -> 160 | K7: =(VLOOKUP('9.0.10'!S7,'9.0.10'!$AM$4:$AO$55,2,FALSE))*IF('9.0.10'!AV$4="是",'9.0.10'!$AY$4,'9.0.10'!$AY$3) -> 50 | L7: =(VLOOKUP('9.0.10'!T7,'9.0.10'!$AM$4:$AO$55,2,FALSE))*IF('9.0.10'!AW$4="是",'9.0.10'!$AY$4,'9.0.10'!$AY$3) -> 160 | M7: =(VLOOKUP('9.0.10'!U7,'9.0.10'!$AM$4:$AO$55,2,FALSE))*IF('9.0.10'!AX$4="是",'9.0.10'!$AY$4,'9.0.10'!$AY$3) -> 160 | ... X7: =(VLOOKUP('9.0.10'!AF7,'9.0.10'!$AM$4:$AO$55,2,FALSE))*IF('9.0.10'!BI$4="是",'9.0.10'!$AY$4,'9.0.10'!$AY$3) -> 0
A8: =(VLOOKUP('9.0.10'!I8,'9.0.10'!$AM$4:$AO$55,2,FALSE))*IF('9.0.10'!AK$4="是",'9.0.10'!$AY$4,'9.0.10'!$AY$3) -> 0 | B8: =(VLOOKUP('9.0.10'!J8,'9.0.10'!$AM$4:$AO$55,2,FALSE))*IF('9.0.10'!AL$4="是",'9.0.10'!$AY$4,'9.0.10'!$AY$3) -> 0 | C8: =(VLOOKUP('9.0.10'!K8,'9.0.10'!$AM$4:$AO$55,2,FALSE))*IF('9.0.10'!AM$4="是",'9.0.10'!$AY$4,'9.0.10'!$AY$3) -> 0 | D8: =(VLOOKUP('9.0.10'!L8,'9.0.10'!$AM$4:$AO$55,2,FALSE))*IF('9.0.10'!AN$4="是",'9.0.10'!$AY$4,'9.0.10'!$AY$3) -> 0 | E8: =(VLOOKUP('9.0.10'!M8,'9.0.10'!$AM$4:$AO$55,2,FALSE))*IF('9.0.10'!AO$4="是",'9.0.10'!$AY$4,'9.0.10'!$AY$3) -> 0 | F8: =(VLOOKUP('9.0.10'!N8,'9.0.10'!$AM$4:$AO$55,2,FALSE))*IF('9.0.10'!AQ$4="是",'9.0.10'!$AY$4,'9.0.10'!$AY$3) -> 0 | G8: =(VLOOKUP('9.0.10'!O8,'9.0.10'!$AM$4:$AO$55,2,FALSE))*IF('9.0.10'!AR$4="是",'9.0.10'!$AY$4,'9.0.10'!$AY$3) -> 0 | H8: =(VLOOKUP('9.0.10'!P8,'9.0.10'!$AM$4:$AO$55,2,FALSE))*IF('9.0.10'!AS$4="是",'9.0.10'!$AY$4,'9.0.10'!$AY$3) -> 0 | I8: =(VLOOKUP('9.0.10'!Q8,'9.0.10'!$AM$4:$AO$55,2,FALSE))*IF('9.0.10'!AT$4="是",'9.0.10'!$AY$4,'9.0.10'!$AY$3) -> 160 | J8: =(VLOOKUP('9.0.10'!R8,'9.0.10'!$AM$4:$AO$55,2,FALSE))*IF('9.0.10'!AU$4="是",'9.0.10'!$AY$4,'9.0.10'!$AY$3) -> 50 | K8: =(VLOOKUP('9.0.10'!S8,'9.0.10'!$AM$4:$AO$55,2,FALSE))*IF('9.0.10'!AV$4="是",'9.0.10'!$AY$4,'9.0.10'!$AY$3) -> 160 | L8: =(VLOOKUP('9.0.10'!T8,'9.0.10'!$AM$4:$AO$55,2,FALSE))*IF('9.0.10'!AW$4="是",'9.0.10'!$AY$4,'9.0.10'!$AY$3) -> 170 | M8: =(VLOOKUP('9.0.10'!U8,'9.0.10'!$AM$4:$AO$55,2,FALSE))*IF('9.0.10'!AX$4="是",'9.0.10'!$AY$4,'9.0.10'!$AY$3) -> 150 | ... X8: =(VLOOKUP('9.0.10'!AF8,'9.0.10'!$AM$4:$AO$55,2,FALSE))*IF('9.0.10'!BI$4="是",'9.0.10'!$AY$4,'9.0.10'!$AY$3) -> 0
A9: =(VLOOKUP('9.0.10'!I9,'9.0.10'!$AM$4:$AO$55,2,FALSE))*IF('9.0.10'!AK$4="是",'9.0.10'!$AY$4,'9.0.10'!$AY$3) -> 0 | B9: =(VLOOKUP('9.0.10'!J9,'9.0.10'!$AM$4:$AO$55,2,FALSE))*IF('9.0.10'!AL$4="是",'9.0.10'!$AY$4,'9.0.10'!$AY$3) -> 0 | C9: =(VLOOKUP('9.0.10'!K9,'9.0.10'!$AM$4:$AO$55,2,FALSE))*IF('9.0.10'!AM$4="是",'9.0.10'!$AY$4,'9.0.10'!$AY$3) -> 0 | D9: =(VLOOKUP('9.0.10'!L9,'9.0.10'!$AM$4:$AO$55,2,FALSE))*IF('9.0.10'!AN$4="是",'9.0.10'!$AY$4,'9.0.10'!$AY$3) -> 0 | E9: =(VLOOKUP('9.0.10'!M9,'9.0.10'!$AM$4:$AO$55,2,FALSE))*IF('9.0.10'!AO$4="是",'9.0.10'!$AY$4,'9.0.10'!$AY$3) -> 0 | F9: =(VLOOKUP('9.0.10'!N9,'9.0.10'!$AM$4:$AO$55,2,FALSE))*IF('9.0.10'!AQ$4="是",'9.0.10'!$AY$4,'9.0.10'!$AY$3) -> 0 | G9: =(VLOOKUP('9.0.10'!O9,'9.0.10'!$AM$4:$AO$55,2,FALSE))*IF('9.0.10'!AR$4="是",'9.0.10'!$AY$4,'9.0.10'!$AY$3) -> 0 | H9: =(VLOOKUP('9.0.10'!P9,'9.0.10'!$AM$4:$AO$55,2,FALSE))*IF('9.0.10'!AS$4="是",'9.0.10'!$AY$4,'9.0.10'!$AY$3) -> 0 | I9: =(VLOOKUP('9.0.10'!Q9,'9.0.10'!$AM$4:$AO$55,2,FALSE))*IF('9.0.10'!AT$4="是",'9.0.10'!$AY$4,'9.0.10'!$AY$3) -> 170 | J9: =(VLOOKUP('9.0.10'!R9,'9.0.10'!$AM$4:$AO$55,2,FALSE))*IF('9.0.10'!AU$4="是",'9.0.10'!$AY$4,'9.0.10'!$AY$3) -> 170 | K9: =(VLOOKUP('9.0.10'!S9,'9.0.10'!$AM$4:$AO$55,2,FALSE))*IF('9.0.10'!AV$4="是",'9.0.10'!$AY$4,'9.0.10'!$AY$3) -> 170 | L9: =(VLOOKUP('9.0.10'!T9,'9.0.10'!$AM$4:$AO$55,2,FALSE))*IF('9.0.10'!AW$4="是",'9.0.10'!$AY$4,'9.0.10'!$AY$3) -> 170 | M9: =(VLOOKUP('9.0.10'!U9,'9.0.10'!$AM$4:$AO$55,2,FALSE))*IF('9.0.10'!AX$4="是",'9.0.10'!$AY$4,'9.0.10'!$AY$3) -> 250 | ... X9: =(VLOOKUP('9.0.10'!AF9,'9.0.10'!$AM$4:$AO$55,2,FALSE))*IF('9.0.10'!BI$4="是",'9.0.10'!$AY$4,'9.0.10'!$AY$3) -> 0
A10: =(VLOOKUP('9.0.10'!I10,'9.0.10'!$AM$4:$AO$55,2,FALSE))*IF('9.0.10'!AK$4="是",'9.0.10'!$AY$4,'9.0.10'!$AY$3) -> 0 | B10: =(VLOOKUP('9.0.10'!J10,'9.0.10'!$AM$4:$AO$55,2,FALSE))*IF('9.0.10'!AL$4="是",'9.0.10'!$AY$4,'9.0.10'!$AY$3) -> 0 | C10: =(VLOOKUP('9.0.10'!K10,'9.0.10'!$AM$4:$AO$55,2,FALSE))*IF('9.0.10'!AM$4="是",'9.0.10'!$AY$4,'9.0.10'!$AY$3) -> 0 | D10: =(VLOOKUP('9.0.10'!L10,'9.0.10'!$AM$4:$AO$55,2,FALSE))*IF('9.0.10'!AN$4="是",'9.0.10'!$AY$4,'9.0.10'!$AY$3) -> 0 | E10: =(VLOOKUP('9.0.10'!M10,'9.0.10'!$AM$4:$AO$55,2,FALSE))*IF('9.0.10'!AO$4="是",'9.0.10'!$AY$4,'9.0.10'!$AY$3) -> 0 | F10: =(VLOOKUP('9.0.10'!N10,'9.0.10'!$AM$4:$AO$55,2,FALSE))*IF('9.0.10'!AQ$4="是",'9.0.10'!$AY$4,'9.0.10'!$AY$3) -> 0 | G10: =(VLOOKUP('9.0.10'!O10,'9.0.10'!$AM$4:$AO$55,2,FALSE))*IF('9.0.10'!AR$4="是",'9.0.10'!$AY$4,'9.0.10'!$AY$3) -> 0 | H10: =(VLOOKUP('9.0.10'!P10,'9.0.10'!$AM$4:$AO$55,2,FALSE))*IF('9.0.10'!AS$4="是",'9.0.10'!$AY$4,'9.0.10'!$AY$3) -> 0 | I10: =(VLOOKUP('9.0.10'!Q10,'9.0.10'!$AM$4:$AO$55,2,FALSE))*IF('9.0.10'!AT$4="是",'9.0.10'!$AY$4,'9.0.10'!$AY$3) -> 160 | J10: =(VLOOKUP('9.0.10'!R10,'9.0.10'!$AM$4:$AO$55,2,FALSE))*IF('9.0.10'!AU$4="是",'9.0.10'!$AY$4,'9.0.10'!$AY$3) -> 160 | K10: =(VLOOKUP('9.0.10'!S10,'9.0.10'!$AM$4:$AO$55,2,FALSE))*IF('9.0.10'!AV$4="是",'9.0.10'!$AY$4,'9.0.10'!$AY$3) -> 160 | L10: =(VLOOKUP('9.0.10'!T10,'9.0.10'!$AM$4:$AO$55,2,FALSE))*IF('9.0.10'!AW$4="是",'9.0.10'!$AY$4,'9.0.10'!$AY$3) -> 160 | M10: =(VLOOKUP('9.0.10'!U10,'9.0.10'!$AM$4:$AO$55,2,FALSE))*IF('9.0.10'!AX$4="是",'9.0.10'!$AY$4,'9.0.10'!$AY$3) -> 170 | ... X10: =(VLOOKUP('9.0.10'!AF10,'9.0.10'!$AM$4:$AO$55,2,FALSE))*IF('9.0.10'!BI$4="是",'9.0.10'!$AY$4,'9.0.10'!$AY$3) -> 0
A11: =(VLOOKUP('9.0.10'!I11,'9.0.10'!$AM$4:$AO$55,2,FALSE))*IF('9.0.10'!AK$4="是",'9.0.10'!$AY$4,'9.0.10'!$AY$3) -> 0 | B11: =(VLOOKUP('9.0.10'!J11,'9.0.10'!$AM$4:$AO$55,2,FALSE))*IF('9.0.10'!AL$4="是",'9.0.10'!$AY$4,'9.0.10'!$AY$3) -> 0 | C11: =(VLOOKUP('9.0.10'!K11,'9.0.10'!$AM$4:$AO$55,2,FALSE))*IF('9.0.10'!AM$4="是",'9.0.10'!$AY$4,'9.0.10'!$AY$3) -> 0 | D11: =(VLOOKUP('9.0.10'!L11,'9.0.10'!$AM$4:$AO$55,2,FALSE))*IF('9.0.10'!AN$4="是",'9.0.10'!$AY$4,'9.0.10'!$AY$3) -> 0 | E11: =(VLOOKUP('9.0.10'!M11,'9.0.10'!$AM$4:$AO$55,2,FALSE))*IF('9.0.10'!AO$4="是",'9.0.10'!$AY$4,'9.0.10'!$AY$3) -> 0 | F11: =(VLOOKUP('9.0.10'!N11,'9.0.10'!$AM$4:$AO$55,2,FALSE))*IF('9.0.10'!AQ$4="是",'9.0.10'!$AY$4,'9.0.10'!$AY$3) -> 0 | G11: =(VLOOKUP('9.0.10'!O11,'9.0.10'!$AM$4:$AO$55,2,FALSE))*IF('9.0.10'!AR$4="是",'9.0.10'!$AY$4,'9.0.10'!$AY$3) -> 0 | H11: =(VLOOKUP('9.0.10'!P11,'9.0.10'!$AM$4:$AO$55,2,FALSE))*IF('9.0.10'!AS$4="是",'9.0.10'!$AY$4,'9.0.10'!$AY$3) -> 0 | I11: =(VLOOKUP('9.0.10'!Q11,'9.0.10'!$AM$4:$AO$55,2,FALSE))*IF('9.0.10'!AT$4="是",'9.0.10'!$AY$4,'9.0.10'!$AY$3) -> 170 | J11: =(VLOOKUP('9.0.10'!R11,'9.0.10'!$AM$4:$AO$55,2,FALSE))*IF('9.0.10'!AU$4="是",'9.0.10'!$AY$4,'9.0.10'!$AY$3) -> 170 | K11: =(VLOOKUP('9.0.10'!S11,'9.0.10'!$AM$4:$AO$55,2,FALSE))*IF('9.0.10'!AV$4="是",'9.0.10'!$AY$4,'9.0.10'!$AY$3) -> 170 | L11: =(VLOOKUP('9.0.10'!T11,'9.0.10'!$AM$4:$AO$55,2,FALSE))*IF('9.0.10'!AW$4="是",'9.0.10'!$AY$4,'9.0.10'!$AY$3) -> 170 | M11: =(VLOOKUP('9.0.10'!U11,'9.0.10'!$AM$4:$AO$55,2,FALSE))*IF('9.0.10'!AX$4="是",'9.0.10'!$AY$4,'9.0.10'!$AY$3) -> 170 | ... X11: =(VLOOKUP('9.0.10'!AF11,'9.0.10'!$AM$4:$AO$55,2,FALSE))*IF('9.0.10'!BI$4="是",'9.0.10'!$AY$4,'9.0.10'!$AY$3) -> 0
A12: =(VLOOKUP('9.0.10'!I12,'9.0.10'!$AM$4:$AO$55,2,FALSE))*IF('9.0.10'!AK$4="是",'9.0.10'!$AY$4,'9.0.10'!$AY$3) -> 0 | B12: =(VLOOKUP('9.0.10'!J12,'9.0.10'!$AM$4:$AO$55,2,FALSE))*IF('9.0.10'!AL$4="是",'9.0.10'!$AY$4,'9.0.10'!$AY$3) -> 0 | C12: =(VLOOKUP('9.0.10'!K12,'9.0.10'!$AM$4:$AO$55,2,FALSE))*IF('9.0.10'!AM$4="是",'9.0.10'!$AY$4,'9.0.10'!$AY$3) -> 0 | D12: =(VLOOKUP('9.0.10'!L12,'9.0.10'!$AM$4:$AO$55,2,FALSE))*IF('9.0.10'!AN$4="是",'9.0.10'!$AY$4,'9.0.10'!$AY$3) -> 0 | E12: =(VLOOKUP('9.0.10'!M12,'9.0.10'!$AM$4:$AO$55,2,FALSE))*IF('9.0.10'!AO$4="是",'9.0.10'!$AY$4,'9.0.10'!$AY$3) -> 0 | F12: =(VLOOKUP('9.0.10'!N12,'9.0.10'!$AM$4:$AO$55,2,FALSE))*IF('9.0.10'!AQ$4="是",'9.0.10'!$AY$4,'9.0.10'!$AY$3) -> 0 | G12: =(VLOOKUP('9.0.10'!O12,'9.0.10'!$AM$4:$AO$55,2,FALSE))*IF('9.0.10'!AR$4="是",'9.0.10'!$AY$4,'9.0.10'!$AY$3) -> 0 | H12: =(VLOOKUP('9.0.10'!P12,'9.0.10'!$AM$4:$AO$55,2,FALSE))*IF('9.0.10'!AS$4="是",'9.0.10'!$AY$4,'9.0.10'!$AY$3) -> 0 | I12: =(VLOOKUP('9.0.10'!Q12,'9.0.10'!$AM$4:$AO$55,2,FALSE))*IF('9.0.10'!AT$4="是",'9.0.10'!$AY$4,'9.0.10'!$AY$3) -> 170 | J12: =(VLOOKUP('9.0.10'!R12,'9.0.10'!$AM$4:$AO$55,2,FALSE))*IF('9.0.10'!AU$4="是",'9.0.10'!$AY$4,'9.0.10'!$AY$3) -> 170 | K12: =(VLOOKUP('9.0.10'!S12,'9.0.10'!$AM$4:$AO$55,2,FALSE))*IF('9.0.10'!AV$4="是",'9.0.10'!$AY$4,'9.0.10'!$AY$3) -> 50 | L12: =(VLOOKUP('9.0.10'!T12,'9.0.10'!$AM$4:$AO$55,2,FALSE))*IF('9.0.10'!AW$4="是",'9.0.10'!$AY$4,'9.0.10'!$AY$3) -> 170 | M12: =(VLOOKUP('9.0.10'!U12,'9.0.10'!$AM$4:$AO$55,2,FALSE))*IF('9.0.10'!AX$4="是",'9.0.10'!$AY$4,'9.0.10'!$AY$3) -> 170 | ... X12: =(VLOOKUP('9.0.10'!AF12,'9.0.10'!$AM$4:$AO$55,2,FALSE))*IF('9.0.10'!BI$4="是",'9.0.10'!$AY$4,'9.0.10'!$AY$3) -> 0
A13: =(VLOOKUP('9.0.10'!I13,'9.0.10'!$AM$4:$AO$55,2,FALSE))*IF('9.0.10'!AK$4="是",'9.0.10'!$AY$4,'9.0.10'!$AY$3) -> 0 | B13: =(VLOOKUP('9.0.10'!J13,'9.0.10'!$AM$4:$AO$55,2,FALSE))*IF('9.0.10'!AL$4="是",'9.0.10'!$AY$4,'9.0.10'!$AY$3) -> 0 | C13: =(VLOOKUP('9.0.10'!K13,'9.0.10'!$AM$4:$AO$55,2,FALSE))*IF('9.0.10'!AM$4="是",'9.0.10'!$AY$4,'9.0.10'!$AY$3) -> 0 | D13: =(VLOOKUP('9.0.10'!L13,'9.0.10'!$AM$4:$AO$55,2,FALSE))*IF('9.0.10'!AN$4="是",'9.0.10'!$AY$4,'9.0.10'!$AY$3) -> 0 | E13: =(VLOOKUP('9.0.10'!M13,'9.0.10'!$AM$4:$AO$55,2,FALSE))*IF('9.0.10'!AO$4="是",'9.0.10'!$AY$4,'9.0.10'!$AY$3) -> 0 | F13: =(VLOOKUP('9.0.10'!N13,'9.0.10'!$AM$4:$AO$55,2,FALSE))*IF('9.0.10'!AQ$4="是",'9.0.10'!$AY$4,'9.0.10'!$AY$3) -> 0 | G13: =(VLOOKUP('9.0.10'!O13,'9.0.10'!$AM$4:$AO$55,2,FALSE))*IF('9.0.10'!AR$4="是",'9.0.10'!$AY$4,'9.0.10'!$AY$3) -> 0 | H13: =(VLOOKUP('9.0.10'!P13,'9.0.10'!$AM$4:$AO$55,2,FALSE))*IF('9.0.10'!AS$4="是",'9.0.10'!$AY$4,'9.0.10'!$AY$3) -> 0 | I13: =(VLOOKUP('9.0.10'!Q13,'9.0.10'!$AM$4:$AO$55,2,FALSE))*IF('9.0.10'!AT$4="是",'9.0.10'!$AY$4,'9.0.10'!$AY$3) -> 170 | J13: =(VLOOKUP('9.0.10'!R13,'9.0.10'!$AM$4:$AO$55,2,FALSE))*IF('9.0.10'!AU$4="是",'9.0.10'!$AY$4,'9.0.10'!$AY$3) -> 170 | K13: =(VLOOKUP('9.0.10'!S13,'9.0.10'!$AM$4:$AO$55,2,FALSE))*IF('9.0.10'!AV$4="是",'9.0.10'!$AY$4,'9.0.10'!$AY$3) -> 170 | L13: =(VLOOKUP('9.0.10'!T13,'9.0.10'!$AM$4:$AO$55,2,FALSE))*IF('9.0.10'!AW$4="是",'9.0.10'!$AY$4,'9.0.10'!$AY$3) -> 170 | M13: =(VLOOKUP('9.0.10'!U13,'9.0.10'!$AM$4:$AO$55,2,FALSE))*IF('9.0.10'!AX$4="是",'9.0.10'!$AY$4,'9.0.10'!$AY$3) -> 170 | ... X13: =(VLOOKUP('9.0.10'!AF13,'9.0.10'!$AM$4:$AO$55,2,FALSE))*IF('9.0.10'!BI$4="是",'9.0.10'!$AY$4,'9.0.10'!$AY$3) -> 0
A14: =(VLOOKUP('9.0.10'!I14,'9.0.10'!$AM$4:$AO$55,2,FALSE))*IF('9.0.10'!AK$4="是",'9.0.10'!$AY$4,'9.0.10'!$AY$3) -> 0 | B14: =(VLOOKUP('9.0.10'!J14,'9.0.10'!$AM$4:$AO$55,2,FALSE))*IF('9.0.10'!AL$4="是",'9.0.10'!$AY$4,'9.0.10'!$AY$3) -> 0 | C14: =(VLOOKUP('9.0.10'!K14,'9.0.10'!$AM$4:$AO$55,2,FALSE))*IF('9.0.10'!AM$4="是",'9.0.10'!$AY$4,'9.0.10'!$AY$3) -> 0 | D14: =(VLOOKUP('9.0.10'!L14,'9.0.10'!$AM$4:$AO$55,2,FALSE))*IF('9.0.10'!AN$4="是",'9.0.10'!$AY$4,'9.0.10'!$AY$3) -> 0 | E14: =(VLOOKUP('9.0.10'!M14,'9.0.10'!$AM$4:$AO$55,2,FALSE))*IF('9.0.10'!AO$4="是",'9.0.10'!$AY$4,'9.0.10'!$AY$3) -> 0 | F14: =(VLOOKUP('9.0.10'!N14,'9.0.10'!$AM$4:$AO$55,2,FALSE))*IF('9.0.10'!AQ$4="是",'9.0.10'!$AY$4,'9.0.10'!$AY$3) -> 0 | G14: =(VLOOKUP('9.0.10'!O14,'9.0.10'!$AM$4:$AO$55,2,FALSE))*IF('9.0.10'!AR$4="是",'9.0.10'!$AY$4,'9.0.10'!$AY$3) -> 0 | H14: =(VLOOKUP('9.0.10'!P14,'9.0.10'!$AM$4:$AO$55,2,FALSE))*IF('9.0.10'!AS$4="是",'9.0.10'!$AY$4,'9.0.10'!$AY$3) -> 0 | I14: =(VLOOKUP('9.0.10'!Q14,'9.0.10'!$AM$4:$AO$55,2,FALSE))*IF('9.0.10'!AT$4="是",'9.0.10'!$AY$4,'9.0.10'!$AY$3) -> 50 | J14: =(VLOOKUP('9.0.10'!R14,'9.0.10'!$AM$4:$AO$55,2,FALSE))*IF('9.0.10'!AU$4="是",'9.0.10'!$AY$4,'9.0.10'!$AY$3) -> 170 | K14: =(VLOOKUP('9.0.10'!S14,'9.0.10'!$AM$4:$AO$55,2,FALSE))*IF('9.0.10'!AV$4="是",'9.0.10'!$AY$4,'9.0.10'!$AY$3) -> 170 | L14: =(VLOOKUP('9.0.10'!T14,'9.0.10'!$AM$4:$AO$55,2,FALSE))*IF('9.0.10'!AW$4="是",'9.0.10'!$AY$4,'9.0.10'!$AY$3) -> 170 | M14: =(VLOOKUP('9.0.10'!U14,'9.0.10'!$AM$4:$AO$55,2,FALSE))*IF('9.0.10'!AX$4="是",'9.0.10'!$AY$4,'9.0.10'!$AY$3) -> 170 | ... X14: =(VLOOKUP('9.0.10'!AF14,'9.0.10'!$AM$4:$AO$55,2,FALSE))*IF('9.0.10'!BI$4="是",'9.0.10'!$AY$4,'9.0.10'!$AY$3) -> 0
A15: =(VLOOKUP('9.0.10'!I15,'9.0.10'!$AM$4:$AO$55,2,FALSE))*IF('9.0.10'!AK$4="是",'9.0.10'!$AY$4,'9.0.10'!$AY$3) -> 0 | B15: =(VLOOKUP('9.0.10'!J15,'9.0.10'!$AM$4:$AO$55,2,FALSE))*IF('9.0.10'!AL$4="是",'9.0.10'!$AY$4,'9.0.10'!$AY$3) -> 0 | C15: =(VLOOKUP('9.0.10'!K15,'9.0.10'!$AM$4:$AO$55,2,FALSE))*IF('9.0.10'!AM$4="是",'9.0.10'!$AY$4,'9.0.10'!$AY$3) -> 0 | D15: =(VLOOKUP('9.0.10'!L15,'9.0.10'!$AM$4:$AO$55,2,FALSE))*IF('9.0.10'!AN$4="是",'9.0.10'!$AY$4,'9.0.10'!$AY$3) -> 0 | E15: =(VLOOKUP('9.0.10'!M15,'9.0.10'!$AM$4:$AO$55,2,FALSE))*IF('9.0.10'!AO$4="是",'9.0.10'!$AY$4,'9.0.10'!$AY$3) -> 0 | F15: =(VLOOKUP('9.0.10'!N15,'9.0.10'!$AM$4:$AO$55,2,FALSE))*IF('9.0.10'!AQ$4="是",'9.0.10'!$AY$4,'9.0.10'!$AY$3) -> 0 | G15: =(VLOOKUP('9.0.10'!O15,'9.0.10'!$AM$4:$AO$55,2,FALSE))*IF('9.0.10'!AR$4="是",'9.0.10'!$AY$4,'9.0.10'!$AY$3) -> 0 | H15: =(VLOOKUP('9.0.10'!P15,'9.0.10'!$AM$4:$AO$55,2,FALSE))*IF('9.0.10'!AS$4="是",'9.0.10'!$AY$4,'9.0.10'!$AY$3) -> 0 | I15: =(VLOOKUP('9.0.10'!Q15,'9.0.10'!$AM$4:$AO$55,2,FALSE))*IF('9.0.10'!AT$4="是",'9.0.10'!$AY$4,'9.0.10'!$AY$3) -> 170 | J15: =(VLOOKUP('9.0.10'!R15,'9.0.10'!$AM$4:$AO$55,2,FALSE))*IF('9.0.10'!AU$4="是",'9.0.10'!$AY$4,'9.0.10'!$AY$3) -> 170 | K15: =(VLOOKUP('9.0.10'!S15,'9.0.10'!$AM$4:$AO$55,2,FALSE))*IF('9.0.10'!AV$4="是",'9.0.10'!$AY$4,'9.0.10'!$AY$3) -> 170 | L15: =(VLOOKUP('9.0.10'!T15,'9.0.10'!$AM$4:$AO$55,2,FALSE))*IF('9.0.10'!AW$4="是",'9.0.10'!$AY$4,'9.0.10'!$AY$3) -> 170 | M15: =(VLOOKUP('9.0.10'!U15,'9.0.10'!$AM$4:$AO$55,2,FALSE))*IF('9.0.10'!AX$4="是",'9.0.10'!$AY$4,'9.0.10'!$AY$3) -> 170 | ... X15: =(VLOOKUP('9.0.10'!AF15,'9.0.10'!$AM$4:$AO$55,2,FALSE))*IF('9.0.10'!BI$4="是",'9.0.10'!$AY$4,'9.0.10'!$AY$3) -> 0
... A94: =(VLOOKUP('9.0.10'!I94,'9.0.10'!$AM$4:$AO$55,2,FALSE))*IF('9.0.10'!AK$4="是",'9.0.10'!$AY$4,'9.0.10'!$AY$3) -> 150 | B94: =(VLOOKUP('9.0.10'!J94,'9.0.10'!$AM$4:$AO$55,2,FALSE))*IF('9.0.10'!AL$4="是",'9.0.10'!$AY$4,'9.0.10'!$AY$3) -> 150 | C94: =(VLOOKUP('9.0.10'!K94,'9.0.10'!$AM$4:$AO$55,2,FALSE))*IF('9.0.10'!AM$4="是",'9.0.10'!$AY$4,'9.0.10'!$AY$3) -> 150 | D94: =(VLOOKUP('9.0.10'!L94,'9.0.10'!$AM$4:$AO$55,2,FALSE))*IF('9.0.10'!AN$4="是",'9.0.10'!$AY$4,'9.0.10'!$AY$3) -> 50 | E94: =(VLOOKUP('9.0.10'!M94,'9.0.10'!$AM$4:$AO$55,2,FALSE))*IF('9.0.10'!AO$4="是",'9.0.10'!$AY$4,'9.0.10'!$AY$3) -> 0 | F94: =(VLOOKUP('9.0.10'!N94,'9.0.10'!$AM$4:$AO$55,2,FALSE))*IF('9.0.10'!AQ$4="是",'9.0.10'!$AY$4,'9.0.10'!$AY$3) -> 0 | G94: =(VLOOKUP('9.0.10'!O94,'9.0.10'!$AM$4:$AO$55,2,FALSE))*IF('9.0.10'!AR$4="是",'9.0.10'!$AY$4,'9.0.10'!$AY$3) -> 0 | H94: =(VLOOKUP('9.0.10'!P94,'9.0.10'!$AM$4:$AO$55,2,FALSE))*IF('9.0.10'!AS$4="是",'9.0.10'!$AY$4,'9.0.10'!$AY$3) -> 0 | I94: =(VLOOKUP('9.0.10'!Q94,'9.0.10'!$AM$4:$AO$55,2,FALSE))*IF('9.0.10'!AT$4="是",'9.0.10'!$AY$4,'9.0.10'!$AY$3) -> 180 | J94: =(VLOOKUP('9.0.10'!R94,'9.0.10'!$AM$4:$AO$55,2,FALSE))*IF('9.0.10'!AU$4="是",'9.0.10'!$AY$4,'9.0.10'!$AY$3) -> 180 | K94: =(VLOOKUP('9.0.10'!S94,'9.0.10'!$AM$4:$AO$55,2,FALSE))*IF('9.0.10'!AV$4="是",'9.0.10'!$AY$4,'9.0.10'!$AY$3) -> 180 | L94: =(VLOOKUP('9.0.10'!T94,'9.0.10'!$AM$4:$AO$55,2,FALSE))*IF('9.0.10'!AW$4="是",'9.0.10'!$AY$4,'9.0.10'!$AY$3) -> 180 | M94: =(VLOOKUP('9.0.10'!U94,'9.0.10'!$AM$4:$AO$55,2,FALSE))*IF('9.0.10'!AX$4="是",'9.0.10'!$AY$4,'9.0.10'!$AY$3) -> 180 | ... X94: =(VLOOKUP('9.0.10'!AF94,'9.0.10'!$AM$4:$AO$55,2,FALSE))*IF('9.0.10'!BI$4="是",'9.0.10'!$AY$4,'9.0.10'!$AY$3) -> 0

Sheet 经验
A2: 队伍一 风 | C2: 步数 | D2: =COUNTIF(A4:H94,"<>空") -> 728 | E2: (不算跳步和传送) | I2: 队伍二 雷 | K2: 步数 | L2: =COUNTIF(I4:P94,"<>空") -> 728 | M2: (不算跳步和传送) | Q2: 队伍三 | S2: 总步数 | T2: =COUNTIF(Q4:X94,"<>空") -> 728 | U2: (不算跳步和传送)
A3: 1 | B3: 2 | C3: 3 | D3: 4 | E3: 5 | F3: 6 | G3: 7 | H3: 8 | I3: 1 | J3: 2 | K3: 3 | L3: 4 | M3: 5 | N3: 6 | O3: 7 | P3: 8 | Q3: 1 | R3: 2 | S3: 3 | T3: 4 | U3: 5 | V3: 6 | W3: 7 | X3: 8
A4: =(VLOOKUP('9.0.10'!I4,'9.0.10'!$AM$4:$AO$55,3,FALSE)) -> 35 | B4: =(VLOOKUP('9.0.10'!J4,'9.0.10'!$AM$4:$AO$55,3,FALSE)) -> 35 | C4: =(VLOOKUP('9.0.10'!K4,'9.0.10'!$AM$4:$AO$55,3,FALSE)) -> 35 | D4: =(VLOOKUP('9.0.10'!L4,'9.0.10'!$AM$4:$AO$55,3,FALSE)) -> 35 | E4: =(VLOOKUP('9.0.10'!M4,'9.0.10'!$AM$4:$AO$55,3,FALSE)) -> 35 | F4: =(VLOOKUP('9.0.10'!N4,'9.0.10'!$AM$4:$AO$55,3,FALSE)) -> 35 | G4: =(VLOOKUP('9.0.10'!O4,'9.0.10'!$AM$4:$AO$55,3,FALSE)) -> 0 | H4: =(VLOOKUP('9.0.10'!P4,'9.0.10'!$AM$4:$AO$55,3,FALSE)) -> 0 | ... X4: =(VLOOKUP('9.0.10'!AF4,'9.0.10'!$AM$4:$AO$55,3,FALSE)) -> 0
A5: =(VLOOKUP('9.0.10'!I5,'9.0.10'!$AM$4:$AO$55,3,FALSE)) -> 0 | B5: =(VLOOKUP('9.0.10'!J5,'9.0.10'!$AM$4:$AO$55,3,FALSE)) -> 0 | C5: =(VLOOKUP('9.0.10'!K5,'9.0.10'!$AM$4:$AO$55,3,FALSE)) -> 0 | D5: =(VLOOKUP('9.0.10'!L5,'9.0.10'!$AM$4:$AO$55,3,FALSE)) -> 0 | E5: =(VLOOKUP('9.0.10'!M5,'9.0.10'!$AM$4:$AO$55,3,FALSE)) -> 0 | F5: =(VLOOKUP('9.0.10'!N5,'9.0.10'!$AM$4:$AO$55,3,FALSE)) -> 0 | G5: =(VLOOKUP('9.0.10'!O5,'9.0.10'!$AM$4:$AO$55,3,FALSE)) -> 0 | H5: =(VLOOKUP('9.0.10'!P5,'9.0.10'!$AM$4:$AO$55,3,FALSE)) -> 0 | ... X5: =(VLOOKUP('9.0.10'!AF5,'9.0.10'!$AM$4:$AO$55,3,FALSE)) -> 35
A6: =(VLOOKUP('9.0.10'!I6,'9.0.10'!$AM$4:$AO$55,3,FALSE)) -> 0 | B6: =(VLOOKUP('9.0.10'!J6,'9.0.10'!$AM$4:$AO$55,3,FALSE)) -> 0 | C6: =(VLOOKUP('9.0.10'!K6,'9.0.10'!$AM$4:$AO$55,3,FALSE)) -> 0 | D6: =(VLOOKUP('9.0.10'!L6,'9.0.10'!$AM$4:$AO$55,3,FALSE)) -> 0 | E6: =(VLOOKUP('9.0.10'!M6,'9.0.10'!$AM$4:$AO$55,3,FALSE)) -> 0 | F6: =(VLOOKUP('9.0.10'!N6,'9.0.10'!$AM$4:$AO$55,3,FALSE)) -> 0 | G6: =(VLOOKUP('9.0.10'!O6,'9.0.10'!$AM$4:$AO$55,3,FALSE)) -> 0 | H6: =(VLOOKUP('9.0.10'!P6,'9.0.10'!$AM$4:$AO$55,3,FALSE)) -> 0 | ... X6: =(VLOOKUP('9.0.10'!AF6,'9.0.10'!$AM$4:$AO$55,3,FALSE)) -> 45
A7: =(VLOOKUP('9.0.10'!I7,'9.0.10'!$AM$4:$AO$55,3,FALSE)) -> 0 | B7: =(VLOOKUP('9.0.10'!J7,'9.0.10'!$AM$4:$AO$55,3,FALSE)) -> 0 | C7: =(VLOOKUP('9.0.10'!K7,'9.0.10'!$AM$4:$AO$55,3,FALSE)) -> 0 | D7: =(VLOOKUP('9.0.10'!L7,'9.0.10'!$AM$4:$AO$55,3,FALSE)) -> 0 | E7: =(VLOOKUP('9.0.10'!M7,'9.0.10'!$AM$4:$AO$55,3,FALSE)) -> 0 | F7: =(VLOOKUP('9.0.10'!N7,'9.0.10'!$AM$4:$AO$55,3,FALSE)) -> 0 | G7: =(VLOOKUP('9.0.10'!O7,'9.0.10'!$AM$4:$AO$55,3,FALSE)) -> 0 | H7: =(VLOOKUP('9.0.10'!P7,'9.0.10'!$AM$4:$AO$55,3,FALSE)) -> 0 | ... X7: =(VLOOKUP('9.0.10'!AF7,'9.0.10'!$AM$4:$AO$55,3,FALSE)) -> 0
A8: =(VLOOKUP('9.0.10'!I8,'9.0.10'!$AM$4:$AO$55,3,FALSE)) -> 0 | B8: =(VLOOKUP('9.0.10'!J8,'9.0.10'!$AM$4:$AO$55,3,FALSE)) -> 0 | C8: =(VLOOKUP('9.0.10'!K8,'9.0.10'!$AM$4:$AO$55,3,FALSE)) -> 0 | D8: =(VLOOKUP('9.0.10'!L8,'9.0.10'!$AM$4:$AO$55,3,FALSE)) -> 0 | E8: =(VLOOKUP('9.0.10'!M8,'9.0.10'!$AM$4:$AO$55,3,FALSE)) -> 0 | F8: =(VLOOKUP('9.0.10'!N8,'9.0.10'!$AM$4:$AO$55,3,FALSE)) -> 0 | G8: =(VLOOKUP('9.0.10'!O8,'9.0.10'!$AM$4:$AO$55,3,FALSE)) -> 0 | H8: =(VLOOKUP('9.0.10'!P8,'9.0.10'!$AM$4:$AO$55,3,FALSE)) -> 0 | ... X8: =(VLOOKUP('9.0.10'!AF8,'9.0.10'!$AM$4:$AO$55,3,FALSE)) -> 0
A9: =(VLOOKUP('9.0.10'!I9,'9.0.10'!$AM$4:$AO$55,3,FALSE)) -> 0 | B9: =(VLOOKUP('9.0.10'!J9,'9.0.10'!$AM$4:$AO$55,3,FALSE)) -> 0 | C9: =(VLOOKUP('9.0.10'!K9,'9.0.10'!$AM$4:$AO$55,3,FALSE)) -> 0 | D9: =(VLOOKUP('9.0.10'!L9,'9.0.10'!$AM$4:$AO$55,3,FALSE)) -> 0 | E9: =(VLOOKUP('9.0.10'!M9,'9.0.10'!$AM$4:$AO$55,3,FALSE)) -> 0 | F9: =(VLOOKUP('9.0.10'!N9,'9.0.10'!$AM$4:$AO$55,3,FALSE)) -> 0 | G9: =(VLOOKUP('9.0.10'!O9,'9.0.10'!$AM$4:$AO$55,3,FALSE)) -> 0 | H9: =(VLOOKUP('9.0.10'!P9,'9.0.10'!$AM$4:$AO$55,3,FALSE)) -> 0 | ... X9: =(VLOOKUP('9.0.10'!AF9,'9.0.10'!$AM$4:$AO$55,3,FALSE)) -> 0
A10: =(VLOOKUP('9.0.10'!I10,'9.0.10'!$AM$4:$AO$55,3,FALSE)) -> 0 | B10: =(VLOOKUP('9.0.10'!J10,'9.0.10'!$AM$4:$AO$55,3,FALSE)) -> 0 | C10: =(VLOOKUP('9.0.10'!K10,'9.0.10'!$AM$4:$AO$55,3,FALSE)) -> 0 | D10: =(VLOOKUP('9.0.10'!L10,'9.0.10'!$AM$4:$AO$55,3,FALSE)) -> 0 | E10: =(VLOOKUP('9.0.10'!M10,'9.0.10'!$AM$4:$AO$55,3,FALSE)) -> 0 | F10: =(VLOOKUP('9.0.10'!N10,'9.0.10'!$AM$4:$AO$55,3,FALSE)) -> 0 | G10: =(VLOOKUP('9.0.10'!O10,'9.0.10'!$AM$4:$AO$55,3,FALSE)) -> 0 | H10: =(VLOOKUP('9.0.10'!P10,'9.0.10'!$AM$4:$AO$55,3,FALSE)) -> 0 | ... X10: =(VLOOKUP('9.0.10'!AF10,'9.0.10'!$AM$4:$AO$55,3,FALSE)) -> 0
A11: =(VLOOKUP('9.0.10'!I11,'9.0.10'!$AM$4:$AO$55,3,FALSE)) -> 0 | B11: =(VLOOKUP('9.0.10'!J11,'9.0.10'!$AM$4:$AO$55,3,FALSE)) -> 0 | C11: =(VLOOKUP('9.0.10'!K11,'9.0.10'!$AM$4:$AO$55,3,FALSE)) -> 0 | D11: =(VLOOKUP('9.0.10'!L11,'9.0.10'!$AM$4:$AO$55,3,FALSE)) -> 0 | E11: =(VLOOKUP('9.0.10'!M11,'9.0.10'!$AM$4:$AO$55,3,FALSE)) -> 0 | F11: =(VLOOKUP('9.0.10'!N11,'9.0.10'!$AM$4:$AO$55,3,FALSE)) -> 0 | G11: =(VLOOKUP('9.0.10'!O11,'9.0.10'!$AM$4:$AO$55,3,FALSE)) -> 0 | H11: =(VLOOKUP('9.0.10'!P11,'9.0.10'!$AM$4:$AO$55,3,FALSE)) -> 0 | ... X11: =(VLOOKUP('9.0.10'!AF11,'9.0.10'!$AM$4:$AO$55,3,FALSE)) -> 0
A12: =(VLOOKUP('9.0.10'!I12,'9.0.10'!$AM$4:$AO$55,3,FALSE)) -> 0 | B12: =(VLOOKUP('9.0.10'!J12,'9.0.10'!$AM$4:$AO$55,3,FALSE)) -> 0 | C12: =(VLOOKUP('9.0.10'!K12,'9.0.10'!$AM$4:$AO$55,3,FALSE)) -> 0 | D12: =(VLOOKUP('9.0.10'!L12,'9.0.10'!$AM$4:$AO$55,3,FALSE)) -> 0 | E12: =(VLOOKUP('9.0.10'!M12,'9.0.10'!$AM$4:$AO$55,3,FALSE)) -> 0 | F12: =(VLOOKUP('9.0.10'!N12,'9.0.10'!$AM$4:$AO$55,3,FALSE)) -> 0 | G12: =(VLOOKUP('9.0.10'!O12,'9.0.10'!$AM$4:$AO$55,3,FALSE)) -> 0 | H12: =(VLOOKUP('9.0.10'!P12,'9.0.10'!$AM$4:$AO$55,3,FALSE)) -> 0 | ... X12: =(VLOOKUP('9.0.10'!AF12,'9.0.10'!$AM$4:$AO$55,3,FALSE)) -> 0
A13: =(VLOOKUP('9.0.10'!I13,'9.0.10'!$AM$4:$AO$55,3,FALSE)) -> 0 | B13: =(VLOOKUP('9.0.10'!J13,'9.0.10'!$AM$4:$AO$55,3,FALSE)) -> 0 | C13: =(VLOOKUP('9.0.10'!K13,'9.0.10'!$AM$4:$AO$55,3,FALSE)) -> 0 | D13: =(VLOOKUP('9.0.10'!L13,'9.0.10'!$AM$4:$AO$55,3,FALSE)) -> 0 | E13: =(VLOOKUP('9.0.10'!M13,'9.0.10'!$AM$4:$AO$55,3,FALSE)) -> 0 | F13: =(VLOOKUP('9.0.10'!N13,'9.0.10'!$AM$4:$AO$55,3,FALSE)) -> 0 | G13: =(VLOOKUP('9.0.10'!O13,'9.0.10'!$AM$4:$AO$55,3,FALSE)) -> 0 | H13: =(VLOOKUP('9.0.10'!P13,'9.0.10'!$AM$4:$AO$55,3,FALSE)) -> 0 | ... X13: =(VLOOKUP('9.0.10'!AF13,'9.0.10'!$AM$4:$AO$55,3,FALSE)) -> 0
A14: =(VLOOKUP('9.0.10'!I14,'9.0.10'!$AM$4:$AO$55,3,FALSE)) -> 0 | B14: =(VLOOKUP('9.0.10'!J14,'9.0.10'!$AM$4:$AO$55,3,FALSE)) -> 0 | C14: =(VLOOKUP('9.0.10'!K14,'9.0.10'!$AM$4:$AO$55,3,FALSE)) -> 0 | D14: =(VLOOKUP('9.0.10'!L14,'9.0.10'!$AM$4:$AO$55,3,FALSE)) -> 0 | E14: =(VLOOKUP('9.0.10'!M14,'9.0.10'!$AM$4:$AO$55,3,FALSE)) -> 0 | F14: =(VLOOKUP('9.0.10'!N14,'9.0.10'!$AM$4:$AO$55,3,FALSE)) -> 0 | G14: =(VLOOKUP('9.0.10'!O14,'9.0.10'!$AM$4:$AO$55,3,FALSE)) -> 0 | H14: =(VLOOKUP('9.0.10'!P14,'9.0.10'!$AM$4:$AO$55,3,FALSE)) -> 0 | ... X14: =(VLOOKUP('9.0.10'!AF14,'9.0.10'!$AM$4:$AO$55,3,FALSE)) -> 0
A15: =(VLOOKUP('9.0.10'!I15,'9.0.10'!$AM$4:$AO$55,3,FALSE)) -> 0 | B15: =(VLOOKUP('9.0.10'!J15,'9.0.10'!$AM$4:$AO$55,3,FALSE)) -> 0 | C15: =(VLOOKUP('9.0.10'!K15,'9.0.10'!$AM$4:$AO$55,3,FALSE)) -> 0 | D15: =(VLOOKUP('9.0.10'!L15,'9.0.10'!$AM$4:$AO$55,3,FALSE)) -> 0 | E15: =(VLOOKUP('9.0.10'!M15,'9.0.10'!$AM$4:$AO$55,3,FALSE)) -> 0 | F15: =(VLOOKUP('9.0.10'!N15,'9.0.10'!$AM$4:$AO$55,3,FALSE)) -> 0 | G15: =(VLOOKUP('9.0.10'!O15,'9.0.10'!$AM$4:$AO$55,3,FALSE)) -> 0 | H15: =(VLOOKUP('9.0.10'!P15,'9.0.10'!$AM$4:$AO$55,3,FALSE)) -> 0 | ... X15: =(VLOOKUP('9.0.10'!AF15,'9.0.10'!$AM$4:$AO$55,3,FALSE)) -> 0
... A94: =(VLOOKUP('9.0.10'!I94,'9.0.10'!$AM$4:$AO$55,3,FALSE)) -> 35 | B94: =(VLOOKUP('9.0.10'!J94,'9.0.10'!$AM$4:$AO$55,3,FALSE)) -> 35 | C94: =(VLOOKUP('9.0.10'!K94,'9.0.10'!$AM$4:$AO$55,3,FALSE)) -> 35 | D94: =(VLOOKUP('9.0.10'!L94,'9.0.10'!$AM$4:$AO$55,3,FALSE)) -> 30 | E94: =(VLOOKUP('9.0.10'!M94,'9.0.10'!$AM$4:$AO$55,3,FALSE)) -> 0 | F94: =(VLOOKUP('9.0.10'!N94,'9.0.10'!$AM$4:$AO$55,3,FALSE)) -> 0 | G94: =(VLOOKUP('9.0.10'!O94,'9.0.10'!$AM$4:$AO$55,3,FALSE)) -> 0 | H94: =(VLOOKUP('9.0.10'!P94,'9.0.10'!$AM$4:$AO$55,3,FALSE)) -> 0 | ... X94: =(VLOOKUP('9.0.10'!AF94,'9.0.10'!$AM$4:$AO$55,3,FALSE)) -> 0

Sheet 亏损
A2: 队伍一 风 | C2: 步数 | D2: =COUNTIF(A4:H94,"<>空") -> 728 | E2: (不算跳步和传送) | I2: 队伍二 雷 | K2: 步数 | L2: =COUNTIF(I4:P94,"<>空") -> 728 | M2: (不算跳步和传送) | Q2: 队伍三 | S2: 总步数 | T2: =COUNTIF(Q4:X94,"<>空") -> 728 | U2: (不算跳步和传送)
A3: 1 | B3: 2 | C3: 3 | D3: 4 | E3: 5 | F3: 6 | G3: 7 | H3: 8 | I3: 1 | J3: 2 | K3: 3 | L3: 4 | M3: 5 | N3: 6 | O3: 7 | P3: 8 | Q3: 1 | R3: 2 | S3: 3 | T3: 4 | U3: 5 | V3: 6 | W3: 7 | X3: 8
A4: =(VLOOKUP('9.0.10'!I4,'9.0.10'!$AM$4:$AP$55,4,FALSE)) -> 44.222109 | B4: =(VLOOKUP('9.0.10'!J4,'9.0.10'!$AM$4:$AP$55,4,FALSE)) -> 44.222109 | C4: =(VLOOKUP('9.0.10'!K4,'9.0.10'!$AM$4:$AP$55,4,FALSE)) -> 44.222109 | D4: =(VLOOKUP('9.0.10'!L4,'9.0.10'!$AM$4:$AP$55,4,FALSE)) -> 44.222109 | E4: =(VLOOKUP('9.0.10'!M4,'9.0.10'!$AM$4:$AP$55,4,FALSE)) -> 44.222109 | F4: =(VLOOKUP('9.0.10'!N4,'9.0.10'!$AM$4:$AP$55,4,FALSE)) -> 44.222109 | G4: =(VLOOKUP('9.0.10'!O4,'9.0.10'!$AM$4:$AP$55,4,FALSE)) -> 0 | H4: =(VLOOKUP('9.0.10'!P4,'9.0.10'!$AM$4:$AP$55,4,FALSE)) -> 0 | ... X4: =(VLOOKUP('9.0.10'!AF4,'9.0.10'!$AM$4:$AP$55,4,FALSE)) -> 0
