Workbook

Sheet 组织分包
A1: 序号 | B1: 28 | D1: 1.战力每两周更新一次，阵容不同会有所浮动 | Y1: Rank Value | AA1: 总积分
D2: 2.战力得分按照比例分配。10%小伙伴获得12分。20%小伙伴获得10分。25%小伙伴获得8分。30%小伙伴获得6分。15%小伙伴获得4分 | Y2: =N9+1 -> 8 | AA2: =M9*N9 -> 154
D3: 3.组织战全勤，本服获得额外积分3分，跨服获得额外积分4分 | Y3: =N10+Y2 -> 15 | AA3: =M10*N10 -> 91
D4: 4.参加忍战，本服单场获得2分，跨服单场获得3分。 | Y4: =N11+Y3 -> 21 | AA4: =M11*N11 -> 60
D5: 5.分包总分=本周得分+上周得分。本周得分=参战得分+战力+奖励得分。参战得分= 组织成员本周参战次数*参战积分。
D6: 6.奖励得分包含并不限于：分包统计，接引新人。详情见备注 | U6: 黄色标记格子需要输入
D7: 7.小号不计得分，默认发放蓝包 | U7: 绿色格子为自动计算
C8: 年 | D8: 月 | F8: 日 | M8: 礼包扣除DKP值 | N8: 数量 | O8: 已发放数量 | P8: 剩余数量
A9: 统计时间 | B9: 起 | C9: 2022 | D9: 12 | F9: 25 | K9: 1 | L9: 传说 | M9: =IF($C$12=1,礼包!N12,礼包!N6) -> 22 | N9: 7 | O9: =COUNTIF($S$15:$S$271,1) -> 7 | P9: =N9-O9 -> 0 | T9: 单次忍战积分 | U9: =IF($C$12=1,2,3) -> 3
B10: 止 | C10: 2022 | D10: 12 | F10: 31 | K10: 2 | L10: 英雄 | M10: =IF($C$12=1,礼包!N13,礼包!N7) -> 13 | N10: 7 | O10: =COUNTIF($S$15:$S$271,2) -> 7 | P10: =N10-O10 -> 0 | T10: 忍战全勤额外积分 | U10: =IF($C$12=1,3,4) -> 4
K11: 3 | L11: 精英 | M11: =IF($C$12=1,礼包!N14,礼包!N8) -> 10 | N11: 6 | O11: =COUNTIF($S$15:$S$271,3) -> 6 | P11: =N11-O11 -> 0 | T11: 本周忍战全勤次数 | U11: =MAX($H$15:$H$153) -> 3
A12: 本周忍战为 | B12: =IF($C$12=1,"本服","跨服") -> 跨服 | C12: 2
H13: =COUNTIF(H15:H186,">0") -> 20
B14: 小号？ | D14: 成员名字 | F14: 战力 （万） | H14: 参战次数 | I14: 贡献值/周 | K14: 战力 | L14: 忍战参战积分 | M14: 忍战全勤积分 | N14: 周贡献 | P14: 上周积分结余 | Q14: 本周积分值 | R14: 积分小计 | S14: 本周礼包 | U14: 礼包扣除DKP | V14: DKP结余 | W14: 备注 | Y14: 备注2 | Z14: Rank function
B15: 0 | D15: 青衫 | F15: =INT(VLOOKUP(D15,战力表!A:B,2,)/10000) -> 353 | H15: 0 | K15: =IF(H15>0,VLOOKUP(D15,战力表!$A$3:$F$58,6,FALSE),0) -> 0 | L15: =H15*$U$9 -> 0 | M15: =IF(H15=$U$11,$U$10,0) -> 0 | N15: =IF(AND(I15<6000,I15>0),1,IF(AND(I15<12000,I15>=6000),2,IF(AND(I15<=30000,I15>=12000),3))) -> FALSE | P15: 285 | Q15: =K15+L15+M15+N15 -> 0 | R15: =P15+Q15 -> 285 | S15: =IF(H15=0,"",IF(B15=1,3,IF(Z15<$Y$2,1,IF(Z15<$Y$3,2,3)))) | T15: =IF(S15=$K$9,$L$9,IF(S15=$K$10,$L$10,IF(S15=$K$11,$L$11))) -> FALSE | U15: =-IF(S15=$K$9,$M$9,IF(S15=$K$10,$M$10,IF(S15=$K$11,$M$11))) -> 0 | V15: =P15+Q15+U15 -> 285 | W15: =IF(H15=0,List!$C$5,$C$3) -> 没有忍战，无法分包 | Y15: =P15+Q15 -> 285 | Z15: =RANK(Y15,$Y$15:$Y$55,0)+COUNTIF($Y$15:Y15,Y15)-1 -> 21
B16: 0 | D16: 神域メ万丈红尘 | F16: =INT(VLOOKUP(D16,战力表!A:B,2,)/10000) -> 253 | H16: 0 | K16: =IF(H16>0,VLOOKUP(D16,战力表!$A$3:$F$58,6,FALSE),0) -> 0 | L16: =H16*$U$9 -> 0 | M16: =IF(H16=$U$11,$U$10,0) -> 0 | N16: =IF(AND(I16<6000,I16>0),1,IF(AND(I16<12000,I16>=6000),2,IF(AND(I16<=30000,I16>=12000),3))) -> FALSE | P16: 213 | Q16: =K16+L16+M16+N16 -> 0 | R16: =P16+Q16 -> 213 | S16: =IF(H16=0,"",IF(B16=1,3,IF(Z16<$Y$2,1,IF(Z16<$Y$3,2,3)))) | T16: =IF(S16=$K$9,$L$9,IF(S16=$K$10,$L$10,IF(S16=$K$11,$L$11))) -> FALSE | U16: =-IF(S16=$K$9,$M$9,IF(S16=$K$10,$M$10,IF(S16=$K$11,$M$11))) -> 0 | V16: =P16+Q16+U16 -> 213 | W16: =IF(H16=0,List!$C$5,$C$3) -> 没有忍战，无法分包 | Y16: =P16+Q16 -> 213 | Z16: =RANK(Y16,$Y$15:$Y$55,0)+COUNTIF($Y$15:Y16,Y16)-1 -> 27
B17: 0 | D17: 无式 | F17: =INT(VLOOKUP(D17,战力表!A:B,2,)/10000) -> 265 | H17: 3 | K17: =IF(H17>0,VLOOKUP(D17,战力表!$A$3:$F$58,6,FALSE),0) -> 10 | L17: =H17*$U$9 -> 9 | M17: =IF(H17=$U$11,$U$10,0) -> 4 | N17: =IF(AND(I17<6000,I17>0),1,IF(AND(I17<12000,I17>=6000),2,IF(AND(I17<=30000,I17>=12000),3))) -> FALSE | P17: 295 | Q17: =K17+L17+M17+N17 -> 23 | R17: =P17+Q17 -> 318 | S17: =IF(H17=0,"",IF(B17=1,3,IF(Z17<$Y$2,1,IF(Z17<$Y$3,2,3)))) -> 1 | T17: =IF(S17=$K$9,$L$9,IF(S17=$K$10,$L$10,IF(S17=$K$11,$L$11))) -> 传说 | U17: =-IF(S17=$K$9,$M$9,IF(S17=$K$10,$M$10,IF(S17=$K$11,$M$11))) -> -22 | V17: =P17+Q17+U17 -> 296 | W17: =IF(H17=0,List!$C$5,$C$3) -> 0 | Y17: =P17+Q17 -> 318 | Z17: =RANK(Y17,$Y$15:$Y$55,0)+COUNTIF($Y$15:Y17,Y17)-1 -> 7
B18: 0 | D18: 冰凌神雨 | F18: =INT(VLOOKUP(D18,战力表!A:B,2,)/10000) -> 257 | H18: 0 | K18: =IF(H18>0,VLOOKUP(D18,战力表!$A$3:$F$58,6,FALSE),0) -> 0 | L18: =H18*$U$9 -> 0 | M18: =IF(H18=$U$11,$U$10,0) -> 0 | N18: =IF(AND(I18<6000,I18>0),1,IF(AND(I18<12000,I18>=6000),2,IF(AND(I18<=30000,I18>=12000),3))) -> FALSE | P18: 275 | Q18: =K18+L18+M18+N18 -> 0 | R18: 267 | S18: =IF(H18=0,"",IF(B18=1,3,IF(Z18<$Y$2,1,IF(Z18<$Y$3,2,3)))) | T18: =IF(S18=$K$9,$L$9,IF(S18=$K$10,$L$10,IF(S18=$K$11,$L$11))) -> FALSE | U18: =-IF(S18=$K$9,$M$9,IF(S18=$K$10,$M$10,IF(S18=$K$11,$M$11))) -> 0 | V18: =P18+Q18+U18 -> 275 | W18: =IF(H18=0,List!$C$5,$C$3) -> 没有忍战，无法分包 | Y18: =P18+Q18 -> 275 | Z18: =RANK(Y18,$Y$15:$Y$55,0)+COUNTIF($Y$15:Y18,Y18)-1 -> 23
B19: 0 | D19: 晚一 | F19: =INT(VLOOKUP(D19,战力表!A:B,2,)/10000) -> 248 | H19: 0 | K19: =IF(H19>0,VLOOKUP(D19,战力表!$A$3:$F$58,6,FALSE),0) -> 0 | L19: =H19*$U$9 -> 0 | M19: =IF(H19=$U$11,$U$10,0) -> 0 | N19: =IF(AND(I19<6000,I19>0),1,IF(AND(I19<12000,I19>=6000),2,IF(AND(I19<=30000,I19>=12000),3))) -> FALSE | P19: 207 | Q19: =K19+L19+M19+N19 -> 0 | R19: =P19+Q19 -> 207 | S19: =IF(H19=0,"",IF(B19=1,3,IF(Z19<$Y$2,1,IF(Z19<$Y$3,2,3)))) | T19: =IF(S19=$K$9,$L$9,IF(S19=$K$10,$L$10,IF(S19=$K$11,$L$11))) -> FALSE | U19: =-IF(S19=$K$9,$M$9,IF(S19=$K$10,$M$10,IF(S19=$K$11,$M$11))) -> 0 | V19: =P19+Q19+U19 -> 207 | W19: =IF(H19=0,List!$C$5,$C$3) -> 没有忍战，无法分包 | Y19: =P19+Q19 -> 207 | Z19: =RANK(Y19,$Y$15:$Y$55,0)+COUNTIF($Y$15:Y19,Y19)-1 -> 28
B20: 0 | D20: 败家の喵了个咪 | F20: =INT(VLOOKUP(D20,战力表!A:B,2,)/10000) -> 259 | H20: 2 | K20: =IF(H20>0,VLOOKUP(D20,战力表!$A$3:$F$58,6,FALSE),0) -> 10 | L20: =H20*$U$9 -> 6 | M20: =IF(H20=$U$11,$U$10,0) -> 0 | N20: =IF(AND(I20<6000,I20>0),1,IF(AND(I20<12000,I20>=6000),2,IF(AND(I20<=30000,I20>=12000),3))) -> FALSE | P20: 274 | Q20: =K20+L20+M20+N20 -> 16 | R20: =P20+Q20 -> 290 | S20: =IF(H20=0,"",IF(B20=1,3,IF(Z20<$Y$2,1,IF(Z20<$Y$3,2,3)))) -> 3 | T20: =IF(S20=$K$9,$L$9,IF(S20=$K$10,$L$10,IF(S20=$K$11,$L$11))) -> 精英 | U20: =-IF(S20=$K$9,$M$9,IF(S20=$K$10,$M$10,IF(S20=$K$11,$M$11))) -> -10 | V20: =P20+Q20+U20 -> 280 | W20: =IF(H20=0,List!$C$5,$C$3) -> 0 | Y20: =P20+Q20 -> 290 | Z20: =RANK(Y20,$Y$15:$Y$55,0)+COUNTIF($Y$15:Y20,Y20)-1 -> 19
B21: 0 | D21: 宇智波斑 | F21: =INT(VLOOKUP(D21,战力表!A:B,2,)/10000) -> 264 | H21: 0 | K21: =IF(H21>0,VLOOKUP(D21,战力表!$A$3:$F$58,6,FALSE),0) -> 0 | L21: =H21*$U$9 -> 0 | M21: =IF(H21=$U$11,$U$10,0) -> 0 | N21: =IF(AND(I21<6000,I21>0),1,IF(AND(I21<12000,I21>=6000),2,IF(AND(I21<=30000,I21>=12000),3))) -> FALSE | P21: 289 | Q21: =K21+L21+M21+N21 -> 0 | R21: =P21+Q21 -> 289 | S21: =IF(H21=0,"",IF(B21=1,3,IF(Z21<$Y$2,1,IF(Z21<$Y$3,2,3)))) | T21: =IF(S21=$K$9,$L$9,IF(S21=$K$10,$L$10,IF(S21=$K$11,$L$11))) -> FALSE | U21: =-IF(S21=$K$9,$M$9,IF(S21=$K$10,$M$10,IF(S21=$K$11,$M$11))) -> 0 | V21: =P21+Q21+U21 -> 289 | W21: =IF(H21=0,List!$C$5,$C$3) -> 没有忍战，无法分包 | Y21: =P21+Q21 -> 289 | Z21: =RANK(Y21,$Y$15:$Y$55,0)+COUNTIF($Y$15:Y21,Y21)-1 -> 20
B22: 0 | D22: 胖纸 | F22: =INT(VLOOKUP(D22,战力表!A:B,2,)/10000) -> 245 | H22: 3 | K22: =IF(H22>0,VLOOKUP(D22,战力表!$A$3:$F$58,6,FALSE),0) -> 10 | L22: =H22*$U$9 -> 9 | M22: =IF(H22=$U$11,$U$10,0) -> 4 | N22: =IF(AND(I22<6000,I22>0),1,IF(AND(I22<12000,I22>=6000),2,IF(AND(I22<=30000,I22>=12000),3))) -> FALSE | P22: 297 | Q22: =K22+L22+M22+N22 -> 23 | R22: =P22+Q22 -> 320 | S22: =IF(H22=0,"",IF(B22=1,3,IF(Z22<$Y$2,1,IF(Z22<$Y$3,2,3)))) -> 1 | T22: =IF(S22=$K$9,$L$9,IF(S22=$K$10,$L$10,IF(S22=$K$11,$L$11))) -> 传说 | U22: =-IF(S22=$K$9,$M$9,IF(S22=$K$10,$M$10,IF(S22=$K$11,$M$11))) -> -22 | V22: =P22+Q22+U22 -> 298 | W22: =IF(H22=0,List!$C$5,$C$3) -> 0 | Y22: =P22+Q22 -> 320 | Z22: =RANK(Y22,$Y$15:$Y$55,0)+COUNTIF($Y$15:Y22,Y22)-1 -> 2
B23: 0 | D23: 文浩 | F23: =INT(VLOOKUP(D23,战力表!A:B,2,)/10000) -> 242 | H23: 2 | K23: =IF(H23>0,VLOOKUP(D23,战力表!$A$3:$F$58,6,FALSE),0) -> 9 | L23: =H23*$U$9 -> 6 | M23: =IF(H23=$U$11,$U$10,0) -> 0 | N23: =IF(AND(I23<6000,I23>0),1,IF(AND(I23<12000,I23>=6000),2,IF(AND(I23<=30000,I23>=12000),3))) -> FALSE | P23: 289 | Q23: =K23+L23+M23+N23 -> 15 | R23: =P23+Q23 -> 304 | S23: =IF(H23=0,"",IF(B23=1,3,IF(Z23<$Y$2,1,IF(Z23<$Y$3,2,3)))) -> 3 | T23: =IF(S23=$K$9,$L$9,IF(S23=$K$10,$L$10,IF(S23=$K$11,$L$11))) -> 精英 | U23: =-IF(S23=$K$9,$M$9,IF(S23=$K$10,$M$10,IF(S23=$K$11,$M$11))) -> -10 | V23: =P23+Q23+U23 -> 294 | W23: =IF(H23=0,List!$C$5,$C$3) -> 0 | Y23: =P23+Q23 -> 304 | Z23: =RANK(Y23,$Y$15:$Y$55,0)+COUNTIF($Y$15:Y23,Y23)-1 -> 16
B24: 0 | D24: 拾壹月拾壹 | F24: =INT(VLOOKUP(D24,战力表!A:B,2,)/10000) -> 244 | H24: 3 | K24: =IF(H24>0,VLOOKUP(D24,战力表!$A$3:$F$58,6,FALSE),0) -> 9 | L24: =H24*$U$9 -> 9 | M24: =IF(H24=$U$11,$U$10,0) -> 4 | N24: =IF(AND(I24<6000,I24>0),1,IF(AND(I24<12000,I24>=6000),2,IF(AND(I24<=30000,I24>=12000),3))) -> FALSE | P24: 299 | Q24: =K24+L24+M24+N24 -> 22 | R24: =P24+Q24 -> 321 | S24: =IF(H24=0,"",IF(B24=1,3,IF(Z24<$Y$2,1,IF(Z24<$Y$3,2,3)))) -> 1 | T24: =IF(S24=$K$9,$L$9,IF(S24=$K$10,$L$10,IF(S24=$K$11,$L$11))) -> 传说 | U24: =-IF(S24=$K$9,$M$9,IF(S24=$K$10,$M$10,IF(S24=$K$11,$M$11))) -> -22 | V24: =P24+Q24+U24 -> 299 | W24: =IF(H24=0,List!$C$5,$C$3) -> 0 | Y24: =P24+Q24 -> 321 | Z24: =RANK(Y24,$Y$15:$Y$55,0)+COUNTIF($Y$15:Y24,Y24)-1 -> 1
B25: 0 | D25: 嘿嘿嘿 | F25: =INT(VLOOKUP(D25,战力表!A:B,2,)/10000) -> 240 | H25: 3 | K25: =IF(H25>0,VLOOKUP(D25,战力表!$A$3:$F$58,6,FALSE),0) -> 9 | L25: =H25*$U$9 -> 9 | M25: =IF(H25=$U$11,$U$10,0) -> 4 | N25: =IF(AND(I25<6000,I25>0),1,IF(AND(I25<12000,I25>=6000),2,IF(AND(I25<=30000,I25>=12000),3))) -> FALSE | P25: 291 | Q25: =K25+L25+M25+N25 -> 22 | R25: =P25+Q25 -> 313 | S25: =IF(H25=0,"",IF(B25=1,3,IF(Z25<$Y$2,1,IF(Z25<$Y$3,2,3)))) -> 2 | T25: =IF(S25=$K$9,$L$9,IF(S25=$K$10,$L$10,IF(S25=$K$11,$L$11))) -> 英雄 | U25: =-IF(S25=$K$9,$M$9,IF(S25=$K$10,$M$10,IF(S25=$K$11,$M$11))) -> -13 | V25: =P25+Q25+U25 -> 300 | W25: =IF(H25=0,List!$C$5,$C$3) -> 0 | Y25: =P25+Q25 -> 313 | Z25: =RANK(Y25,$Y$15:$Y$55,0)+COUNTIF($Y$15:Y25,Y25)-1 -> 13
B26: 0 | D26: Ms、音梵塔 | F26: 234 | H26: 3 | K26: =IF(H26>0,VLOOKUP(D26,战力表!$A$3:$F$58,6,FALSE),0) -> 10 | L26: =H26*$U$9 -> 9 | M26: =IF(H26=$U$11,$U$10,0) -> 4 | N26: =IF(AND(I26<6000,I26>0),1,IF(AND(I26<12000,I26>=6000),2,IF(AND(I26<=30000,I26>=12000),3))) -> FALSE | P26: 292 | Q26: =K26+L26+M26+N26 -> 23 | R26: =P26+Q26 -> 315 | S26: =IF(H26=0,"",IF(B26=1,3,IF(Z26<$Y$2,1,IF(Z26<$Y$3,2,3)))) -> 2 | T26: =IF(S26=$K$9,$L$9,IF(S26=$K$10,$L$10,IF(S26=$K$11,$L$11))) -> 英雄 | U26: =-IF(S26=$K$9,$M$9,IF(S26=$K$10,$M$10,IF(S26=$K$11,$M$11))) -> -13 | V26: =P26+Q26+U26 -> 302 | W26: =IF(H26=0,List!$C$5,$C$3) -> 0 | Y26: =P26+Q26 -> 315 | Z26: =RANK(Y26,$Y$15:$Y$55,0)+COUNTIF($Y$15:Y26,Y26)-1 -> 10
B27: 0 | D27: 血魂 | F27: =INT(VLOOKUP(D27,战力表!A:B,2,)/10000) -> 239 | H27: 3 | K27: =IF(H27>0,VLOOKUP(D27,战力表!$A$3:$F$58,6,FALSE),0) -> 9 | L27: =H27*$U$9 -> 9 | M27: =IF(H27=$U$11,$U$10,0) -> 4 | N27: =IF(AND(I27<6000,I27>0),1,IF(AND(I27<12000,I27>=6000),2,IF(AND(I27<=30000,I27>=12000),3))) -> FALSE | P27: 292 | Q27: =K27+L27+M27+N27 -> 22 | R27: =P27+Q27 -> 314 | S27: =IF(H27=0,"",IF(B27=1,3,IF(Z27<$Y$2,1,IF(Z27<$Y$3,2,3)))) -> 2 | T27: =IF(S27=$K$9,$L$9,IF(S27=$K$10,$L$10,IF(S27=$K$11,$L$11))) -> 英雄 | U27: =-IF(S27=$K$9,$M$9,IF(S27=$K$10,$M$10,IF(S27=$K$11,$M$11))) -> -13 | V27: =P27+Q27+U27 -> 301 | W27: =IF(H27=0,List!$C$5,$C$3) -> 0 | Y27: =P27+Q27 -> 314 | Z27: =RANK(Y27,$Y$15:$Y$55,0)+COUNTIF($Y$15:Y27,Y27)-1 -> 11
B28: 0 | D28: 风起时 | F28: =INT(VLOOKUP(D28,战力表!A:B,2,)/10000) -> 231 | H28: 3 | K28: =IF(H28>0,VLOOKUP(D28,战力表!$A$3:$F$58,6,FALSE),0) -> 8 | L28: =H28*$U$9 -> 9 | M28: =IF(H28=$U$11,$U$10,0) -> 4 | N28: =IF(AND(I28<6000,I28>0),1,IF(AND(I28<12000,I28>=6000),2,IF(AND(I28<=30000,I28>=12000),3))) -> FALSE | P28: 299 | Q28: =K28+L28+M28+N28 -> 21 | R28: =P28+Q28 -> 320 | S28: =IF(H28=0,"",IF(B28=1,3,IF(Z28<$Y$2,1,IF(Z28<$Y$3,2,3)))) -> 1 | T28: =IF(S28=$K$9,$L$9,IF(S28=$K$10,$L$10,IF(S28=$K$11,$L$11))) -> 传说 | U28: =-IF(S28=$K$9,$M$9,IF(S28=$K$10,$M$10,IF(S28=$K$11,$M$11))) -> -22 | V28: =P28+Q28+U28 -> 298 | W28: =IF(H28=0,List!$C$5,$C$3) -> 0 | Y28: =P28+Q28 -> 320 | Z28: =RANK(Y28,$Y$15:$Y$55,0)+COUNTIF($Y$15:Y28,Y28)-1 -> 3
B29: 0 | D29: }蟑螂恶霸{ | F29: =INT(VLOOKUP(D29,战力表!A:B,2,)/10000) -> 204 | H29: 0 | K29: =IF(H29>0,VLOOKUP(D29,战力表!$A$3:$F$58,6,FALSE),0) -> 0 | L29: =H29*$U$9 -> 0 | M29: =IF(H29=$U$11,$U$10,0) -> 0 | N29: =IF(AND(I29<6000,I29>0),1,IF(AND(I29<12000,I29>=6000),2,IF(AND(I29<=30000,I29>=12000),3))) -> FALSE | P29: 177 | Q29: =K29+L29+M29+N29 -> 0 | R29: =P29+Q29 -> 177 | S29: =IF(H29=0,"",IF(B29=1,3,IF(Z29<$Y$2,1,IF(Z29<$Y$3,2,3)))) | T29: =IF(S29=$K$9,$L$9,IF(S29=$K$10,$L$10,IF(S29=$K$11,$L$11))) -> FALSE | U29: =-IF(S29=$K$9,$M$9,IF(S29=$K$10,$M$10,IF(S29=$K$11,$M$11))) -> 0 | V29: =P29+Q29+U29 -> 177 | W29: =IF(H29=0,List!$C$5,$C$3) -> 没有忍战，无法分包 | Y29: =P29+Q29 -> 177 | Z29: =RANK(Y29,$Y$15:$Y$55,0)+COUNTIF($Y$15:Y29,Y29)-1 -> 31
B30: 0 | D30: 失研患者 | F30: =INT(VLOOKUP(D30,战力表!A:B,2,)/10000) -> 217 | H30: 2 | K30: =IF(H30>0,VLOOKUP(D30,战力表!$A$3:$F$58,6,FALSE),0) -> 8 | L30: =H30*$U$9 -> 6 | M30: =IF(H30=$U$11,$U$10,0) -> 0 | N30: =IF(AND(I30<6000,I30>0),1,IF(AND(I30<12000,I30>=6000),2,IF(AND(I30<=30000,I30>=12000),3))) -> FALSE | P30: 297 | Q30: =K30+L30+M30+N30 -> 14 | R30: =P30+Q30 -> 311 | S30: =IF(H30=0,"",IF(B30=1,3,IF(Z30<$Y$2,1,IF(Z30<$Y$3,2,3)))) -> 2 | T30: =IF(S30=$K$9,$L$9,IF(S30=$K$10,$L$10,IF(S30=$K$11,$L$11))) -> 英雄 | U30: =-IF(S30=$K$9,$M$9,IF(S30=$K$10,$M$10,IF(S30=$K$11,$M$11))) -> -13 | V30: =P30+Q30+U30 -> 298 | W30: =IF(H30=0,List!$C$5,$C$3) -> 0 | Y30: =P30+Q30 -> 311 | Z30: =RANK(Y30,$Y$15:$Y$55,0)+COUNTIF($Y$15:Y30,Y30)-1 -> 14
B31: 0 | D31: 过路人停驻 | F31: =INT(VLOOKUP(D31,战力表!A:B,2,)/10000) -> 210 | H31: 3 | K31: =IF(H31>0,VLOOKUP(D31,战力表!$A$3:$F$58,6,FALSE),0) -> 8 | L31: =H31*$U$9 -> 9 | M31: =IF(H31=$U$11,$U$10,0) -> 4 | N31: =IF(AND(I31<6000,I31>0),1,IF(AND(I31<12000,I31>=6000),2,IF(AND(I31<=30000,I31>=12000),3))) -> FALSE | P31: 298 | Q31: =K31+L31+M31+N31 -> 21 | R31: =P31+Q31 -> 319 | S31: =IF(H31=0,"",IF(B31=1,3,IF(Z31<$Y$2,1,IF(Z31<$Y$3,2,3)))) -> 1 | T31: =IF(S31=$K$9,$L$9,IF(S31=$K$10,$L$10,IF(S31=$K$11,$L$11))) -> 传说 | U31: =-IF(S31=$K$9,$M$9,IF(S31=$K$10,$M$10,IF(S31=$K$11,$M$11))) -> -22 | V31: =P31+Q31+U31 -> 297 | W31: =IF(H31=0,List!$C$5,$C$3) -> 0 | Y31: =P31+Q31 -> 319 | Z31: =RANK(Y31,$Y$15:$Y$55,0)+COUNTIF($Y$15:Y31,Y31)-1 -> 5
B32: 0 | D32: 神域メ诗航 | F32: =INT(VLOOKUP(D32,战力表!A:B,2,)/10000) -> 210 | H32: 0 | K32: =IF(H32>0,VLOOKUP(D32,战力表!$A$3:$F$58,6,FALSE),0) -> 0 | L32: =H32*$U$9 -> 0 | M32: =IF(H32=$U$11,$U$10,0) -> 0 | N32: =IF(AND(I32<6000,I32>0),1,IF(AND(I32<12000,I32>=6000),2,IF(AND(I32<=30000,I32>=12000),3))) -> FALSE | P32: 295 | Q32: =K32+L32+M32+N32 -> 0 | R32: =P32+Q32 -> 295 | S32: =IF(H32=0,"",IF(B32=1,3,IF(Z32<$Y$2,1,IF(Z32<$Y$3,2,3)))) | T32: =IF(S32=$K$9,$L$9,IF(S32=$K$10,$L$10,IF(S32=$K$11,$L$11))) -> FALSE | U32: =-IF(S32=$K$9,$M$9,IF(S32=$K$10,$M$10,IF(S32=$K$11,$M$11))) -> 0 | V32: =P32+Q32+U32 -> 295 | W32: =IF(H32=0,List!$C$5,$C$3) -> 没有忍战，无法分包 | Y32: =P32+Q32 -> 295 | Z32: =RANK(Y32,$Y$15:$Y$55,0)+COUNTIF($Y$15:Y32,Y32)-1 -> 17
B33: 0 | D33: 小宫山云空 | F33: =INT(VLOOKUP(D33,战力表!A:B,2,)/10000) -> 204 | H33: 3 | K33: =IF(H33>0,VLOOKUP(D33,战力表!$A$3:$F$58,6,FALSE),0) -> 8 | L33: =H33*$U$9 -> 9 | M33: =IF(H33=$U$11,$U$10,0) -> 4 | N33: =IF(AND(I33<6000,I33>0),1,IF(AND(I33<12000,I33>=6000),2,IF(AND(I33<=30000,I33>=12000),3))) -> FALSE | P33: 298 | Q33: =K33+L33+M33+N33 -> 21 | R33: =P33+Q33 -> 319 | S33: =IF(H33=0,"",IF(B33=1,3,IF(Z33<$Y$2,1,IF(Z33<$Y$3,2,3)))) -> 1 | T33: =IF(S33=$K$9,$L$9,IF(S33=$K$10,$L$10,IF(S33=$K$11,$L$11))) -> 传说 | U33: =-IF(S33=$K$9,$M$9,IF(S33=$K$10,$M$10,IF(S33=$K$11,$M$11))) -> -22 | V33: =P33+Q33+U33 -> 297 | W33: =IF(H33=0,List!$C$5,$C$3) -> 0 | Y33: =P33+Q33 -> 319 | Z33: =RANK(Y33,$Y$15:$Y$55,0)+COUNTIF($Y$15:Y33,Y33)-1 -> 6
B34: 0 | D34: 月光の胜者达 | F34: =INT(VLOOKUP(D34,战力表!A:B,2,)/10000) -> 197 | H34: 0 | K34: =IF(H34>0,VLOOKUP(D34,战力表!$A$3:$F$58,6,FALSE),0) -> 0 | L34: =H34*$U$9 -> 0 | M34: =IF(H34=$U$11,$U$10,0) -> 0 | N34: =IF(AND(I34<6000,I34>0),1,IF(AND(I34<12000,I34>=6000),2,IF(AND(I34<=30000,I34>=12000),3))) -> FALSE | P34: 270 | Q34: =K34+L34+M34+N34 -> 0 | R34: =P34+Q34 -> 270 | S34: =IF(H34=0,"",IF(B34=1,3,IF(Z34<$Y$2,1,IF(Z34<$Y$3,2,3)))) | T34: =IF(S34=$K$9,$L$9,IF(S34=$K$10,$L$10,IF(S34=$K$11,$L$11))) -> FALSE | U34: =-IF(S34=$K$9,$M$9,IF(S34=$K$10,$M$10,IF(S34=$K$11,$M$11))) -> 0 | V34: =P34+Q34+U34 -> 270 | W34: =IF(H34=0,List!$C$5,$C$3) -> 没有忍战，无法分包 | Y34: =P34+Q34 -> 270 | Z34: =RANK(Y34,$Y$15:$Y$55,0)+COUNTIF($Y$15:Y34,Y34)-1 -> 24
B35: 0 | D35: 神域メ空空 | F35: =INT(VLOOKUP(D35,战力表!A:B,2,)/10000) -> 169 | H35: 0 | K35: =IF(H35>0,VLOOKUP(D35,战力表!$A$3:$F$58,6,FALSE),0) -> 0 | L35: =H35*$U$9 -> 0 | M35: =IF(H35=$U$11,$U$10,0) -> 0 | N35: =IF(AND(I35<6000,I35>0),1,IF(AND(I35<12000,I35>=6000),2,IF(AND(I35<=30000,I35>=12000),3))) -> FALSE | P35: 206 | Q35: =K35+L35+M35+N35 -> 0 | R35: =P35+Q35 -> 206 | S35: =IF(H35=0,"",IF(B35=1,3,IF(Z35<$Y$2,1,IF(Z35<$Y$3,2,3)))) | T35: =IF(S35=$K$9,$L$9,IF(S35=$K$10,$L$10,IF(S35=$K$11,$L$11))) -> FALSE | U35: =-IF(S35=$K$9,$M$9,IF(S35=$K$10,$M$10,IF(S35=$K$11,$M$11))) -> 0 | V35: =P35+Q35+U35 -> 206 | W35: =IF(H35=0,List!$C$5,$C$3) -> 没有忍战，无法分包 | Y35: =P35+Q35 -> 206 | Z35: =RANK(Y35,$Y$15:$Y$55,0)+COUNTIF($Y$15:Y35,Y35)-1 -> 29
B36: 0 | D36: 神域メ快乐 | F36: =INT(VLOOKUP(D36,战力表!A:B,2,)/10000) -> 178 | H36: 3 | K36: =IF(H36>0,VLOOKUP(D36,战力表!$A$3:$F$58,6,FALSE),0) -> 8 | L36: =H36*$U$9 -> 9 | M36: =IF(H36=$U$11,$U$10,0) -> 4 | N36: =IF(AND(I36<6000,I36>0),1,IF(AND(I36<12000,I36>=6000),2,IF(AND(I36<=30000,I36>=12000),3))) -> FALSE | P36: 295 | Q36: =K36+L36+M36+N36 -> 21 | R36: =P36+Q36 -> 316 | S36: =IF(H36=0,"",IF(B36=1,3,IF(Z36<$Y$2,1,IF(Z36<$Y$3,2,3)))) -> 2 | T36: =IF(S36=$K$9,$L$9,IF(S36=$K$10,$L$10,IF(S36=$K$11,$L$11))) -> 英雄 | U36: =-IF(S36=$K$9,$M$9,IF(S36=$K$10,$M$10,IF(S36=$K$11,$M$11))) -> -13 | V36: =P36+Q36+U36 -> 303 | W36: =IF(H36=0,List!$C$5,$C$3) -> 0 | Y36: =P36+Q36 -> 316 | Z36: =RANK(Y36,$Y$15:$Y$55,0)+COUNTIF($Y$15:Y36,Y36)-1 -> 9
B37: 0 | D37: 木叶の白牙 | F37: =INT(VLOOKUP(D37,战力表!A:B,2,)/10000) -> 184 | H37: 0 | K37: =IF(H37>0,VLOOKUP(D37,战力表!$A$3:$F$58,6,FALSE),0) -> 0 | L37: =H37*$U$9 -> 0 | M37: =IF(H37=$U$11,$U$10,0) -> 0 | N37: =IF(AND(I37<6000,I37>0),1,IF(AND(I37<12000,I37>=6000),2,IF(AND(I37<=30000,I37>=12000),3))) -> FALSE | P37: 265 | Q37: =K37+L37+M37+N37 -> 0 | R37: =P37+Q37 -> 265 | S37: =IF(H37=0,"",IF(B37=1,3,IF(Z37<$Y$2,1,IF(Z37<$Y$3,2,3)))) | T37: =IF(S37=$K$9,$L$9,IF(S37=$K$10,$L$10,IF(S37=$K$11,$L$11))) -> FALSE | U37: =-IF(S37=$K$9,$M$9,IF(S37=$K$10,$M$10,IF(S37=$K$11,$M$11))) -> 0 | V37: =P37+Q37+U37 -> 265 | W37: =IF(H37=0,List!$C$5,$C$3) -> 没有忍战，无法分包 | Y37: =P37+Q37 -> 265 | Z37: =RANK(Y37,$Y$15:$Y$55,0)+COUNTIF($Y$15:Y37,Y37)-1 -> 25
B38: 0 | D38: 六道轮回 | F38: =INT(VLOOKUP(D38,战力表!A:B,2,)/10000) -> 160 | H38: 0 | K38: =IF(H38>0,VLOOKUP(D38,战力表!$A$3:$F$58,6,FALSE),0) -> 0 | L38: =H38*$U$9 -> 0 | M38: =IF(H38=$U$11,$U$10,0) -> 0 | N38: =IF(AND(I38<6000,I38>0),1,IF(AND(I38<12000,I38>=6000),2,IF(AND(I38<=30000,I38>=12000),3))) -> FALSE | P38: 105 | Q38: =K38+L38+M38+N38 -> 0 | R38: =P38+Q38 -> 105 | S38: =IF(H38=0,"",IF(B38=1,3,IF(Z38<$Y$2,1,IF(Z38<$Y$3,2,3)))) | T38: =IF(S38=$K$9,$L$9,IF(S38=$K$10,$L$10,IF(S38=$K$11,$L$11))) -> FALSE | U38: =-IF(S38=$K$9,$M$9,IF(S38=$K$10,$M$10,IF(S38=$K$11,$M$11))) -> 0 | V38: =P38+Q38+U38 -> 105 | W38: =IF(H38=0,List!$C$5,$C$3) -> 没有忍战，无法分包 | Y38: =P38+Q38 -> 105 | Z38: =RANK(Y38,$Y$15:$Y$55,0)+COUNTIF($Y$15:Y38,Y38)-1 -> 37
... B53: 1 | D53: 一汪薄青 | F53: =INT(VLOOKUP(D53,战力表!A:B,2,)/10000) -> 6 | H53: 0 | K53: =IF(H53>0,VLOOKUP(D53,战力表!$A$3:$F$58,6,FALSE),0) -> 0 | L53: =H53*$U$9 -> 0 | M53: =IF(H53=$U$11,$U$10,0) -> 0 | N53: =IF(AND(I53<6000,I53>0),1,IF(AND(I53<12000,I53>=6000),2,IF(AND(I53<=30000,I53>=12000),3))) -> FALSE | P53: 156 | Q53: =K53+L53+M53+N53 -> 0 | R53: =P53+Q53 -> 156 | S53: =IF(H53=0,"",IF(B53=1,3,IF(Z53<$Y$2,1,IF(Z53<$Y$3,2,3)))) | T53: =IF(S53=$K$9,$L$9,IF(S53=$K$10,$L$10,IF(S53=$K$11,$L$11))) -> FALSE | U53: =-IF(S53=$K$9,$M$9,IF(S53=$K$10,$M$10,IF(S53=$K$11,$M$11))) -> 0 | V53: =P53+Q53+U53 -> 156 | W53: =IF(H53=0,List!$C$5,$C$3) -> 没有忍战，无法分包 | Y53: =P53+Q53 -> 156 | Z53: =RANK(Y53,$Y$15:$Y$55,0)+COUNTIF($Y$15:Y53,Y53)-1 -> 33
D54: 幼稚园学渣 | F54: =INT(VLOOKUP(D54,战力表!A:B,2,)/10000) -> 188 | H54: 3 | K54: =IF(H54>0,VLOOKUP(D54,战力表!$A$3:$F$58,6,FALSE),0) -> 8 | L54: =H54*$U$9 -> 9 | M54: =IF(H54=$U$11,$U$10,0) -> 4 | N54: =IF(AND(I54<6000,I54>0),1,IF(AND(I54<12000,I54>=6000),2,IF(AND(I54<=30000,I54>=12000),3))) -> FALSE | P54: 299 | Q54: =K54+L54+M54+N54 -> 21 | R54: =P54+Q54 -> 320 | S54: =IF(H54=0,"",IF(B54=1,3,IF(Z54<$Y$2,1,IF(Z54<$Y$3,2,3)))) -> 1 | T54: =IF(S54=$K$9,$L$9,IF(S54=$K$10,$L$10,IF(S54=$K$11,$L$11))) -> 传说 | U54: =-IF(S54=$K$9,$M$9,IF(S54=$K$10,$M$10,IF(S54=$K$11,$M$11))) -> -22 | V54: =P54+Q54+U54 -> 298 | W54: =IF(H54=0,List!$C$5,$C$3) -> 0 | Y54: =P54+Q54 -> 320 | Z54: =RANK(Y54,$Y$15:$Y$55,0)+COUNTIF($Y$15:Y54,Y54)-1 -> 4
...

Sheet List
C4: 种类
C5: 没有忍战，无法分包

Sheet 战力表
B1: =COUNT(B3:B39) -> 37 | C1: =COUNTIF(C3:C41,1) -> 18
B2: 战力 | C2: 参战与否 | F2: 战力积分 | J2: 战力分布 | K2: 战力积分 | L2: 人数 | M2: 累加人数
A3: 青衫 | B3: 3530000 | C3: =IF(VLOOKUP(A3,组织分包!$D$15:$H$62,5,FALSE)>0,1,0) -> 0 | D3: =IF(C3=1,B3) -> FALSE | E3: =RANK(D3,$D$3:$D$43) -> #N/A | F3: =IF(C3=0,"",IF(E3<=$M$3,$K$3,IF(E3<=$M$4,$K$4,IF(E3<=$M$5,$K$5,IF(E3<=$M$6,$K$6,IF(E3<=$M$7,$K$7,IF(E3<=$M$8,$K$8,$K$9))))))) | J3: =L3/$C$1 -> 0.22222222 | K3: 10 | L3: 4 | M3: =L3 -> 4
A4: 神域メ万丈红尘 | B4: 2530000 | C4: =IF(VLOOKUP(A4,组织分包!$D$15:$H$62,5,FALSE)>0,1,0) -> 0 | D4: =IF(C4=1,B4) -> FALSE | E4: =RANK(D4,$D$3:$D$43) -> #N/A | F4: =IF(C4=0,"",IF(E4<=$M$3,$K$3,IF(E4<=$M$4,$K$4,IF(E4<=$M$5,$K$5,IF(E4<=$M$6,$K$6,IF(E4<=$M$7,$K$7,IF(E4<=$M$8,$K$8,$K$9))))))) | J4: =L4/$C$1 -> 0.22222222 | K4: 9 | L4: 4 | M4: =L4+M3 -> 8
A5: 无式 | B5: 2650000 | C5: =IF(VLOOKUP(A5,组织分包!$D$15:$H$62,5,FALSE)>0,1,0) -> 1 | D5: =IF(C5=1,B5) -> 2650000 | E5: =RANK(D5,$D$3:$D$43) -> 1 | F5: =IF(C5=0,"",IF(E5<=$M$3,$K$3,IF(E5<=$M$4,$K$4,IF(E5<=$M$5,$K$5,IF(E5<=$M$6,$K$6,IF(E5<=$M$7,$K$7,IF(E5<=$M$8,$K$8,$K$9))))))) -> 10 | J5: =L5/$C$1 -> 0.33333333 | K5: 8 | L5: 6 | M5: =L5+M4 -> 14
A6: 晚一 | B6: 2480000 | C6: =IF(VLOOKUP(A6,组织分包!$D$15:$H$62,5,FALSE)>0,1,0) -> 0 | D6: =IF(C6=1,B6) -> FALSE | E6: =RANK(D6,$D$3:$D$43) -> #N/A | F6: =IF(C6=0,"",IF(E6<=$M$3,$K$3,IF(E6<=$M$4,$K$4,IF(E6<=$M$5,$K$5,IF(E6<=$M$6,$K$6,IF(E6<=$M$7,$K$7,IF(E6<=$M$8,$K$8,$K$9))))))) | J6: =L6/$C$1 -> 0.55555556 | K6: 7 | L6: 10 | M6: =L6+M5 -> 24
A7: 冰凌神雨 | B7: 2570000 | C7: =IF(VLOOKUP(A7,组织分包!$D$15:$H$62,5,FALSE)>0,1,0) -> 0 | D7: =IF(C7=1,B7) -> FALSE | E7: =RANK(D7,$D$3:$D$43) -> #N/A | F7: =IF(C7=0,"",IF(E7<=$M$3,$K$3,IF(E7<=$M$4,$K$4,IF(E7<=$M$5,$K$5,IF(E7<=$M$6,$K$6,IF(E7<=$M$7,$K$7,IF(E7<=$M$8,$K$8,$K$9))))))) | J7: =L7/$C$1 -> 0.33333333 | K7: 6 | L7: 6 | M7: =L7+M6 -> 30
A8: 败家の喵了个咪 | B8: 2590000 | C8: =IF(VLOOKUP(A8,组织分包!$D$15:$H$62,5,FALSE)>0,1,0) -> 1 | D8: =IF(C8=1,B8) -> 2590000 | E8: =RANK(D8,$D$3:$D$43) -> 2 | F8: =IF(C8=0,"",IF(E8<=$M$3,$K$3,IF(E8<=$M$4,$K$4,IF(E8<=$M$5,$K$5,IF(E8<=$M$6,$K$6,IF(E8<=$M$7,$K$7,IF(E8<=$M$8,$K$8,$K$9))))))) -> 10 | J8: =L8/$C$1 -> 0.22222222 | K8: 5 | L8: 4 | M8: =L8+M7 -> 34
A9: 宇智波斑 | B9: 2640000 | C9: =IF(VLOOKUP(A9,组织分包!$D$15:$H$62,5,FALSE)>0,1,0) -> 0 | D9: =IF(C9=1,B9) -> FALSE | E9: =RANK(D9,$D$3:$D$43) -> #N/A | F9: =IF(C9=0,"",IF(E9<=$M$3,$K$3,IF(E9<=$M$4,$K$4,IF(E9<=$M$5,$K$5,IF(E9<=$M$6,$K$6,IF(E9<=$M$7,$K$7,IF(E9<=$M$8,$K$8,$K$9))))))) | J9: =L9/$C$1 -> -0.88888889 | K9: 4 | L9: =C1-SUM(L3:L8) -> -16 | M9: =L9+M8 -> 18
A10: 胖纸 | B10: 2450000 | C10: =IF(VLOOKUP(A10,组织分包!$D$15:$H$62,5,FALSE)>0,1,0) -> 1 | D10: =IF(C10=1,B10) -> 2450000 | E10: =RANK(D10,$D$3:$D$43) -> 4 | F10: =IF(C10=0,"",IF(E10<=$M$3,$K$3,IF(E10<=$M$4,$K$4,IF(E10<=$M$5,$K$5,IF(E10<=$M$6,$K$6,IF(E10<=$M$7,$K$7,IF(E10<=$M$8,$K$8,$K$9))))))) -> 10
A11: 文浩 | B11: 2420000 | C11: =IF(VLOOKUP(A11,组织分包!$D$15:$H$62,5,FALSE)>0,1,0) -> 1 | D11: =IF(C11=1,B11) -> 2420000 | E11: =RANK(D11,$D$3:$D$43) -> 6 | F11: =IF(C11=0,"",IF(E11<=$M$3,$K$3,IF(E11<=$M$4,$K$4,IF(E11<=$M$5,$K$5,IF(E11<=$M$6,$K$6,IF(E11<=$M$7,$K$7,IF(E11<=$M$8,$K$8,$K$9))))))) -> 9 | J11: =SUM(J3:J10) -> 1
A12: 拾壹月拾壹 | B12: 2440000 | C12: =IF(VLOOKUP(A12,组织分包!$D$15:$H$62,5,FALSE)>0,1,0) -> 1 | D12: =IF(C12=1,B12) -> 2440000 | E12: =RANK(D12,$D$3:$D$43) -> 5 | F12: =IF(C12=0,"",IF(E12<=$M$3,$K$3,IF(E12<=$M$4,$K$4,IF(E12<=$M$5,$K$5,IF(E12<=$M$6,$K$6,IF(E12<=$M$7,$K$7,IF(E12<=$M$8,$K$8,$K$9))))))) -> 9
A13: 嘿嘿嘿 | B13: 2400000 | C13: =IF(VLOOKUP(A13,组织分包!$D$15:$H$62,5,FALSE)>0,1,0) -> 1 | D13: =IF(C13=1,B13) -> 2400000 | E13: =RANK(D13,$D$3:$D$43) -> 7 | F13: =IF(C13=0,"",IF(E13<=$M$3,$K$3,IF(E13<=$M$4,$K$4,IF(E13<=$M$5,$K$5,IF(E13<=$M$6,$K$6,IF(E13<=$M$7,$K$7,IF(E13<=$M$8,$K$8,$K$9))))))) -> 9
A14: Ms、音梵塔 | B14: 2580000 | C14: =IF(VLOOKUP(A14,组织分包!$D$15:$H$62,5,FALSE)>0,1,0) -> 1 | D14: =IF(C14=1,B14) -> 2580000 | E14: =RANK(D14,$D$3:$D$43) -> 3 | F14: =IF(C14=0,"",IF(E14<=$M$3,$K$3,IF(E14<=$M$4,$K$4,IF(E14<=$M$5,$K$5,IF(E14<=$M$6,$K$6,IF(E14<=$M$7,$K$7,IF(E14<=$M$8,$K$8,$K$9))))))) -> 10
A15: 血魂 | B15: 2390000 | C15: =IF(VLOOKUP(A15,组织分包!$D$15:$H$62,5,FALSE)>0,1,0) -> 1 | D15: =IF(C15=1,B15) -> 2390000 | E15: =RANK(D15,$D$3:$D$43) -> 8 | F15: =IF(C15=0,"",IF(E15<=$M$3,$K$3,IF(E15<=$M$4,$K$4,IF(E15<=$M$5,$K$5,IF(E15<=$M$6,$K$6,IF(E15<=$M$7,$K$7,IF(E15<=$M$8,$K$8,$K$9))))))) -> 9
A16: 风起时 | B16: 2310000 | C16: =IF(VLOOKUP(A16,组织分包!$D$15:$H$62,5,FALSE)>0,1,0) -> 1 | D16: =IF(C16=1,B16) -> 2310000 | E16: =RANK(D16,$D$3:$D$43) -> 9 | F16: =IF(C16=0,"",IF(E16<=$M$3,$K$3,IF(E16<=$M$4,$K$4,IF(E16<=$M$5,$K$5,IF(E16<=$M$6,$K$6,IF(E16<=$M$7,$K$7,IF(E16<=$M$8,$K$8,$K$9))))))) -> 8
A17: }蟑螂恶霸{ | B17: 2045784 | C17: =IF(VLOOKUP(A17,组织分包!$D$15:$H$62,5,FALSE)>0,1,0) -> 0 | D17: =IF(C17=1,B17) -> FALSE | E17: =RANK(D17,$D$3:$D$43) -> #N/A | F17: =IF(C17=0,"",IF(E17<=$M$3,$K$3,IF(E17<=$M$4,$K$4,IF(E17<=$M$5,$K$5,IF(E17<=$M$6,$K$6,IF(E17<=$M$7,$K$7,IF(E17<=$M$8,$K$8,$K$9)))))))
A18: 失研患者 | B18: 2170000 | C18: =IF(VLOOKUP(A18,组织分包!$D$15:$H$62,5,FALSE)>0,1,0) -> 1 | D18: =IF(C18=1,B18) -> 2170000 | E18: =RANK(D18,$D$3:$D$43) -> 10 | F18: =IF(C18=0,"",IF(E18<=$M$3,$K$3,IF(E18<=$M$4,$K$4,IF(E18<=$M$5,$K$5,IF(E18<=$M$6,$K$6,IF(E18<=$M$7,$K$7,IF(E18<=$M$8,$K$8,$K$9))))))) -> 8
A19: 过路人停驻 | B19: 2100000 | C19: =IF(VLOOKUP(A19,组织分包!$D$15:$H$62,5,FALSE)>0,1,0) -> 1 | D19: =IF(C19=1,B19) -> 2100000 | E19: =RANK(D19,$D$3:$D$43) -> 11 | F19: =IF(C19=0,"",IF(E19<=$M$3,$K$3,IF(E19<=$M$4,$K$4,IF(E19<=$M$5,$K$5,IF(E19<=$M$6,$K$6,IF(E19<=$M$7,$K$7,IF(E19<=$M$8,$K$8,$K$9))))))) -> 8
A20: 神域メ诗航 | B20: 2100000 | C20: =IF(VLOOKUP(A20,组织分包!$D$15:$H$62,5,FALSE)>0,1,0) -> 0 | D20: =IF(C20=1,B20) -> FALSE | E20: =RANK(D20,$D$3:$D$43) -> #N/A | F20: =IF(C20=0,"",IF(E20<=$M$3,$K$3,IF(E20<=$M$4,$K$4,IF(E20<=$M$5,$K$5,IF(E20<=$M$6,$K$6,IF(E20<=$M$7,$K$7,IF(E20<=$M$8,$K$8,$K$9)))))))
A21: 小宫山云空 | B21: 2040000 | C21: =IF(VLOOKUP(A21,组织分包!$D$15:$H$62,5,FALSE)>0,1,0) -> 1 | D21: =IF(C21=1,B21) -> 2040000 | E21: =RANK(D21,$D$3:$D$43) -> 12 | F21: =IF(C21=0,"",IF(E21<=$M$3,$K$3,IF(E21<=$M$4,$K$4,IF(E21<=$M$5,$K$5,IF(E21<=$M$6,$K$6,IF(E21<=$M$7,$K$7,IF(E21<=$M$8,$K$8,$K$9))))))) -> 8
A22: 月光の胜者达 | B22: 1970000 | C22: =IF(VLOOKUP(A22,组织分包!$D$15:$H$62,5,FALSE)>0,1,0) -> 0 | D22: =IF(C22=1,B22) -> FALSE | E22: =RANK(D22,$D$3:$D$43) -> #N/A | F22: =IF(C22=0,"",IF(E22<=$M$3,$K$3,IF(E22<=$M$4,$K$4,IF(E22<=$M$5,$K$5,IF(E22<=$M$6,$K$6,IF(E22<=$M$7,$K$7,IF(E22<=$M$8,$K$8,$K$9)))))))
A23: 神域メ空空 | B23: 1697897 | C23: =IF(VLOOKUP(A23,组织分包!$D$15:$H$62,5,FALSE)>0,1,0) -> 0 | D23: =IF(C23=1,B23) -> FALSE | E23: =RANK(D23,$D$3:$D$43) -> #N/A | F23: =IF(C23=0,"",IF(E23<=$M$3,$K$3,IF(E23<=$M$4,$K$4,IF(E23<=$M$5,$K$5,IF(E23<=$M$6,$K$6,IF(E23<=$M$7,$K$7,IF(E23<=$M$8,$K$8,$K$9)))))))
... A43: 逆转 | B43: 630000 | C43: =IF(VLOOKUP(A43,组织分包!$D$15:$H$62,5,FALSE)>0,1,0) -> 1 | D43: =IF(C43=1,B43) -> 630000 | E43: =RANK(D43,$D$3:$D$43) -> 19 | F43: =IF(C43=0,"",IF(E43<=$M$3,$K$3,IF(E43<=$M$4,$K$4,IF(E43<=$M$5,$K$5,IF(E43<=$M$6,$K$6,IF(E43<=$M$7,$K$7,IF(E43<=$M$8,$K$8,$K$9))))))) -> 7
A44: 小李马路 | B44: 1868233
A45: 乌漆嘛黑
A46: 神域メ墨殇
A47: 神域メ基德
A48: 叶树落
A49: 肝琦 | B49: 1066676
A50: 百目鬼城夜 | B50: 1027326
A51: 飘逸的白 | B51: 1005928
A52: 岸本齐史 | B52: 618320
A53: 神域メ宠物 | B53: 608160
A54: 天龙.旒笙 | B54: 604504
A55: 神域メ斋藤 | B55: 869720
A56: 神域メ降临 | B56: 858119
A57: 神域メ舔蒂 | B57: 855959
A58: 神域メ大仲马 | B58: 803274
A59: 记忆中的你 | B59: 740352
...

Sheet 礼包
C2: 礼包积分计算
E3: 单价（元宝） | F3: 198 | G3: 100 | H3: 10
F4: 封印 | G4: 通灵 | H4: 原石 | I4: 小计 | J4: 消耗积分
C5: 跨服 | D5: 传说 | E5: 数量 | F5: 5 | G5: 7 | H5: 20
E6: 元宝 | F6: =F5*$F$3 -> 990 | G6: =G5*$G$3 -> 700 | H6: =H5*$H$3 -> 200 | I6: =SUM(F6:H6) -> 1890 | J6: 19 | L6: 19 | N6: =INT(L6*1.2) -> 22
D7: 英雄 | E7: 数量 | F7: 4 | G7: 6 | H7: 15 | L7: 15 | N7: =INT(L7/1.1) -> 13
E8: 元宝 | F8: =F7*$F$3 -> 792 | G8: =G7*$G$3 -> 600 | H8: =H7*$H$3 -> 150 | I8: =SUM(F8:H8) -> 1542 | J8: 15 | L8: 12 | N8: =INT(L8/1.2) -> 10
D9: 精英 | E9: 数量 | F9: 3 | G9: 5 | H9: 10
E10: 元宝 | F10: =F9*$F$3 -> 594 | G10: =G9*$G$3 -> 500 | H10: =H9*$H$3 -> 100 | I10: =SUM(F10:H10) -> 1194 | J10: 12
C11: 本服 | D11: 传说 | E11: 数量 | F11: 4 | G11: 5
E12: 元宝 | F12: =F11*$F$3 -> 792 | G12: =G11*$G$3 -> 500 | I12: =SUM(F12:H12) -> 1292 | J12: 13 | L12: 13 | N12: =INT(L12*1.2) -> 15
D13: 英雄 | E13: 数量 | F13: 3 | G13: 4 | L13: 10 | N13: =INT(L13/1.1) -> 9
E14: 元宝 | F14: =F13*$F$3 -> 594 | G14: =G13*$G$3 -> 400 | I14: =SUM(F14:H14) -> 994 | J14: 10 | L14: 7 | N14: =INT(L14/1.2) -> 5
D15: 精英 | E15: 数量 | F15: 2 | G15: 3
E16: 元宝 | F16: =F15*$F$3 -> 396 | G16: =G15*$G$3 -> 300 | I16: =SUM(F16:H16) -> 696 | J16: 7
C19: 积分原则
B20: 1 | C20: 参加忍战一次，积2分
B21: 2 | C21: 本周忍战全勤，额外活动2分
B22: 3 | C22: 战力对应积分计算。当前战力，除以10万，取整数，再减去3。距离65万战力，65/10-3 = 3积分
C25: 获得礼包时扣除相应的积分。
C26: 发放礼包时不因礼包颜色而有区别，当前分高者优先获得橙色，橙色发放完，发紫色，直至没有礼包。

Sheet 忍战
B3: 9分 | C3: 第1组 | G3: 8分 | H3: 第1组 | L3: 7分 | M3: 第1组 | R3: 成员名字 | S3: 战力 （万）
B4: 分组 | C4: 战力 | D4: 阵容 | G4: 分组 | H4: 战力 | I4: 阵容 | L4: 分组 | M4: 战力 | N4: 阵容 | R4: 青衫 | S4: 304
R5: 无羡 | S5: 234
R6: 神域メ万丈红尘 | S6: 232
R7: 晚一 | S7: 230
R8: 败家の喵了个咪 | S8: 226
B9: 9分 | C9: 第2组 | G9: 8分 | H9: 第2组 | L9: 7分 | M9: 第2组 | R9: 宇智波斑 | S9: 224
B10: 分组 | C10: 战力 | D10: 阵容 | G10: 分组 | H10: 战力 | I10: 阵容 | L10: 分组 | M10: 战力 | N10: 阵容 | R10: 无式 | S10: 217
R11: 文浩 | S11: 213
R12: 拾壹月拾壹 | S12: 210
R13: 嘿嘿嘿 | S13: 206
R14: 胖纸 | S14: 205
B15: 9分 | C15: 第3组 | G15: 8分 | H15: 第3组 | R15: Ms、音梵塔 | S15: 200
B16: 分组 | C16: 战力 | D16: 阵容 | G16: 分组 | H16: 战力 | I16: 阵容 | R16: 血魂 | S16: 199
R17: }蟑螂恶霸{ | S17: 194
R18: 失研患者 | S18: 188
R19: 旗木卡卡西づ | S19: 188
R20: 风起时 | S20: 183
B21: 6分 | C21: 第1组 | G21: 5分 | H21: 第1组 | L21: 4分 | M21: 第1组 | R21: 过路人停驻 | S21: 182
B22: 分组 | C22: 战力 | D22: 阵容 | G22: 分组 | H22: 战力 | I22: 阵容 | L22: 分组 | M22: 战力 | N22: 阵容 | R22: 神域メ诗航 | S22: 176
R23: 小宫山云空 | S23: 174
R24: 月光の胜者达 | S24: 165
R25: 神域メ宗麟 | S25: 163
R26: 冰凌神雨 | S26: 160
B27: 6分 | C27: 第2组 | G27: 5分 | H27: 第2组 | L27: 4分 | M27: 第2组 | R27: 神域メ快乐 | S27: 156
B28: 分组 | C28: 战力 | D28: 阵容 | G28: 分组 | H28: 战力 | I28: 阵容 | L28: 分组 | M28: 战力 | N28: 阵容 | R28: 神域メ空空 | S28: 153
R29: 六道轮回 | S29: 152
R30: 木叶の白牙 | S30: 151
R31: Mythe | S31: 146
R32: 佩恩天道づ | S32: 144
R33: 神域メ影皇 | S33: 135
R34: 神域メ咸湿老 | S34: 132
R35: 服部鬼 | S35: 124
R36: 烟头 | S36: 109
R37: 神域メ空调 | S37: 106

Sheet 积分调整（单次）
C2: 积分 | E2: 0.1
B3: 青衫 | C3: 477 | E3: =INT(C3*$E$2) -> 47
B4: 神、夜月 | C4: 329 | E4: =INT(C4*$E$2) -> 32
B5: 无羡 | C5: 372 | E5: =INT(C5*$E$2) -> 37
B6: 神域メ万丈红尘 | C6: 370 | E6: =INT(C6*$E$2) -> 37
B7: 败家の喵了个咪 | C7: 373 | E7: =INT(C7*$E$2) -> 37
B8: 晚一 | C8: 372 | E8: =INT(C8*$E$2) -> 37
B9: 无式 | C9: 366 | E9: =INT(C9*$E$2) -> 36
B10: 宇智波斑 | C10: 367 | E10: =INT(C10*$E$2) -> 36
B11: 文浩 | C11: 367 | E11: =INT(C11*$E$2) -> 36
B12: 胖纸 | C12: 366 | E12: =INT(C12*$E$2) -> 36
B13: 小李马路 | C13: 348 | E13: =INT(C13*$E$2) -> 34
B14: 拾壹月拾壹 | C14: 370 | E14: =INT(C14*$E$2) -> 37
... B39: 烟头 | C39: 112 | E39: =INT(C39*$E$2) -> 11
